Workbook

Sheet Inicio
A1: Simulador de motores – Introducción a Motores (MA.01.04)
A2: Instituto Superior Tecnológico Sudamericano · Carrera de Mecánica Automotriz · PAO octubre 2026 – febrero 2027
A4: Hoja | B4: Qué simula | C4: Unidad del PEA
A5: Ciclo_Otto | B5: Ciclo Otto ideal de aire estándar: estados, trabajo, rendimiento, PME y diagramas P–v y T–s | C5: 2.4 Ciclo Otto
A6: Ciclo_Diesel | B6: Ciclo Diesel ideal: estados, rendimiento y diagramas P–v y T–s; comparación con el Otto | C6: 2.5 y 2.6 Ciclo Diesel; Otto vs Diesel
A7: Rendimiento_r | B7: Rendimiento teórico en función de la relación de compresión (Otto y Diesel) | C7: 2.4.2 Influencia de la relación de compresión
A8: Geometria | B8: Cilindrada, relación de compresión, efecto de la junta de culata y aplanado de la culata | C8: 4.1 y 4.2 Geometría y parámetros
A9: Curvas | B9: Curvas características a partir del par medido: potencia, PME, consumo específico y elasticidad | C9: 4.3 Características del motor
A10: Biela_manivela | B10: Posición, velocidad y aceleración del pistón según el ángulo del cigüeñal | C10: 4.4 Mecanismo biela–manivela
A12: Cómo usar el simulador
A13: 1. Modifique solo las celdas amarillas con texto azul (datos de entrada). Todo lo demás se calcula con fórmulas y los diagramas se actualizan solos.
A14: 2. Cada hoja trae un ejemplo resuelto con datos de la guía didáctica o de la Actividad de aprendizaje N.° 1; compare sus cálculos a mano con los resultados.
A15: 3. Modelo de aire estándar con calores específicos constantes (cv = 0,718 kJ/kg·K; cp = 1,005 kJ/kg·K; R = 0,287 kJ/kg·K; k = 1,4), como en Çengel y Boles (2012).
A16: 4. Presión atmosférica de Loja ≈ 79 kPa (unos 2 060 m de altitud): úsela como P1 para ver la pérdida de PME de un motor atmosférico.
A17: 5. Actividad sugerida: cambie un dato, anote el resultado en una tabla y explique la tendencia (por ejemplo, η frente a r o Rc frente al espesor de la junta).
A19: Leyenda
A20: Dato de entrada
A21: Resultado calculado
A23: Referencias: Çengel, Y. A., y Boles, M. A. (2012). Termodinámica (7.ª ed.). McGraw-Hill · Escudero Fernández, S. et al. (2011). Motores. Macmillan · Payri, F., y Desantes, J. M. (2011). Motores de combustión interna alternativos. Reverté.

Sheet Ciclo_Otto
A1: Ciclo Otto ideal de aire estándar
A2: Unidad 2 · 2.4. Procesos: 1→2 compresión isentrópica · 2→3 aporte de calor a v = cte · 3→4 expansión isentrópica · 4→1 rechazo de calor a v = cte
A4: Datos de entrada
A5: Presión inicial P1 | B5: 100 | C5: kPa | D5: Admisión al final de la carrera (Loja ≈ 79 kPa) | E5: Ejemplo: Çengel y Boles (2012), ejemplo 9-2 (r = 8; 100 kPa; 17 °C; 800 kJ/kg). Respuestas del libro (calores variables): η = 52,8 %; con cv constante se obtiene 56,5 %.
A6: Temperatura inicial T1 | B6: 290 | C6: K | D6: 17 °C
A7: Relación de compresión r | B7: 8 | C7: – | D7: Gasolina: 8 a 12
A8: Calor suministrado q_entrada | B8: 800 | C8: kJ/kg | D8: Energía de la combustión por kg de aire
A9: Relación de calores k | B9: 1.4 | C9: –
A10: Calor específico cv | B10: 0.718 | C10: kJ/kg·K
A11: Constante del aire R | B11: 0.287 | C11: kJ/kg·K
A13: Estados del ciclo
A14: Estado | B14: P (kPa) | C14: v (m³/kg) | D14: T (K) | E14: s – s1 (kJ/kg·K)
A15: 1 | B15: =B5 -> 100 | C15: =B11*B6/B5 -> 0.8323 | D15: =B6 -> 290 | E15: =0 -> 0
A16: 2 | B16: =B5*B7^B9 -> 1837.9174 | C16: =C15/B7 -> 0.1040375 | D16: =B6*B7^(B9-1) -> 666.24505 | E16: =0 -> 0
A17: 3 | B17: =B16*D17/D16 -> 4911.5894 | C17: =C16 -> 0.1040375 | D17: =D16+B8/B10 -> 1780.4512 | E17: =B10*LN(D17/D16) -> 0.70576854
A18: 4 | B18: =B17/B7^B9 -> 267.23668 | C18: =C15 -> 0.8323 | D18: =D17/B7^(B9-1) -> 774.98639 | E18: =E17 -> 0.70576854
A20: Resultados
A21: Calor rechazado q_salida | B21: =B10*(D18-D15) -> 348.22023 | C21: kJ/kg
A22: Trabajo neto w_neto | B22: =B8-B21 -> 451.77977 | C22: kJ/kg
A23: Rendimiento térmico η (balance) | B23: =B22/B8 -> 0.56472472 | C23: –
A24: Rendimiento térmico η = 1 – 1/r^(k–1) | B24: =1-1/B7^(B9-1) -> 0.56472472 | C24: –
A25: Presión máxima P3 | B25: =B17/100 -> 49.115894 | C25: bar
A26: Presión media efectiva PME | B26: =B22/(C15-C16) -> 620.35293 | C26: kPa
A27: Temperatura máxima T3 | B27: =D17-273.15 -> 1507.3012 | C27: °C
A30: Puntos para los diagramas (no modificar)
A31: Tramo | B31: v (m³/kg) | C31: P (kPa) | D31: T (K) | E31: s – s1
A32: 1→2 | B32: =$C$15-($C$15-$C$16)*0/30 -> 0.8323 | C32: =$B$15*($C$15/B32)^B9 -> 100 | D32: =C32*B32/B11 -> 290 | E32: =0 -> 0
A33: 1→2 | B33: =$C$15-($C$15-$C$16)*1/30 -> 0.80802458 | C33: =$B$15*($C$15/B33)^B9 -> 104.23113 | D33: =C33*B33/B11 -> 293.45406 | E33: =0 -> 0
A34: 1→2 | B34: =$C$15-($C$15-$C$16)*2/30 -> 0.78374917 | C34: =$B$15*($C$15/B34)^B9 -> 108.77871 | D34: =C34*B34/B11 -> 297.05654 | E34: =0 -> 0
A35: 1→2 | B35: =$C$15-($C$15-$C$16)*3/30 -> 0.75947375 | C35: =$B$15*($C$15/B35)^B9 -> 113.67736 | D35: =C35*B35/B11 -> 300.81871 | E35: =0 -> 0
A36: 1→2 | B36: =$C$15-($C$15-$C$16)*4/30 -> 0.73519833 | C36: =$B$15*($C$15/B36)^B9 -> 118.96673 | D36: =C36*B36/B11 -> 304.75311 | E36: =0 -> 0
A37: 1→2 | B37: =$C$15-($C$15-$C$16)*5/30 -> 0.71092292 | C37: =$B$15*($C$15/B37)^B9 -> 124.6925 | D37: =C37*B37/B11 -> 308.87371 | E37: =0 -> 0
A38: 1→2 | B38: =$C$15-($C$15-$C$16)*6/30 -> 0.6866475 | C38: =$B$15*($C$15/B38)^B9 -> 130.90748 | D38: =C38*B38/B11 -> 313.19615 | E38: =0 -> 0
A39: 1→2 | B39: =$C$15-($C$15-$C$16)*7/30 -> 0.66237208 | C39: =$B$15*($C$15/B39)^B9 -> 137.67308 | D39: =C39*B39/B11 -> 317.73799 | E39: =0 -> 0
A40: 1→2 | B40: =$C$15-($C$15-$C$16)*8/30 -> 0.63809667 | C40: =$B$15*($C$15/B40)^B9 -> 145.06104 | D40: =C40*B40/B11 -> 322.51905 | E40: =0 -> 0
A41: 1→2 | B41: =$C$15-($C$15-$C$16)*9/30 -> 0.61382125 | C41: =$B$15*($C$15/B41)^B9 -> 153.1557 | D41: =C41*B41/B11 -> 327.56175 | E41: =0 -> 0
A42: 1→2 | B42: =$C$15-($C$15-$C$16)*10/30 -> 0.58954583 | C42: =$B$15*($C$15/B42)^B9 -> 162.0568 | D42: =C42*B42/B11 -> 332.89167 | E42: =0 -> 0
A43: 1→2 | B43: =$C$15-($C$15-$C$16)*11/30 -> 0.56527042 | C43: =$B$15*($C$15/B43)^B9 -> 171.88307 | D43: =C43*B43/B11 -> 338.53802 | E43: =0 -> 0
A44: 1→2 | B44: =$C$15-($C$15-$C$16)*12/30 -> 0.540995 | C44: =$B$15*($C$15/B44)^B9 -> 182.7769 | D44: =C44*B44/B11 -> 344.53445 | E44: =0 -> 0
A45: 1→2 | B45: =$C$15-($C$15-$C$16)*13/30 -> 0.51671958 | C45: =$B$15*($C$15/B45)^B9 -> 194.91038 | D45: =C45*B45/B11 -> 350.91989 | E45: =0 -> 0
...

Sheet Ciclo_Diesel
A1: Ciclo Diesel ideal de aire estándar
A2: Unidad 2 · 2.5. Procesos: 1→2 compresión isentrópica · 2→3 aporte de calor a P = cte · 3→4 expansión isentrópica · 4→1 rechazo de calor a v = cte
A4: Datos de entrada
A5: Presión inicial P1 | B5: 95 | C5: kPa | D5: Loja ≈ 79 kPa
A6: Temperatura inicial T1 | B6: 300 | C6: K
A7: Relación de compresión r | B7: 18 | C7: – | D7: Diésel: 15 a 24
A8: Relación de corte rc = v3/v2 | B8: 2 | C8: – | D8: Duración de la inyección
A9: Relación de calores k | B9: 1.4 | C9: –
A10: Calor específico cv | B10: 0.718 | C10: kJ/kg·K
A11: Calor específico cp | B11: 1.005 | C11: kJ/kg·K
A12: Constante del aire R | B12: 0.287 | C12: kJ/kg·K
A14: Estados del ciclo
A15: Estado | B15: P (kPa) | C15: v (m³/kg) | D15: T (K) | E15: s – s1 (kJ/kg·K)
A16: 1 | B16: =B5 -> 95 | C16: =B12*B6/B5 -> 0.90631579 | D16: =B6 -> 300 | E16: =0 -> 0
A17: 2 | B17: =B5*B7^B9 -> 5433.8183 | C17: =C16/B7 -> 0.050350877 | D17: =B6*B7^(B9-1) -> 953.30146 | E17: =0 -> 0
A18: 3 | B18: =B17 -> 5433.8183 | C18: =C17*B8 -> 0.10070175 | D18: =D17*B8 -> 1906.6029 | E18: =B11*LN(D18/D17) -> 0.69661292
A19: 4 | B19: =B18*(C18/C16)^B9 -> 250.7065 | C19: =C16 -> 0.90631579 | D19: =D18*(C18/C16)^(B9-1) -> 791.70475 | E19: =E18 -> 0.69661292
A21: Resultados
A22: Calor suministrado q_entrada | B22: =B11*(D18-D17) -> 958.06796 | C22: kJ/kg
A23: Calor rechazado q_salida | B23: =B10*(D19-D16) -> 353.04401 | C23: kJ/kg
A24: Trabajo neto w_neto | B24: =B22-B23 -> 605.02396 | C24: kJ/kg
A25: Rendimiento térmico η (balance) | B25: =B24/B22 -> 0.63150421 | C25: –
A26: η = 1 – (rc^k – 1)/(k·(rc – 1)·r^(k–1)) | B26: =1-(B8^B9-1)/(B9*(B8-1)*B7^(B9-1)) -> 0.63157753 | C26: –
A27: Rendimiento Otto con la misma r | B27: =1-1/B7^(B9-1) -> 0.68530416 | C27: –
A28: Presión máxima P2 = P3 | B28: =B17/100 -> 54.338183 | C28: bar
A29: Presión media efectiva PME | B29: =B24/(C16-C17) -> 706.83266 | C29: kPa
A31: A igual relación de compresión el Otto es más eficiente; el Diesel lo supera porque trabaja con r mucho mayores.
A33: Puntos para los diagramas (no modificar)
A34: Tramo | B34: v (m³/kg) | C34: P (kPa) | D34: T (K) | E34: s – s1
A35: 1→2 | B35: =$C$16-($C$16-$C$17)*0/30 -> 0.90631579 | C35: =$B$16*($C$16/B35)^B9 -> 95 | D35: =C35*B35/B12 -> 300 | E35: =0 -> 0
A36: 1→2 | B36: =$C$16-($C$16-$C$17)*1/30 -> 0.87778363 | C36: =$B$16*($C$16/B36)^B9 -> 99.35106 | D36: =C36*B36/B12 -> 303.86318 | E36: =0 -> 0
A37: 1→2 | B37: =$C$16-($C$16-$C$17)*2/30 -> 0.84925146 | C37: =$B$16*($C$16/B37)^B9 -> 104.05529 | D37: =C37*B37/B12 -> 307.90628 | E37: =0 -> 0
A38: 1→2 | B38: =$C$16-($C$16-$C$17)*3/30 -> 0.8207193 | C38: =$B$16*($C$16/B38)^B9 -> 109.15471 | D38: =C38*B38/B12 -> 312.14416 | E38: =0 -> 0
A39: 1→2 | B39: =$C$16-($C$16-$C$17)*4/30 -> 0.79218713 | C39: =$B$16*($C$16/B39)^B9 -> 114.69806 | D39: =C39*B39/B12 -> 316.59347 | E39: =0 -> 0
A40: 1→2 | B40: =$C$16-($C$16-$C$17)*5/30 -> 0.76365497 | C40: =$B$16*($C$16/B40)^B9 -> 120.74215 | D40: =C40*B40/B12 -> 321.27298 | E40: =0 -> 0
A41: 1→2 | B41: =$C$16-($C$16-$C$17)*6/30 -> 0.73512281 | C41: =$B$16*($C$16/B41)^B9 -> 127.35357 | D41: =C41*B41/B12 -> 326.20387 | E41: =0 -> 0
A42: 1→2 | B42: =$C$16-($C$16-$C$17)*7/30 -> 0.70659064 | C42: =$B$16*($C$16/B42)^B9 -> 134.61081 | D42: =C42*B42/B12 -> 331.41024 | E42: =0 -> 0
A43: 1→2 | B43: =$C$16-($C$16-$C$17)*8/30 -> 0.67805848 | C43: =$B$16*($C$16/B43)^B9 -> 142.60704 | D43: =C43*B43/B12 -> 336.91955 | E43: =0 -> 0
A44: 1→2 | B44: =$C$16-($C$16-$C$17)*9/30 -> 0.64952632 | C44: =$B$16*($C$16/B44)^B9 -> 151.45357 | D44: =C44*B44/B12 -> 342.76335 | E44: =0 -> 0
A45: 1→2 | B45: =$C$16-($C$16-$C$17)*10/30 -> 0.62099415 | C45: =$B$16*($C$16/B45)^B9 -> 161.28443 | D45: =C45*B45/B12 -> 348.97802 | E45: =0 -> 0
...

Sheet Rendimiento_r
A1: Rendimiento teórico frente a la relación de compresión
A2: Unidad 2 · 2.4.2 y 2.6.3. η_Otto = 1 – 1/r^(k–1) · η_Diesel = 1 – (rc^k – 1)/(k·(rc – 1)·r^(k–1))
A4: Relación de calores k | B4: 1.4 | C4: –
A5: Relación de corte rc (curva 1) | B5: 2 | C5: –
A6: Relación de corte rc (curva 2) | B6: 3 | C6: –
A8: r | B8: η Otto | C8: η Diesel rc1 | D8: η Diesel rc2
A9: 2 | B9: =1-1/A9^(B4-1) -> 0.24214172 | C9: =1-(B5^B4-1)/(B4*(B5-1)*A9^(B4-1)) -> 0.11275592 | D9: =1-(B6^B4-1)/(B4*(B6-1)*A9^(B4-1)) -> 0.010579006
A10: 3 | B10: =1-1/A10^(B4-1) -> 0.35560599 | C10: =1-(B5^B4-1)/(B4*(B5-1)*A10^(B4-1)) -> 0.24559144 | D10: =1-(B6^B4-1)/(B4*(B6-1)*A10^(B4-1)) -> 0.15871215
A11: 4 | B11: =1-1/A11^(B4-1) -> 0.42565082 | C11: =1-(B5^B4-1)/(B4*(B5-1)*A11^(B4-1)) -> 0.32759472 | D11: =1-(B6^B4-1)/(B4*(B6-1)*A11^(B4-1)) -> 0.2501591
A12: 5 | B12: =1-1/A12^(B4-1) -> 0.47469444 | C12: =1-(B5^B4-1)/(B4*(B5-1)*A12^(B4-1)) -> 0.38501134 | D12: =1-(B6^B4-1)/(B4*(B6-1)*A12^(B4-1)) -> 0.31418794
A13: 6 | B13: =1-1/A13^(B4-1) -> 0.51164066 | C13: =1-(B5^B4-1)/(B4*(B5-1)*A13^(B4-1)) -> 0.42826522 | D13: =1-(B6^B4-1)/(B4*(B6-1)*A13^(B4-1)) -> 0.36242303
A14: 7 | B14: =1-1/A14^(B4-1) -> 0.54084345 | C14: =1-(B5^B4-1)/(B4*(B5-1)*A14^(B4-1)) -> 0.46245368 | D14: =1-(B6^B4-1)/(B4*(B6-1)*A14^(B4-1)) -> 0.4005487
A15: 8 | B15: =1-1/A15^(B4-1) -> 0.56472472 | C15: =1-(B5^B4-1)/(B4*(B5-1)*A15^(B4-1)) -> 0.49041209 | D15: =1-(B6^B4-1)/(B4*(B6-1)*A15^(B4-1)) -> 0.43172687
A16: 9 | B16: =1-1/A16^(B4-1) -> 0.58475635 | C16: =1-(B5^B4-1)/(B4*(B5-1)*A16^(B4-1)) -> 0.51386364 | D16: =1-(B6^B4-1)/(B4*(B6-1)*A16^(B4-1)) -> 0.45787914
A17: 10 | B17: =1-1/A17^(B4-1) -> 0.60189283 | C17: =1-(B5^B4-1)/(B4*(B5-1)*A17^(B4-1)) -> 0.53392575 | D17: =1-(B6^B4-1)/(B4*(B6-1)*A17^(B4-1)) -> 0.48025165
A18: 11 | B18: =1-1/A18^(B4-1) -> 0.61678462 | C18: =1-(B5^B4-1)/(B4*(B5-1)*A18^(B4-1)) -> 0.55135995 | D18: =1-(B6^B4-1)/(B4*(B6-1)*A18^(B4-1)) -> 0.49969361
A19: 12 | B19: =1-1/A19^(B4-1) -> 0.62989283 | C19: =1-(B5^B4-1)/(B4*(B5-1)*A19^(B4-1)) -> 0.56670606 | D19: =1-(B6^B4-1)/(B4*(B6-1)*A19^(B4-1)) -> 0.51680701
A20: 13 | B20: =1-1/A20^(B4-1) -> 0.64155489 | C20: =1-(B5^B4-1)/(B4*(B5-1)*A20^(B4-1)) -> 0.58035914 | D20: =1-(B6^B4-1)/(B4*(B6-1)*A20^(B4-1)) -> 0.53203241
A21: 14 | B21: =1-1/A21^(B4-1) -> 0.65202441 | C21: =1-(B5^B4-1)/(B4*(B5-1)*A21^(B4-1)) -> 0.59261607 | D21: =1-(B6^B4-1)/(B4*(B6-1)*A21^(B4-1)) -> 0.54570087
A22: 15 | B22: =1-1/A22^(B4-1) -> 0.66149624 | C22: =1-(B5^B4-1)/(B4*(B5-1)*A22^(B4-1)) -> 0.60370499 | D22: =1-(B6^B4-1)/(B4*(B6-1)*A22^(B4-1)) -> 0.55806681
A23: 16 | B23: =1-1/A23^(B4-1) -> 0.67012302 | C23: =1-(B5^B4-1)/(B4*(B5-1)*A23^(B4-1)) -> 0.61380458 | D23: =1-(B6^B4-1)/(B4*(B6-1)*A23^(B4-1)) -> 0.5693295
A24: 17 | B24: =1-1/A24^(B4-1) -> 0.67802628 | C24: =1-(B5^B4-1)/(B4*(B5-1)*A24^(B4-1)) -> 0.62305712 | D24: =1-(B6^B4-1)/(B4*(B6-1)*A24^(B4-1)) -> 0.57964758
A25: 18 | B25: =1-1/A25^(B4-1) -> 0.68530416 | C25: =1-(B5^B4-1)/(B4*(B5-1)*A25^(B4-1)) -> 0.63157753 | D25: =1-(B6^B4-1)/(B4*(B6-1)*A25^(B4-1)) -> 0.58914922
A26: 19 | B26: =1-1/A26^(B4-1) -> 0.69203699 | C26: =1-(B5^B4-1)/(B4*(B5-1)*A26^(B4-1)) -> 0.63945982 | D26: =1-(B6^B4-1)/(B4*(B6-1)*A26^(B4-1)) -> 0.59793925 | F26: Zona habitual: gasolina r = 8–12; diésel r = 15–22.
A27: 20 | B27: =1-1/A27^(B4-1) -> 0.69829118 | C27: =1-(B5^B4-1)/(B4*(B5-1)*A27^(B4-1)) -> 0.64678177 | D27: =1-(B6^B4-1)/(B4*(B6-1)*A27^(B4-1)) -> 0.60610441
A28: 21 | B28: =1-1/A28^(B4-1) -> 0.70412227 | C28: =1-(B5^B4-1)/(B4*(B5-1)*A28^(B4-1)) -> 0.65360837 | D28: =1-(B6^B4-1)/(B4*(B6-1)*A28^(B4-1)) -> 0.61371717
A29: 22 | B29: =1-1/A29^(B4-1) -> 0.70957705 | C29: =1-(B5^B4-1)/(B4*(B5-1)*A29^(B4-1)) -> 0.65999443 | D29: =1-(B6^B4-1)/(B4*(B6-1)*A29^(B4-1)) -> 0.62083866
A30: 23 | B30: =1-1/A30^(B4-1) -> 0.71469534 | C30: =1-(B5^B4-1)/(B4*(B5-1)*A30^(B4-1)) -> 0.66598653 | D30: =1-(B6^B4-1)/(B4*(B6-1)*A30^(B4-1)) -> 0.62752083
A31: 24 | B31: =1-1/A31^(B4-1) -> 0.71951121 | C31: =1-(B5^B4-1)/(B4*(B5-1)*A31^(B4-1)) -> 0.6716246 | D31: =1-(B6^B4-1)/(B4*(B6-1)*A31^(B4-1)) -> 0.63380819

Sheet Geometria
A1: Geometría y parámetros del motor
A2: Unidad 4 · 4.1 y 4.2. Notación de la guía: D, L, N, Vu, Vt, Vcc, Rc; junta: Vj, Rcj
A4: Datos de entrada
A5: Diámetro (alesaje) D | B5: 84 | C5: mm | D5: Ej.: Nissan, hoja «Parámetros de motores»
A6: Carrera L | B6: 81 | C6: mm
A7: Número de cilindros N | B7: 4 | C7: –
A8: Relación de compresión del fabricante Rc | B8: 9.9 | C8: –
A9: Espesor de la junta de culata e | B9: 1.5 | C9: mm
A10: Relación de compresión deseada (aplanado) | B10: 10.5 | C10: –
A11: Régimen n | B11: 6000 | C11: rpm
A13: Resultados
A14: Superficie del pistón Sp = πD²/4 | B14: =PI()*(B5/10)^2/4 -> 55.417694 | C14: cm²
A15: Cilindrada unitaria Vu = Sp·L | B15: =B14*B6/10 -> 448.88332 | C15: cm³
A16: Cilindrada total Vt = Vu·N | B16: =B15*B7 -> 1795.5333 | C16: cm³
A17: Volumen de la cámara Vcc = Vu/(Rc – 1) | B17: =B15/(B8-1) -> 50.436329 | C17: cm³
A18: Volumen de la junta Vj = Sp·e | B18: =B14*B9/10 -> 8.3126542 | C18: cm³
A19: Rc con junta Rcj = (Vu+Vcc+Vj)/(Vcc+Vj) | B19: =(B15+B17+B18)/(B17+B18) -> 8.6406995 | C19: –
A20: Relación carrera–diámetro L/D | B20: =B6/B5 -> 0.96428571 | C20: –
A21: Tipo de motor | B21: =IF(ABS(B20-1)<0.02,"Cuadrado",IF(B20<1,"Supercuadrado (carrera corta)","Carrera larga")) -> Supercuadrado (carrera corta)
A22: Rebaje de culata X = L/(Rc–1) – L/(Rc,n–1) | B22: =B6/(B8-1)-B6/(B10-1) -> 0.57480781 | C22: mm
A23: Velocidad media del pistón vm = L·n/30 | B23: =B6/1000*B11/30 -> 16.2 | C23: m/s
A25: Comprobación: con los datos de ejemplo Vu = 448,9 cm³, Vt = 1 795,5 cm³, Vcc = 50,44 cm³, Vj = 8,31 cm³ y Rcj = 8,64.
A27: Efecto del espesor de la junta en la relación de compresión
A28: Espesor e (mm) | B28: Vj (cm³) | C28: Rcj
A29: 0.5 | B29: =$B$14*A29/10 -> 2.7708847 | C29: =($B$15+$B$17+B29)/($B$17+B29) -> 9.4365126
A30: 0.75 | B30: =$B$14*A30/10 -> 4.1563271 | C30: =($B$15+$B$17+B30)/($B$17+B30) -> 9.2224123
A31: 1 | B31: =$B$14*A31/10 -> 5.5417694 | C31: =($B$15+$B$17+B31)/($B$17+B31) -> 9.0189099
A32: 1.25 | B32: =$B$14*A32/10 -> 6.9272118 | C32: =($B$15+$B$17+B32)/($B$17+B32) -> 8.8252374
A33: 1.5 | B33: =$B$14*A33/10 -> 8.3126542 | C33: =($B$15+$B$17+B33)/($B$17+B33) -> 8.6406995
A34: 1.75 | B34: =$B$14*A34/10 -> 9.6980965 | C34: =($B$15+$B$17+B34)/($B$17+B34) -> 8.4646648
A35: 2 | B35: =$B$14*A35/10 -> 11.083539 | C35: =($B$15+$B$17+B35)/($B$17+B35) -> 8.2965587
A36: 2.25 | B36: =$B$14*A36/10 -> 12.468981 | C36: =($B$15+$B$17+B36)/($B$17+B36) -> 8.1358575
A37: 2.5 | B37: =$B$14*A37/10 -> 13.854424 | C37: =($B$15+$B$17+B37)/($B$17+B37) -> 7.9820823
A38: 2.75 | B38: =$B$14*A38/10 -> 15.239866 | C38: =($B$15+$B$17+B38)/($B$17+B38) -> 7.834795
A39: 3 | B39: =$B$14*A39/10 -> 16.625308 | C39: =($B$15+$B$17+B39)/($B$17+B39) -> 7.6935933
A42: Volumen del cilindro según la posición del pistón (enlaza con Biela_manivela)
A43: V(θ) = Vcc + Sp·x(θ); el diagrama de la hoja Biela_manivela usa estos datos.

Sheet Curvas
A1: Curvas características del motor
A2: Unidad 4 · 4.3. Introduzca el par medido en el banco; P = M·n/9 550; PME = 4π·M/Vt (4T); ge = consumo horario / P
A4: Cilindrada total Vt | B4: 1.6 | C4: L
A5: Poder calorífico del combustible | B5: 44 | C5: MJ/kg | D5: Gasolina ≈ 44; diésel ≈ 42,5
A7: n (rpm) | B7: Par M (N·m) | C7: Consumo (kg/h) | D7: Potencia P (kW) | E7: Potencia (CV) | F7: PME (bar) | G7: ge (g/kWh) | H7: η efectivo
A8: 1000 | B8: 170 | C8: 5.6 | D8: =B8*A8/9550 -> 17.801047 | E8: =D8*1.36 -> 24.209424 | F8: =4*PI()*B8/(B4/1000)/100000 -> 13.351769 | G8: =IF(C8>0,C8*1000/D8,"") -> 314.58824 | H8: =IF(C8>0,3600/(G8*B5),"") -> 0.26008023
A9: 1500 | B9: 182 | C9: 8.4 | D9: =B9*A9/9550 -> 28.586387 | E9: =D9*1.36 -> 38.877487 | F9: =4*PI()*B9/(B4/1000)/100000 -> 14.294247 | G9: =IF(C9>0,C9*1000/D9,"") -> 293.84615 | H9: =IF(C9>0,3600/(G9*B5),"") -> 0.27843884
A10: 2000 | B10: 195 | C10: 11.2 | D10: =B10*A10/9550 -> 40.837696 | E10: =D10*1.36 -> 55.539267 | F10: =4*PI()*B10/(B4/1000)/100000 -> 15.315264 | G10: =IF(C10>0,C10*1000/D10,"") -> 274.25641 | H10: =IF(C10>0,3600/(G10*B5),"") -> 0.29832733
A11: 2500 | B11: 205 | C11: 14.2 | D11: =B11*A11/9550 -> 53.664921 | E11: =D11*1.36 -> 72.984293 | F11: =4*PI()*B11/(B4/1000)/100000 -> 16.100662 | G11: =IF(C11>0,C11*1000/D11,"") -> 264.60488 | H11: =IF(C11>0,3600/(G11*B5),"") -> 0.30920889
A12: 3000 | B12: 211 | C12: 17.3 | D12: =B12*A12/9550 -> 66.282723 | E12: =D12*1.36 -> 90.144503 | F12: =4*PI()*B12/(B4/1000)/100000 -> 16.571901 | G12: =IF(C12>0,C12*1000/D12,"") -> 261.00316 | H12: =IF(C12>0,3600/(G12*B5),"") -> 0.31347583
A13: 3500 | B13: 216 | C13: 20.6 | D13: =B13*A13/9550 -> 79.162304 | E13: =D13*1.36 -> 107.66073 | F13: =4*PI()*B13/(B4/1000)/100000 -> 16.9646 | G13: =IF(C13>0,C13*1000/D13,"") -> 260.22487 | H13: =IF(C13>0,3600/(G13*B5),"") -> 0.31441339
A14: 4000 | B14: 219 | C14: 23.9 | D14: =B14*A14/9550 -> 91.727749 | E14: =D14*1.36 -> 124.74974 | F14: =4*PI()*B14/(B4/1000)/100000 -> 17.20022 | G14: =IF(C14>0,C14*1000/D14,"") -> 260.55365 | H14: =IF(C14>0,3600/(G14*B5),"") -> 0.31401664
A15: 4200 | B15: 220 | C15: 25.2 | D15: =B15*A15/9550 -> 96.753927 | E15: =D15*1.36 -> 131.58534 | F15: =4*PI()*B15/(B4/1000)/100000 -> 17.27876 | G15: =IF(C15>0,C15*1000/D15,"") -> 260.45455 | H15: =IF(C15>0,3600/(G15*B5),"") -> 0.31413613
A16: 4500 | B16: 218 | C16: 27.4 | D16: =B16*A16/9550 -> 102.72251 | E16: =D16*1.36 -> 139.70262 | F16: =4*PI()*B16/(B4/1000)/100000 -> 17.12168 | G16: =IF(C16>0,C16*1000/D16,"") -> 266.73802 | H16: =IF(C16>0,3600/(G16*B5),"") -> 0.3067361
A17: 5000 | B17: 210 | C17: 30.8 | D17: =B17*A17/9550 -> 109.94764 | E17: =D17*1.36 -> 149.5288 | F17: =4*PI()*B17/(B4/1000)/100000 -> 16.493361 | G17: =IF(C17>0,C17*1000/D17,"") -> 280.13333 | H17: =IF(C17>0,3600/(G17*B5),"") -> 0.29206871
A18: 5500 | B18: 192 | C18: 32.8 | D18: =B18*A18/9550 -> 110.57592 | E18: =D18*1.36 -> 150.38325 | F18: =4*PI()*B18/(B4/1000)/100000 -> 15.079645 | G18: =IF(C18>0,C18*1000/D18,"") -> 296.62879 | H18: =IF(C18>0,3600/(G18*B5),"") -> 0.27582684
A19: 6000 | B19: 170 | C19: 32.1 | D19: =B19*A19/9550 -> 106.80628 | E19: =D19*1.36 -> 145.25654 | F19: =4*PI()*B19/(B4/1000)/100000 -> 13.351769 | G19: =IF(C19>0,C19*1000/D19,"") -> 300.54412 | H19: =IF(C19>0,3600/(G19*B5),"") -> 0.27223352
A20: Datos de par: ejemplo de clase (motor de gasolina 1,6 L). Consumo horario: valores ilustrativos para practicar; sustitúyalos por los medidos en el banco.
A22: Puntos característicos y elasticidad
A23: Par máximo Mmáx | B23: =MAX(B8:B19) -> 220 | C23: N·m
A24: Régimen de par máximo nM | B24: =INDEX(A8:A19,MATCH(B23,B8:B19,0)) -> 4200 | C24: rpm
A25: Potencia máxima Pmáx | B25: =MAX(D8:D19) -> 110.57592 | C25: kW
A26: Régimen de potencia máxima nP | B26: =INDEX(A8:A19,MATCH(B25,D8:D19,0)) -> 5500 | C26: rpm
A27: Par a potencia máxima MP | B27: =INDEX(B8:B19,MATCH(B25,D8:D19,0)) -> 192 | C27: N·m
A28: Elasticidad de par Ep = Mmáx/MP | B28: =B23/B27 -> 1.1458333 | C28: –
A29: Elasticidad de régimen En = nP/nM | B29: =B26/B24 -> 1.3095238 | C29: –
A30: Elasticidad total E = Ep·En | B30: =B28*B29 -> 1.500496 | C30: –
A31: Consumo específico mínimo | B31: =MIN(G8:G19) -> 260.22487 | C31: g/kWh

Sheet Biela_manivela
A1: Cinemática del mecanismo biela–manivela
A2: Unidad 4 · 4.4. x = r[(1 – cos θ) + (1/λ)(1 – √(1 – λ² sin²θ))]; v ≈ rω(sin θ + λ/2·sin 2θ); a ≈ rω²(cos θ + λ cos 2θ)
A4: Carrera L | B4: 81 | C4: mm
A5: Longitud de la biela l | B5: 135 | C5: mm | D5: Entre centros
A6: Régimen n | B6: 6000 | C6: rpm
A8: Radio de la manivela r = L/2 | B8: =B4/2 -> 40.5 | C8: mm
A9: Relación λ = r/l | B9: =B8/B5 -> 0.3 | C9: –
A10: Velocidad angular ω | B10: =2*PI()*B6/60 -> 628.31853 | C10: rad/s
A11: Velocidad media del pistón vm | B11: =B4/1000*B6/30 -> 16.2 | C11: m/s
A12: Velocidad máxima del pistón | B12: =MAX(D17:D89) -> 26.488336 | C12: m/s
A13: Posición a 90° (más de L/2 por la oblicuidad) | B13: =INDEX(C17:C89,MATCH(90,A17:A89,0)) -> 46.718208 | C13: mm
A16: θ (°) | B16: θ (rad) | C16: x (mm) | D16: v (m/s) | E16: a (m/s²) | F16: x armónico (mm) | G16: V cilindro (cm³)
A17: 0 | B17: =RADIANS(A17) -> 0 | C17: =$B$8*((1-COS(B17))+(1/$B$9)*(1-SQRT(1-$B$9^2*SIN(B17)^2))) -> 0 | D17: =$B$8/1000*$B$10*(SIN(B17)+$B$9/2*SIN(2*B17)) -> 0 | E17: =$B$8/1000*$B$10^2*(COS(B17)+$B$9*COS(2*B17)) -> 20785.387 | F17: =$B$8*(1-COS(B17)) -> 0 | G17: =Geometria!$B$17+Geometria!$B$14*C17/10 -> 50.436329
A18: 5 | B18: =RADIANS(A18) -> 0.087266463 | C18: =$B$8*((1-COS(B18))+(1/$B$9)*(1-SQRT(1-$B$9^2*SIN(B18)^2))) -> 0.20026907 | D18: =$B$8/1000*$B$10*(SIN(B18)+$B$9/2*SIN(2*B18)) -> 2.8806647 | E18: =$B$8/1000*$B$10^2*(COS(B18)+$B$9*COS(2*B18)) -> 20651.673 | F18: =$B$8*(1-COS(B18)) -> 0.15411473 | G18: =Geometria!$B$17+Geometria!$B$14*C18/10 -> 51.546174
A19: 10 | B19: =RADIANS(A19) -> 0.17453293 | C19: =$B$8*((1-COS(B19))+(1/$B$9)*(1-SQRT(1-$B$9^2*SIN(B19)^2))) -> 0.79859412 | D19: =$B$8/1000*$B$10*(SIN(B19)+$B$9/2*SIN(2*B19)) -> 5.7243108 | E19: =$B$8/1000*$B$10^2*(COS(B19)+$B$9*COS(2*B19)) -> 20253.21 | F19: =$B$8*(1-COS(B19)) -> 0.615286 | G19: =Geometria!$B$17+Geometria!$B$14*C19/10 -> 54.861953
A20: 15 | B20: =RADIANS(A20) -> 0.26179939 | C20: =$B$8*((1-COS(B20))+(1/$B$9)*(1-SQRT(1-$B$9^2*SIN(B20)^2))) -> 1.7875671 | D20: =$B$8/1000*$B$10*(SIN(B20)+$B$9/2*SIN(2*B20)) -> 8.49466 | E20: =$B$8/1000*$B$10^2*(COS(B20)+$B$9*COS(2*B20)) -> 19597.957 | F20: =$B$8*(1-COS(B20)) -> 1.380004 | G20: =Geometria!$B$17+Geometria!$B$14*C20/10 -> 60.342613
A21: 20 | B21: =RADIANS(A21) -> 0.34906585 | C21: =$B$8*((1-COS(B21))+(1/$B$9)*(1-SQRT(1-$B$9^2*SIN(B21)^2))) -> 3.1549692 | D21: =$B$8/1000*$B$10*(SIN(B21)+$B$9/2*SIN(2*B21)) -> 11.156895 | E21: =$B$8/1000*$B$10^2*(COS(B21)+$B$9*COS(2*B21)) -> 18698.949 | F21: =$B$8*(1-COS(B21)) -> 2.4424489 | G21: =Geometria!$B$17+Geometria!$B$14*C21/10 -> 67.92044
A22: 25 | B22: =RADIANS(A22) -> 0.43633231 | C22: =$B$8*((1-COS(B22))+(1/$B$9)*(1-SQRT(1-$B$9^2*SIN(B22)^2))) -> 4.883963 | D22: =$B$8/1000*$B$10*(SIN(B22)+$B$9/2*SIN(2*B22)) -> 13.678343 | E22: =$B$8/1000*$B$10^2*(COS(B22)+$B$9*COS(2*B22)) -> 17573.95 | F22: =$B$8*(1-COS(B22)) -> 3.7945346 | G22: =Geometria!$B$17+Geometria!$B$14*C22/10 -> 77.502126
A23: 30 | B23: =RADIANS(A23) -> 0.52359878 | C23: =$B$8*((1-COS(B23))+(1/$B$9)*(1-SQRT(1-$B$9^2*SIN(B23)^2))) -> 6.9533616 | D23: =$B$8/1000*$B$10*(SIN(B23)+$B$9/2*SIN(2*B23)) -> 16.0291 | E23: =$B$8/1000*$B$10^2*(COS(B23)+$B$9*COS(2*B23)) -> 16244.985 | F23: =$B$8*(1-COS(B23)) -> 5.4259711 | G23: =Geometria!$B$17+Geometria!$B$14*C23/10 -> 88.970255
A24: 35 | B24: =RADIANS(A24) -> 0.61086524 | C24: =$B$8*((1-COS(B24))+(1/$B$9)*(1-SQRT(1-$B$9^2*SIN(B24)^2))) -> 9.3379735 | D24: =$B$8/1000*$B$10*(SIN(B24)+$B$9/2*SIN(2*B24)) -> 18.182582 | E24: =$B$8/1000*$B$10^2*(COS(B24)+$B$9*COS(2*B24)) -> 14737.768 | F24: =$B$8*(1-COS(B24)) -> 7.3243422 | G24: =Geometria!$B$17+Geometria!$B$14*C24/10 -> 102.18522
A25: 40 | B25: =RADIANS(A25) -> 0.6981317 | C25: =$B$8*((1-COS(B25))+(1/$B$9)*(1-SQRT(1-$B$9^2*SIN(B25)^2))) -> 12.009022 | D25: =$B$8/1000*$B$10*(SIN(B25)+$B$9/2*SIN(2*B25)) -> 20.115998 | E25: =$B$8/1000*$B$10^2*(COS(B25)+$B$9*COS(2*B25)) -> 13081.026 | F25: =$B$8*(1-COS(B25)) -> 9.4752001 | G25: =Geometria!$B$17+Geometria!$B$14*C25/10 -> 116.98756
A26: 45 | B26: =RADIANS(A26) -> 0.78539816 | C26: =$B$8*((1-COS(B26))+(1/$B$9)*(1-SQRT(1-$B$9^2*SIN(B26)^2))) -> 14.934638 | D26: =$B$8/1000*$B$10*(SIN(B26)+$B$9/2*SIN(2*B26)) -> 21.810711 | E26: =$B$8/1000*$B$10^2*(COS(B26)+$B$9*COS(2*B26)) -> 11305.76 | F26: =$B$8*(1-COS(B26)) -> 11.862175 | G26: =Geometria!$B$17+Geometria!$B$14*C26/10 -> 133.20065
A27: 50 | B27: =RADIANS(A27) -> 0.87266463 | C27: =$B$8*((1-COS(B27))+(1/$B$9)*(1-SQRT(1-$B$9^2*SIN(B27)^2))) -> 18.080414 | D27: =$B$8/1000*$B$10*(SIN(B27)+$B$9/2*SIN(2*B27)) -> 23.252502 | E27: =$B$8/1000*$B$10^2*(COS(B27)+$B$9*COS(2*B27)) -> 9444.4506 | F27: =$B$8*(1-COS(B27)) -> 14.467102 | G27: =Geometria!$B$17+Geometria!$B$14*C27/10 -> 150.63381
A28: 55 | B28: =RADIANS(A28) -> 0.95993109 | C28: =$B$8*((1-COS(B28))+(1/$B$9)*(1-SQRT(1-$B$9^2*SIN(B28)^2))) -> 21.410016 | D28: =$B$8/1000*$B$10*(SIN(B28)+$B$9/2*SIN(2*B28)) -> 24.43172 | E28: =$B$8/1000*$B$10^2*(COS(B28)+$B$9*COS(2*B28)) -> 7530.2322 | F28: =$B$8*(1-COS(B28)) -> 17.270154 | G28: =Geometria!$B$17+Geometria!$B$14*C28/10 -> 169.0857
... A89: 360 | B89: =RADIANS(A89) -> 6.2831853 | C89: =$B$8*((1-COS(B89))+(1/$B$9)*(1-SQRT(1-$B$9^2*SIN(B89)^2))) -> 0 | D89: =$B$8/1000*$B$10*(SIN(B89)+$B$9/2*SIN(2*B89)) -> -8.102501e-15 | E89: =$B$8/1000*$B$10^2*(COS(B89)+$B$9*COS(2*B89)) -> 20785.387 | F89: =$B$8*(1-COS(B89)) -> 0 | G89: =Geometria!$B$17+Geometria!$B$14*C89/10 -> 50.436329
A91: La columna V cilindro usa Sp y Vcc de la hoja Geometria (cámbielos allí).
