Workbook

Sheet Simulador
A1: Simulador · Orden de encendido según el número y la disposición de los cilindros
A2: Sistemas del Funcionamiento del Motor (MA.02.06) · Unidad 1 · Elija la configuración y mueva el ángulo del cigüeñal; edite solo las celdas amarillas.
A4: Datos de entrada | B4: Valor
A5: Configuración del motor | B5: Personalizado (en línea, escriba z y el orden)
A6: Personalizado: número de cilindros z | B6: 4
A7: Personalizado: orden de encendido | B7: 1-4-3-2 | I7: =IF($B$9<>25,"",IF(COUNT(Configuraciones!B30:M30)<>B6,"Revise el orden personalizado: faltan cilindros",IF(SUMPRODUCT((COUNTIF(Configuraciones!B30:M30,ROW(INDIRECT("1:"&B6)))<>1)*1)>0,"Revise el orden: cada cilindro debe aparecer una sola vez",IF(INDEX(Configuraciones!B30:M30,1)<>1,"El orden debe empezar por el cilindro 1","Orden personalizado válido")))) -> Orden personalizado válido
A8: Ángulo del cigüeñal θ (°) | B8: 0
A9: Fila del catálogo | B9: =MATCH(B5,Configuraciones!$A$3:$A$27,0) -> 25
A11: Resultados | B11: Valor
A12: Número de cilindros z | B12: =INDEX(Configuraciones!$B$3:$B$27,$B$9) -> 4
A13: Orden de encendido | B13: =INDEX(Configuraciones!$C$3:$C$27,$B$9) -> 1-4-3-2
A14: Disposición | B14: =INDEX(Configuraciones!$D$3:$D$27,$B$9)&IF(INDEX(Configuraciones!$E$3:$E$27,$B$9)>0," · ángulo entre bancadas "&INDEX(Configuraciones!$E$3:$E$27,$B$9)&"°","") -> En línea
A15: División del ciclo (intervalo teórico) | B15: ="720° / "&B12&" = "&IF(MOD(720/B12,1)=0,TEXT(720/B12,"0"),TEXT(720/B12,"0.00"))&"°" -> 720° / 4 = 180°
A16: Intervalos reales entre encendidos | B16: ='Datos gráficos'!W14&IF(MAX('Datos gráficos'!U3:U14)-MIN('Datos gráficos'!U3:U14)<0.5," · encendidos regulares"," · encendidos IRREGULARES") -> 180°, 180°, 180°, 180° · encendidos regulares
A17: Cilindros en expansión al mismo tiempo | B17: =IF(MIN('Diagrama de fases'!C18:DR18)=MAX('Diagrama de fases'!C18:DR18),MIN('Diagrama de fases'!C18:DR18),MIN('Diagrama de fases'!C18:DR18)&" a "&MAX('Diagrama de fases'!C18:DR18))&IF(MIN('Diagrama de fases'!C18:DR18)=0," · hay tramos sin ningún cilindro en expansión","") -> 1
A18: Cilindro que está encendiendo o en expansión inicial | B18: =IFERROR(INDEX(A22:A33,MATCH(1,INDEX((G22:G33="Expansión")*(I22:I33<720/B12),0),0)),"—") -> 1
A19: =INDEX(Configuraciones!$F$3:$F$27,$B$9) -> Motor en línea definido por el usuario: el intervalo es 720°/z y el orden se toma de la celda B7 del simulador.
A21: Cilindro | B21: Bancada | C21: Eje del cilindro β (°) | D21: Encendido a (° de cigüeñal) | E21: Muñequilla a θ = 0° (°) | F21: Muñequilla a θ (°) | G21: Tiempo en θ | H21: Pistón | I21: φ (°) | S21: Cigüeñal visto de lado, en el plano de la muñequilla 1: la línea gris son los apoyos de bancada y cada codo es el brazo y la muñequilla de un cilindro. Entre paréntesis, el ángulo de cada muñequilla (vista frontal, θ = 0°).
A22: =IF(1>$B$12,"",1) -> 1 | B22: =IF(A22="","",INDEX(Configuraciones!$G$3:$G$27,$B$9)) -> - | C22: =IF(A22="","",INDEX(Configuraciones!$H$3:$H$27,$B$9)) -> 0 | D22: =IF(A22="","",INDEX(Configuraciones!$I$3:$I$27,$B$9)) -> 0 | E22: =IF(OR(A22="",D22=""),"",MOD(ROUND(C22-D22,1),360)) -> 0 | F22: =IF(E22="","",MOD(E22+$B$8,360)) -> 0 | G22: =IF(I22="","",CHOOSE(INT(I22/180)+1,"Expansión","Escape","Admisión","Compresión")) -> Expansión | H22: =IF(I22="","",IF(MOD(I22,360)=0,"PMS",IF(MOD(I22,180)=0,"PMI",IF(MOD(I22,360)<180,"Baja","Sube")))) -> PMS | I22: =IF(D22="","",MOD($B$8-D22,720)) -> 0 | S22: Dibujo en perspectiva oblicua: las muñequillas a 90° de la n.º 1 quedan a media altura (arriba si van adelantadas, abajo si van retrasadas). Compárelo con la vista frontal para reconocer la forma del cigüeñal (plano, cruciforme, a 120°, a 72°…).
A23: =IF(2>$B$12,"",2) -> 2 | B23: =IF(A23="","",INDEX(Configuraciones!$L$3:$L$27,$B$9)) -> - | C23: =IF(A23="","",INDEX(Configuraciones!$M$3:$M$27,$B$9)) -> 0 | D23: =IF(A23="","",INDEX(Configuraciones!$N$3:$N$27,$B$9)) -> 540 | E23: =IF(OR(A23="",D23=""),"",MOD(ROUND(C23-D23,1),360)) -> 180 | F23: =IF(E23="","",MOD(E23+$B$8,360)) -> 180 | G23: =IF(I23="","",CHOOSE(INT(I23/180)+1,"Expansión","Escape","Admisión","Compresión")) -> Escape | H23: =IF(I23="","",IF(MOD(I23,360)=0,"PMS",IF(MOD(I23,180)=0,"PMI",IF(MOD(I23,360)<180,"Baja","Sube")))) -> PMI | I23: =IF(D23="","",MOD($B$8-D23,720)) -> 180
A24: =IF(3>$B$12,"",3) -> 3 | B24: =IF(A24="","",INDEX(Configuraciones!$Q$3:$Q$27,$B$9)) -> - | C24: =IF(A24="","",INDEX(Configuraciones!$R$3:$R$27,$B$9)) -> 0 | D24: =IF(A24="","",INDEX(Configuraciones!$S$3:$S$27,$B$9)) -> 360 | E24: =IF(OR(A24="",D24=""),"",MOD(ROUND(C24-D24,1),360)) -> 0 | F24: =IF(E24="","",MOD(E24+$B$8,360)) -> 0 | G24: =IF(I24="","",CHOOSE(INT(I24/180)+1,"Expansión","Escape","Admisión","Compresión")) -> Admisión | H24: =IF(I24="","",IF(MOD(I24,360)=0,"PMS",IF(MOD(I24,180)=0,"PMI",IF(MOD(I24,360)<180,"Baja","Sube")))) -> PMS | I24: =IF(D24="","",MOD($B$8-D24,720)) -> 360
A25: =IF(4>$B$12,"",4) -> 4 | B25: =IF(A25="","",INDEX(Configuraciones!$V$3:$V$27,$B$9)) -> - | C25: =IF(A25="","",INDEX(Configuraciones!$W$3:$W$27,$B$9)) -> 0 | D25: =IF(A25="","",INDEX(Configuraciones!$X$3:$X$27,$B$9)) -> 180 | E25: =IF(OR(A25="",D25=""),"",MOD(ROUND(C25-D25,1),360)) -> 180 | F25: =IF(E25="","",MOD(E25+$B$8,360)) -> 180 | G25: =IF(I25="","",CHOOSE(INT(I25/180)+1,"Expansión","Escape","Admisión","Compresión")) -> Compresión | H25: =IF(I25="","",IF(MOD(I25,360)=0,"PMS",IF(MOD(I25,180)=0,"PMI",IF(MOD(I25,360)<180,"Baja","Sube")))) -> PMI | I25: =IF(D25="","",MOD($B$8-D25,720)) -> 540
A26: =IF(5>$B$12,"",5) | B26: =IF(A26="","",INDEX(Configuraciones!$AA$3:$AA$27,$B$9)) | C26: =IF(A26="","",INDEX(Configuraciones!$AB$3:$AB$27,$B$9)) | D26: =IF(A26="","",INDEX(Configuraciones!$AC$3:$AC$27,$B$9)) | E26: =IF(OR(A26="",D26=""),"",MOD(ROUND(C26-D26,1),360)) | F26: =IF(E26="","",MOD(E26+$B$8,360)) | G26: =IF(I26="","",CHOOSE(INT(I26/180)+1,"Expansión","Escape","Admisión","Compresión")) | H26: =IF(I26="","",IF(MOD(I26,360)=0,"PMS",IF(MOD(I26,180)=0,"PMI",IF(MOD(I26,360)<180,"Baja","Sube")))) | I26: =IF(D26="","",MOD($B$8-D26,720))
A27: =IF(6>$B$12,"",6) | B27: =IF(A27="","",INDEX(Configuraciones!$AF$3:$AF$27,$B$9)) | C27: =IF(A27="","",INDEX(Configuraciones!$AG$3:$AG$27,$B$9)) | D27: =IF(A27="","",INDEX(Configuraciones!$AH$3:$AH$27,$B$9)) | E27: =IF(OR(A27="",D27=""),"",MOD(ROUND(C27-D27,1),360)) | F27: =IF(E27="","",MOD(E27+$B$8,360)) | G27: =IF(I27="","",CHOOSE(INT(I27/180)+1,"Expansión","Escape","Admisión","Compresión")) | H27: =IF(I27="","",IF(MOD(I27,360)=0,"PMS",IF(MOD(I27,180)=0,"PMI",IF(MOD(I27,360)<180,"Baja","Sube")))) | I27: =IF(D27="","",MOD($B$8-D27,720))
A28: =IF(7>$B$12,"",7) | B28: =IF(A28="","",INDEX(Configuraciones!$AK$3:$AK$27,$B$9)) | C28: =IF(A28="","",INDEX(Configuraciones!$AL$3:$AL$27,$B$9)) | D28: =IF(A28="","",INDEX(Configuraciones!$AM$3:$AM$27,$B$9)) | E28: =IF(OR(A28="",D28=""),"",MOD(ROUND(C28-D28,1),360)) | F28: =IF(E28="","",MOD(E28+$B$8,360)) | G28: =IF(I28="","",CHOOSE(INT(I28/180)+1,"Expansión","Escape","Admisión","Compresión")) | H28: =IF(I28="","",IF(MOD(I28,360)=0,"PMS",IF(MOD(I28,180)=0,"PMI",IF(MOD(I28,360)<180,"Baja","Sube")))) | I28: =IF(D28="","",MOD($B$8-D28,720))
A29: =IF(8>$B$12,"",8) | B29: =IF(A29="","",INDEX(Configuraciones!$AP$3:$AP$27,$B$9)) | C29: =IF(A29="","",INDEX(Configuraciones!$AQ$3:$AQ$27,$B$9)) | D29: =IF(A29="","",INDEX(Configuraciones!$AR$3:$AR$27,$B$9)) | E29: =IF(OR(A29="",D29=""),"",MOD(ROUND(C29-D29,1),360)) | F29: =IF(E29="","",MOD(E29+$B$8,360)) | G29: =IF(I29="","",CHOOSE(INT(I29/180)+1,"Expansión","Escape","Admisión","Compresión")) | H29: =IF(I29="","",IF(MOD(I29,360)=0,"PMS",IF(MOD(I29,180)=0,"PMI",IF(MOD(I29,360)<180,"Baja","Sube")))) | I29: =IF(D29="","",MOD($B$8-D29,720))
A30: =IF(9>$B$12,"",9) | B30: =IF(A30="","",INDEX(Configuraciones!$AU$3:$AU$27,$B$9)) | C30: =IF(A30="","",INDEX(Configuraciones!$AV$3:$AV$27,$B$9)) | D30: =IF(A30="","",INDEX(Configuraciones!$AW$3:$AW$27,$B$9)) | E30: =IF(OR(A30="",D30=""),"",MOD(ROUND(C30-D30,1),360)) | F30: =IF(E30="","",MOD(E30+$B$8,360)) | G30: =IF(I30="","",CHOOSE(INT(I30/180)+1,"Expansión","Escape","Admisión","Compresión")) | H30: =IF(I30="","",IF(MOD(I30,360)=0,"PMS",IF(MOD(I30,180)=0,"PMI",IF(MOD(I30,360)<180,"Baja","Sube")))) | I30: =IF(D30="","",MOD($B$8-D30,720))
A31: =IF(10>$B$12,"",10) | B31: =IF(A31="","",INDEX(Configuraciones!$AZ$3:$AZ$27,$B$9)) | C31: =IF(A31="","",INDEX(Configuraciones!$BA$3:$BA$27,$B$9)) | D31: =IF(A31="","",INDEX(Configuraciones!$BB$3:$BB$27,$B$9)) | E31: =IF(OR(A31="",D31=""),"",MOD(ROUND(C31-D31,1),360)) | F31: =IF(E31="","",MOD(E31+$B$8,360)) | G31: =IF(I31="","",CHOOSE(INT(I31/180)+1,"Expansión","Escape","Admisión","Compresión")) | H31: =IF(I31="","",IF(MOD(I31,360)=0,"PMS",IF(MOD(I31,180)=0,"PMI",IF(MOD(I31,360)<180,"Baja","Sube")))) | I31: =IF(D31="","",MOD($B$8-D31,720))
A32: =IF(11>$B$12,"",11) | B32: =IF(A32="","",INDEX(Configuraciones!$BE$3:$BE$27,$B$9)) | C32: =IF(A32="","",INDEX(Configuraciones!$BF$3:$BF$27,$B$9)) | D32: =IF(A32="","",INDEX(Configuraciones!$BG$3:$BG$27,$B$9)) | E32: =IF(OR(A32="",D32=""),"",MOD(ROUND(C32-D32,1),360)) | F32: =IF(E32="","",MOD(E32+$B$8,360)) | G32: =IF(I32="","",CHOOSE(INT(I32/180)+1,"Expansión","Escape","Admisión","Compresión")) | H32: =IF(I32="","",IF(MOD(I32,360)=0,"PMS",IF(MOD(I32,180)=0,"PMI",IF(MOD(I32,360)<180,"Baja","Sube")))) | I32: =IF(D32="","",MOD($B$8-D32,720))
A33: =IF(12>$B$12,"",12) | B33: =IF(A33="","",INDEX(Configuraciones!$BJ$3:$BJ$27,$B$9)) | C33: =IF(A33="","",INDEX(Configuraciones!$BK$3:$BK$27,$B$9)) | D33: =IF(A33="","",INDEX(Configuraciones!$BL$3:$BL$27,$B$9)) | E33: =IF(OR(A33="",D33=""),"",MOD(ROUND(C33-D33,1),360)) | F33: =IF(E33="","",MOD(E33+$B$8,360)) | G33: =IF(I33="","",CHOOSE(INT(I33/180)+1,"Expansión","Escape","Admisión","Compresión")) | H33: =IF(I33="","",IF(MOD(I33,360)=0,"PMS",IF(MOD(I33,180)=0,"PMI",IF(MOD(I33,360)<180,"Baja","Sube")))) | I33: =IF(D33="","",MOD($B$8-D33,720))
A34: β = ángulo del eje del cilindro visto de frente (sentido horario desde la vertical). El pistón está en el PMS cuando su muñequilla apunta a su eje. φ = posición del cilindro dentro de su ciclo de 720°.
A35: El diagrama de fases completo (tipo tabla del libro) está en la hoja «Diagrama de fases».

Sheet Diagrama de fases
A1: Diagrama de fases del orden de encendido (cada columna = 6° de cigüeñal)
A2: ="Configuración: "&Simulador!B5&" · orden "&Simulador!B13&" · "&Simulador!B15 -> Configuración: Personalizado (en línea, escriba z y el orden) · orden 1-4-3-2 · 720° / 4 = 180°
C4: 0° | R4: 90° | AG4: 180° | AV4: 270° | BK4: 360° | BZ4: 450° | CO4: 540° | DD4: 630° | DS4: 720°
B5: Encendido (°) | C5: 0 | D5: 6 | E5: 12 | F5: 18 | G5: 24 | H5: 30 | I5: 36 | J5: 42 | K5: 48 | L5: 54 | M5: 60 | N5: 66 | O5: 72 | P5: 78 | Q5: 84 | R5: 90 | S5: 96 | T5: 102 | U5: 108 | V5: 114 | W5: 120 | X5: 126 | Y5: 132 | Z5: 138 | AA5: 144 | AB5: 150 | AC5: 156 | AD5: 162 | AE5: 168 | AF5: 174 | AG5: 180 | AH5: 186 | AI5: 192 | AJ5: 198 | AK5: 204 | AL5: 210 | AM5: 216 | AN5: 222 | AO5: 228 | AP5: 234 | AQ5: 240 | AR5: 246 | AS5: 252 | AT5: 258 | AU5: 264 | AV5: 270 | AW5: 276 | AX5: 282 | AY5: 288 | AZ5: 294 | BA5: 300 | BB5: 306 | BC5: 312 | BD5: 318 | BE5: 324 | BF5: 330 | BG5: 336 | BH5: 342 | BI5: 348 | BJ5: 354 | BK5: 360 | BL5: 366 | BM5: 372 | BN5: 378 | BO5: 384 | BP5: 390 | BQ5: 396 | BR5: 402 | BS5: 408 | BT5: 414 | BU5: 420 | BV5: 426 | BW5: 432 | BX5: 438 | BY5: 444 | BZ5: 450 | CA5: 456 | CB5: 462 | CC5: 468 | CD5: 474 | CE5: 480 | CF5: 486 | CG5: 492 | CH5: 498 | CI5: 504 | CJ5: 510 | CK5: 516 | CL5: 522 | CM5: 528 | CN5: 534 | CO5: 540 | CP5: 546 | CQ5: 552 | CR5: 558 | CS5: 564 | CT5: 570 | CU5: 576 | CV5: 582 | CW5: 588 | CX5: 594 | CY5: 600 | CZ5: 606 | DA5: 612 | DB5: 618 | DC5: 624 | DD5: 630 | DE5: 636 | DF5: 642 | DG5: 648 | DH5: 654 | DI5: 660 | DJ5: 666 | DK5: 672 | DL5: 678 | DM5: 684 | DN5: 690 | DO5: 696 | DP5: 702 | DQ5: 708 | DR5: 714
A6: =IF(1>Simulador!$B$12,"","Cilindro "&1) -> Cilindro 1 | B6: =IF(Simulador!D22="","",Simulador!D22) -> 0 | C6: =IF($B6="","",CHOOSE(INT(MOD(C$5+3-$B6,720)/180)+1,"EX","E","A","C")) -> EX | D6: =IF($B6="","",CHOOSE(INT(MOD(D$5+3-$B6,720)/180)+1,"EX","E","A","C")) -> EX | E6: =IF($B6="","",CHOOSE(INT(MOD(E$5+3-$B6,720)/180)+1,"EX","E","A","C")) -> EX | F6: =IF($B6="","",CHOOSE(INT(MOD(F$5+3-$B6,720)/180)+1,"EX","E","A","C")) -> EX | G6: =IF($B6="","",CHOOSE(INT(MOD(G$5+3-$B6,720)/180)+1,"EX","E","A","C")) -> EX | H6: =IF($B6="","",CHOOSE(INT(MOD(H$5+3-$B6,720)/180)+1,"EX","E","A","C")) -> EX | I6: =IF($B6="","",CHOOSE(INT(MOD(I$5+3-$B6,720)/180)+1,"EX","E","A","C")) -> EX | J6: =IF($B6="","",CHOOSE(INT(MOD(J$5+3-$B6,720)/180)+1,"EX","E","A","C")) -> EX | ... DR6: =IF($B6="","",CHOOSE(INT(MOD(DR$5+3-$B6,720)/180)+1,"EX","E","A","C")) -> C
A7: =IF(2>Simulador!$B$12,"","Cilindro "&2) -> Cilindro 2 | B7: =IF(Simulador!D23="","",Simulador!D23) -> 540 | C7: =IF($B7="","",CHOOSE(INT(MOD(C$5+3-$B7,720)/180)+1,"EX","E","A","C")) -> E | D7: =IF($B7="","",CHOOSE(INT(MOD(D$5+3-$B7,720)/180)+1,"EX","E","A","C")) -> E | E7: =IF($B7="","",CHOOSE(INT(MOD(E$5+3-$B7,720)/180)+1,"EX","E","A","C")) -> E | F7: =IF($B7="","",CHOOSE(INT(MOD(F$5+3-$B7,720)/180)+1,"EX","E","A","C")) -> E | G7: =IF($B7="","",CHOOSE(INT(MOD(G$5+3-$B7,720)/180)+1,"EX","E","A","C")) -> E | H7: =IF($B7="","",CHOOSE(INT(MOD(H$5+3-$B7,720)/180)+1,"EX","E","A","C")) -> E | I7: =IF($B7="","",CHOOSE(INT(MOD(I$5+3-$B7,720)/180)+1,"EX","E","A","C")) -> E | J7: =IF($B7="","",CHOOSE(INT(MOD(J$5+3-$B7,720)/180)+1,"EX","E","A","C")) -> E | ... DR7: =IF($B7="","",CHOOSE(INT(MOD(DR$5+3-$B7,720)/180)+1,"EX","E","A","C")) -> EX
A8: =IF(3>Simulador!$B$12,"","Cilindro "&3) -> Cilindro 3 | B8: =IF(Simulador!D24="","",Simulador!D24) -> 360 | C8: =IF($B8="","",CHOOSE(INT(MOD(C$5+3-$B8,720)/180)+1,"EX","E","A","C")) -> A | D8: =IF($B8="","",CHOOSE(INT(MOD(D$5+3-$B8,720)/180)+1,"EX","E","A","C")) -> A | E8: =IF($B8="","",CHOOSE(INT(MOD(E$5+3-$B8,720)/180)+1,"EX","E","A","C")) -> A | F8: =IF($B8="","",CHOOSE(INT(MOD(F$5+3-$B8,720)/180)+1,"EX","E","A","C")) -> A | G8: =IF($B8="","",CHOOSE(INT(MOD(G$5+3-$B8,720)/180)+1,"EX","E","A","C")) -> A | H8: =IF($B8="","",CHOOSE(INT(MOD(H$5+3-$B8,720)/180)+1,"EX","E","A","C")) -> A | I8: =IF($B8="","",CHOOSE(INT(MOD(I$5+3-$B8,720)/180)+1,"EX","E","A","C")) -> A | J8: =IF($B8="","",CHOOSE(INT(MOD(J$5+3-$B8,720)/180)+1,"EX","E","A","C")) -> A | ... DR8: =IF($B8="","",CHOOSE(INT(MOD(DR$5+3-$B8,720)/180)+1,"EX","E","A","C")) -> E
A9: =IF(4>Simulador!$B$12,"","Cilindro "&4) -> Cilindro 4 | B9: =IF(Simulador!D25="","",Simulador!D25) -> 180 | C9: =IF($B9="","",CHOOSE(INT(MOD(C$5+3-$B9,720)/180)+1,"EX","E","A","C")) -> C | D9: =IF($B9="","",CHOOSE(INT(MOD(D$5+3-$B9,720)/180)+1,"EX","E","A","C")) -> C | E9: =IF($B9="","",CHOOSE(INT(MOD(E$5+3-$B9,720)/180)+1,"EX","E","A","C")) -> C | F9: =IF($B9="","",CHOOSE(INT(MOD(F$5+3-$B9,720)/180)+1,"EX","E","A","C")) -> C | G9: =IF($B9="","",CHOOSE(INT(MOD(G$5+3-$B9,720)/180)+1,"EX","E","A","C")) -> C | H9: =IF($B9="","",CHOOSE(INT(MOD(H$5+3-$B9,720)/180)+1,"EX","E","A","C")) -> C | I9: =IF($B9="","",CHOOSE(INT(MOD(I$5+3-$B9,720)/180)+1,"EX","E","A","C")) -> C | J9: =IF($B9="","",CHOOSE(INT(MOD(J$5+3-$B9,720)/180)+1,"EX","E","A","C")) -> C | ... DR9: =IF($B9="","",CHOOSE(INT(MOD(DR$5+3-$B9,720)/180)+1,"EX","E","A","C")) -> A
A10: =IF(5>Simulador!$B$12,"","Cilindro "&5) | B10: =IF(Simulador!D26="","",Simulador!D26) | C10: =IF($B10="","",CHOOSE(INT(MOD(C$5+3-$B10,720)/180)+1,"EX","E","A","C")) | D10: =IF($B10="","",CHOOSE(INT(MOD(D$5+3-$B10,720)/180)+1,"EX","E","A","C")) | E10: =IF($B10="","",CHOOSE(INT(MOD(E$5+3-$B10,720)/180)+1,"EX","E","A","C")) | F10: =IF($B10="","",CHOOSE(INT(MOD(F$5+3-$B10,720)/180)+1,"EX","E","A","C")) | G10: =IF($B10="","",CHOOSE(INT(MOD(G$5+3-$B10,720)/180)+1,"EX","E","A","C")) | H10: =IF($B10="","",CHOOSE(INT(MOD(H$5+3-$B10,720)/180)+1,"EX","E","A","C")) | I10: =IF($B10="","",CHOOSE(INT(MOD(I$5+3-$B10,720)/180)+1,"EX","E","A","C")) | J10: =IF($B10="","",CHOOSE(INT(MOD(J$5+3-$B10,720)/180)+1,"EX","E","A","C")) | ... DR10: =IF($B10="","",CHOOSE(INT(MOD(DR$5+3-$B10,720)/180)+1,"EX","E","A","C"))
A11: =IF(6>Simulador!$B$12,"","Cilindro "&6) | B11: =IF(Simulador!D27="","",Simulador!D27) | C11: =IF($B11="","",CHOOSE(INT(MOD(C$5+3-$B11,720)/180)+1,"EX","E","A","C")) | D11: =IF($B11="","",CHOOSE(INT(MOD(D$5+3-$B11,720)/180)+1,"EX","E","A","C")) | E11: =IF($B11="","",CHOOSE(INT(MOD(E$5+3-$B11,720)/180)+1,"EX","E","A","C")) | F11: =IF($B11="","",CHOOSE(INT(MOD(F$5+3-$B11,720)/180)+1,"EX","E","A","C")) | G11: =IF($B11="","",CHOOSE(INT(MOD(G$5+3-$B11,720)/180)+1,"EX","E","A","C")) | H11: =IF($B11="","",CHOOSE(INT(MOD(H$5+3-$B11,720)/180)+1,"EX","E","A","C")) | I11: =IF($B11="","",CHOOSE(INT(MOD(I$5+3-$B11,720)/180)+1,"EX","E","A","C")) | J11: =IF($B11="","",CHOOSE(INT(MOD(J$5+3-$B11,720)/180)+1,"EX","E","A","C")) | ... DR11: =IF($B11="","",CHOOSE(INT(MOD(DR$5+3-$B11,720)/180)+1,"EX","E","A","C"))
A12: =IF(7>Simulador!$B$12,"","Cilindro "&7) | B12: =IF(Simulador!D28="","",Simulador!D28) | C12: =IF($B12="","",CHOOSE(INT(MOD(C$5+3-$B12,720)/180)+1,"EX","E","A","C")) | D12: =IF($B12="","",CHOOSE(INT(MOD(D$5+3-$B12,720)/180)+1,"EX","E","A","C")) | E12: =IF($B12="","",CHOOSE(INT(MOD(E$5+3-$B12,720)/180)+1,"EX","E","A","C")) | F12: =IF($B12="","",CHOOSE(INT(MOD(F$5+3-$B12,720)/180)+1,"EX","E","A","C")) | G12: =IF($B12="","",CHOOSE(INT(MOD(G$5+3-$B12,720)/180)+1,"EX","E","A","C")) | H12: =IF($B12="","",CHOOSE(INT(MOD(H$5+3-$B12,720)/180)+1,"EX","E","A","C")) | I12: =IF($B12="","",CHOOSE(INT(MOD(I$5+3-$B12,720)/180)+1,"EX","E","A","C")) | J12: =IF($B12="","",CHOOSE(INT(MOD(J$5+3-$B12,720)/180)+1,"EX","E","A","C")) | ... DR12: =IF($B12="","",CHOOSE(INT(MOD(DR$5+3-$B12,720)/180)+1,"EX","E","A","C"))
A13: =IF(8>Simulador!$B$12,"","Cilindro "&8) | B13: =IF(Simulador!D29="","",Simulador!D29) | C13: =IF($B13="","",CHOOSE(INT(MOD(C$5+3-$B13,720)/180)+1,"EX","E","A","C")) | D13: =IF($B13="","",CHOOSE(INT(MOD(D$5+3-$B13,720)/180)+1,"EX","E","A","C")) | E13: =IF($B13="","",CHOOSE(INT(MOD(E$5+3-$B13,720)/180)+1,"EX","E","A","C")) | F13: =IF($B13="","",CHOOSE(INT(MOD(F$5+3-$B13,720)/180)+1,"EX","E","A","C")) | G13: =IF($B13="","",CHOOSE(INT(MOD(G$5+3-$B13,720)/180)+1,"EX","E","A","C")) | H13: =IF($B13="","",CHOOSE(INT(MOD(H$5+3-$B13,720)/180)+1,"EX","E","A","C")) | I13: =IF($B13="","",CHOOSE(INT(MOD(I$5+3-$B13,720)/180)+1,"EX","E","A","C")) | J13: =IF($B13="","",CHOOSE(INT(MOD(J$5+3-$B13,720)/180)+1,"EX","E","A","C")) | ... DR13: =IF($B13="","",CHOOSE(INT(MOD(DR$5+3-$B13,720)/180)+1,"EX","E","A","C"))
A14: =IF(9>Simulador!$B$12,"","Cilindro "&9) | B14: =IF(Simulador!D30="","",Simulador!D30) | C14: =IF($B14="","",CHOOSE(INT(MOD(C$5+3-$B14,720)/180)+1,"EX","E","A","C")) | D14: =IF($B14="","",CHOOSE(INT(MOD(D$5+3-$B14,720)/180)+1,"EX","E","A","C")) | E14: =IF($B14="","",CHOOSE(INT(MOD(E$5+3-$B14,720)/180)+1,"EX","E","A","C")) | F14: =IF($B14="","",CHOOSE(INT(MOD(F$5+3-$B14,720)/180)+1,"EX","E","A","C")) | G14: =IF($B14="","",CHOOSE(INT(MOD(G$5+3-$B14,720)/180)+1,"EX","E","A","C")) | H14: =IF($B14="","",CHOOSE(INT(MOD(H$5+3-$B14,720)/180)+1,"EX","E","A","C")) | I14: =IF($B14="","",CHOOSE(INT(MOD(I$5+3-$B14,720)/180)+1,"EX","E","A","C")) | J14: =IF($B14="","",CHOOSE(INT(MOD(J$5+3-$B14,720)/180)+1,"EX","E","A","C")) | ... DR14: =IF($B14="","",CHOOSE(INT(MOD(DR$5+3-$B14,720)/180)+1,"EX","E","A","C"))
A15: =IF(10>Simulador!$B$12,"","Cilindro "&10) | B15: =IF(Simulador!D31="","",Simulador!D31) | C15: =IF($B15="","",CHOOSE(INT(MOD(C$5+3-$B15,720)/180)+1,"EX","E","A","C")) | D15: =IF($B15="","",CHOOSE(INT(MOD(D$5+3-$B15,720)/180)+1,"EX","E","A","C")) | E15: =IF($B15="","",CHOOSE(INT(MOD(E$5+3-$B15,720)/180)+1,"EX","E","A","C")) | F15: =IF($B15="","",CHOOSE(INT(MOD(F$5+3-$B15,720)/180)+1,"EX","E","A","C")) | G15: =IF($B15="","",CHOOSE(INT(MOD(G$5+3-$B15,720)/180)+1,"EX","E","A","C")) | H15: =IF($B15="","",CHOOSE(INT(MOD(H$5+3-$B15,720)/180)+1,"EX","E","A","C")) | I15: =IF($B15="","",CHOOSE(INT(MOD(I$5+3-$B15,720)/180)+1,"EX","E","A","C")) | J15: =IF($B15="","",CHOOSE(INT(MOD(J$5+3-$B15,720)/180)+1,"EX","E","A","C")) | ... DR15: =IF($B15="","",CHOOSE(INT(MOD(DR$5+3-$B15,720)/180)+1,"EX","E","A","C"))
A16: =IF(11>Simulador!$B$12,"","Cilindro "&11) | B16: =IF(Simulador!D32="","",Simulador!D32) | C16: =IF($B16="","",CHOOSE(INT(MOD(C$5+3-$B16,720)/180)+1,"EX","E","A","C")) | D16: =IF($B16="","",CHOOSE(INT(MOD(D$5+3-$B16,720)/180)+1,"EX","E","A","C")) | E16: =IF($B16="","",CHOOSE(INT(MOD(E$5+3-$B16,720)/180)+1,"EX","E","A","C")) | F16: =IF($B16="","",CHOOSE(INT(MOD(F$5+3-$B16,720)/180)+1,"EX","E","A","C")) | G16: =IF($B16="","",CHOOSE(INT(MOD(G$5+3-$B16,720)/180)+1,"EX","E","A","C")) | H16: =IF($B16="","",CHOOSE(INT(MOD(H$5+3-$B16,720)/180)+1,"EX","E","A","C")) | I16: =IF($B16="","",CHOOSE(INT(MOD(I$5+3-$B16,720)/180)+1,"EX","E","A","C")) | J16: =IF($B16="","",CHOOSE(INT(MOD(J$5+3-$B16,720)/180)+1,"EX","E","A","C")) | ... DR16: =IF($B16="","",CHOOSE(INT(MOD(DR$5+3-$B16,720)/180)+1,"EX","E","A","C"))
A17: =IF(12>Simulador!$B$12,"","Cilindro "&12) | B17: =IF(Simulador!D33="","",Simulador!D33) | C17: =IF($B17="","",CHOOSE(INT(MOD(C$5+3-$B17,720)/180)+1,"EX","E","A","C")) | D17: =IF($B17="","",CHOOSE(INT(MOD(D$5+3-$B17,720)/180)+1,"EX","E","A","C")) | E17: =IF($B17="","",CHOOSE(INT(MOD(E$5+3-$B17,720)/180)+1,"EX","E","A","C")) | F17: =IF($B17="","",CHOOSE(INT(MOD(F$5+3-$B17,720)/180)+1,"EX","E","A","C")) | G17: =IF($B17="","",CHOOSE(INT(MOD(G$5+3-$B17,720)/180)+1,"EX","E","A","C")) | H17: =IF($B17="","",CHOOSE(INT(MOD(H$5+3-$B17,720)/180)+1,"EX","E","A","C")) | I17: =IF($B17="","",CHOOSE(INT(MOD(I$5+3-$B17,720)/180)+1,"EX","E","A","C")) | J17: =IF($B17="","",CHOOSE(INT(MOD(J$5+3-$B17,720)/180)+1,"EX","E","A","C")) | ... DR17: =IF($B17="","",CHOOSE(INT(MOD(DR$5+3-$B17,720)/180)+1,"EX","E","A","C"))
A18: En expansión | C18: =COUNTIF(C6:C17,"EX") -> 1 | D18: =COUNTIF(D6:D17,"EX") -> 1 | E18: =COUNTIF(E6:E17,"EX") -> 1 | F18: =COUNTIF(F6:F17,"EX") -> 1 | G18: =COUNTIF(G6:G17,"EX") -> 1 | H18: =COUNTIF(H6:H17,"EX") -> 1 | I18: =COUNTIF(I6:I17,"EX") -> 1 | J18: =COUNTIF(J6:J17,"EX") -> 1 | ... DR18: =COUNTIF(DR6:DR17,"EX") -> 1
A19: Posición de θ | C19: =IF(AND(Simulador!$B$8>=C$5,Simulador!$B$8<C$5+6),"▲","") -> ▲ | D19: =IF(AND(Simulador!$B$8>=D$5,Simulador!$B$8<D$5+6),"▲","") | E19: =IF(AND(Simulador!$B$8>=E$5,Simulador!$B$8<E$5+6),"▲","") | F19: =IF(AND(Simulador!$B$8>=F$5,Simulador!$B$8<F$5+6),"▲","") | G19: =IF(AND(Simulador!$B$8>=G$5,Simulador!$B$8<G$5+6),"▲","") | H19: =IF(AND(Simulador!$B$8>=H$5,Simulador!$B$8<H$5+6),"▲","") | I19: =IF(AND(Simulador!$B$8>=I$5,Simulador!$B$8<I$5+6),"▲","") | J19: =IF(AND(Simulador!$B$8>=J$5,Simulador!$B$8<J$5+6),"▲","") | ... DR19: =IF(AND(Simulador!$B$8>=DR$5,Simulador!$B$8<DR$5+6),"▲","")
A21: EX = expansión (trabajo) · E = escape · A = admisión · C = compresión. La letra aparece al comienzo de cada tiempo; la columna «Encendido» indica el ángulo del cigüeñal en que salta la chispa en cada cilindro.
A22: Las celdas rosadas de la fila «En expansión» señalan tramos sin ningún cilindro produciendo trabajo.

Sheet Resumen
A1: Resumen · intervalos de encendido por número y disposición de cilindros
A2: Valores calculados para todas las configuraciones del simulador.
A4: Configuración | B4: Cilindros | C4: División 720°/z | D4: Orden de encendido | E4: Disposición | F4: Intervalos reales (°) | G4: Cilindros en expansión a la vez | H4: Observación
A5: 1 cilindro (monocilíndrico) | B5: 1 | C5: 720° | D5: 1 | E5: En línea | F5: 720 (regular) | G5: 0 a 1 | H5: Un solo encendido cada 720°: tres tiempos sin trabajo; necesita un volante grande.
A6: 2 cilindros en línea (cigüeñal a 360°) | B6: 2 | C6: 360° | D6: 1-2 | E6: En línea | F6: 360 (regular) | G6: 0 a 1 | H6: Las dos muñequillas están juntas: los pistones suben y bajan a la vez y se alternan los tiempos. Intervalo regular de 360°.
A7: 2 cilindros en línea (cigüeñal a 180°) | B7: 2 | C7: 360° | D7: 1-2 | E7: En línea | F7: 180, 540 (irregular) | G7: 0 a 1 | H7: Muñequillas opuestas: mejor equilibrio de masas, pero encendidos irregulares (180° y 540°).
A8: 2 cilindros horizontales opuestos (bóxer) | B8: 2 | C8: 360° | D8: 1-2 | E8: Bóxer | F8: 360 (regular) | G8: 0 a 1 | H8: Cilindros enfrentados y muñequillas a 180°: los pistones se mueven en sentidos opuestos y las fuerzas de inercia se anulan. Intervalo de 360°.
A9: 2 cilindros en V a 90° | B9: 2 | C9: 360° | D9: 1-2 | E9: En V 90° | F9: 270, 450 (irregular) | G9: 0 a 1 | H9: Dos bielas en la misma muñequilla: encendidos a 450° y 270°, el sonido irregular típico de las motos en V.
A10: 3 cilindros en línea (1-3-2) | B10: 3 | C10: 240° | D10: 1-3-2 | E10: En línea | F10: 240 (regular) | G10: 0 a 1 | H10: Muñequillas a 120°. Intervalo de 240°: entre una expansión y la siguiente hay 60° sin trabajo.
A11: 3 cilindros en línea (1-2-3) | B11: 3 | C11: 240° | D11: 1-2-3 | E11: En línea | F11: 240 (regular) | G11: 0 a 1 | H11: Mismo intervalo de 240° con el orden inverso de las muñequillas.
A12: 4 cilindros en línea (1-3-4-2) | B12: 4 | C12: 180° | D12: 1-3-4-2 | E12: En línea | F12: 180 (regular) | G12: 1 | H12: Muñequillas 1-4 arriba y 2-3 abajo. Intervalo de 180°: siempre hay un cilindro en expansión. Orden más usado.
A13: 4 cilindros en línea (1-2-4-3) | B13: 4 | C13: 180° | D13: 1-2-4-3 | E13: En línea | F13: 180 (regular) | G13: 1 | H13: Mismo cigüeñal; cambia el árbol de levas. Intervalo de 180°.
A14: 4 cilindros bóxer (1-4-3-2, VW) | B14: 4 | C14: 180° | D14: 1-4-3-2 | E14: Bóxer | F14: 180 (regular) | G14: 1 | H14: Cilindros 1-2 a la derecha y 3-4 a la izquierda (numeración VW). Intervalo de 180°.
A15: 4 cilindros bóxer (1-3-2-4, Subaru) | B15: 4 | C15: 180° | D15: 1-3-2-4 | E15: Bóxer | F15: 180 (regular) | G15: 1 | H15: Impares a la derecha y pares a la izquierda (numeración Subaru). Intervalo de 180°.
A16: 5 cilindros en línea (1-2-4-5-3) | B16: 5 | C16: 144° | D16: 1-2-4-5-3 | E16: En línea | F16: 144 (regular) | G16: 1 a 2 | H16: Muñequillas a 72°. Intervalo de 144°: las expansiones se solapan 36°.
... A28: Radial (estrella) de 9 cilindros (1-3-5-7-9-2-4-6-8) | B28: 9 | C28: 80° | D28: 1-3-5-7-9-2-4-6-8 | E28: Radial | F28: 80 (regular) | G28: 2 a 3 | H28: Cilindros en estrella a 40.0° alrededor de una sola muñequilla: el número impar permite encender uno sí y otro no. Intervalo de 80.0°.

Sheet Guía
B2: Simulador del orden de encendido
B3: Relaciona el número de cilindros, su disposición (en línea, en V, bóxer, VR y radial), la forma del cigüeñal y el orden de encendido, como en el tema «Formas del cigüeñal y tiempos de trabajo».
B4: Cómo se usa
B5: 1. En B5 elija la configuración. La hoja muestra la división 720°/z, los intervalos reales (algunos motores, como el 2 en V o el 2 en línea a 180°, encienden de forma irregular) y cuántos cilindros trabajan a la vez.
B6: 2. El diagrama de fases reproduce las tablas del libro (EX, E, A, C) con una columna cada 6°: cada fila es un cilindro y se ve el desfase de 720°/z entre encendidos sucesivos.
B7: 3. Cambie θ (B8) en pasos de 30° o del intervalo: la tabla indica el tiempo y la posición de cada pistón, el gráfico de muñequillas gira y el triángulo rojo marca θ en el diagrama. Un pistón está en el PMS cuando su muñequilla coincide con el eje discontinuo de su cilindro.
B8: 4. «Personalizado» permite escribir cualquier número de cilindros (1 a 12) y cualquier orden para un motor en línea, por ejemplo para comprobar el orden de un motor del taller.
B9: Actividades
B10: • Compare el 4 en línea 1-3-4-2 con el 1-2-4-3: el cigüeñal es el mismo y solo cambia el árbol de levas.
B11: • Compare los dos V8 (cruciforme y plano) y el 2 en línea a 360° y a 180°: ¿por qué uno es regular y el otro no?
B12: • Observe la fila «Cilindros en expansión»: con 3 cilindros hay tramos sin trabajo; con 6 o más siempre se solapan expansiones (motor más suave).
B13: • En los radiales, explique por qué el número de cilindros es impar.
... B15: Las numeraciones de cilindros siguen la convención indicada en cada configuración (GM, VW, Subaru, Porsche, Ferrari); otros fabricantes numeran distinto: consulte siempre el manual. Fuente de referencia: González Calleja, D. (2018). Motores (2.ª ed.). Paraninfo.

Sheet Configuraciones
A1: Catálogo de configuraciones (no editar; la fila «Personalizado» toma los datos de la hoja Simulador)
A2: Configuración | B2: Cilindros z | C2: Orden de encendido | D2: Disposición | E2: Ángulo entre bancadas (°) | F2: Descripción | G2: C1 bancada | H2: C1 eje β (°) | I2: C1 encendido (°) | J2: C1 x | K2: C1 y | L2: C2 bancada | M2: C2 eje β (°) | N2: C2 encendido (°) | O2: C2 x | P2: C2 y | Q2: C3 bancada | R2: C3 eje β (°) | S2: C3 encendido (°) | T2: C3 x | U2: C3 y | V2: C4 bancada | W2: C4 eje β (°) | X2: C4 encendido (°) | Y2: C4 x | Z2: C4 y | AA2: C5 bancada | AB2: C5 eje β (°) | AC2: C5 encendido (°) | AD2: C5 x | AE2: C5 y | AF2: C6 bancada | AG2: C6 eje β (°) | AH2: C6 encendido (°) | AI2: C6 x | AJ2: C6 y | AK2: C7 bancada | AL2: C7 eje β (°) | AM2: C7 encendido (°) | AN2: C7 x | AO2: C7 y | AP2: C8 bancada | AQ2: C8 eje β (°) | AR2: C8 encendido (°) | AS2: C8 x | AT2: C8 y | AU2: C9 bancada | AV2: C9 eje β (°) | AW2: C9 encendido (°) | AX2: C9 x | AY2: C9 y | AZ2: C10 bancada | BA2: C10 eje β (°) | BB2: C10 encendido (°) | BC2: C10 x | BD2: C10 y | BE2: C11 bancada | BF2: C11 eje β (°) | BG2: C11 encendido (°) | BH2: C11 x | BI2: C11 y | BJ2: C12 bancada | BK2: C12 eje β (°) | BL2: C12 encendido (°) | BM2: C12 x | BN2: C12 y
A3: 1 cilindro (monocilíndrico) | B3: 1 | C3: 1 | D3: En línea | E3: 0 | F3: Un solo encendido cada 720°: tres tiempos sin trabajo; necesita un volante grande. | G3: - | H3: 0 | I3: 0 | J3: 1 | K3: 0
A4: 2 cilindros en línea (cigüeñal a 360°) | B4: 2 | C4: 1-2 | D4: En línea | E4: 0 | F4: Las dos muñequillas están juntas: los pistones suben y bajan a la vez y se alternan los tiempos. Intervalo regular de 360°. | G4: - | H4: 0 | I4: 0 | J4: 1 | K4: 0 | L4: - | M4: 0 | N4: 360 | O4: 2 | P4: 0
A5: 2 cilindros en línea (cigüeñal a 180°) | B5: 2 | C5: 1-2 | D5: En línea | E5: 0 | F5: Muñequillas opuestas: mejor equilibrio de masas, pero encendidos irregulares (180° y 540°). | G5: - | H5: 0 | I5: 0 | J5: 1 | K5: 0 | L5: - | M5: 0 | N5: 180 | O5: 2 | P5: 0
A6: 2 cilindros horizontales opuestos (bóxer) | B6: 2 | C6: 1-2 | D6: Bóxer | E6: 180 | F6: Cilindros enfrentados y muñequillas a 180°: los pistones se mueven en sentidos opuestos y las fuerzas de inercia se anulan. Intervalo de 360°. | G6: B | H6: -90 | I6: 0 | J6: 1 | K6: -1 | L6: A | M6: 90 | N6: 360 | O6: 1.35 | P6: 1
A7: 2 cilindros en V a 90° | B7: 2 | C7: 1-2 | D7: En V | E7: 90 | F7: Dos bielas en la misma muñequilla: encendidos a 450° y 270°, el sonido irregular típico de las motos en V. | G7: B | H7: -45 | I7: 0 | J7: 1 | K7: -1 | L7: A | M7: 45 | N7: 450 | O7: 1 | P7: 1
A8: 3 cilindros en línea (1-3-2) | B8: 3 | C8: 1-3-2 | D8: En línea | E8: 0 | F8: Muñequillas a 120°. Intervalo de 240°: entre una expansión y la siguiente hay 60° sin trabajo. | G8: - | H8: 0 | I8: 0 | J8: 1 | K8: 0 | L8: - | M8: 0 | N8: 480 | O8: 2 | P8: 0 | Q8: - | R8: 0 | S8: 240 | T8: 3 | U8: 0
A9: 3 cilindros en línea (1-2-3) | B9: 3 | C9: 1-2-3 | D9: En línea | E9: 0 | F9: Mismo intervalo de 240° con el orden inverso de las muñequillas. | G9: - | H9: 0 | I9: 0 | J9: 1 | K9: 0 | L9: - | M9: 0 | N9: 240 | O9: 2 | P9: 0 | Q9: - | R9: 0 | S9: 480 | T9: 3 | U9: 0
A10: 4 cilindros en línea (1-3-4-2) | B10: 4 | C10: 1-3-4-2 | D10: En línea | E10: 0 | F10: Muñequillas 1-4 arriba y 2-3 abajo. Intervalo de 180°: siempre hay un cilindro en expansión. Orden más usado. | G10: - | H10: 0 | I10: 0 | J10: 1 | K10: 0 | L10: - | M10: 0 | N10: 540 | O10: 2 | P10: 0 | Q10: - | R10: 0 | S10: 180 | T10: 3 | U10: 0 | V10: - | W10: 0 | X10: 360 | Y10: 4 | Z10: 0
A11: 4 cilindros en línea (1-2-4-3) | B11: 4 | C11: 1-2-4-3 | D11: En línea | E11: 0 | F11: Mismo cigüeñal; cambia el árbol de levas. Intervalo de 180°. | G11: - | H11: 0 | I11: 0 | J11: 1 | K11: 0 | L11: - | M11: 0 | N11: 180 | O11: 2 | P11: 0 | Q11: - | R11: 0 | S11: 540 | T11: 3 | U11: 0 | V11: - | W11: 0 | X11: 360 | Y11: 4 | Z11: 0
A12: 4 cilindros bóxer (1-4-3-2, VW) | B12: 4 | C12: 1-4-3-2 | D12: Bóxer | E12: 180 | F12: Cilindros 1-2 a la derecha y 3-4 a la izquierda (numeración VW). Intervalo de 180°. | G12: A | H12: 90 | I12: 0 | J12: 1 | K12: 1 | L12: A | M12: 90 | N12: 540 | O12: 2 | P12: 1 | Q12: B | R12: -90 | S12: 360 | T12: 1.35 | U12: -1 | V12: B | W12: -90 | X12: 180 | Y12: 2.35 | Z12: -1
A13: 4 cilindros bóxer (1-3-2-4, Subaru) | B13: 4 | C13: 1-3-2-4 | D13: Bóxer | E13: 180 | F13: Impares a la derecha y pares a la izquierda (numeración Subaru). Intervalo de 180°. | G13: A | H13: 90 | I13: 0 | J13: 1 | K13: 1 | L13: B | M13: -90 | N13: 360 | O13: 1.35 | P13: -1 | Q13: A | R13: 90 | S13: 180 | T13: 2 | U13: 1 | V13: B | W13: -90 | X13: 540 | Y13: 2.35 | Z13: -1
A14: 5 cilindros en línea (1-2-4-5-3) | B14: 5 | C14: 1-2-4-5-3 | D14: En línea | E14: 0 | F14: Muñequillas a 72°. Intervalo de 144°: las expansiones se solapan 36°. | G14: - | H14: 0 | I14: 0 | J14: 1 | K14: 0 | L14: - | M14: 0 | N14: 144 | O14: 2 | P14: 0 | Q14: - | R14: 0 | S14: 576 | T14: 3 | U14: 0 | V14: - | W14: 0 | X14: 288 | Y14: 4 | Z14: 0 | AA14: - | AB14: 0 | AC14: 432 | AD14: 5 | AE14: 0
A15: 6 cilindros en línea (1-5-3-6-2-4) | B15: 6 | C15: 1-5-3-6-2-4 | D15: En línea | E15: 0 | F15: Muñequillas a 120° por parejas (1-6, 2-5, 3-4). Intervalo de 120°; equilibrio perfecto de fuerzas de 1.º y 2.º orden. | G15: - | H15: 0 | I15: 0 | J15: 1 | K15: 0 | L15: - | M15: 0 | N15: 480 | O15: 2 | P15: 0 | Q15: - | R15: 0 | S15: 240 | T15: 3 | U15: 0 | V15: - | W15: 0 | X15: 600 | Y15: 4 | Z15: 0 | AA15: - | AB15: 0 | AC15: 120 | AD15: 5 | AE15: 0 | AF15: - | AG15: 0 | AH15: 360 | AI15: 6 | AJ15: 0
A16: 6 cilindros en V a 60° (1-2-3-4-5-6) | B16: 6 | C16: 1-2-3-4-5-6 | D16: En V | E16: 60 | F16: Impares en una bancada y pares en la otra; cada cilindro tiene su muñequilla. Intervalo de 120°. | G16: A | H16: 30 | I16: 0 | J16: 1 | K16: 1 | L16: B | M16: -30 | N16: 120 | O16: 1.35 | P16: -1 | Q16: A | R16: 30 | S16: 240 | T16: 2 | U16: 1 | V16: B | W16: -30 | X16: 360 | Y16: 2.35 | Z16: -1 | AA16: A | AB16: 30 | AC16: 480 | AD16: 3 | AE16: 1 | AF16: B | AG16: -30 | AH16: 600 | AI16: 3.35 | AJ16: -1
A17: VR6 a 15° (1-5-3-6-2-4) | B17: 6 | C17: 1-5-3-6-2-4 | D17: VR | E17: 15 | F17: Dos filas casi paralelas en un bloque y una sola culata (VW). Intervalo de 120°. | G17: A | H17: 7.5 | I17: 0 | J17: 1 | K17: 0.35 | L17: B | M17: -7.5 | N17: 480 | O17: 2 | P17: -0.35 | Q17: A | R17: 7.5 | S17: 240 | T17: 3 | U17: 0.35 | V17: B | W17: -7.5 | X17: 600 | Y17: 4 | Z17: -0.35 | AA17: A | AB17: 7.5 | AC17: 120 | AD17: 5 | AE17: 0.35 | AF17: B | AG17: -7.5 | AH17: 360 | AI17: 6 | AJ17: -0.35
A18: 6 cilindros bóxer (1-6-2-4-3-5, Porsche) | B18: 6 | C18: 1-6-2-4-3-5 | D18: Bóxer | E18: 180 | F18: Cilindros 1-2-3 en una bancada y 4-5-6 en la otra. Intervalo de 120°. | G18: A | H18: 90 | I18: 0 | J18: 1 | K18: 1 | L18: A | M18: 90 | N18: 240 | O18: 2 | P18: 1 | Q18: A | R18: 90 | S18: 480 | T18: 3 | U18: 1 | V18: B | W18: -90 | X18: 360 | Y18: 1.35 | Z18: -1 | AA18: B | AB18: -90 | AC18: 600 | AD18: 2.35 | AE18: -1 | AF18: B | AG18: -90 | AH18: 120 | AI18: 3.35 | AJ18: -1
A19: 8 cilindros en línea (1-6-2-5-8-3-7-4) | B19: 8 | C19: 1-6-2-5-8-3-7-4 | D19: En línea | E19: 0 | F19: Cigüeñal muy largo (motores de época y marinos). Intervalo de 90°. | G19: - | H19: 0 | I19: 0 | J19: 1 | K19: 0 | L19: - | M19: 0 | N19: 180 | O19: 2 | P19: 0 | Q19: - | R19: 0 | S19: 450 | T19: 3 | U19: 0 | V19: - | W19: 0 | X19: 630 | Y19: 4 | Z19: 0 | AA19: - | AB19: 0 | AC19: 270 | AD19: 5 | AE19: 0 | AF19: - | AG19: 0 | AH19: 90 | AI19: 6 | AJ19: 0 | AK19: - | AL19: 0 | AM19: 540 | AN19: 7 | AO19: 0 | AP19: - | AQ19: 0 | AR19: 360 | AS19: 8 | AT19: 0
A20: 8 cilindros en V a 90° cruciforme (1-8-4-3-6-5-7-2) | B20: 8 | C20: 1-8-4-3-6-5-7-2 | D20: En V | E20: 90 | F20: Muñequillas a 90° en cruz, dos bielas por muñequilla (numeración GM: impares en una bancada). Intervalo de 90°. | G20: A | H20: 45 | I20: 0 | J20: 1 | K20: 1 | L20: B | M20: -45 | N20: 630 | O20: 1.35 | P20: -1 | Q20: A | R20: 45 | S20: 270 | T20: 2 | U20: 1 | V20: B | W20: -45 | X20: 180 | Y20: 2.35 | Z20: -1 | AA20: A | AB20: 45 | AC20: 450 | AD20: 3 | AE20: 1 | AF20: B | AG20: -45 | AH20: 360 | AI20: 3.35 | AJ20: -1 | AK20: A | AL20: 45 | AM20: 540 | AN20: 4 | AO20: 1 | AP20: B | AQ20: -45 | AR20: 90 | AS20: 4.35 | AT20: -1
A21: 8 cilindros en V a 90° plano (1-5-3-7-4-8-2-6) | B21: 8 | C21: 1-5-3-7-4-8-2-6 | D21: En V | E21: 90 | F21: Cigüeñal plano a 180°: como dos motores de 4 en línea. Encendidos alternos entre bancadas (numeración Ferrari 1-4 y 5-8). Intervalo de 90°. | G21: B | H21: -45 | I21: 0 | J21: 1 | K21: -1 | L21: B | M21: -45 | N21: 540 | O21: 2 | P21: -1 | Q21: B | R21: -45 | S21: 180 | T21: 3 | U21: -1 | V21: B | W21: -45 | X21: 360 | Y21: 4 | Z21: -1 | AA21: A | AB21: 45 | AC21: 90 | AD21: 1.35 | AE21: 1 | AF21: A | AG21: 45 | AH21: 630 | AI21: 2.35 | AJ21: 1 | AK21: A | AL21: 45 | AM21: 270 | AN21: 3.35 | AO21: 1 | AP21: A | AQ21: 45 | AR21: 450 | AS21: 4.35 | AT21: 1
A22: 10 cilindros en V a 90° (1-10-9-4-3-6-5-8-7-2) | B22: 10 | C22: 1-10-9-4-3-6-5-8-7-2 | D22: En V | E22: 90 | F22: Intervalo de 72° (muñequillas desplazadas para encendido regular). | G22: A | H22: 45 | I22: 0 | J22: 1 | K22: 1 | L22: B | M22: -45 | N22: 648 | O22: 1.35 | P22: -1 | Q22: A | R22: 45 | S22: 288 | T22: 2 | U22: 1 | V22: B | W22: -45 | X22: 216 | Y22: 2.35 | Z22: -1 | AA22: A | AB22: 45 | AC22: 432 | AD22: 3 | AE22: 1 | AF22: B | AG22: -45 | AH22: 360 | AI22: 3.35 | AJ22: -1 | AK22: A | AL22: 45 | AM22: 576 | AN22: 4 | AO22: 1 | AP22: B | AQ22: -45 | AR22: 504 | AS22: 4.35 | AT22: -1 | AU22: A | AV22: 45 | AW22: 144 | AX22: 5 | AY22: 1 | AZ22: B | BA22: -45 | BB22: 72 | BC22: 5.35 | BD22: -1
A23: 12 cilindros en V a 60° (1-7-5-11-3-9-6-12-2-8-4-10) | B23: 12 | C23: 1-7-5-11-3-9-6-12-2-8-4-10 | D23: En V | E23: 60 | F23: Dos motores de 6 en línea sobre un cigüeñal común; bancada 1-6 y 7-12. Intervalo de 60°: siempre hay 3 cilindros en expansión. | G23: B | H23: -30 | I23: 0 | J23: 1 | K23: -1 | L23: B | M23: -30 | N23: 480 | O23: 2 | P23: -1 | Q23: B | R23: -30 | S23: 240 | T23: 3 | U23: -1 | V23: B | W23: -30 | X23: 600 | Y23: 4 | Z23: -1 | AA23: B | AB23: -30 | AC23: 120 | AD23: 5 | AE23: -1 | AF23: B | AG23: -30 | AH23: 360 | AI23: 6 | AJ23: -1 | AK23: A | AL23: 30 | AM23: 60 | AN23: 1.35 | AO23: 1 | AP23: A | AQ23: 30 | AR23: 540 | AS23: 2.35 | AT23: 1 | AU23: A | AV23: 30 | AW23: 300 | AX23: 3.35 | AY23: 1 | AZ23: A | BA23: 30 | BB23: 660 | BC23: 4.35 | BD23: 1 | BE23: A | BF23: 30 | BG23: 180 | BH23: 5.35 | BI23: 1 | BJ23: A | BK23: 30 | BL23: 420 | BM23: 6.35 | BN23: 1
A24: Radial (estrella) de 5 cilindros (1-3-5-2-4) | B24: 5 | C24: 1-3-5-2-4 | D24: Radial | E24: 72 | F24: Cilindros en estrella a 72.0° alrededor de una sola muñequilla: el número impar permite encender uno sí y otro no. Intervalo de 144.0°. | G24: - | H24: 0 | I24: 0 | J24: 0 | K24: 1 | L24: - | M24: 72 | N24: 432 | O24: 0.951 | P24: 0.309 | Q24: - | R24: 144 | S24: 144 | T24: 0.588 | U24: -0.809 | V24: - | W24: 216 | X24: 576 | Y24: -0.588 | Z24: -0.809 | AA24: - | AB24: 288 | AC24: 288 | AD24: -0.951 | AE24: 0.309
A25: Radial (estrella) de 7 cilindros (1-3-5-7-2-4-6) | B25: 7 | C25: 1-3-5-7-2-4-6 | D25: Radial | E25: 51.43 | F25: Cilindros en estrella a 51.4° alrededor de una sola muñequilla: el número impar permite encender uno sí y otro no. Intervalo de 102.9°. | G25: - | H25: 0 | I25: 0 | J25: 0 | K25: 1 | L25: - | M25: 51.43 | N25: 411.4286 | O25: 0.782 | P25: 0.623 | Q25: - | R25: 102.86 | S25: 102.8571 | T25: 0.975 | U25: -0.223 | V25: - | W25: 154.29 | X25: 514.2857 | Y25: 0.434 | Z25: -0.901 | AA25: - | AB25: 205.71 | AC25: 205.7143 | AD25: -0.434 | AE25: -0.901 | AF25: - | AG25: 257.14 | AH25: 617.1429 | AI25: -0.975 | AJ25: -0.223 | AK25: - | AL25: 308.57 | AM25: 308.5714 | AN25: -0.782 | AO25: 0.623
A26: Radial (estrella) de 9 cilindros (1-3-5-7-9-2-4-6-8) | B26: 9 | C26: 1-3-5-7-9-2-4-6-8 | D26: Radial | E26: 40 | F26: Cilindros en estrella a 40.0° alrededor de una sola muñequilla: el número impar permite encender uno sí y otro no. Intervalo de 80.0°. | G26: - | H26: 0 | I26: 0 | J26: 0 | K26: 1 | L26: - | M26: 40 | N26: 400 | O26: 0.643 | P26: 0.766 | Q26: - | R26: 80 | S26: 80 | T26: 0.985 | U26: 0.174 | V26: - | W26: 120 | X26: 480 | Y26: 0.866 | Z26: -0.5 | AA26: - | AB26: 160 | AC26: 160 | AD26: 0.342 | AE26: -0.94 | AF26: - | AG26: 200 | AH26: 560 | AI26: -0.342 | AJ26: -0.94 | AK26: - | AL26: 240 | AM26: 240 | AN26: -0.866 | AO26: -0.5 | AP26: - | AQ26: 280 | AR26: 640 | AS26: -0.985 | AT26: 0.174 | AU26: - | AV26: 320 | AW26: 320 | AX26: -0.643 | AY26: 0.766
A27: Personalizado (en línea, escriba z y el orden) | B27: =Simulador!B6 -> 4 | C27: =Simulador!B7 -> 1-4-3-2 | D27: En línea | E27: 0 | F27: Motor en línea definido por el usuario: el intervalo es 720°/z y el orden se toma de la celda B7 del simulador. | G27: =IF(1>$B$27,"","-") -> - | H27: =IF(1>$B$27,"",0) -> 0 | I27: =IF(1>$B$27,"",IFERROR((MATCH(1,$B$30:$M$30,0)-1)*720/$B$27,"")) -> 0 | J27: =IF(1>$B$27,"",1) -> 1 | K27: =IF(1>$B$27,"",0) -> 0 | L27: =IF(2>$B$27,"","-") -> - | M27: =IF(2>$B$27,"",0) -> 0 | N27: =IF(2>$B$27,"",IFERROR((MATCH(2,$B$30:$M$30,0)-1)*720/$B$27,"")) -> 540 | O27: =IF(2>$B$27,"",2) -> 2 | P27: =IF(2>$B$27,"",0) -> 0 | Q27: =IF(3>$B$27,"","-") -> - | R27: =IF(3>$B$27,"",0) -> 0 | S27: =IF(3>$B$27,"",IFERROR((MATCH(3,$B$30:$M$30,0)-1)*720/$B$27,"")) -> 360 | T27: =IF(3>$B$27,"",3) -> 3 | U27: =IF(3>$B$27,"",0) -> 0 | V27: =IF(4>$B$27,"","-") -> - | W27: =IF(4>$B$27,"",0) -> 0 | X27: =IF(4>$B$27,"",IFERROR((MATCH(4,$B$30:$M$30,0)-1)*720/$B$27,"")) -> 180 | Y27: =IF(4>$B$27,"",4) -> 4 | Z27: =IF(4>$B$27,"",0) -> 0 | AA27: =IF(5>$B$27,"","-") | AB27: =IF(5>$B$27,"",0) | AC27: =IF(5>$B$27,"",IFERROR((MATCH(5,$B$30:$M$30,0)-1)*720/$B$27,"")) | AD27: =IF(5>$B$27,"",5) | AE27: =IF(5>$B$27,"",0) | AF27: =IF(6>$B$27,"","-") | AG27: =IF(6>$B$27,"",0) | AH27: =IF(6>$B$27,"",IFERROR((MATCH(6,$B$30:$M$30,0)-1)*720/$B$27,"")) | AI27: =IF(6>$B$27,"",6) | AJ27: =IF(6>$B$27,"",0) | AK27: =IF(7>$B$27,"","-") | AL27: =IF(7>$B$27,"",0) | AM27: =IF(7>$B$27,"",IFERROR((MATCH(7,$B$30:$M$30,0)-1)*720/$B$27,"")) | AN27: =IF(7>$B$27,"",7) | AO27: =IF(7>$B$27,"",0) | AP27: =IF(8>$B$27,"","-") | AQ27: =IF(8>$B$27,"",0) | AR27: =IF(8>$B$27,"",IFERROR((MATCH(8,$B$30:$M$30,0)-1)*720/$B$27,"")) | AS27: =IF(8>$B$27,"",8) | AT27: =IF(8>$B$27,"",0) | AU27: =IF(9>$B$27,"","-") | AV27: =IF(9>$B$27,"",0) | AW27: =IF(9>$B$27,"",IFERROR((MATCH(9,$B$30:$M$30,0)-1)*720/$B$27,"")) | AX27: =IF(9>$B$27,"",9) | AY27: =IF(9>$B$27,"",0) | AZ27: =IF(10>$B$27,"","-") | BA27: =IF(10>$B$27,"",0) | BB27: =IF(10>$B$27,"",IFERROR((MATCH(10,$B$30:$M$30,0)-1)*720/$B$27,"")) | BC27: =IF(10>$B$27,"",10) | BD27: =IF(10>$B$27,"",0) | BE27: =IF(11>$B$27,"","-") | BF27: =IF(11>$B$27,"",0) | BG27: =IF(11>$B$27,"",IFERROR((MATCH(11,$B$30:$M$30,0)-1)*720/$B$27,"")) | BH27: =IF(11>$B$27,"",11) | BI27: =IF(11>$B$27,"",0) | BJ27: =IF(12>$B$27,"","-") | BK27: =IF(12>$B$27,"",0) | BL27: =IF(12>$B$27,"",IFERROR((MATCH(12,$B$30:$M$30,0)-1)*720/$B$27,"")) | BM27: =IF(12>$B$27,"",12) | BN27: =IF(12>$B$27,"",0)
A29: Análisis del orden personalizado: cilindro en cada posición
B30: =IF(1>Simulador!$B$6,"",IFERROR(VALUE(TRIM(MID(SUBSTITUTE(Simulador!$B$7,"-",REPT(" ",20)),(1-1)*20+1,20))),"")) -> 1 | C30: =IF(2>Simulador!$B$6,"",IFERROR(VALUE(TRIM(MID(SUBSTITUTE(Simulador!$B$7,"-",REPT(" ",20)),(2-1)*20+1,20))),"")) -> 4 | D30: =IF(3>Simulador!$B$6,"",IFERROR(VALUE(TRIM(MID(SUBSTITUTE(Simulador!$B$7,"-",REPT(" ",20)),(3-1)*20+1,20))),"")) -> 3 | E30: =IF(4>Simulador!$B$6,"",IFERROR(VALUE(TRIM(MID(SUBSTITUTE(Simulador!$B$7,"-",REPT(" ",20)),(4-1)*20+1,20))),"")) -> 2 | F30: =IF(5>Simulador!$B$6,"",IFERROR(VALUE(TRIM(MID(SUBSTITUTE(Simulador!$B$7,"-",REPT(" ",20)),(5-1)*20+1,20))),"")) | G30: =IF(6>Simulador!$B$6,"",IFERROR(VALUE(TRIM(MID(SUBSTITUTE(Simulador!$B$7,"-",REPT(" ",20)),(6-1)*20+1,20))),"")) | H30: =IF(7>Simulador!$B$6,"",IFERROR(VALUE(TRIM(MID(SUBSTITUTE(Simulador!$B$7,"-",REPT(" ",20)),(7-1)*20+1,20))),"")) | I30: =IF(8>Simulador!$B$6,"",IFERROR(VALUE(TRIM(MID(SUBSTITUTE(Simulador!$B$7,"-",REPT(" ",20)),(8-1)*20+1,20))),"")) | J30: =IF(9>Simulador!$B$6,"",IFERROR(VALUE(TRIM(MID(SUBSTITUTE(Simulador!$B$7,"-",REPT(" ",20)),(9-1)*20+1,20))),"")) | K30: =IF(10>Simulador!$B$6,"",IFERROR(VALUE(TRIM(MID(SUBSTITUTE(Simulador!$B$7,"-",REPT(" ",20)),(10-1)*20+1,20))),"")) | L30: =IF(11>Simulador!$B$6,"",IFERROR(VALUE(TRIM(MID(SUBSTITUTE(Simulador!$B$7,"-",REPT(" ",20)),(11-1)*20+1,20))),"")) | M30: =IF(12>Simulador!$B$6,"",IFERROR(VALUE(TRIM(MID(SUBSTITUTE(Simulador!$B$7,"-",REPT(" ",20)),(12-1)*20+1,20))),""))

Sheet Datos gráficos
A1: Datos de los gráficos (no editar)
A2: Muñequilla x | B2: y | C2: Nombre | E2: Eje x | F2: Eje y | H2: Círculo x | I2: y | K2: Esquema x | L2: y | M2: Nombre | N2: Cigüeñal x | O2: y | Q2: θ (°) | R2: Cil. en expansión | T2: Encendidos ordenados | U2: Intervalo | V2: Texto | X2: Cigüeñal x | Y2: y | Z2: Nombre | AA2: Eje x | AB2: y | AC2: Posición axial
A3: 0 | B3: 0 | C3: =IF(Simulador!$A$22=""," ",""&1) -> 1 | E3: 0 | F3: 0 | H3: 0 | I3: 1 | K3: =IF(Simulador!$A$22="",$K$3,INDEX(Configuraciones!$J$3:$J$27,Simulador!$B$9)) -> 1 | L3: =IF(Simulador!$A$22="",$L$3,INDEX(Configuraciones!$K$3:$K$27,Simulador!$B$9)) -> 0 | M3: =IF(Simulador!$A$22=""," ",""&1) -> 1 | N3: =IF(ISNUMBER(SEARCH("Radial",INDEX(Configuraciones!$D$3:$D$27,Simulador!$B$9))),0,MIN(K3:K14)-0.5) -> 0.5 | O3: 0 | Q3: 0 | R3: ='Diagrama de fases'!C18 -> 1 | T3: =IF(1>Simulador!$B$12,"",SMALL(Simulador!$D$22:$D$33,1)) -> 0 | U3: =IF(T3="","",IF(1=Simulador!$B$12,720-T3+$T$3,T4-T3)) -> 180 | V3: =IF(U3="","",IF(MOD(U3,1)=0,TEXT(U3,"0"),TEXT(U3,"0.0"))&"°") -> 180° | W3: =V3 -> 180° | X3: =$AC$3+(-0.17) -> 0.83 | Y3: 0 | Z3: =IF(Simulador!$A$22=""," ",1&" ("&TEXT(Simulador!$E$22,"0")&"°)") -> 1 (0°) | AA3: =MIN(AC3:AC14)-0.6 -> 0.4 | AB3: 0 | AC3: =IF(Simulador!$A$22="",$AC$3,IF(ISNUMBER(SEARCH("Radial",INDEX(Configuraciones!$D$3:$D$27,Simulador!$B$9))),1,K3)) -> 1
A4: =IF(Simulador!$F$22="",0,IF(Simulador!$B$22="B",0.75,1)*SIN(RADIANS(Simulador!$F$22))) -> 0 | B4: =IF(Simulador!$F$22="",0,IF(Simulador!$B$22="B",0.75,1)*COS(RADIANS(Simulador!$F$22))) -> 1 | E4: =IF(Simulador!$C$22="",0,1.4*SIN(RADIANS(Simulador!$C$22))) -> 0 | F4: =IF(Simulador!$C$22="",0,1.4*COS(RADIANS(Simulador!$C$22))) -> 1.4 | H4: 0.1736 | I4: 0.9848 | K4: =IF(Simulador!$A$23="",$K$3,INDEX(Configuraciones!$O$3:$O$27,Simulador!$B$9)) -> 2 | L4: =IF(Simulador!$A$23="",$L$3,INDEX(Configuraciones!$P$3:$P$27,Simulador!$B$9)) -> 0 | M4: =IF(Simulador!$A$23=""," ",""&2) -> 2 | N4: =IF(ISNUMBER(SEARCH("Radial",INDEX(Configuraciones!$D$3:$D$27,Simulador!$B$9))),0,MAX(K3:K14)+0.5) -> 4.5 | O4: 0 | Q4: 6 | R4: ='Diagrama de fases'!C18 -> 1 | T4: =IF(2>Simulador!$B$12,"",SMALL(Simulador!$D$22:$D$33,2)) -> 180 | U4: =IF(T4="","",IF(2=Simulador!$B$12,720-T4+$T$3,T5-T4)) -> 180 | V4: =IF(U4="","",IF(MOD(U4,1)=0,TEXT(U4,"0"),TEXT(U4,"0.0"))&"°") -> 180° | W4: =IF(V4="",W3,W3&", "&V4) -> 180°, 180° | X4: =$AC$3+(-0.17) -> 0.83 | Y4: =IF(Simulador!$E$22="",0,(COS(RADIANS(Simulador!$E$22-Simulador!$E$22))+0.4*SIN(RADIANS(Simulador!$E$22-Simulador!$E$22)))/1.077) -> 0.92850511 | AA4: =MAX(AC3:AC14)+0.6 -> 4.6 | AB4: 0 | AC4: =IF(Simulador!$A$23="",$AC$3,IF(ISNUMBER(SEARCH("Radial",INDEX(Configuraciones!$D$3:$D$27,Simulador!$B$9))),1,K4)) -> 2
H5: 0.342 | I5: 0.9397 | K5: =IF(Simulador!$A$24="",$K$3,INDEX(Configuraciones!$T$3:$T$27,Simulador!$B$9)) -> 3 | L5: =IF(Simulador!$A$24="",$L$3,INDEX(Configuraciones!$U$3:$U$27,Simulador!$B$9)) -> 0 | M5: =IF(Simulador!$A$24=""," ",""&3) -> 3 | Q5: 6 | R5: ='Diagrama de fases'!D18 -> 1 | T5: =IF(3>Simulador!$B$12,"",SMALL(Simulador!$D$22:$D$33,3)) -> 360 | U5: =IF(T5="","",IF(3=Simulador!$B$12,720-T5+$T$3,T6-T5)) -> 180 | V5: =IF(U5="","",IF(MOD(U5,1)=0,TEXT(U5,"0"),TEXT(U5,"0.0"))&"°") -> 180° | W5: =IF(V5="",W4,W4&", "&V5) -> 180°, 180°, 180° | X5: =$AC$3+(0.17) -> 1.17 | Y5: =IF(Simulador!$E$22="",0,(COS(RADIANS(Simulador!$E$22-Simulador!$E$22))+0.4*SIN(RADIANS(Simulador!$E$22-Simulador!$E$22)))/1.077) -> 0.92850511 | AC5: =IF(Simulador!$A$24="",$AC$3,IF(ISNUMBER(SEARCH("Radial",INDEX(Configuraciones!$D$3:$D$27,Simulador!$B$9))),1,K5)) -> 3
A6: 0 | B6: 0 | C6: =IF(Simulador!$A$23=""," ",""&2) -> 2 | E6: 0 | F6: 0 | H6: 0.5 | I6: 0.866 | K6: =IF(Simulador!$A$25="",$K$3,INDEX(Configuraciones!$Y$3:$Y$27,Simulador!$B$9)) -> 4 | L6: =IF(Simulador!$A$25="",$L$3,INDEX(Configuraciones!$Z$3:$Z$27,Simulador!$B$9)) -> 0 | M6: =IF(Simulador!$A$25=""," ",""&4) -> 4 | Q6: 12 | R6: ='Diagrama de fases'!D18 -> 1 | T6: =IF(4>Simulador!$B$12,"",SMALL(Simulador!$D$22:$D$33,4)) -> 540 | U6: =IF(T6="","",IF(4=Simulador!$B$12,720-T6+$T$3,T7-T6)) -> 180 | V6: =IF(U6="","",IF(MOD(U6,1)=0,TEXT(U6,"0"),TEXT(U6,"0.0"))&"°") -> 180° | W6: =IF(V6="",W5,W5&", "&V6) -> 180°, 180°, 180°, 180° | X6: =$AC$3+(0.17) -> 1.17 | Y6: 0 | AC6: =IF(Simulador!$A$25="",$AC$3,IF(ISNUMBER(SEARCH("Radial",INDEX(Configuraciones!$D$3:$D$27,Simulador!$B$9))),1,K6)) -> 4
A7: =IF(Simulador!$F$23="",0,IF(Simulador!$B$23="B",0.75,1)*SIN(RADIANS(Simulador!$F$23))) -> 1.2251485e-16 | B7: =IF(Simulador!$F$23="",0,IF(Simulador!$B$23="B",0.75,1)*COS(RADIANS(Simulador!$F$23))) -> -1 | E7: =IF(Simulador!$C$23="",0,1.4*SIN(RADIANS(Simulador!$C$23))) -> 0 | F7: =IF(Simulador!$C$23="",0,1.4*COS(RADIANS(Simulador!$C$23))) -> 1.4 | H7: 0.6428 | I7: 0.766 | K7: =IF(Simulador!$A$26="",$K$3,INDEX(Configuraciones!$AD$3:$AD$27,Simulador!$B$9)) -> 1 | L7: =IF(Simulador!$A$26="",$L$3,INDEX(Configuraciones!$AE$3:$AE$27,Simulador!$B$9)) -> 0 | M7: =IF(Simulador!$A$26=""," ",""&5) | Q7: 12 | R7: ='Diagrama de fases'!E18 -> 1 | T7: =IF(5>Simulador!$B$12,"",SMALL(Simulador!$D$22:$D$33,5)) | U7: =IF(T7="","",IF(5=Simulador!$B$12,720-T7+$T$3,T8-T7)) | V7: =IF(U7="","",IF(MOD(U7,1)=0,TEXT(U7,"0"),TEXT(U7,"0.0"))&"°") | W7: =IF(V7="",W6,W6&", "&V7) -> 180°, 180°, 180°, 180° | AC7: =IF(Simulador!$A$26="",$AC$3,IF(ISNUMBER(SEARCH("Radial",INDEX(Configuraciones!$D$3:$D$27,Simulador!$B$9))),1,K7)) -> 1
H8: 0.766 | I8: 0.6428 | K8: =IF(Simulador!$A$27="",$K$3,INDEX(Configuraciones!$AI$3:$AI$27,Simulador!$B$9)) -> 1 | L8: =IF(Simulador!$A$27="",$L$3,INDEX(Configuraciones!$AJ$3:$AJ$27,Simulador!$B$9)) -> 0 | M8: =IF(Simulador!$A$27=""," ",""&6) | Q8: 18 | R8: ='Diagrama de fases'!E18 -> 1 | T8: =IF(6>Simulador!$B$12,"",SMALL(Simulador!$D$22:$D$33,6)) | U8: =IF(T8="","",IF(6=Simulador!$B$12,720-T8+$T$3,T9-T8)) | V8: =IF(U8="","",IF(MOD(U8,1)=0,TEXT(U8,"0"),TEXT(U8,"0.0"))&"°") | W8: =IF(V8="",W7,W7&", "&V8) -> 180°, 180°, 180°, 180° | X8: =$AC$4+(-0.17) -> 1.83 | Y8: 0 | Z8: =IF(Simulador!$A$23=""," ",2&" ("&TEXT(Simulador!$E$23,"0")&"°)") -> 2 (180°) | AC8: =IF(Simulador!$A$27="",$AC$3,IF(ISNUMBER(SEARCH("Radial",INDEX(Configuraciones!$D$3:$D$27,Simulador!$B$9))),1,K8)) -> 1
A9: 0 | B9: 0 | C9: =IF(Simulador!$A$24=""," ",""&3) -> 3 | E9: 0 | F9: 0 | H9: 0.866 | I9: 0.5 | K9: =IF(Simulador!$A$28="",$K$3,INDEX(Configuraciones!$AN$3:$AN$27,Simulador!$B$9)) -> 1 | L9: =IF(Simulador!$A$28="",$L$3,INDEX(Configuraciones!$AO$3:$AO$27,Simulador!$B$9)) -> 0 | M9: =IF(Simulador!$A$28=""," ",""&7) | Q9: 18 | R9: ='Diagrama de fases'!F18 -> 1 | T9: =IF(7>Simulador!$B$12,"",SMALL(Simulador!$D$22:$D$33,7)) | U9: =IF(T9="","",IF(7=Simulador!$B$12,720-T9+$T$3,T10-T9)) | V9: =IF(U9="","",IF(MOD(U9,1)=0,TEXT(U9,"0"),TEXT(U9,"0.0"))&"°") | W9: =IF(V9="",W8,W8&", "&V9) -> 180°, 180°, 180°, 180° | X9: =$AC$4+(-0.17) -> 1.83 | Y9: =IF(Simulador!$E$23="",0,(COS(RADIANS(Simulador!$E$23-Simulador!$E$22))+0.4*SIN(RADIANS(Simulador!$E$23-Simulador!$E$22)))/1.077) -> -0.92850511 | AC9: =IF(Simulador!$A$28="",$AC$3,IF(ISNUMBER(SEARCH("Radial",INDEX(Configuraciones!$D$3:$D$27,Simulador!$B$9))),1,K9)) -> 1
A10: =IF(Simulador!$F$24="",0,IF(Simulador!$B$24="B",0.75,1)*SIN(RADIANS(Simulador!$F$24))) -> 0 | B10: =IF(Simulador!$F$24="",0,IF(Simulador!$B$24="B",0.75,1)*COS(RADIANS(Simulador!$F$24))) -> 1 | E10: =IF(Simulador!$C$24="",0,1.4*SIN(RADIANS(Simulador!$C$24))) -> 0 | F10: =IF(Simulador!$C$24="",0,1.4*COS(RADIANS(Simulador!$C$24))) -> 1.4 | H10: 0.9397 | I10: 0.342 | K10: =IF(Simulador!$A$29="",$K$3,INDEX(Configuraciones!$AS$3:$AS$27,Simulador!$B$9)) -> 1 | L10: =IF(Simulador!$A$29="",$L$3,INDEX(Configuraciones!$AT$3:$AT$27,Simulador!$B$9)) -> 0 | M10: =IF(Simulador!$A$29=""," ",""&8) | Q10: 24 | R10: ='Diagrama de fases'!F18 -> 1 | T10: =IF(8>Simulador!$B$12,"",SMALL(Simulador!$D$22:$D$33,8)) | U10: =IF(T10="","",IF(8=Simulador!$B$12,720-T10+$T$3,T11-T10)) | V10: =IF(U10="","",IF(MOD(U10,1)=0,TEXT(U10,"0"),TEXT(U10,"0.0"))&"°") | W10: =IF(V10="",W9,W9&", "&V10) -> 180°, 180°, 180°, 180° | X10: =$AC$4+(0.17) -> 2.17 | Y10: =IF(Simulador!$E$23="",0,(COS(RADIANS(Simulador!$E$23-Simulador!$E$22))+0.4*SIN(RADIANS(Simulador!$E$23-Simulador!$E$22)))/1.077) -> -0.92850511 | AC10: =IF(Simulador!$A$29="",$AC$3,IF(ISNUMBER(SEARCH("Radial",INDEX(Configuraciones!$D$3:$D$27,Simulador!$B$9))),1,K10)) -> 1
H11: 0.9848 | I11: 0.1736 | K11: =IF(Simulador!$A$30="",$K$3,INDEX(Configuraciones!$AX$3:$AX$27,Simulador!$B$9)) -> 1 | L11: =IF(Simulador!$A$30="",$L$3,INDEX(Configuraciones!$AY$3:$AY$27,Simulador!$B$9)) -> 0 | M11: =IF(Simulador!$A$30=""," ",""&9) | Q11: 24 | R11: ='Diagrama de fases'!G18 -> 1 | T11: =IF(9>Simulador!$B$12,"",SMALL(Simulador!$D$22:$D$33,9)) | U11: =IF(T11="","",IF(9=Simulador!$B$12,720-T11+$T$3,T12-T11)) | V11: =IF(U11="","",IF(MOD(U11,1)=0,TEXT(U11,"0"),TEXT(U11,"0.0"))&"°") | W11: =IF(V11="",W10,W10&", "&V11) -> 180°, 180°, 180°, 180° | X11: =$AC$4+(0.17) -> 2.17 | Y11: 0 | AC11: =IF(Simulador!$A$30="",$AC$3,IF(ISNUMBER(SEARCH("Radial",INDEX(Configuraciones!$D$3:$D$27,Simulador!$B$9))),1,K11)) -> 1
A12: 0 | B12: 0 | C12: =IF(Simulador!$A$25=""," ",""&4) -> 4 | E12: 0 | F12: 0 | H12: 1 | I12: 0 | K12: =IF(Simulador!$A$31="",$K$3,INDEX(Configuraciones!$BC$3:$BC$27,Simulador!$B$9)) -> 1 | L12: =IF(Simulador!$A$31="",$L$3,INDEX(Configuraciones!$BD$3:$BD$27,Simulador!$B$9)) -> 0 | M12: =IF(Simulador!$A$31=""," ",""&10) | Q12: 30 | R12: ='Diagrama de fases'!G18 -> 1 | T12: =IF(10>Simulador!$B$12,"",SMALL(Simulador!$D$22:$D$33,10)) | U12: =IF(T12="","",IF(10=Simulador!$B$12,720-T12+$T$3,T13-T12)) | V12: =IF(U12="","",IF(MOD(U12,1)=0,TEXT(U12,"0"),TEXT(U12,"0.0"))&"°") | W12: =IF(V12="",W11,W11&", "&V12) -> 180°, 180°, 180°, 180° | AC12: =IF(Simulador!$A$31="",$AC$3,IF(ISNUMBER(SEARCH("Radial",INDEX(Configuraciones!$D$3:$D$27,Simulador!$B$9))),1,K12)) -> 1
A13: =IF(Simulador!$F$25="",0,IF(Simulador!$B$25="B",0.75,1)*SIN(RADIANS(Simulador!$F$25))) -> 1.2251485e-16 | B13: =IF(Simulador!$F$25="",0,IF(Simulador!$B$25="B",0.75,1)*COS(RADIANS(Simulador!$F$25))) -> -1 | E13: =IF(Simulador!$C$25="",0,1.4*SIN(RADIANS(Simulador!$C$25))) -> 0 | F13: =IF(Simulador!$C$25="",0,1.4*COS(RADIANS(Simulador!$C$25))) -> 1.4 | H13: 0.9848 | I13: -0.1736 | K13: =IF(Simulador!$A$32="",$K$3,INDEX(Configuraciones!$BH$3:$BH$27,Simulador!$B$9)) -> 1 | L13: =IF(Simulador!$A$32="",$L$3,INDEX(Configuraciones!$BI$3:$BI$27,Simulador!$B$9)) -> 0 | M13: =IF(Simulador!$A$32=""," ",""&11) | Q13: 30 | R13: ='Diagrama de fases'!H18 -> 1 | T13: =IF(11>Simulador!$B$12,"",SMALL(Simulador!$D$22:$D$33,11)) | U13: =IF(T13="","",IF(11=Simulador!$B$12,720-T13+$T$3,T14-T13)) | V13: =IF(U13="","",IF(MOD(U13,1)=0,TEXT(U13,"0"),TEXT(U13,"0.0"))&"°") | W13: =IF(V13="",W12,W12&", "&V13) -> 180°, 180°, 180°, 180° | X13: =$AC$5+(-0.17) -> 2.83 | Y13: 0 | Z13: =IF(Simulador!$A$24=""," ",3&" ("&TEXT(Simulador!$E$24,"0")&"°)") -> 3 (0°) | AC13: =IF(Simulador!$A$32="",$AC$3,IF(ISNUMBER(SEARCH("Radial",INDEX(Configuraciones!$D$3:$D$27,Simulador!$B$9))),1,K13)) -> 1
H14: 0.9397 | I14: -0.342 | K14: =IF(Simulador!$A$33="",$K$3,INDEX(Configuraciones!$BM$3:$BM$27,Simulador!$B$9)) -> 1 | L14: =IF(Simulador!$A$33="",$L$3,INDEX(Configuraciones!$BN$3:$BN$27,Simulador!$B$9)) -> 0 | M14: =IF(Simulador!$A$33=""," ",""&12) | Q14: 36 | R14: ='Diagrama de fases'!H18 -> 1 | T14: =IF(12>Simulador!$B$12,"",SMALL(Simulador!$D$22:$D$33,12)) | U14: =IF(T14="","",IF(12=Simulador!$B$12,720-T14+$T$3,T15-T14)) | V14: =IF(U14="","",IF(MOD(U14,1)=0,TEXT(U14,"0"),TEXT(U14,"0.0"))&"°") | W14: =IF(V14="",W13,W13&", "&V14) -> 180°, 180°, 180°, 180° | X14: =$AC$5+(-0.17) -> 2.83 | Y14: =IF(Simulador!$E$24="",0,(COS(RADIANS(Simulador!$E$24-Simulador!$E$22))+0.4*SIN(RADIANS(Simulador!$E$24-Simulador!$E$22)))/1.077) -> 0.92850511 | AC14: =IF(Simulador!$A$33="",$AC$3,IF(ISNUMBER(SEARCH("Radial",INDEX(Configuraciones!$D$3:$D$27,Simulador!$B$9))),1,K14)) -> 1
A15: 0 | B15: 0 | C15: =IF(Simulador!$A$26=""," ",""&5) | E15: 0 | F15: 0 | H15: 0.866 | I15: -0.5 | Q15: 36 | R15: ='Diagrama de fases'!I18 -> 1 | X15: =$AC$5+(0.17) -> 3.17 | Y15: =IF(Simulador!$E$24="",0,(COS(RADIANS(Simulador!$E$24-Simulador!$E$22))+0.4*SIN(RADIANS(Simulador!$E$24-Simulador!$E$22)))/1.077) -> 0.92850511
A16: =IF(Simulador!$F$26="",0,IF(Simulador!$B$26="B",0.75,1)*SIN(RADIANS(Simulador!$F$26))) -> 0 | B16: =IF(Simulador!$F$26="",0,IF(Simulador!$B$26="B",0.75,1)*COS(RADIANS(Simulador!$F$26))) -> 0 | E16: =IF(Simulador!$C$26="",0,1.4*SIN(RADIANS(Simulador!$C$26))) -> 0 | F16: =IF(Simulador!$C$26="",0,1.4*COS(RADIANS(Simulador!$C$26))) -> 0 | H16: 0.766 | I16: -0.6428 | Q16: 42 | R16: ='Diagrama de fases'!I18 -> 1 | X16: =$AC$5+(0.17) -> 3.17 | Y16: 0
H17: 0.6428 | I17: -0.766 | Q17: 42 | R17: ='Diagrama de fases'!J18 -> 1
A18: 0 | B18: 0 | C18: =IF(Simulador!$A$27=""," ",""&6) | E18: 0 | F18: 0 | H18: 0.5 | I18: -0.866 | Q18: 48 | R18: ='Diagrama de fases'!J18 -> 1 | X18: =$AC$6+(-0.17) -> 3.83 | Y18: 0 | Z18: =IF(Simulador!$A$25=""," ",4&" ("&TEXT(Simulador!$E$25,"0")&"°)") -> 4 (180°)
A19: =IF(Simulador!$F$27="",0,IF(Simulador!$B$27="B",0.75,1)*SIN(RADIANS(Simulador!$F$27))) -> 0 | B19: =IF(Simulador!$F$27="",0,IF(Simulador!$B$27="B",0.75,1)*COS(RADIANS(Simulador!$F$27))) -> 0 | E19: =IF(Simulador!$C$27="",0,1.4*SIN(RADIANS(Simulador!$C$27))) -> 0 | F19: =IF(Simulador!$C$27="",0,1.4*COS(RADIANS(Simulador!$C$27))) -> 0 | H19: 0.342 | I19: -0.9397 | Q19: 48 | R19: ='Diagrama de fases'!K18 -> 1 | X19: =$AC$6+(-0.17) -> 3.83 | Y19: =IF(Simulador!$E$25="",0,(COS(RADIANS(Simulador!$E$25-Simulador!$E$22))+0.4*SIN(RADIANS(Simulador!$E$25-Simulador!$E$22)))/1.077) -> -0.92850511
H20: 0.1736 | I20: -0.9848 | Q20: 54 | R20: ='Diagrama de fases'!K18 -> 1 | X20: =$AC$6+(0.17) -> 4.17 | Y20: =IF(Simulador!$E$25="",0,(COS(RADIANS(Simulador!$E$25-Simulador!$E$22))+0.4*SIN(RADIANS(Simulador!$E$25-Simulador!$E$22)))/1.077) -> -0.92850511
A21: 0 | B21: 0 | C21: =IF(Simulador!$A$28=""," ",""&7) | E21: 0 | F21: 0 | H21: 0 | I21: -1 | Q21: 54 | R21: ='Diagrama de fases'!L18 -> 1 | X21: =$AC$6+(0.17) -> 4.17 | Y21: 0
A22: =IF(Simulador!$F$28="",0,IF(Simulador!$B$28="B",0.75,1)*SIN(RADIANS(Simulador!$F$28))) -> 0 | B22: =IF(Simulador!$F$28="",0,IF(Simulador!$B$28="B",0.75,1)*COS(RADIANS(Simulador!$F$28))) -> 0 | E22: =IF(Simulador!$C$28="",0,1.4*SIN(RADIANS(Simulador!$C$28))) -> 0 | F22: =IF(Simulador!$C$28="",0,1.4*COS(RADIANS(Simulador!$C$28))) -> 0 | H22: -0.1736 | I22: -0.9848 | Q22: 60 | R22: ='Diagrama de fases'!L18 -> 1
H23: -0.342 | I23: -0.9397 | Q23: 60 | R23: ='Diagrama de fases'!M18 -> 1 | X23: =$AC$7+(-0.17) -> 0.83 | Y23: 0 | Z23: =IF(Simulador!$A$26=""," ",5&" ("&TEXT(Simulador!$E$26,"0")&"°)")
A24: 0 | B24: 0 | C24: =IF(Simulador!$A$29=""," ",""&8) | E24: 0 | F24: 0 | H24: -0.5 | I24: -0.866 | Q24: 66 | R24: ='Diagrama de fases'!M18 -> 1 | X24: =$AC$7+(-0.17) -> 0.83 | Y24: =IF(Simulador!$E$26="",0,(COS(RADIANS(Simulador!$E$26-Simulador!$E$22))+0.4*SIN(RADIANS(Simulador!$E$26-Simulador!$E$22)))/1.077) -> 0
