Workbook

Sheet Biela-manivela
A1: Simulador 1 · Cinemática del mecanismo biela-manivela
A2: Sistemas del Funcionamiento del Motor (MA.02.06) · Unidad 1 · Edite solo las celdas amarillas (texto azul); todo lo demás se recalcula.
A4: Datos de entrada | B4: Valor
A5: Carrera S (mm) | B5: 70
A6: Longitud de la biela L (entre centros, mm) | B6: 130
A7: Régimen de giro n (rpm) | B7: 4000
A9: Resultados | B9: Valor | C9: Cómo se obtiene
A10: Radio de la manivela r (mm) | B10: =B5/2 -> 35 | C10: r = S / 2
A11: Relación biela-manivela λ = r / L | B11: =B10/B6 -> 0.26923077 | C11: Valores típicos 0,25 – 0,35
A12: Velocidad angular ω (rad/s) | B12: =2*PI()*B7/60 -> 418.87902 | C12: ω = 2π·n / 60
A13: Velocidad media del pistón (m/s) | B13: =2*B5*B7/60/1000 -> 9.3333333 | C13: vm = 2·S·n / 60
A14: Velocidad máxima del pistón (m/s) | B14: =MAX(Datos!C3:C75) -> 15.183156 | C14: Máximo de la tabla de la hoja Datos
A15: Ángulo de velocidad máxima (° después del PMS) | B15: =INDEX(Datos!A3:A75,MATCH(B14,Datos!C3:C75,0)) -> 75 | C15: Cerca de 75°, no a 90°: efecto de la oblicuidad de la biela
A16: Aceleración en el PMS (m/s²) | B16: =B10/1000*B12^2*(1+B11) -> 7794.4568 | C16: a = r·ω²·(1 + λ): la mayor del ciclo
A17: Aceleración en el PMI (m/s²) | B17: =B10/1000*B12^2*(1-B11) -> 4487.7176 | C17: a = r·ω²·(1 − λ)
A18: Aceleración en el PMS en número de gravedades (g) | B18: =B16/9.81 -> 794.54198 | C18: Fuerza de inercia por cada kg de pistón
A20: Modelo: x = r(1 − cos θ) + L(1 − √(1 − λ²·sen²θ)); v = dx/dt; a ≈ r·ω²(cos θ + λ·cos 2θ). θ = ángulo del cigüeñal desde el PMS.

Sheet Cilindrada y Rc
A1: Simulador 2 · Cilindrada, relación de compresión y modificación del motor
A2: Sistemas del Funcionamiento del Motor (MA.02.06) · Unidad 1 · Edite solo las celdas amarillas (texto azul); todo lo demás se recalcula.
A4: Datos de entrada | B4: Valor
A5: Diámetro del cilindro D (mm) | B5: 76
A6: Carrera S (mm) | B6: 70
A7: Número de cilindros z | B7: 4
A8: Volumen de la cámara en la culata (cm³) | B8: 28
A9: Espesor comprimido de la junta (mm) | B9: 1.2
A10: Diámetro interior de la junta (mm) | B10: 78
A11: Volumen del rebaje o cúpula del pistón (cm³) | B11: 3
A12: Distancia del pistón al plano en el PMS (mm) | B12: 0.3
A13: Cepillado de la culata (mm) | B13: 0
A14: Sobremedida del rectificado del cilindro (mm) | B14: 0
A16: Resultados | B16: Original | C16: Modificado (cepillado + sobremedida)
A17: Área del pistón Ap (cm²) | B17: =PI()/4*(B5/10)^2 -> 45.364598 | C17: =PI()/4*((B5+B14)/10)^2 -> 45.364598
A18: Cilindrada unitaria Vu (cm³) | B18: =B17*B6/10 -> 317.55219 | C18: =C17*B6/10 -> 317.55219
A19: Volumen de la junta (cm³) | B19: =PI()/4*(B10/10)^2*B9/10 -> 5.7340349 | C19: =B19 -> 5.7340349
A20: Volumen sobre el pistón en el PMS (cm³) | B20: =B17*B12/10 -> 1.3609379 | C20: =C17*B12/10 -> 1.3609379
A21: Volumen de la cámara en la culata (cm³) | B21: =B8 -> 28 | C21: =B8-B17*B13/10 -> 28
A22: Volumen total de la cámara Vcc (cm³) | B22: =B21+B19+B11+B20 -> 38.094973 | C22: =C21+C19+B11+C20 -> 38.094973 | E22: El gráfico parte del motor con la sobremedida indicada y muestra cómo sube Rc al retirar material de la culata.
A23: Relación de compresión Rc | B23: =(B18+B22)/B22 -> 9.3358029 | C23: =(C18+C22)/C22 -> 9.3358029
A24: Cilindrada total VT (cm³) | B24: =B18*B7 -> 1270.2087 | C24: =C18*B7 -> 1270.2087
A25: Cilindrada comercial (L) | B25: =ROUND(B24/1000,1) -> 1.3 | C25: =ROUND(C24/1000,1) -> 1.3
A27: =IF(C23>11,"Atención: Rc modificada mayor a 11 — riesgo de detonación con gasolina de bajo octanaje","Rc modificada dentro de un rango habitual para gasolina") -> Rc modificada dentro de un rango habitual para gasolina
A28: Simplificación: el cepillado reduce el volumen de la cámara en el área del cilindro × espesor retirado (en la realidad el área es la de la cámara).

Sheet Curvas par-potencia
A1: Simulador 3 · Curvas características: par, potencia, consumo y corrección por altitud
A2: Sistemas del Funcionamiento del Motor (MA.02.06) · Unidad 1 · Edite solo las celdas amarillas (texto azul); todo lo demás se recalcula.
A4: Régimen n (rpm) | B4: Par M (N·m) | C4: Consumo esp. (g/kWh) | D4: Potencia (kW) | E4: Potencia (CV) | F4: Potencia en la altitud (kW) | H4: Condiciones del lugar | I4: Valor
A5: 1000 | B5: 105 | C5: 330 | D5: =B5*A5/9550 -> 10.994764 | E5: =D5/0.7355 -> 14.948694 | F5: =D5*$I$12 -> 8.5507856 | H5: Altitud sobre el nivel del mar (m) | I5: 2100
A6: 1500 | B6: 118 | C6: 300 | D6: =B6*A6/9550 -> 18.534031 | E6: =D6/0.7355 -> 25.199227 | F6: =D6*$I$12 -> 14.414181 | H6: Temperatura del aire (°C) | I6: 18
A7: 2000 | B7: 128 | C7: 280 | D7: =B7*A7/9550 -> 26.806283 | E7: =D7/0.7355 -> 36.44634 | F7: =D7*$I$12 -> 20.84763
A8: 2500 | B8: 136 | C8: 265 | D8: =B8*A8/9550 -> 35.602094 | E8: =D8/0.7355 -> 48.405295 | F8: =D8*$I$12 -> 27.688258 | H8: Resultados | I8: Valor | J8: Cómo se obtiene
A9: 3000 | B9: 142 | C9: 255 | D9: =B9*A9/9550 -> 44.60733 | E9: =D9/0.7355 -> 60.648987 | F9: =D9*$I$12 -> 34.691759 | H9: Par máximo (N·m) | I9: =MAX(B5:B16) -> 148 | J9: =" a "&INDEX(A5:A16,MATCH(I9,B5:B16,0))&" rpm" -> a 4000 rpm
A10: 3500 | B10: 146 | C10: 250 | D10: =B10*A10/9550 -> 53.507853 | E10: =D10/0.7355 -> 72.750311 | F10: =D10*$I$12 -> 41.613823 | H10: Potencia máxima (kW) | I10: =MAX(D5:D16) -> 76.649215 | J10: =" a "&INDEX(A5:A16,MATCH(I10,D5:D16,0))&" rpm · "&TEXT(I10/0.7355,"0")&" CV" -> a 6000 rpm · 104 CV
A11: 4000 | B11: 148 | C11: 248 | D11: =B11*A11/9550 -> 61.989529 | E11: =D11/0.7355 -> 84.28216 | F11: =D11*$I$12 -> 48.210143 | H11: Presión atmosférica en el lugar (kPa) | I11: =101.325*(1-0.0000225577*I5)^5.25588 -> 78.513117 | J11: Atmósfera estándar
A12: 4500 | B12: 146 | C12: 252 | D12: =B12*A12/9550 -> 68.795812 | E12: =D12/0.7355 -> 93.536114 | F12: =D12*$I$12 -> 53.503487 | H12: Factor de corrección (DIN 70020) | I12: =(I11/101.3)*SQRT(293/(I6+273)) -> 0.77771431 | J12: P_lugar = P_ref · (p/101,3) · √(293/T)
A13: 5000 | B13: 141 | C13: 260 | D13: =B13*A13/9550 -> 73.82199 | E13: =D13/0.7355 -> 100.3698 | F13: =D13*$I$12 -> 57.412417 | H13: Potencia máxima en el lugar (kW) | I13: =MAX(F5:F16) -> 59.611191
A14: 5500 | B14: 133 | C14: 272 | D14: =B14*A14/9550 -> 76.596859 | E14: =D14/0.7355 -> 104.14257 | F14: =D14*$I$12 -> 59.570473 | H14: Pérdida de potencia por altitud (%) | I14: =1-I12 -> 0.22228569
A15: 6000 | B15: 122 | C15: 290 | D15: =B15*A15/9550 -> 76.649215 | E15: =D15/0.7355 -> 104.21375 | F15: =D15*$I$12 -> 59.611191 | H15: Elasticidad de régimen n(Pmáx)/n(Mmáx) | I15: =INDEX(A5:A16,MATCH(I10,D5:D16,0))/INDEX(A5:A16,MATCH(I9,B5:B16,0)) -> 1.5
A16: 6500 | B16: 108 | C16: 315 | D16: =B16*A16/9550 -> 73.507853 | E16: =D16/0.7355 -> 99.942697 | F16: =D16*$I$12 -> 57.168109 | H16: Consumo específico mínimo (g/kWh) | I16: =MIN(C5:C16) -> 248

Sheet Pie de rey
A1: Simulador · Pie de rey o calibre con nonio (milímetros y pulgadas)
A2: Sistemas del Funcionamiento del Motor (MA.02.06) · Unidad 1 · Metrología · Edite solo las celdas amarillas (texto azul).
AS3: Parámetros de los instrumentos (no editar)
A4: Configuración | B4: Valor | AS4: Tipo | AT4: inch | AU4: m | AV4: n | AW4: k | AX4: ap | AY4: L | AZ4: M | BA4: S | BB4: lab | BC4: maxdiv | BD4: nlab | BE4: dec | BF4: labtype
A5: Instrumento y resolución (modo aleatorio) | B5: Pulgada · 1/128" (8 div.) | AS5: Milímetro · 0,1 mm (10 div.) | AT5: 0 | AU5: 1 | AV5: 10 | AW5: 1 | AX5: 0.1 | AY5: 10 | AZ5: 5 | BA5: 1 | BB5: 10 | BC5: 40 | BD5: 5 | BE5: 1 | BF5: 1
A6: Número de ejercicio (aleatorio: 1 – 999; guía: n.º de la tabla) | B6: 1 | AS6: Milímetro · 0,05 mm (20 div.) | AT6: 0 | AU6: 1 | AV6: 20 | AW6: 2 | AX6: 0.05 | AY6: 10 | AZ6: 5 | BA6: 1 | BB6: 10 | BC6: 40 | BD6: 4 | BE6: 2 | BF6: 1
A7: Ejercicio de la guía (elija el banco) | B7: Aleatorio (generado por el simulador) | AS7: Milímetro · 0,02 mm (50 div.) | AT7: 0 | AU7: 1 | AV7: 50 | AW7: 1 | AX7: 0.02 | AY7: 10 | AZ7: 5 | BA7: 1 | BB7: 10 | BC7: 40 | BD7: 10 | BE7: 2 | BF7: 1
A8: Respuesta del estudiante | B8: Valor | AS8: Pulgada · 0,001" (25 div.) | AT8: 1 | AU8: 0.025 | AV8: 25 | AW8: 1 | AX8: 0.001 | AY8: 40 | AZ8: 4 | BA8: 2 | BB8: 4 | BC8: 60 | BD8: 5 | BE8: 3 | BF8: 2
A9: Su lectura (en la unidad del instrumento) | AS9: Pulgada · 0,001" (50 div.) | AT9: 1 | AU9: 0.05 | AV9: 50 | AW9: 1 | AX9: 0.001 | AY9: 20 | AZ9: 2 | BA9: 1 | BB9: 2 | BC9: 40 | BD9: 10 | BE9: 3 | BF9: 3
A10: ¿Mostrar el solucionario? (SI / NO) | B10: SI | AS10: Pulgada · 1/128" (8 div.) | AT10: 1 | AU10: 0.0625 | AV10: 8 | AW10: 1 | AX10: 0.0078125 | AY10: 16 | AZ10: 8 | BA10: 4 | BB10: 16 | BC10: 60 | BD10: 4 | BE10: 4 | BF10: 4
A12: =IF($B$62=0,"Ese número no está en el banco elegido: use del "&$B$64&" al "&($B$64+19),IF(B9="","Escriba su lectura en la celda B9",IF(ABS(B9-$B$49)<$B$45/2,"¡Correcto! Lectura bien hecha","Revise la lectura: siga los pasos del solucionario"))) -> Escriba su lectura en la celda B9
A13: =IF($B$58=1,"Ejercicio "&$B$6&" · "&$B$7&" (mismo valor que el solucionario de la guía)","Ejercicio aleatorio n.º "&$B$6) -> Ejercicio aleatorio n.º 1
A14: Solucionario comentado
A15: =IF($B$10="SI","1. Regla fija","") -> 1. Regla fija | B15: =IF($B$10="SI","El cero del nonio pasó "&'Pie de rey'!$B$47&" divisiones de "&IF('Pie de rey'!$B$57=4,"1/16",FIXED('Pie de rey'!$B$42,IF('Pie de rey'!$B$41=1,3,0),TRUE))&IF('Pie de rey'!$B$41=1," pulg"," mm")&" → "&IF('Pie de rey'!$B$57=4,'Pie de rey'!$B$47&"/16 = "&IF(('Pie de rey'!$B$47*8)=0,"0",IF(INT(('Pie de rey'!$B$47*8)/128)>0,INT(('Pie de rey'!$B$47*8)/128)&" ","")&IF(MOD(('Pie de rey'!$B$47*8),128)=0,"",MOD(('Pie de rey'!$B$47*8),128)/GCD(MOD(('Pie de rey'!$B$47*8),128),128)&"/"&128/GCD(MOD(('Pie de rey'!$B$47*8),128),128))),FIXED('Pie de rey'!$B$47*'Pie de rey'!$B$42,'Pie de rey'!$B$51,TRUE))&IF('Pie de rey'!$B$41=1," pulg"," mm"),"") -> El cero del nonio pasó 11 divisiones de 1/16 pulg → 11/16 = 11/16 pulg
A16: =IF($B$10="SI","2. Nonio","") -> 2. Nonio | B16: =IF($B$10="SI","Coincide la raya "&'Pie de rey'!$B$48&" del nonio con una raya de la regla → "&'Pie de rey'!$B$48&" × "&IF('Pie de rey'!$B$57=4,"1/128",FIXED('Pie de rey'!$B$45,'Pie de rey'!$B$51,TRUE))&" = "&IF('Pie de rey'!$B$57=4,IF(('Pie de rey'!$B$48)=0,"0",IF(INT(('Pie de rey'!$B$48)/128)>0,INT(('Pie de rey'!$B$48)/128)&" ","")&IF(MOD(('Pie de rey'!$B$48),128)=0,"",MOD(('Pie de rey'!$B$48),128)/GCD(MOD(('Pie de rey'!$B$48),128),128)&"/"&128/GCD(MOD(('Pie de rey'!$B$48),128),128))),FIXED('Pie de rey'!$B$48*'Pie de rey'!$B$45,'Pie de rey'!$B$51,TRUE))&IF('Pie de rey'!$B$41=1," pulg"," mm"),"") -> Coincide la raya 6 del nonio con una raya de la regla → 6 × 1/128 = 3/64 pulg
A17: =IF($B$10="SI","3. Lectura","") -> 3. Lectura | B17: =IF($B$10="SI",IF('Pie de rey'!$B$57=4,IF(('Pie de rey'!$B$47*8)=0,"0",IF(INT(('Pie de rey'!$B$47*8)/128)>0,INT(('Pie de rey'!$B$47*8)/128)&" ","")&IF(MOD(('Pie de rey'!$B$47*8),128)=0,"",MOD(('Pie de rey'!$B$47*8),128)/GCD(MOD(('Pie de rey'!$B$47*8),128),128)&"/"&128/GCD(MOD(('Pie de rey'!$B$47*8),128),128)))&" + "&IF(('Pie de rey'!$B$48)=0,"0",IF(INT(('Pie de rey'!$B$48)/128)>0,INT(('Pie de rey'!$B$48)/128)&" ","")&IF(MOD(('Pie de rey'!$B$48),128)=0,"",MOD(('Pie de rey'!$B$48),128)/GCD(MOD(('Pie de rey'!$B$48),128),128)&"/"&128/GCD(MOD(('Pie de rey'!$B$48),128),128)))&" = "&IF(('Pie de rey'!$B$47*8+'Pie de rey'!$B$48)=0,"0",IF(INT(('Pie de rey'!$B$47*8+'Pie de rey'!$B$48)/128)>0,INT(('Pie de rey'!$B$47*8+'Pie de rey'!$B$48)/128)&" ","")&IF(MOD(('Pie de rey'!$B$47*8+'Pie de rey'!$B$48),128)=0,"",MOD(('Pie de rey'!$B$47*8+'Pie de rey'!$B$48),128)/GCD(MOD(('Pie de rey'!$B$47*8+'Pie de rey'!$B$48),128),128)&"/"&128/GCD(MOD(('Pie de rey'!$B$47*8+'Pie de rey'!$B$48),128),128)))&IF('Pie de rey'!$B$41=1," pulg"," mm")&" (= "&FIXED('Pie de rey'!$B$49,4,TRUE)&" pulg en decimal)",FIXED('Pie de rey'!$B$47*'Pie de rey'!$B$42,'Pie de rey'!$B$51,TRUE)&" + "&FIXED('Pie de rey'!$B$48*'Pie de rey'!$B$45,'Pie de rey'!$B$51,TRUE)&" = "&FIXED('Pie de rey'!$B$49,'Pie de rey'!$B$51,TRUE)&IF('Pie de rey'!$B$41=1," pulg"," mm")),"") -> 11/16 + 3/64 = 47/64 pulg (= 0.7344 pulg en decimal)
A18: =IF($B$10="SI","4. Interpretación","") -> 4. Interpretación | B18: =IF($B$10="SI","El cero del nonio pasó "&$B$47&IF($B$57=4," marcas de 1/16"""," marcas de la regla")&" y la raya "&$B$48&" del nonio está alineada con una raya de la regla. Lectura: "&IF($B$57=4,'Datos guía'!$F$1,FIXED($B$49,$B$51,TRUE)&IF($B$41=1," in"," mm")),"") -> El cero del nonio pasó 11 marcas de 1/16" y la raya 6 del nonio está alineada con una raya de la regla. Lectura: 47/64"
A20: Lista de práctica | B20: Valor
A21: Número de lista (aleatorio: 1 – 99; guía: 1 – 2) | B21: 1
A23: Ejercicio (escríbalo en B6) | B23: Su lectura | C23: Resultado | D23: Solución | BH23: Lectura (aux.) | BI23: Solución (aux.)
A24: =IF($B$58=1,$B$64+($B$21-1)*10+0,($B$21-1)*10+1) -> 1 | C24: =IF(B24="","",IF(BH24="","—",IF(ABS(B24-BH24)<$B$45/2,"Correcto","Incorrecto"))) | D24: =IF($B$10="SI",BI24,"") -> 47/64 pulg | BH24: =IF($B$58=1,IFERROR(INDEX('Datos guía'!$E$5:$E$544,MATCH($B$7&"|"&$A24,'Datos guía'!$A$5:$A$544,0)),""),INT(MOD($A24*7919+104729,INDEX($BC$5:$BC$10,MATCH($B$59,$AS$5:$AS$10,0))*INDEX($AV$5:$AV$10,MATCH($B$59,$AS$5:$AS$10,0))+1)/$B$43)*$B$42+MOD(MOD($A24*7919+104729,INDEX($BC$5:$BC$10,MATCH($B$59,$AS$5:$AS$10,0))*INDEX($AV$5:$AV$10,MATCH($B$59,$AS$5:$AS$10,0))+1),$B$43)*$B$45) -> 0.734375 | BI24: =IF($B$58=1,IFERROR(INDEX('Datos guía'!$F$5:$F$544,MATCH($B$7&"|"&$A24,'Datos guía'!$A$5:$A$544,0)),"No está en el banco"),IF($B$57=4,IF((ROUND((INT(MOD($A24*7919+104729,INDEX($BC$5:$BC$10,MATCH($B$59,$AS$5:$AS$10,0))*INDEX($AV$5:$AV$10,MATCH($B$59,$AS$5:$AS$10,0))+1)/$B$43)*$B$42+MOD(MOD($A24*7919+104729,INDEX($BC$5:$BC$10,MATCH($B$59,$AS$5:$AS$10,0))*INDEX($AV$5:$AV$10,MATCH($B$59,$AS$5:$AS$10,0))+1),$B$43)*$B$45)*128,0))=0,"0",IF(INT((ROUND((INT(MOD($A24*7919+104729,INDEX($BC$5:$BC$10,MATCH($B$59,$AS$5:$AS$10,0))*INDEX($AV$5:$AV$10,MATCH($B$59,$AS$5:$AS$10,0))+1)/$B$43)*$B$42+MOD(MOD($A24*7919+104729,INDEX($BC$5:$BC$10,MATCH($B$59,$AS$5:$AS$10,0))*INDEX($AV$5:$AV$10,MATCH($B$59,$AS$5:$AS$10,0))+1),$B$43)*$B$45)*128,0))/128)>0,INT((ROUND((INT(MOD($A24*7919+104729,INDEX($BC$5:$BC$10,MATCH($B$59,$AS$5:$AS$10,0))*INDEX($AV$5:$AV$10,MATCH($B$59,$AS$5:$AS$10,0))+1)/$B$43)*$B$42+MOD(MOD($A24*7919+104729,INDEX($BC$5:$BC$10,MATCH($B$59,$AS$5:$AS$10,0))*INDEX($AV$5:$AV$10,MATCH($B$59,$AS$5:$AS$10,0))+1),$B$43)*$B$45)*128,0))/128)&" ","")&IF(MOD((ROUND((INT(MOD($A24*7919+104729,INDEX($BC$5:$BC$10,MATCH($B$59,$AS$5:$AS$10,0))*INDEX($AV$5:$AV$10,MATCH($B$59,$AS$5:$AS$10,0))+1)/$B$43)*$B$42+MOD(MOD($A24*7919+104729,INDEX($BC$5:$BC$10,MATCH($B$59,$AS$5:$AS$10,0))*INDEX($AV$5:$AV$10,MATCH($B$59,$AS$5:$AS$10,0))+1),$B$43)*$B$45)*128,0)),128)=0,"",MOD((ROUND((INT(MOD($A24*7919+104729,INDEX($BC$5:$BC$10,MATCH($B$59,$AS$5:$AS$10,0))*INDEX($AV$5:$AV$10,MATCH($B$59,$AS$5:$AS$10,0))+1)/$B$43)*$B$42+MOD(MOD($A24*7919+104729,INDEX($BC$5:$BC$10,MATCH($B$59,$AS$5:$AS$10,0))*INDEX($AV$5:$AV$10,MATCH($B$59,$AS$5:$AS$10,0))+1),$B$43)*$B$45)*128,0)),128)/GCD(MOD((ROUND((INT(MOD($A24*7919+104729,INDEX($BC$5:$BC$10,MATCH($B$59,$AS$5:$AS$10,0))*INDEX($AV$5:$AV$10,MATCH($B$59,$AS$5:$AS$10,0))+1)/$B$43)*$B$42+MOD(MOD($A24*7919+104729,INDEX($BC$5:$BC$10,MATCH($B$59,$AS$5:$AS$10,0))*INDEX($AV$5:$AV$10,MATCH($B$59,$AS$5:$AS$10,0))+1),$B$43)*$B$45)*128,0)),128),128)&"/"&128/GCD(MOD((ROUND((INT(MOD($A24*7919+104729,INDEX($BC$5:$BC$10,MATCH($B$59,$AS$5:$AS$10,0))*INDEX($AV$5:$AV$10,MATCH($B$59,$AS$5:$AS$10,0))+1)/$B$43)*$B$42+MOD(MOD($A24*7919+104729,INDEX($BC$5:$BC$10,MATCH($B$59,$AS$5:$AS$10,0))*INDEX($AV$5:$AV$10,MATCH($B$59,$AS$5:$AS$10,0))+1),$B$43)*$B$45)*128,0)),128),128))),FIXED(INT(MOD($A24*7919+104729,INDEX($BC$5:$BC$10,MATCH($B$59,$AS$5:$AS$10,0))*INDEX($AV$5:$AV$10,MATCH($B$59,$AS$5:$AS$10,0))+1)/$B$43)*$B$42+MOD(MOD($A24*7919+104729,INDEX($BC$5:$BC$10,MATCH($B$59,$AS$5:$AS$10,0))*INDEX($AV$5:$AV$10,MATCH($B$59,$AS$5:$AS$10,0))+1),$B$43)*$B$45,$B$51,TRUE))&IF('Pie de rey'!$B$41=1," pulg"," mm")) -> 47/64 pulg
A25: =IF($B$58=1,$B$64+($B$21-1)*10+1,($B$21-1)*10+2) -> 2 | C25: =IF(B25="","",IF(BH25="","—",IF(ABS(B25-BH25)<$B$45/2,"Correcto","Incorrecto"))) | D25: =IF($B$10="SI",BI25,"") -> 2 61/128 pulg | BH25: =IF($B$58=1,IFERROR(INDEX('Datos guía'!$E$5:$E$544,MATCH($B$7&"|"&$A25,'Datos guía'!$A$5:$A$544,0)),""),INT(MOD($A25*7919+104729,INDEX($BC$5:$BC$10,MATCH($B$59,$AS$5:$AS$10,0))*INDEX($AV$5:$AV$10,MATCH($B$59,$AS$5:$AS$10,0))+1)/$B$43)*$B$42+MOD(MOD($A25*7919+104729,INDEX($BC$5:$BC$10,MATCH($B$59,$AS$5:$AS$10,0))*INDEX($AV$5:$AV$10,MATCH($B$59,$AS$5:$AS$10,0))+1),$B$43)*$B$45) -> 2.4765625 | BI25: =IF($B$58=1,IFERROR(INDEX('Datos guía'!$F$5:$F$544,MATCH($B$7&"|"&$A25,'Datos guía'!$A$5:$A$544,0)),"No está en el banco"),IF($B$57=4,IF((ROUND((INT(MOD($A25*7919+104729,INDEX($BC$5:$BC$10,MATCH($B$59,$AS$5:$AS$10,0))*INDEX($AV$5:$AV$10,MATCH($B$59,$AS$5:$AS$10,0))+1)/$B$43)*$B$42+MOD(MOD($A25*7919+104729,INDEX($BC$5:$BC$10,MATCH($B$59,$AS$5:$AS$10,0))*INDEX($AV$5:$AV$10,MATCH($B$59,$AS$5:$AS$10,0))+1),$B$43)*$B$45)*128,0))=0,"0",IF(INT((ROUND((INT(MOD($A25*7919+104729,INDEX($BC$5:$BC$10,MATCH($B$59,$AS$5:$AS$10,0))*INDEX($AV$5:$AV$10,MATCH($B$59,$AS$5:$AS$10,0))+1)/$B$43)*$B$42+MOD(MOD($A25*7919+104729,INDEX($BC$5:$BC$10,MATCH($B$59,$AS$5:$AS$10,0))*INDEX($AV$5:$AV$10,MATCH($B$59,$AS$5:$AS$10,0))+1),$B$43)*$B$45)*128,0))/128)>0,INT((ROUND((INT(MOD($A25*7919+104729,INDEX($BC$5:$BC$10,MATCH($B$59,$AS$5:$AS$10,0))*INDEX($AV$5:$AV$10,MATCH($B$59,$AS$5:$AS$10,0))+1)/$B$43)*$B$42+MOD(MOD($A25*7919+104729,INDEX($BC$5:$BC$10,MATCH($B$59,$AS$5:$AS$10,0))*INDEX($AV$5:$AV$10,MATCH($B$59,$AS$5:$AS$10,0))+1),$B$43)*$B$45)*128,0))/128)&" ","")&IF(MOD((ROUND((INT(MOD($A25*7919+104729,INDEX($BC$5:$BC$10,MATCH($B$59,$AS$5:$AS$10,0))*INDEX($AV$5:$AV$10,MATCH($B$59,$AS$5:$AS$10,0))+1)/$B$43)*$B$42+MOD(MOD($A25*7919+104729,INDEX($BC$5:$BC$10,MATCH($B$59,$AS$5:$AS$10,0))*INDEX($AV$5:$AV$10,MATCH($B$59,$AS$5:$AS$10,0))+1),$B$43)*$B$45)*128,0)),128)=0,"",MOD((ROUND((INT(MOD($A25*7919+104729,INDEX($BC$5:$BC$10,MATCH($B$59,$AS$5:$AS$10,0))*INDEX($AV$5:$AV$10,MATCH($B$59,$AS$5:$AS$10,0))+1)/$B$43)*$B$42+MOD(MOD($A25*7919+104729,INDEX($BC$5:$BC$10,MATCH($B$59,$AS$5:$AS$10,0))*INDEX($AV$5:$AV$10,MATCH($B$59,$AS$5:$AS$10,0))+1),$B$43)*$B$45)*128,0)),128)/GCD(MOD((ROUND((INT(MOD($A25*7919+104729,INDEX($BC$5:$BC$10,MATCH($B$59,$AS$5:$AS$10,0))*INDEX($AV$5:$AV$10,MATCH($B$59,$AS$5:$AS$10,0))+1)/$B$43)*$B$42+MOD(MOD($A25*7919+104729,INDEX($BC$5:$BC$10,MATCH($B$59,$AS$5:$AS$10,0))*INDEX($AV$5:$AV$10,MATCH($B$59,$AS$5:$AS$10,0))+1),$B$43)*$B$45)*128,0)),128),128)&"/"&128/GCD(MOD((ROUND((INT(MOD($A25*7919+104729,INDEX($BC$5:$BC$10,MATCH($B$59,$AS$5:$AS$10,0))*INDEX($AV$5:$AV$10,MATCH($B$59,$AS$5:$AS$10,0))+1)/$B$43)*$B$42+MOD(MOD($A25*7919+104729,INDEX($BC$5:$BC$10,MATCH($B$59,$AS$5:$AS$10,0))*INDEX($AV$5:$AV$10,MATCH($B$59,$AS$5:$AS$10,0))+1),$B$43)*$B$45)*128,0)),128),128))),FIXED(INT(MOD($A25*7919+104729,INDEX($BC$5:$BC$10,MATCH($B$59,$AS$5:$AS$10,0))*INDEX($AV$5:$AV$10,MATCH($B$59,$AS$5:$AS$10,0))+1)/$B$43)*$B$42+MOD(MOD($A25*7919+104729,INDEX($BC$5:$BC$10,MATCH($B$59,$AS$5:$AS$10,0))*INDEX($AV$5:$AV$10,MATCH($B$59,$AS$5:$AS$10,0))+1),$B$43)*$B$45,$B$51,TRUE))&IF('Pie de rey'!$B$41=1," pulg"," mm")) -> 2 61/128 pulg
A26: =IF($B$58=1,$B$64+($B$21-1)*10+2,($B$21-1)*10+3) -> 3 | C26: =IF(B26="","",IF(BH26="","—",IF(ABS(B26-BH26)<$B$45/2,"Correcto","Incorrecto"))) | D26: =IF($B$10="SI",BI26,"") -> 59/128 pulg | BH26: =IF($B$58=1,IFERROR(INDEX('Datos guía'!$E$5:$E$544,MATCH($B$7&"|"&$A26,'Datos guía'!$A$5:$A$544,0)),""),INT(MOD($A26*7919+104729,INDEX($BC$5:$BC$10,MATCH($B$59,$AS$5:$AS$10,0))*INDEX($AV$5:$AV$10,MATCH($B$59,$AS$5:$AS$10,0))+1)/$B$43)*$B$42+MOD(MOD($A26*7919+104729,INDEX($BC$5:$BC$10,MATCH($B$59,$AS$5:$AS$10,0))*INDEX($AV$5:$AV$10,MATCH($B$59,$AS$5:$AS$10,0))+1),$B$43)*$B$45) -> 0.4609375 | BI26: =IF($B$58=1,IFERROR(INDEX('Datos guía'!$F$5:$F$544,MATCH($B$7&"|"&$A26,'Datos guía'!$A$5:$A$544,0)),"No está en el banco"),IF($B$57=4,IF((ROUND((INT(MOD($A26*7919+104729,INDEX($BC$5:$BC$10,MATCH($B$59,$AS$5:$AS$10,0))*INDEX($AV$5:$AV$10,MATCH($B$59,$AS$5:$AS$10,0))+1)/$B$43)*$B$42+MOD(MOD($A26*7919+104729,INDEX($BC$5:$BC$10,MATCH($B$59,$AS$5:$AS$10,0))*INDEX($AV$5:$AV$10,MATCH($B$59,$AS$5:$AS$10,0))+1),$B$43)*$B$45)*128,0))=0,"0",IF(INT((ROUND((INT(MOD($A26*7919+104729,INDEX($BC$5:$BC$10,MATCH($B$59,$AS$5:$AS$10,0))*INDEX($AV$5:$AV$10,MATCH($B$59,$AS$5:$AS$10,0))+1)/$B$43)*$B$42+MOD(MOD($A26*7919+104729,INDEX($BC$5:$BC$10,MATCH($B$59,$AS$5:$AS$10,0))*INDEX($AV$5:$AV$10,MATCH($B$59,$AS$5:$AS$10,0))+1),$B$43)*$B$45)*128,0))/128)>0,INT((ROUND((INT(MOD($A26*7919+104729,INDEX($BC$5:$BC$10,MATCH($B$59,$AS$5:$AS$10,0))*INDEX($AV$5:$AV$10,MATCH($B$59,$AS$5:$AS$10,0))+1)/$B$43)*$B$42+MOD(MOD($A26*7919+104729,INDEX($BC$5:$BC$10,MATCH($B$59,$AS$5:$AS$10,0))*INDEX($AV$5:$AV$10,MATCH($B$59,$AS$5:$AS$10,0))+1),$B$43)*$B$45)*128,0))/128)&" ","")&IF(MOD((ROUND((INT(MOD($A26*7919+104729,INDEX($BC$5:$BC$10,MATCH($B$59,$AS$5:$AS$10,0))*INDEX($AV$5:$AV$10,MATCH($B$59,$AS$5:$AS$10,0))+1)/$B$43)*$B$42+MOD(MOD($A26*7919+104729,INDEX($BC$5:$BC$10,MATCH($B$59,$AS$5:$AS$10,0))*INDEX($AV$5:$AV$10,MATCH($B$59,$AS$5:$AS$10,0))+1),$B$43)*$B$45)*128,0)),128)=0,"",MOD((ROUND((INT(MOD($A26*7919+104729,INDEX($BC$5:$BC$10,MATCH($B$59,$AS$5:$AS$10,0))*INDEX($AV$5:$AV$10,MATCH($B$59,$AS$5:$AS$10,0))+1)/$B$43)*$B$42+MOD(MOD($A26*7919+104729,INDEX($BC$5:$BC$10,MATCH($B$59,$AS$5:$AS$10,0))*INDEX($AV$5:$AV$10,MATCH($B$59,$AS$5:$AS$10,0))+1),$B$43)*$B$45)*128,0)),128)/GCD(MOD((ROUND((INT(MOD($A26*7919+104729,INDEX($BC$5:$BC$10,MATCH($B$59,$AS$5:$AS$10,0))*INDEX($AV$5:$AV$10,MATCH($B$59,$AS$5:$AS$10,0))+1)/$B$43)*$B$42+MOD(MOD($A26*7919+104729,INDEX($BC$5:$BC$10,MATCH($B$59,$AS$5:$AS$10,0))*INDEX($AV$5:$AV$10,MATCH($B$59,$AS$5:$AS$10,0))+1),$B$43)*$B$45)*128,0)),128),128)&"/"&128/GCD(MOD((ROUND((INT(MOD($A26*7919+104729,INDEX($BC$5:$BC$10,MATCH($B$59,$AS$5:$AS$10,0))*INDEX($AV$5:$AV$10,MATCH($B$59,$AS$5:$AS$10,0))+1)/$B$43)*$B$42+MOD(MOD($A26*7919+104729,INDEX($BC$5:$BC$10,MATCH($B$59,$AS$5:$AS$10,0))*INDEX($AV$5:$AV$10,MATCH($B$59,$AS$5:$AS$10,0))+1),$B$43)*$B$45)*128,0)),128),128))),FIXED(INT(MOD($A26*7919+104729,INDEX($BC$5:$BC$10,MATCH($B$59,$AS$5:$AS$10,0))*INDEX($AV$5:$AV$10,MATCH($B$59,$AS$5:$AS$10,0))+1)/$B$43)*$B$42+MOD(MOD($A26*7919+104729,INDEX($BC$5:$BC$10,MATCH($B$59,$AS$5:$AS$10,0))*INDEX($AV$5:$AV$10,MATCH($B$59,$AS$5:$AS$10,0))+1),$B$43)*$B$45,$B$51,TRUE))&IF('Pie de rey'!$B$41=1," pulg"," mm")) -> 59/128 pulg
A27: =IF($B$58=1,$B$64+($B$21-1)*10+3,($B$21-1)*10+4) -> 4 | C27: =IF(B27="","",IF(BH27="","—",IF(ABS(B27-BH27)<$B$45/2,"Correcto","Incorrecto"))) | D27: =IF($B$10="SI",BI27,"") -> 2 13/64 pulg | BH27: =IF($B$58=1,IFERROR(INDEX('Datos guía'!$E$5:$E$544,MATCH($B$7&"|"&$A27,'Datos guía'!$A$5:$A$544,0)),""),INT(MOD($A27*7919+104729,INDEX($BC$5:$BC$10,MATCH($B$59,$AS$5:$AS$10,0))*INDEX($AV$5:$AV$10,MATCH($B$59,$AS$5:$AS$10,0))+1)/$B$43)*$B$42+MOD(MOD($A27*7919+104729,INDEX($BC$5:$BC$10,MATCH($B$59,$AS$5:$AS$10,0))*INDEX($AV$5:$AV$10,MATCH($B$59,$AS$5:$AS$10,0))+1),$B$43)*$B$45) -> 2.203125 | BI27: =IF($B$58=1,IFERROR(INDEX('Datos guía'!$F$5:$F$544,MATCH($B$7&"|"&$A27,'Datos guía'!$A$5:$A$544,0)),"No está en el banco"),IF($B$57=4,IF((ROUND((INT(MOD($A27*7919+104729,INDEX($BC$5:$BC$10,MATCH($B$59,$AS$5:$AS$10,0))*INDEX($AV$5:$AV$10,MATCH($B$59,$AS$5:$AS$10,0))+1)/$B$43)*$B$42+MOD(MOD($A27*7919+104729,INDEX($BC$5:$BC$10,MATCH($B$59,$AS$5:$AS$10,0))*INDEX($AV$5:$AV$10,MATCH($B$59,$AS$5:$AS$10,0))+1),$B$43)*$B$45)*128,0))=0,"0",IF(INT((ROUND((INT(MOD($A27*7919+104729,INDEX($BC$5:$BC$10,MATCH($B$59,$AS$5:$AS$10,0))*INDEX($AV$5:$AV$10,MATCH($B$59,$AS$5:$AS$10,0))+1)/$B$43)*$B$42+MOD(MOD($A27*7919+104729,INDEX($BC$5:$BC$10,MATCH($B$59,$AS$5:$AS$10,0))*INDEX($AV$5:$AV$10,MATCH($B$59,$AS$5:$AS$10,0))+1),$B$43)*$B$45)*128,0))/128)>0,INT((ROUND((INT(MOD($A27*7919+104729,INDEX($BC$5:$BC$10,MATCH($B$59,$AS$5:$AS$10,0))*INDEX($AV$5:$AV$10,MATCH($B$59,$AS$5:$AS$10,0))+1)/$B$43)*$B$42+MOD(MOD($A27*7919+104729,INDEX($BC$5:$BC$10,MATCH($B$59,$AS$5:$AS$10,0))*INDEX($AV$5:$AV$10,MATCH($B$59,$AS$5:$AS$10,0))+1),$B$43)*$B$45)*128,0))/128)&" ","")&IF(MOD((ROUND((INT(MOD($A27*7919+104729,INDEX($BC$5:$BC$10,MATCH($B$59,$AS$5:$AS$10,0))*INDEX($AV$5:$AV$10,MATCH($B$59,$AS$5:$AS$10,0))+1)/$B$43)*$B$42+MOD(MOD($A27*7919+104729,INDEX($BC$5:$BC$10,MATCH($B$59,$AS$5:$AS$10,0))*INDEX($AV$5:$AV$10,MATCH($B$59,$AS$5:$AS$10,0))+1),$B$43)*$B$45)*128,0)),128)=0,"",MOD((ROUND((INT(MOD($A27*7919+104729,INDEX($BC$5:$BC$10,MATCH($B$59,$AS$5:$AS$10,0))*INDEX($AV$5:$AV$10,MATCH($B$59,$AS$5:$AS$10,0))+1)/$B$43)*$B$42+MOD(MOD($A27*7919+104729,INDEX($BC$5:$BC$10,MATCH($B$59,$AS$5:$AS$10,0))*INDEX($AV$5:$AV$10,MATCH($B$59,$AS$5:$AS$10,0))+1),$B$43)*$B$45)*128,0)),128)/GCD(MOD((ROUND((INT(MOD($A27*7919+104729,INDEX($BC$5:$BC$10,MATCH($B$59,$AS$5:$AS$10,0))*INDEX($AV$5:$AV$10,MATCH($B$59,$AS$5:$AS$10,0))+1)/$B$43)*$B$42+MOD(MOD($A27*7919+104729,INDEX($BC$5:$BC$10,MATCH($B$59,$AS$5:$AS$10,0))*INDEX($AV$5:$AV$10,MATCH($B$59,$AS$5:$AS$10,0))+1),$B$43)*$B$45)*128,0)),128),128)&"/"&128/GCD(MOD((ROUND((INT(MOD($A27*7919+104729,INDEX($BC$5:$BC$10,MATCH($B$59,$AS$5:$AS$10,0))*INDEX($AV$5:$AV$10,MATCH($B$59,$AS$5:$AS$10,0))+1)/$B$43)*$B$42+MOD(MOD($A27*7919+104729,INDEX($BC$5:$BC$10,MATCH($B$59,$AS$5:$AS$10,0))*INDEX($AV$5:$AV$10,MATCH($B$59,$AS$5:$AS$10,0))+1),$B$43)*$B$45)*128,0)),128),128))),FIXED(INT(MOD($A27*7919+104729,INDEX($BC$5:$BC$10,MATCH($B$59,$AS$5:$AS$10,0))*INDEX($AV$5:$AV$10,MATCH($B$59,$AS$5:$AS$10,0))+1)/$B$43)*$B$42+MOD(MOD($A27*7919+104729,INDEX($BC$5:$BC$10,MATCH($B$59,$AS$5:$AS$10,0))*INDEX($AV$5:$AV$10,MATCH($B$59,$AS$5:$AS$10,0))+1),$B$43)*$B$45,$B$51,TRUE))&IF('Pie de rey'!$B$41=1," pulg"," mm")) -> 2 13/64 pulg
A28: =IF($B$58=1,$B$64+($B$21-1)*10+4,($B$21-1)*10+5) -> 5 | C28: =IF(B28="","",IF(BH28="","—",IF(ABS(B28-BH28)<$B$45/2,"Correcto","Incorrecto"))) | D28: =IF($B$10="SI",BI28,"") -> 3/16 pulg | BH28: =IF($B$58=1,IFERROR(INDEX('Datos guía'!$E$5:$E$544,MATCH($B$7&"|"&$A28,'Datos guía'!$A$5:$A$544,0)),""),INT(MOD($A28*7919+104729,INDEX($BC$5:$BC$10,MATCH($B$59,$AS$5:$AS$10,0))*INDEX($AV$5:$AV$10,MATCH($B$59,$AS$5:$AS$10,0))+1)/$B$43)*$B$42+MOD(MOD($A28*7919+104729,INDEX($BC$5:$BC$10,MATCH($B$59,$AS$5:$AS$10,0))*INDEX($AV$5:$AV$10,MATCH($B$59,$AS$5:$AS$10,0))+1),$B$43)*$B$45) -> 0.1875 | BI28: =IF($B$58=1,IFERROR(INDEX('Datos guía'!$F$5:$F$544,MATCH($B$7&"|"&$A28,'Datos guía'!$A$5:$A$544,0)),"No está en el banco"),IF($B$57=4,IF((ROUND((INT(MOD($A28*7919+104729,INDEX($BC$5:$BC$10,MATCH($B$59,$AS$5:$AS$10,0))*INDEX($AV$5:$AV$10,MATCH($B$59,$AS$5:$AS$10,0))+1)/$B$43)*$B$42+MOD(MOD($A28*7919+104729,INDEX($BC$5:$BC$10,MATCH($B$59,$AS$5:$AS$10,0))*INDEX($AV$5:$AV$10,MATCH($B$59,$AS$5:$AS$10,0))+1),$B$43)*$B$45)*128,0))=0,"0",IF(INT((ROUND((INT(MOD($A28*7919+104729,INDEX($BC$5:$BC$10,MATCH($B$59,$AS$5:$AS$10,0))*INDEX($AV$5:$AV$10,MATCH($B$59,$AS$5:$AS$10,0))+1)/$B$43)*$B$42+MOD(MOD($A28*7919+104729,INDEX($BC$5:$BC$10,MATCH($B$59,$AS$5:$AS$10,0))*INDEX($AV$5:$AV$10,MATCH($B$59,$AS$5:$AS$10,0))+1),$B$43)*$B$45)*128,0))/128)>0,INT((ROUND((INT(MOD($A28*7919+104729,INDEX($BC$5:$BC$10,MATCH($B$59,$AS$5:$AS$10,0))*INDEX($AV$5:$AV$10,MATCH($B$59,$AS$5:$AS$10,0))+1)/$B$43)*$B$42+MOD(MOD($A28*7919+104729,INDEX($BC$5:$BC$10,MATCH($B$59,$AS$5:$AS$10,0))*INDEX($AV$5:$AV$10,MATCH($B$59,$AS$5:$AS$10,0))+1),$B$43)*$B$45)*128,0))/128)&" ","")&IF(MOD((ROUND((INT(MOD($A28*7919+104729,INDEX($BC$5:$BC$10,MATCH($B$59,$AS$5:$AS$10,0))*INDEX($AV$5:$AV$10,MATCH($B$59,$AS$5:$AS$10,0))+1)/$B$43)*$B$42+MOD(MOD($A28*7919+104729,INDEX($BC$5:$BC$10,MATCH($B$59,$AS$5:$AS$10,0))*INDEX($AV$5:$AV$10,MATCH($B$59,$AS$5:$AS$10,0))+1),$B$43)*$B$45)*128,0)),128)=0,"",MOD((ROUND((INT(MOD($A28*7919+104729,INDEX($BC$5:$BC$10,MATCH($B$59,$AS$5:$AS$10,0))*INDEX($AV$5:$AV$10,MATCH($B$59,$AS$5:$AS$10,0))+1)/$B$43)*$B$42+MOD(MOD($A28*7919+104729,INDEX($BC$5:$BC$10,MATCH($B$59,$AS$5:$AS$10,0))*INDEX($AV$5:$AV$10,MATCH($B$59,$AS$5:$AS$10,0))+1),$B$43)*$B$45)*128,0)),128)/GCD(MOD((ROUND((INT(MOD($A28*7919+104729,INDEX($BC$5:$BC$10,MATCH($B$59,$AS$5:$AS$10,0))*INDEX($AV$5:$AV$10,MATCH($B$59,$AS$5:$AS$10,0))+1)/$B$43)*$B$42+MOD(MOD($A28*7919+104729,INDEX($BC$5:$BC$10,MATCH($B$59,$AS$5:$AS$10,0))*INDEX($AV$5:$AV$10,MATCH($B$59,$AS$5:$AS$10,0))+1),$B$43)*$B$45)*128,0)),128),128)&"/"&128/GCD(MOD((ROUND((INT(MOD($A28*7919+104729,INDEX($BC$5:$BC$10,MATCH($B$59,$AS$5:$AS$10,0))*INDEX($AV$5:$AV$10,MATCH($B$59,$AS$5:$AS$10,0))+1)/$B$43)*$B$42+MOD(MOD($A28*7919+104729,INDEX($BC$5:$BC$10,MATCH($B$59,$AS$5:$AS$10,0))*INDEX($AV$5:$AV$10,MATCH($B$59,$AS$5:$AS$10,0))+1),$B$43)*$B$45)*128,0)),128),128))),FIXED(INT(MOD($A28*7919+104729,INDEX($BC$5:$BC$10,MATCH($B$59,$AS$5:$AS$10,0))*INDEX($AV$5:$AV$10,MATCH($B$59,$AS$5:$AS$10,0))+1)/$B$43)*$B$42+MOD(MOD($A28*7919+104729,INDEX($BC$5:$BC$10,MATCH($B$59,$AS$5:$AS$10,0))*INDEX($AV$5:$AV$10,MATCH($B$59,$AS$5:$AS$10,0))+1),$B$43)*$B$45,$B$51,TRUE))&IF('Pie de rey'!$B$41=1," pulg"," mm")) -> 3/16 pulg
A29: =IF($B$58=1,$B$64+($B$21-1)*10+5,($B$21-1)*10+6) -> 6 | C29: =IF(B29="","",IF(BH29="","—",IF(ABS(B29-BH29)<$B$45/2,"Correcto","Incorrecto"))) | D29: =IF($B$10="SI",BI29,"") -> 1 119/128 pulg | BH29: =IF($B$58=1,IFERROR(INDEX('Datos guía'!$E$5:$E$544,MATCH($B$7&"|"&$A29,'Datos guía'!$A$5:$A$544,0)),""),INT(MOD($A29*7919+104729,INDEX($BC$5:$BC$10,MATCH($B$59,$AS$5:$AS$10,0))*INDEX($AV$5:$AV$10,MATCH($B$59,$AS$5:$AS$10,0))+1)/$B$43)*$B$42+MOD(MOD($A29*7919+104729,INDEX($BC$5:$BC$10,MATCH($B$59,$AS$5:$AS$10,0))*INDEX($AV$5:$AV$10,MATCH($B$59,$AS$5:$AS$10,0))+1),$B$43)*$B$45) -> 1.9296875 | BI29: =IF($B$58=1,IFERROR(INDEX('Datos guía'!$F$5:$F$544,MATCH($B$7&"|"&$A29,'Datos guía'!$A$5:$A$544,0)),"No está en el banco"),IF($B$57=4,IF((ROUND((INT(MOD($A29*7919+104729,INDEX($BC$5:$BC$10,MATCH($B$59,$AS$5:$AS$10,0))*INDEX($AV$5:$AV$10,MATCH($B$59,$AS$5:$AS$10,0))+1)/$B$43)*$B$42+MOD(MOD($A29*7919+104729,INDEX($BC$5:$BC$10,MATCH($B$59,$AS$5:$AS$10,0))*INDEX($AV$5:$AV$10,MATCH($B$59,$AS$5:$AS$10,0))+1),$B$43)*$B$45)*128,0))=0,"0",IF(INT((ROUND((INT(MOD($A29*7919+104729,INDEX($BC$5:$BC$10,MATCH($B$59,$AS$5:$AS$10,0))*INDEX($AV$5:$AV$10,MATCH($B$59,$AS$5:$AS$10,0))+1)/$B$43)*$B$42+MOD(MOD($A29*7919+104729,INDEX($BC$5:$BC$10,MATCH($B$59,$AS$5:$AS$10,0))*INDEX($AV$5:$AV$10,MATCH($B$59,$AS$5:$AS$10,0))+1),$B$43)*$B$45)*128,0))/128)>0,INT((ROUND((INT(MOD($A29*7919+104729,INDEX($BC$5:$BC$10,MATCH($B$59,$AS$5:$AS$10,0))*INDEX($AV$5:$AV$10,MATCH($B$59,$AS$5:$AS$10,0))+1)/$B$43)*$B$42+MOD(MOD($A29*7919+104729,INDEX($BC$5:$BC$10,MATCH($B$59,$AS$5:$AS$10,0))*INDEX($AV$5:$AV$10,MATCH($B$59,$AS$5:$AS$10,0))+1),$B$43)*$B$45)*128,0))/128)&" ","")&IF(MOD((ROUND((INT(MOD($A29*7919+104729,INDEX($BC$5:$BC$10,MATCH($B$59,$AS$5:$AS$10,0))*INDEX($AV$5:$AV$10,MATCH($B$59,$AS$5:$AS$10,0))+1)/$B$43)*$B$42+MOD(MOD($A29*7919+104729,INDEX($BC$5:$BC$10,MATCH($B$59,$AS$5:$AS$10,0))*INDEX($AV$5:$AV$10,MATCH($B$59,$AS$5:$AS$10,0))+1),$B$43)*$B$45)*128,0)),128)=0,"",MOD((ROUND((INT(MOD($A29*7919+104729,INDEX($BC$5:$BC$10,MATCH($B$59,$AS$5:$AS$10,0))*INDEX($AV$5:$AV$10,MATCH($B$59,$AS$5:$AS$10,0))+1)/$B$43)*$B$42+MOD(MOD($A29*7919+104729,INDEX($BC$5:$BC$10,MATCH($B$59,$AS$5:$AS$10,0))*INDEX($AV$5:$AV$10,MATCH($B$59,$AS$5:$AS$10,0))+1),$B$43)*$B$45)*128,0)),128)/GCD(MOD((ROUND((INT(MOD($A29*7919+104729,INDEX($BC$5:$BC$10,MATCH($B$59,$AS$5:$AS$10,0))*INDEX($AV$5:$AV$10,MATCH($B$59,$AS$5:$AS$10,0))+1)/$B$43)*$B$42+MOD(MOD($A29*7919+104729,INDEX($BC$5:$BC$10,MATCH($B$59,$AS$5:$AS$10,0))*INDEX($AV$5:$AV$10,MATCH($B$59,$AS$5:$AS$10,0))+1),$B$43)*$B$45)*128,0)),128),128)&"/"&128/GCD(MOD((ROUND((INT(MOD($A29*7919+104729,INDEX($BC$5:$BC$10,MATCH($B$59,$AS$5:$AS$10,0))*INDEX($AV$5:$AV$10,MATCH($B$59,$AS$5:$AS$10,0))+1)/$B$43)*$B$42+MOD(MOD($A29*7919+104729,INDEX($BC$5:$BC$10,MATCH($B$59,$AS$5:$AS$10,0))*INDEX($AV$5:$AV$10,MATCH($B$59,$AS$5:$AS$10,0))+1),$B$43)*$B$45)*128,0)),128),128))),FIXED(INT(MOD($A29*7919+104729,INDEX($BC$5:$BC$10,MATCH($B$59,$AS$5:$AS$10,0))*INDEX($AV$5:$AV$10,MATCH($B$59,$AS$5:$AS$10,0))+1)/$B$43)*$B$42+MOD(MOD($A29*7919+104729,INDEX($BC$5:$BC$10,MATCH($B$59,$AS$5:$AS$10,0))*INDEX($AV$5:$AV$10,MATCH($B$59,$AS$5:$AS$10,0))+1),$B$43)*$B$45,$B$51,TRUE))&IF('Pie de rey'!$B$41=1," pulg"," mm")) -> 1 119/128 pulg
A30: =IF($B$58=1,$B$64+($B$21-1)*10+6,($B$21-1)*10+7) -> 7 | C30: =IF(B30="","",IF(BH30="","—",IF(ABS(B30-BH30)<$B$45/2,"Correcto","Incorrecto"))) | D30: =IF($B$10="SI",BI30,"") -> 3 43/64 pulg | BH30: =IF($B$58=1,IFERROR(INDEX('Datos guía'!$E$5:$E$544,MATCH($B$7&"|"&$A30,'Datos guía'!$A$5:$A$544,0)),""),INT(MOD($A30*7919+104729,INDEX($BC$5:$BC$10,MATCH($B$59,$AS$5:$AS$10,0))*INDEX($AV$5:$AV$10,MATCH($B$59,$AS$5:$AS$10,0))+1)/$B$43)*$B$42+MOD(MOD($A30*7919+104729,INDEX($BC$5:$BC$10,MATCH($B$59,$AS$5:$AS$10,0))*INDEX($AV$5:$AV$10,MATCH($B$59,$AS$5:$AS$10,0))+1),$B$43)*$B$45) -> 3.671875 | BI30: =IF($B$58=1,IFERROR(INDEX('Datos guía'!$F$5:$F$544,MATCH($B$7&"|"&$A30,'Datos guía'!$A$5:$A$544,0)),"No está en el banco"),IF($B$57=4,IF((ROUND((INT(MOD($A30*7919+104729,INDEX($BC$5:$BC$10,MATCH($B$59,$AS$5:$AS$10,0))*INDEX($AV$5:$AV$10,MATCH($B$59,$AS$5:$AS$10,0))+1)/$B$43)*$B$42+MOD(MOD($A30*7919+104729,INDEX($BC$5:$BC$10,MATCH($B$59,$AS$5:$AS$10,0))*INDEX($AV$5:$AV$10,MATCH($B$59,$AS$5:$AS$10,0))+1),$B$43)*$B$45)*128,0))=0,"0",IF(INT((ROUND((INT(MOD($A30*7919+104729,INDEX($BC$5:$BC$10,MATCH($B$59,$AS$5:$AS$10,0))*INDEX($AV$5:$AV$10,MATCH($B$59,$AS$5:$AS$10,0))+1)/$B$43)*$B$42+MOD(MOD($A30*7919+104729,INDEX($BC$5:$BC$10,MATCH($B$59,$AS$5:$AS$10,0))*INDEX($AV$5:$AV$10,MATCH($B$59,$AS$5:$AS$10,0))+1),$B$43)*$B$45)*128,0))/128)>0,INT((ROUND((INT(MOD($A30*7919+104729,INDEX($BC$5:$BC$10,MATCH($B$59,$AS$5:$AS$10,0))*INDEX($AV$5:$AV$10,MATCH($B$59,$AS$5:$AS$10,0))+1)/$B$43)*$B$42+MOD(MOD($A30*7919+104729,INDEX($BC$5:$BC$10,MATCH($B$59,$AS$5:$AS$10,0))*INDEX($AV$5:$AV$10,MATCH($B$59,$AS$5:$AS$10,0))+1),$B$43)*$B$45)*128,0))/128)&" ","")&IF(MOD((ROUND((INT(MOD($A30*7919+104729,INDEX($BC$5:$BC$10,MATCH($B$59,$AS$5:$AS$10,0))*INDEX($AV$5:$AV$10,MATCH($B$59,$AS$5:$AS$10,0))+1)/$B$43)*$B$42+MOD(MOD($A30*7919+104729,INDEX($BC$5:$BC$10,MATCH($B$59,$AS$5:$AS$10,0))*INDEX($AV$5:$AV$10,MATCH($B$59,$AS$5:$AS$10,0))+1),$B$43)*$B$45)*128,0)),128)=0,"",MOD((ROUND((INT(MOD($A30*7919+104729,INDEX($BC$5:$BC$10,MATCH($B$59,$AS$5:$AS$10,0))*INDEX($AV$5:$AV$10,MATCH($B$59,$AS$5:$AS$10,0))+1)/$B$43)*$B$42+MOD(MOD($A30*7919+104729,INDEX($BC$5:$BC$10,MATCH($B$59,$AS$5:$AS$10,0))*INDEX($AV$5:$AV$10,MATCH($B$59,$AS$5:$AS$10,0))+1),$B$43)*$B$45)*128,0)),128)/GCD(MOD((ROUND((INT(MOD($A30*7919+104729,INDEX($BC$5:$BC$10,MATCH($B$59,$AS$5:$AS$10,0))*INDEX($AV$5:$AV$10,MATCH($B$59,$AS$5:$AS$10,0))+1)/$B$43)*$B$42+MOD(MOD($A30*7919+104729,INDEX($BC$5:$BC$10,MATCH($B$59,$AS$5:$AS$10,0))*INDEX($AV$5:$AV$10,MATCH($B$59,$AS$5:$AS$10,0))+1),$B$43)*$B$45)*128,0)),128),128)&"/"&128/GCD(MOD((ROUND((INT(MOD($A30*7919+104729,INDEX($BC$5:$BC$10,MATCH($B$59,$AS$5:$AS$10,0))*INDEX($AV$5:$AV$10,MATCH($B$59,$AS$5:$AS$10,0))+1)/$B$43)*$B$42+MOD(MOD($A30*7919+104729,INDEX($BC$5:$BC$10,MATCH($B$59,$AS$5:$AS$10,0))*INDEX($AV$5:$AV$10,MATCH($B$59,$AS$5:$AS$10,0))+1),$B$43)*$B$45)*128,0)),128),128))),FIXED(INT(MOD($A30*7919+104729,INDEX($BC$5:$BC$10,MATCH($B$59,$AS$5:$AS$10,0))*INDEX($AV$5:$AV$10,MATCH($B$59,$AS$5:$AS$10,0))+1)/$B$43)*$B$42+MOD(MOD($A30*7919+104729,INDEX($BC$5:$BC$10,MATCH($B$59,$AS$5:$AS$10,0))*INDEX($AV$5:$AV$10,MATCH($B$59,$AS$5:$AS$10,0))+1),$B$43)*$B$45,$B$51,TRUE))&IF('Pie de rey'!$B$41=1," pulg"," mm")) -> 3 43/64 pulg
A31: =IF($B$58=1,$B$64+($B$21-1)*10+7,($B$21-1)*10+8) -> 8 | C31: =IF(B31="","",IF(BH31="","—",IF(ABS(B31-BH31)<$B$45/2,"Correcto","Incorrecto"))) | D31: =IF($B$10="SI",BI31,"") -> 1 21/32 pulg | BH31: =IF($B$58=1,IFERROR(INDEX('Datos guía'!$E$5:$E$544,MATCH($B$7&"|"&$A31,'Datos guía'!$A$5:$A$544,0)),""),INT(MOD($A31*7919+104729,INDEX($BC$5:$BC$10,MATCH($B$59,$AS$5:$AS$10,0))*INDEX($AV$5:$AV$10,MATCH($B$59,$AS$5:$AS$10,0))+1)/$B$43)*$B$42+MOD(MOD($A31*7919+104729,INDEX($BC$5:$BC$10,MATCH($B$59,$AS$5:$AS$10,0))*INDEX($AV$5:$AV$10,MATCH($B$59,$AS$5:$AS$10,0))+1),$B$43)*$B$45) -> 1.65625 | BI31: =IF($B$58=1,IFERROR(INDEX('Datos guía'!$F$5:$F$544,MATCH($B$7&"|"&$A31,'Datos guía'!$A$5:$A$544,0)),"No está en el banco"),IF($B$57=4,IF((ROUND((INT(MOD($A31*7919+104729,INDEX($BC$5:$BC$10,MATCH($B$59,$AS$5:$AS$10,0))*INDEX($AV$5:$AV$10,MATCH($B$59,$AS$5:$AS$10,0))+1)/$B$43)*$B$42+MOD(MOD($A31*7919+104729,INDEX($BC$5:$BC$10,MATCH($B$59,$AS$5:$AS$10,0))*INDEX($AV$5:$AV$10,MATCH($B$59,$AS$5:$AS$10,0))+1),$B$43)*$B$45)*128,0))=0,"0",IF(INT((ROUND((INT(MOD($A31*7919+104729,INDEX($BC$5:$BC$10,MATCH($B$59,$AS$5:$AS$10,0))*INDEX($AV$5:$AV$10,MATCH($B$59,$AS$5:$AS$10,0))+1)/$B$43)*$B$42+MOD(MOD($A31*7919+104729,INDEX($BC$5:$BC$10,MATCH($B$59,$AS$5:$AS$10,0))*INDEX($AV$5:$AV$10,MATCH($B$59,$AS$5:$AS$10,0))+1),$B$43)*$B$45)*128,0))/128)>0,INT((ROUND((INT(MOD($A31*7919+104729,INDEX($BC$5:$BC$10,MATCH($B$59,$AS$5:$AS$10,0))*INDEX($AV$5:$AV$10,MATCH($B$59,$AS$5:$AS$10,0))+1)/$B$43)*$B$42+MOD(MOD($A31*7919+104729,INDEX($BC$5:$BC$10,MATCH($B$59,$AS$5:$AS$10,0))*INDEX($AV$5:$AV$10,MATCH($B$59,$AS$5:$AS$10,0))+1),$B$43)*$B$45)*128,0))/128)&" ","")&IF(MOD((ROUND((INT(MOD($A31*7919+104729,INDEX($BC$5:$BC$10,MATCH($B$59,$AS$5:$AS$10,0))*INDEX($AV$5:$AV$10,MATCH($B$59,$AS$5:$AS$10,0))+1)/$B$43)*$B$42+MOD(MOD($A31*7919+104729,INDEX($BC$5:$BC$10,MATCH($B$59,$AS$5:$AS$10,0))*INDEX($AV$5:$AV$10,MATCH($B$59,$AS$5:$AS$10,0))+1),$B$43)*$B$45)*128,0)),128)=0,"",MOD((ROUND((INT(MOD($A31*7919+104729,INDEX($BC$5:$BC$10,MATCH($B$59,$AS$5:$AS$10,0))*INDEX($AV$5:$AV$10,MATCH($B$59,$AS$5:$AS$10,0))+1)/$B$43)*$B$42+MOD(MOD($A31*7919+104729,INDEX($BC$5:$BC$10,MATCH($B$59,$AS$5:$AS$10,0))*INDEX($AV$5:$AV$10,MATCH($B$59,$AS$5:$AS$10,0))+1),$B$43)*$B$45)*128,0)),128)/GCD(MOD((ROUND((INT(MOD($A31*7919+104729,INDEX($BC$5:$BC$10,MATCH($B$59,$AS$5:$AS$10,0))*INDEX($AV$5:$AV$10,MATCH($B$59,$AS$5:$AS$10,0))+1)/$B$43)*$B$42+MOD(MOD($A31*7919+104729,INDEX($BC$5:$BC$10,MATCH($B$59,$AS$5:$AS$10,0))*INDEX($AV$5:$AV$10,MATCH($B$59,$AS$5:$AS$10,0))+1),$B$43)*$B$45)*128,0)),128),128)&"/"&128/GCD(MOD((ROUND((INT(MOD($A31*7919+104729,INDEX($BC$5:$BC$10,MATCH($B$59,$AS$5:$AS$10,0))*INDEX($AV$5:$AV$10,MATCH($B$59,$AS$5:$AS$10,0))+1)/$B$43)*$B$42+MOD(MOD($A31*7919+104729,INDEX($BC$5:$BC$10,MATCH($B$59,$AS$5:$AS$10,0))*INDEX($AV$5:$AV$10,MATCH($B$59,$AS$5:$AS$10,0))+1),$B$43)*$B$45)*128,0)),128),128))),FIXED(INT(MOD($A31*7919+104729,INDEX($BC$5:$BC$10,MATCH($B$59,$AS$5:$AS$10,0))*INDEX($AV$5:$AV$10,MATCH($B$59,$AS$5:$AS$10,0))+1)/$B$43)*$B$42+MOD(MOD($A31*7919+104729,INDEX($BC$5:$BC$10,MATCH($B$59,$AS$5:$AS$10,0))*INDEX($AV$5:$AV$10,MATCH($B$59,$AS$5:$AS$10,0))+1),$B$43)*$B$45,$B$51,TRUE))&IF('Pie de rey'!$B$41=1," pulg"," mm")) -> 1 21/32 pulg
A32: =IF($B$58=1,$B$64+($B$21-1)*10+8,($B$21-1)*10+9) -> 9 | C32: =IF(B32="","",IF(BH32="","—",IF(ABS(B32-BH32)<$B$45/2,"Correcto","Incorrecto"))) | D32: =IF($B$10="SI",BI32,"") -> 3 51/128 pulg | BH32: =IF($B$58=1,IFERROR(INDEX('Datos guía'!$E$5:$E$544,MATCH($B$7&"|"&$A32,'Datos guía'!$A$5:$A$544,0)),""),INT(MOD($A32*7919+104729,INDEX($BC$5:$BC$10,MATCH($B$59,$AS$5:$AS$10,0))*INDEX($AV$5:$AV$10,MATCH($B$59,$AS$5:$AS$10,0))+1)/$B$43)*$B$42+MOD(MOD($A32*7919+104729,INDEX($BC$5:$BC$10,MATCH($B$59,$AS$5:$AS$10,0))*INDEX($AV$5:$AV$10,MATCH($B$59,$AS$5:$AS$10,0))+1),$B$43)*$B$45) -> 3.3984375 | BI32: =IF($B$58=1,IFERROR(INDEX('Datos guía'!$F$5:$F$544,MATCH($B$7&"|"&$A32,'Datos guía'!$A$5:$A$544,0)),"No está en el banco"),IF($B$57=4,IF((ROUND((INT(MOD($A32*7919+104729,INDEX($BC$5:$BC$10,MATCH($B$59,$AS$5:$AS$10,0))*INDEX($AV$5:$AV$10,MATCH($B$59,$AS$5:$AS$10,0))+1)/$B$43)*$B$42+MOD(MOD($A32*7919+104729,INDEX($BC$5:$BC$10,MATCH($B$59,$AS$5:$AS$10,0))*INDEX($AV$5:$AV$10,MATCH($B$59,$AS$5:$AS$10,0))+1),$B$43)*$B$45)*128,0))=0,"0",IF(INT((ROUND((INT(MOD($A32*7919+104729,INDEX($BC$5:$BC$10,MATCH($B$59,$AS$5:$AS$10,0))*INDEX($AV$5:$AV$10,MATCH($B$59,$AS$5:$AS$10,0))+1)/$B$43)*$B$42+MOD(MOD($A32*7919+104729,INDEX($BC$5:$BC$10,MATCH($B$59,$AS$5:$AS$10,0))*INDEX($AV$5:$AV$10,MATCH($B$59,$AS$5:$AS$10,0))+1),$B$43)*$B$45)*128,0))/128)>0,INT((ROUND((INT(MOD($A32*7919+104729,INDEX($BC$5:$BC$10,MATCH($B$59,$AS$5:$AS$10,0))*INDEX($AV$5:$AV$10,MATCH($B$59,$AS$5:$AS$10,0))+1)/$B$43)*$B$42+MOD(MOD($A32*7919+104729,INDEX($BC$5:$BC$10,MATCH($B$59,$AS$5:$AS$10,0))*INDEX($AV$5:$AV$10,MATCH($B$59,$AS$5:$AS$10,0))+1),$B$43)*$B$45)*128,0))/128)&" ","")&IF(MOD((ROUND((INT(MOD($A32*7919+104729,INDEX($BC$5:$BC$10,MATCH($B$59,$AS$5:$AS$10,0))*INDEX($AV$5:$AV$10,MATCH($B$59,$AS$5:$AS$10,0))+1)/$B$43)*$B$42+MOD(MOD($A32*7919+104729,INDEX($BC$5:$BC$10,MATCH($B$59,$AS$5:$AS$10,0))*INDEX($AV$5:$AV$10,MATCH($B$59,$AS$5:$AS$10,0))+1),$B$43)*$B$45)*128,0)),128)=0,"",MOD((ROUND((INT(MOD($A32*7919+104729,INDEX($BC$5:$BC$10,MATCH($B$59,$AS$5:$AS$10,0))*INDEX($AV$5:$AV$10,MATCH($B$59,$AS$5:$AS$10,0))+1)/$B$43)*$B$42+MOD(MOD($A32*7919+104729,INDEX($BC$5:$BC$10,MATCH($B$59,$AS$5:$AS$10,0))*INDEX($AV$5:$AV$10,MATCH($B$59,$AS$5:$AS$10,0))+1),$B$43)*$B$45)*128,0)),128)/GCD(MOD((ROUND((INT(MOD($A32*7919+104729,INDEX($BC$5:$BC$10,MATCH($B$59,$AS$5:$AS$10,0))*INDEX($AV$5:$AV$10,MATCH($B$59,$AS$5:$AS$10,0))+1)/$B$43)*$B$42+MOD(MOD($A32*7919+104729,INDEX($BC$5:$BC$10,MATCH($B$59,$AS$5:$AS$10,0))*INDEX($AV$5:$AV$10,MATCH($B$59,$AS$5:$AS$10,0))+1),$B$43)*$B$45)*128,0)),128),128)&"/"&128/GCD(MOD((ROUND((INT(MOD($A32*7919+104729,INDEX($BC$5:$BC$10,MATCH($B$59,$AS$5:$AS$10,0))*INDEX($AV$5:$AV$10,MATCH($B$59,$AS$5:$AS$10,0))+1)/$B$43)*$B$42+MOD(MOD($A32*7919+104729,INDEX($BC$5:$BC$10,MATCH($B$59,$AS$5:$AS$10,0))*INDEX($AV$5:$AV$10,MATCH($B$59,$AS$5:$AS$10,0))+1),$B$43)*$B$45)*128,0)),128),128))),FIXED(INT(MOD($A32*7919+104729,INDEX($BC$5:$BC$10,MATCH($B$59,$AS$5:$AS$10,0))*INDEX($AV$5:$AV$10,MATCH($B$59,$AS$5:$AS$10,0))+1)/$B$43)*$B$42+MOD(MOD($A32*7919+104729,INDEX($BC$5:$BC$10,MATCH($B$59,$AS$5:$AS$10,0))*INDEX($AV$5:$AV$10,MATCH($B$59,$AS$5:$AS$10,0))+1),$B$43)*$B$45,$B$51,TRUE))&IF('Pie de rey'!$B$41=1," pulg"," mm")) -> 3 51/128 pulg
A33: =IF($B$58=1,$B$64+($B$21-1)*10+9,($B$21-1)*10+10) -> 10 | C33: =IF(B33="","",IF(BH33="","—",IF(ABS(B33-BH33)<$B$45/2,"Correcto","Incorrecto"))) | D33: =IF($B$10="SI",BI33,"") -> 1 49/128 pulg | BH33: =IF($B$58=1,IFERROR(INDEX('Datos guía'!$E$5:$E$544,MATCH($B$7&"|"&$A33,'Datos guía'!$A$5:$A$544,0)),""),INT(MOD($A33*7919+104729,INDEX($BC$5:$BC$10,MATCH($B$59,$AS$5:$AS$10,0))*INDEX($AV$5:$AV$10,MATCH($B$59,$AS$5:$AS$10,0))+1)/$B$43)*$B$42+MOD(MOD($A33*7919+104729,INDEX($BC$5:$BC$10,MATCH($B$59,$AS$5:$AS$10,0))*INDEX($AV$5:$AV$10,MATCH($B$59,$AS$5:$AS$10,0))+1),$B$43)*$B$45) -> 1.3828125 | BI33: =IF($B$58=1,IFERROR(INDEX('Datos guía'!$F$5:$F$544,MATCH($B$7&"|"&$A33,'Datos guía'!$A$5:$A$544,0)),"No está en el banco"),IF($B$57=4,IF((ROUND((INT(MOD($A33*7919+104729,INDEX($BC$5:$BC$10,MATCH($B$59,$AS$5:$AS$10,0))*INDEX($AV$5:$AV$10,MATCH($B$59,$AS$5:$AS$10,0))+1)/$B$43)*$B$42+MOD(MOD($A33*7919+104729,INDEX($BC$5:$BC$10,MATCH($B$59,$AS$5:$AS$10,0))*INDEX($AV$5:$AV$10,MATCH($B$59,$AS$5:$AS$10,0))+1),$B$43)*$B$45)*128,0))=0,"0",IF(INT((ROUND((INT(MOD($A33*7919+104729,INDEX($BC$5:$BC$10,MATCH($B$59,$AS$5:$AS$10,0))*INDEX($AV$5:$AV$10,MATCH($B$59,$AS$5:$AS$10,0))+1)/$B$43)*$B$42+MOD(MOD($A33*7919+104729,INDEX($BC$5:$BC$10,MATCH($B$59,$AS$5:$AS$10,0))*INDEX($AV$5:$AV$10,MATCH($B$59,$AS$5:$AS$10,0))+1),$B$43)*$B$45)*128,0))/128)>0,INT((ROUND((INT(MOD($A33*7919+104729,INDEX($BC$5:$BC$10,MATCH($B$59,$AS$5:$AS$10,0))*INDEX($AV$5:$AV$10,MATCH($B$59,$AS$5:$AS$10,0))+1)/$B$43)*$B$42+MOD(MOD($A33*7919+104729,INDEX($BC$5:$BC$10,MATCH($B$59,$AS$5:$AS$10,0))*INDEX($AV$5:$AV$10,MATCH($B$59,$AS$5:$AS$10,0))+1),$B$43)*$B$45)*128,0))/128)&" ","")&IF(MOD((ROUND((INT(MOD($A33*7919+104729,INDEX($BC$5:$BC$10,MATCH($B$59,$AS$5:$AS$10,0))*INDEX($AV$5:$AV$10,MATCH($B$59,$AS$5:$AS$10,0))+1)/$B$43)*$B$42+MOD(MOD($A33*7919+104729,INDEX($BC$5:$BC$10,MATCH($B$59,$AS$5:$AS$10,0))*INDEX($AV$5:$AV$10,MATCH($B$59,$AS$5:$AS$10,0))+1),$B$43)*$B$45)*128,0)),128)=0,"",MOD((ROUND((INT(MOD($A33*7919+104729,INDEX($BC$5:$BC$10,MATCH($B$59,$AS$5:$AS$10,0))*INDEX($AV$5:$AV$10,MATCH($B$59,$AS$5:$AS$10,0))+1)/$B$43)*$B$42+MOD(MOD($A33*7919+104729,INDEX($BC$5:$BC$10,MATCH($B$59,$AS$5:$AS$10,0))*INDEX($AV$5:$AV$10,MATCH($B$59,$AS$5:$AS$10,0))+1),$B$43)*$B$45)*128,0)),128)/GCD(MOD((ROUND((INT(MOD($A33*7919+104729,INDEX($BC$5:$BC$10,MATCH($B$59,$AS$5:$AS$10,0))*INDEX($AV$5:$AV$10,MATCH($B$59,$AS$5:$AS$10,0))+1)/$B$43)*$B$42+MOD(MOD($A33*7919+104729,INDEX($BC$5:$BC$10,MATCH($B$59,$AS$5:$AS$10,0))*INDEX($AV$5:$AV$10,MATCH($B$59,$AS$5:$AS$10,0))+1),$B$43)*$B$45)*128,0)),128),128)&"/"&128/GCD(MOD((ROUND((INT(MOD($A33*7919+104729,INDEX($BC$5:$BC$10,MATCH($B$59,$AS$5:$AS$10,0))*INDEX($AV$5:$AV$10,MATCH($B$59,$AS$5:$AS$10,0))+1)/$B$43)*$B$42+MOD(MOD($A33*7919+104729,INDEX($BC$5:$BC$10,MATCH($B$59,$AS$5:$AS$10,0))*INDEX($AV$5:$AV$10,MATCH($B$59,$AS$5:$AS$10,0))+1),$B$43)*$B$45)*128,0)),128),128))),FIXED(INT(MOD($A33*7919+104729,INDEX($BC$5:$BC$10,MATCH($B$59,$AS$5:$AS$10,0))*INDEX($AV$5:$AV$10,MATCH($B$59,$AS$5:$AS$10,0))+1)/$B$43)*$B$42+MOD(MOD($A33*7919+104729,INDEX($BC$5:$BC$10,MATCH($B$59,$AS$5:$AS$10,0))*INDEX($AV$5:$AV$10,MATCH($B$59,$AS$5:$AS$10,0))+1),$B$43)*$B$45,$B$51,TRUE))&IF('Pie de rey'!$B$41=1," pulg"," mm")) -> 1 49/128 pulg
A35: =COUNTIF(C24:C33,"Correcto")&" de 10 correctas" -> 0 de 10 correctas
A40: Cálculos internos (no editar) | B40: Valor
A41: Sistema (0 = mm, 1 = pulgada) | B41: =INDEX($AT$5:$AT$10,MATCH($B$59,$AS$5:$AS$10,0)) -> 1
A42: Valor de una división de la regla | B42: =INDEX($AU$5:$AU$10,MATCH($B$59,$AS$5:$AS$10,0)) -> 0.0625
A43: Divisiones del nonio | B43: =INDEX($AV$5:$AV$10,MATCH($B$59,$AS$5:$AS$10,0)) -> 8
A44: Módulo del nonio | B44: =INDEX($AW$5:$AW$10,MATCH($B$59,$AS$5:$AS$10,0)) -> 1
A45: Apreciación (resolución) | B45: =INDEX($AX$5:$AX$10,MATCH($B$59,$AS$5:$AS$10,0)) -> 0.0078125
A46: Pasos de apreciación de la lectura | B46: =IF(AND($B$58=1,$B$62=1),ROUND($B$61/$B$45,0),MOD($B$6*7919+104729,INDEX($BC$5:$BC$10,MATCH($B$59,$AS$5:$AS$10,0))*INDEX($AV$5:$AV$10,MATCH($B$59,$AS$5:$AS$10,0))+1)) -> 94
A47: Divisiones enteras de la regla | B47: =INT(B46/B43) -> 11
A48: Raya del nonio que coincide | B48: =MOD(B46,B43) -> 6
...

Sheet Micrómetro
A1: Simulador · Micrómetro de exteriores (milímetros y pulgadas)
A2: Sistemas del Funcionamiento del Motor (MA.02.06) · Unidad 1 · Metrología · Edite solo las celdas amarillas (texto azul).
AS3: Parámetros de los instrumentos (no editar)
A4: Configuración | B4: Valor | AS4: Tipo | AT4: inch | AU4: sd | AV4: divs | AW4: Nt | AX4: apt | AY4: vern | AZ4: ap | BA4: dec
A5: Instrumento y resolución (modo aleatorio) | B5: Milímetro · 0,01 mm | AS5: Milímetro · 0,01 mm | AT5: 0 | AU5: 0.5 | AV5: 50 | AW5: 50 | AX5: 0.01 | AY5: 0 | AZ5: 0.01 | BA5: 2
A6: Número de ejercicio (aleatorio: 1 – 999; guía: n.º de la tabla) | B6: 1 | AS6: Milímetro · 0,001 mm (con nonio) | AT6: 0 | AU6: 0.5 | AV6: 50 | AW6: 50 | AX6: 0.01 | AY6: 1 | AZ6: 0.001 | BA6: 3
A7: Alcance inicial del micrómetro (modo aleatorio) | B7: 0 | AS7: Pulgada · 0,001" | AT7: 1 | AU7: 0.025 | AV7: 40 | AW7: 25 | AX7: 0.001 | AY7: 0 | AZ7: 0.001 | BA7: 3
A8: Ejercicio de la guía (elija el banco) | B8: Guía 03 · Tabla 19 · 0,0001" · ej. 41-60 | AS8: Pulgada · 0,0001" (con nonio) | AT8: 1 | AU8: 0.025 | AV8: 40 | AW8: 25 | AX8: 0.001 | AY8: 1 | AZ8: 0.0001 | BA8: 4
A9: Respuesta del estudiante | B9: Valor
A10: Su lectura (en la unidad del instrumento)
A11: ¿Mostrar el solucionario? (SI / NO) | B11: NO
A13: =IF($B$64=0,"Ese número no está en el banco elegido: use del "&$B$63&" al "&($B$63+19),IF(B10="","Escriba su lectura en la celda B10",IF(OR(ABS(B10-$B$51)<$B$47/2,ABS(ROUNDDOWN(B10,$B$53)-$B$51)<$B$47/100),"¡Correcto! Lectura bien hecha","Revise la lectura: siga los pasos del solucionario"))) -> Ese número no está en el banco elegido: use del 41 al 60
A14: =IF($B$56=1,"Ejercicio "&$B$6&" · "&$B$8&" (mismo valor que el solucionario de la guía)","Ejercicio aleatorio n.º "&$B$6) -> Ejercicio 1 · Guía 03 · Tabla 19 · 0,0001" · ej. 41-60 (mismo valor que el solucionario de la guía)
A15: Solucionario comentado
A16: =IF($B$11="SI","1. Alcance inicial","") | B16: =IF($B$11="SI","El micrómetro empieza en "&Micrómetro!$B$58&IF(Micrómetro!$B$41=1," pulg"," mm"),"")
A17: =IF($B$11="SI","2. Vaina (cilindro)","") | B17: =IF($B$11="SI","Se ven "&Micrómetro!$B$48&" divisiones de "&FIXED(Micrómetro!$B$42,IF(Micrómetro!$B$41=1,3,1),TRUE)&IF(Micrómetro!$B$41=1," pulg"," mm")&" → "&FIXED(Micrómetro!$B$48*Micrómetro!$B$42,IF(Micrómetro!$B$41=1,3,1),TRUE)&IF(Micrómetro!$B$41=1," pulg"," mm")&IF(Micrómetro!$B$41=0," (enteros arriba y medios milímetros abajo de la línea)"," (cada número de la vaina = 0,100 pulg)"),"")
A18: =IF($B$11="SI","3. Tambor","") | B18: =IF($B$11="SI","La línea "&Micrómetro!$B$49&" del tambor coincide con la línea de referencia → "&Micrómetro!$B$49&" × "&FIXED(Micrómetro!$B$45,IF(Micrómetro!$B$41=1,3,2),TRUE)&" = "&FIXED(Micrómetro!$B$49*Micrómetro!$B$45,IF(Micrómetro!$B$41=1,3,2),TRUE)&IF(Micrómetro!$B$41=1," pulg"," mm"),"")
A19: =IF($B$11="SI","4. Nonio","") | B19: =IF($B$11="SI",IF(Micrómetro!$B$46=0,"Este micrómetro no tiene nonio","La línea "&Micrómetro!$B$50&" del nonio coincide con una línea del tambor → "&Micrómetro!$B$50&" × "&FIXED(Micrómetro!$B$47,Micrómetro!$B$53,TRUE)&" = "&FIXED(Micrómetro!$B$50*Micrómetro!$B$47,Micrómetro!$B$53,TRUE)&IF(Micrómetro!$B$41=1," pulg"," mm")),"")
A20: =IF($B$11="SI","5. Lectura","") | B20: =IF($B$11="SI",Micrómetro!$B$58&" + "&FIXED(Micrómetro!$B$48*Micrómetro!$B$42,IF(Micrómetro!$B$41=1,3,1),TRUE)&" + "&FIXED(Micrómetro!$B$49*Micrómetro!$B$45,IF(Micrómetro!$B$41=1,3,2),TRUE)&IF(Micrómetro!$B$46=1," + "&FIXED(Micrómetro!$B$50*Micrómetro!$B$47,Micrómetro!$B$53,TRUE),"")&" = "&FIXED(Micrómetro!$B$51,Micrómetro!$B$53,TRUE)&IF(Micrómetro!$B$41=1," pulg"," mm"),"")
A21: =IF($B$11="SI","6. Interpretación","") | B21: =IF($B$11="SI","El alcance de este micrómetro es "&$B$58&"–"&($B$58+IF($B$41=1,1,25))&IF($B$41=1," in"," mm")&"; el tambor dejó a la vista "&$B$48&" divisiones de la vaina, la marca "&$B$49&" del tambor coincide con la línea de referencia"&IF($B$46=1," y la línea "&$B$50&" del nonio coincide con una línea del tambor","")&". Lectura: "&FIXED($B$51,$B$53,TRUE)&IF($B$41=1," in"," mm")&IF(ISNUMBER($B$61)," (Stefanelli estima además la cifra siguiente: "&FIXED($B$61,$B$53+1,TRUE)&")",""),"")
A22: Lista de práctica | B22: Valor
A23: Número de lista (aleatorio: 1 – 99; guía: 1 – 2) | B23: 1
A25: Ejercicio (escríbalo en B6) | B25: Su lectura | C25: Resultado | D25: Solución | BC25: Lectura (aux.) | BD25: Solución (aux.)
A26: =IF($B$56=1,$B$63+($B$23-1)*10+0,($B$23-1)*10+1) -> 41 | C26: =IF(B26="","",IF(BC26="","—",IF(OR(ABS(B26-BC26)<$B$47/2,ABS(ROUNDDOWN(B26,$B$53)-BC26)<$B$47/100),"Correcto","Incorrecto"))) | D26: =IF($B$11="SI",BD26,"") | BC26: =IF($B$56=1,IFERROR(INDEX('Datos guía'!$E$5:$E$544,MATCH($B$8&"|"&$A26,'Datos guía'!$A$5:$A$544,0)),""),$B$58+MOD($A26*7919+104729,$B$43)*$B$42+MOD($A26*15485863+7,$B$44)*$B$45+$B$46*MOD($A26*31+17,10)*$B$45/10) -> 6.4181 | BD26: =IF($B$56=1,IFERROR(INDEX('Datos guía'!$F$5:$F$544,MATCH($B$8&"|"&$A26,'Datos guía'!$A$5:$A$544,0)),"No está en el banco"),FIXED(BC26,$B$53,TRUE)&IF($B$41=1," pulg"," mm")) -> 6,4181 in
A27: =IF($B$56=1,$B$63+($B$23-1)*10+1,($B$23-1)*10+2) -> 42 | C27: =IF(B27="","",IF(BC27="","—",IF(OR(ABS(B27-BC27)<$B$47/2,ABS(ROUNDDOWN(B27,$B$53)-BC27)<$B$47/100),"Correcto","Incorrecto"))) | D27: =IF($B$11="SI",BD27,"") | BC27: =IF($B$56=1,IFERROR(INDEX('Datos guía'!$E$5:$E$544,MATCH($B$8&"|"&$A27,'Datos guía'!$A$5:$A$544,0)),""),$B$58+MOD($A27*7919+104729,$B$43)*$B$42+MOD($A27*15485863+7,$B$44)*$B$45+$B$46*MOD($A27*31+17,10)*$B$45/10) -> 19.6867 | BD27: =IF($B$56=1,IFERROR(INDEX('Datos guía'!$F$5:$F$544,MATCH($B$8&"|"&$A27,'Datos guía'!$A$5:$A$544,0)),"No está en el banco"),FIXED(BC27,$B$53,TRUE)&IF($B$41=1," pulg"," mm")) -> 19,6867 in
A28: =IF($B$56=1,$B$63+($B$23-1)*10+2,($B$23-1)*10+3) -> 43 | C28: =IF(B28="","",IF(BC28="","—",IF(OR(ABS(B28-BC28)<$B$47/2,ABS(ROUNDDOWN(B28,$B$53)-BC28)<$B$47/100),"Correcto","Incorrecto"))) | D28: =IF($B$11="SI",BD28,"") | BC28: =IF($B$56=1,IFERROR(INDEX('Datos guía'!$E$5:$E$544,MATCH($B$8&"|"&$A28,'Datos guía'!$A$5:$A$544,0)),""),$B$58+MOD($A28*7919+104729,$B$43)*$B$42+MOD($A28*15485863+7,$B$44)*$B$45+$B$46*MOD($A28*31+17,10)*$B$45/10) -> 11.6159 | BD28: =IF($B$56=1,IFERROR(INDEX('Datos guía'!$F$5:$F$544,MATCH($B$8&"|"&$A28,'Datos guía'!$A$5:$A$544,0)),"No está en el banco"),FIXED(BC28,$B$53,TRUE)&IF($B$41=1," pulg"," mm")) -> 11,6159 in
A29: =IF($B$56=1,$B$63+($B$23-1)*10+3,($B$23-1)*10+4) -> 44 | C29: =IF(B29="","",IF(BC29="","—",IF(OR(ABS(B29-BC29)<$B$47/2,ABS(ROUNDDOWN(B29,$B$53)-BC29)<$B$47/100),"Correcto","Incorrecto"))) | D29: =IF($B$11="SI",BD29,"") | BC29: =IF($B$56=1,IFERROR(INDEX('Datos guía'!$E$5:$E$544,MATCH($B$8&"|"&$A29,'Datos guía'!$A$5:$A$544,0)),""),$B$58+MOD($A29*7919+104729,$B$43)*$B$42+MOD($A29*15485863+7,$B$44)*$B$45+$B$46*MOD($A29*31+17,10)*$B$45/10) -> 28.6317 | BD29: =IF($B$56=1,IFERROR(INDEX('Datos guía'!$F$5:$F$544,MATCH($B$8&"|"&$A29,'Datos guía'!$A$5:$A$544,0)),"No está en el banco"),FIXED(BC29,$B$53,TRUE)&IF($B$41=1," pulg"," mm")) -> 28,6317 in
A30: =IF($B$56=1,$B$63+($B$23-1)*10+4,($B$23-1)*10+5) -> 45 | C30: =IF(B30="","",IF(BC30="","—",IF(OR(ABS(B30-BC30)<$B$47/2,ABS(ROUNDDOWN(B30,$B$53)-BC30)<$B$47/100),"Correcto","Incorrecto"))) | D30: =IF($B$11="SI",BD30,"") | BC30: =IF($B$56=1,IFERROR(INDEX('Datos guía'!$E$5:$E$544,MATCH($B$8&"|"&$A30,'Datos guía'!$A$5:$A$544,0)),""),$B$58+MOD($A30*7919+104729,$B$43)*$B$42+MOD($A30*15485863+7,$B$44)*$B$45+$B$46*MOD($A30*31+17,10)*$B$45/10) -> 11.8251 | BD30: =IF($B$56=1,IFERROR(INDEX('Datos guía'!$F$5:$F$544,MATCH($B$8&"|"&$A30,'Datos guía'!$A$5:$A$544,0)),"No está en el banco"),FIXED(BC30,$B$53,TRUE)&IF($B$41=1," pulg"," mm")) -> 11,8251 in
A31: =IF($B$56=1,$B$63+($B$23-1)*10+5,($B$23-1)*10+6) -> 46 | C31: =IF(B31="","",IF(BC31="","—",IF(OR(ABS(B31-BC31)<$B$47/2,ABS(ROUNDDOWN(B31,$B$53)-BC31)<$B$47/100),"Correcto","Incorrecto"))) | D31: =IF($B$11="SI",BD31,"") | BC31: =IF($B$56=1,IFERROR(INDEX('Datos guía'!$E$5:$E$544,MATCH($B$8&"|"&$A31,'Datos guía'!$A$5:$A$544,0)),""),$B$58+MOD($A31*7919+104729,$B$43)*$B$42+MOD($A31*15485863+7,$B$44)*$B$45+$B$46*MOD($A31*31+17,10)*$B$45/10) -> 1.5996 | BD31: =IF($B$56=1,IFERROR(INDEX('Datos guía'!$F$5:$F$544,MATCH($B$8&"|"&$A31,'Datos guía'!$A$5:$A$544,0)),"No está en el banco"),FIXED(BC31,$B$53,TRUE)&IF($B$41=1," pulg"," mm")) -> 1,5996 in
A32: =IF($B$56=1,$B$63+($B$23-1)*10+6,($B$23-1)*10+7) -> 47 | C32: =IF(B32="","",IF(BC32="","—",IF(OR(ABS(B32-BC32)<$B$47/2,ABS(ROUNDDOWN(B32,$B$53)-BC32)<$B$47/100),"Correcto","Incorrecto"))) | D32: =IF($B$11="SI",BD32,"") | BC32: =IF($B$56=1,IFERROR(INDEX('Datos guía'!$E$5:$E$544,MATCH($B$8&"|"&$A32,'Datos guía'!$A$5:$A$544,0)),""),$B$58+MOD($A32*7919+104729,$B$43)*$B$42+MOD($A32*15485863+7,$B$44)*$B$45+$B$46*MOD($A32*31+17,10)*$B$45/10) -> 12.7951 | BD32: =IF($B$56=1,IFERROR(INDEX('Datos guía'!$F$5:$F$544,MATCH($B$8&"|"&$A32,'Datos guía'!$A$5:$A$544,0)),"No está en el banco"),FIXED(BC32,$B$53,TRUE)&IF($B$41=1," pulg"," mm")) -> 12,7951 in
A33: =IF($B$56=1,$B$63+($B$23-1)*10+7,($B$23-1)*10+8) -> 48 | C33: =IF(B33="","",IF(BC33="","—",IF(OR(ABS(B33-BC33)<$B$47/2,ABS(ROUNDDOWN(B33,$B$53)-BC33)<$B$47/100),"Correcto","Incorrecto"))) | D33: =IF($B$11="SI",BD33,"") | BC33: =IF($B$56=1,IFERROR(INDEX('Datos guía'!$E$5:$E$544,MATCH($B$8&"|"&$A33,'Datos guía'!$A$5:$A$544,0)),""),$B$58+MOD($A33*7919+104729,$B$43)*$B$42+MOD($A33*15485863+7,$B$44)*$B$45+$B$46*MOD($A33*31+17,10)*$B$45/10) -> 3.2419 | BD33: =IF($B$56=1,IFERROR(INDEX('Datos guía'!$F$5:$F$544,MATCH($B$8&"|"&$A33,'Datos guía'!$A$5:$A$544,0)),"No está en el banco"),FIXED(BC33,$B$53,TRUE)&IF($B$41=1," pulg"," mm")) -> 3,2419 in
A34: =IF($B$56=1,$B$63+($B$23-1)*10+8,($B$23-1)*10+9) -> 49 | C34: =IF(B34="","",IF(BC34="","—",IF(OR(ABS(B34-BC34)<$B$47/2,ABS(ROUNDDOWN(B34,$B$53)-BC34)<$B$47/100),"Correcto","Incorrecto"))) | D34: =IF($B$11="SI",BD34,"") | BC34: =IF($B$56=1,IFERROR(INDEX('Datos guía'!$E$5:$E$544,MATCH($B$8&"|"&$A34,'Datos guía'!$A$5:$A$544,0)),""),$B$58+MOD($A34*7919+104729,$B$43)*$B$42+MOD($A34*15485863+7,$B$44)*$B$45+$B$46*MOD($A34*31+17,10)*$B$45/10) -> 9.3004 | BD34: =IF($B$56=1,IFERROR(INDEX('Datos guía'!$F$5:$F$544,MATCH($B$8&"|"&$A34,'Datos guía'!$A$5:$A$544,0)),"No está en el banco"),FIXED(BC34,$B$53,TRUE)&IF($B$41=1," pulg"," mm")) -> 9,3004 in
A35: =IF($B$56=1,$B$63+($B$23-1)*10+9,($B$23-1)*10+10) -> 50 | C35: =IF(B35="","",IF(BC35="","—",IF(OR(ABS(B35-BC35)<$B$47/2,ABS(ROUNDDOWN(B35,$B$53)-BC35)<$B$47/100),"Correcto","Incorrecto"))) | D35: =IF($B$11="SI",BD35,"") | BC35: =IF($B$56=1,IFERROR(INDEX('Datos guía'!$E$5:$E$544,MATCH($B$8&"|"&$A35,'Datos guía'!$A$5:$A$544,0)),""),$B$58+MOD($A35*7919+104729,$B$43)*$B$42+MOD($A35*15485863+7,$B$44)*$B$45+$B$46*MOD($A35*31+17,10)*$B$45/10) -> 27.4711 | BD35: =IF($B$56=1,IFERROR(INDEX('Datos guía'!$F$5:$F$544,MATCH($B$8&"|"&$A35,'Datos guía'!$A$5:$A$544,0)),"No está en el banco"),FIXED(BC35,$B$53,TRUE)&IF($B$41=1," pulg"," mm")) -> 27,4711 in
A37: =COUNTIF(C26:C35,"Correcto")&" de 10 correctas" -> 0 de 10 correctas
A40: Cálculos internos (no editar) | B40: Valor
A41: Sistema (0 = mm, 1 = pulgada) | B41: =INDEX($AT$5:$AT$8,MATCH($B$59,$AS$5:$AS$8,0)) -> 0
A42: Valor de una división de la vaina | B42: =INDEX($AU$5:$AU$8,MATCH($B$59,$AS$5:$AS$8,0)) -> 0.5
A43: Divisiones de la vaina en el rango | B43: =INDEX($AV$5:$AV$8,MATCH($B$59,$AS$5:$AS$8,0)) -> 50
A44: Divisiones del tambor | B44: =INDEX($AW$5:$AW$8,MATCH($B$59,$AS$5:$AS$8,0)) -> 50
A45: Valor de una división del tambor | B45: =INDEX($AX$5:$AX$8,MATCH($B$59,$AS$5:$AS$8,0)) -> 0.01
...

Sheet Reloj comparador
A1: Simulador · Reloj comparador (milímetros y pulgadas)
A2: Sistemas del Funcionamiento del Motor (MA.02.06) · Unidad 1 · Metrología · Edite solo las celdas amarillas (texto azul).
AS3: Parámetros de los instrumentos (no editar)
A4: Configuración | B4: Valor | AS4: Tipo | AT4: inch | AU4: ap | AV4: vuelta | AW4: dec
A5: Instrumento y resolución | B5: Milímetro · 0,01 mm (1 mm por vuelta) | AS5: Milímetro · 0,01 mm (1 mm por vuelta) | AT5: 0 | AU5: 0.01 | AV5: 1 | AW5: 2
A6: Número de ejercicio (1 – 999) | B6: 1 | AS6: Pulgada · 0,001" (0,100" por vuelta) | AT6: 1 | AU6: 0.001 | AV6: 0.1 | AW6: 3
A8: Respuesta del estudiante | B8: Valor
A9: Su lectura (en la unidad del instrumento)
A10: ¿Mostrar el solucionario? (SI / NO) | B10: NO
A12: =IF(B9="","Escriba su lectura en la celda B9",IF(ABS(B9-$B$46)<$B$42/2,"¡Correcto! Lectura bien hecha","Revise la lectura: siga los pasos del solucionario")) -> Escriba su lectura en la celda B9
A14: Solucionario comentado
A15: =IF($B$10="SI","1. Cuentavueltas","") | B15: =IF($B$10="SI","La aguja pequeña pasó "&'Reloj comparador'!$B$44&" vueltas de "&FIXED('Reloj comparador'!$B$43,IF('Reloj comparador'!$B$41=1,3,0),TRUE)&IF('Reloj comparador'!$B$41=1," pulg"," mm")&" → "&FIXED('Reloj comparador'!$B$44*'Reloj comparador'!$B$43,'Reloj comparador'!$B$47,TRUE)&IF('Reloj comparador'!$B$41=1," pulg"," mm"),"")
A16: =IF($B$10="SI","2. Aguja grande","") | B16: =IF($B$10="SI","La aguja grande marca "&'Reloj comparador'!$B$45&" divisiones × "&FIXED('Reloj comparador'!$B$42,'Reloj comparador'!$B$47,TRUE)&" = "&FIXED('Reloj comparador'!$B$45*'Reloj comparador'!$B$42,'Reloj comparador'!$B$47,TRUE)&IF('Reloj comparador'!$B$41=1," pulg"," mm"),"")
A17: =IF($B$10="SI","3. Lectura","") | B17: =IF($B$10="SI",FIXED('Reloj comparador'!$B$44*'Reloj comparador'!$B$43,'Reloj comparador'!$B$47,TRUE)&" + "&FIXED('Reloj comparador'!$B$45*'Reloj comparador'!$B$42,'Reloj comparador'!$B$47,TRUE)&" = "&FIXED('Reloj comparador'!$B$46,'Reloj comparador'!$B$47,TRUE)&IF('Reloj comparador'!$B$41=1," pulg"," mm"),"")
A18: =IF($B$10="SI","Recuerde","") | B18: =IF($B$10="SI","El reloj mide desplazamientos respecto al cero ajustado: excentricidad, juego axial, saliente o planitud","")
A20: Lista de práctica | B20: Valor
A21: Número de lista (1 – 99) | B21: 1
A23: Ejercicio (escríbalo en B6) | B23: Su lectura | C23: Resultado | D23: Solución
