Workbook

Sheet Presion_cilindro
A1: Avance del encendido · Desarrollo de la presión de combustión p(α)
A2: Reproduce la figura 2.20: presión en el cilindro frente al ángulo del cigüeñal α, con combustión normal (1), desarrollo irregular de la combustión / detonación (2) y la curva sin combustión (arrastre). Modelo de una zona: compresión y expansión politrópicas y liberación de calor con la ley de Wiebe. Cambie solo las celdas amarillas (azul = dato). Valores orientativos con fines didácticos. | N2: Tabla de cálculo (paso 0,5°)
N3: α (°) | O3: V (cm³) | P3: x_b curva 1 | Q3: p curva 1 (bar) | R3: p arrastre (bar) | S3: x_b curva 2 | T3: p curva 2 sin ondas (bar) | U3: p curva 2 (bar) | V3: W₁ (J) | W3: W₂ (J)
A4: Geometría del motor | N4: -180 | O4: =$B$30+PI()/4*($B$5/10)^2*($B$31+$B$7/10-$B$31*COS(RADIANS(N4))-SQRT(($B$7/10)^2-($B$31*SIN(RADIANS(N4)))^2)) -> 403.24087 | P4: =IF(N4>$B$36,1-EXP(-$B$16*((N4-$B$36)/$B$35)^($B$17+1)),0) -> 0 | Q4: =$B$32 -> 0.72 | R4: =$B$32 -> 0.72 | S4: =IF(N4<=$B$38,IF(N4>$B$37,1-EXP(-$B$16*((N4-$B$37)/$B$35)^($B$17+1)),0),$B$22+(1-$B$22)*(1-EXP(-(N4-$B$38)/$B$23))) -> 0 | T4: =$B$32 -> 0.72 | U4: =T4+IF(N4>$B$38,$B$24*EXP(-(N4-$B$38)/$B$26)*SIN(2*PI()*(N4-$B$38)/$B$39),0) -> 0.72 | V4: 0 | W4: 0
A5: Diámetro del cilindro D | B5: 76 | C5: mm | N5: -179.5 | O5: =$B$30+PI()/4*($B$5/10)^2*($B$31+$B$7/10-$B$31*COS(RADIANS(N5))-SQRT(($B$7/10)^2-($B$31*SIN(RADIANS(N5)))^2)) -> 403.23594 | P5: =IF(N5>$B$36,1-EXP(-$B$16*((N5-$B$36)/$B$35)^($B$17+1)),0) -> 0 | Q5: =Q4*(O4/O5)^$B$9+10*($B$9-1)*$B$33*(P5-P4)/((O4+O5)/2) -> 0.72001172 | R5: =R4*(O4/O5)^$B$9 -> 0.72001172 | S5: =IF(N5<=$B$38,IF(N5>$B$37,1-EXP(-$B$16*((N5-$B$37)/$B$35)^($B$17+1)),0),$B$22+(1-$B$22)*(1-EXP(-(N5-$B$38)/$B$23))) -> 0 | T5: =T4*(O4/O5)^$B$9+10*($B$9-1)*$B$33*(S5-S4)/((O4+O5)/2) -> 0.72001172 | U5: =T5+IF(N5>$B$38,$B$24*EXP(-(N5-$B$38)/$B$26)*SIN(2*PI()*(N5-$B$38)/$B$39),0) -> 0.72001172 | V5: =V4+(Q4+Q5)/2*(O5-O4)/10 -> -0.0003553449 | W5: =W4+(T4+T5)/2*(O5-O4)/10 -> -0.0003553449
A6: Carrera S | B6: 80 | C6: mm | N6: -179 | O6: =$B$30+PI()/4*($B$5/10)^2*($B$31+$B$7/10-$B$31*COS(RADIANS(N6))-SQRT(($B$7/10)^2-($B$31*SIN(RADIANS(N6)))^2)) -> 403.22113 | P6: =IF(N6>$B$36,1-EXP(-$B$16*((N6-$B$36)/$B$35)^($B$17+1)),0) -> 0 | Q6: =Q5*(O5/O6)^$B$9+10*($B$9-1)*$B$33*(P6-P5)/((O5+O6)/2) -> 0.72004688 | R6: =R5*(O5/O6)^$B$9 -> 0.72004688 | S6: =IF(N6<=$B$38,IF(N6>$B$37,1-EXP(-$B$16*((N6-$B$37)/$B$35)^($B$17+1)),0),$B$22+(1-$B$22)*(1-EXP(-(N6-$B$38)/$B$23))) -> 0 | T6: =T5*(O5/O6)^$B$9+10*($B$9-1)*$B$33*(S6-S5)/((O5+O6)/2) -> 0.72004688 | U6: =T6+IF(N6>$B$38,$B$24*EXP(-(N6-$B$38)/$B$26)*SIN(2*PI()*(N6-$B$38)/$B$39),0) -> 0.72004688 | V6: =V5+(Q5+Q6)/2*(O6-O5)/10 -> -0.0014214171 | W6: =W5+(T5+T6)/2*(O6-O5)/10 -> -0.0014214171
A7: Longitud de biela L | B7: 140 | C7: mm | N7: -178.5 | O7: =$B$30+PI()/4*($B$5/10)^2*($B$31+$B$7/10-$B$31*COS(RADIANS(N7))-SQRT(($B$7/10)^2-($B$31*SIN(RADIANS(N7)))^2)) -> 403.19645 | P7: =IF(N7>$B$36,1-EXP(-$B$16*((N7-$B$36)/$B$35)^($B$17+1)),0) -> 0 | Q7: =Q6*(O6/O7)^$B$9+10*($B$9-1)*$B$33*(P7-P6)/((O6+O7)/2) -> 0.7201055 | R7: =R6*(O6/O7)^$B$9 -> 0.7201055 | S7: =IF(N7<=$B$38,IF(N7>$B$37,1-EXP(-$B$16*((N7-$B$37)/$B$35)^($B$17+1)),0),$B$22+(1-$B$22)*(1-EXP(-(N7-$B$38)/$B$23))) -> 0 | T7: =T6*(O6/O7)^$B$9+10*($B$9-1)*$B$33*(S7-S6)/((O6+O7)/2) -> 0.7201055 | U7: =T7+IF(N7>$B$38,$B$24*EXP(-(N7-$B$38)/$B$26)*SIN(2*PI()*(N7-$B$38)/$B$39),0) -> 0.7201055 | V7: =V6+(Q6+Q7)/2*(O7-O6)/10 -> -0.0031983289 | W7: =W6+(T6+T7)/2*(O7-O6)/10 -> -0.0031983289
A8: Relación de compresión ε | B8: 10 | C8: — | N8: -178 | O8: =$B$30+PI()/4*($B$5/10)^2*($B$31+$B$7/10-$B$31*COS(RADIANS(N8))-SQRT(($B$7/10)^2-($B$31*SIN(RADIANS(N8)))^2)) -> 403.1619 | P8: =IF(N8>$B$36,1-EXP(-$B$16*((N8-$B$36)/$B$35)^($B$17+1)),0) -> 0 | Q8: =Q7*(O7/O8)^$B$9+10*($B$9-1)*$B$33*(P8-P7)/((O7+O8)/2) -> 0.72018757 | R8: =R7*(O7/O8)^$B$9 -> 0.72018757 | S8: =IF(N8<=$B$38,IF(N8>$B$37,1-EXP(-$B$16*((N8-$B$37)/$B$35)^($B$17+1)),0),$B$22+(1-$B$22)*(1-EXP(-(N8-$B$38)/$B$23))) -> 0 | T8: =T7*(O7/O8)^$B$9+10*($B$9-1)*$B$33*(S8-S7)/((O7+O8)/2) -> 0.72018757 | U8: =T8+IF(N8>$B$38,$B$24*EXP(-(N8-$B$38)/$B$26)*SIN(2*PI()*(N8-$B$38)/$B$39),0) -> 0.72018757 | V8: =V7+(Q7+Q8)/2*(O8-O7)/10 -> -0.0056862677 | W8: =W7+(T7+T8)/2*(O8-O7)/10 -> -0.0056862677
A9: Exponente politrópico γ | B9: 1.33 | C9: — | N9: -177.5 | O9: =$B$30+PI()/4*($B$5/10)^2*($B$31+$B$7/10-$B$31*COS(RADIANS(N9))-SQRT(($B$7/10)^2-($B$31*SIN(RADIANS(N9)))^2)) -> 403.11749 | P9: =IF(N9>$B$36,1-EXP(-$B$16*((N9-$B$36)/$B$35)^($B$17+1)),0) -> 0 | Q9: =Q8*(O8/O9)^$B$9+10*($B$9-1)*$B$33*(P9-P8)/((O8+O9)/2) -> 0.72029311 | R9: =R8*(O8/O9)^$B$9 -> 0.72029311 | S9: =IF(N9<=$B$38,IF(N9>$B$37,1-EXP(-$B$16*((N9-$B$37)/$B$35)^($B$17+1)),0),$B$22+(1-$B$22)*(1-EXP(-(N9-$B$38)/$B$23))) -> 0 | T9: =T8*(O8/O9)^$B$9+10*($B$9-1)*$B$33*(S9-S8)/((O8+O9)/2) -> 0.72029311 | U9: =T9+IF(N9>$B$38,$B$24*EXP(-(N9-$B$38)/$B$26)*SIN(2*PI()*(N9-$B$38)/$B$39),0) -> 0.72029311 | V9: =V8+(Q8+Q9)/2*(O9-O8)/10 -> -0.008885496 | W9: =W8+(T8+T9)/2*(O9-O8)/10 -> -0.008885496
A10: Funcionamiento | N10: -177 | O10: =$B$30+PI()/4*($B$5/10)^2*($B$31+$B$7/10-$B$31*COS(RADIANS(N10))-SQRT(($B$7/10)^2-($B$31*SIN(RADIANS(N10)))^2)) -> 403.0632 | P10: =IF(N10>$B$36,1-EXP(-$B$16*((N10-$B$36)/$B$35)^($B$17+1)),0) -> 0 | Q10: =Q9*(O9/O10)^$B$9+10*($B$9-1)*$B$33*(P10-P9)/((O9+O10)/2) -> 0.72042215 | R10: =R9*(O9/O10)^$B$9 -> 0.72042215 | S10: =IF(N10<=$B$38,IF(N10>$B$37,1-EXP(-$B$16*((N10-$B$37)/$B$35)^($B$17+1)),0),$B$22+(1-$B$22)*(1-EXP(-(N10-$B$38)/$B$23))) -> 0 | T10: =T9*(O9/O10)^$B$9+10*($B$9-1)*$B$33*(S10-S9)/((O9+O10)/2) -> 0.72042215 | U10: =T10+IF(N10>$B$38,$B$24*EXP(-(N10-$B$38)/$B$26)*SIN(2*PI()*(N10-$B$38)/$B$39),0) -> 0.72042215 | V10: =V9+(Q9+Q10)/2*(O10-O9)/10 -> -0.012796351 | W10: =W9+(T9+T10)/2*(O10-O9)/10 -> -0.012796351
A11: Régimen n | B11: 2000 | C11: rpm | N11: -176.5 | O11: =$B$30+PI()/4*($B$5/10)^2*($B$31+$B$7/10-$B$31*COS(RADIANS(N11))-SQRT(($B$7/10)^2-($B$31*SIN(RADIANS(N11)))^2)) -> 402.99903 | P11: =IF(N11>$B$36,1-EXP(-$B$16*((N11-$B$36)/$B$35)^($B$17+1)),0) -> 0 | Q11: =Q10*(O10/O11)^$B$9+10*($B$9-1)*$B$33*(P11-P10)/((O10+O11)/2) -> 0.72057471 | R11: =R10*(O10/O11)^$B$9 -> 0.72057471 | S11: =IF(N11<=$B$38,IF(N11>$B$37,1-EXP(-$B$16*((N11-$B$37)/$B$35)^($B$17+1)),0),$B$22+(1-$B$22)*(1-EXP(-(N11-$B$38)/$B$23))) -> 0 | T11: =T10*(O10/O11)^$B$9+10*($B$9-1)*$B$33*(S11-S10)/((O10+O11)/2) -> 0.72057471 | U11: =T11+IF(N11>$B$38,$B$24*EXP(-(N11-$B$38)/$B$26)*SIN(2*PI()*(N11-$B$38)/$B$39),0) -> 0.72057471 | V11: =V10+(Q10+Q11)/2*(O11-O10)/10 -> -0.017419245 | W11: =W10+(T10+T11)/2*(O11-O10)/10 -> -0.017419245
A12: Carga (apertura de mariposa) | B12: 0.6 | C12: % | N12: -176 | O12: =$B$30+PI()/4*($B$5/10)^2*($B$31+$B$7/10-$B$31*COS(RADIANS(N12))-SQRT(($B$7/10)^2-($B$31*SIN(RADIANS(N12)))^2)) -> 402.925 | P12: =IF(N12>$B$36,1-EXP(-$B$16*((N12-$B$36)/$B$35)^($B$17+1)),0) -> 0 | Q12: =Q11*(O11/O12)^$B$9+10*($B$9-1)*$B$33*(P12-P11)/((O11+O12)/2) -> 0.72075081 | R12: =R11*(O11/O12)^$B$9 -> 0.72075081 | S12: =IF(N12<=$B$38,IF(N12>$B$37,1-EXP(-$B$16*((N12-$B$37)/$B$35)^($B$17+1)),0),$B$22+(1-$B$22)*(1-EXP(-(N12-$B$38)/$B$23))) -> 0 | T12: =T11*(O11/O12)^$B$9+10*($B$9-1)*$B$33*(S12-S11)/((O11+O12)/2) -> 0.72075081 | U12: =T12+IF(N12>$B$38,$B$24*EXP(-(N12-$B$38)/$B$26)*SIN(2*PI()*(N12-$B$38)/$B$39),0) -> 0.72075081 | V12: =V11+(Q11+Q12)/2*(O12-O11)/10 -> -0.022754666 | W12: =W11+(T11+T12)/2*(O12-O11)/10 -> -0.022754666
A13: Calor aportado a plena carga Q | B13: 650 | C13: J | N13: -175.5 | O13: =$B$30+PI()/4*($B$5/10)^2*($B$31+$B$7/10-$B$31*COS(RADIANS(N13))-SQRT(($B$7/10)^2-($B$31*SIN(RADIANS(N13)))^2)) -> 402.84109 | P13: =IF(N13>$B$36,1-EXP(-$B$16*((N13-$B$36)/$B$35)^($B$17+1)),0) -> 0 | Q13: =Q12*(O12/O13)^$B$9+10*($B$9-1)*$B$33*(P13-P12)/((O12+O13)/2) -> 0.72095048 | R13: =R12*(O12/O13)^$B$9 -> 0.72095048 | S13: =IF(N13<=$B$38,IF(N13>$B$37,1-EXP(-$B$16*((N13-$B$37)/$B$35)^($B$17+1)),0),$B$22+(1-$B$22)*(1-EXP(-(N13-$B$38)/$B$23))) -> 0 | T13: =T12*(O12/O13)^$B$9+10*($B$9-1)*$B$33*(S13-S12)/((O12+O13)/2) -> 0.72095048 | U13: =T13+IF(N13>$B$38,$B$24*EXP(-(N13-$B$38)/$B$26)*SIN(2*PI()*(N13-$B$38)/$B$39),0) -> 0.72095048 | V13: =V12+(Q12+Q13)/2*(O13-O12)/10 -> -0.028803176 | W13: =W12+(T12+T13)/2*(O13-O12)/10 -> -0.028803176
A14: Retardo de inflamación | B14: 0.6 | C14: ms | N14: -175 | O14: =$B$30+PI()/4*($B$5/10)^2*($B$31+$B$7/10-$B$31*COS(RADIANS(N14))-SQRT(($B$7/10)^2-($B$31*SIN(RADIANS(N14)))^2)) -> 402.74731 | P14: =IF(N14>$B$36,1-EXP(-$B$16*((N14-$B$36)/$B$35)^($B$17+1)),0) -> 0 | Q14: =Q13*(O13/O14)^$B$9+10*($B$9-1)*$B$33*(P14-P13)/((O13+O14)/2) -> 0.72117376 | R14: =R13*(O13/O14)^$B$9 -> 0.72117376 | S14: =IF(N14<=$B$38,IF(N14>$B$37,1-EXP(-$B$16*((N14-$B$37)/$B$35)^($B$17+1)),0),$B$22+(1-$B$22)*(1-EXP(-(N14-$B$38)/$B$23))) -> 0 | T14: =T13*(O13/O14)^$B$9+10*($B$9-1)*$B$33*(S14-S13)/((O13+O14)/2) -> 0.72117376 | U14: =T14+IF(N14>$B$38,$B$24*EXP(-(N14-$B$38)/$B$26)*SIN(2*PI()*(N14-$B$38)/$B$39),0) -> 0.72117376 | V14: =V13+(Q13+Q14)/2*(O14-O13)/10 -> -0.035565413 | W14: =W13+(T13+T14)/2*(O14-O13)/10 -> -0.035565413
A15: Duración de la combustión a plena carga | B15: 40 | C15: ° | N15: -174.5 | O15: =$B$30+PI()/4*($B$5/10)^2*($B$31+$B$7/10-$B$31*COS(RADIANS(N15))-SQRT(($B$7/10)^2-($B$31*SIN(RADIANS(N15)))^2)) -> 402.64365 | P15: =IF(N15>$B$36,1-EXP(-$B$16*((N15-$B$36)/$B$35)^($B$17+1)),0) -> 0 | Q15: =Q14*(O14/O15)^$B$9+10*($B$9-1)*$B$33*(P15-P14)/((O14+O15)/2) -> 0.7214207 | R15: =R14*(O14/O15)^$B$9 -> 0.7214207 | S15: =IF(N15<=$B$38,IF(N15>$B$37,1-EXP(-$B$16*((N15-$B$37)/$B$35)^($B$17+1)),0),$B$22+(1-$B$22)*(1-EXP(-(N15-$B$38)/$B$23))) -> 0 | T15: =T14*(O14/O15)^$B$9+10*($B$9-1)*$B$33*(S15-S14)/((O14+O15)/2) -> 0.7214207 | U15: =T15+IF(N15>$B$38,$B$24*EXP(-(N15-$B$38)/$B$26)*SIN(2*PI()*(N15-$B$38)/$B$39),0) -> 0.7214207 | V15: =V14+(Q14+Q15)/2*(O15-O14)/10 -> -0.043042091 | W15: =W14+(T14+T15)/2*(O15-O14)/10 -> -0.043042091
A16: Parámetro de Wiebe a | B16: 5 | C16: — | N16: -174 | O16: =$B$30+PI()/4*($B$5/10)^2*($B$31+$B$7/10-$B$31*COS(RADIANS(N16))-SQRT(($B$7/10)^2-($B$31*SIN(RADIANS(N16)))^2)) -> 402.53012 | P16: =IF(N16>$B$36,1-EXP(-$B$16*((N16-$B$36)/$B$35)^($B$17+1)),0) -> 0 | Q16: =Q15*(O15/O16)^$B$9+10*($B$9-1)*$B$33*(P16-P15)/((O15+O16)/2) -> 0.72169133 | R16: =R15*(O15/O16)^$B$9 -> 0.72169133 | S16: =IF(N16<=$B$38,IF(N16>$B$37,1-EXP(-$B$16*((N16-$B$37)/$B$35)^($B$17+1)),0),$B$22+(1-$B$22)*(1-EXP(-(N16-$B$38)/$B$23))) -> 0 | T16: =T15*(O15/O16)^$B$9+10*($B$9-1)*$B$33*(S16-S15)/((O15+O16)/2) -> 0.72169133 | U16: =T16+IF(N16>$B$38,$B$24*EXP(-(N16-$B$38)/$B$26)*SIN(2*PI()*(N16-$B$38)/$B$39),0) -> 0.72169133 | V16: =V15+(Q15+Q16)/2*(O16-O15)/10 -> -0.051233998 | W16: =W15+(T15+T16)/2*(O16-O15)/10 -> -0.051233998
A17: Parámetro de forma m | B17: 2 | C17: — | N17: -173.5 | O17: =$B$30+PI()/4*($B$5/10)^2*($B$31+$B$7/10-$B$31*COS(RADIANS(N17))-SQRT(($B$7/10)^2-($B$31*SIN(RADIANS(N17)))^2)) -> 402.40671 | P17: =IF(N17>$B$36,1-EXP(-$B$16*((N17-$B$36)/$B$35)^($B$17+1)),0) -> 0 | Q17: =Q16*(O16/O17)^$B$9+10*($B$9-1)*$B$33*(P17-P16)/((O16+O17)/2) -> 0.72198571 | R17: =R16*(O16/O17)^$B$9 -> 0.72198571 | S17: =IF(N17<=$B$38,IF(N17>$B$37,1-EXP(-$B$16*((N17-$B$37)/$B$35)^($B$17+1)),0),$B$22+(1-$B$22)*(1-EXP(-(N17-$B$38)/$B$23))) -> 0 | T17: =T16*(O16/O17)^$B$9+10*($B$9-1)*$B$33*(S17-S16)/((O16+O17)/2) -> 0.72198571 | U17: =T17+IF(N17>$B$38,$B$24*EXP(-(N17-$B$38)/$B$26)*SIN(2*PI()*(N17-$B$38)/$B$39),0) -> 0.72198571 | V17: =V16+(Q16+Q17)/2*(O17-O16)/10 -> -0.060141998 | W17: =W16+(T16+T17)/2*(O17-O16)/10 -> -0.060141998
A18: Curva 1 · Combustión normal | N18: -173 | O18: =$B$30+PI()/4*($B$5/10)^2*($B$31+$B$7/10-$B$31*COS(RADIANS(N18))-SQRT(($B$7/10)^2-($B$31*SIN(RADIANS(N18)))^2)) -> 402.27343 | P18: =IF(N18>$B$36,1-EXP(-$B$16*((N18-$B$36)/$B$35)^($B$17+1)),0) -> 0 | Q18: =Q17*(O17/O18)^$B$9+10*($B$9-1)*$B$33*(P18-P17)/((O17+O18)/2) -> 0.72230388 | R18: =R17*(O17/O18)^$B$9 -> 0.72230388 | S18: =IF(N18<=$B$38,IF(N18>$B$37,1-EXP(-$B$16*((N18-$B$37)/$B$35)^($B$17+1)),0),$B$22+(1-$B$22)*(1-EXP(-(N18-$B$38)/$B$23))) -> 0 | T18: =T17*(O17/O18)^$B$9+10*($B$9-1)*$B$33*(S18-S17)/((O17+O18)/2) -> 0.72230388 | U18: =T18+IF(N18>$B$38,$B$24*EXP(-(N18-$B$38)/$B$26)*SIN(2*PI()*(N18-$B$38)/$B$39),0) -> 0.72230388 | V18: =V17+(Q17+Q18)/2*(O18-O17)/10 -> -0.069767032 | W18: =W17+(T17+T18)/2*(O18-O17)/10 -> -0.069767032
A19: Avance del encendido AE (curva 1) | B19: 30 | C19: ° APMS | N19: -172.5 | O19: =$B$30+PI()/4*($B$5/10)^2*($B$31+$B$7/10-$B$31*COS(RADIANS(N19))-SQRT(($B$7/10)^2-($B$31*SIN(RADIANS(N19)))^2)) -> 402.13027 | P19: =IF(N19>$B$36,1-EXP(-$B$16*((N19-$B$36)/$B$35)^($B$17+1)),0) -> 0 | Q19: =Q18*(O18/O19)^$B$9+10*($B$9-1)*$B$33*(P19-P18)/((O18+O19)/2) -> 0.7226459 | R19: =R18*(O18/O19)^$B$9 -> 0.7226459 | S19: =IF(N19<=$B$38,IF(N19>$B$37,1-EXP(-$B$16*((N19-$B$37)/$B$35)^($B$17+1)),0),$B$22+(1-$B$22)*(1-EXP(-(N19-$B$38)/$B$23))) -> 0 | T19: =T18*(O18/O19)^$B$9+10*($B$9-1)*$B$33*(S19-S18)/((O18+O19)/2) -> 0.7226459 | U19: =T19+IF(N19>$B$38,$B$24*EXP(-(N19-$B$38)/$B$26)*SIN(2*PI()*(N19-$B$38)/$B$39),0) -> 0.7226459 | V19: =V18+(Q18+Q19)/2*(O19-O18)/10 -> -0.080110113 | W19: =W18+(T18+T19)/2*(O19-O18)/10 -> -0.080110113
A20: Curva 2 · Desarrollo irregular (detonación) | N20: -172 | O20: =$B$30+PI()/4*($B$5/10)^2*($B$31+$B$7/10-$B$31*COS(RADIANS(N20))-SQRT(($B$7/10)^2-($B$31*SIN(RADIANS(N20)))^2)) -> 401.97723 | P20: =IF(N20>$B$36,1-EXP(-$B$16*((N20-$B$36)/$B$35)^($B$17+1)),0) -> 0 | Q20: =Q19*(O19/O20)^$B$9+10*($B$9-1)*$B$33*(P20-P19)/((O19+O20)/2) -> 0.72301184 | R20: =R19*(O19/O20)^$B$9 -> 0.72301184 | S20: =IF(N20<=$B$38,IF(N20>$B$37,1-EXP(-$B$16*((N20-$B$37)/$B$35)^($B$17+1)),0),$B$22+(1-$B$22)*(1-EXP(-(N20-$B$38)/$B$23))) -> 0 | T20: =T19*(O19/O20)^$B$9+10*($B$9-1)*$B$33*(S20-S19)/((O19+O20)/2) -> 0.72301184 | U20: =T20+IF(N20>$B$38,$B$24*EXP(-(N20-$B$38)/$B$26)*SIN(2*PI()*(N20-$B$38)/$B$39),0) -> 0.72301184 | V20: =V19+(Q19+Q20)/2*(O20-O19)/10 -> -0.091172335 | W20: =W19+(T19+T20)/2*(O20-O19)/10 -> -0.091172335
A21: Avance del encendido AE (curva 2) | B21: 34 | C21: ° APMS | N21: -171.5 | O21: =$B$30+PI()/4*($B$5/10)^2*($B$31+$B$7/10-$B$31*COS(RADIANS(N21))-SQRT(($B$7/10)^2-($B$31*SIN(RADIANS(N21)))^2)) -> 401.81431 | P21: =IF(N21>$B$36,1-EXP(-$B$16*((N21-$B$36)/$B$35)^($B$17+1)),0) -> 0 | Q21: =Q20*(O20/O21)^$B$9+10*($B$9-1)*$B$33*(P21-P20)/((O20+O21)/2) -> 0.72340176 | R21: =R20*(O20/O21)^$B$9 -> 0.72340176 | S21: =IF(N21<=$B$38,IF(N21>$B$37,1-EXP(-$B$16*((N21-$B$37)/$B$35)^($B$17+1)),0),$B$22+(1-$B$22)*(1-EXP(-(N21-$B$38)/$B$23))) -> 0 | T21: =T20*(O20/O21)^$B$9+10*($B$9-1)*$B$33*(S21-S20)/((O20+O21)/2) -> 0.72340176 | U21: =T21+IF(N21>$B$38,$B$24*EXP(-(N21-$B$38)/$B$26)*SIN(2*PI()*(N21-$B$38)/$B$39),0) -> 0.72340176 | V21: =V20+(Q20+Q21)/2*(O21-O20)/10 -> -0.10295486 | W21: =W20+(T20+T21)/2*(O21-O20)/10 -> -0.10295486
A22: Fracción quemada al iniciar la detonación | B22: 0.6 | C22: — | N22: -171 | O22: =$B$30+PI()/4*($B$5/10)^2*($B$31+$B$7/10-$B$31*COS(RADIANS(N22))-SQRT(($B$7/10)^2-($B$31*SIN(RADIANS(N22)))^2)) -> 401.64151 | P22: =IF(N22>$B$36,1-EXP(-$B$16*((N22-$B$36)/$B$35)^($B$17+1)),0) -> 0 | Q22: =Q21*(O21/O22)^$B$9+10*($B$9-1)*$B$33*(P22-P21)/((O21+O22)/2) -> 0.72381573 | R22: =R21*(O21/O22)^$B$9 -> 0.72381573 | S22: =IF(N22<=$B$38,IF(N22>$B$37,1-EXP(-$B$16*((N22-$B$37)/$B$35)^($B$17+1)),0),$B$22+(1-$B$22)*(1-EXP(-(N22-$B$38)/$B$23))) -> 0 | T22: =T21*(O21/O22)^$B$9+10*($B$9-1)*$B$33*(S22-S21)/((O21+O22)/2) -> 0.72381573 | U22: =T22+IF(N22>$B$38,$B$24*EXP(-(N22-$B$38)/$B$26)*SIN(2*PI()*(N22-$B$38)/$B$39),0) -> 0.72381573 | V22: =V21+(Q21+Q22)/2*(O22-O21)/10 -> -0.11545894 | W22: =W21+(T21+T22)/2*(O22-O21)/10 -> -0.11545894
A23: Rapidez de la combustión detonante τ | B23: 1.5 | C23: ° | N23: -170.5 | O23: =$B$30+PI()/4*($B$5/10)^2*($B$31+$B$7/10-$B$31*COS(RADIANS(N23))-SQRT(($B$7/10)^2-($B$31*SIN(RADIANS(N23)))^2)) -> 401.45882 | P23: =IF(N23>$B$36,1-EXP(-$B$16*((N23-$B$36)/$B$35)^($B$17+1)),0) -> 0 | Q23: =Q22*(O22/O23)^$B$9+10*($B$9-1)*$B$33*(P23-P22)/((O22+O23)/2) -> 0.72425383 | R23: =R22*(O22/O23)^$B$9 -> 0.72425383 | S23: =IF(N23<=$B$38,IF(N23>$B$37,1-EXP(-$B$16*((N23-$B$37)/$B$35)^($B$17+1)),0),$B$22+(1-$B$22)*(1-EXP(-(N23-$B$38)/$B$23))) -> 0 | T23: =T22*(O22/O23)^$B$9+10*($B$9-1)*$B$33*(S23-S22)/((O22+O23)/2) -> 0.72425383 | U23: =T23+IF(N23>$B$38,$B$24*EXP(-(N23-$B$38)/$B$26)*SIN(2*PI()*(N23-$B$38)/$B$39),0) -> 0.72425383 | V23: =V22+(Q22+Q23)/2*(O23-O22)/10 -> -0.1286859 | W23: =W22+(T22+T23)/2*(O23-O22)/10 -> -0.1286859
A24: Amplitud de las oscilaciones | B24: 3 | C24: bar | N24: -170 | O24: =$B$30+PI()/4*($B$5/10)^2*($B$31+$B$7/10-$B$31*COS(RADIANS(N24))-SQRT(($B$7/10)^2-($B$31*SIN(RADIANS(N24)))^2)) -> 401.26625 | P24: =IF(N24>$B$36,1-EXP(-$B$16*((N24-$B$36)/$B$35)^($B$17+1)),0) -> 0 | Q24: =Q23*(O23/O24)^$B$9+10*($B$9-1)*$B$33*(P24-P23)/((O23+O24)/2) -> 0.72471614 | R24: =R23*(O23/O24)^$B$9 -> 0.72471614 | S24: =IF(N24<=$B$38,IF(N24>$B$37,1-EXP(-$B$16*((N24-$B$37)/$B$35)^($B$17+1)),0),$B$22+(1-$B$22)*(1-EXP(-(N24-$B$38)/$B$23))) -> 0 | T24: =T23*(O23/O24)^$B$9+10*($B$9-1)*$B$33*(S24-S23)/((O23+O24)/2) -> 0.72471614 | U24: =T24+IF(N24>$B$38,$B$24*EXP(-(N24-$B$38)/$B$26)*SIN(2*PI()*(N24-$B$38)/$B$39),0) -> 0.72471614 | V24: =V23+(Q23+Q24)/2*(O24-O23)/10 -> -0.14263711 | W24: =W23+(T23+T24)/2*(O24-O23)/10 -> -0.14263711
A25: Frecuencia de las oscilaciones | B25: 6 | C25: kHz | N25: -169.5 | O25: =$B$30+PI()/4*($B$5/10)^2*($B$31+$B$7/10-$B$31*COS(RADIANS(N25))-SQRT(($B$7/10)^2-($B$31*SIN(RADIANS(N25)))^2)) -> 401.0638 | P25: =IF(N25>$B$36,1-EXP(-$B$16*((N25-$B$36)/$B$35)^($B$17+1)),0) -> 0 | Q25: =Q24*(O24/O25)^$B$9+10*($B$9-1)*$B$33*(P25-P24)/((O24+O25)/2) -> 0.72520273 | R25: =R24*(O24/O25)^$B$9 -> 0.72520273 | S25: =IF(N25<=$B$38,IF(N25>$B$37,1-EXP(-$B$16*((N25-$B$37)/$B$35)^($B$17+1)),0),$B$22+(1-$B$22)*(1-EXP(-(N25-$B$38)/$B$23))) -> 0 | T25: =T24*(O24/O25)^$B$9+10*($B$9-1)*$B$33*(S25-S24)/((O24+O25)/2) -> 0.72520273 | U25: =T25+IF(N25>$B$38,$B$24*EXP(-(N25-$B$38)/$B$26)*SIN(2*PI()*(N25-$B$38)/$B$39),0) -> 0.72520273 | V25: =V24+(Q24+Q25)/2*(O25-O24)/10 -> -0.15731407 | W25: =W24+(T24+T25)/2*(O25-O24)/10 -> -0.15731407
A26: Amortiguación de las oscilaciones | B26: 10 | C26: ° | N26: -169 | O26: =$B$30+PI()/4*($B$5/10)^2*($B$31+$B$7/10-$B$31*COS(RADIANS(N26))-SQRT(($B$7/10)^2-($B$31*SIN(RADIANS(N26)))^2)) -> 400.85146 | P26: =IF(N26>$B$36,1-EXP(-$B$16*((N26-$B$36)/$B$35)^($B$17+1)),0) -> 0 | Q26: =Q25*(O25/O26)^$B$9+10*($B$9-1)*$B$33*(P26-P25)/((O25+O26)/2) -> 0.7257137 | R26: =R25*(O25/O26)^$B$9 -> 0.7257137 | S26: =IF(N26<=$B$38,IF(N26>$B$37,1-EXP(-$B$16*((N26-$B$37)/$B$35)^($B$17+1)),0),$B$22+(1-$B$22)*(1-EXP(-(N26-$B$38)/$B$23))) -> 0 | T26: =T25*(O25/O26)^$B$9+10*($B$9-1)*$B$33*(S26-S25)/((O25+O26)/2) -> 0.7257137 | U26: =T26+IF(N26>$B$38,$B$24*EXP(-(N26-$B$38)/$B$26)*SIN(2*PI()*(N26-$B$38)/$B$39),0) -> 0.7257137 | V26: =V25+(Q25+Q26)/2*(O26-O25)/10 -> -0.17271832 | W26: =W25+(T25+T26)/2*(O26-O25)/10 -> -0.17271832
N27: -168.5 | O27: =$B$30+PI()/4*($B$5/10)^2*($B$31+$B$7/10-$B$31*COS(RADIANS(N27))-SQRT(($B$7/10)^2-($B$31*SIN(RADIANS(N27)))^2)) -> 400.62924 | P27: =IF(N27>$B$36,1-EXP(-$B$16*((N27-$B$36)/$B$35)^($B$17+1)),0) -> 0 | Q27: =Q26*(O26/O27)^$B$9+10*($B$9-1)*$B$33*(P27-P26)/((O26+O27)/2) -> 0.72624913 | R27: =R26*(O26/O27)^$B$9 -> 0.72624913 | S27: =IF(N27<=$B$38,IF(N27>$B$37,1-EXP(-$B$16*((N27-$B$37)/$B$35)^($B$17+1)),0),$B$22+(1-$B$22)*(1-EXP(-(N27-$B$38)/$B$23))) -> 0 | T27: =T26*(O26/O27)^$B$9+10*($B$9-1)*$B$33*(S27-S26)/((O26+O27)/2) -> 0.72624913 | U27: =T27+IF(N27>$B$38,$B$24*EXP(-(N27-$B$38)/$B$26)*SIN(2*PI()*(N27-$B$38)/$B$39),0) -> 0.72624913 | V27: =V26+(Q26+Q27)/2*(O27-O26)/10 -> -0.18885148 | W27: =W26+(T26+T27)/2*(O27-O26)/10 -> -0.18885148
A28: Valores calculados | N28: -168 | O28: =$B$30+PI()/4*($B$5/10)^2*($B$31+$B$7/10-$B$31*COS(RADIANS(N28))-SQRT(($B$7/10)^2-($B$31*SIN(RADIANS(N28)))^2)) -> 400.39712 | P28: =IF(N28>$B$36,1-EXP(-$B$16*((N28-$B$36)/$B$35)^($B$17+1)),0) -> 0 | Q28: =Q27*(O27/O28)^$B$9+10*($B$9-1)*$B$33*(P28-P27)/((O27+O28)/2) -> 0.72680913 | R28: =R27*(O27/O28)^$B$9 -> 0.72680913 | S28: =IF(N28<=$B$38,IF(N28>$B$37,1-EXP(-$B$16*((N28-$B$37)/$B$35)^($B$17+1)),0),$B$22+(1-$B$22)*(1-EXP(-(N28-$B$38)/$B$23))) -> 0 | T28: =T27*(O27/O28)^$B$9+10*($B$9-1)*$B$33*(S28-S27)/((O27+O28)/2) -> 0.72680913 | U28: =T28+IF(N28>$B$38,$B$24*EXP(-(N28-$B$38)/$B$26)*SIN(2*PI()*(N28-$B$38)/$B$39),0) -> 0.72680913 | V28: =V27+(Q27+Q28)/2*(O28-O27)/10 -> -0.20571527 | W28: =W27+(T27+T28)/2*(O28-O27)/10 -> -0.20571527
A29: Cilindrada unitaria Vd | B29: =PI()/4*($B$5/10)^2*($B$6/10) -> 362.91678 | C29: cm³ | N29: -167.5 | O29: =$B$30+PI()/4*($B$5/10)^2*($B$31+$B$7/10-$B$31*COS(RADIANS(N29))-SQRT(($B$7/10)^2-($B$31*SIN(RADIANS(N29)))^2)) -> 400.15512 | P29: =IF(N29>$B$36,1-EXP(-$B$16*((N29-$B$36)/$B$35)^($B$17+1)),0) -> 0 | Q29: =Q28*(O28/O29)^$B$9+10*($B$9-1)*$B$33*(P29-P28)/((O28+O29)/2) -> 0.7273938 | R29: =R28*(O28/O29)^$B$9 -> 0.7273938 | S29: =IF(N29<=$B$38,IF(N29>$B$37,1-EXP(-$B$16*((N29-$B$37)/$B$35)^($B$17+1)),0),$B$22+(1-$B$22)*(1-EXP(-(N29-$B$38)/$B$23))) -> 0 | T29: =T28*(O28/O29)^$B$9+10*($B$9-1)*$B$33*(S29-S28)/((O28+O29)/2) -> 0.7273938 | U29: =T29+IF(N29>$B$38,$B$24*EXP(-(N29-$B$38)/$B$26)*SIN(2*PI()*(N29-$B$38)/$B$39),0) -> 0.7273938 | V29: =V28+(Q28+Q29)/2*(O29-O28)/10 -> -0.22331145 | W29: =W28+(T28+T29)/2*(O29-O28)/10 -> -0.22331145
A30: Volumen de la cámara Vc | B30: =$B$29/($B$8-1) -> 40.324087 | C30: cm³ | N30: -167 | O30: =$B$30+PI()/4*($B$5/10)^2*($B$31+$B$7/10-$B$31*COS(RADIANS(N30))-SQRT(($B$7/10)^2-($B$31*SIN(RADIANS(N30)))^2)) -> 399.90322 | P30: =IF(N30>$B$36,1-EXP(-$B$16*((N30-$B$36)/$B$35)^($B$17+1)),0) -> 0 | Q30: =Q29*(O29/O30)^$B$9+10*($B$9-1)*$B$33*(P30-P29)/((O29+O30)/2) -> 0.72800325 | R30: =R29*(O29/O30)^$B$9 -> 0.72800325 | S30: =IF(N30<=$B$38,IF(N30>$B$37,1-EXP(-$B$16*((N30-$B$37)/$B$35)^($B$17+1)),0),$B$22+(1-$B$22)*(1-EXP(-(N30-$B$38)/$B$23))) -> 0 | T30: =T29*(O29/O30)^$B$9+10*($B$9-1)*$B$33*(S30-S29)/((O29+O30)/2) -> 0.72800325 | U30: =T30+IF(N30>$B$38,$B$24*EXP(-(N30-$B$38)/$B$26)*SIN(2*PI()*(N30-$B$38)/$B$39),0) -> 0.72800325 | V30: =V29+(Q29+Q30)/2*(O30-O29)/10 -> -0.2416419 | W30: =W29+(T29+T30)/2*(O30-O29)/10 -> -0.2416419
A31: Radio de la manivela r | B31: =$B$6/20 -> 4 | C31: cm | N31: -166.5 | O31: =$B$30+PI()/4*($B$5/10)^2*($B$31+$B$7/10-$B$31*COS(RADIANS(N31))-SQRT(($B$7/10)^2-($B$31*SIN(RADIANS(N31)))^2)) -> 399.64143 | P31: =IF(N31>$B$36,1-EXP(-$B$16*((N31-$B$36)/$B$35)^($B$17+1)),0) -> 0 | Q31: =Q30*(O30/O31)^$B$9+10*($B$9-1)*$B$33*(P31-P30)/((O30+O31)/2) -> 0.72863757 | R31: =R30*(O30/O31)^$B$9 -> 0.72863757 | S31: =IF(N31<=$B$38,IF(N31>$B$37,1-EXP(-$B$16*((N31-$B$37)/$B$35)^($B$17+1)),0),$B$22+(1-$B$22)*(1-EXP(-(N31-$B$38)/$B$23))) -> 0 | T31: =T30*(O30/O31)^$B$9+10*($B$9-1)*$B$33*(S31-S30)/((O30+O31)/2) -> 0.72863757 | U31: =T31+IF(N31>$B$38,$B$24*EXP(-(N31-$B$38)/$B$26)*SIN(2*PI()*(N31-$B$38)/$B$39),0) -> 0.72863757 | V31: =V30+(Q30+Q31)/2*(O31-O30)/10 -> -0.26070855 | W31: =W30+(T30+T31)/2*(O31-O30)/10 -> -0.26070855
A32: Presión al cerrar la admisión p₀ | B32: =0.3+0.7*$B$12 -> 0.72 | C32: bar | N32: -166 | O32: =$B$30+PI()/4*($B$5/10)^2*($B$31+$B$7/10-$B$31*COS(RADIANS(N32))-SQRT(($B$7/10)^2-($B$31*SIN(RADIANS(N32)))^2)) -> 399.36975 | P32: =IF(N32>$B$36,1-EXP(-$B$16*((N32-$B$36)/$B$35)^($B$17+1)),0) -> 0 | Q32: =Q31*(O31/O32)^$B$9+10*($B$9-1)*$B$33*(P32-P31)/((O31+O32)/2) -> 0.7292969 | R32: =R31*(O31/O32)^$B$9 -> 0.7292969 | S32: =IF(N32<=$B$38,IF(N32>$B$37,1-EXP(-$B$16*((N32-$B$37)/$B$35)^($B$17+1)),0),$B$22+(1-$B$22)*(1-EXP(-(N32-$B$38)/$B$23))) -> 0 | T32: =T31*(O31/O32)^$B$9+10*($B$9-1)*$B$33*(S32-S31)/((O31+O32)/2) -> 0.7292969 | U32: =T32+IF(N32>$B$38,$B$24*EXP(-(N32-$B$38)/$B$26)*SIN(2*PI()*(N32-$B$38)/$B$39),0) -> 0.7292969 | V32: =V31+(Q31+Q32)/2*(O32-O31)/10 -> -0.28051341 | W32: =W31+(T31+T32)/2*(O32-O31)/10 -> -0.28051341
A33: Calor aportado Q | B33: =$B$13*$B$12 -> 390 | C33: J | N33: -165.5 | O33: =$B$30+PI()/4*($B$5/10)^2*($B$31+$B$7/10-$B$31*COS(RADIANS(N33))-SQRT(($B$7/10)^2-($B$31*SIN(RADIANS(N33)))^2)) -> 399.08817 | P33: =IF(N33>$B$36,1-EXP(-$B$16*((N33-$B$36)/$B$35)^($B$17+1)),0) -> 0 | Q33: =Q32*(O32/O33)^$B$9+10*($B$9-1)*$B$33*(P33-P32)/((O32+O33)/2) -> 0.72998135 | R33: =R32*(O32/O33)^$B$9 -> 0.72998135 | S33: =IF(N33<=$B$38,IF(N33>$B$37,1-EXP(-$B$16*((N33-$B$37)/$B$35)^($B$17+1)),0),$B$22+(1-$B$22)*(1-EXP(-(N33-$B$38)/$B$23))) -> 0 | T33: =T32*(O32/O33)^$B$9+10*($B$9-1)*$B$33*(S33-S32)/((O32+O33)/2) -> 0.72998135 | U33: =T33+IF(N33>$B$38,$B$24*EXP(-(N33-$B$38)/$B$26)*SIN(2*PI()*(N33-$B$38)/$B$39),0) -> 0.72998135 | V33: =V32+(Q32+Q33)/2*(O33-O32)/10 -> -0.30105858 | W33: =W32+(T32+T33)/2*(O33-O32)/10 -> -0.30105858
A34: Retardo de inflamación en grados | B34: =6*$B$11*$B$14/1000 -> 7.2 | C34: ° | N34: -165 | O34: =$B$30+PI()/4*($B$5/10)^2*($B$31+$B$7/10-$B$31*COS(RADIANS(N34))-SQRT(($B$7/10)^2-($B$31*SIN(RADIANS(N34)))^2)) -> 398.79669 | P34: =IF(N34>$B$36,1-EXP(-$B$16*((N34-$B$36)/$B$35)^($B$17+1)),0) -> 0 | Q34: =Q33*(O33/O34)^$B$9+10*($B$9-1)*$B$33*(P34-P33)/((O33+O34)/2) -> 0.73069104 | R34: =R33*(O33/O34)^$B$9 -> 0.73069104 | S34: =IF(N34<=$B$38,IF(N34>$B$37,1-EXP(-$B$16*((N34-$B$37)/$B$35)^($B$17+1)),0),$B$22+(1-$B$22)*(1-EXP(-(N34-$B$38)/$B$23))) -> 0 | T34: =T33*(O33/O34)^$B$9+10*($B$9-1)*$B$33*(S34-S33)/((O33+O34)/2) -> 0.73069104 | U34: =T34+IF(N34>$B$38,$B$24*EXP(-(N34-$B$38)/$B$26)*SIN(2*PI()*(N34-$B$38)/$B$39),0) -> 0.73069104 | V34: =V33+(Q33+Q34)/2*(O34-O33)/10 -> -0.32234623 | W34: =W33+(T33+T34)/2*(O34-O33)/10 -> -0.32234623
A35: Duración de la combustión | B35: =$B$15*(1+0.6*(1-$B$12)) -> 49.6 | C35: ° | N35: -164.5 | O35: =$B$30+PI()/4*($B$5/10)^2*($B$31+$B$7/10-$B$31*COS(RADIANS(N35))-SQRT(($B$7/10)^2-($B$31*SIN(RADIANS(N35)))^2)) -> 398.49532 | P35: =IF(N35>$B$36,1-EXP(-$B$16*((N35-$B$36)/$B$35)^($B$17+1)),0) -> 0 | Q35: =Q34*(O34/O35)^$B$9+10*($B$9-1)*$B$33*(P35-P34)/((O34+O35)/2) -> 0.7314261 | R35: =R34*(O34/O35)^$B$9 -> 0.7314261 | S35: =IF(N35<=$B$38,IF(N35>$B$37,1-EXP(-$B$16*((N35-$B$37)/$B$35)^($B$17+1)),0),$B$22+(1-$B$22)*(1-EXP(-(N35-$B$38)/$B$23))) -> 0 | T35: =T34*(O34/O35)^$B$9+10*($B$9-1)*$B$33*(S35-S34)/((O34+O35)/2) -> 0.7314261 | U35: =T35+IF(N35>$B$38,$B$24*EXP(-(N35-$B$38)/$B$26)*SIN(2*PI()*(N35-$B$38)/$B$39),0) -> 0.7314261 | V35: =V34+(Q34+Q35)/2*(O35-O34)/10 -> -0.3443786 | W35: =W34+(T34+T35)/2*(O35-O34)/10 -> -0.3443786
A36: Inicio de la combustión (curva 1) | B36: =-$B$19+$B$34 -> -22.8 | C36: ° | N36: -164 | O36: =$B$30+PI()/4*($B$5/10)^2*($B$31+$B$7/10-$B$31*COS(RADIANS(N36))-SQRT(($B$7/10)^2-($B$31*SIN(RADIANS(N36)))^2)) -> 398.18404 | P36: =IF(N36>$B$36,1-EXP(-$B$16*((N36-$B$36)/$B$35)^($B$17+1)),0) -> 0 | Q36: =Q35*(O35/O36)^$B$9+10*($B$9-1)*$B$33*(P36-P35)/((O35+O36)/2) -> 0.73218668 | R36: =R35*(O35/O36)^$B$9 -> 0.73218668 | S36: =IF(N36<=$B$38,IF(N36>$B$37,1-EXP(-$B$16*((N36-$B$37)/$B$35)^($B$17+1)),0),$B$22+(1-$B$22)*(1-EXP(-(N36-$B$38)/$B$23))) -> 0 | T36: =T35*(O35/O36)^$B$9+10*($B$9-1)*$B$33*(S36-S35)/((O35+O36)/2) -> 0.73218668 | U36: =T36+IF(N36>$B$38,$B$24*EXP(-(N36-$B$38)/$B$26)*SIN(2*PI()*(N36-$B$38)/$B$39),0) -> 0.73218668 | V36: =V35+(Q35+Q36)/2*(O36-O35)/10 -> -0.36715804 | W36: =W35+(T35+T36)/2*(O36-O35)/10 -> -0.36715804
A37: Inicio de la combustión (curva 2) | B37: =-$B$21+$B$34 -> -26.8 | C37: ° | N37: -163.5 | O37: =$B$30+PI()/4*($B$5/10)^2*($B$31+$B$7/10-$B$31*COS(RADIANS(N37))-SQRT(($B$7/10)^2-($B$31*SIN(RADIANS(N37)))^2)) -> 397.86286 | P37: =IF(N37>$B$36,1-EXP(-$B$16*((N37-$B$36)/$B$35)^($B$17+1)),0) -> 0 | Q37: =Q36*(O36/O37)^$B$9+10*($B$9-1)*$B$33*(P37-P36)/((O36+O37)/2) -> 0.7329729 | R37: =R36*(O36/O37)^$B$9 -> 0.7329729 | S37: =IF(N37<=$B$38,IF(N37>$B$37,1-EXP(-$B$16*((N37-$B$37)/$B$35)^($B$17+1)),0),$B$22+(1-$B$22)*(1-EXP(-(N37-$B$38)/$B$23))) -> 0 | T37: =T36*(O36/O37)^$B$9+10*($B$9-1)*$B$33*(S37-S36)/((O36+O37)/2) -> 0.7329729 | U37: =T37+IF(N37>$B$38,$B$24*EXP(-(N37-$B$38)/$B$26)*SIN(2*PI()*(N37-$B$38)/$B$39),0) -> 0.7329729 | V37: =V36+(Q36+Q37)/2*(O37-O36)/10 -> -0.39068696 | W37: =W36+(T36+T37)/2*(O37-O36)/10 -> -0.39068696
A38: Ángulo de inicio de la detonación | B38: =$B$37+$B$35*(-LN(1-$B$22)/$B$16)^(1/($B$17+1)) -> 1.3731953 | C38: ° | N38: -163 | O38: =$B$30+PI()/4*($B$5/10)^2*($B$31+$B$7/10-$B$31*COS(RADIANS(N38))-SQRT(($B$7/10)^2-($B$31*SIN(RADIANS(N38)))^2)) -> 397.53178 | P38: =IF(N38>$B$36,1-EXP(-$B$16*((N38-$B$36)/$B$35)^($B$17+1)),0) -> 0 | Q38: =Q37*(O37/O38)^$B$9+10*($B$9-1)*$B$33*(P38-P37)/((O37+O38)/2) -> 0.73378491 | R38: =R37*(O37/O38)^$B$9 -> 0.73378491 | S38: =IF(N38<=$B$38,IF(N38>$B$37,1-EXP(-$B$16*((N38-$B$37)/$B$35)^($B$17+1)),0),$B$22+(1-$B$22)*(1-EXP(-(N38-$B$38)/$B$23))) -> 0 | T38: =T37*(O37/O38)^$B$9+10*($B$9-1)*$B$33*(S38-S37)/((O37+O38)/2) -> 0.73378491 | U38: =T38+IF(N38>$B$38,$B$24*EXP(-(N38-$B$38)/$B$26)*SIN(2*PI()*(N38-$B$38)/$B$39),0) -> 0.73378491 | V38: =V37+(Q37+Q38)/2*(O38-O37)/10 -> -0.41496783 | W38: =W37+(T37+T38)/2*(O38-O37)/10 -> -0.41496783
A39: Periodo de las oscilaciones | B39: =6*$B$11/($B$25*1000) -> 2 | C39: ° | N39: -162.5 | O39: =$B$30+PI()/4*($B$5/10)^2*($B$31+$B$7/10-$B$31*COS(RADIANS(N39))-SQRT(($B$7/10)^2-($B$31*SIN(RADIANS(N39)))^2)) -> 397.19079 | P39: =IF(N39>$B$36,1-EXP(-$B$16*((N39-$B$36)/$B$35)^($B$17+1)),0) -> 0 | Q39: =Q38*(O38/O39)^$B$9+10*($B$9-1)*$B$33*(P39-P38)/((O38+O39)/2) -> 0.73462287 | R39: =R38*(O38/O39)^$B$9 -> 0.73462287 | S39: =IF(N39<=$B$38,IF(N39>$B$37,1-EXP(-$B$16*((N39-$B$37)/$B$35)^($B$17+1)),0),$B$22+(1-$B$22)*(1-EXP(-(N39-$B$38)/$B$23))) -> 0 | T39: =T38*(O38/O39)^$B$9+10*($B$9-1)*$B$33*(S39-S38)/((O38+O39)/2) -> 0.73462287 | U39: =T39+IF(N39>$B$38,$B$24*EXP(-(N39-$B$38)/$B$26)*SIN(2*PI()*(N39-$B$38)/$B$39),0) -> 0.73462287 | V39: =V38+(Q38+Q39)/2*(O39-O38)/10 -> -0.44000323 | W39: =W38+(T38+T39)/2*(O39-O38)/10 -> -0.44000323
N40: -162 | O40: =$B$30+PI()/4*($B$5/10)^2*($B$31+$B$7/10-$B$31*COS(RADIANS(N40))-SQRT(($B$7/10)^2-($B$31*SIN(RADIANS(N40)))^2)) -> 396.8399 | P40: =IF(N40>$B$36,1-EXP(-$B$16*((N40-$B$36)/$B$35)^($B$17+1)),0) -> 0 | Q40: =Q39*(O39/O40)^$B$9+10*($B$9-1)*$B$33*(P40-P39)/((O39+O40)/2) -> 0.73548692 | R40: =R39*(O39/O40)^$B$9 -> 0.73548692 | S40: =IF(N40<=$B$38,IF(N40>$B$37,1-EXP(-$B$16*((N40-$B$37)/$B$35)^($B$17+1)),0),$B$22+(1-$B$22)*(1-EXP(-(N40-$B$38)/$B$23))) -> 0 | T40: =T39*(O39/O40)^$B$9+10*($B$9-1)*$B$33*(S40-S39)/((O39+O40)/2) -> 0.73548692 | U40: =T40+IF(N40>$B$38,$B$24*EXP(-(N40-$B$38)/$B$26)*SIN(2*PI()*(N40-$B$38)/$B$39),0) -> 0.73548692 | V40: =V39+(Q39+Q40)/2*(O40-O39)/10 -> -0.46579582 | W40: =W39+(T39+T40)/2*(O40-O39)/10 -> -0.46579582
...

Sheet Tres_avances
A1: Presión en la cámara con avance correcto, demasiado avanzado y demasiado retardado
A2: Reproduce la figura «Desarrollo de la presión en la cámara de combustión a diferente avance de encendido»: Za correcto (azul), Zb demasiado avanzado con detonación (verde) y Zc demasiado retardado (rojo). El eje horizontal es el ángulo del cigüeñal respecto del PMS: positivo = antes del PMS, negativo = después (como en la figura, de 75° a −75°). Usa la geometría, rpm y carga de la hoja Presion_cilindro.
A4: Datos | N4: α_z (° APMS) | O4: x_b Za | P4: p Za (bar) | Q4: x_b Zb | R4: p Zb base (bar) | S4: p Zb (bar) | T4: x_b Zc | U4: p Zc (bar)
A5: Za · encendido correcto | B5: 30 | C5: ° APMS | N5: =-Presion_cilindro!N4 -> 180 | O5: =IF(Presion_cilindro!N4>$B$12,1-EXP(-Presion_cilindro!$B$16*((Presion_cilindro!N4-$B$12)/Presion_cilindro!$B$35)^(Presion_cilindro!$B$17+1)),0) -> 0 | P5: =Presion_cilindro!$B$32 -> 0.72 | Q5: =IF(OR($B$9=0,Presion_cilindro!N4<=$B$15),IF(Presion_cilindro!N4>$B$13,1-EXP(-Presion_cilindro!$B$16*((Presion_cilindro!N4-$B$13)/Presion_cilindro!$B$35)^(Presion_cilindro!$B$17+1)),0),$B$8+(1-$B$8)*(1-EXP(-(Presion_cilindro!N4-$B$15)/Presion_cilindro!$B$23))) -> 0 | R5: =Presion_cilindro!$B$32 -> 0.72 | S5: =R5+IF(AND($B$9=1,Presion_cilindro!N4>$B$15),Presion_cilindro!$B$24*2.5*EXP(-(Presion_cilindro!N4-$B$15)/Presion_cilindro!$B$26)*SIN(2*PI()*(Presion_cilindro!N4-$B$15)/Presion_cilindro!$B$39),0) -> 0.72 | T5: =IF(Presion_cilindro!N4>$B$14,1-EXP(-Presion_cilindro!$B$16*((Presion_cilindro!N4-$B$14)/Presion_cilindro!$B$35)^(Presion_cilindro!$B$17+1)),0) -> 0 | U5: =Presion_cilindro!$B$32 -> 0.72
A6: Zb · encendido demasiado avanzado | B6: 50 | C6: ° APMS | N6: =-Presion_cilindro!N5 -> 179.5 | O6: =IF(Presion_cilindro!N5>$B$12,1-EXP(-Presion_cilindro!$B$16*((Presion_cilindro!N5-$B$12)/Presion_cilindro!$B$35)^(Presion_cilindro!$B$17+1)),0) -> 0 | P6: =P5*(Presion_cilindro!O4/Presion_cilindro!O5)^Presion_cilindro!$B$9+10*(Presion_cilindro!$B$9-1)*Presion_cilindro!$B$33*(O6-O5)/((Presion_cilindro!O4+Presion_cilindro!O5)/2) -> 0.72001172 | Q6: =IF(OR($B$9=0,Presion_cilindro!N5<=$B$15),IF(Presion_cilindro!N5>$B$13,1-EXP(-Presion_cilindro!$B$16*((Presion_cilindro!N5-$B$13)/Presion_cilindro!$B$35)^(Presion_cilindro!$B$17+1)),0),$B$8+(1-$B$8)*(1-EXP(-(Presion_cilindro!N5-$B$15)/Presion_cilindro!$B$23))) -> 0 | R6: =R5*(Presion_cilindro!O4/Presion_cilindro!O5)^Presion_cilindro!$B$9+10*(Presion_cilindro!$B$9-1)*Presion_cilindro!$B$33*(Q6-Q5)/((Presion_cilindro!O4+Presion_cilindro!O5)/2) -> 0.72001172 | S6: =R6+IF(AND($B$9=1,Presion_cilindro!N5>$B$15),Presion_cilindro!$B$24*2.5*EXP(-(Presion_cilindro!N5-$B$15)/Presion_cilindro!$B$26)*SIN(2*PI()*(Presion_cilindro!N5-$B$15)/Presion_cilindro!$B$39),0) -> 0.72001172 | T6: =IF(Presion_cilindro!N5>$B$14,1-EXP(-Presion_cilindro!$B$16*((Presion_cilindro!N5-$B$14)/Presion_cilindro!$B$35)^(Presion_cilindro!$B$17+1)),0) -> 0 | U6: =U5*(Presion_cilindro!O4/Presion_cilindro!O5)^Presion_cilindro!$B$9+10*(Presion_cilindro!$B$9-1)*Presion_cilindro!$B$33*(T6-T5)/((Presion_cilindro!O4+Presion_cilindro!O5)/2) -> 0.72001172
A7: Zc · encendido demasiado retardado | B7: -10 | C7: ° APMS | N7: =-Presion_cilindro!N6 -> 179 | O7: =IF(Presion_cilindro!N6>$B$12,1-EXP(-Presion_cilindro!$B$16*((Presion_cilindro!N6-$B$12)/Presion_cilindro!$B$35)^(Presion_cilindro!$B$17+1)),0) -> 0 | P7: =P6*(Presion_cilindro!O5/Presion_cilindro!O6)^Presion_cilindro!$B$9+10*(Presion_cilindro!$B$9-1)*Presion_cilindro!$B$33*(O7-O6)/((Presion_cilindro!O5+Presion_cilindro!O6)/2) -> 0.72004688 | Q7: =IF(OR($B$9=0,Presion_cilindro!N6<=$B$15),IF(Presion_cilindro!N6>$B$13,1-EXP(-Presion_cilindro!$B$16*((Presion_cilindro!N6-$B$13)/Presion_cilindro!$B$35)^(Presion_cilindro!$B$17+1)),0),$B$8+(1-$B$8)*(1-EXP(-(Presion_cilindro!N6-$B$15)/Presion_cilindro!$B$23))) -> 0 | R7: =R6*(Presion_cilindro!O5/Presion_cilindro!O6)^Presion_cilindro!$B$9+10*(Presion_cilindro!$B$9-1)*Presion_cilindro!$B$33*(Q7-Q6)/((Presion_cilindro!O5+Presion_cilindro!O6)/2) -> 0.72004688 | S7: =R7+IF(AND($B$9=1,Presion_cilindro!N6>$B$15),Presion_cilindro!$B$24*2.5*EXP(-(Presion_cilindro!N6-$B$15)/Presion_cilindro!$B$26)*SIN(2*PI()*(Presion_cilindro!N6-$B$15)/Presion_cilindro!$B$39),0) -> 0.72004688 | T7: =IF(Presion_cilindro!N6>$B$14,1-EXP(-Presion_cilindro!$B$16*((Presion_cilindro!N6-$B$14)/Presion_cilindro!$B$35)^(Presion_cilindro!$B$17+1)),0) -> 0 | U7: =U6*(Presion_cilindro!O5/Presion_cilindro!O6)^Presion_cilindro!$B$9+10*(Presion_cilindro!$B$9-1)*Presion_cilindro!$B$33*(T7-T6)/((Presion_cilindro!O5+Presion_cilindro!O6)/2) -> 0.72004688
A8: Fracción quemada al iniciar la detonación (Zb) | B8: 0.85 | C8: — | N8: =-Presion_cilindro!N7 -> 178.5 | O8: =IF(Presion_cilindro!N7>$B$12,1-EXP(-Presion_cilindro!$B$16*((Presion_cilindro!N7-$B$12)/Presion_cilindro!$B$35)^(Presion_cilindro!$B$17+1)),0) -> 0 | P8: =P7*(Presion_cilindro!O6/Presion_cilindro!O7)^Presion_cilindro!$B$9+10*(Presion_cilindro!$B$9-1)*Presion_cilindro!$B$33*(O8-O7)/((Presion_cilindro!O6+Presion_cilindro!O7)/2) -> 0.7201055 | Q8: =IF(OR($B$9=0,Presion_cilindro!N7<=$B$15),IF(Presion_cilindro!N7>$B$13,1-EXP(-Presion_cilindro!$B$16*((Presion_cilindro!N7-$B$13)/Presion_cilindro!$B$35)^(Presion_cilindro!$B$17+1)),0),$B$8+(1-$B$8)*(1-EXP(-(Presion_cilindro!N7-$B$15)/Presion_cilindro!$B$23))) -> 0 | R8: =R7*(Presion_cilindro!O6/Presion_cilindro!O7)^Presion_cilindro!$B$9+10*(Presion_cilindro!$B$9-1)*Presion_cilindro!$B$33*(Q8-Q7)/((Presion_cilindro!O6+Presion_cilindro!O7)/2) -> 0.7201055 | S8: =R8+IF(AND($B$9=1,Presion_cilindro!N7>$B$15),Presion_cilindro!$B$24*2.5*EXP(-(Presion_cilindro!N7-$B$15)/Presion_cilindro!$B$26)*SIN(2*PI()*(Presion_cilindro!N7-$B$15)/Presion_cilindro!$B$39),0) -> 0.7201055 | T8: =IF(Presion_cilindro!N7>$B$14,1-EXP(-Presion_cilindro!$B$16*((Presion_cilindro!N7-$B$14)/Presion_cilindro!$B$35)^(Presion_cilindro!$B$17+1)),0) -> 0 | U8: =U7*(Presion_cilindro!O6/Presion_cilindro!O7)^Presion_cilindro!$B$9+10*(Presion_cilindro!$B$9-1)*Presion_cilindro!$B$33*(T8-T7)/((Presion_cilindro!O6+Presion_cilindro!O7)/2) -> 0.7201055
A9: ¿Hay detonación con Zb? (1 = sí, 0 = no) | B9: 1 | C9: — | N9: =-Presion_cilindro!N8 -> 178 | O9: =IF(Presion_cilindro!N8>$B$12,1-EXP(-Presion_cilindro!$B$16*((Presion_cilindro!N8-$B$12)/Presion_cilindro!$B$35)^(Presion_cilindro!$B$17+1)),0) -> 0 | P9: =P8*(Presion_cilindro!O7/Presion_cilindro!O8)^Presion_cilindro!$B$9+10*(Presion_cilindro!$B$9-1)*Presion_cilindro!$B$33*(O9-O8)/((Presion_cilindro!O7+Presion_cilindro!O8)/2) -> 0.72018757 | Q9: =IF(OR($B$9=0,Presion_cilindro!N8<=$B$15),IF(Presion_cilindro!N8>$B$13,1-EXP(-Presion_cilindro!$B$16*((Presion_cilindro!N8-$B$13)/Presion_cilindro!$B$35)^(Presion_cilindro!$B$17+1)),0),$B$8+(1-$B$8)*(1-EXP(-(Presion_cilindro!N8-$B$15)/Presion_cilindro!$B$23))) -> 0 | R9: =R8*(Presion_cilindro!O7/Presion_cilindro!O8)^Presion_cilindro!$B$9+10*(Presion_cilindro!$B$9-1)*Presion_cilindro!$B$33*(Q9-Q8)/((Presion_cilindro!O7+Presion_cilindro!O8)/2) -> 0.72018757 | S9: =R9+IF(AND($B$9=1,Presion_cilindro!N8>$B$15),Presion_cilindro!$B$24*2.5*EXP(-(Presion_cilindro!N8-$B$15)/Presion_cilindro!$B$26)*SIN(2*PI()*(Presion_cilindro!N8-$B$15)/Presion_cilindro!$B$39),0) -> 0.72018757 | T9: =IF(Presion_cilindro!N8>$B$14,1-EXP(-Presion_cilindro!$B$16*((Presion_cilindro!N8-$B$14)/Presion_cilindro!$B$35)^(Presion_cilindro!$B$17+1)),0) -> 0 | U9: =U8*(Presion_cilindro!O7/Presion_cilindro!O8)^Presion_cilindro!$B$9+10*(Presion_cilindro!$B$9-1)*Presion_cilindro!$B$33*(T9-T8)/((Presion_cilindro!O7+Presion_cilindro!O8)/2) -> 0.72018757
N10: =-Presion_cilindro!N9 -> 177.5 | O10: =IF(Presion_cilindro!N9>$B$12,1-EXP(-Presion_cilindro!$B$16*((Presion_cilindro!N9-$B$12)/Presion_cilindro!$B$35)^(Presion_cilindro!$B$17+1)),0) -> 0 | P10: =P9*(Presion_cilindro!O8/Presion_cilindro!O9)^Presion_cilindro!$B$9+10*(Presion_cilindro!$B$9-1)*Presion_cilindro!$B$33*(O10-O9)/((Presion_cilindro!O8+Presion_cilindro!O9)/2) -> 0.72029311 | Q10: =IF(OR($B$9=0,Presion_cilindro!N9<=$B$15),IF(Presion_cilindro!N9>$B$13,1-EXP(-Presion_cilindro!$B$16*((Presion_cilindro!N9-$B$13)/Presion_cilindro!$B$35)^(Presion_cilindro!$B$17+1)),0),$B$8+(1-$B$8)*(1-EXP(-(Presion_cilindro!N9-$B$15)/Presion_cilindro!$B$23))) -> 0 | R10: =R9*(Presion_cilindro!O8/Presion_cilindro!O9)^Presion_cilindro!$B$9+10*(Presion_cilindro!$B$9-1)*Presion_cilindro!$B$33*(Q10-Q9)/((Presion_cilindro!O8+Presion_cilindro!O9)/2) -> 0.72029311 | S10: =R10+IF(AND($B$9=1,Presion_cilindro!N9>$B$15),Presion_cilindro!$B$24*2.5*EXP(-(Presion_cilindro!N9-$B$15)/Presion_cilindro!$B$26)*SIN(2*PI()*(Presion_cilindro!N9-$B$15)/Presion_cilindro!$B$39),0) -> 0.72029311 | T10: =IF(Presion_cilindro!N9>$B$14,1-EXP(-Presion_cilindro!$B$16*((Presion_cilindro!N9-$B$14)/Presion_cilindro!$B$35)^(Presion_cilindro!$B$17+1)),0) -> 0 | U10: =U9*(Presion_cilindro!O8/Presion_cilindro!O9)^Presion_cilindro!$B$9+10*(Presion_cilindro!$B$9-1)*Presion_cilindro!$B$33*(T10-T9)/((Presion_cilindro!O8+Presion_cilindro!O9)/2) -> 0.72029311
A11: Valores calculados | N11: =-Presion_cilindro!N10 -> 177 | O11: =IF(Presion_cilindro!N10>$B$12,1-EXP(-Presion_cilindro!$B$16*((Presion_cilindro!N10-$B$12)/Presion_cilindro!$B$35)^(Presion_cilindro!$B$17+1)),0) -> 0 | P11: =P10*(Presion_cilindro!O9/Presion_cilindro!O10)^Presion_cilindro!$B$9+10*(Presion_cilindro!$B$9-1)*Presion_cilindro!$B$33*(O11-O10)/((Presion_cilindro!O9+Presion_cilindro!O10)/2) -> 0.72042215 | Q11: =IF(OR($B$9=0,Presion_cilindro!N10<=$B$15),IF(Presion_cilindro!N10>$B$13,1-EXP(-Presion_cilindro!$B$16*((Presion_cilindro!N10-$B$13)/Presion_cilindro!$B$35)^(Presion_cilindro!$B$17+1)),0),$B$8+(1-$B$8)*(1-EXP(-(Presion_cilindro!N10-$B$15)/Presion_cilindro!$B$23))) -> 0 | R11: =R10*(Presion_cilindro!O9/Presion_cilindro!O10)^Presion_cilindro!$B$9+10*(Presion_cilindro!$B$9-1)*Presion_cilindro!$B$33*(Q11-Q10)/((Presion_cilindro!O9+Presion_cilindro!O10)/2) -> 0.72042215 | S11: =R11+IF(AND($B$9=1,Presion_cilindro!N10>$B$15),Presion_cilindro!$B$24*2.5*EXP(-(Presion_cilindro!N10-$B$15)/Presion_cilindro!$B$26)*SIN(2*PI()*(Presion_cilindro!N10-$B$15)/Presion_cilindro!$B$39),0) -> 0.72042215 | T11: =IF(Presion_cilindro!N10>$B$14,1-EXP(-Presion_cilindro!$B$16*((Presion_cilindro!N10-$B$14)/Presion_cilindro!$B$35)^(Presion_cilindro!$B$17+1)),0) -> 0 | U11: =U10*(Presion_cilindro!O9/Presion_cilindro!O10)^Presion_cilindro!$B$9+10*(Presion_cilindro!$B$9-1)*Presion_cilindro!$B$33*(T11-T10)/((Presion_cilindro!O9+Presion_cilindro!O10)/2) -> 0.72042215
A12: Inicio de la combustión Za | B12: =-$B$5+Presion_cilindro!$B$34 -> -22.8 | C12: ° | N12: =-Presion_cilindro!N11 -> 176.5 | O12: =IF(Presion_cilindro!N11>$B$12,1-EXP(-Presion_cilindro!$B$16*((Presion_cilindro!N11-$B$12)/Presion_cilindro!$B$35)^(Presion_cilindro!$B$17+1)),0) -> 0 | P12: =P11*(Presion_cilindro!O10/Presion_cilindro!O11)^Presion_cilindro!$B$9+10*(Presion_cilindro!$B$9-1)*Presion_cilindro!$B$33*(O12-O11)/((Presion_cilindro!O10+Presion_cilindro!O11)/2) -> 0.72057471 | Q12: =IF(OR($B$9=0,Presion_cilindro!N11<=$B$15),IF(Presion_cilindro!N11>$B$13,1-EXP(-Presion_cilindro!$B$16*((Presion_cilindro!N11-$B$13)/Presion_cilindro!$B$35)^(Presion_cilindro!$B$17+1)),0),$B$8+(1-$B$8)*(1-EXP(-(Presion_cilindro!N11-$B$15)/Presion_cilindro!$B$23))) -> 0 | R12: =R11*(Presion_cilindro!O10/Presion_cilindro!O11)^Presion_cilindro!$B$9+10*(Presion_cilindro!$B$9-1)*Presion_cilindro!$B$33*(Q12-Q11)/((Presion_cilindro!O10+Presion_cilindro!O11)/2) -> 0.72057471 | S12: =R12+IF(AND($B$9=1,Presion_cilindro!N11>$B$15),Presion_cilindro!$B$24*2.5*EXP(-(Presion_cilindro!N11-$B$15)/Presion_cilindro!$B$26)*SIN(2*PI()*(Presion_cilindro!N11-$B$15)/Presion_cilindro!$B$39),0) -> 0.72057471 | T12: =IF(Presion_cilindro!N11>$B$14,1-EXP(-Presion_cilindro!$B$16*((Presion_cilindro!N11-$B$14)/Presion_cilindro!$B$35)^(Presion_cilindro!$B$17+1)),0) -> 0 | U12: =U11*(Presion_cilindro!O10/Presion_cilindro!O11)^Presion_cilindro!$B$9+10*(Presion_cilindro!$B$9-1)*Presion_cilindro!$B$33*(T12-T11)/((Presion_cilindro!O10+Presion_cilindro!O11)/2) -> 0.72057471
A13: Inicio de la combustión Zb | B13: =-$B$6+Presion_cilindro!$B$34 -> -42.8 | C13: ° | N13: =-Presion_cilindro!N12 -> 176 | O13: =IF(Presion_cilindro!N12>$B$12,1-EXP(-Presion_cilindro!$B$16*((Presion_cilindro!N12-$B$12)/Presion_cilindro!$B$35)^(Presion_cilindro!$B$17+1)),0) -> 0 | P13: =P12*(Presion_cilindro!O11/Presion_cilindro!O12)^Presion_cilindro!$B$9+10*(Presion_cilindro!$B$9-1)*Presion_cilindro!$B$33*(O13-O12)/((Presion_cilindro!O11+Presion_cilindro!O12)/2) -> 0.72075081 | Q13: =IF(OR($B$9=0,Presion_cilindro!N12<=$B$15),IF(Presion_cilindro!N12>$B$13,1-EXP(-Presion_cilindro!$B$16*((Presion_cilindro!N12-$B$13)/Presion_cilindro!$B$35)^(Presion_cilindro!$B$17+1)),0),$B$8+(1-$B$8)*(1-EXP(-(Presion_cilindro!N12-$B$15)/Presion_cilindro!$B$23))) -> 0 | R13: =R12*(Presion_cilindro!O11/Presion_cilindro!O12)^Presion_cilindro!$B$9+10*(Presion_cilindro!$B$9-1)*Presion_cilindro!$B$33*(Q13-Q12)/((Presion_cilindro!O11+Presion_cilindro!O12)/2) -> 0.72075081 | S13: =R13+IF(AND($B$9=1,Presion_cilindro!N12>$B$15),Presion_cilindro!$B$24*2.5*EXP(-(Presion_cilindro!N12-$B$15)/Presion_cilindro!$B$26)*SIN(2*PI()*(Presion_cilindro!N12-$B$15)/Presion_cilindro!$B$39),0) -> 0.72075081 | T13: =IF(Presion_cilindro!N12>$B$14,1-EXP(-Presion_cilindro!$B$16*((Presion_cilindro!N12-$B$14)/Presion_cilindro!$B$35)^(Presion_cilindro!$B$17+1)),0) -> 0 | U13: =U12*(Presion_cilindro!O11/Presion_cilindro!O12)^Presion_cilindro!$B$9+10*(Presion_cilindro!$B$9-1)*Presion_cilindro!$B$33*(T13-T12)/((Presion_cilindro!O11+Presion_cilindro!O12)/2) -> 0.72075081
A14: Inicio de la combustión Zc | B14: =-$B$7+Presion_cilindro!$B$34 -> 17.2 | C14: ° | N14: =-Presion_cilindro!N13 -> 175.5 | O14: =IF(Presion_cilindro!N13>$B$12,1-EXP(-Presion_cilindro!$B$16*((Presion_cilindro!N13-$B$12)/Presion_cilindro!$B$35)^(Presion_cilindro!$B$17+1)),0) -> 0 | P14: =P13*(Presion_cilindro!O12/Presion_cilindro!O13)^Presion_cilindro!$B$9+10*(Presion_cilindro!$B$9-1)*Presion_cilindro!$B$33*(O14-O13)/((Presion_cilindro!O12+Presion_cilindro!O13)/2) -> 0.72095048 | Q14: =IF(OR($B$9=0,Presion_cilindro!N13<=$B$15),IF(Presion_cilindro!N13>$B$13,1-EXP(-Presion_cilindro!$B$16*((Presion_cilindro!N13-$B$13)/Presion_cilindro!$B$35)^(Presion_cilindro!$B$17+1)),0),$B$8+(1-$B$8)*(1-EXP(-(Presion_cilindro!N13-$B$15)/Presion_cilindro!$B$23))) -> 0 | R14: =R13*(Presion_cilindro!O12/Presion_cilindro!O13)^Presion_cilindro!$B$9+10*(Presion_cilindro!$B$9-1)*Presion_cilindro!$B$33*(Q14-Q13)/((Presion_cilindro!O12+Presion_cilindro!O13)/2) -> 0.72095048 | S14: =R14+IF(AND($B$9=1,Presion_cilindro!N13>$B$15),Presion_cilindro!$B$24*2.5*EXP(-(Presion_cilindro!N13-$B$15)/Presion_cilindro!$B$26)*SIN(2*PI()*(Presion_cilindro!N13-$B$15)/Presion_cilindro!$B$39),0) -> 0.72095048 | T14: =IF(Presion_cilindro!N13>$B$14,1-EXP(-Presion_cilindro!$B$16*((Presion_cilindro!N13-$B$14)/Presion_cilindro!$B$35)^(Presion_cilindro!$B$17+1)),0) -> 0 | U14: =U13*(Presion_cilindro!O12/Presion_cilindro!O13)^Presion_cilindro!$B$9+10*(Presion_cilindro!$B$9-1)*Presion_cilindro!$B$33*(T14-T13)/((Presion_cilindro!O12+Presion_cilindro!O13)/2) -> 0.72095048
A15: Ángulo de inicio de la detonación (Zb) | B15: =$B$13+Presion_cilindro!$B$35*(-LN(1-$B$8)/Presion_cilindro!$B$16)^(1/(Presion_cilindro!$B$17+1)) -> -6.8921054 | C15: ° | N15: =-Presion_cilindro!N14 -> 175 | O15: =IF(Presion_cilindro!N14>$B$12,1-EXP(-Presion_cilindro!$B$16*((Presion_cilindro!N14-$B$12)/Presion_cilindro!$B$35)^(Presion_cilindro!$B$17+1)),0) -> 0 | P15: =P14*(Presion_cilindro!O13/Presion_cilindro!O14)^Presion_cilindro!$B$9+10*(Presion_cilindro!$B$9-1)*Presion_cilindro!$B$33*(O15-O14)/((Presion_cilindro!O13+Presion_cilindro!O14)/2) -> 0.72117376 | Q15: =IF(OR($B$9=0,Presion_cilindro!N14<=$B$15),IF(Presion_cilindro!N14>$B$13,1-EXP(-Presion_cilindro!$B$16*((Presion_cilindro!N14-$B$13)/Presion_cilindro!$B$35)^(Presion_cilindro!$B$17+1)),0),$B$8+(1-$B$8)*(1-EXP(-(Presion_cilindro!N14-$B$15)/Presion_cilindro!$B$23))) -> 0 | R15: =R14*(Presion_cilindro!O13/Presion_cilindro!O14)^Presion_cilindro!$B$9+10*(Presion_cilindro!$B$9-1)*Presion_cilindro!$B$33*(Q15-Q14)/((Presion_cilindro!O13+Presion_cilindro!O14)/2) -> 0.72117376 | S15: =R15+IF(AND($B$9=1,Presion_cilindro!N14>$B$15),Presion_cilindro!$B$24*2.5*EXP(-(Presion_cilindro!N14-$B$15)/Presion_cilindro!$B$26)*SIN(2*PI()*(Presion_cilindro!N14-$B$15)/Presion_cilindro!$B$39),0) -> 0.72117376 | T15: =IF(Presion_cilindro!N14>$B$14,1-EXP(-Presion_cilindro!$B$16*((Presion_cilindro!N14-$B$14)/Presion_cilindro!$B$35)^(Presion_cilindro!$B$17+1)),0) -> 0 | U15: =U14*(Presion_cilindro!O13/Presion_cilindro!O14)^Presion_cilindro!$B$9+10*(Presion_cilindro!$B$9-1)*Presion_cilindro!$B$33*(T15-T14)/((Presion_cilindro!O13+Presion_cilindro!O14)/2) -> 0.72117376
N16: =-Presion_cilindro!N15 -> 174.5 | O16: =IF(Presion_cilindro!N15>$B$12,1-EXP(-Presion_cilindro!$B$16*((Presion_cilindro!N15-$B$12)/Presion_cilindro!$B$35)^(Presion_cilindro!$B$17+1)),0) -> 0 | P16: =P15*(Presion_cilindro!O14/Presion_cilindro!O15)^Presion_cilindro!$B$9+10*(Presion_cilindro!$B$9-1)*Presion_cilindro!$B$33*(O16-O15)/((Presion_cilindro!O14+Presion_cilindro!O15)/2) -> 0.7214207 | Q16: =IF(OR($B$9=0,Presion_cilindro!N15<=$B$15),IF(Presion_cilindro!N15>$B$13,1-EXP(-Presion_cilindro!$B$16*((Presion_cilindro!N15-$B$13)/Presion_cilindro!$B$35)^(Presion_cilindro!$B$17+1)),0),$B$8+(1-$B$8)*(1-EXP(-(Presion_cilindro!N15-$B$15)/Presion_cilindro!$B$23))) -> 0 | R16: =R15*(Presion_cilindro!O14/Presion_cilindro!O15)^Presion_cilindro!$B$9+10*(Presion_cilindro!$B$9-1)*Presion_cilindro!$B$33*(Q16-Q15)/((Presion_cilindro!O14+Presion_cilindro!O15)/2) -> 0.7214207 | S16: =R16+IF(AND($B$9=1,Presion_cilindro!N15>$B$15),Presion_cilindro!$B$24*2.5*EXP(-(Presion_cilindro!N15-$B$15)/Presion_cilindro!$B$26)*SIN(2*PI()*(Presion_cilindro!N15-$B$15)/Presion_cilindro!$B$39),0) -> 0.7214207 | T16: =IF(Presion_cilindro!N15>$B$14,1-EXP(-Presion_cilindro!$B$16*((Presion_cilindro!N15-$B$14)/Presion_cilindro!$B$35)^(Presion_cilindro!$B$17+1)),0) -> 0 | U16: =U15*(Presion_cilindro!O14/Presion_cilindro!O15)^Presion_cilindro!$B$9+10*(Presion_cilindro!$B$9-1)*Presion_cilindro!$B$33*(T16-T15)/((Presion_cilindro!O14+Presion_cilindro!O15)/2) -> 0.7214207
A17: Resultados | N17: =-Presion_cilindro!N16 -> 174 | O17: =IF(Presion_cilindro!N16>$B$12,1-EXP(-Presion_cilindro!$B$16*((Presion_cilindro!N16-$B$12)/Presion_cilindro!$B$35)^(Presion_cilindro!$B$17+1)),0) -> 0 | P17: =P16*(Presion_cilindro!O15/Presion_cilindro!O16)^Presion_cilindro!$B$9+10*(Presion_cilindro!$B$9-1)*Presion_cilindro!$B$33*(O17-O16)/((Presion_cilindro!O15+Presion_cilindro!O16)/2) -> 0.72169133 | Q17: =IF(OR($B$9=0,Presion_cilindro!N16<=$B$15),IF(Presion_cilindro!N16>$B$13,1-EXP(-Presion_cilindro!$B$16*((Presion_cilindro!N16-$B$13)/Presion_cilindro!$B$35)^(Presion_cilindro!$B$17+1)),0),$B$8+(1-$B$8)*(1-EXP(-(Presion_cilindro!N16-$B$15)/Presion_cilindro!$B$23))) -> 0 | R17: =R16*(Presion_cilindro!O15/Presion_cilindro!O16)^Presion_cilindro!$B$9+10*(Presion_cilindro!$B$9-1)*Presion_cilindro!$B$33*(Q17-Q16)/((Presion_cilindro!O15+Presion_cilindro!O16)/2) -> 0.72169133 | S17: =R17+IF(AND($B$9=1,Presion_cilindro!N16>$B$15),Presion_cilindro!$B$24*2.5*EXP(-(Presion_cilindro!N16-$B$15)/Presion_cilindro!$B$26)*SIN(2*PI()*(Presion_cilindro!N16-$B$15)/Presion_cilindro!$B$39),0) -> 0.72169133 | T17: =IF(Presion_cilindro!N16>$B$14,1-EXP(-Presion_cilindro!$B$16*((Presion_cilindro!N16-$B$14)/Presion_cilindro!$B$35)^(Presion_cilindro!$B$17+1)),0) -> 0 | U17: =U16*(Presion_cilindro!O15/Presion_cilindro!O16)^Presion_cilindro!$B$9+10*(Presion_cilindro!$B$9-1)*Presion_cilindro!$B$33*(T17-T16)/((Presion_cilindro!O15+Presion_cilindro!O16)/2) -> 0.72169133
A18: Presión máxima Za | B18: =MAX(P5:P725) -> 35.93293 | C18: bar | N18: =-Presion_cilindro!N17 -> 173.5 | O18: =IF(Presion_cilindro!N17>$B$12,1-EXP(-Presion_cilindro!$B$16*((Presion_cilindro!N17-$B$12)/Presion_cilindro!$B$35)^(Presion_cilindro!$B$17+1)),0) -> 0 | P18: =P17*(Presion_cilindro!O16/Presion_cilindro!O17)^Presion_cilindro!$B$9+10*(Presion_cilindro!$B$9-1)*Presion_cilindro!$B$33*(O18-O17)/((Presion_cilindro!O16+Presion_cilindro!O17)/2) -> 0.72198571 | Q18: =IF(OR($B$9=0,Presion_cilindro!N17<=$B$15),IF(Presion_cilindro!N17>$B$13,1-EXP(-Presion_cilindro!$B$16*((Presion_cilindro!N17-$B$13)/Presion_cilindro!$B$35)^(Presion_cilindro!$B$17+1)),0),$B$8+(1-$B$8)*(1-EXP(-(Presion_cilindro!N17-$B$15)/Presion_cilindro!$B$23))) -> 0 | R18: =R17*(Presion_cilindro!O16/Presion_cilindro!O17)^Presion_cilindro!$B$9+10*(Presion_cilindro!$B$9-1)*Presion_cilindro!$B$33*(Q18-Q17)/((Presion_cilindro!O16+Presion_cilindro!O17)/2) -> 0.72198571 | S18: =R18+IF(AND($B$9=1,Presion_cilindro!N17>$B$15),Presion_cilindro!$B$24*2.5*EXP(-(Presion_cilindro!N17-$B$15)/Presion_cilindro!$B$26)*SIN(2*PI()*(Presion_cilindro!N17-$B$15)/Presion_cilindro!$B$39),0) -> 0.72198571 | T18: =IF(Presion_cilindro!N17>$B$14,1-EXP(-Presion_cilindro!$B$16*((Presion_cilindro!N17-$B$14)/Presion_cilindro!$B$35)^(Presion_cilindro!$B$17+1)),0) -> 0 | U18: =U17*(Presion_cilindro!O16/Presion_cilindro!O17)^Presion_cilindro!$B$9+10*(Presion_cilindro!$B$9-1)*Presion_cilindro!$B$33*(T18-T17)/((Presion_cilindro!O16+Presion_cilindro!O17)/2) -> 0.72198571
A19: Ángulo de la presión máxima Za | B19: =INDEX(N5:N725,MATCH(MAX(P5:P725),P5:P725,0)) -> -11 | C19: ° (− = DPMS) | N19: =-Presion_cilindro!N18 -> 173 | O19: =IF(Presion_cilindro!N18>$B$12,1-EXP(-Presion_cilindro!$B$16*((Presion_cilindro!N18-$B$12)/Presion_cilindro!$B$35)^(Presion_cilindro!$B$17+1)),0) -> 0 | P19: =P18*(Presion_cilindro!O17/Presion_cilindro!O18)^Presion_cilindro!$B$9+10*(Presion_cilindro!$B$9-1)*Presion_cilindro!$B$33*(O19-O18)/((Presion_cilindro!O17+Presion_cilindro!O18)/2) -> 0.72230388 | Q19: =IF(OR($B$9=0,Presion_cilindro!N18<=$B$15),IF(Presion_cilindro!N18>$B$13,1-EXP(-Presion_cilindro!$B$16*((Presion_cilindro!N18-$B$13)/Presion_cilindro!$B$35)^(Presion_cilindro!$B$17+1)),0),$B$8+(1-$B$8)*(1-EXP(-(Presion_cilindro!N18-$B$15)/Presion_cilindro!$B$23))) -> 0 | R19: =R18*(Presion_cilindro!O17/Presion_cilindro!O18)^Presion_cilindro!$B$9+10*(Presion_cilindro!$B$9-1)*Presion_cilindro!$B$33*(Q19-Q18)/((Presion_cilindro!O17+Presion_cilindro!O18)/2) -> 0.72230388 | S19: =R19+IF(AND($B$9=1,Presion_cilindro!N18>$B$15),Presion_cilindro!$B$24*2.5*EXP(-(Presion_cilindro!N18-$B$15)/Presion_cilindro!$B$26)*SIN(2*PI()*(Presion_cilindro!N18-$B$15)/Presion_cilindro!$B$39),0) -> 0.72230388 | T19: =IF(Presion_cilindro!N18>$B$14,1-EXP(-Presion_cilindro!$B$16*((Presion_cilindro!N18-$B$14)/Presion_cilindro!$B$35)^(Presion_cilindro!$B$17+1)),0) -> 0 | U19: =U18*(Presion_cilindro!O17/Presion_cilindro!O18)^Presion_cilindro!$B$9+10*(Presion_cilindro!$B$9-1)*Presion_cilindro!$B$33*(T19-T18)/((Presion_cilindro!O17+Presion_cilindro!O18)/2) -> 0.72230388
A20: Presión máxima Zb | B20: =MAX(S5:S725) -> 53.933372 | C20: bar | N20: =-Presion_cilindro!N19 -> 172.5 | O20: =IF(Presion_cilindro!N19>$B$12,1-EXP(-Presion_cilindro!$B$16*((Presion_cilindro!N19-$B$12)/Presion_cilindro!$B$35)^(Presion_cilindro!$B$17+1)),0) -> 0 | P20: =P19*(Presion_cilindro!O18/Presion_cilindro!O19)^Presion_cilindro!$B$9+10*(Presion_cilindro!$B$9-1)*Presion_cilindro!$B$33*(O20-O19)/((Presion_cilindro!O18+Presion_cilindro!O19)/2) -> 0.7226459 | Q20: =IF(OR($B$9=0,Presion_cilindro!N19<=$B$15),IF(Presion_cilindro!N19>$B$13,1-EXP(-Presion_cilindro!$B$16*((Presion_cilindro!N19-$B$13)/Presion_cilindro!$B$35)^(Presion_cilindro!$B$17+1)),0),$B$8+(1-$B$8)*(1-EXP(-(Presion_cilindro!N19-$B$15)/Presion_cilindro!$B$23))) -> 0 | R20: =R19*(Presion_cilindro!O18/Presion_cilindro!O19)^Presion_cilindro!$B$9+10*(Presion_cilindro!$B$9-1)*Presion_cilindro!$B$33*(Q20-Q19)/((Presion_cilindro!O18+Presion_cilindro!O19)/2) -> 0.7226459 | S20: =R20+IF(AND($B$9=1,Presion_cilindro!N19>$B$15),Presion_cilindro!$B$24*2.5*EXP(-(Presion_cilindro!N19-$B$15)/Presion_cilindro!$B$26)*SIN(2*PI()*(Presion_cilindro!N19-$B$15)/Presion_cilindro!$B$39),0) -> 0.7226459 | T20: =IF(Presion_cilindro!N19>$B$14,1-EXP(-Presion_cilindro!$B$16*((Presion_cilindro!N19-$B$14)/Presion_cilindro!$B$35)^(Presion_cilindro!$B$17+1)),0) -> 0 | U20: =U19*(Presion_cilindro!O18/Presion_cilindro!O19)^Presion_cilindro!$B$9+10*(Presion_cilindro!$B$9-1)*Presion_cilindro!$B$33*(T20-T19)/((Presion_cilindro!O18+Presion_cilindro!O19)/2) -> 0.7226459
A21: Ángulo de la presión máxima Zb | B21: =INDEX(N5:N725,MATCH(MAX(S5:S725),S5:S725,0)) -> 2.5 | C21: ° (− = DPMS) | N21: =-Presion_cilindro!N20 -> 172 | O21: =IF(Presion_cilindro!N20>$B$12,1-EXP(-Presion_cilindro!$B$16*((Presion_cilindro!N20-$B$12)/Presion_cilindro!$B$35)^(Presion_cilindro!$B$17+1)),0) -> 0 | P21: =P20*(Presion_cilindro!O19/Presion_cilindro!O20)^Presion_cilindro!$B$9+10*(Presion_cilindro!$B$9-1)*Presion_cilindro!$B$33*(O21-O20)/((Presion_cilindro!O19+Presion_cilindro!O20)/2) -> 0.72301184 | Q21: =IF(OR($B$9=0,Presion_cilindro!N20<=$B$15),IF(Presion_cilindro!N20>$B$13,1-EXP(-Presion_cilindro!$B$16*((Presion_cilindro!N20-$B$13)/Presion_cilindro!$B$35)^(Presion_cilindro!$B$17+1)),0),$B$8+(1-$B$8)*(1-EXP(-(Presion_cilindro!N20-$B$15)/Presion_cilindro!$B$23))) -> 0 | R21: =R20*(Presion_cilindro!O19/Presion_cilindro!O20)^Presion_cilindro!$B$9+10*(Presion_cilindro!$B$9-1)*Presion_cilindro!$B$33*(Q21-Q20)/((Presion_cilindro!O19+Presion_cilindro!O20)/2) -> 0.72301184 | S21: =R21+IF(AND($B$9=1,Presion_cilindro!N20>$B$15),Presion_cilindro!$B$24*2.5*EXP(-(Presion_cilindro!N20-$B$15)/Presion_cilindro!$B$26)*SIN(2*PI()*(Presion_cilindro!N20-$B$15)/Presion_cilindro!$B$39),0) -> 0.72301184 | T21: =IF(Presion_cilindro!N20>$B$14,1-EXP(-Presion_cilindro!$B$16*((Presion_cilindro!N20-$B$14)/Presion_cilindro!$B$35)^(Presion_cilindro!$B$17+1)),0) -> 0 | U21: =U20*(Presion_cilindro!O19/Presion_cilindro!O20)^Presion_cilindro!$B$9+10*(Presion_cilindro!$B$9-1)*Presion_cilindro!$B$33*(T21-T20)/((Presion_cilindro!O19+Presion_cilindro!O20)/2) -> 0.72301184
A22: Presión máxima Zc | B22: =MAX(U5:U725) -> 15.393327 | C22: bar | N22: =-Presion_cilindro!N21 -> 171.5 | O22: =IF(Presion_cilindro!N21>$B$12,1-EXP(-Presion_cilindro!$B$16*((Presion_cilindro!N21-$B$12)/Presion_cilindro!$B$35)^(Presion_cilindro!$B$17+1)),0) -> 0 | P22: =P21*(Presion_cilindro!O20/Presion_cilindro!O21)^Presion_cilindro!$B$9+10*(Presion_cilindro!$B$9-1)*Presion_cilindro!$B$33*(O22-O21)/((Presion_cilindro!O20+Presion_cilindro!O21)/2) -> 0.72340176 | Q22: =IF(OR($B$9=0,Presion_cilindro!N21<=$B$15),IF(Presion_cilindro!N21>$B$13,1-EXP(-Presion_cilindro!$B$16*((Presion_cilindro!N21-$B$13)/Presion_cilindro!$B$35)^(Presion_cilindro!$B$17+1)),0),$B$8+(1-$B$8)*(1-EXP(-(Presion_cilindro!N21-$B$15)/Presion_cilindro!$B$23))) -> 0 | R22: =R21*(Presion_cilindro!O20/Presion_cilindro!O21)^Presion_cilindro!$B$9+10*(Presion_cilindro!$B$9-1)*Presion_cilindro!$B$33*(Q22-Q21)/((Presion_cilindro!O20+Presion_cilindro!O21)/2) -> 0.72340176 | S22: =R22+IF(AND($B$9=1,Presion_cilindro!N21>$B$15),Presion_cilindro!$B$24*2.5*EXP(-(Presion_cilindro!N21-$B$15)/Presion_cilindro!$B$26)*SIN(2*PI()*(Presion_cilindro!N21-$B$15)/Presion_cilindro!$B$39),0) -> 0.72340176 | T22: =IF(Presion_cilindro!N21>$B$14,1-EXP(-Presion_cilindro!$B$16*((Presion_cilindro!N21-$B$14)/Presion_cilindro!$B$35)^(Presion_cilindro!$B$17+1)),0) -> 0 | U22: =U21*(Presion_cilindro!O20/Presion_cilindro!O21)^Presion_cilindro!$B$9+10*(Presion_cilindro!$B$9-1)*Presion_cilindro!$B$33*(T22-T21)/((Presion_cilindro!O20+Presion_cilindro!O21)/2) -> 0.72340176
A23: Ángulo de la presión máxima Zc | B23: =INDEX(N5:N725,MATCH(MAX(U5:U725),U5:U725,0)) -> 0 | C23: ° (− = DPMS) | N23: =-Presion_cilindro!N22 -> 171 | O23: =IF(Presion_cilindro!N22>$B$12,1-EXP(-Presion_cilindro!$B$16*((Presion_cilindro!N22-$B$12)/Presion_cilindro!$B$35)^(Presion_cilindro!$B$17+1)),0) -> 0 | P23: =P22*(Presion_cilindro!O21/Presion_cilindro!O22)^Presion_cilindro!$B$9+10*(Presion_cilindro!$B$9-1)*Presion_cilindro!$B$33*(O23-O22)/((Presion_cilindro!O21+Presion_cilindro!O22)/2) -> 0.72381573 | Q23: =IF(OR($B$9=0,Presion_cilindro!N22<=$B$15),IF(Presion_cilindro!N22>$B$13,1-EXP(-Presion_cilindro!$B$16*((Presion_cilindro!N22-$B$13)/Presion_cilindro!$B$35)^(Presion_cilindro!$B$17+1)),0),$B$8+(1-$B$8)*(1-EXP(-(Presion_cilindro!N22-$B$15)/Presion_cilindro!$B$23))) -> 0 | R23: =R22*(Presion_cilindro!O21/Presion_cilindro!O22)^Presion_cilindro!$B$9+10*(Presion_cilindro!$B$9-1)*Presion_cilindro!$B$33*(Q23-Q22)/((Presion_cilindro!O21+Presion_cilindro!O22)/2) -> 0.72381573 | S23: =R23+IF(AND($B$9=1,Presion_cilindro!N22>$B$15),Presion_cilindro!$B$24*2.5*EXP(-(Presion_cilindro!N22-$B$15)/Presion_cilindro!$B$26)*SIN(2*PI()*(Presion_cilindro!N22-$B$15)/Presion_cilindro!$B$39),0) -> 0.72381573 | T23: =IF(Presion_cilindro!N22>$B$14,1-EXP(-Presion_cilindro!$B$16*((Presion_cilindro!N22-$B$14)/Presion_cilindro!$B$35)^(Presion_cilindro!$B$17+1)),0) -> 0 | U23: =U22*(Presion_cilindro!O21/Presion_cilindro!O22)^Presion_cilindro!$B$9+10*(Presion_cilindro!$B$9-1)*Presion_cilindro!$B$33*(T23-T22)/((Presion_cilindro!O21+Presion_cilindro!O22)/2) -> 0.72381573
