Workbook

Sheet Dwell y bobina
A1: Simulador 1 · Ángulo Dwell y saturación de la bobina (encendido convencional)
A2: Sistemas del Funcionamiento del Motor (MA.02.06) · Unidad 2 · Edite solo las celdas amarillas (texto azul); todo lo demás se recalcula.
A4: Datos de entrada | B4: Valor
A5: Número de cilindros z | B5: 4
A6: Ángulo Dwell (° de distribuidor) | B6: 54
A7: Tensión de alimentación (V) | B7: 13.5
A8: Resistencia total del primario (Ω) | B8: 3
A9: Inductancia del primario (mH) | B9: 7
A10: Régimen de estudio (rpm del motor) | B10: 3000
A12: Resultados al régimen de estudio | B12: Valor | C12: Cómo se obtiene
A13: Ángulo entre chispas (° de distribuidor) | B13: =360/B5 | C13: 360° / z
A14: Dwell en porcentaje (%) | B14: =B6/B13 | C14: Dwell / ángulo entre chispas
A15: Dwell en grados de cigüeñal | B15: =2*B6 | C15: El distribuidor gira a la mitad que el cigüeñal
A16: Constante de tiempo τ = L / R (ms) | B16: =B9/B8 | C16: Tiempo para alcanzar el 63 % de la corriente máxima
A17: Corriente máxima posible V / R (A) | B17: =B7/B8
A18: Tiempo de cierre del ruptor (ms) | B18: =B6*120000/(360*B10) | C18: t = Dwell/360 · 60/(n/2)
A19: Corriente en el instante de corte (A) | B19: =B17*(1-EXP(-B18/B16)) | C19: I = V/R · (1 − e^(−t/τ))
A20: Energía almacenada en la bobina (mJ) | B20: =0.5*B9*B19^2 | C20: E = ½ · L · I²
A21: Saturación alcanzada (%) | B21: =B19/B17
A23: =IF(B21<0.8,"A este régimen la bobina no se carga del todo: la chispa se debilita","La bobina alcanza buena saturación a este régimen")
A25: Modelo: circuito RL del primario. No incluye la tensión inducida en el secundario ni las pérdidas del condensador.

Sheet Curva de avance
A1: Simulador 2 · Curva de avance al encendido (centrífugo + vacío)
A2: Sistemas del Funcionamiento del Motor (MA.02.06) · Unidad 2 · Edite solo las celdas amarillas (texto azul); todo lo demás se recalcula.
A4: Datos de entrada (grados de cigüeñal) | B4: Valor
A5: Avance inicial o estático (°) | B5: 8
A6: Centrífugo: régimen de inicio (rpm) | B6: 1000
A7: Centrífugo: régimen de avance máximo (rpm) | B7: 4000
A8: Centrífugo: avance máximo (°) | B8: 24
A9: Vacío: depresión de inicio (mbar) | B9: 100
A10: Vacío: depresión de avance máximo (mbar) | B10: 350
A11: Vacío: avance máximo (°) | B11: 15
A12: Depresión a carga parcial que se estudia (mbar) | B12: 300
A13: Régimen de estudio (rpm) | B13: 3000
A15: Resultados al régimen de estudio | B15: Valor | C15: Cómo se obtiene
A16: Avance centrífugo (°) | B16: =B8*MIN(1,MAX(0,(B13-B6)/(B7-B6))) | C16: Lineal entre el régimen de inicio y el de máximo
A17: Avance por vacío (°) | B17: =B11*MIN(1,MAX(0,(B12-B9)/(B10-B9))) | C17: Lineal entre la depresión de inicio y la de máximo
A18: Avance total a plena carga (°) | B18: =B5+B16 | C18: Inicial + centrífugo
A19: Avance total a carga parcial (°) | B19: =B18+B17 | C19: Inicial + centrífugo + vacío
A20: Tiempo que la chispa se adelanta al PMS (ms) | B20: =B19/(6*B13)*1000 | C20: t = grados / (6·n)
A22: Modelo didáctico con un solo tramo lineal por corrector; los distribuidores reales pueden tener dos pendientes (dos muelles).

Sheet Lambda y gases
A1: Simulador 3 · Relación aire-combustible, factor lambda y gases de escape
A2: Sistemas del Funcionamiento del Motor (MA.02.06) · Unidad 2 · Edite solo las celdas amarillas (texto azul); todo lo demás se recalcula.
A4: Datos de entrada | B4: Valor
A5: Masa de aire aspirada (kg/h) | B5: 120
A6: Masa de combustible (kg/h) | B6: 8.6
A7: Relación estequiométrica de la gasolina | B7: 14.7
A9: Resultados | B9: Valor | C9: Interpretación
A10: Relación aire-combustible real (AFR) | B10: =B5/B6
A11: Factor lambda λ | B11: =B10/B7 | C11: =IF(B11<0.97,"Mezcla rica: falta aire",IF(B11>1.03,"Mezcla pobre: sobra aire","Mezcla estequiométrica (ventana lambda)"))
A12: CO estimado (%) | B12: =IF(B11<1,0.3+33*(1-B11),0.3*EXP(-15*(B11-1))) | C12: Sube con la mezcla rica (falta oxígeno)
A13: CO₂ estimado (%) | B13: =IF(B11<1,14.7-22*(1-B11),14.7/B11) | C13: Máximo cerca de λ = 1: combustión completa
A14: O₂ estimado (%) | B14: =IF(B11>1,0.3+20.9*(B11-1)/B11,0.3*EXP(-10*(1-B11))) | C14: Sube con la mezcla pobre o con fallos de encendido
A15: HC estimado (ppm) | B15: =IF(B11<1.05,120+18000*(B11-1.05)^2,120+IF(B11>1.15,40000*(B11-1.15)^2,0)) | C15: Combustible sin quemar: rica o fallo de encendido
A16: NOx estimado (ppm) | B16: =2800*EXP(-1*((B11-1.08)/0.12)^2) | C16: Máximo ligeramente pobre: mucha temperatura y oxígeno
A18: Modelo cualitativo de un motor de gasolina sin catalizador; los valores son orientativos para interpretar el analizador, no datos de un motor concreto.

Sheet Venturi del carburador
A1: Simulador · Venturi del carburador: depresión y dosificación (Bernoulli)
A2: Sistemas del Funcionamiento del Motor (MA.02.06) · Unidad 2 · Edite solo las celdas amarillas (texto azul); todo lo demás se recalcula.
A4: Datos de entrada | B4: Valor
A5: Cilindrada total VT (cm³) | B5: 1600
A6: Régimen n (rpm) | B6: 3000
A7: Rendimiento volumétrico ηv | B7: 0.8
A8: Apertura de la mariposa (%) | B8: 100
A9: Diámetro del colector d1 (mm) | B9: 32
A10: Diámetro del difusor d2 (mm) | B10: 24
A11: Densidad del aire ρa (kg/m³) | B11: 0.95
A12: Diámetro del chiclé principal (mm) | B12: 1.55
A13: Coeficiente de descarga del chiclé Cd | B13: 0.7
A14: Densidad de la gasolina ρc (kg/m³) | B14: 740
A15: Desnivel del surtidor sobre la cuba h (mm) | B15: 5
A17: Resultados | B17: Valor | C17: Cómo se obtiene
A18: Caudal de aire Q (m³/s) | B18: =B5/1000000*B6/2/60*B7*B8/100 | C18: Q = VT·(n/2)/60·ηv·apertura
A19: Velocidad en el colector v1 (m/s) | B19: =B18/(PI()/4*(B9/1000)^2) | C19: v = Q/A
A20: Velocidad en el difusor v2 (m/s) | B20: =B18/(PI()/4*(B10/1000)^2)
A21: Depresión en el difusor Δp (Pa) | B21: =B11/2*(B20^2-B19^2) | C21: Bernoulli: Δp = ρa/2·(v2² − v1²)
A22: Depresión en mm de columna de agua | B22: =B21/9.81 | C22: 1 mmH₂O = 9,81 Pa
A23: Depresión necesaria para elevar la gasolina (Pa) | B23: =B14*9.81*B15/1000 | C23: ρc·g·h
A24: Masa de aire (g/s) | B24: =B11*B18*1000
A25: Masa de gasolina (g/s) | B25: =IF(B21>B23,B13*PI()/4*(B12/1000)^2*SQRT(2*B14*(B21-B23))*1000,0) | C25: ṁc = Cd·Achiclé·√(2·ρc·(Δp − ρc·g·h))
A26: Relación aire/combustible A/C | B26: =IF(B25>0,B24/B25,"sin flujo")
A27: Factor lambda λ | B27: =IF(B25>0,B26/14.7,"—") | C27: λ = (A/C)/14,7
A28: Consumo de gasolina (L/h) | B28: =B25*3600/B14
A30: =IF(B25=0,"La depresión no alcanza para elevar la gasolina: el circuito principal no aporta (actúa el de ralentí)",IF(B27<0.9,"Mezcla rica: chiclé grande o difusor pequeño",IF(B27>1.1,"Mezcla pobre: chiclé pequeño, obstruido o difusor grande","Mezcla próxima a la estequiométrica")))
A31: Modelo didáctico de un carburador elemental (sin emulsión ni compensación). Muestra por qué se necesitan los circuitos de ralentí, compensación y enriquecimiento.

Sheet Oscilograma secundario
A1: Simulador · Oscilograma del secundario de encendido y diagnóstico de fallas
A2: Sistemas del Funcionamiento del Motor (MA.02.06) · Unidad 2 · Edite solo las celdas amarillas (texto azul); todo lo demás se recalcula.
A4: Datos de entrada | B4: Valor
A5: Régimen n (rpm) | B5: 900
A6: Número de cilindros z | B6: 4
A7: Ángulo de cierre (dwell, %) | B7: 55
A8: Falla a simular (modo práctica) | B8: Normal
A9: Modo examen (SI/NO) | B9: NO
A10: Número de ejercicio | B10: 1
A11: Su diagnóstico (modo examen) | B11: Normal
A13: Lectura del oscilograma | B13: Valor | C13: Observación
A14: Falla simulada | B14: =IF(B9="SI","(oculta)",B8)
A15: Tiempo de un ciclo de encendido (ms) | B15: =120000/(B5*B6) | C15: T = 120 000/(n·z)
A16: Tiempo de cierre del primario (ms) | B16: =B15*B7/100 | C16: Dwell × T: tiempo de carga de la bobina
A17: Tensión de encendido (kV) | B17: =INDEX('Datos oscilograma'!$B$3:$B$8,'Datos oscilograma'!$K$3) | C17: Pico (línea de encendido)
A18: Tensión de la chispa (kV) | B18: =INDEX('Datos oscilograma'!$C$3:$C$8,'Datos oscilograma'!$K$3)
A19: Duración de la chispa (ms) | B19: =INDEX('Datos oscilograma'!$D$3:$D$8,'Datos oscilograma'!$K$3)
A21: =IF(B9="SI",IF(B11=INDEX('Datos oscilograma'!$A$3:$A$8,'Datos oscilograma'!$K$3),"¡Correcto! "&INDEX('Datos oscilograma'!$G$3:$G$8,'Datos oscilograma'!$K$3),"Incorrecto: observe de nuevo el pico, la línea de chispa y las oscilaciones."),INDEX('Datos oscilograma'!$G$3:$G$8,'Datos oscilograma'!$K$3))
A25: Partes del oscilograma: 1) línea de encendido (pico), 2) línea de chispa, 3) oscilaciones de la bobina, 4) cierre del primario (inicio del dwell) y 5) zona de dwell hasta el siguiente encendido.

Sheet Guía
B2: Simuladores de la Unidad 2 · Alimentación, ignición y escape
B3: Simulador 1 · Ángulo Dwell y saturación de la bobina
B4: Cambie el Dwell y el régimen. El tiempo de cierre del ruptor se acorta al subir las rpm y la bobina ya no alcanza su corriente máxima: la energía de la chispa cae. Actividad: compare un motor de 4 y de 6 cilindros con el mismo Dwell en porcentaje.
B5: Simulador 2 · Curva de avance
B6: Ingrese los datos del distribuidor (ficha técnica o Autodata) y compare el avance a plena carga con el de carga parcial. Actividad: ¿qué avance total tendría el motor a 3000 rpm si se desconecta la cápsula de vacío?
B7: Simulador 3 · Lambda y gases
B8: Cambie la masa de aire o de combustible y observe cómo se mueven CO, CO₂, O₂, HC y NOx alrededor de λ = 1. Actividad: con una lectura del analizador del laboratorio, estime si la mezcla es rica o pobre y qué sistema revisaría.
B9: Fuentes
B10: Sánchez, E. (2011). Sistemas auxiliares del motor. Macmillan Iberia. · González Calleja, D. (2015). Motores térmicos y sus sistemas auxiliares. Paraninfo. · Los modelos de emisiones son cualitativos y se usan solo con fines didácticos.
B12: Simuladores añadidos (octubre 2026)
B13: Simulador · Venturi del carburador
B14: Aplica la ecuación de Bernoulli al difusor y calcula la gasolina que sale por el chiclé. Observe que a bajo régimen la depresión no alcanza para elevar la gasolina (por eso existe el circuito de ralentí). Actividad: cambie el chiclé de 1,55 a 1,40 mm y lea cómo cambia λ; luego cambie la densidad del aire de 1,20 a 0,95 y explique el enriquecimiento en altura.
... B16: Elija una falla y observe el pico de encendido, la línea de chispa y las oscilaciones. En modo examen (SI) la hoja oculta la falla según el número de ejercicio: el estudiante elige su diagnóstico y recibe la corrección.

Sheet Datos
A2: Régimen (rpm) | B2: Tiempo de cierre (ms) | C2: Corriente de corte (A) | D2: Energía (mJ) | F2: t (ms) | G2: Corriente I(t) (A) | H2: Corte x | I2: Corte y | K2: Régimen (rpm) | L2: Centrífugo (°) | M2: Total plena carga (°) | N2: Total carga parcial (°) | P2: Depresión (mbar) | Q2: Avance vacío (°) | S2: λ | T2: CO (%) | U2: CO₂ (%) | V2: O₂ (%) | W2: HC (ppm) | X2: NOx (ppm) | Z2: λ actual x | AA2: λ actual y
A3: 500 | B3: ='Dwell y bobina'!$B$6*120000/(360*A3) | C3: ='Dwell y bobina'!$B$17*(1-EXP(-B3/'Dwell y bobina'!$B$16)) | D3: =0.5*'Dwell y bobina'!$B$9*C3^2 | F3: 0 | G3: ='Dwell y bobina'!$B$17*(1-EXP(-F3/'Dwell y bobina'!$B$16)) | H3: ='Dwell y bobina'!$B$18 | I3: 0 | K3: 0 | L3: ='Curva de avance'!$B$8*MIN(1,MAX(0,(K3-'Curva de avance'!$B$6)/('Curva de avance'!$B$7-'Curva de avance'!$B$6))) | M3: ='Curva de avance'!$B$5+L3 | N3: =M3+'Curva de avance'!$B$17 | P3: 0 | Q3: ='Curva de avance'!$B$11*MIN(1,MAX(0,(P3-'Curva de avance'!$B$9)/('Curva de avance'!$B$10-'Curva de avance'!$B$9))) | S3: 0.8 | T3: =IF(S3<1,0.3+33*(1-S3),0.3*EXP(-15*(S3-1))) | U3: =IF(S3<1,14.7-22*(1-S3),14.7/S3) | V3: =IF(S3>1,0.3+20.9*(S3-1)/S3,0.3*EXP(-10*(1-S3))) | W3: =IF(S3<1.05,120+18000*(S3-1.05)^2,120+IF(S3>1.15,40000*(S3-1.15)^2,0)) | X3: =2800*EXP(-1*((S3-1.08)/0.12)^2) | Z3: =MIN(1.3,MAX(0.8,'Lambda y gases'!$B$11)) | AA3: 0 | AB3: =Z3 | AC3: 0
A4: 750 | B4: ='Dwell y bobina'!$B$6*120000/(360*A4) | C4: ='Dwell y bobina'!$B$17*(1-EXP(-B4/'Dwell y bobina'!$B$16)) | D4: =0.5*'Dwell y bobina'!$B$9*C4^2 | F4: 0.25 | G4: ='Dwell y bobina'!$B$17*(1-EXP(-F4/'Dwell y bobina'!$B$16)) | H4: ='Dwell y bobina'!$B$18 | I4: ='Dwell y bobina'!$B$17*1.05 | K4: 250 | L4: ='Curva de avance'!$B$8*MIN(1,MAX(0,(K4-'Curva de avance'!$B$6)/('Curva de avance'!$B$7-'Curva de avance'!$B$6))) | M4: ='Curva de avance'!$B$5+L4 | N4: =M4+'Curva de avance'!$B$17 | P4: 25 | Q4: ='Curva de avance'!$B$11*MIN(1,MAX(0,(P4-'Curva de avance'!$B$9)/('Curva de avance'!$B$10-'Curva de avance'!$B$9))) | S4: 0.81 | T4: =IF(S4<1,0.3+33*(1-S4),0.3*EXP(-15*(S4-1))) | U4: =IF(S4<1,14.7-22*(1-S4),14.7/S4) | V4: =IF(S4>1,0.3+20.9*(S4-1)/S4,0.3*EXP(-10*(1-S4))) | W4: =IF(S4<1.05,120+18000*(S4-1.05)^2,120+IF(S4>1.15,40000*(S4-1.15)^2,0)) | X4: =2800*EXP(-1*((S4-1.08)/0.12)^2) | Z4: =Z3 | AA4: 16 | AB4: =Z3 | AC4: 3000
A5: 1000 | B5: ='Dwell y bobina'!$B$6*120000/(360*A5) | C5: ='Dwell y bobina'!$B$17*(1-EXP(-B5/'Dwell y bobina'!$B$16)) | D5: =0.5*'Dwell y bobina'!$B$9*C5^2 | F5: 0.5 | G5: ='Dwell y bobina'!$B$17*(1-EXP(-F5/'Dwell y bobina'!$B$16)) | K5: 500 | L5: ='Curva de avance'!$B$8*MIN(1,MAX(0,(K5-'Curva de avance'!$B$6)/('Curva de avance'!$B$7-'Curva de avance'!$B$6))) | M5: ='Curva de avance'!$B$5+L5 | N5: =M5+'Curva de avance'!$B$17 | P5: 50 | Q5: ='Curva de avance'!$B$11*MIN(1,MAX(0,(P5-'Curva de avance'!$B$9)/('Curva de avance'!$B$10-'Curva de avance'!$B$9))) | S5: 0.82 | T5: =IF(S5<1,0.3+33*(1-S5),0.3*EXP(-15*(S5-1))) | U5: =IF(S5<1,14.7-22*(1-S5),14.7/S5) | V5: =IF(S5>1,0.3+20.9*(S5-1)/S5,0.3*EXP(-10*(1-S5))) | W5: =IF(S5<1.05,120+18000*(S5-1.05)^2,120+IF(S5>1.15,40000*(S5-1.15)^2,0)) | X5: =2800*EXP(-1*((S5-1.08)/0.12)^2)
A6: 1250 | B6: ='Dwell y bobina'!$B$6*120000/(360*A6) | C6: ='Dwell y bobina'!$B$17*(1-EXP(-B6/'Dwell y bobina'!$B$16)) | D6: =0.5*'Dwell y bobina'!$B$9*C6^2 | F6: 0.75 | G6: ='Dwell y bobina'!$B$17*(1-EXP(-F6/'Dwell y bobina'!$B$16)) | K6: 750 | L6: ='Curva de avance'!$B$8*MIN(1,MAX(0,(K6-'Curva de avance'!$B$6)/('Curva de avance'!$B$7-'Curva de avance'!$B$6))) | M6: ='Curva de avance'!$B$5+L6 | N6: =M6+'Curva de avance'!$B$17 | P6: 75 | Q6: ='Curva de avance'!$B$11*MIN(1,MAX(0,(P6-'Curva de avance'!$B$9)/('Curva de avance'!$B$10-'Curva de avance'!$B$9))) | S6: 0.83 | T6: =IF(S6<1,0.3+33*(1-S6),0.3*EXP(-15*(S6-1))) | U6: =IF(S6<1,14.7-22*(1-S6),14.7/S6) | V6: =IF(S6>1,0.3+20.9*(S6-1)/S6,0.3*EXP(-10*(1-S6))) | W6: =IF(S6<1.05,120+18000*(S6-1.05)^2,120+IF(S6>1.15,40000*(S6-1.15)^2,0)) | X6: =2800*EXP(-1*((S6-1.08)/0.12)^2)
A7: 1500 | B7: ='Dwell y bobina'!$B$6*120000/(360*A7) | C7: ='Dwell y bobina'!$B$17*(1-EXP(-B7/'Dwell y bobina'!$B$16)) | D7: =0.5*'Dwell y bobina'!$B$9*C7^2 | F7: 1 | G7: ='Dwell y bobina'!$B$17*(1-EXP(-F7/'Dwell y bobina'!$B$16)) | K7: 1000 | L7: ='Curva de avance'!$B$8*MIN(1,MAX(0,(K7-'Curva de avance'!$B$6)/('Curva de avance'!$B$7-'Curva de avance'!$B$6))) | M7: ='Curva de avance'!$B$5+L7 | N7: =M7+'Curva de avance'!$B$17 | P7: 100 | Q7: ='Curva de avance'!$B$11*MIN(1,MAX(0,(P7-'Curva de avance'!$B$9)/('Curva de avance'!$B$10-'Curva de avance'!$B$9))) | S7: 0.84 | T7: =IF(S7<1,0.3+33*(1-S7),0.3*EXP(-15*(S7-1))) | U7: =IF(S7<1,14.7-22*(1-S7),14.7/S7) | V7: =IF(S7>1,0.3+20.9*(S7-1)/S7,0.3*EXP(-10*(1-S7))) | W7: =IF(S7<1.05,120+18000*(S7-1.05)^2,120+IF(S7>1.15,40000*(S7-1.15)^2,0)) | X7: =2800*EXP(-1*((S7-1.08)/0.12)^2)
A8: 1750 | B8: ='Dwell y bobina'!$B$6*120000/(360*A8) | C8: ='Dwell y bobina'!$B$17*(1-EXP(-B8/'Dwell y bobina'!$B$16)) | D8: =0.5*'Dwell y bobina'!$B$9*C8^2 | F8: 1.25 | G8: ='Dwell y bobina'!$B$17*(1-EXP(-F8/'Dwell y bobina'!$B$16)) | K8: 1250 | L8: ='Curva de avance'!$B$8*MIN(1,MAX(0,(K8-'Curva de avance'!$B$6)/('Curva de avance'!$B$7-'Curva de avance'!$B$6))) | M8: ='Curva de avance'!$B$5+L8 | N8: =M8+'Curva de avance'!$B$17 | P8: 125 | Q8: ='Curva de avance'!$B$11*MIN(1,MAX(0,(P8-'Curva de avance'!$B$9)/('Curva de avance'!$B$10-'Curva de avance'!$B$9))) | S8: 0.85 | T8: =IF(S8<1,0.3+33*(1-S8),0.3*EXP(-15*(S8-1))) | U8: =IF(S8<1,14.7-22*(1-S8),14.7/S8) | V8: =IF(S8>1,0.3+20.9*(S8-1)/S8,0.3*EXP(-10*(1-S8))) | W8: =IF(S8<1.05,120+18000*(S8-1.05)^2,120+IF(S8>1.15,40000*(S8-1.15)^2,0)) | X8: =2800*EXP(-1*((S8-1.08)/0.12)^2)
A9: 2000 | B9: ='Dwell y bobina'!$B$6*120000/(360*A9) | C9: ='Dwell y bobina'!$B$17*(1-EXP(-B9/'Dwell y bobina'!$B$16)) | D9: =0.5*'Dwell y bobina'!$B$9*C9^2 | F9: 1.5 | G9: ='Dwell y bobina'!$B$17*(1-EXP(-F9/'Dwell y bobina'!$B$16)) | K9: 1500 | L9: ='Curva de avance'!$B$8*MIN(1,MAX(0,(K9-'Curva de avance'!$B$6)/('Curva de avance'!$B$7-'Curva de avance'!$B$6))) | M9: ='Curva de avance'!$B$5+L9 | N9: =M9+'Curva de avance'!$B$17 | P9: 150 | Q9: ='Curva de avance'!$B$11*MIN(1,MAX(0,(P9-'Curva de avance'!$B$9)/('Curva de avance'!$B$10-'Curva de avance'!$B$9))) | S9: 0.86 | T9: =IF(S9<1,0.3+33*(1-S9),0.3*EXP(-15*(S9-1))) | U9: =IF(S9<1,14.7-22*(1-S9),14.7/S9) | V9: =IF(S9>1,0.3+20.9*(S9-1)/S9,0.3*EXP(-10*(1-S9))) | W9: =IF(S9<1.05,120+18000*(S9-1.05)^2,120+IF(S9>1.15,40000*(S9-1.15)^2,0)) | X9: =2800*EXP(-1*((S9-1.08)/0.12)^2)
A10: 2250 | B10: ='Dwell y bobina'!$B$6*120000/(360*A10) | C10: ='Dwell y bobina'!$B$17*(1-EXP(-B10/'Dwell y bobina'!$B$16)) | D10: =0.5*'Dwell y bobina'!$B$9*C10^2 | F10: 1.75 | G10: ='Dwell y bobina'!$B$17*(1-EXP(-F10/'Dwell y bobina'!$B$16)) | K10: 1750 | L10: ='Curva de avance'!$B$8*MIN(1,MAX(0,(K10-'Curva de avance'!$B$6)/('Curva de avance'!$B$7-'Curva de avance'!$B$6))) | M10: ='Curva de avance'!$B$5+L10 | N10: =M10+'Curva de avance'!$B$17 | P10: 175 | Q10: ='Curva de avance'!$B$11*MIN(1,MAX(0,(P10-'Curva de avance'!$B$9)/('Curva de avance'!$B$10-'Curva de avance'!$B$9))) | S10: 0.87 | T10: =IF(S10<1,0.3+33*(1-S10),0.3*EXP(-15*(S10-1))) | U10: =IF(S10<1,14.7-22*(1-S10),14.7/S10) | V10: =IF(S10>1,0.3+20.9*(S10-1)/S10,0.3*EXP(-10*(1-S10))) | W10: =IF(S10<1.05,120+18000*(S10-1.05)^2,120+IF(S10>1.15,40000*(S10-1.15)^2,0)) | X10: =2800*EXP(-1*((S10-1.08)/0.12)^2)
A11: 2500 | B11: ='Dwell y bobina'!$B$6*120000/(360*A11) | C11: ='Dwell y bobina'!$B$17*(1-EXP(-B11/'Dwell y bobina'!$B$16)) | D11: =0.5*'Dwell y bobina'!$B$9*C11^2 | F11: 2 | G11: ='Dwell y bobina'!$B$17*(1-EXP(-F11/'Dwell y bobina'!$B$16)) | K11: 2000 | L11: ='Curva de avance'!$B$8*MIN(1,MAX(0,(K11-'Curva de avance'!$B$6)/('Curva de avance'!$B$7-'Curva de avance'!$B$6))) | M11: ='Curva de avance'!$B$5+L11 | N11: =M11+'Curva de avance'!$B$17 | P11: 200 | Q11: ='Curva de avance'!$B$11*MIN(1,MAX(0,(P11-'Curva de avance'!$B$9)/('Curva de avance'!$B$10-'Curva de avance'!$B$9))) | S11: 0.88 | T11: =IF(S11<1,0.3+33*(1-S11),0.3*EXP(-15*(S11-1))) | U11: =IF(S11<1,14.7-22*(1-S11),14.7/S11) | V11: =IF(S11>1,0.3+20.9*(S11-1)/S11,0.3*EXP(-10*(1-S11))) | W11: =IF(S11<1.05,120+18000*(S11-1.05)^2,120+IF(S11>1.15,40000*(S11-1.15)^2,0)) | X11: =2800*EXP(-1*((S11-1.08)/0.12)^2)
A12: 2750 | B12: ='Dwell y bobina'!$B$6*120000/(360*A12) | C12: ='Dwell y bobina'!$B$17*(1-EXP(-B12/'Dwell y bobina'!$B$16)) | D12: =0.5*'Dwell y bobina'!$B$9*C12^2 | F12: 2.25 | G12: ='Dwell y bobina'!$B$17*(1-EXP(-F12/'Dwell y bobina'!$B$16)) | K12: 2250 | L12: ='Curva de avance'!$B$8*MIN(1,MAX(0,(K12-'Curva de avance'!$B$6)/('Curva de avance'!$B$7-'Curva de avance'!$B$6))) | M12: ='Curva de avance'!$B$5+L12 | N12: =M12+'Curva de avance'!$B$17 | P12: 225 | Q12: ='Curva de avance'!$B$11*MIN(1,MAX(0,(P12-'Curva de avance'!$B$9)/('Curva de avance'!$B$10-'Curva de avance'!$B$9))) | S12: 0.89 | T12: =IF(S12<1,0.3+33*(1-S12),0.3*EXP(-15*(S12-1))) | U12: =IF(S12<1,14.7-22*(1-S12),14.7/S12) | V12: =IF(S12>1,0.3+20.9*(S12-1)/S12,0.3*EXP(-10*(1-S12))) | W12: =IF(S12<1.05,120+18000*(S12-1.05)^2,120+IF(S12>1.15,40000*(S12-1.15)^2,0)) | X12: =2800*EXP(-1*((S12-1.08)/0.12)^2)
A13: 3000 | B13: ='Dwell y bobina'!$B$6*120000/(360*A13) | C13: ='Dwell y bobina'!$B$17*(1-EXP(-B13/'Dwell y bobina'!$B$16)) | D13: =0.5*'Dwell y bobina'!$B$9*C13^2 | F13: 2.5 | G13: ='Dwell y bobina'!$B$17*(1-EXP(-F13/'Dwell y bobina'!$B$16)) | K13: 2500 | L13: ='Curva de avance'!$B$8*MIN(1,MAX(0,(K13-'Curva de avance'!$B$6)/('Curva de avance'!$B$7-'Curva de avance'!$B$6))) | M13: ='Curva de avance'!$B$5+L13 | N13: =M13+'Curva de avance'!$B$17 | P13: 250 | Q13: ='Curva de avance'!$B$11*MIN(1,MAX(0,(P13-'Curva de avance'!$B$9)/('Curva de avance'!$B$10-'Curva de avance'!$B$9))) | S13: 0.9 | T13: =IF(S13<1,0.3+33*(1-S13),0.3*EXP(-15*(S13-1))) | U13: =IF(S13<1,14.7-22*(1-S13),14.7/S13) | V13: =IF(S13>1,0.3+20.9*(S13-1)/S13,0.3*EXP(-10*(1-S13))) | W13: =IF(S13<1.05,120+18000*(S13-1.05)^2,120+IF(S13>1.15,40000*(S13-1.15)^2,0)) | X13: =2800*EXP(-1*((S13-1.08)/0.12)^2)
A14: 3250 | B14: ='Dwell y bobina'!$B$6*120000/(360*A14) | C14: ='Dwell y bobina'!$B$17*(1-EXP(-B14/'Dwell y bobina'!$B$16)) | D14: =0.5*'Dwell y bobina'!$B$9*C14^2 | F14: 2.75 | G14: ='Dwell y bobina'!$B$17*(1-EXP(-F14/'Dwell y bobina'!$B$16)) | K14: 2750 | L14: ='Curva de avance'!$B$8*MIN(1,MAX(0,(K14-'Curva de avance'!$B$6)/('Curva de avance'!$B$7-'Curva de avance'!$B$6))) | M14: ='Curva de avance'!$B$5+L14 | N14: =M14+'Curva de avance'!$B$17 | P14: 275 | Q14: ='Curva de avance'!$B$11*MIN(1,MAX(0,(P14-'Curva de avance'!$B$9)/('Curva de avance'!$B$10-'Curva de avance'!$B$9))) | S14: 0.91 | T14: =IF(S14<1,0.3+33*(1-S14),0.3*EXP(-15*(S14-1))) | U14: =IF(S14<1,14.7-22*(1-S14),14.7/S14) | V14: =IF(S14>1,0.3+20.9*(S14-1)/S14,0.3*EXP(-10*(1-S14))) | W14: =IF(S14<1.05,120+18000*(S14-1.05)^2,120+IF(S14>1.15,40000*(S14-1.15)^2,0)) | X14: =2800*EXP(-1*((S14-1.08)/0.12)^2)
A15: 3500 | B15: ='Dwell y bobina'!$B$6*120000/(360*A15) | C15: ='Dwell y bobina'!$B$17*(1-EXP(-B15/'Dwell y bobina'!$B$16)) | D15: =0.5*'Dwell y bobina'!$B$9*C15^2 | F15: 3 | G15: ='Dwell y bobina'!$B$17*(1-EXP(-F15/'Dwell y bobina'!$B$16)) | K15: 3000 | L15: ='Curva de avance'!$B$8*MIN(1,MAX(0,(K15-'Curva de avance'!$B$6)/('Curva de avance'!$B$7-'Curva de avance'!$B$6))) | M15: ='Curva de avance'!$B$5+L15 | N15: =M15+'Curva de avance'!$B$17 | P15: 300 | Q15: ='Curva de avance'!$B$11*MIN(1,MAX(0,(P15-'Curva de avance'!$B$9)/('Curva de avance'!$B$10-'Curva de avance'!$B$9))) | S15: 0.92 | T15: =IF(S15<1,0.3+33*(1-S15),0.3*EXP(-15*(S15-1))) | U15: =IF(S15<1,14.7-22*(1-S15),14.7/S15) | V15: =IF(S15>1,0.3+20.9*(S15-1)/S15,0.3*EXP(-10*(1-S15))) | W15: =IF(S15<1.05,120+18000*(S15-1.05)^2,120+IF(S15>1.15,40000*(S15-1.15)^2,0)) | X15: =2800*EXP(-1*((S15-1.08)/0.12)^2)
A16: 3750 | B16: ='Dwell y bobina'!$B$6*120000/(360*A16) | C16: ='Dwell y bobina'!$B$17*(1-EXP(-B16/'Dwell y bobina'!$B$16)) | D16: =0.5*'Dwell y bobina'!$B$9*C16^2 | F16: 3.25 | G16: ='Dwell y bobina'!$B$17*(1-EXP(-F16/'Dwell y bobina'!$B$16)) | K16: 3250 | L16: ='Curva de avance'!$B$8*MIN(1,MAX(0,(K16-'Curva de avance'!$B$6)/('Curva de avance'!$B$7-'Curva de avance'!$B$6))) | M16: ='Curva de avance'!$B$5+L16 | N16: =M16+'Curva de avance'!$B$17 | P16: 325 | Q16: ='Curva de avance'!$B$11*MIN(1,MAX(0,(P16-'Curva de avance'!$B$9)/('Curva de avance'!$B$10-'Curva de avance'!$B$9))) | S16: 0.93 | T16: =IF(S16<1,0.3+33*(1-S16),0.3*EXP(-15*(S16-1))) | U16: =IF(S16<1,14.7-22*(1-S16),14.7/S16) | V16: =IF(S16>1,0.3+20.9*(S16-1)/S16,0.3*EXP(-10*(1-S16))) | W16: =IF(S16<1.05,120+18000*(S16-1.05)^2,120+IF(S16>1.15,40000*(S16-1.15)^2,0)) | X16: =2800*EXP(-1*((S16-1.08)/0.12)^2)
... A27: 6500 | B27: ='Dwell y bobina'!$B$6*120000/(360*A27) | C27: ='Dwell y bobina'!$B$17*(1-EXP(-B27/'Dwell y bobina'!$B$16)) | D27: =0.5*'Dwell y bobina'!$B$9*C27^2 | F27: 6 | G27: ='Dwell y bobina'!$B$17*(1-EXP(-F27/'Dwell y bobina'!$B$16)) | K27: 6000 | L27: ='Curva de avance'!$B$8*MIN(1,MAX(0,(K27-'Curva de avance'!$B$6)/('Curva de avance'!$B$7-'Curva de avance'!$B$6))) | M27: ='Curva de avance'!$B$5+L27 | N27: =M27+'Curva de avance'!$B$17 | P27: 600 | Q27: ='Curva de avance'!$B$11*MIN(1,MAX(0,(P27-'Curva de avance'!$B$9)/('Curva de avance'!$B$10-'Curva de avance'!$B$9))) | S27: 1.04 | T27: =IF(S27<1,0.3+33*(1-S27),0.3*EXP(-15*(S27-1))) | U27: =IF(S27<1,14.7-22*(1-S27),14.7/S27) | V27: =IF(S27>1,0.3+20.9*(S27-1)/S27,0.3*EXP(-10*(1-S27))) | W27: =IF(S27<1.05,120+18000*(S27-1.05)^2,120+IF(S27>1.15,40000*(S27-1.15)^2,0)) | X27: =2800*EXP(-1*((S27-1.08)/0.12)^2)
A28: 6750 | B28: ='Dwell y bobina'!$B$6*120000/(360*A28) | C28: ='Dwell y bobina'!$B$17*(1-EXP(-B28/'Dwell y bobina'!$B$16)) | D28: =0.5*'Dwell y bobina'!$B$9*C28^2 | F28: 6.25 | G28: ='Dwell y bobina'!$B$17*(1-EXP(-F28/'Dwell y bobina'!$B$16)) | K28: 6250 | L28: ='Curva de avance'!$B$8*MIN(1,MAX(0,(K28-'Curva de avance'!$B$6)/('Curva de avance'!$B$7-'Curva de avance'!$B$6))) | M28: ='Curva de avance'!$B$5+L28 | N28: =M28+'Curva de avance'!$B$17 | S28: 1.05 | T28: =IF(S28<1,0.3+33*(1-S28),0.3*EXP(-15*(S28-1))) | U28: =IF(S28<1,14.7-22*(1-S28),14.7/S28) | V28: =IF(S28>1,0.3+20.9*(S28-1)/S28,0.3*EXP(-10*(1-S28))) | W28: =IF(S28<1.05,120+18000*(S28-1.05)^2,120+IF(S28>1.15,40000*(S28-1.15)^2,0)) | X28: =2800*EXP(-1*((S28-1.08)/0.12)^2)
A29: 7000 | B29: ='Dwell y bobina'!$B$6*120000/(360*A29) | C29: ='Dwell y bobina'!$B$17*(1-EXP(-B29/'Dwell y bobina'!$B$16)) | D29: =0.5*'Dwell y bobina'!$B$9*C29^2 | F29: 6.5 | G29: ='Dwell y bobina'!$B$17*(1-EXP(-F29/'Dwell y bobina'!$B$16)) | K29: 6500 | L29: ='Curva de avance'!$B$8*MIN(1,MAX(0,(K29-'Curva de avance'!$B$6)/('Curva de avance'!$B$7-'Curva de avance'!$B$6))) | M29: ='Curva de avance'!$B$5+L29 | N29: =M29+'Curva de avance'!$B$17 | S29: 1.06 | T29: =IF(S29<1,0.3+33*(1-S29),0.3*EXP(-15*(S29-1))) | U29: =IF(S29<1,14.7-22*(1-S29),14.7/S29) | V29: =IF(S29>1,0.3+20.9*(S29-1)/S29,0.3*EXP(-10*(1-S29))) | W29: =IF(S29<1.05,120+18000*(S29-1.05)^2,120+IF(S29>1.15,40000*(S29-1.15)^2,0)) | X29: =2800*EXP(-1*((S29-1.08)/0.12)^2)
F30: 6.75 | G30: ='Dwell y bobina'!$B$17*(1-EXP(-F30/'Dwell y bobina'!$B$16)) | K30: 6750 | L30: ='Curva de avance'!$B$8*MIN(1,MAX(0,(K30-'Curva de avance'!$B$6)/('Curva de avance'!$B$7-'Curva de avance'!$B$6))) | M30: ='Curva de avance'!$B$5+L30 | N30: =M30+'Curva de avance'!$B$17 | S30: 1.07 | T30: =IF(S30<1,0.3+33*(1-S30),0.3*EXP(-15*(S30-1))) | U30: =IF(S30<1,14.7-22*(1-S30),14.7/S30) | V30: =IF(S30>1,0.3+20.9*(S30-1)/S30,0.3*EXP(-10*(1-S30))) | W30: =IF(S30<1.05,120+18000*(S30-1.05)^2,120+IF(S30>1.15,40000*(S30-1.15)^2,0)) | X30: =2800*EXP(-1*((S30-1.08)/0.12)^2)
F31: 7 | G31: ='Dwell y bobina'!$B$17*(1-EXP(-F31/'Dwell y bobina'!$B$16)) | K31: 7000 | L31: ='Curva de avance'!$B$8*MIN(1,MAX(0,(K31-'Curva de avance'!$B$6)/('Curva de avance'!$B$7-'Curva de avance'!$B$6))) | M31: ='Curva de avance'!$B$5+L31 | N31: =M31+'Curva de avance'!$B$17 | S31: 1.08 | T31: =IF(S31<1,0.3+33*(1-S31),0.3*EXP(-15*(S31-1))) | U31: =IF(S31<1,14.7-22*(1-S31),14.7/S31) | V31: =IF(S31>1,0.3+20.9*(S31-1)/S31,0.3*EXP(-10*(1-S31))) | W31: =IF(S31<1.05,120+18000*(S31-1.05)^2,120+IF(S31>1.15,40000*(S31-1.15)^2,0)) | X31: =2800*EXP(-1*((S31-1.08)/0.12)^2)
F32: 7.25 | G32: ='Dwell y bobina'!$B$17*(1-EXP(-F32/'Dwell y bobina'!$B$16)) | S32: 1.09 | T32: =IF(S32<1,0.3+33*(1-S32),0.3*EXP(-15*(S32-1))) | U32: =IF(S32<1,14.7-22*(1-S32),14.7/S32) | V32: =IF(S32>1,0.3+20.9*(S32-1)/S32,0.3*EXP(-10*(1-S32))) | W32: =IF(S32<1.05,120+18000*(S32-1.05)^2,120+IF(S32>1.15,40000*(S32-1.15)^2,0)) | X32: =2800*EXP(-1*((S32-1.08)/0.12)^2)
F33: 7.5 | G33: ='Dwell y bobina'!$B$17*(1-EXP(-F33/'Dwell y bobina'!$B$16)) | S33: 1.1 | T33: =IF(S33<1,0.3+33*(1-S33),0.3*EXP(-15*(S33-1))) | U33: =IF(S33<1,14.7-22*(1-S33),14.7/S33) | V33: =IF(S33>1,0.3+20.9*(S33-1)/S33,0.3*EXP(-10*(1-S33))) | W33: =IF(S33<1.05,120+18000*(S33-1.05)^2,120+IF(S33>1.15,40000*(S33-1.15)^2,0)) | X33: =2800*EXP(-1*((S33-1.08)/0.12)^2)
F34: 7.75 | G34: ='Dwell y bobina'!$B$17*(1-EXP(-F34/'Dwell y bobina'!$B$16)) | S34: 1.11 | T34: =IF(S34<1,0.3+33*(1-S34),0.3*EXP(-15*(S34-1))) | U34: =IF(S34<1,14.7-22*(1-S34),14.7/S34) | V34: =IF(S34>1,0.3+20.9*(S34-1)/S34,0.3*EXP(-10*(1-S34))) | W34: =IF(S34<1.05,120+18000*(S34-1.05)^2,120+IF(S34>1.15,40000*(S34-1.15)^2,0)) | X34: =2800*EXP(-1*((S34-1.08)/0.12)^2)
F35: 8 | G35: ='Dwell y bobina'!$B$17*(1-EXP(-F35/'Dwell y bobina'!$B$16)) | S35: 1.12 | T35: =IF(S35<1,0.3+33*(1-S35),0.3*EXP(-15*(S35-1))) | U35: =IF(S35<1,14.7-22*(1-S35),14.7/S35) | V35: =IF(S35>1,0.3+20.9*(S35-1)/S35,0.3*EXP(-10*(1-S35))) | W35: =IF(S35<1.05,120+18000*(S35-1.05)^2,120+IF(S35>1.15,40000*(S35-1.15)^2,0)) | X35: =2800*EXP(-1*((S35-1.08)/0.12)^2)
F36: 8.25 | G36: ='Dwell y bobina'!$B$17*(1-EXP(-F36/'Dwell y bobina'!$B$16)) | S36: 1.13 | T36: =IF(S36<1,0.3+33*(1-S36),0.3*EXP(-15*(S36-1))) | U36: =IF(S36<1,14.7-22*(1-S36),14.7/S36) | V36: =IF(S36>1,0.3+20.9*(S36-1)/S36,0.3*EXP(-10*(1-S36))) | W36: =IF(S36<1.05,120+18000*(S36-1.05)^2,120+IF(S36>1.15,40000*(S36-1.15)^2,0)) | X36: =2800*EXP(-1*((S36-1.08)/0.12)^2)
F37: 8.5 | G37: ='Dwell y bobina'!$B$17*(1-EXP(-F37/'Dwell y bobina'!$B$16)) | S37: 1.14 | T37: =IF(S37<1,0.3+33*(1-S37),0.3*EXP(-15*(S37-1))) | U37: =IF(S37<1,14.7-22*(1-S37),14.7/S37) | V37: =IF(S37>1,0.3+20.9*(S37-1)/S37,0.3*EXP(-10*(1-S37))) | W37: =IF(S37<1.05,120+18000*(S37-1.05)^2,120+IF(S37>1.15,40000*(S37-1.15)^2,0)) | X37: =2800*EXP(-1*((S37-1.08)/0.12)^2)
F38: 8.75 | G38: ='Dwell y bobina'!$B$17*(1-EXP(-F38/'Dwell y bobina'!$B$16)) | S38: 1.15 | T38: =IF(S38<1,0.3+33*(1-S38),0.3*EXP(-15*(S38-1))) | U38: =IF(S38<1,14.7-22*(1-S38),14.7/S38) | V38: =IF(S38>1,0.3+20.9*(S38-1)/S38,0.3*EXP(-10*(1-S38))) | W38: =IF(S38<1.05,120+18000*(S38-1.05)^2,120+IF(S38>1.15,40000*(S38-1.15)^2,0)) | X38: =2800*EXP(-1*((S38-1.08)/0.12)^2)
F39: 9 | G39: ='Dwell y bobina'!$B$17*(1-EXP(-F39/'Dwell y bobina'!$B$16)) | S39: 1.16 | T39: =IF(S39<1,0.3+33*(1-S39),0.3*EXP(-15*(S39-1))) | U39: =IF(S39<1,14.7-22*(1-S39),14.7/S39) | V39: =IF(S39>1,0.3+20.9*(S39-1)/S39,0.3*EXP(-10*(1-S39))) | W39: =IF(S39<1.05,120+18000*(S39-1.05)^2,120+IF(S39>1.15,40000*(S39-1.15)^2,0)) | X39: =2800*EXP(-1*((S39-1.08)/0.12)^2)
F40: 9.25 | G40: ='Dwell y bobina'!$B$17*(1-EXP(-F40/'Dwell y bobina'!$B$16)) | S40: 1.17 | T40: =IF(S40<1,0.3+33*(1-S40),0.3*EXP(-15*(S40-1))) | U40: =IF(S40<1,14.7-22*(1-S40),14.7/S40) | V40: =IF(S40>1,0.3+20.9*(S40-1)/S40,0.3*EXP(-10*(1-S40))) | W40: =IF(S40<1.05,120+18000*(S40-1.05)^2,120+IF(S40>1.15,40000*(S40-1.15)^2,0)) | X40: =2800*EXP(-1*((S40-1.08)/0.12)^2)
F41: 9.5 | G41: ='Dwell y bobina'!$B$17*(1-EXP(-F41/'Dwell y bobina'!$B$16)) | S41: 1.18 | T41: =IF(S41<1,0.3+33*(1-S41),0.3*EXP(-15*(S41-1))) | U41: =IF(S41<1,14.7-22*(1-S41),14.7/S41) | V41: =IF(S41>1,0.3+20.9*(S41-1)/S41,0.3*EXP(-10*(1-S41))) | W41: =IF(S41<1.05,120+18000*(S41-1.05)^2,120+IF(S41>1.15,40000*(S41-1.15)^2,0)) | X41: =2800*EXP(-1*((S41-1.08)/0.12)^2)
F42: 9.75 | G42: ='Dwell y bobina'!$B$17*(1-EXP(-F42/'Dwell y bobina'!$B$16)) | S42: 1.19 | T42: =IF(S42<1,0.3+33*(1-S42),0.3*EXP(-15*(S42-1))) | U42: =IF(S42<1,14.7-22*(1-S42),14.7/S42) | V42: =IF(S42>1,0.3+20.9*(S42-1)/S42,0.3*EXP(-10*(1-S42))) | W42: =IF(S42<1.05,120+18000*(S42-1.05)^2,120+IF(S42>1.15,40000*(S42-1.15)^2,0)) | X42: =2800*EXP(-1*((S42-1.08)/0.12)^2)
F43: 10 | G43: ='Dwell y bobina'!$B$17*(1-EXP(-F43/'Dwell y bobina'!$B$16)) | S43: 1.2 | T43: =IF(S43<1,0.3+33*(1-S43),0.3*EXP(-15*(S43-1))) | U43: =IF(S43<1,14.7-22*(1-S43),14.7/S43) | V43: =IF(S43>1,0.3+20.9*(S43-1)/S43,0.3*EXP(-10*(1-S43))) | W43: =IF(S43<1.05,120+18000*(S43-1.05)^2,120+IF(S43>1.15,40000*(S43-1.15)^2,0)) | X43: =2800*EXP(-1*((S43-1.08)/0.12)^2)
... F51: 12 | G51: ='Dwell y bobina'!$B$17*(1-EXP(-F51/'Dwell y bobina'!$B$16)) | S51: 1.28 | T51: =IF(S51<1,0.3+33*(1-S51),0.3*EXP(-15*(S51-1))) | U51: =IF(S51<1,14.7-22*(1-S51),14.7/S51) | V51: =IF(S51>1,0.3+20.9*(S51-1)/S51,0.3*EXP(-10*(1-S51))) | W51: =IF(S51<1.05,120+18000*(S51-1.05)^2,120+IF(S51>1.15,40000*(S51-1.15)^2,0)) | X51: =2800*EXP(-1*((S51-1.08)/0.12)^2)
S52: 1.29 | T52: =IF(S52<1,0.3+33*(1-S52),0.3*EXP(-15*(S52-1))) | U52: =IF(S52<1,14.7-22*(1-S52),14.7/S52) | V52: =IF(S52>1,0.3+20.9*(S52-1)/S52,0.3*EXP(-10*(1-S52))) | W52: =IF(S52<1.05,120+18000*(S52-1.05)^2,120+IF(S52>1.15,40000*(S52-1.15)^2,0)) | X52: =2800*EXP(-1*((S52-1.08)/0.12)^2)
S53: 1.3 | T53: =IF(S53<1,0.3+33*(1-S53),0.3*EXP(-15*(S53-1))) | U53: =IF(S53<1,14.7-22*(1-S53),14.7/S53) | V53: =IF(S53>1,0.3+20.9*(S53-1)/S53,0.3*EXP(-10*(1-S53))) | W53: =IF(S53<1.05,120+18000*(S53-1.05)^2,120+IF(S53>1.15,40000*(S53-1.15)^2,0)) | X53: =2800*EXP(-1*((S53-1.08)/0.12)^2)

Sheet Datos venturi
A1: Barrido de régimen (no editar)
A2: rpm | B2: Δp (mmH₂O) | C2: λ | D2: λ = 1
A3: 600 | B3: =('Venturi del carburador'!$B$11/2*((('Venturi del carburador'!$B$5/1000000*A3/2/60*'Venturi del carburador'!$B$7*'Venturi del carburador'!$B$8/100)/(PI()/4*('Venturi del carburador'!$B$10/1000)^2))^2-(('Venturi del carburador'!$B$5/1000000*A3/2/60*'Venturi del carburador'!$B$7*'Venturi del carburador'!$B$8/100)/(PI()/4*('Venturi del carburador'!$B$9/1000)^2))^2))/9.81 | C3: =IF(B3*9.81>'Venturi del carburador'!$B$23,'Venturi del carburador'!$B$11*('Venturi del carburador'!$B$5/1000000*A3/2/60*'Venturi del carburador'!$B$7*'Venturi del carburador'!$B$8/100)/('Venturi del carburador'!$B$13*PI()/4*('Venturi del carburador'!$B$12/1000)^2*SQRT(2*'Venturi del carburador'!$B$14*MAX(B3*9.81-'Venturi del carburador'!$B$23,0)))/14.7,NA()) | D3: 1
A4: 800 | B4: =('Venturi del carburador'!$B$11/2*((('Venturi del carburador'!$B$5/1000000*A4/2/60*'Venturi del carburador'!$B$7*'Venturi del carburador'!$B$8/100)/(PI()/4*('Venturi del carburador'!$B$10/1000)^2))^2-(('Venturi del carburador'!$B$5/1000000*A4/2/60*'Venturi del carburador'!$B$7*'Venturi del carburador'!$B$8/100)/(PI()/4*('Venturi del carburador'!$B$9/1000)^2))^2))/9.81 | C4: =IF(B4*9.81>'Venturi del carburador'!$B$23,'Venturi del carburador'!$B$11*('Venturi del carburador'!$B$5/1000000*A4/2/60*'Venturi del carburador'!$B$7*'Venturi del carburador'!$B$8/100)/('Venturi del carburador'!$B$13*PI()/4*('Venturi del carburador'!$B$12/1000)^2*SQRT(2*'Venturi del carburador'!$B$14*MAX(B4*9.81-'Venturi del carburador'!$B$23,0)))/14.7,NA()) | D4: 1
A5: 1000 | B5: =('Venturi del carburador'!$B$11/2*((('Venturi del carburador'!$B$5/1000000*A5/2/60*'Venturi del carburador'!$B$7*'Venturi del carburador'!$B$8/100)/(PI()/4*('Venturi del carburador'!$B$10/1000)^2))^2-(('Venturi del carburador'!$B$5/1000000*A5/2/60*'Venturi del carburador'!$B$7*'Venturi del carburador'!$B$8/100)/(PI()/4*('Venturi del carburador'!$B$9/1000)^2))^2))/9.81 | C5: =IF(B5*9.81>'Venturi del carburador'!$B$23,'Venturi del carburador'!$B$11*('Venturi del carburador'!$B$5/1000000*A5/2/60*'Venturi del carburador'!$B$7*'Venturi del carburador'!$B$8/100)/('Venturi del carburador'!$B$13*PI()/4*('Venturi del carburador'!$B$12/1000)^2*SQRT(2*'Venturi del carburador'!$B$14*MAX(B5*9.81-'Venturi del carburador'!$B$23,0)))/14.7,NA()) | D5: 1
A6: 1200 | B6: =('Venturi del carburador'!$B$11/2*((('Venturi del carburador'!$B$5/1000000*A6/2/60*'Venturi del carburador'!$B$7*'Venturi del carburador'!$B$8/100)/(PI()/4*('Venturi del carburador'!$B$10/1000)^2))^2-(('Venturi del carburador'!$B$5/1000000*A6/2/60*'Venturi del carburador'!$B$7*'Venturi del carburador'!$B$8/100)/(PI()/4*('Venturi del carburador'!$B$9/1000)^2))^2))/9.81 | C6: =IF(B6*9.81>'Venturi del carburador'!$B$23,'Venturi del carburador'!$B$11*('Venturi del carburador'!$B$5/1000000*A6/2/60*'Venturi del carburador'!$B$7*'Venturi del carburador'!$B$8/100)/('Venturi del carburador'!$B$13*PI()/4*('Venturi del carburador'!$B$12/1000)^2*SQRT(2*'Venturi del carburador'!$B$14*MAX(B6*9.81-'Venturi del carburador'!$B$23,0)))/14.7,NA()) | D6: 1
A7: 1400 | B7: =('Venturi del carburador'!$B$11/2*((('Venturi del carburador'!$B$5/1000000*A7/2/60*'Venturi del carburador'!$B$7*'Venturi del carburador'!$B$8/100)/(PI()/4*('Venturi del carburador'!$B$10/1000)^2))^2-(('Venturi del carburador'!$B$5/1000000*A7/2/60*'Venturi del carburador'!$B$7*'Venturi del carburador'!$B$8/100)/(PI()/4*('Venturi del carburador'!$B$9/1000)^2))^2))/9.81 | C7: =IF(B7*9.81>'Venturi del carburador'!$B$23,'Venturi del carburador'!$B$11*('Venturi del carburador'!$B$5/1000000*A7/2/60*'Venturi del carburador'!$B$7*'Venturi del carburador'!$B$8/100)/('Venturi del carburador'!$B$13*PI()/4*('Venturi del carburador'!$B$12/1000)^2*SQRT(2*'Venturi del carburador'!$B$14*MAX(B7*9.81-'Venturi del carburador'!$B$23,0)))/14.7,NA()) | D7: 1
A8: 1600 | B8: =('Venturi del carburador'!$B$11/2*((('Venturi del carburador'!$B$5/1000000*A8/2/60*'Venturi del carburador'!$B$7*'Venturi del carburador'!$B$8/100)/(PI()/4*('Venturi del carburador'!$B$10/1000)^2))^2-(('Venturi del carburador'!$B$5/1000000*A8/2/60*'Venturi del carburador'!$B$7*'Venturi del carburador'!$B$8/100)/(PI()/4*('Venturi del carburador'!$B$9/1000)^2))^2))/9.81 | C8: =IF(B8*9.81>'Venturi del carburador'!$B$23,'Venturi del carburador'!$B$11*('Venturi del carburador'!$B$5/1000000*A8/2/60*'Venturi del carburador'!$B$7*'Venturi del carburador'!$B$8/100)/('Venturi del carburador'!$B$13*PI()/4*('Venturi del carburador'!$B$12/1000)^2*SQRT(2*'Venturi del carburador'!$B$14*MAX(B8*9.81-'Venturi del carburador'!$B$23,0)))/14.7,NA()) | D8: 1
A9: 1800 | B9: =('Venturi del carburador'!$B$11/2*((('Venturi del carburador'!$B$5/1000000*A9/2/60*'Venturi del carburador'!$B$7*'Venturi del carburador'!$B$8/100)/(PI()/4*('Venturi del carburador'!$B$10/1000)^2))^2-(('Venturi del carburador'!$B$5/1000000*A9/2/60*'Venturi del carburador'!$B$7*'Venturi del carburador'!$B$8/100)/(PI()/4*('Venturi del carburador'!$B$9/1000)^2))^2))/9.81 | C9: =IF(B9*9.81>'Venturi del carburador'!$B$23,'Venturi del carburador'!$B$11*('Venturi del carburador'!$B$5/1000000*A9/2/60*'Venturi del carburador'!$B$7*'Venturi del carburador'!$B$8/100)/('Venturi del carburador'!$B$13*PI()/4*('Venturi del carburador'!$B$12/1000)^2*SQRT(2*'Venturi del carburador'!$B$14*MAX(B9*9.81-'Venturi del carburador'!$B$23,0)))/14.7,NA()) | D9: 1
A10: 2000 | B10: =('Venturi del carburador'!$B$11/2*((('Venturi del carburador'!$B$5/1000000*A10/2/60*'Venturi del carburador'!$B$7*'Venturi del carburador'!$B$8/100)/(PI()/4*('Venturi del carburador'!$B$10/1000)^2))^2-(('Venturi del carburador'!$B$5/1000000*A10/2/60*'Venturi del carburador'!$B$7*'Venturi del carburador'!$B$8/100)/(PI()/4*('Venturi del carburador'!$B$9/1000)^2))^2))/9.81 | C10: =IF(B10*9.81>'Venturi del carburador'!$B$23,'Venturi del carburador'!$B$11*('Venturi del carburador'!$B$5/1000000*A10/2/60*'Venturi del carburador'!$B$7*'Venturi del carburador'!$B$8/100)/('Venturi del carburador'!$B$13*PI()/4*('Venturi del carburador'!$B$12/1000)^2*SQRT(2*'Venturi del carburador'!$B$14*MAX(B10*9.81-'Venturi del carburador'!$B$23,0)))/14.7,NA()) | D10: 1
A11: 2200 | B11: =('Venturi del carburador'!$B$11/2*((('Venturi del carburador'!$B$5/1000000*A11/2/60*'Venturi del carburador'!$B$7*'Venturi del carburador'!$B$8/100)/(PI()/4*('Venturi del carburador'!$B$10/1000)^2))^2-(('Venturi del carburador'!$B$5/1000000*A11/2/60*'Venturi del carburador'!$B$7*'Venturi del carburador'!$B$8/100)/(PI()/4*('Venturi del carburador'!$B$9/1000)^2))^2))/9.81 | C11: =IF(B11*9.81>'Venturi del carburador'!$B$23,'Venturi del carburador'!$B$11*('Venturi del carburador'!$B$5/1000000*A11/2/60*'Venturi del carburador'!$B$7*'Venturi del carburador'!$B$8/100)/('Venturi del carburador'!$B$13*PI()/4*('Venturi del carburador'!$B$12/1000)^2*SQRT(2*'Venturi del carburador'!$B$14*MAX(B11*9.81-'Venturi del carburador'!$B$23,0)))/14.7,NA()) | D11: 1
A12: 2400 | B12: =('Venturi del carburador'!$B$11/2*((('Venturi del carburador'!$B$5/1000000*A12/2/60*'Venturi del carburador'!$B$7*'Venturi del carburador'!$B$8/100)/(PI()/4*('Venturi del carburador'!$B$10/1000)^2))^2-(('Venturi del carburador'!$B$5/1000000*A12/2/60*'Venturi del carburador'!$B$7*'Venturi del carburador'!$B$8/100)/(PI()/4*('Venturi del carburador'!$B$9/1000)^2))^2))/9.81 | C12: =IF(B12*9.81>'Venturi del carburador'!$B$23,'Venturi del carburador'!$B$11*('Venturi del carburador'!$B$5/1000000*A12/2/60*'Venturi del carburador'!$B$7*'Venturi del carburador'!$B$8/100)/('Venturi del carburador'!$B$13*PI()/4*('Venturi del carburador'!$B$12/1000)^2*SQRT(2*'Venturi del carburador'!$B$14*MAX(B12*9.81-'Venturi del carburador'!$B$23,0)))/14.7,NA()) | D12: 1
A13: 2600 | B13: =('Venturi del carburador'!$B$11/2*((('Venturi del carburador'!$B$5/1000000*A13/2/60*'Venturi del carburador'!$B$7*'Venturi del carburador'!$B$8/100)/(PI()/4*('Venturi del carburador'!$B$10/1000)^2))^2-(('Venturi del carburador'!$B$5/1000000*A13/2/60*'Venturi del carburador'!$B$7*'Venturi del carburador'!$B$8/100)/(PI()/4*('Venturi del carburador'!$B$9/1000)^2))^2))/9.81 | C13: =IF(B13*9.81>'Venturi del carburador'!$B$23,'Venturi del carburador'!$B$11*('Venturi del carburador'!$B$5/1000000*A13/2/60*'Venturi del carburador'!$B$7*'Venturi del carburador'!$B$8/100)/('Venturi del carburador'!$B$13*PI()/4*('Venturi del carburador'!$B$12/1000)^2*SQRT(2*'Venturi del carburador'!$B$14*MAX(B13*9.81-'Venturi del carburador'!$B$23,0)))/14.7,NA()) | D13: 1
A14: 2800 | B14: =('Venturi del carburador'!$B$11/2*((('Venturi del carburador'!$B$5/1000000*A14/2/60*'Venturi del carburador'!$B$7*'Venturi del carburador'!$B$8/100)/(PI()/4*('Venturi del carburador'!$B$10/1000)^2))^2-(('Venturi del carburador'!$B$5/1000000*A14/2/60*'Venturi del carburador'!$B$7*'Venturi del carburador'!$B$8/100)/(PI()/4*('Venturi del carburador'!$B$9/1000)^2))^2))/9.81 | C14: =IF(B14*9.81>'Venturi del carburador'!$B$23,'Venturi del carburador'!$B$11*('Venturi del carburador'!$B$5/1000000*A14/2/60*'Venturi del carburador'!$B$7*'Venturi del carburador'!$B$8/100)/('Venturi del carburador'!$B$13*PI()/4*('Venturi del carburador'!$B$12/1000)^2*SQRT(2*'Venturi del carburador'!$B$14*MAX(B14*9.81-'Venturi del carburador'!$B$23,0)))/14.7,NA()) | D14: 1
... A30: 6000 | B30: =('Venturi del carburador'!$B$11/2*((('Venturi del carburador'!$B$5/1000000*A30/2/60*'Venturi del carburador'!$B$7*'Venturi del carburador'!$B$8/100)/(PI()/4*('Venturi del carburador'!$B$10/1000)^2))^2-(('Venturi del carburador'!$B$5/1000000*A30/2/60*'Venturi del carburador'!$B$7*'Venturi del carburador'!$B$8/100)/(PI()/4*('Venturi del carburador'!$B$9/1000)^2))^2))/9.81 | C30: =IF(B30*9.81>'Venturi del carburador'!$B$23,'Venturi del carburador'!$B$11*('Venturi del carburador'!$B$5/1000000*A30/2/60*'Venturi del carburador'!$B$7*'Venturi del carburador'!$B$8/100)/('Venturi del carburador'!$B$13*PI()/4*('Venturi del carburador'!$B$12/1000)^2*SQRT(2*'Venturi del carburador'!$B$14*MAX(B30*9.81-'Venturi del carburador'!$B$23,0)))/14.7,NA()) | D30: 1

Sheet Datos oscilograma
A1: Parámetros por falla y puntos de la curva (no editar)
A2: Falla | B2: kV encendido | C2: kV chispa | D2: Duración chispa (ms) | E2: Pendiente (kV/ms) | F2: Oscilación (kV) | G2: Diagnóstico | J2: Índice de falla
A3: Normal | B3: 10 | C3: 1.5 | D3: 1.5 | E3: 0.1 | F3: 3 | G3: Oscilograma correcto: tensión de encendido de 8 a 12 kV, línea de chispa casi plana de 1 a 2 ms y 3 a 5 oscilaciones. | I3: SI | K3: =IF('Oscilograma secundario'!B9="SI",MOD('Oscilograma secundario'!B10*5+2,6)+1,MATCH('Oscilograma secundario'!B8,A3:A8,0))
A4: Luz de bujía excesiva | B4: 18 | C4: 2.2 | D4: 0.9 | E4: 0.3 | F4: 3 | G4: Tensión de encendido alta y chispa corta: luz de electrodos excesiva o electrodos desgastados. Calibrar o sustituir la bujía. | I4: NO | J4: kV | K4: =INDEX(B3:B8,K3)
A5: Cable de bujía cortado | B5: 28 | C5: 4 | D5: 0.3 | E5: 0 | F5: 2 | G5: Pico muy alto y casi sin línea de chispa: cable de alta abierto o desconectado. Riesgo de dañar la bobina. | J5: ks | K5: =INDEX(C3:C8,K3)
A6: Mezcla pobre | B6: 14 | C6: 2 | D6: 1 | E6: 1.2 | F6: 3 | G6: Tensión de encendido elevada y línea de chispa ascendente: mezcla pobre o entrada de aire en ese cilindro. | J6: ts | K6: =INDEX(D3:D8,K3)
A7: Bujía engrasada o en corto | B7: 5 | C7: 0.8 | D7: 2.3 | E7: 0 | F7: 1.5 | G7: Tensión de encendido baja y chispa larga: bujía engrasada, carbonizada o con el aislador fisurado. | J7: pend | K7: =INDEX(E3:E8,K3)
A8: Bobina débil o con fuga | B8: 7 | C8: 1.2 | D8: 0.8 | E8: 0 | F8: 1 | G8: Pocas oscilaciones y tensiones bajas en todos los cilindros: bobina débil o con fuga, o alimentación deficiente del primario. | J8: osc | K8: =INDEX(F3:F8,K3)
J9: T | K9: ='Oscilograma secundario'!B15
J10: t cierre | K10: =K9*(1-'Oscilograma secundario'!B7/100)
J11: E | K11: =MIN(4,K10)
A13: j | B13: t en el ciclo (ms) | C13: t (ms) | D13: Tensión (kV)
A14: - | B14: 0 | C14: 0 | D14: 0
A15: 0 | B15: =0 | C15: =B15+1 | D15: =IF(B15<=0.03,$K$4*B15/0.03,IF(B15<=0.07,$K$4-($K$4-$K$5)*(B15-0.03)/0.04,IF(B15<=0.07+$K$6,$K$5+$K$7*(B15-0.07),IF(B15<$K$10,$K$8*EXP(-(B15-0.07-$K$6)/0.35)*SIN(2*PI()*4*(B15-0.07-$K$6)),-2.5*EXP(-(B15-$K$10)/0.25)*SIN(2*PI()*6*(B15-$K$10))))))
A16: 1 | B16: =0.03 | C16: =B16+1 | D16: =IF(B16<=0.03,$K$4*B16/0.03,IF(B16<=0.07,$K$4-($K$4-$K$5)*(B16-0.03)/0.04,IF(B16<=0.07+$K$6,$K$5+$K$7*(B16-0.07),IF(B16<$K$10,$K$8*EXP(-(B16-0.07-$K$6)/0.35)*SIN(2*PI()*4*(B16-0.07-$K$6)),-2.5*EXP(-(B16-$K$10)/0.25)*SIN(2*PI()*6*(B16-$K$10))))))
A17: 2 | B17: =0.07 | C17: =B17+1 | D17: =IF(B17<=0.03,$K$4*B17/0.03,IF(B17<=0.07,$K$4-($K$4-$K$5)*(B17-0.03)/0.04,IF(B17<=0.07+$K$6,$K$5+$K$7*(B17-0.07),IF(B17<$K$10,$K$8*EXP(-(B17-0.07-$K$6)/0.35)*SIN(2*PI()*4*(B17-0.07-$K$6)),-2.5*EXP(-(B17-$K$10)/0.25)*SIN(2*PI()*6*(B17-$K$10))))))
A18: 3 | B18: =0.07+(3-2)*($K$11-0.07)/97 | C18: =B18+1 | D18: =IF(B18<=0.03,$K$4*B18/0.03,IF(B18<=0.07,$K$4-($K$4-$K$5)*(B18-0.03)/0.04,IF(B18<=0.07+$K$6,$K$5+$K$7*(B18-0.07),IF(B18<$K$10,$K$8*EXP(-(B18-0.07-$K$6)/0.35)*SIN(2*PI()*4*(B18-0.07-$K$6)),-2.5*EXP(-(B18-$K$10)/0.25)*SIN(2*PI()*6*(B18-$K$10))))))
A19: 4 | B19: =0.07+(4-2)*($K$11-0.07)/97 | C19: =B19+1 | D19: =IF(B19<=0.03,$K$4*B19/0.03,IF(B19<=0.07,$K$4-($K$4-$K$5)*(B19-0.03)/0.04,IF(B19<=0.07+$K$6,$K$5+$K$7*(B19-0.07),IF(B19<$K$10,$K$8*EXP(-(B19-0.07-$K$6)/0.35)*SIN(2*PI()*4*(B19-0.07-$K$6)),-2.5*EXP(-(B19-$K$10)/0.25)*SIN(2*PI()*6*(B19-$K$10))))))
A20: 5 | B20: =0.07+(5-2)*($K$11-0.07)/97 | C20: =B20+1 | D20: =IF(B20<=0.03,$K$4*B20/0.03,IF(B20<=0.07,$K$4-($K$4-$K$5)*(B20-0.03)/0.04,IF(B20<=0.07+$K$6,$K$5+$K$7*(B20-0.07),IF(B20<$K$10,$K$8*EXP(-(B20-0.07-$K$6)/0.35)*SIN(2*PI()*4*(B20-0.07-$K$6)),-2.5*EXP(-(B20-$K$10)/0.25)*SIN(2*PI()*6*(B20-$K$10))))))
A21: 6 | B21: =0.07+(6-2)*($K$11-0.07)/97 | C21: =B21+1 | D21: =IF(B21<=0.03,$K$4*B21/0.03,IF(B21<=0.07,$K$4-($K$4-$K$5)*(B21-0.03)/0.04,IF(B21<=0.07+$K$6,$K$5+$K$7*(B21-0.07),IF(B21<$K$10,$K$8*EXP(-(B21-0.07-$K$6)/0.35)*SIN(2*PI()*4*(B21-0.07-$K$6)),-2.5*EXP(-(B21-$K$10)/0.25)*SIN(2*PI()*6*(B21-$K$10))))))
A22: 7 | B22: =0.07+(7-2)*($K$11-0.07)/97 | C22: =B22+1 | D22: =IF(B22<=0.03,$K$4*B22/0.03,IF(B22<=0.07,$K$4-($K$4-$K$5)*(B22-0.03)/0.04,IF(B22<=0.07+$K$6,$K$5+$K$7*(B22-0.07),IF(B22<$K$10,$K$8*EXP(-(B22-0.07-$K$6)/0.35)*SIN(2*PI()*4*(B22-0.07-$K$6)),-2.5*EXP(-(B22-$K$10)/0.25)*SIN(2*PI()*6*(B22-$K$10))))))
A23: 8 | B23: =0.07+(8-2)*($K$11-0.07)/97 | C23: =B23+1 | D23: =IF(B23<=0.03,$K$4*B23/0.03,IF(B23<=0.07,$K$4-($K$4-$K$5)*(B23-0.03)/0.04,IF(B23<=0.07+$K$6,$K$5+$K$7*(B23-0.07),IF(B23<$K$10,$K$8*EXP(-(B23-0.07-$K$6)/0.35)*SIN(2*PI()*4*(B23-0.07-$K$6)),-2.5*EXP(-(B23-$K$10)/0.25)*SIN(2*PI()*6*(B23-$K$10))))))
A24: 9 | B24: =0.07+(9-2)*($K$11-0.07)/97 | C24: =B24+1 | D24: =IF(B24<=0.03,$K$4*B24/0.03,IF(B24<=0.07,$K$4-($K$4-$K$5)*(B24-0.03)/0.04,IF(B24<=0.07+$K$6,$K$5+$K$7*(B24-0.07),IF(B24<$K$10,$K$8*EXP(-(B24-0.07-$K$6)/0.35)*SIN(2*PI()*4*(B24-0.07-$K$6)),-2.5*EXP(-(B24-$K$10)/0.25)*SIN(2*PI()*6*(B24-$K$10))))))
A25: 10 | B25: =0.07+(10-2)*($K$11-0.07)/97 | C25: =B25+1 | D25: =IF(B25<=0.03,$K$4*B25/0.03,IF(B25<=0.07,$K$4-($K$4-$K$5)*(B25-0.03)/0.04,IF(B25<=0.07+$K$6,$K$5+$K$7*(B25-0.07),IF(B25<$K$10,$K$8*EXP(-(B25-0.07-$K$6)/0.35)*SIN(2*PI()*4*(B25-0.07-$K$6)),-2.5*EXP(-(B25-$K$10)/0.25)*SIN(2*PI()*6*(B25-$K$10))))))
A26: 11 | B26: =0.07+(11-2)*($K$11-0.07)/97 | C26: =B26+1 | D26: =IF(B26<=0.03,$K$4*B26/0.03,IF(B26<=0.07,$K$4-($K$4-$K$5)*(B26-0.03)/0.04,IF(B26<=0.07+$K$6,$K$5+$K$7*(B26-0.07),IF(B26<$K$10,$K$8*EXP(-(B26-0.07-$K$6)/0.35)*SIN(2*PI()*4*(B26-0.07-$K$6)),-2.5*EXP(-(B26-$K$10)/0.25)*SIN(2*PI()*6*(B26-$K$10))))))
A27: 12 | B27: =0.07+(12-2)*($K$11-0.07)/97 | C27: =B27+1 | D27: =IF(B27<=0.03,$K$4*B27/0.03,IF(B27<=0.07,$K$4-($K$4-$K$5)*(B27-0.03)/0.04,IF(B27<=0.07+$K$6,$K$5+$K$7*(B27-0.07),IF(B27<$K$10,$K$8*EXP(-(B27-0.07-$K$6)/0.35)*SIN(2*PI()*4*(B27-0.07-$K$6)),-2.5*EXP(-(B27-$K$10)/0.25)*SIN(2*PI()*6*(B27-$K$10))))))
A28: 13 | B28: =0.07+(13-2)*($K$11-0.07)/97 | C28: =B28+1 | D28: =IF(B28<=0.03,$K$4*B28/0.03,IF(B28<=0.07,$K$4-($K$4-$K$5)*(B28-0.03)/0.04,IF(B28<=0.07+$K$6,$K$5+$K$7*(B28-0.07),IF(B28<$K$10,$K$8*EXP(-(B28-0.07-$K$6)/0.35)*SIN(2*PI()*4*(B28-0.07-$K$6)),-2.5*EXP(-(B28-$K$10)/0.25)*SIN(2*PI()*6*(B28-$K$10))))))
A29: 14 | B29: =0.07+(14-2)*($K$11-0.07)/97 | C29: =B29+1 | D29: =IF(B29<=0.03,$K$4*B29/0.03,IF(B29<=0.07,$K$4-($K$4-$K$5)*(B29-0.03)/0.04,IF(B29<=0.07+$K$6,$K$5+$K$7*(B29-0.07),IF(B29<$K$10,$K$8*EXP(-(B29-0.07-$K$6)/0.35)*SIN(2*PI()*4*(B29-0.07-$K$6)),-2.5*EXP(-(B29-$K$10)/0.25)*SIN(2*PI()*6*(B29-$K$10))))))
A30: 15 | B30: =0.07+(15-2)*($K$11-0.07)/97 | C30: =B30+1 | D30: =IF(B30<=0.03,$K$4*B30/0.03,IF(B30<=0.07,$K$4-($K$4-$K$5)*(B30-0.03)/0.04,IF(B30<=0.07+$K$6,$K$5+$K$7*(B30-0.07),IF(B30<$K$10,$K$8*EXP(-(B30-0.07-$K$6)/0.35)*SIN(2*PI()*4*(B30-0.07-$K$6)),-2.5*EXP(-(B30-$K$10)/0.25)*SIN(2*PI()*6*(B30-$K$10))))))
A31: 16 | B31: =0.07+(16-2)*($K$11-0.07)/97 | C31: =B31+1 | D31: =IF(B31<=0.03,$K$4*B31/0.03,IF(B31<=0.07,$K$4-($K$4-$K$5)*(B31-0.03)/0.04,IF(B31<=0.07+$K$6,$K$5+$K$7*(B31-0.07),IF(B31<$K$10,$K$8*EXP(-(B31-0.07-$K$6)/0.35)*SIN(2*PI()*4*(B31-0.07-$K$6)),-2.5*EXP(-(B31-$K$10)/0.25)*SIN(2*PI()*6*(B31-$K$10))))))
A32: 17 | B32: =0.07+(17-2)*($K$11-0.07)/97 | C32: =B32+1 | D32: =IF(B32<=0.03,$K$4*B32/0.03,IF(B32<=0.07,$K$4-($K$4-$K$5)*(B32-0.03)/0.04,IF(B32<=0.07+$K$6,$K$5+$K$7*(B32-0.07),IF(B32<$K$10,$K$8*EXP(-(B32-0.07-$K$6)/0.35)*SIN(2*PI()*4*(B32-0.07-$K$6)),-2.5*EXP(-(B32-$K$10)/0.25)*SIN(2*PI()*6*(B32-$K$10))))))
A33: 18 | B33: =0.07+(18-2)*($K$11-0.07)/97 | C33: =B33+1 | D33: =IF(B33<=0.03,$K$4*B33/0.03,IF(B33<=0.07,$K$4-($K$4-$K$5)*(B33-0.03)/0.04,IF(B33<=0.07+$K$6,$K$5+$K$7*(B33-0.07),IF(B33<$K$10,$K$8*EXP(-(B33-0.07-$K$6)/0.35)*SIN(2*PI()*4*(B33-0.07-$K$6)),-2.5*EXP(-(B33-$K$10)/0.25)*SIN(2*PI()*6*(B33-$K$10))))))
A34: 19 | B34: =0.07+(19-2)*($K$11-0.07)/97 | C34: =B34+1 | D34: =IF(B34<=0.03,$K$4*B34/0.03,IF(B34<=0.07,$K$4-($K$4-$K$5)*(B34-0.03)/0.04,IF(B34<=0.07+$K$6,$K$5+$K$7*(B34-0.07),IF(B34<$K$10,$K$8*EXP(-(B34-0.07-$K$6)/0.35)*SIN(2*PI()*4*(B34-0.07-$K$6)),-2.5*EXP(-(B34-$K$10)/0.25)*SIN(2*PI()*6*(B34-$K$10))))))
A35: 20 | B35: =0.07+(20-2)*($K$11-0.07)/97 | C35: =B35+1 | D35: =IF(B35<=0.03,$K$4*B35/0.03,IF(B35<=0.07,$K$4-($K$4-$K$5)*(B35-0.03)/0.04,IF(B35<=0.07+$K$6,$K$5+$K$7*(B35-0.07),IF(B35<$K$10,$K$8*EXP(-(B35-0.07-$K$6)/0.35)*SIN(2*PI()*4*(B35-0.07-$K$6)),-2.5*EXP(-(B35-$K$10)/0.25)*SIN(2*PI()*6*(B35-$K$10))))))
A36: 21 | B36: =0.07+(21-2)*($K$11-0.07)/97 | C36: =B36+1 | D36: =IF(B36<=0.03,$K$4*B36/0.03,IF(B36<=0.07,$K$4-($K$4-$K$5)*(B36-0.03)/0.04,IF(B36<=0.07+$K$6,$K$5+$K$7*(B36-0.07),IF(B36<$K$10,$K$8*EXP(-(B36-0.07-$K$6)/0.35)*SIN(2*PI()*4*(B36-0.07-$K$6)),-2.5*EXP(-(B36-$K$10)/0.25)*SIN(2*PI()*6*(B36-$K$10))))))
A37: 22 | B37: =0.07+(22-2)*($K$11-0.07)/97 | C37: =B37+1 | D37: =IF(B37<=0.03,$K$4*B37/0.03,IF(B37<=0.07,$K$4-($K$4-$K$5)*(B37-0.03)/0.04,IF(B37<=0.07+$K$6,$K$5+$K$7*(B37-0.07),IF(B37<$K$10,$K$8*EXP(-(B37-0.07-$K$6)/0.35)*SIN(2*PI()*4*(B37-0.07-$K$6)),-2.5*EXP(-(B37-$K$10)/0.25)*SIN(2*PI()*6*(B37-$K$10))))))
A38: 23 | B38: =0.07+(23-2)*($K$11-0.07)/97 | C38: =B38+1 | D38: =IF(B38<=0.03,$K$4*B38/0.03,IF(B38<=0.07,$K$4-($K$4-$K$5)*(B38-0.03)/0.04,IF(B38<=0.07+$K$6,$K$5+$K$7*(B38-0.07),IF(B38<$K$10,$K$8*EXP(-(B38-0.07-$K$6)/0.35)*SIN(2*PI()*4*(B38-0.07-$K$6)),-2.5*EXP(-(B38-$K$10)/0.25)*SIN(2*PI()*6*(B38-$K$10))))))
A39: 24 | B39: =0.07+(24-2)*($K$11-0.07)/97 | C39: =B39+1 | D39: =IF(B39<=0.03,$K$4*B39/0.03,IF(B39<=0.07,$K$4-($K$4-$K$5)*(B39-0.03)/0.04,IF(B39<=0.07+$K$6,$K$5+$K$7*(B39-0.07),IF(B39<$K$10,$K$8*EXP(-(B39-0.07-$K$6)/0.35)*SIN(2*PI()*4*(B39-0.07-$K$6)),-2.5*EXP(-(B39-$K$10)/0.25)*SIN(2*PI()*6*(B39-$K$10))))))
A40: 25 | B40: =0.07+(25-2)*($K$11-0.07)/97 | C40: =B40+1 | D40: =IF(B40<=0.03,$K$4*B40/0.03,IF(B40<=0.07,$K$4-($K$4-$K$5)*(B40-0.03)/0.04,IF(B40<=0.07+$K$6,$K$5+$K$7*(B40-0.07),IF(B40<$K$10,$K$8*EXP(-(B40-0.07-$K$6)/0.35)*SIN(2*PI()*4*(B40-0.07-$K$6)),-2.5*EXP(-(B40-$K$10)/0.25)*SIN(2*PI()*6*(B40-$K$10))))))
A41: 26 | B41: =0.07+(26-2)*($K$11-0.07)/97 | C41: =B41+1 | D41: =IF(B41<=0.03,$K$4*B41/0.03,IF(B41<=0.07,$K$4-($K$4-$K$5)*(B41-0.03)/0.04,IF(B41<=0.07+$K$6,$K$5+$K$7*(B41-0.07),IF(B41<$K$10,$K$8*EXP(-(B41-0.07-$K$6)/0.35)*SIN(2*PI()*4*(B41-0.07-$K$6)),-2.5*EXP(-(B41-$K$10)/0.25)*SIN(2*PI()*6*(B41-$K$10))))))
...
