Workbook

Sheet Simulador
A1: Simulador del alzado de válvulas y del cruce — Sistema de distribución
A2: Sistemas del Funcionamiento del Motor (MA.02.06) · Unidad 3 · Edite solo las celdas amarillas (texto azul); todo lo demás se recalcula.
A4: Datos de entrada | B4: Valor | D4: Perfil | E4: Apertura (°) | F4: Cierre (°) | G4: Duración (°)
A5: Adelanto de apertura de escape AAE (° cigüeñal) | B5: 45 | D5: Escape adelantado | E5: =180-$B$5-$B$12 -> 120 | F5: =360+$B$6-$B$12 -> 365 | G5: =F5-E5 -> 245
A6: Retraso de cierre de escape RCE (°) | B6: 20 | D6: Escape base | E6: =180-$B$5 -> 135 | F6: =360+$B$6 -> 380 | G6: =F6-E6 -> 245
A7: Adelanto de apertura de admisión AAA (°) | B7: 20 | D7: Escape retrasado | E7: =180-$B$5+$B$12 -> 150 | F7: =360+$B$6+$B$12 -> 395 | G7: =F7-E7 -> 245
A8: Retraso de cierre de admisión RCA (°) | B8: 50 | D8: Admisión adelantada | E8: =360-$B$7-$B$13 -> 325 | F8: =540+$B$8-$B$13 -> 575 | G8: =F8-E8 -> 250
A9: Alzada máxima de escape (mm) | B9: 9.5 | D9: Admisión base | E9: =360-$B$7 -> 340 | F9: =540+$B$8 -> 590 | G9: =F9-E9 -> 250
A10: Alzada máxima de admisión (mm) | B10: 8.5 | D10: Admisión retrasada | E10: =360-$B$7+$B$13 -> 355 | F10: =540+$B$8+$B$13 -> 605 | G10: =F10-E10 -> 250
A11: Fracción de rampa del perfil (0,10 – 0,50) | B11: 0.42
A12: Variación de fase del escape (± °) | B12: 15 | D12: Resultado | E12: Grados | F12: Cómo se obtiene
A13: Variación de fase de la admisión (± °) | B13: 15 | D13: Cruce base (°) | E13: =MAX(0,F6-E9) -> 40 | F13: RCE + AAA
A14: Paso de cálculo (°) | B14: 2 | D14: Cruce máximo (°) | E14: =MAX(0,F7-E8) -> 70 | F14: Escape retrasado + admisión adelantada
D15: Cruce mínimo (°) | E15: =MAX(0,F5-E10) -> 10 | F15: Escape adelantado + admisión retrasada
A16: Comprobación | D16: Duración de escape (°) | E16: =G6 -> 245 | F16: AAE + 180 + RCE
A17: =IF(AND($B$11>=0.1,$B$11<=0.5),"Fracción de rampa válida","Revise: la fracción de rampa debe estar entre 0,10 y 0,50") -> Fracción de rampa válida | D17: Duración de admisión (°) | E17: =G9 -> 250 | F17: AAA + 180 + RCA
A18: =IF(E15>0,"Hay cruce en todas las fases","Con la admisión retrasada y el escape adelantado desaparece el cruce") -> Hay cruce en todas las fases | D18: Duración de admisión en el árbol de levas (°) | E18: =G9/2 -> 125 | F18: El árbol gira a la mitad que el cigüeñal
A20: Referencias angulares: PMS de inicio de admisión/cruce = 360°; PMI = 180° y 540°; PMS de combustión = 0° y 720°.
A21: Perfil de alzada: flancos en coseno (subida y bajada suaves) con meseta central, modelo didáctico del perfil real de la leva.

Sheet Diagrama circular
A1: Diagrama circular de la distribución y cruce de válvulas
A2: Usa los ángulos base de la hoja Simulador (sin variador). Edite solo la celda amarilla de esta hoja.
A4: Dato | B4: Valor | D4: Fase del ciclo real | E4: Duración (°) | F4: Desde → hasta
A5: AAE (de la hoja Simulador) | B5: =Simulador!B5 -> 45 | D5: Admisión | E5: =B7+180+B8 -> 250 | F5: ="AAA "&B7&"° antes PMS → RCA "&B8&"° después PMI" -> AAA 20° antes PMS → RCA 50° después PMI
A6: RCE | B6: =Simulador!B6 -> 20 | D6: Compresión | E6: =180-B8-B9 -> 120 | F6: ="RCA → chispa "&B9&"° antes PMS" -> RCA → chispa 10° antes PMS
A7: AAA | B7: =Simulador!B7 -> 20 | D7: Combustión (explosión) | E7: =B9 -> 10 | F7: ="Chispa → PMS" -> Chispa → PMS
A8: RCA | B8: =Simulador!B8 -> 50 | D8: Trabajo útil (expansión) | E8: =180-B5 -> 135 | F8: ="PMS → AAE "&B5&"° antes PMI" -> PMS → AAE 45° antes PMI
A9: Avance de encendido AE (° antes del PMS) | B9: 10 | D9: Escape | E9: =B5+180+B6 -> 245 | F9: ="AAE → RCE "&B6&"° después PMS" -> AAE → RCE 20° después PMS
D10: Cruce de válvulas | E10: =B7+B6 -> 40 | F10: ="AAA + RCE alrededor del PMS" -> AAA + RCE alrededor del PMS
D11: Total del ciclo: suma de fases − cruce (= 720°) | E11: =SUM(E5:E9)-E10 -> 720 | F11: ="El cruce se cuenta en admisión y en escape" -> El cruce se cuenta en admisión y en escape
D13: =IF(E11=720,"El ciclo suma 720°: diagrama coherente","Revise los ángulos: el ciclo no suma 720°") -> El ciclo suma 720°: diagrama coherente
F37: En el ciclo teórico las válvulas abren y cierran justo en PMS y PMI; en el real se adelantan las aperturas y se retrasan los cierres, y aparece el cruce alrededor del PMS.

Sheet Datos
A1: Ángulo cigüeñal (°) | B1: Escape adelantado | C1: Escape base | D1: Escape retrasado | E1: Admisión adelantada | F1: Admisión base | G1: Admisión retrasada | I1: Cruce máximo x | J1: Cruce máximo y | K1: Cruce mínimo x | L1: Cruce mínimo y | M1: PMS x | N1: PMS y
A2: 0 | B2: =IF(OR((($A2-Simulador!$E$5)/Simulador!$G$5)<=0,(($A2-Simulador!$E$5)/Simulador!$G$5)>=1),0,IF((($A2-Simulador!$E$5)/Simulador!$G$5)<Simulador!$B$11,Simulador!$B$9*(1-COS(PI()*(($A2-Simulador!$E$5)/Simulador!$G$5)/Simulador!$B$11))/2,IF((($A2-Simulador!$E$5)/Simulador!$G$5)>1-Simulador!$B$11,Simulador!$B$9*(1-COS(PI()*(1-(($A2-Simulador!$E$5)/Simulador!$G$5))/Simulador!$B$11))/2,Simulador!$B$9))) -> 0 | C2: =IF(OR((($A2-Simulador!$E$6)/Simulador!$G$6)<=0,(($A2-Simulador!$E$6)/Simulador!$G$6)>=1),0,IF((($A2-Simulador!$E$6)/Simulador!$G$6)<Simulador!$B$11,Simulador!$B$9*(1-COS(PI()*(($A2-Simulador!$E$6)/Simulador!$G$6)/Simulador!$B$11))/2,IF((($A2-Simulador!$E$6)/Simulador!$G$6)>1-Simulador!$B$11,Simulador!$B$9*(1-COS(PI()*(1-(($A2-Simulador!$E$6)/Simulador!$G$6))/Simulador!$B$11))/2,Simulador!$B$9))) -> 0 | D2: =IF(OR((($A2-Simulador!$E$7)/Simulador!$G$7)<=0,(($A2-Simulador!$E$7)/Simulador!$G$7)>=1),0,IF((($A2-Simulador!$E$7)/Simulador!$G$7)<Simulador!$B$11,Simulador!$B$9*(1-COS(PI()*(($A2-Simulador!$E$7)/Simulador!$G$7)/Simulador!$B$11))/2,IF((($A2-Simulador!$E$7)/Simulador!$G$7)>1-Simulador!$B$11,Simulador!$B$9*(1-COS(PI()*(1-(($A2-Simulador!$E$7)/Simulador!$G$7))/Simulador!$B$11))/2,Simulador!$B$9))) -> 0 | E2: =IF(OR((($A2-Simulador!$E$8)/Simulador!$G$8)<=0,(($A2-Simulador!$E$8)/Simulador!$G$8)>=1),0,IF((($A2-Simulador!$E$8)/Simulador!$G$8)<Simulador!$B$11,Simulador!$B$10*(1-COS(PI()*(($A2-Simulador!$E$8)/Simulador!$G$8)/Simulador!$B$11))/2,IF((($A2-Simulador!$E$8)/Simulador!$G$8)>1-Simulador!$B$11,Simulador!$B$10*(1-COS(PI()*(1-(($A2-Simulador!$E$8)/Simulador!$G$8))/Simulador!$B$11))/2,Simulador!$B$10))) -> 0 | F2: =IF(OR((($A2-Simulador!$E$9)/Simulador!$G$9)<=0,(($A2-Simulador!$E$9)/Simulador!$G$9)>=1),0,IF((($A2-Simulador!$E$9)/Simulador!$G$9)<Simulador!$B$11,Simulador!$B$10*(1-COS(PI()*(($A2-Simulador!$E$9)/Simulador!$G$9)/Simulador!$B$11))/2,IF((($A2-Simulador!$E$9)/Simulador!$G$9)>1-Simulador!$B$11,Simulador!$B$10*(1-COS(PI()*(1-(($A2-Simulador!$E$9)/Simulador!$G$9))/Simulador!$B$11))/2,Simulador!$B$10))) -> 0 | G2: =IF(OR((($A2-Simulador!$E$10)/Simulador!$G$10)<=0,(($A2-Simulador!$E$10)/Simulador!$G$10)>=1),0,IF((($A2-Simulador!$E$10)/Simulador!$G$10)<Simulador!$B$11,Simulador!$B$10*(1-COS(PI()*(($A2-Simulador!$E$10)/Simulador!$G$10)/Simulador!$B$11))/2,IF((($A2-Simulador!$E$10)/Simulador!$G$10)>1-Simulador!$B$11,Simulador!$B$10*(1-COS(PI()*(1-(($A2-Simulador!$E$10)/Simulador!$G$10))/Simulador!$B$11))/2,Simulador!$B$10))) -> 0 | I2: =Simulador!$E$8 -> 325 | J2: 0 | K2: =Simulador!$E$10 -> 355 | L2: 0 | M2: 360 | N2: 0
A3: =A2+Simulador!$B$14 -> 2 | B3: =IF(OR((($A3-Simulador!$E$5)/Simulador!$G$5)<=0,(($A3-Simulador!$E$5)/Simulador!$G$5)>=1),0,IF((($A3-Simulador!$E$5)/Simulador!$G$5)<Simulador!$B$11,Simulador!$B$9*(1-COS(PI()*(($A3-Simulador!$E$5)/Simulador!$G$5)/Simulador!$B$11))/2,IF((($A3-Simulador!$E$5)/Simulador!$G$5)>1-Simulador!$B$11,Simulador!$B$9*(1-COS(PI()*(1-(($A3-Simulador!$E$5)/Simulador!$G$5))/Simulador!$B$11))/2,Simulador!$B$9))) -> 0 | C3: =IF(OR((($A3-Simulador!$E$6)/Simulador!$G$6)<=0,(($A3-Simulador!$E$6)/Simulador!$G$6)>=1),0,IF((($A3-Simulador!$E$6)/Simulador!$G$6)<Simulador!$B$11,Simulador!$B$9*(1-COS(PI()*(($A3-Simulador!$E$6)/Simulador!$G$6)/Simulador!$B$11))/2,IF((($A3-Simulador!$E$6)/Simulador!$G$6)>1-Simulador!$B$11,Simulador!$B$9*(1-COS(PI()*(1-(($A3-Simulador!$E$6)/Simulador!$G$6))/Simulador!$B$11))/2,Simulador!$B$9))) -> 0 | D3: =IF(OR((($A3-Simulador!$E$7)/Simulador!$G$7)<=0,(($A3-Simulador!$E$7)/Simulador!$G$7)>=1),0,IF((($A3-Simulador!$E$7)/Simulador!$G$7)<Simulador!$B$11,Simulador!$B$9*(1-COS(PI()*(($A3-Simulador!$E$7)/Simulador!$G$7)/Simulador!$B$11))/2,IF((($A3-Simulador!$E$7)/Simulador!$G$7)>1-Simulador!$B$11,Simulador!$B$9*(1-COS(PI()*(1-(($A3-Simulador!$E$7)/Simulador!$G$7))/Simulador!$B$11))/2,Simulador!$B$9))) -> 0 | E3: =IF(OR((($A3-Simulador!$E$8)/Simulador!$G$8)<=0,(($A3-Simulador!$E$8)/Simulador!$G$8)>=1),0,IF((($A3-Simulador!$E$8)/Simulador!$G$8)<Simulador!$B$11,Simulador!$B$10*(1-COS(PI()*(($A3-Simulador!$E$8)/Simulador!$G$8)/Simulador!$B$11))/2,IF((($A3-Simulador!$E$8)/Simulador!$G$8)>1-Simulador!$B$11,Simulador!$B$10*(1-COS(PI()*(1-(($A3-Simulador!$E$8)/Simulador!$G$8))/Simulador!$B$11))/2,Simulador!$B$10))) -> 0 | F3: =IF(OR((($A3-Simulador!$E$9)/Simulador!$G$9)<=0,(($A3-Simulador!$E$9)/Simulador!$G$9)>=1),0,IF((($A3-Simulador!$E$9)/Simulador!$G$9)<Simulador!$B$11,Simulador!$B$10*(1-COS(PI()*(($A3-Simulador!$E$9)/Simulador!$G$9)/Simulador!$B$11))/2,IF((($A3-Simulador!$E$9)/Simulador!$G$9)>1-Simulador!$B$11,Simulador!$B$10*(1-COS(PI()*(1-(($A3-Simulador!$E$9)/Simulador!$G$9))/Simulador!$B$11))/2,Simulador!$B$10))) -> 0 | G3: =IF(OR((($A3-Simulador!$E$10)/Simulador!$G$10)<=0,(($A3-Simulador!$E$10)/Simulador!$G$10)>=1),0,IF((($A3-Simulador!$E$10)/Simulador!$G$10)<Simulador!$B$11,Simulador!$B$10*(1-COS(PI()*(($A3-Simulador!$E$10)/Simulador!$G$10)/Simulador!$B$11))/2,IF((($A3-Simulador!$E$10)/Simulador!$G$10)>1-Simulador!$B$11,Simulador!$B$10*(1-COS(PI()*(1-(($A3-Simulador!$E$10)/Simulador!$G$10))/Simulador!$B$11))/2,Simulador!$B$10))) -> 0 | I3: =Simulador!$E$8 -> 325 | J3: 0.05 | K3: =Simulador!$E$10 -> 355 | L3: 0.05 | M3: 360 | N3: =MAX(Simulador!$B$9,Simulador!$B$10)*1.05 -> 9.975
A4: =A3+Simulador!$B$14 -> 4 | B4: =IF(OR((($A4-Simulador!$E$5)/Simulador!$G$5)<=0,(($A4-Simulador!$E$5)/Simulador!$G$5)>=1),0,IF((($A4-Simulador!$E$5)/Simulador!$G$5)<Simulador!$B$11,Simulador!$B$9*(1-COS(PI()*(($A4-Simulador!$E$5)/Simulador!$G$5)/Simulador!$B$11))/2,IF((($A4-Simulador!$E$5)/Simulador!$G$5)>1-Simulador!$B$11,Simulador!$B$9*(1-COS(PI()*(1-(($A4-Simulador!$E$5)/Simulador!$G$5))/Simulador!$B$11))/2,Simulador!$B$9))) -> 0 | C4: =IF(OR((($A4-Simulador!$E$6)/Simulador!$G$6)<=0,(($A4-Simulador!$E$6)/Simulador!$G$6)>=1),0,IF((($A4-Simulador!$E$6)/Simulador!$G$6)<Simulador!$B$11,Simulador!$B$9*(1-COS(PI()*(($A4-Simulador!$E$6)/Simulador!$G$6)/Simulador!$B$11))/2,IF((($A4-Simulador!$E$6)/Simulador!$G$6)>1-Simulador!$B$11,Simulador!$B$9*(1-COS(PI()*(1-(($A4-Simulador!$E$6)/Simulador!$G$6))/Simulador!$B$11))/2,Simulador!$B$9))) -> 0 | D4: =IF(OR((($A4-Simulador!$E$7)/Simulador!$G$7)<=0,(($A4-Simulador!$E$7)/Simulador!$G$7)>=1),0,IF((($A4-Simulador!$E$7)/Simulador!$G$7)<Simulador!$B$11,Simulador!$B$9*(1-COS(PI()*(($A4-Simulador!$E$7)/Simulador!$G$7)/Simulador!$B$11))/2,IF((($A4-Simulador!$E$7)/Simulador!$G$7)>1-Simulador!$B$11,Simulador!$B$9*(1-COS(PI()*(1-(($A4-Simulador!$E$7)/Simulador!$G$7))/Simulador!$B$11))/2,Simulador!$B$9))) -> 0 | E4: =IF(OR((($A4-Simulador!$E$8)/Simulador!$G$8)<=0,(($A4-Simulador!$E$8)/Simulador!$G$8)>=1),0,IF((($A4-Simulador!$E$8)/Simulador!$G$8)<Simulador!$B$11,Simulador!$B$10*(1-COS(PI()*(($A4-Simulador!$E$8)/Simulador!$G$8)/Simulador!$B$11))/2,IF((($A4-Simulador!$E$8)/Simulador!$G$8)>1-Simulador!$B$11,Simulador!$B$10*(1-COS(PI()*(1-(($A4-Simulador!$E$8)/Simulador!$G$8))/Simulador!$B$11))/2,Simulador!$B$10))) -> 0 | F4: =IF(OR((($A4-Simulador!$E$9)/Simulador!$G$9)<=0,(($A4-Simulador!$E$9)/Simulador!$G$9)>=1),0,IF((($A4-Simulador!$E$9)/Simulador!$G$9)<Simulador!$B$11,Simulador!$B$10*(1-COS(PI()*(($A4-Simulador!$E$9)/Simulador!$G$9)/Simulador!$B$11))/2,IF((($A4-Simulador!$E$9)/Simulador!$G$9)>1-Simulador!$B$11,Simulador!$B$10*(1-COS(PI()*(1-(($A4-Simulador!$E$9)/Simulador!$G$9))/Simulador!$B$11))/2,Simulador!$B$10))) -> 0 | G4: =IF(OR((($A4-Simulador!$E$10)/Simulador!$G$10)<=0,(($A4-Simulador!$E$10)/Simulador!$G$10)>=1),0,IF((($A4-Simulador!$E$10)/Simulador!$G$10)<Simulador!$B$11,Simulador!$B$10*(1-COS(PI()*(($A4-Simulador!$E$10)/Simulador!$G$10)/Simulador!$B$11))/2,IF((($A4-Simulador!$E$10)/Simulador!$G$10)>1-Simulador!$B$11,Simulador!$B$10*(1-COS(PI()*(1-(($A4-Simulador!$E$10)/Simulador!$G$10))/Simulador!$B$11))/2,Simulador!$B$10))) -> 0 | I4: =Simulador!$E$8 -> 325 | J4: =MAX(Simulador!$B$9,Simulador!$B$10)*1.32-0.05 -> 12.49 | K4: =Simulador!$E$10 -> 355 | L4: =MAX(Simulador!$B$9,Simulador!$B$10)*1.16-0.05 -> 10.97
A5: =A4+Simulador!$B$14 -> 6 | B5: =IF(OR((($A5-Simulador!$E$5)/Simulador!$G$5)<=0,(($A5-Simulador!$E$5)/Simulador!$G$5)>=1),0,IF((($A5-Simulador!$E$5)/Simulador!$G$5)<Simulador!$B$11,Simulador!$B$9*(1-COS(PI()*(($A5-Simulador!$E$5)/Simulador!$G$5)/Simulador!$B$11))/2,IF((($A5-Simulador!$E$5)/Simulador!$G$5)>1-Simulador!$B$11,Simulador!$B$9*(1-COS(PI()*(1-(($A5-Simulador!$E$5)/Simulador!$G$5))/Simulador!$B$11))/2,Simulador!$B$9))) -> 0 | C5: =IF(OR((($A5-Simulador!$E$6)/Simulador!$G$6)<=0,(($A5-Simulador!$E$6)/Simulador!$G$6)>=1),0,IF((($A5-Simulador!$E$6)/Simulador!$G$6)<Simulador!$B$11,Simulador!$B$9*(1-COS(PI()*(($A5-Simulador!$E$6)/Simulador!$G$6)/Simulador!$B$11))/2,IF((($A5-Simulador!$E$6)/Simulador!$G$6)>1-Simulador!$B$11,Simulador!$B$9*(1-COS(PI()*(1-(($A5-Simulador!$E$6)/Simulador!$G$6))/Simulador!$B$11))/2,Simulador!$B$9))) -> 0 | D5: =IF(OR((($A5-Simulador!$E$7)/Simulador!$G$7)<=0,(($A5-Simulador!$E$7)/Simulador!$G$7)>=1),0,IF((($A5-Simulador!$E$7)/Simulador!$G$7)<Simulador!$B$11,Simulador!$B$9*(1-COS(PI()*(($A5-Simulador!$E$7)/Simulador!$G$7)/Simulador!$B$11))/2,IF((($A5-Simulador!$E$7)/Simulador!$G$7)>1-Simulador!$B$11,Simulador!$B$9*(1-COS(PI()*(1-(($A5-Simulador!$E$7)/Simulador!$G$7))/Simulador!$B$11))/2,Simulador!$B$9))) -> 0 | E5: =IF(OR((($A5-Simulador!$E$8)/Simulador!$G$8)<=0,(($A5-Simulador!$E$8)/Simulador!$G$8)>=1),0,IF((($A5-Simulador!$E$8)/Simulador!$G$8)<Simulador!$B$11,Simulador!$B$10*(1-COS(PI()*(($A5-Simulador!$E$8)/Simulador!$G$8)/Simulador!$B$11))/2,IF((($A5-Simulador!$E$8)/Simulador!$G$8)>1-Simulador!$B$11,Simulador!$B$10*(1-COS(PI()*(1-(($A5-Simulador!$E$8)/Simulador!$G$8))/Simulador!$B$11))/2,Simulador!$B$10))) -> 0 | F5: =IF(OR((($A5-Simulador!$E$9)/Simulador!$G$9)<=0,(($A5-Simulador!$E$9)/Simulador!$G$9)>=1),0,IF((($A5-Simulador!$E$9)/Simulador!$G$9)<Simulador!$B$11,Simulador!$B$10*(1-COS(PI()*(($A5-Simulador!$E$9)/Simulador!$G$9)/Simulador!$B$11))/2,IF((($A5-Simulador!$E$9)/Simulador!$G$9)>1-Simulador!$B$11,Simulador!$B$10*(1-COS(PI()*(1-(($A5-Simulador!$E$9)/Simulador!$G$9))/Simulador!$B$11))/2,Simulador!$B$10))) -> 0 | G5: =IF(OR((($A5-Simulador!$E$10)/Simulador!$G$10)<=0,(($A5-Simulador!$E$10)/Simulador!$G$10)>=1),0,IF((($A5-Simulador!$E$10)/Simulador!$G$10)<Simulador!$B$11,Simulador!$B$10*(1-COS(PI()*(($A5-Simulador!$E$10)/Simulador!$G$10)/Simulador!$B$11))/2,IF((($A5-Simulador!$E$10)/Simulador!$G$10)>1-Simulador!$B$11,Simulador!$B$10*(1-COS(PI()*(1-(($A5-Simulador!$E$10)/Simulador!$G$10))/Simulador!$B$11))/2,Simulador!$B$10))) -> 0 | I5: =Simulador!$E$8 -> 325 | J5: =MAX(Simulador!$B$9,Simulador!$B$10)*1.32 -> 12.54 | K5: =Simulador!$E$10 -> 355 | L5: =MAX(Simulador!$B$9,Simulador!$B$10)*1.16 -> 11.02
A6: =A5+Simulador!$B$14 -> 8 | B6: =IF(OR((($A6-Simulador!$E$5)/Simulador!$G$5)<=0,(($A6-Simulador!$E$5)/Simulador!$G$5)>=1),0,IF((($A6-Simulador!$E$5)/Simulador!$G$5)<Simulador!$B$11,Simulador!$B$9*(1-COS(PI()*(($A6-Simulador!$E$5)/Simulador!$G$5)/Simulador!$B$11))/2,IF((($A6-Simulador!$E$5)/Simulador!$G$5)>1-Simulador!$B$11,Simulador!$B$9*(1-COS(PI()*(1-(($A6-Simulador!$E$5)/Simulador!$G$5))/Simulador!$B$11))/2,Simulador!$B$9))) -> 0 | C6: =IF(OR((($A6-Simulador!$E$6)/Simulador!$G$6)<=0,(($A6-Simulador!$E$6)/Simulador!$G$6)>=1),0,IF((($A6-Simulador!$E$6)/Simulador!$G$6)<Simulador!$B$11,Simulador!$B$9*(1-COS(PI()*(($A6-Simulador!$E$6)/Simulador!$G$6)/Simulador!$B$11))/2,IF((($A6-Simulador!$E$6)/Simulador!$G$6)>1-Simulador!$B$11,Simulador!$B$9*(1-COS(PI()*(1-(($A6-Simulador!$E$6)/Simulador!$G$6))/Simulador!$B$11))/2,Simulador!$B$9))) -> 0 | D6: =IF(OR((($A6-Simulador!$E$7)/Simulador!$G$7)<=0,(($A6-Simulador!$E$7)/Simulador!$G$7)>=1),0,IF((($A6-Simulador!$E$7)/Simulador!$G$7)<Simulador!$B$11,Simulador!$B$9*(1-COS(PI()*(($A6-Simulador!$E$7)/Simulador!$G$7)/Simulador!$B$11))/2,IF((($A6-Simulador!$E$7)/Simulador!$G$7)>1-Simulador!$B$11,Simulador!$B$9*(1-COS(PI()*(1-(($A6-Simulador!$E$7)/Simulador!$G$7))/Simulador!$B$11))/2,Simulador!$B$9))) -> 0 | E6: =IF(OR((($A6-Simulador!$E$8)/Simulador!$G$8)<=0,(($A6-Simulador!$E$8)/Simulador!$G$8)>=1),0,IF((($A6-Simulador!$E$8)/Simulador!$G$8)<Simulador!$B$11,Simulador!$B$10*(1-COS(PI()*(($A6-Simulador!$E$8)/Simulador!$G$8)/Simulador!$B$11))/2,IF((($A6-Simulador!$E$8)/Simulador!$G$8)>1-Simulador!$B$11,Simulador!$B$10*(1-COS(PI()*(1-(($A6-Simulador!$E$8)/Simulador!$G$8))/Simulador!$B$11))/2,Simulador!$B$10))) -> 0 | F6: =IF(OR((($A6-Simulador!$E$9)/Simulador!$G$9)<=0,(($A6-Simulador!$E$9)/Simulador!$G$9)>=1),0,IF((($A6-Simulador!$E$9)/Simulador!$G$9)<Simulador!$B$11,Simulador!$B$10*(1-COS(PI()*(($A6-Simulador!$E$9)/Simulador!$G$9)/Simulador!$B$11))/2,IF((($A6-Simulador!$E$9)/Simulador!$G$9)>1-Simulador!$B$11,Simulador!$B$10*(1-COS(PI()*(1-(($A6-Simulador!$E$9)/Simulador!$G$9))/Simulador!$B$11))/2,Simulador!$B$10))) -> 0 | G6: =IF(OR((($A6-Simulador!$E$10)/Simulador!$G$10)<=0,(($A6-Simulador!$E$10)/Simulador!$G$10)>=1),0,IF((($A6-Simulador!$E$10)/Simulador!$G$10)<Simulador!$B$11,Simulador!$B$10*(1-COS(PI()*(($A6-Simulador!$E$10)/Simulador!$G$10)/Simulador!$B$11))/2,IF((($A6-Simulador!$E$10)/Simulador!$G$10)>1-Simulador!$B$11,Simulador!$B$10*(1-COS(PI()*(1-(($A6-Simulador!$E$10)/Simulador!$G$10))/Simulador!$B$11))/2,Simulador!$B$10))) -> 0 | I6: =Simulador!$E$8+0.5 -> 325.5 | J6: =MAX(Simulador!$B$9,Simulador!$B$10)*1.32 -> 12.54 | K6: =Simulador!$E$10+0.5 -> 355.5 | L6: =MAX(Simulador!$B$9,Simulador!$B$10)*1.16 -> 11.02
A7: =A6+Simulador!$B$14 -> 10 | B7: =IF(OR((($A7-Simulador!$E$5)/Simulador!$G$5)<=0,(($A7-Simulador!$E$5)/Simulador!$G$5)>=1),0,IF((($A7-Simulador!$E$5)/Simulador!$G$5)<Simulador!$B$11,Simulador!$B$9*(1-COS(PI()*(($A7-Simulador!$E$5)/Simulador!$G$5)/Simulador!$B$11))/2,IF((($A7-Simulador!$E$5)/Simulador!$G$5)>1-Simulador!$B$11,Simulador!$B$9*(1-COS(PI()*(1-(($A7-Simulador!$E$5)/Simulador!$G$5))/Simulador!$B$11))/2,Simulador!$B$9))) -> 0 | C7: =IF(OR((($A7-Simulador!$E$6)/Simulador!$G$6)<=0,(($A7-Simulador!$E$6)/Simulador!$G$6)>=1),0,IF((($A7-Simulador!$E$6)/Simulador!$G$6)<Simulador!$B$11,Simulador!$B$9*(1-COS(PI()*(($A7-Simulador!$E$6)/Simulador!$G$6)/Simulador!$B$11))/2,IF((($A7-Simulador!$E$6)/Simulador!$G$6)>1-Simulador!$B$11,Simulador!$B$9*(1-COS(PI()*(1-(($A7-Simulador!$E$6)/Simulador!$G$6))/Simulador!$B$11))/2,Simulador!$B$9))) -> 0 | D7: =IF(OR((($A7-Simulador!$E$7)/Simulador!$G$7)<=0,(($A7-Simulador!$E$7)/Simulador!$G$7)>=1),0,IF((($A7-Simulador!$E$7)/Simulador!$G$7)<Simulador!$B$11,Simulador!$B$9*(1-COS(PI()*(($A7-Simulador!$E$7)/Simulador!$G$7)/Simulador!$B$11))/2,IF((($A7-Simulador!$E$7)/Simulador!$G$7)>1-Simulador!$B$11,Simulador!$B$9*(1-COS(PI()*(1-(($A7-Simulador!$E$7)/Simulador!$G$7))/Simulador!$B$11))/2,Simulador!$B$9))) -> 0 | E7: =IF(OR((($A7-Simulador!$E$8)/Simulador!$G$8)<=0,(($A7-Simulador!$E$8)/Simulador!$G$8)>=1),0,IF((($A7-Simulador!$E$8)/Simulador!$G$8)<Simulador!$B$11,Simulador!$B$10*(1-COS(PI()*(($A7-Simulador!$E$8)/Simulador!$G$8)/Simulador!$B$11))/2,IF((($A7-Simulador!$E$8)/Simulador!$G$8)>1-Simulador!$B$11,Simulador!$B$10*(1-COS(PI()*(1-(($A7-Simulador!$E$8)/Simulador!$G$8))/Simulador!$B$11))/2,Simulador!$B$10))) -> 0 | F7: =IF(OR((($A7-Simulador!$E$9)/Simulador!$G$9)<=0,(($A7-Simulador!$E$9)/Simulador!$G$9)>=1),0,IF((($A7-Simulador!$E$9)/Simulador!$G$9)<Simulador!$B$11,Simulador!$B$10*(1-COS(PI()*(($A7-Simulador!$E$9)/Simulador!$G$9)/Simulador!$B$11))/2,IF((($A7-Simulador!$E$9)/Simulador!$G$9)>1-Simulador!$B$11,Simulador!$B$10*(1-COS(PI()*(1-(($A7-Simulador!$E$9)/Simulador!$G$9))/Simulador!$B$11))/2,Simulador!$B$10))) -> 0 | G7: =IF(OR((($A7-Simulador!$E$10)/Simulador!$G$10)<=0,(($A7-Simulador!$E$10)/Simulador!$G$10)>=1),0,IF((($A7-Simulador!$E$10)/Simulador!$G$10)<Simulador!$B$11,Simulador!$B$10*(1-COS(PI()*(($A7-Simulador!$E$10)/Simulador!$G$10)/Simulador!$B$11))/2,IF((($A7-Simulador!$E$10)/Simulador!$G$10)>1-Simulador!$B$11,Simulador!$B$10*(1-COS(PI()*(1-(($A7-Simulador!$E$10)/Simulador!$G$10))/Simulador!$B$11))/2,Simulador!$B$10))) -> 0 | I7: =Simulador!$F$7-0.5 -> 394.5 | J7: =MAX(Simulador!$B$9,Simulador!$B$10)*1.32 -> 12.54 | K7: =Simulador!$F$5-0.5 -> 364.5 | L7: =MAX(Simulador!$B$9,Simulador!$B$10)*1.16 -> 11.02
A8: =A7+Simulador!$B$14 -> 12 | B8: =IF(OR((($A8-Simulador!$E$5)/Simulador!$G$5)<=0,(($A8-Simulador!$E$5)/Simulador!$G$5)>=1),0,IF((($A8-Simulador!$E$5)/Simulador!$G$5)<Simulador!$B$11,Simulador!$B$9*(1-COS(PI()*(($A8-Simulador!$E$5)/Simulador!$G$5)/Simulador!$B$11))/2,IF((($A8-Simulador!$E$5)/Simulador!$G$5)>1-Simulador!$B$11,Simulador!$B$9*(1-COS(PI()*(1-(($A8-Simulador!$E$5)/Simulador!$G$5))/Simulador!$B$11))/2,Simulador!$B$9))) -> 0 | C8: =IF(OR((($A8-Simulador!$E$6)/Simulador!$G$6)<=0,(($A8-Simulador!$E$6)/Simulador!$G$6)>=1),0,IF((($A8-Simulador!$E$6)/Simulador!$G$6)<Simulador!$B$11,Simulador!$B$9*(1-COS(PI()*(($A8-Simulador!$E$6)/Simulador!$G$6)/Simulador!$B$11))/2,IF((($A8-Simulador!$E$6)/Simulador!$G$6)>1-Simulador!$B$11,Simulador!$B$9*(1-COS(PI()*(1-(($A8-Simulador!$E$6)/Simulador!$G$6))/Simulador!$B$11))/2,Simulador!$B$9))) -> 0 | D8: =IF(OR((($A8-Simulador!$E$7)/Simulador!$G$7)<=0,(($A8-Simulador!$E$7)/Simulador!$G$7)>=1),0,IF((($A8-Simulador!$E$7)/Simulador!$G$7)<Simulador!$B$11,Simulador!$B$9*(1-COS(PI()*(($A8-Simulador!$E$7)/Simulador!$G$7)/Simulador!$B$11))/2,IF((($A8-Simulador!$E$7)/Simulador!$G$7)>1-Simulador!$B$11,Simulador!$B$9*(1-COS(PI()*(1-(($A8-Simulador!$E$7)/Simulador!$G$7))/Simulador!$B$11))/2,Simulador!$B$9))) -> 0 | E8: =IF(OR((($A8-Simulador!$E$8)/Simulador!$G$8)<=0,(($A8-Simulador!$E$8)/Simulador!$G$8)>=1),0,IF((($A8-Simulador!$E$8)/Simulador!$G$8)<Simulador!$B$11,Simulador!$B$10*(1-COS(PI()*(($A8-Simulador!$E$8)/Simulador!$G$8)/Simulador!$B$11))/2,IF((($A8-Simulador!$E$8)/Simulador!$G$8)>1-Simulador!$B$11,Simulador!$B$10*(1-COS(PI()*(1-(($A8-Simulador!$E$8)/Simulador!$G$8))/Simulador!$B$11))/2,Simulador!$B$10))) -> 0 | F8: =IF(OR((($A8-Simulador!$E$9)/Simulador!$G$9)<=0,(($A8-Simulador!$E$9)/Simulador!$G$9)>=1),0,IF((($A8-Simulador!$E$9)/Simulador!$G$9)<Simulador!$B$11,Simulador!$B$10*(1-COS(PI()*(($A8-Simulador!$E$9)/Simulador!$G$9)/Simulador!$B$11))/2,IF((($A8-Simulador!$E$9)/Simulador!$G$9)>1-Simulador!$B$11,Simulador!$B$10*(1-COS(PI()*(1-(($A8-Simulador!$E$9)/Simulador!$G$9))/Simulador!$B$11))/2,Simulador!$B$10))) -> 0 | G8: =IF(OR((($A8-Simulador!$E$10)/Simulador!$G$10)<=0,(($A8-Simulador!$E$10)/Simulador!$G$10)>=1),0,IF((($A8-Simulador!$E$10)/Simulador!$G$10)<Simulador!$B$11,Simulador!$B$10*(1-COS(PI()*(($A8-Simulador!$E$10)/Simulador!$G$10)/Simulador!$B$11))/2,IF((($A8-Simulador!$E$10)/Simulador!$G$10)>1-Simulador!$B$11,Simulador!$B$10*(1-COS(PI()*(1-(($A8-Simulador!$E$10)/Simulador!$G$10))/Simulador!$B$11))/2,Simulador!$B$10))) -> 0 | I8: =Simulador!$F$7 -> 395 | J8: =MAX(Simulador!$B$9,Simulador!$B$10)*1.32 -> 12.54 | K8: =Simulador!$F$5 -> 365 | L8: =MAX(Simulador!$B$9,Simulador!$B$10)*1.16 -> 11.02
A9: =A8+Simulador!$B$14 -> 14 | B9: =IF(OR((($A9-Simulador!$E$5)/Simulador!$G$5)<=0,(($A9-Simulador!$E$5)/Simulador!$G$5)>=1),0,IF((($A9-Simulador!$E$5)/Simulador!$G$5)<Simulador!$B$11,Simulador!$B$9*(1-COS(PI()*(($A9-Simulador!$E$5)/Simulador!$G$5)/Simulador!$B$11))/2,IF((($A9-Simulador!$E$5)/Simulador!$G$5)>1-Simulador!$B$11,Simulador!$B$9*(1-COS(PI()*(1-(($A9-Simulador!$E$5)/Simulador!$G$5))/Simulador!$B$11))/2,Simulador!$B$9))) -> 0 | C9: =IF(OR((($A9-Simulador!$E$6)/Simulador!$G$6)<=0,(($A9-Simulador!$E$6)/Simulador!$G$6)>=1),0,IF((($A9-Simulador!$E$6)/Simulador!$G$6)<Simulador!$B$11,Simulador!$B$9*(1-COS(PI()*(($A9-Simulador!$E$6)/Simulador!$G$6)/Simulador!$B$11))/2,IF((($A9-Simulador!$E$6)/Simulador!$G$6)>1-Simulador!$B$11,Simulador!$B$9*(1-COS(PI()*(1-(($A9-Simulador!$E$6)/Simulador!$G$6))/Simulador!$B$11))/2,Simulador!$B$9))) -> 0 | D9: =IF(OR((($A9-Simulador!$E$7)/Simulador!$G$7)<=0,(($A9-Simulador!$E$7)/Simulador!$G$7)>=1),0,IF((($A9-Simulador!$E$7)/Simulador!$G$7)<Simulador!$B$11,Simulador!$B$9*(1-COS(PI()*(($A9-Simulador!$E$7)/Simulador!$G$7)/Simulador!$B$11))/2,IF((($A9-Simulador!$E$7)/Simulador!$G$7)>1-Simulador!$B$11,Simulador!$B$9*(1-COS(PI()*(1-(($A9-Simulador!$E$7)/Simulador!$G$7))/Simulador!$B$11))/2,Simulador!$B$9))) -> 0 | E9: =IF(OR((($A9-Simulador!$E$8)/Simulador!$G$8)<=0,(($A9-Simulador!$E$8)/Simulador!$G$8)>=1),0,IF((($A9-Simulador!$E$8)/Simulador!$G$8)<Simulador!$B$11,Simulador!$B$10*(1-COS(PI()*(($A9-Simulador!$E$8)/Simulador!$G$8)/Simulador!$B$11))/2,IF((($A9-Simulador!$E$8)/Simulador!$G$8)>1-Simulador!$B$11,Simulador!$B$10*(1-COS(PI()*(1-(($A9-Simulador!$E$8)/Simulador!$G$8))/Simulador!$B$11))/2,Simulador!$B$10))) -> 0 | F9: =IF(OR((($A9-Simulador!$E$9)/Simulador!$G$9)<=0,(($A9-Simulador!$E$9)/Simulador!$G$9)>=1),0,IF((($A9-Simulador!$E$9)/Simulador!$G$9)<Simulador!$B$11,Simulador!$B$10*(1-COS(PI()*(($A9-Simulador!$E$9)/Simulador!$G$9)/Simulador!$B$11))/2,IF((($A9-Simulador!$E$9)/Simulador!$G$9)>1-Simulador!$B$11,Simulador!$B$10*(1-COS(PI()*(1-(($A9-Simulador!$E$9)/Simulador!$G$9))/Simulador!$B$11))/2,Simulador!$B$10))) -> 0 | G9: =IF(OR((($A9-Simulador!$E$10)/Simulador!$G$10)<=0,(($A9-Simulador!$E$10)/Simulador!$G$10)>=1),0,IF((($A9-Simulador!$E$10)/Simulador!$G$10)<Simulador!$B$11,Simulador!$B$10*(1-COS(PI()*(($A9-Simulador!$E$10)/Simulador!$G$10)/Simulador!$B$11))/2,IF((($A9-Simulador!$E$10)/Simulador!$G$10)>1-Simulador!$B$11,Simulador!$B$10*(1-COS(PI()*(1-(($A9-Simulador!$E$10)/Simulador!$G$10))/Simulador!$B$11))/2,Simulador!$B$10))) -> 0 | I9: =Simulador!$F$7 -> 395 | J9: =MAX(Simulador!$B$9,Simulador!$B$10)*1.32-0.05 -> 12.49 | K9: =Simulador!$F$5 -> 365 | L9: =MAX(Simulador!$B$9,Simulador!$B$10)*1.16-0.05 -> 10.97
A10: =A9+Simulador!$B$14 -> 16 | B10: =IF(OR((($A10-Simulador!$E$5)/Simulador!$G$5)<=0,(($A10-Simulador!$E$5)/Simulador!$G$5)>=1),0,IF((($A10-Simulador!$E$5)/Simulador!$G$5)<Simulador!$B$11,Simulador!$B$9*(1-COS(PI()*(($A10-Simulador!$E$5)/Simulador!$G$5)/Simulador!$B$11))/2,IF((($A10-Simulador!$E$5)/Simulador!$G$5)>1-Simulador!$B$11,Simulador!$B$9*(1-COS(PI()*(1-(($A10-Simulador!$E$5)/Simulador!$G$5))/Simulador!$B$11))/2,Simulador!$B$9))) -> 0 | C10: =IF(OR((($A10-Simulador!$E$6)/Simulador!$G$6)<=0,(($A10-Simulador!$E$6)/Simulador!$G$6)>=1),0,IF((($A10-Simulador!$E$6)/Simulador!$G$6)<Simulador!$B$11,Simulador!$B$9*(1-COS(PI()*(($A10-Simulador!$E$6)/Simulador!$G$6)/Simulador!$B$11))/2,IF((($A10-Simulador!$E$6)/Simulador!$G$6)>1-Simulador!$B$11,Simulador!$B$9*(1-COS(PI()*(1-(($A10-Simulador!$E$6)/Simulador!$G$6))/Simulador!$B$11))/2,Simulador!$B$9))) -> 0 | D10: =IF(OR((($A10-Simulador!$E$7)/Simulador!$G$7)<=0,(($A10-Simulador!$E$7)/Simulador!$G$7)>=1),0,IF((($A10-Simulador!$E$7)/Simulador!$G$7)<Simulador!$B$11,Simulador!$B$9*(1-COS(PI()*(($A10-Simulador!$E$7)/Simulador!$G$7)/Simulador!$B$11))/2,IF((($A10-Simulador!$E$7)/Simulador!$G$7)>1-Simulador!$B$11,Simulador!$B$9*(1-COS(PI()*(1-(($A10-Simulador!$E$7)/Simulador!$G$7))/Simulador!$B$11))/2,Simulador!$B$9))) -> 0 | E10: =IF(OR((($A10-Simulador!$E$8)/Simulador!$G$8)<=0,(($A10-Simulador!$E$8)/Simulador!$G$8)>=1),0,IF((($A10-Simulador!$E$8)/Simulador!$G$8)<Simulador!$B$11,Simulador!$B$10*(1-COS(PI()*(($A10-Simulador!$E$8)/Simulador!$G$8)/Simulador!$B$11))/2,IF((($A10-Simulador!$E$8)/Simulador!$G$8)>1-Simulador!$B$11,Simulador!$B$10*(1-COS(PI()*(1-(($A10-Simulador!$E$8)/Simulador!$G$8))/Simulador!$B$11))/2,Simulador!$B$10))) -> 0 | F10: =IF(OR((($A10-Simulador!$E$9)/Simulador!$G$9)<=0,(($A10-Simulador!$E$9)/Simulador!$G$9)>=1),0,IF((($A10-Simulador!$E$9)/Simulador!$G$9)<Simulador!$B$11,Simulador!$B$10*(1-COS(PI()*(($A10-Simulador!$E$9)/Simulador!$G$9)/Simulador!$B$11))/2,IF((($A10-Simulador!$E$9)/Simulador!$G$9)>1-Simulador!$B$11,Simulador!$B$10*(1-COS(PI()*(1-(($A10-Simulador!$E$9)/Simulador!$G$9))/Simulador!$B$11))/2,Simulador!$B$10))) -> 0 | G10: =IF(OR((($A10-Simulador!$E$10)/Simulador!$G$10)<=0,(($A10-Simulador!$E$10)/Simulador!$G$10)>=1),0,IF((($A10-Simulador!$E$10)/Simulador!$G$10)<Simulador!$B$11,Simulador!$B$10*(1-COS(PI()*(($A10-Simulador!$E$10)/Simulador!$G$10)/Simulador!$B$11))/2,IF((($A10-Simulador!$E$10)/Simulador!$G$10)>1-Simulador!$B$11,Simulador!$B$10*(1-COS(PI()*(1-(($A10-Simulador!$E$10)/Simulador!$G$10))/Simulador!$B$11))/2,Simulador!$B$10))) -> 0 | I10: =Simulador!$F$7 -> 395 | J10: 0.05 | K10: =Simulador!$F$5 -> 365 | L10: 0.05
A11: =A10+Simulador!$B$14 -> 18 | B11: =IF(OR((($A11-Simulador!$E$5)/Simulador!$G$5)<=0,(($A11-Simulador!$E$5)/Simulador!$G$5)>=1),0,IF((($A11-Simulador!$E$5)/Simulador!$G$5)<Simulador!$B$11,Simulador!$B$9*(1-COS(PI()*(($A11-Simulador!$E$5)/Simulador!$G$5)/Simulador!$B$11))/2,IF((($A11-Simulador!$E$5)/Simulador!$G$5)>1-Simulador!$B$11,Simulador!$B$9*(1-COS(PI()*(1-(($A11-Simulador!$E$5)/Simulador!$G$5))/Simulador!$B$11))/2,Simulador!$B$9))) -> 0 | C11: =IF(OR((($A11-Simulador!$E$6)/Simulador!$G$6)<=0,(($A11-Simulador!$E$6)/Simulador!$G$6)>=1),0,IF((($A11-Simulador!$E$6)/Simulador!$G$6)<Simulador!$B$11,Simulador!$B$9*(1-COS(PI()*(($A11-Simulador!$E$6)/Simulador!$G$6)/Simulador!$B$11))/2,IF((($A11-Simulador!$E$6)/Simulador!$G$6)>1-Simulador!$B$11,Simulador!$B$9*(1-COS(PI()*(1-(($A11-Simulador!$E$6)/Simulador!$G$6))/Simulador!$B$11))/2,Simulador!$B$9))) -> 0 | D11: =IF(OR((($A11-Simulador!$E$7)/Simulador!$G$7)<=0,(($A11-Simulador!$E$7)/Simulador!$G$7)>=1),0,IF((($A11-Simulador!$E$7)/Simulador!$G$7)<Simulador!$B$11,Simulador!$B$9*(1-COS(PI()*(($A11-Simulador!$E$7)/Simulador!$G$7)/Simulador!$B$11))/2,IF((($A11-Simulador!$E$7)/Simulador!$G$7)>1-Simulador!$B$11,Simulador!$B$9*(1-COS(PI()*(1-(($A11-Simulador!$E$7)/Simulador!$G$7))/Simulador!$B$11))/2,Simulador!$B$9))) -> 0 | E11: =IF(OR((($A11-Simulador!$E$8)/Simulador!$G$8)<=0,(($A11-Simulador!$E$8)/Simulador!$G$8)>=1),0,IF((($A11-Simulador!$E$8)/Simulador!$G$8)<Simulador!$B$11,Simulador!$B$10*(1-COS(PI()*(($A11-Simulador!$E$8)/Simulador!$G$8)/Simulador!$B$11))/2,IF((($A11-Simulador!$E$8)/Simulador!$G$8)>1-Simulador!$B$11,Simulador!$B$10*(1-COS(PI()*(1-(($A11-Simulador!$E$8)/Simulador!$G$8))/Simulador!$B$11))/2,Simulador!$B$10))) -> 0 | F11: =IF(OR((($A11-Simulador!$E$9)/Simulador!$G$9)<=0,(($A11-Simulador!$E$9)/Simulador!$G$9)>=1),0,IF((($A11-Simulador!$E$9)/Simulador!$G$9)<Simulador!$B$11,Simulador!$B$10*(1-COS(PI()*(($A11-Simulador!$E$9)/Simulador!$G$9)/Simulador!$B$11))/2,IF((($A11-Simulador!$E$9)/Simulador!$G$9)>1-Simulador!$B$11,Simulador!$B$10*(1-COS(PI()*(1-(($A11-Simulador!$E$9)/Simulador!$G$9))/Simulador!$B$11))/2,Simulador!$B$10))) -> 0 | G11: =IF(OR((($A11-Simulador!$E$10)/Simulador!$G$10)<=0,(($A11-Simulador!$E$10)/Simulador!$G$10)>=1),0,IF((($A11-Simulador!$E$10)/Simulador!$G$10)<Simulador!$B$11,Simulador!$B$10*(1-COS(PI()*(($A11-Simulador!$E$10)/Simulador!$G$10)/Simulador!$B$11))/2,IF((($A11-Simulador!$E$10)/Simulador!$G$10)>1-Simulador!$B$11,Simulador!$B$10*(1-COS(PI()*(1-(($A11-Simulador!$E$10)/Simulador!$G$10))/Simulador!$B$11))/2,Simulador!$B$10))) -> 0 | I11: =Simulador!$F$7 -> 395 | J11: 0 | K11: =Simulador!$F$5 -> 365 | L11: 0
A12: =A11+Simulador!$B$14 -> 20 | B12: =IF(OR((($A12-Simulador!$E$5)/Simulador!$G$5)<=0,(($A12-Simulador!$E$5)/Simulador!$G$5)>=1),0,IF((($A12-Simulador!$E$5)/Simulador!$G$5)<Simulador!$B$11,Simulador!$B$9*(1-COS(PI()*(($A12-Simulador!$E$5)/Simulador!$G$5)/Simulador!$B$11))/2,IF((($A12-Simulador!$E$5)/Simulador!$G$5)>1-Simulador!$B$11,Simulador!$B$9*(1-COS(PI()*(1-(($A12-Simulador!$E$5)/Simulador!$G$5))/Simulador!$B$11))/2,Simulador!$B$9))) -> 0 | C12: =IF(OR((($A12-Simulador!$E$6)/Simulador!$G$6)<=0,(($A12-Simulador!$E$6)/Simulador!$G$6)>=1),0,IF((($A12-Simulador!$E$6)/Simulador!$G$6)<Simulador!$B$11,Simulador!$B$9*(1-COS(PI()*(($A12-Simulador!$E$6)/Simulador!$G$6)/Simulador!$B$11))/2,IF((($A12-Simulador!$E$6)/Simulador!$G$6)>1-Simulador!$B$11,Simulador!$B$9*(1-COS(PI()*(1-(($A12-Simulador!$E$6)/Simulador!$G$6))/Simulador!$B$11))/2,Simulador!$B$9))) -> 0 | D12: =IF(OR((($A12-Simulador!$E$7)/Simulador!$G$7)<=0,(($A12-Simulador!$E$7)/Simulador!$G$7)>=1),0,IF((($A12-Simulador!$E$7)/Simulador!$G$7)<Simulador!$B$11,Simulador!$B$9*(1-COS(PI()*(($A12-Simulador!$E$7)/Simulador!$G$7)/Simulador!$B$11))/2,IF((($A12-Simulador!$E$7)/Simulador!$G$7)>1-Simulador!$B$11,Simulador!$B$9*(1-COS(PI()*(1-(($A12-Simulador!$E$7)/Simulador!$G$7))/Simulador!$B$11))/2,Simulador!$B$9))) -> 0 | E12: =IF(OR((($A12-Simulador!$E$8)/Simulador!$G$8)<=0,(($A12-Simulador!$E$8)/Simulador!$G$8)>=1),0,IF((($A12-Simulador!$E$8)/Simulador!$G$8)<Simulador!$B$11,Simulador!$B$10*(1-COS(PI()*(($A12-Simulador!$E$8)/Simulador!$G$8)/Simulador!$B$11))/2,IF((($A12-Simulador!$E$8)/Simulador!$G$8)>1-Simulador!$B$11,Simulador!$B$10*(1-COS(PI()*(1-(($A12-Simulador!$E$8)/Simulador!$G$8))/Simulador!$B$11))/2,Simulador!$B$10))) -> 0 | F12: =IF(OR((($A12-Simulador!$E$9)/Simulador!$G$9)<=0,(($A12-Simulador!$E$9)/Simulador!$G$9)>=1),0,IF((($A12-Simulador!$E$9)/Simulador!$G$9)<Simulador!$B$11,Simulador!$B$10*(1-COS(PI()*(($A12-Simulador!$E$9)/Simulador!$G$9)/Simulador!$B$11))/2,IF((($A12-Simulador!$E$9)/Simulador!$G$9)>1-Simulador!$B$11,Simulador!$B$10*(1-COS(PI()*(1-(($A12-Simulador!$E$9)/Simulador!$G$9))/Simulador!$B$11))/2,Simulador!$B$10))) -> 0 | G12: =IF(OR((($A12-Simulador!$E$10)/Simulador!$G$10)<=0,(($A12-Simulador!$E$10)/Simulador!$G$10)>=1),0,IF((($A12-Simulador!$E$10)/Simulador!$G$10)<Simulador!$B$11,Simulador!$B$10*(1-COS(PI()*(($A12-Simulador!$E$10)/Simulador!$G$10)/Simulador!$B$11))/2,IF((($A12-Simulador!$E$10)/Simulador!$G$10)>1-Simulador!$B$11,Simulador!$B$10*(1-COS(PI()*(1-(($A12-Simulador!$E$10)/Simulador!$G$10))/Simulador!$B$11))/2,Simulador!$B$10))) -> 0
A13: =A12+Simulador!$B$14 -> 22 | B13: =IF(OR((($A13-Simulador!$E$5)/Simulador!$G$5)<=0,(($A13-Simulador!$E$5)/Simulador!$G$5)>=1),0,IF((($A13-Simulador!$E$5)/Simulador!$G$5)<Simulador!$B$11,Simulador!$B$9*(1-COS(PI()*(($A13-Simulador!$E$5)/Simulador!$G$5)/Simulador!$B$11))/2,IF((($A13-Simulador!$E$5)/Simulador!$G$5)>1-Simulador!$B$11,Simulador!$B$9*(1-COS(PI()*(1-(($A13-Simulador!$E$5)/Simulador!$G$5))/Simulador!$B$11))/2,Simulador!$B$9))) -> 0 | C13: =IF(OR((($A13-Simulador!$E$6)/Simulador!$G$6)<=0,(($A13-Simulador!$E$6)/Simulador!$G$6)>=1),0,IF((($A13-Simulador!$E$6)/Simulador!$G$6)<Simulador!$B$11,Simulador!$B$9*(1-COS(PI()*(($A13-Simulador!$E$6)/Simulador!$G$6)/Simulador!$B$11))/2,IF((($A13-Simulador!$E$6)/Simulador!$G$6)>1-Simulador!$B$11,Simulador!$B$9*(1-COS(PI()*(1-(($A13-Simulador!$E$6)/Simulador!$G$6))/Simulador!$B$11))/2,Simulador!$B$9))) -> 0 | D13: =IF(OR((($A13-Simulador!$E$7)/Simulador!$G$7)<=0,(($A13-Simulador!$E$7)/Simulador!$G$7)>=1),0,IF((($A13-Simulador!$E$7)/Simulador!$G$7)<Simulador!$B$11,Simulador!$B$9*(1-COS(PI()*(($A13-Simulador!$E$7)/Simulador!$G$7)/Simulador!$B$11))/2,IF((($A13-Simulador!$E$7)/Simulador!$G$7)>1-Simulador!$B$11,Simulador!$B$9*(1-COS(PI()*(1-(($A13-Simulador!$E$7)/Simulador!$G$7))/Simulador!$B$11))/2,Simulador!$B$9))) -> 0 | E13: =IF(OR((($A13-Simulador!$E$8)/Simulador!$G$8)<=0,(($A13-Simulador!$E$8)/Simulador!$G$8)>=1),0,IF((($A13-Simulador!$E$8)/Simulador!$G$8)<Simulador!$B$11,Simulador!$B$10*(1-COS(PI()*(($A13-Simulador!$E$8)/Simulador!$G$8)/Simulador!$B$11))/2,IF((($A13-Simulador!$E$8)/Simulador!$G$8)>1-Simulador!$B$11,Simulador!$B$10*(1-COS(PI()*(1-(($A13-Simulador!$E$8)/Simulador!$G$8))/Simulador!$B$11))/2,Simulador!$B$10))) -> 0 | F13: =IF(OR((($A13-Simulador!$E$9)/Simulador!$G$9)<=0,(($A13-Simulador!$E$9)/Simulador!$G$9)>=1),0,IF((($A13-Simulador!$E$9)/Simulador!$G$9)<Simulador!$B$11,Simulador!$B$10*(1-COS(PI()*(($A13-Simulador!$E$9)/Simulador!$G$9)/Simulador!$B$11))/2,IF((($A13-Simulador!$E$9)/Simulador!$G$9)>1-Simulador!$B$11,Simulador!$B$10*(1-COS(PI()*(1-(($A13-Simulador!$E$9)/Simulador!$G$9))/Simulador!$B$11))/2,Simulador!$B$10))) -> 0 | G13: =IF(OR((($A13-Simulador!$E$10)/Simulador!$G$10)<=0,(($A13-Simulador!$E$10)/Simulador!$G$10)>=1),0,IF((($A13-Simulador!$E$10)/Simulador!$G$10)<Simulador!$B$11,Simulador!$B$10*(1-COS(PI()*(($A13-Simulador!$E$10)/Simulador!$G$10)/Simulador!$B$11))/2,IF((($A13-Simulador!$E$10)/Simulador!$G$10)>1-Simulador!$B$11,Simulador!$B$10*(1-COS(PI()*(1-(($A13-Simulador!$E$10)/Simulador!$G$10))/Simulador!$B$11))/2,Simulador!$B$10))) -> 0 | I13: Las columnas I–N dibujan los corchetes de cruce y la línea del PMS en el gráfico.
A14: =A13+Simulador!$B$14 -> 24 | B14: =IF(OR((($A14-Simulador!$E$5)/Simulador!$G$5)<=0,(($A14-Simulador!$E$5)/Simulador!$G$5)>=1),0,IF((($A14-Simulador!$E$5)/Simulador!$G$5)<Simulador!$B$11,Simulador!$B$9*(1-COS(PI()*(($A14-Simulador!$E$5)/Simulador!$G$5)/Simulador!$B$11))/2,IF((($A14-Simulador!$E$5)/Simulador!$G$5)>1-Simulador!$B$11,Simulador!$B$9*(1-COS(PI()*(1-(($A14-Simulador!$E$5)/Simulador!$G$5))/Simulador!$B$11))/2,Simulador!$B$9))) -> 0 | C14: =IF(OR((($A14-Simulador!$E$6)/Simulador!$G$6)<=0,(($A14-Simulador!$E$6)/Simulador!$G$6)>=1),0,IF((($A14-Simulador!$E$6)/Simulador!$G$6)<Simulador!$B$11,Simulador!$B$9*(1-COS(PI()*(($A14-Simulador!$E$6)/Simulador!$G$6)/Simulador!$B$11))/2,IF((($A14-Simulador!$E$6)/Simulador!$G$6)>1-Simulador!$B$11,Simulador!$B$9*(1-COS(PI()*(1-(($A14-Simulador!$E$6)/Simulador!$G$6))/Simulador!$B$11))/2,Simulador!$B$9))) -> 0 | D14: =IF(OR((($A14-Simulador!$E$7)/Simulador!$G$7)<=0,(($A14-Simulador!$E$7)/Simulador!$G$7)>=1),0,IF((($A14-Simulador!$E$7)/Simulador!$G$7)<Simulador!$B$11,Simulador!$B$9*(1-COS(PI()*(($A14-Simulador!$E$7)/Simulador!$G$7)/Simulador!$B$11))/2,IF((($A14-Simulador!$E$7)/Simulador!$G$7)>1-Simulador!$B$11,Simulador!$B$9*(1-COS(PI()*(1-(($A14-Simulador!$E$7)/Simulador!$G$7))/Simulador!$B$11))/2,Simulador!$B$9))) -> 0 | E14: =IF(OR((($A14-Simulador!$E$8)/Simulador!$G$8)<=0,(($A14-Simulador!$E$8)/Simulador!$G$8)>=1),0,IF((($A14-Simulador!$E$8)/Simulador!$G$8)<Simulador!$B$11,Simulador!$B$10*(1-COS(PI()*(($A14-Simulador!$E$8)/Simulador!$G$8)/Simulador!$B$11))/2,IF((($A14-Simulador!$E$8)/Simulador!$G$8)>1-Simulador!$B$11,Simulador!$B$10*(1-COS(PI()*(1-(($A14-Simulador!$E$8)/Simulador!$G$8))/Simulador!$B$11))/2,Simulador!$B$10))) -> 0 | F14: =IF(OR((($A14-Simulador!$E$9)/Simulador!$G$9)<=0,(($A14-Simulador!$E$9)/Simulador!$G$9)>=1),0,IF((($A14-Simulador!$E$9)/Simulador!$G$9)<Simulador!$B$11,Simulador!$B$10*(1-COS(PI()*(($A14-Simulador!$E$9)/Simulador!$G$9)/Simulador!$B$11))/2,IF((($A14-Simulador!$E$9)/Simulador!$G$9)>1-Simulador!$B$11,Simulador!$B$10*(1-COS(PI()*(1-(($A14-Simulador!$E$9)/Simulador!$G$9))/Simulador!$B$11))/2,Simulador!$B$10))) -> 0 | G14: =IF(OR((($A14-Simulador!$E$10)/Simulador!$G$10)<=0,(($A14-Simulador!$E$10)/Simulador!$G$10)>=1),0,IF((($A14-Simulador!$E$10)/Simulador!$G$10)<Simulador!$B$11,Simulador!$B$10*(1-COS(PI()*(($A14-Simulador!$E$10)/Simulador!$G$10)/Simulador!$B$11))/2,IF((($A14-Simulador!$E$10)/Simulador!$G$10)>1-Simulador!$B$11,Simulador!$B$10*(1-COS(PI()*(1-(($A14-Simulador!$E$10)/Simulador!$G$10))/Simulador!$B$11))/2,Simulador!$B$10))) -> 0
A15: =A14+Simulador!$B$14 -> 26 | B15: =IF(OR((($A15-Simulador!$E$5)/Simulador!$G$5)<=0,(($A15-Simulador!$E$5)/Simulador!$G$5)>=1),0,IF((($A15-Simulador!$E$5)/Simulador!$G$5)<Simulador!$B$11,Simulador!$B$9*(1-COS(PI()*(($A15-Simulador!$E$5)/Simulador!$G$5)/Simulador!$B$11))/2,IF((($A15-Simulador!$E$5)/Simulador!$G$5)>1-Simulador!$B$11,Simulador!$B$9*(1-COS(PI()*(1-(($A15-Simulador!$E$5)/Simulador!$G$5))/Simulador!$B$11))/2,Simulador!$B$9))) -> 0 | C15: =IF(OR((($A15-Simulador!$E$6)/Simulador!$G$6)<=0,(($A15-Simulador!$E$6)/Simulador!$G$6)>=1),0,IF((($A15-Simulador!$E$6)/Simulador!$G$6)<Simulador!$B$11,Simulador!$B$9*(1-COS(PI()*(($A15-Simulador!$E$6)/Simulador!$G$6)/Simulador!$B$11))/2,IF((($A15-Simulador!$E$6)/Simulador!$G$6)>1-Simulador!$B$11,Simulador!$B$9*(1-COS(PI()*(1-(($A15-Simulador!$E$6)/Simulador!$G$6))/Simulador!$B$11))/2,Simulador!$B$9))) -> 0 | D15: =IF(OR((($A15-Simulador!$E$7)/Simulador!$G$7)<=0,(($A15-Simulador!$E$7)/Simulador!$G$7)>=1),0,IF((($A15-Simulador!$E$7)/Simulador!$G$7)<Simulador!$B$11,Simulador!$B$9*(1-COS(PI()*(($A15-Simulador!$E$7)/Simulador!$G$7)/Simulador!$B$11))/2,IF((($A15-Simulador!$E$7)/Simulador!$G$7)>1-Simulador!$B$11,Simulador!$B$9*(1-COS(PI()*(1-(($A15-Simulador!$E$7)/Simulador!$G$7))/Simulador!$B$11))/2,Simulador!$B$9))) -> 0 | E15: =IF(OR((($A15-Simulador!$E$8)/Simulador!$G$8)<=0,(($A15-Simulador!$E$8)/Simulador!$G$8)>=1),0,IF((($A15-Simulador!$E$8)/Simulador!$G$8)<Simulador!$B$11,Simulador!$B$10*(1-COS(PI()*(($A15-Simulador!$E$8)/Simulador!$G$8)/Simulador!$B$11))/2,IF((($A15-Simulador!$E$8)/Simulador!$G$8)>1-Simulador!$B$11,Simulador!$B$10*(1-COS(PI()*(1-(($A15-Simulador!$E$8)/Simulador!$G$8))/Simulador!$B$11))/2,Simulador!$B$10))) -> 0 | F15: =IF(OR((($A15-Simulador!$E$9)/Simulador!$G$9)<=0,(($A15-Simulador!$E$9)/Simulador!$G$9)>=1),0,IF((($A15-Simulador!$E$9)/Simulador!$G$9)<Simulador!$B$11,Simulador!$B$10*(1-COS(PI()*(($A15-Simulador!$E$9)/Simulador!$G$9)/Simulador!$B$11))/2,IF((($A15-Simulador!$E$9)/Simulador!$G$9)>1-Simulador!$B$11,Simulador!$B$10*(1-COS(PI()*(1-(($A15-Simulador!$E$9)/Simulador!$G$9))/Simulador!$B$11))/2,Simulador!$B$10))) -> 0 | G15: =IF(OR((($A15-Simulador!$E$10)/Simulador!$G$10)<=0,(($A15-Simulador!$E$10)/Simulador!$G$10)>=1),0,IF((($A15-Simulador!$E$10)/Simulador!$G$10)<Simulador!$B$11,Simulador!$B$10*(1-COS(PI()*(($A15-Simulador!$E$10)/Simulador!$G$10)/Simulador!$B$11))/2,IF((($A15-Simulador!$E$10)/Simulador!$G$10)>1-Simulador!$B$11,Simulador!$B$10*(1-COS(PI()*(1-(($A15-Simulador!$E$10)/Simulador!$G$10))/Simulador!$B$11))/2,Simulador!$B$10))) -> 0
A16: =A15+Simulador!$B$14 -> 28 | B16: =IF(OR((($A16-Simulador!$E$5)/Simulador!$G$5)<=0,(($A16-Simulador!$E$5)/Simulador!$G$5)>=1),0,IF((($A16-Simulador!$E$5)/Simulador!$G$5)<Simulador!$B$11,Simulador!$B$9*(1-COS(PI()*(($A16-Simulador!$E$5)/Simulador!$G$5)/Simulador!$B$11))/2,IF((($A16-Simulador!$E$5)/Simulador!$G$5)>1-Simulador!$B$11,Simulador!$B$9*(1-COS(PI()*(1-(($A16-Simulador!$E$5)/Simulador!$G$5))/Simulador!$B$11))/2,Simulador!$B$9))) -> 0 | C16: =IF(OR((($A16-Simulador!$E$6)/Simulador!$G$6)<=0,(($A16-Simulador!$E$6)/Simulador!$G$6)>=1),0,IF((($A16-Simulador!$E$6)/Simulador!$G$6)<Simulador!$B$11,Simulador!$B$9*(1-COS(PI()*(($A16-Simulador!$E$6)/Simulador!$G$6)/Simulador!$B$11))/2,IF((($A16-Simulador!$E$6)/Simulador!$G$6)>1-Simulador!$B$11,Simulador!$B$9*(1-COS(PI()*(1-(($A16-Simulador!$E$6)/Simulador!$G$6))/Simulador!$B$11))/2,Simulador!$B$9))) -> 0 | D16: =IF(OR((($A16-Simulador!$E$7)/Simulador!$G$7)<=0,(($A16-Simulador!$E$7)/Simulador!$G$7)>=1),0,IF((($A16-Simulador!$E$7)/Simulador!$G$7)<Simulador!$B$11,Simulador!$B$9*(1-COS(PI()*(($A16-Simulador!$E$7)/Simulador!$G$7)/Simulador!$B$11))/2,IF((($A16-Simulador!$E$7)/Simulador!$G$7)>1-Simulador!$B$11,Simulador!$B$9*(1-COS(PI()*(1-(($A16-Simulador!$E$7)/Simulador!$G$7))/Simulador!$B$11))/2,Simulador!$B$9))) -> 0 | E16: =IF(OR((($A16-Simulador!$E$8)/Simulador!$G$8)<=0,(($A16-Simulador!$E$8)/Simulador!$G$8)>=1),0,IF((($A16-Simulador!$E$8)/Simulador!$G$8)<Simulador!$B$11,Simulador!$B$10*(1-COS(PI()*(($A16-Simulador!$E$8)/Simulador!$G$8)/Simulador!$B$11))/2,IF((($A16-Simulador!$E$8)/Simulador!$G$8)>1-Simulador!$B$11,Simulador!$B$10*(1-COS(PI()*(1-(($A16-Simulador!$E$8)/Simulador!$G$8))/Simulador!$B$11))/2,Simulador!$B$10))) -> 0 | F16: =IF(OR((($A16-Simulador!$E$9)/Simulador!$G$9)<=0,(($A16-Simulador!$E$9)/Simulador!$G$9)>=1),0,IF((($A16-Simulador!$E$9)/Simulador!$G$9)<Simulador!$B$11,Simulador!$B$10*(1-COS(PI()*(($A16-Simulador!$E$9)/Simulador!$G$9)/Simulador!$B$11))/2,IF((($A16-Simulador!$E$9)/Simulador!$G$9)>1-Simulador!$B$11,Simulador!$B$10*(1-COS(PI()*(1-(($A16-Simulador!$E$9)/Simulador!$G$9))/Simulador!$B$11))/2,Simulador!$B$10))) -> 0 | G16: =IF(OR((($A16-Simulador!$E$10)/Simulador!$G$10)<=0,(($A16-Simulador!$E$10)/Simulador!$G$10)>=1),0,IF((($A16-Simulador!$E$10)/Simulador!$G$10)<Simulador!$B$11,Simulador!$B$10*(1-COS(PI()*(($A16-Simulador!$E$10)/Simulador!$G$10)/Simulador!$B$11))/2,IF((($A16-Simulador!$E$10)/Simulador!$G$10)>1-Simulador!$B$11,Simulador!$B$10*(1-COS(PI()*(1-(($A16-Simulador!$E$10)/Simulador!$G$10))/Simulador!$B$11))/2,Simulador!$B$10))) -> 0
A17: =A16+Simulador!$B$14 -> 30 | B17: =IF(OR((($A17-Simulador!$E$5)/Simulador!$G$5)<=0,(($A17-Simulador!$E$5)/Simulador!$G$5)>=1),0,IF((($A17-Simulador!$E$5)/Simulador!$G$5)<Simulador!$B$11,Simulador!$B$9*(1-COS(PI()*(($A17-Simulador!$E$5)/Simulador!$G$5)/Simulador!$B$11))/2,IF((($A17-Simulador!$E$5)/Simulador!$G$5)>1-Simulador!$B$11,Simulador!$B$9*(1-COS(PI()*(1-(($A17-Simulador!$E$5)/Simulador!$G$5))/Simulador!$B$11))/2,Simulador!$B$9))) -> 0 | C17: =IF(OR((($A17-Simulador!$E$6)/Simulador!$G$6)<=0,(($A17-Simulador!$E$6)/Simulador!$G$6)>=1),0,IF((($A17-Simulador!$E$6)/Simulador!$G$6)<Simulador!$B$11,Simulador!$B$9*(1-COS(PI()*(($A17-Simulador!$E$6)/Simulador!$G$6)/Simulador!$B$11))/2,IF((($A17-Simulador!$E$6)/Simulador!$G$6)>1-Simulador!$B$11,Simulador!$B$9*(1-COS(PI()*(1-(($A17-Simulador!$E$6)/Simulador!$G$6))/Simulador!$B$11))/2,Simulador!$B$9))) -> 0 | D17: =IF(OR((($A17-Simulador!$E$7)/Simulador!$G$7)<=0,(($A17-Simulador!$E$7)/Simulador!$G$7)>=1),0,IF((($A17-Simulador!$E$7)/Simulador!$G$7)<Simulador!$B$11,Simulador!$B$9*(1-COS(PI()*(($A17-Simulador!$E$7)/Simulador!$G$7)/Simulador!$B$11))/2,IF((($A17-Simulador!$E$7)/Simulador!$G$7)>1-Simulador!$B$11,Simulador!$B$9*(1-COS(PI()*(1-(($A17-Simulador!$E$7)/Simulador!$G$7))/Simulador!$B$11))/2,Simulador!$B$9))) -> 0 | E17: =IF(OR((($A17-Simulador!$E$8)/Simulador!$G$8)<=0,(($A17-Simulador!$E$8)/Simulador!$G$8)>=1),0,IF((($A17-Simulador!$E$8)/Simulador!$G$8)<Simulador!$B$11,Simulador!$B$10*(1-COS(PI()*(($A17-Simulador!$E$8)/Simulador!$G$8)/Simulador!$B$11))/2,IF((($A17-Simulador!$E$8)/Simulador!$G$8)>1-Simulador!$B$11,Simulador!$B$10*(1-COS(PI()*(1-(($A17-Simulador!$E$8)/Simulador!$G$8))/Simulador!$B$11))/2,Simulador!$B$10))) -> 0 | F17: =IF(OR((($A17-Simulador!$E$9)/Simulador!$G$9)<=0,(($A17-Simulador!$E$9)/Simulador!$G$9)>=1),0,IF((($A17-Simulador!$E$9)/Simulador!$G$9)<Simulador!$B$11,Simulador!$B$10*(1-COS(PI()*(($A17-Simulador!$E$9)/Simulador!$G$9)/Simulador!$B$11))/2,IF((($A17-Simulador!$E$9)/Simulador!$G$9)>1-Simulador!$B$11,Simulador!$B$10*(1-COS(PI()*(1-(($A17-Simulador!$E$9)/Simulador!$G$9))/Simulador!$B$11))/2,Simulador!$B$10))) -> 0 | G17: =IF(OR((($A17-Simulador!$E$10)/Simulador!$G$10)<=0,(($A17-Simulador!$E$10)/Simulador!$G$10)>=1),0,IF((($A17-Simulador!$E$10)/Simulador!$G$10)<Simulador!$B$11,Simulador!$B$10*(1-COS(PI()*(($A17-Simulador!$E$10)/Simulador!$G$10)/Simulador!$B$11))/2,IF((($A17-Simulador!$E$10)/Simulador!$G$10)>1-Simulador!$B$11,Simulador!$B$10*(1-COS(PI()*(1-(($A17-Simulador!$E$10)/Simulador!$G$10))/Simulador!$B$11))/2,Simulador!$B$10))) -> 0
A18: =A17+Simulador!$B$14 -> 32 | B18: =IF(OR((($A18-Simulador!$E$5)/Simulador!$G$5)<=0,(($A18-Simulador!$E$5)/Simulador!$G$5)>=1),0,IF((($A18-Simulador!$E$5)/Simulador!$G$5)<Simulador!$B$11,Simulador!$B$9*(1-COS(PI()*(($A18-Simulador!$E$5)/Simulador!$G$5)/Simulador!$B$11))/2,IF((($A18-Simulador!$E$5)/Simulador!$G$5)>1-Simulador!$B$11,Simulador!$B$9*(1-COS(PI()*(1-(($A18-Simulador!$E$5)/Simulador!$G$5))/Simulador!$B$11))/2,Simulador!$B$9))) -> 0 | C18: =IF(OR((($A18-Simulador!$E$6)/Simulador!$G$6)<=0,(($A18-Simulador!$E$6)/Simulador!$G$6)>=1),0,IF((($A18-Simulador!$E$6)/Simulador!$G$6)<Simulador!$B$11,Simulador!$B$9*(1-COS(PI()*(($A18-Simulador!$E$6)/Simulador!$G$6)/Simulador!$B$11))/2,IF((($A18-Simulador!$E$6)/Simulador!$G$6)>1-Simulador!$B$11,Simulador!$B$9*(1-COS(PI()*(1-(($A18-Simulador!$E$6)/Simulador!$G$6))/Simulador!$B$11))/2,Simulador!$B$9))) -> 0 | D18: =IF(OR((($A18-Simulador!$E$7)/Simulador!$G$7)<=0,(($A18-Simulador!$E$7)/Simulador!$G$7)>=1),0,IF((($A18-Simulador!$E$7)/Simulador!$G$7)<Simulador!$B$11,Simulador!$B$9*(1-COS(PI()*(($A18-Simulador!$E$7)/Simulador!$G$7)/Simulador!$B$11))/2,IF((($A18-Simulador!$E$7)/Simulador!$G$7)>1-Simulador!$B$11,Simulador!$B$9*(1-COS(PI()*(1-(($A18-Simulador!$E$7)/Simulador!$G$7))/Simulador!$B$11))/2,Simulador!$B$9))) -> 0 | E18: =IF(OR((($A18-Simulador!$E$8)/Simulador!$G$8)<=0,(($A18-Simulador!$E$8)/Simulador!$G$8)>=1),0,IF((($A18-Simulador!$E$8)/Simulador!$G$8)<Simulador!$B$11,Simulador!$B$10*(1-COS(PI()*(($A18-Simulador!$E$8)/Simulador!$G$8)/Simulador!$B$11))/2,IF((($A18-Simulador!$E$8)/Simulador!$G$8)>1-Simulador!$B$11,Simulador!$B$10*(1-COS(PI()*(1-(($A18-Simulador!$E$8)/Simulador!$G$8))/Simulador!$B$11))/2,Simulador!$B$10))) -> 0 | F18: =IF(OR((($A18-Simulador!$E$9)/Simulador!$G$9)<=0,(($A18-Simulador!$E$9)/Simulador!$G$9)>=1),0,IF((($A18-Simulador!$E$9)/Simulador!$G$9)<Simulador!$B$11,Simulador!$B$10*(1-COS(PI()*(($A18-Simulador!$E$9)/Simulador!$G$9)/Simulador!$B$11))/2,IF((($A18-Simulador!$E$9)/Simulador!$G$9)>1-Simulador!$B$11,Simulador!$B$10*(1-COS(PI()*(1-(($A18-Simulador!$E$9)/Simulador!$G$9))/Simulador!$B$11))/2,Simulador!$B$10))) -> 0 | G18: =IF(OR((($A18-Simulador!$E$10)/Simulador!$G$10)<=0,(($A18-Simulador!$E$10)/Simulador!$G$10)>=1),0,IF((($A18-Simulador!$E$10)/Simulador!$G$10)<Simulador!$B$11,Simulador!$B$10*(1-COS(PI()*(($A18-Simulador!$E$10)/Simulador!$G$10)/Simulador!$B$11))/2,IF((($A18-Simulador!$E$10)/Simulador!$G$10)>1-Simulador!$B$11,Simulador!$B$10*(1-COS(PI()*(1-(($A18-Simulador!$E$10)/Simulador!$G$10))/Simulador!$B$11))/2,Simulador!$B$10))) -> 0
A19: =A18+Simulador!$B$14 -> 34 | B19: =IF(OR((($A19-Simulador!$E$5)/Simulador!$G$5)<=0,(($A19-Simulador!$E$5)/Simulador!$G$5)>=1),0,IF((($A19-Simulador!$E$5)/Simulador!$G$5)<Simulador!$B$11,Simulador!$B$9*(1-COS(PI()*(($A19-Simulador!$E$5)/Simulador!$G$5)/Simulador!$B$11))/2,IF((($A19-Simulador!$E$5)/Simulador!$G$5)>1-Simulador!$B$11,Simulador!$B$9*(1-COS(PI()*(1-(($A19-Simulador!$E$5)/Simulador!$G$5))/Simulador!$B$11))/2,Simulador!$B$9))) -> 0 | C19: =IF(OR((($A19-Simulador!$E$6)/Simulador!$G$6)<=0,(($A19-Simulador!$E$6)/Simulador!$G$6)>=1),0,IF((($A19-Simulador!$E$6)/Simulador!$G$6)<Simulador!$B$11,Simulador!$B$9*(1-COS(PI()*(($A19-Simulador!$E$6)/Simulador!$G$6)/Simulador!$B$11))/2,IF((($A19-Simulador!$E$6)/Simulador!$G$6)>1-Simulador!$B$11,Simulador!$B$9*(1-COS(PI()*(1-(($A19-Simulador!$E$6)/Simulador!$G$6))/Simulador!$B$11))/2,Simulador!$B$9))) -> 0 | D19: =IF(OR((($A19-Simulador!$E$7)/Simulador!$G$7)<=0,(($A19-Simulador!$E$7)/Simulador!$G$7)>=1),0,IF((($A19-Simulador!$E$7)/Simulador!$G$7)<Simulador!$B$11,Simulador!$B$9*(1-COS(PI()*(($A19-Simulador!$E$7)/Simulador!$G$7)/Simulador!$B$11))/2,IF((($A19-Simulador!$E$7)/Simulador!$G$7)>1-Simulador!$B$11,Simulador!$B$9*(1-COS(PI()*(1-(($A19-Simulador!$E$7)/Simulador!$G$7))/Simulador!$B$11))/2,Simulador!$B$9))) -> 0 | E19: =IF(OR((($A19-Simulador!$E$8)/Simulador!$G$8)<=0,(($A19-Simulador!$E$8)/Simulador!$G$8)>=1),0,IF((($A19-Simulador!$E$8)/Simulador!$G$8)<Simulador!$B$11,Simulador!$B$10*(1-COS(PI()*(($A19-Simulador!$E$8)/Simulador!$G$8)/Simulador!$B$11))/2,IF((($A19-Simulador!$E$8)/Simulador!$G$8)>1-Simulador!$B$11,Simulador!$B$10*(1-COS(PI()*(1-(($A19-Simulador!$E$8)/Simulador!$G$8))/Simulador!$B$11))/2,Simulador!$B$10))) -> 0 | F19: =IF(OR((($A19-Simulador!$E$9)/Simulador!$G$9)<=0,(($A19-Simulador!$E$9)/Simulador!$G$9)>=1),0,IF((($A19-Simulador!$E$9)/Simulador!$G$9)<Simulador!$B$11,Simulador!$B$10*(1-COS(PI()*(($A19-Simulador!$E$9)/Simulador!$G$9)/Simulador!$B$11))/2,IF((($A19-Simulador!$E$9)/Simulador!$G$9)>1-Simulador!$B$11,Simulador!$B$10*(1-COS(PI()*(1-(($A19-Simulador!$E$9)/Simulador!$G$9))/Simulador!$B$11))/2,Simulador!$B$10))) -> 0 | G19: =IF(OR((($A19-Simulador!$E$10)/Simulador!$G$10)<=0,(($A19-Simulador!$E$10)/Simulador!$G$10)>=1),0,IF((($A19-Simulador!$E$10)/Simulador!$G$10)<Simulador!$B$11,Simulador!$B$10*(1-COS(PI()*(($A19-Simulador!$E$10)/Simulador!$G$10)/Simulador!$B$11))/2,IF((($A19-Simulador!$E$10)/Simulador!$G$10)>1-Simulador!$B$11,Simulador!$B$10*(1-COS(PI()*(1-(($A19-Simulador!$E$10)/Simulador!$G$10))/Simulador!$B$11))/2,Simulador!$B$10))) -> 0
A20: =A19+Simulador!$B$14 -> 36 | B20: =IF(OR((($A20-Simulador!$E$5)/Simulador!$G$5)<=0,(($A20-Simulador!$E$5)/Simulador!$G$5)>=1),0,IF((($A20-Simulador!$E$5)/Simulador!$G$5)<Simulador!$B$11,Simulador!$B$9*(1-COS(PI()*(($A20-Simulador!$E$5)/Simulador!$G$5)/Simulador!$B$11))/2,IF((($A20-Simulador!$E$5)/Simulador!$G$5)>1-Simulador!$B$11,Simulador!$B$9*(1-COS(PI()*(1-(($A20-Simulador!$E$5)/Simulador!$G$5))/Simulador!$B$11))/2,Simulador!$B$9))) -> 0 | C20: =IF(OR((($A20-Simulador!$E$6)/Simulador!$G$6)<=0,(($A20-Simulador!$E$6)/Simulador!$G$6)>=1),0,IF((($A20-Simulador!$E$6)/Simulador!$G$6)<Simulador!$B$11,Simulador!$B$9*(1-COS(PI()*(($A20-Simulador!$E$6)/Simulador!$G$6)/Simulador!$B$11))/2,IF((($A20-Simulador!$E$6)/Simulador!$G$6)>1-Simulador!$B$11,Simulador!$B$9*(1-COS(PI()*(1-(($A20-Simulador!$E$6)/Simulador!$G$6))/Simulador!$B$11))/2,Simulador!$B$9))) -> 0 | D20: =IF(OR((($A20-Simulador!$E$7)/Simulador!$G$7)<=0,(($A20-Simulador!$E$7)/Simulador!$G$7)>=1),0,IF((($A20-Simulador!$E$7)/Simulador!$G$7)<Simulador!$B$11,Simulador!$B$9*(1-COS(PI()*(($A20-Simulador!$E$7)/Simulador!$G$7)/Simulador!$B$11))/2,IF((($A20-Simulador!$E$7)/Simulador!$G$7)>1-Simulador!$B$11,Simulador!$B$9*(1-COS(PI()*(1-(($A20-Simulador!$E$7)/Simulador!$G$7))/Simulador!$B$11))/2,Simulador!$B$9))) -> 0 | E20: =IF(OR((($A20-Simulador!$E$8)/Simulador!$G$8)<=0,(($A20-Simulador!$E$8)/Simulador!$G$8)>=1),0,IF((($A20-Simulador!$E$8)/Simulador!$G$8)<Simulador!$B$11,Simulador!$B$10*(1-COS(PI()*(($A20-Simulador!$E$8)/Simulador!$G$8)/Simulador!$B$11))/2,IF((($A20-Simulador!$E$8)/Simulador!$G$8)>1-Simulador!$B$11,Simulador!$B$10*(1-COS(PI()*(1-(($A20-Simulador!$E$8)/Simulador!$G$8))/Simulador!$B$11))/2,Simulador!$B$10))) -> 0 | F20: =IF(OR((($A20-Simulador!$E$9)/Simulador!$G$9)<=0,(($A20-Simulador!$E$9)/Simulador!$G$9)>=1),0,IF((($A20-Simulador!$E$9)/Simulador!$G$9)<Simulador!$B$11,Simulador!$B$10*(1-COS(PI()*(($A20-Simulador!$E$9)/Simulador!$G$9)/Simulador!$B$11))/2,IF((($A20-Simulador!$E$9)/Simulador!$G$9)>1-Simulador!$B$11,Simulador!$B$10*(1-COS(PI()*(1-(($A20-Simulador!$E$9)/Simulador!$G$9))/Simulador!$B$11))/2,Simulador!$B$10))) -> 0 | G20: =IF(OR((($A20-Simulador!$E$10)/Simulador!$G$10)<=0,(($A20-Simulador!$E$10)/Simulador!$G$10)>=1),0,IF((($A20-Simulador!$E$10)/Simulador!$G$10)<Simulador!$B$11,Simulador!$B$10*(1-COS(PI()*(($A20-Simulador!$E$10)/Simulador!$G$10)/Simulador!$B$11))/2,IF((($A20-Simulador!$E$10)/Simulador!$G$10)>1-Simulador!$B$11,Simulador!$B$10*(1-COS(PI()*(1-(($A20-Simulador!$E$10)/Simulador!$G$10))/Simulador!$B$11))/2,Simulador!$B$10))) -> 0
A21: =A20+Simulador!$B$14 -> 38 | B21: =IF(OR((($A21-Simulador!$E$5)/Simulador!$G$5)<=0,(($A21-Simulador!$E$5)/Simulador!$G$5)>=1),0,IF((($A21-Simulador!$E$5)/Simulador!$G$5)<Simulador!$B$11,Simulador!$B$9*(1-COS(PI()*(($A21-Simulador!$E$5)/Simulador!$G$5)/Simulador!$B$11))/2,IF((($A21-Simulador!$E$5)/Simulador!$G$5)>1-Simulador!$B$11,Simulador!$B$9*(1-COS(PI()*(1-(($A21-Simulador!$E$5)/Simulador!$G$5))/Simulador!$B$11))/2,Simulador!$B$9))) -> 0 | C21: =IF(OR((($A21-Simulador!$E$6)/Simulador!$G$6)<=0,(($A21-Simulador!$E$6)/Simulador!$G$6)>=1),0,IF((($A21-Simulador!$E$6)/Simulador!$G$6)<Simulador!$B$11,Simulador!$B$9*(1-COS(PI()*(($A21-Simulador!$E$6)/Simulador!$G$6)/Simulador!$B$11))/2,IF((($A21-Simulador!$E$6)/Simulador!$G$6)>1-Simulador!$B$11,Simulador!$B$9*(1-COS(PI()*(1-(($A21-Simulador!$E$6)/Simulador!$G$6))/Simulador!$B$11))/2,Simulador!$B$9))) -> 0 | D21: =IF(OR((($A21-Simulador!$E$7)/Simulador!$G$7)<=0,(($A21-Simulador!$E$7)/Simulador!$G$7)>=1),0,IF((($A21-Simulador!$E$7)/Simulador!$G$7)<Simulador!$B$11,Simulador!$B$9*(1-COS(PI()*(($A21-Simulador!$E$7)/Simulador!$G$7)/Simulador!$B$11))/2,IF((($A21-Simulador!$E$7)/Simulador!$G$7)>1-Simulador!$B$11,Simulador!$B$9*(1-COS(PI()*(1-(($A21-Simulador!$E$7)/Simulador!$G$7))/Simulador!$B$11))/2,Simulador!$B$9))) -> 0 | E21: =IF(OR((($A21-Simulador!$E$8)/Simulador!$G$8)<=0,(($A21-Simulador!$E$8)/Simulador!$G$8)>=1),0,IF((($A21-Simulador!$E$8)/Simulador!$G$8)<Simulador!$B$11,Simulador!$B$10*(1-COS(PI()*(($A21-Simulador!$E$8)/Simulador!$G$8)/Simulador!$B$11))/2,IF((($A21-Simulador!$E$8)/Simulador!$G$8)>1-Simulador!$B$11,Simulador!$B$10*(1-COS(PI()*(1-(($A21-Simulador!$E$8)/Simulador!$G$8))/Simulador!$B$11))/2,Simulador!$B$10))) -> 0 | F21: =IF(OR((($A21-Simulador!$E$9)/Simulador!$G$9)<=0,(($A21-Simulador!$E$9)/Simulador!$G$9)>=1),0,IF((($A21-Simulador!$E$9)/Simulador!$G$9)<Simulador!$B$11,Simulador!$B$10*(1-COS(PI()*(($A21-Simulador!$E$9)/Simulador!$G$9)/Simulador!$B$11))/2,IF((($A21-Simulador!$E$9)/Simulador!$G$9)>1-Simulador!$B$11,Simulador!$B$10*(1-COS(PI()*(1-(($A21-Simulador!$E$9)/Simulador!$G$9))/Simulador!$B$11))/2,Simulador!$B$10))) -> 0 | G21: =IF(OR((($A21-Simulador!$E$10)/Simulador!$G$10)<=0,(($A21-Simulador!$E$10)/Simulador!$G$10)>=1),0,IF((($A21-Simulador!$E$10)/Simulador!$G$10)<Simulador!$B$11,Simulador!$B$10*(1-COS(PI()*(($A21-Simulador!$E$10)/Simulador!$G$10)/Simulador!$B$11))/2,IF((($A21-Simulador!$E$10)/Simulador!$G$10)>1-Simulador!$B$11,Simulador!$B$10*(1-COS(PI()*(1-(($A21-Simulador!$E$10)/Simulador!$G$10))/Simulador!$B$11))/2,Simulador!$B$10))) -> 0
A22: =A21+Simulador!$B$14 -> 40 | B22: =IF(OR((($A22-Simulador!$E$5)/Simulador!$G$5)<=0,(($A22-Simulador!$E$5)/Simulador!$G$5)>=1),0,IF((($A22-Simulador!$E$5)/Simulador!$G$5)<Simulador!$B$11,Simulador!$B$9*(1-COS(PI()*(($A22-Simulador!$E$5)/Simulador!$G$5)/Simulador!$B$11))/2,IF((($A22-Simulador!$E$5)/Simulador!$G$5)>1-Simulador!$B$11,Simulador!$B$9*(1-COS(PI()*(1-(($A22-Simulador!$E$5)/Simulador!$G$5))/Simulador!$B$11))/2,Simulador!$B$9))) -> 0 | C22: =IF(OR((($A22-Simulador!$E$6)/Simulador!$G$6)<=0,(($A22-Simulador!$E$6)/Simulador!$G$6)>=1),0,IF((($A22-Simulador!$E$6)/Simulador!$G$6)<Simulador!$B$11,Simulador!$B$9*(1-COS(PI()*(($A22-Simulador!$E$6)/Simulador!$G$6)/Simulador!$B$11))/2,IF((($A22-Simulador!$E$6)/Simulador!$G$6)>1-Simulador!$B$11,Simulador!$B$9*(1-COS(PI()*(1-(($A22-Simulador!$E$6)/Simulador!$G$6))/Simulador!$B$11))/2,Simulador!$B$9))) -> 0 | D22: =IF(OR((($A22-Simulador!$E$7)/Simulador!$G$7)<=0,(($A22-Simulador!$E$7)/Simulador!$G$7)>=1),0,IF((($A22-Simulador!$E$7)/Simulador!$G$7)<Simulador!$B$11,Simulador!$B$9*(1-COS(PI()*(($A22-Simulador!$E$7)/Simulador!$G$7)/Simulador!$B$11))/2,IF((($A22-Simulador!$E$7)/Simulador!$G$7)>1-Simulador!$B$11,Simulador!$B$9*(1-COS(PI()*(1-(($A22-Simulador!$E$7)/Simulador!$G$7))/Simulador!$B$11))/2,Simulador!$B$9))) -> 0 | E22: =IF(OR((($A22-Simulador!$E$8)/Simulador!$G$8)<=0,(($A22-Simulador!$E$8)/Simulador!$G$8)>=1),0,IF((($A22-Simulador!$E$8)/Simulador!$G$8)<Simulador!$B$11,Simulador!$B$10*(1-COS(PI()*(($A22-Simulador!$E$8)/Simulador!$G$8)/Simulador!$B$11))/2,IF((($A22-Simulador!$E$8)/Simulador!$G$8)>1-Simulador!$B$11,Simulador!$B$10*(1-COS(PI()*(1-(($A22-Simulador!$E$8)/Simulador!$G$8))/Simulador!$B$11))/2,Simulador!$B$10))) -> 0 | F22: =IF(OR((($A22-Simulador!$E$9)/Simulador!$G$9)<=0,(($A22-Simulador!$E$9)/Simulador!$G$9)>=1),0,IF((($A22-Simulador!$E$9)/Simulador!$G$9)<Simulador!$B$11,Simulador!$B$10*(1-COS(PI()*(($A22-Simulador!$E$9)/Simulador!$G$9)/Simulador!$B$11))/2,IF((($A22-Simulador!$E$9)/Simulador!$G$9)>1-Simulador!$B$11,Simulador!$B$10*(1-COS(PI()*(1-(($A22-Simulador!$E$9)/Simulador!$G$9))/Simulador!$B$11))/2,Simulador!$B$10))) -> 0 | G22: =IF(OR((($A22-Simulador!$E$10)/Simulador!$G$10)<=0,(($A22-Simulador!$E$10)/Simulador!$G$10)>=1),0,IF((($A22-Simulador!$E$10)/Simulador!$G$10)<Simulador!$B$11,Simulador!$B$10*(1-COS(PI()*(($A22-Simulador!$E$10)/Simulador!$G$10)/Simulador!$B$11))/2,IF((($A22-Simulador!$E$10)/Simulador!$G$10)>1-Simulador!$B$11,Simulador!$B$10*(1-COS(PI()*(1-(($A22-Simulador!$E$10)/Simulador!$G$10))/Simulador!$B$11))/2,Simulador!$B$10))) -> 0
