Workbook

Sheet Simulador
A1: Simulador del alzado de válvulas y del cruce — Sistema de distribución
A2: Sistemas del Funcionamiento del Motor (MA.02.06) · Unidad 3 · Edite solo las celdas amarillas (texto azul); todo lo demás se recalcula.
A4: Datos de entrada | B4: Valor | D4: Perfil | E4: Apertura (°) | F4: Cierre (°) | G4: Duración (°)
A5: Adelanto de apertura de escape AAE (° cigüeñal) | B5: 45 | D5: Escape adelantado | E5: =180-$B$5-$B$12 | F5: =360+$B$6-$B$12 | G5: =F5-E5
A6: Retraso de cierre de escape RCE (°) | B6: 20 | D6: Escape base | E6: =180-$B$5 | F6: =360+$B$6 | G6: =F6-E6
A7: Adelanto de apertura de admisión AAA (°) | B7: 20 | D7: Escape retrasado | E7: =180-$B$5+$B$12 | F7: =360+$B$6+$B$12 | G7: =F7-E7
A8: Retraso de cierre de admisión RCA (°) | B8: 50 | D8: Admisión adelantada | E8: =360-$B$7-$B$13 | F8: =540+$B$8-$B$13 | G8: =F8-E8
A9: Alzada máxima de escape (mm) | B9: 9.5 | D9: Admisión base | E9: =360-$B$7 | F9: =540+$B$8 | G9: =F9-E9
A10: Alzada máxima de admisión (mm) | B10: 8.5 | D10: Admisión retrasada | E10: =360-$B$7+$B$13 | F10: =540+$B$8+$B$13 | G10: =F10-E10
A11: Fracción de rampa del perfil (0,10 – 0,50) | B11: 0.42
A12: Variación de fase del escape (± °) | B12: 15 | D12: Resultado | E12: Grados | F12: Cómo se obtiene
A13: Variación de fase de la admisión (± °) | B13: 15 | D13: Cruce base (°) | E13: =MAX(0,F6-E9) | F13: RCE + AAA
A14: Paso de cálculo (°) | B14: 2 | D14: Cruce máximo (°) | E14: =MAX(0,F7-E8) | F14: Escape retrasado + admisión adelantada
D15: Cruce mínimo (°) | E15: =MAX(0,F5-E10) | F15: Escape adelantado + admisión retrasada
A16: Comprobación | D16: Duración de escape (°) | E16: =G6 | F16: AAE + 180 + RCE
A17: =IF(AND($B$11>=0.1,$B$11<=0.5),"Fracción de rampa válida","Revise: la fracción de rampa debe estar entre 0,10 y 0,50") | D17: Duración de admisión (°) | E17: =G9 | F17: AAA + 180 + RCA
A18: =IF(E15>0,"Hay cruce en todas las fases","Con la admisión retrasada y el escape adelantado desaparece el cruce") | D18: Duración de admisión en el árbol de levas (°) | E18: =G9/2 | F18: El árbol gira a la mitad que el cigüeñal
A20: Referencias angulares: PMS de inicio de admisión/cruce = 360°; PMI = 180° y 540°; PMS de combustión = 0° y 720°.
A21: Perfil de alzada: flancos en coseno (subida y bajada suaves) con meseta central, modelo didáctico del perfil real de la leva.

Sheet Diagrama circular
A1: Diagrama circular de la distribución y cruce de válvulas
A2: Usa los ángulos base de la hoja Simulador (sin variador). Edite solo la celda amarilla de esta hoja.
A4: Dato | B4: Valor | D4: Fase del ciclo real | E4: Duración (°) | F4: Desde → hasta
A5: AAE (de la hoja Simulador) | B5: =Simulador!B5 | D5: Admisión | E5: =B7+180+B8 | F5: ="AAA "&B7&"° antes PMS → RCA "&B8&"° después PMI"
A6: RCE | B6: =Simulador!B6 | D6: Compresión | E6: =180-B8-B9 | F6: ="RCA → chispa "&B9&"° antes PMS"
A7: AAA | B7: =Simulador!B7 | D7: Combustión (explosión) | E7: =B9 | F7: ="Chispa → PMS"
A8: RCA | B8: =Simulador!B8 | D8: Trabajo útil (expansión) | E8: =180-B5 | F8: ="PMS → AAE "&B5&"° antes PMI"
A9: Avance de encendido AE (° antes del PMS) | B9: 10 | D9: Escape | E9: =B5+180+B6 | F9: ="AAE → RCE "&B6&"° después PMS"
D10: Cruce de válvulas | E10: =B7+B6 | F10: ="AAA + RCE alrededor del PMS"
D11: Total del ciclo: suma de fases − cruce (= 720°) | E11: =SUM(E5:E9)-E10 | F11: ="El cruce se cuenta en admisión y en escape"
D13: =IF(E11=720,"El ciclo suma 720°: diagrama coherente","Revise los ángulos: el ciclo no suma 720°")
F37: En el ciclo teórico las válvulas abren y cierran justo en PMS y PMI; en el real se adelantan las aperturas y se retrasan los cierres, y aparece el cruce alrededor del PMS.

Sheet Salto de dientes
A1: Simulador · Salto de dientes de la correa o cadena de distribución
A2: Sistemas del Funcionamiento del Motor (MA.02.06) · Unidad 3 · Edite solo las celdas amarillas (texto azul); todo lo demás se recalcula.
A4: Datos de entrada | B4: Valor
A5: Dientes del piñón del árbol de levas | B5: 42
A6: Dientes desfasados (+ árbol retrasado, − adelantado) | B6: 1
A7: Carrera S (mm) | B7: 70
A8: Longitud de la biela L (mm) | B8: 130
A9: Relación de compresión geométrica Rc | B9: 9.5
A11: Desfase por diente (° de cigüeñal) | B11: =720/B5 | C11: Un giro del árbol = 720° de cigüeñal
A12: Desfase total δ (° de cigüeñal) | B12: =B6*B11
A14: Cota de distribución | B14: Base | C14: Desfasado | D14: Qué significa
A15: AAA (° antes del PMS) | B15: =Simulador!B7 | C15: =B15-$B$12 | D15: Negativo = la admisión abre después del PMS
A16: RCA (° después del PMI) | B16: =Simulador!B8 | C16: =B16+$B$12 | D16: Más RCA = el cilindro empieza a comprimir más tarde
A17: AAE (° antes del PMI) | B17: =Simulador!B5 | C17: =B17-$B$12 | D17: Menos AAE = se aprovecha más la expansión pero cuesta más vaciar
A18: RCE (° después del PMS) | B18: =Simulador!B6 | C18: =B18+$B$12
A19: Cruce de válvulas (°) | B19: =B15+B18 | C19: =C15+C18 | D19: Con un solo árbol el cruce no cambia: se desplaza
A20: Centro del cruce (° respecto al PMS, + después) | B20: =(B18-B15)/2 | C20: =(C18-C15)/2 | D20: El cruce deja de estar centrado en el PMS
A21: Compresión efectiva (Rc desde el cierre de admisión) | B21: =1+($B$9-1)*(($B$7/2)*(1-COS(RADIANS(180+B16)))+$B$8*(1-SQRT(1-($B$7/2/$B$8)^2*SIN(RADIANS(180+B16))^2)))/$B$7 | C21: =1+($B$9-1)*(($B$7/2)*(1-COS(RADIANS(180+C16)))+$B$8*(1-SQRT(1-($B$7/2/$B$8)^2*SIN(RADIANS(180+C16))^2)))/$B$7 | D21: Rc_ef = 1 + (Rc − 1)·x(180° + RCA)/S
A23: =IF(C21<B21-0.3,"El retraso del árbol reduce la compresión efectiva: arranque difícil y pérdida de par a bajo régimen",IF(C21>B21+0.3,"El adelanto del árbol aumenta la compresión efectiva: más par abajo, menos llenado arriba","Desfase pequeño: efecto leve en la compresión"))
A24: =IF(B6<>0,"En motores de interferencia, un desfase puede hacer chocar válvulas y pistones: girar siempre a mano dos vueltas antes de arrancar","Distribución en fase")

Sheet Levas superpuestas
A1: Simulador · Levas de admisión y escape superpuestas
A2: Usa los ángulos base y las alzadas de la hoja Simulador. Edite solo la celda amarilla de esta hoja.
A4: Dato | B4: Valor
A5: Radio del círculo base de la leva (mm) | B5: 18
A7: Resultados | B7: Valor | C7: Cómo se obtiene
A8: Duración de escape (° cigüeñal) | B8: =Simulador!G6 | C8: AAE + 180 + RCE
A9: Duración de admisión (° cigüeñal) | B9: =Simulador!G9 | C9: AAA + 180 + RCA
A10: Centro de la leva de escape ECL (° antes del PMS) | B10: =B8/2-Simulador!B6 | C10: Duración/2 − RCE
A11: Centro de la leva de admisión ICL (° después del PMS) | B11: =B9/2-Simulador!B7 | C11: Duración/2 − AAA
A12: Separación entre levas LSA (° de árbol de levas) | B12: =(B10+B11)/2 | C12: (ECL + ICL) / 2
A13: Cruce de válvulas (° cigüeñal) | B13: =Simulador!B7+Simulador!B6 | C13: AAA + RCE
A14: Ángulo de la nariz de escape (° de árbol, desde el PMS) | B14: =-B10/2
A15: Ángulo de la nariz de admisión (° de árbol) | B15: =B11/2
A17: Los ángulos de la leva son la mitad de los del cigüeñal porque el árbol gira a la mitad de velocidad.

Sheet Pastillas de reglaje
A1: Simulador · Reglaje de holgura de válvulas con pastillas calibradas
A2: Sistemas del Funcionamiento del Motor (MA.02.06) · Unidad 3 · Edite solo las celdas amarillas (texto azul); todo lo demás se recalcula.
A4: Especificación | C4: Nominal (mm) | D4: Mínima (mm) | E4: Máxima (mm)
A5: Admisión | C5: 0.25 | D5: 0.2 | E5: 0.3
A6: Escape | C6: 0.3 | D6: 0.25 | E6: 0.35
A7: Paso entre pastillas disponibles (mm) | E7: 0.05
A9: Cilindro | B9: Válvula | C9: Holgura medida (mm) | D9: Pastilla actual (mm) | E9: ¿En tolerancia? | F9: Pastilla calculada (mm) | G9: Pastilla a montar (mm) | H9: Holgura resultante (mm)
A10: 1 | B10: ADM | C10: 0.22 | D10: 2.6 | E10: =IF(AND(C10>=$D$5,C10<=$E$5),"Sí","No: cambiar") | F10: =D10+C10-$C$5 | G10: =IF(E10="Sí",D10,ROUND(F10/$E$7,0)*$E$7) | H10: =C10+D10-G10
A11: 1 | B11: ESC | C11: 0.31 | D11: 2.55 | E11: =IF(AND(C11>=$D$6,C11<=$E$6),"Sí","No: cambiar") | F11: =D11+C11-$C$6 | G11: =IF(E11="Sí",D11,ROUND(F11/$E$7,0)*$E$7) | H11: =C11+D11-G11
A12: 2 | B12: ADM | C12: 0.18 | D12: 2.65 | E12: =IF(AND(C12>=$D$5,C12<=$E$5),"Sí","No: cambiar") | F12: =D12+C12-$C$5 | G12: =IF(E12="Sí",D12,ROUND(F12/$E$7,0)*$E$7) | H12: =C12+D12-G12
A13: 2 | B13: ESC | C13: 0.27 | D13: 2.5 | E13: =IF(AND(C13>=$D$6,C13<=$E$6),"Sí","No: cambiar") | F13: =D13+C13-$C$6 | G13: =IF(E13="Sí",D13,ROUND(F13/$E$7,0)*$E$7) | H13: =C13+D13-G13
A14: 3 | B14: ADM | C14: 0.26 | D14: 2.6 | E14: =IF(AND(C14>=$D$5,C14<=$E$5),"Sí","No: cambiar") | F14: =D14+C14-$C$5 | G14: =IF(E14="Sí",D14,ROUND(F14/$E$7,0)*$E$7) | H14: =C14+D14-G14
A15: 3 | B15: ESC | C15: 0.4 | D15: 2.45 | E15: =IF(AND(C15>=$D$6,C15<=$E$6),"Sí","No: cambiar") | F15: =D15+C15-$C$6 | G15: =IF(E15="Sí",D15,ROUND(F15/$E$7,0)*$E$7) | H15: =C15+D15-G15
A16: 4 | B16: ADM | C16: 0.24 | D16: 2.7 | E16: =IF(AND(C16>=$D$5,C16<=$E$5),"Sí","No: cambiar") | F16: =D16+C16-$C$5 | G16: =IF(E16="Sí",D16,ROUND(F16/$E$7,0)*$E$7) | H16: =C16+D16-G16
A17: 4 | B17: ESC | C17: 0.33 | D17: 2.55 | E17: =IF(AND(C17>=$D$6,C17<=$E$6),"Sí","No: cambiar") | F17: =D17+C17-$C$6 | G17: =IF(E17="Sí",D17,ROUND(F17/$E$7,0)*$E$7) | H17: =C17+D17-G17
A19: Pastilla nueva = pastilla actual + (holgura medida − holgura nominal), redondeada al espesor disponible. Mida con el motor frío y la leva en su círculo base.
A20: Ejemplo: pastilla 2,65 mm, holgura medida 0,18 mm, nominal 0,25 mm → 2,65 + 0,18 − 0,25 = 2,58 → se monta 2,60 mm y queda una holgura de 0,23 mm.
A22: =COUNTIF(E10:E17,"No: cambiar")&" de 8 válvulas necesitan cambio de pastilla"

Sheet Apriete de culata
A1: Simulador · Secuencia y control del apriete de la culata
A2: Sistemas del Funcionamiento del Motor (MA.02.06) · Unidad 3 · Edite solo las celdas amarillas (texto azul); todo lo demás se recalcula.
A4: Datos de entrada | B4: Valor
A5: Número de tornillos de la culata | B5: 10
A6: Etapa 1: par (N·m) | B6: 30
A7: Etapa 2: par (N·m) | B7: 60
A8: Etapa 3: ángulo (°) | B8: 90
A9: Etapa 4: ángulo (°) (0 si no aplica) | B9: 90
A10: Longitud nominal del tornillo (mm) | B10: 120
A11: Alargamiento máximo admisible (mm) | B11: 0.5
A12: Tolerancia del par (± %) | B12: 5
A14: Orden de APRIETE (vista superior)
A15: Lado de admisión | B15: =IF(N(INDEX('Datos apriete'!B$3:B$8,MATCH($B$5,'Datos apriete'!$A$3:$A$8,0)))=0,"",INDEX('Datos apriete'!B$3:B$8,MATCH($B$5,'Datos apriete'!$A$3:$A$8,0))) | C15: =IF(N(INDEX('Datos apriete'!C$3:C$8,MATCH($B$5,'Datos apriete'!$A$3:$A$8,0)))=0,"",INDEX('Datos apriete'!C$3:C$8,MATCH($B$5,'Datos apriete'!$A$3:$A$8,0))) | D15: =IF(N(INDEX('Datos apriete'!D$3:D$8,MATCH($B$5,'Datos apriete'!$A$3:$A$8,0)))=0,"",INDEX('Datos apriete'!D$3:D$8,MATCH($B$5,'Datos apriete'!$A$3:$A$8,0))) | E15: =IF(N(INDEX('Datos apriete'!E$3:E$8,MATCH($B$5,'Datos apriete'!$A$3:$A$8,0)))=0,"",INDEX('Datos apriete'!E$3:E$8,MATCH($B$5,'Datos apriete'!$A$3:$A$8,0))) | F15: =IF(N(INDEX('Datos apriete'!F$3:F$8,MATCH($B$5,'Datos apriete'!$A$3:$A$8,0)))=0,"",INDEX('Datos apriete'!F$3:F$8,MATCH($B$5,'Datos apriete'!$A$3:$A$8,0))) | G15: =IF(N(INDEX('Datos apriete'!G$3:G$8,MATCH($B$5,'Datos apriete'!$A$3:$A$8,0)))=0,"",INDEX('Datos apriete'!G$3:G$8,MATCH($B$5,'Datos apriete'!$A$3:$A$8,0))) | H15: =IF(N(INDEX('Datos apriete'!H$3:H$8,MATCH($B$5,'Datos apriete'!$A$3:$A$8,0)))=0,"",INDEX('Datos apriete'!H$3:H$8,MATCH($B$5,'Datos apriete'!$A$3:$A$8,0))) | I15: =IF(N(INDEX('Datos apriete'!I$3:I$8,MATCH($B$5,'Datos apriete'!$A$3:$A$8,0)))=0,"",INDEX('Datos apriete'!I$3:I$8,MATCH($B$5,'Datos apriete'!$A$3:$A$8,0))) | J15: =IF(N(INDEX('Datos apriete'!J$3:J$8,MATCH($B$5,'Datos apriete'!$A$3:$A$8,0)))=0,"",INDEX('Datos apriete'!J$3:J$8,MATCH($B$5,'Datos apriete'!$A$3:$A$8,0)))
A16: Lado de escape | B16: =IF(N(INDEX('Datos apriete'!B$12:B$17,MATCH($B$5,'Datos apriete'!$A$12:$A$17,0)))=0,"",INDEX('Datos apriete'!B$12:B$17,MATCH($B$5,'Datos apriete'!$A$12:$A$17,0))) | C16: =IF(N(INDEX('Datos apriete'!C$12:C$17,MATCH($B$5,'Datos apriete'!$A$12:$A$17,0)))=0,"",INDEX('Datos apriete'!C$12:C$17,MATCH($B$5,'Datos apriete'!$A$12:$A$17,0))) | D16: =IF(N(INDEX('Datos apriete'!D$12:D$17,MATCH($B$5,'Datos apriete'!$A$12:$A$17,0)))=0,"",INDEX('Datos apriete'!D$12:D$17,MATCH($B$5,'Datos apriete'!$A$12:$A$17,0))) | E16: =IF(N(INDEX('Datos apriete'!E$12:E$17,MATCH($B$5,'Datos apriete'!$A$12:$A$17,0)))=0,"",INDEX('Datos apriete'!E$12:E$17,MATCH($B$5,'Datos apriete'!$A$12:$A$17,0))) | F16: =IF(N(INDEX('Datos apriete'!F$12:F$17,MATCH($B$5,'Datos apriete'!$A$12:$A$17,0)))=0,"",INDEX('Datos apriete'!F$12:F$17,MATCH($B$5,'Datos apriete'!$A$12:$A$17,0))) | G16: =IF(N(INDEX('Datos apriete'!G$12:G$17,MATCH($B$5,'Datos apriete'!$A$12:$A$17,0)))=0,"",INDEX('Datos apriete'!G$12:G$17,MATCH($B$5,'Datos apriete'!$A$12:$A$17,0))) | H16: =IF(N(INDEX('Datos apriete'!H$12:H$17,MATCH($B$5,'Datos apriete'!$A$12:$A$17,0)))=0,"",INDEX('Datos apriete'!H$12:H$17,MATCH($B$5,'Datos apriete'!$A$12:$A$17,0))) | I16: =IF(N(INDEX('Datos apriete'!I$12:I$17,MATCH($B$5,'Datos apriete'!$A$12:$A$17,0)))=0,"",INDEX('Datos apriete'!I$12:I$17,MATCH($B$5,'Datos apriete'!$A$12:$A$17,0))) | J16: =IF(N(INDEX('Datos apriete'!J$12:J$17,MATCH($B$5,'Datos apriete'!$A$12:$A$17,0)))=0,"",INDEX('Datos apriete'!J$12:J$17,MATCH($B$5,'Datos apriete'!$A$12:$A$17,0)))
A18: Orden de AFLOJADO (inverso)
A19: Lado de admisión | B19: =IF(IF(N(INDEX('Datos apriete'!B$3:B$8,MATCH($B$5,'Datos apriete'!$A$3:$A$8,0)))=0,"",INDEX('Datos apriete'!B$3:B$8,MATCH($B$5,'Datos apriete'!$A$3:$A$8,0)))="","",$B$5+1-IF(N(INDEX('Datos apriete'!B$3:B$8,MATCH($B$5,'Datos apriete'!$A$3:$A$8,0)))=0,"",INDEX('Datos apriete'!B$3:B$8,MATCH($B$5,'Datos apriete'!$A$3:$A$8,0)))) | C19: =IF(IF(N(INDEX('Datos apriete'!C$3:C$8,MATCH($B$5,'Datos apriete'!$A$3:$A$8,0)))=0,"",INDEX('Datos apriete'!C$3:C$8,MATCH($B$5,'Datos apriete'!$A$3:$A$8,0)))="","",$B$5+1-IF(N(INDEX('Datos apriete'!C$3:C$8,MATCH($B$5,'Datos apriete'!$A$3:$A$8,0)))=0,"",INDEX('Datos apriete'!C$3:C$8,MATCH($B$5,'Datos apriete'!$A$3:$A$8,0)))) | D19: =IF(IF(N(INDEX('Datos apriete'!D$3:D$8,MATCH($B$5,'Datos apriete'!$A$3:$A$8,0)))=0,"",INDEX('Datos apriete'!D$3:D$8,MATCH($B$5,'Datos apriete'!$A$3:$A$8,0)))="","",$B$5+1-IF(N(INDEX('Datos apriete'!D$3:D$8,MATCH($B$5,'Datos apriete'!$A$3:$A$8,0)))=0,"",INDEX('Datos apriete'!D$3:D$8,MATCH($B$5,'Datos apriete'!$A$3:$A$8,0)))) | E19: =IF(IF(N(INDEX('Datos apriete'!E$3:E$8,MATCH($B$5,'Datos apriete'!$A$3:$A$8,0)))=0,"",INDEX('Datos apriete'!E$3:E$8,MATCH($B$5,'Datos apriete'!$A$3:$A$8,0)))="","",$B$5+1-IF(N(INDEX('Datos apriete'!E$3:E$8,MATCH($B$5,'Datos apriete'!$A$3:$A$8,0)))=0,"",INDEX('Datos apriete'!E$3:E$8,MATCH($B$5,'Datos apriete'!$A$3:$A$8,0)))) | F19: =IF(IF(N(INDEX('Datos apriete'!F$3:F$8,MATCH($B$5,'Datos apriete'!$A$3:$A$8,0)))=0,"",INDEX('Datos apriete'!F$3:F$8,MATCH($B$5,'Datos apriete'!$A$3:$A$8,0)))="","",$B$5+1-IF(N(INDEX('Datos apriete'!F$3:F$8,MATCH($B$5,'Datos apriete'!$A$3:$A$8,0)))=0,"",INDEX('Datos apriete'!F$3:F$8,MATCH($B$5,'Datos apriete'!$A$3:$A$8,0)))) | G19: =IF(IF(N(INDEX('Datos apriete'!G$3:G$8,MATCH($B$5,'Datos apriete'!$A$3:$A$8,0)))=0,"",INDEX('Datos apriete'!G$3:G$8,MATCH($B$5,'Datos apriete'!$A$3:$A$8,0)))="","",$B$5+1-IF(N(INDEX('Datos apriete'!G$3:G$8,MATCH($B$5,'Datos apriete'!$A$3:$A$8,0)))=0,"",INDEX('Datos apriete'!G$3:G$8,MATCH($B$5,'Datos apriete'!$A$3:$A$8,0)))) | H19: =IF(IF(N(INDEX('Datos apriete'!H$3:H$8,MATCH($B$5,'Datos apriete'!$A$3:$A$8,0)))=0,"",INDEX('Datos apriete'!H$3:H$8,MATCH($B$5,'Datos apriete'!$A$3:$A$8,0)))="","",$B$5+1-IF(N(INDEX('Datos apriete'!H$3:H$8,MATCH($B$5,'Datos apriete'!$A$3:$A$8,0)))=0,"",INDEX('Datos apriete'!H$3:H$8,MATCH($B$5,'Datos apriete'!$A$3:$A$8,0)))) | I19: =IF(IF(N(INDEX('Datos apriete'!I$3:I$8,MATCH($B$5,'Datos apriete'!$A$3:$A$8,0)))=0,"",INDEX('Datos apriete'!I$3:I$8,MATCH($B$5,'Datos apriete'!$A$3:$A$8,0)))="","",$B$5+1-IF(N(INDEX('Datos apriete'!I$3:I$8,MATCH($B$5,'Datos apriete'!$A$3:$A$8,0)))=0,"",INDEX('Datos apriete'!I$3:I$8,MATCH($B$5,'Datos apriete'!$A$3:$A$8,0)))) | J19: =IF(IF(N(INDEX('Datos apriete'!J$3:J$8,MATCH($B$5,'Datos apriete'!$A$3:$A$8,0)))=0,"",INDEX('Datos apriete'!J$3:J$8,MATCH($B$5,'Datos apriete'!$A$3:$A$8,0)))="","",$B$5+1-IF(N(INDEX('Datos apriete'!J$3:J$8,MATCH($B$5,'Datos apriete'!$A$3:$A$8,0)))=0,"",INDEX('Datos apriete'!J$3:J$8,MATCH($B$5,'Datos apriete'!$A$3:$A$8,0))))
A20: Lado de escape | B20: =IF(IF(N(INDEX('Datos apriete'!B$12:B$17,MATCH($B$5,'Datos apriete'!$A$12:$A$17,0)))=0,"",INDEX('Datos apriete'!B$12:B$17,MATCH($B$5,'Datos apriete'!$A$12:$A$17,0)))="","",$B$5+1-IF(N(INDEX('Datos apriete'!B$12:B$17,MATCH($B$5,'Datos apriete'!$A$12:$A$17,0)))=0,"",INDEX('Datos apriete'!B$12:B$17,MATCH($B$5,'Datos apriete'!$A$12:$A$17,0)))) | C20: =IF(IF(N(INDEX('Datos apriete'!C$12:C$17,MATCH($B$5,'Datos apriete'!$A$12:$A$17,0)))=0,"",INDEX('Datos apriete'!C$12:C$17,MATCH($B$5,'Datos apriete'!$A$12:$A$17,0)))="","",$B$5+1-IF(N(INDEX('Datos apriete'!C$12:C$17,MATCH($B$5,'Datos apriete'!$A$12:$A$17,0)))=0,"",INDEX('Datos apriete'!C$12:C$17,MATCH($B$5,'Datos apriete'!$A$12:$A$17,0)))) | D20: =IF(IF(N(INDEX('Datos apriete'!D$12:D$17,MATCH($B$5,'Datos apriete'!$A$12:$A$17,0)))=0,"",INDEX('Datos apriete'!D$12:D$17,MATCH($B$5,'Datos apriete'!$A$12:$A$17,0)))="","",$B$5+1-IF(N(INDEX('Datos apriete'!D$12:D$17,MATCH($B$5,'Datos apriete'!$A$12:$A$17,0)))=0,"",INDEX('Datos apriete'!D$12:D$17,MATCH($B$5,'Datos apriete'!$A$12:$A$17,0)))) | E20: =IF(IF(N(INDEX('Datos apriete'!E$12:E$17,MATCH($B$5,'Datos apriete'!$A$12:$A$17,0)))=0,"",INDEX('Datos apriete'!E$12:E$17,MATCH($B$5,'Datos apriete'!$A$12:$A$17,0)))="","",$B$5+1-IF(N(INDEX('Datos apriete'!E$12:E$17,MATCH($B$5,'Datos apriete'!$A$12:$A$17,0)))=0,"",INDEX('Datos apriete'!E$12:E$17,MATCH($B$5,'Datos apriete'!$A$12:$A$17,0)))) | F20: =IF(IF(N(INDEX('Datos apriete'!F$12:F$17,MATCH($B$5,'Datos apriete'!$A$12:$A$17,0)))=0,"",INDEX('Datos apriete'!F$12:F$17,MATCH($B$5,'Datos apriete'!$A$12:$A$17,0)))="","",$B$5+1-IF(N(INDEX('Datos apriete'!F$12:F$17,MATCH($B$5,'Datos apriete'!$A$12:$A$17,0)))=0,"",INDEX('Datos apriete'!F$12:F$17,MATCH($B$5,'Datos apriete'!$A$12:$A$17,0)))) | G20: =IF(IF(N(INDEX('Datos apriete'!G$12:G$17,MATCH($B$5,'Datos apriete'!$A$12:$A$17,0)))=0,"",INDEX('Datos apriete'!G$12:G$17,MATCH($B$5,'Datos apriete'!$A$12:$A$17,0)))="","",$B$5+1-IF(N(INDEX('Datos apriete'!G$12:G$17,MATCH($B$5,'Datos apriete'!$A$12:$A$17,0)))=0,"",INDEX('Datos apriete'!G$12:G$17,MATCH($B$5,'Datos apriete'!$A$12:$A$17,0)))) | H20: =IF(IF(N(INDEX('Datos apriete'!H$12:H$17,MATCH($B$5,'Datos apriete'!$A$12:$A$17,0)))=0,"",INDEX('Datos apriete'!H$12:H$17,MATCH($B$5,'Datos apriete'!$A$12:$A$17,0)))="","",$B$5+1-IF(N(INDEX('Datos apriete'!H$12:H$17,MATCH($B$5,'Datos apriete'!$A$12:$A$17,0)))=0,"",INDEX('Datos apriete'!H$12:H$17,MATCH($B$5,'Datos apriete'!$A$12:$A$17,0)))) | I20: =IF(IF(N(INDEX('Datos apriete'!I$12:I$17,MATCH($B$5,'Datos apriete'!$A$12:$A$17,0)))=0,"",INDEX('Datos apriete'!I$12:I$17,MATCH($B$5,'Datos apriete'!$A$12:$A$17,0)))="","",$B$5+1-IF(N(INDEX('Datos apriete'!I$12:I$17,MATCH($B$5,'Datos apriete'!$A$12:$A$17,0)))=0,"",INDEX('Datos apriete'!I$12:I$17,MATCH($B$5,'Datos apriete'!$A$12:$A$17,0)))) | J20: =IF(IF(N(INDEX('Datos apriete'!J$12:J$17,MATCH($B$5,'Datos apriete'!$A$12:$A$17,0)))=0,"",INDEX('Datos apriete'!J$12:J$17,MATCH($B$5,'Datos apriete'!$A$12:$A$17,0)))="","",$B$5+1-IF(N(INDEX('Datos apriete'!J$12:J$17,MATCH($B$5,'Datos apriete'!$A$12:$A$17,0)))=0,"",INDEX('Datos apriete'!J$12:J$17,MATCH($B$5,'Datos apriete'!$A$12:$A$17,0))))
A21: Secuencia genérica en espiral desde el centro hacia los extremos y en cruz; prevalece siempre la secuencia del manual del motor.
A23: Paso | B23: Fila | C23: Columna | D23: Etapa 1 (N·m) | E23: Etapa 2 (N·m) | F23: Etapa 3 (°) | G23: Etapa 4 (°) | H23: Long. medida (mm) | I23: Estado del apriete | J23: Tornillo
A24: =IF(1>$B$5,"",1) | B24: =IF(A24="","",IF(COUNTIF($B$15:$J$15,A24)>0,"Superior","Inferior")) | C24: =IF(A24="","",IFERROR(MATCH(A24,$B$15:$J$15,0),MATCH(A24,$B$16:$J$16,0))) | D24: 30 | E24: 60 | F24: 90 | G24: 90 | H24: 120.2 | I24: =IF(A24="","",IF(COUNT(D24:G24)<IF($B$9>0,4,3),"Pendiente",IF(AND(ABS(D24-$B$6)<=$B$6*$B$12/100,ABS(E24-$B$7)<=$B$7*$B$12/100,ABS(F24-$B$8)<=3,OR($B$9=0,ABS(G24-$B$9)<=3)),"Correcto","Revisar"))) | J24: =IF(OR(A24="",H24=""),"",IF(H24>$B$10+$B$11,"Sustituir (alargado)","Reutilizable"))
A25: =IF(2>$B$5,"",2) | B25: =IF(A25="","",IF(COUNTIF($B$15:$J$15,A25)>0,"Superior","Inferior")) | C25: =IF(A25="","",IFERROR(MATCH(A25,$B$15:$J$15,0),MATCH(A25,$B$16:$J$16,0))) | D25: 31 | E25: 59 | F25: 90 | G25: 90 | H25: 120.6 | I25: =IF(A25="","",IF(COUNT(D25:G25)<IF($B$9>0,4,3),"Pendiente",IF(AND(ABS(D25-$B$6)<=$B$6*$B$12/100,ABS(E25-$B$7)<=$B$7*$B$12/100,ABS(F25-$B$8)<=3,OR($B$9=0,ABS(G25-$B$9)<=3)),"Correcto","Revisar"))) | J25: =IF(OR(A25="",H25=""),"",IF(H25>$B$10+$B$11,"Sustituir (alargado)","Reutilizable"))
A26: =IF(3>$B$5,"",3) | B26: =IF(A26="","",IF(COUNTIF($B$15:$J$15,A26)>0,"Superior","Inferior")) | C26: =IF(A26="","",IFERROR(MATCH(A26,$B$15:$J$15,0),MATCH(A26,$B$16:$J$16,0))) | I26: =IF(A26="","",IF(COUNT(D26:G26)<IF($B$9>0,4,3),"Pendiente",IF(AND(ABS(D26-$B$6)<=$B$6*$B$12/100,ABS(E26-$B$7)<=$B$7*$B$12/100,ABS(F26-$B$8)<=3,OR($B$9=0,ABS(G26-$B$9)<=3)),"Correcto","Revisar"))) | J26: =IF(OR(A26="",H26=""),"",IF(H26>$B$10+$B$11,"Sustituir (alargado)","Reutilizable"))
A27: =IF(4>$B$5,"",4) | B27: =IF(A27="","",IF(COUNTIF($B$15:$J$15,A27)>0,"Superior","Inferior")) | C27: =IF(A27="","",IFERROR(MATCH(A27,$B$15:$J$15,0),MATCH(A27,$B$16:$J$16,0))) | I27: =IF(A27="","",IF(COUNT(D27:G27)<IF($B$9>0,4,3),"Pendiente",IF(AND(ABS(D27-$B$6)<=$B$6*$B$12/100,ABS(E27-$B$7)<=$B$7*$B$12/100,ABS(F27-$B$8)<=3,OR($B$9=0,ABS(G27-$B$9)<=3)),"Correcto","Revisar"))) | J27: =IF(OR(A27="",H27=""),"",IF(H27>$B$10+$B$11,"Sustituir (alargado)","Reutilizable"))
A28: =IF(5>$B$5,"",5) | B28: =IF(A28="","",IF(COUNTIF($B$15:$J$15,A28)>0,"Superior","Inferior")) | C28: =IF(A28="","",IFERROR(MATCH(A28,$B$15:$J$15,0),MATCH(A28,$B$16:$J$16,0))) | I28: =IF(A28="","",IF(COUNT(D28:G28)<IF($B$9>0,4,3),"Pendiente",IF(AND(ABS(D28-$B$6)<=$B$6*$B$12/100,ABS(E28-$B$7)<=$B$7*$B$12/100,ABS(F28-$B$8)<=3,OR($B$9=0,ABS(G28-$B$9)<=3)),"Correcto","Revisar"))) | J28: =IF(OR(A28="",H28=""),"",IF(H28>$B$10+$B$11,"Sustituir (alargado)","Reutilizable"))
A29: =IF(6>$B$5,"",6) | B29: =IF(A29="","",IF(COUNTIF($B$15:$J$15,A29)>0,"Superior","Inferior")) | C29: =IF(A29="","",IFERROR(MATCH(A29,$B$15:$J$15,0),MATCH(A29,$B$16:$J$16,0))) | I29: =IF(A29="","",IF(COUNT(D29:G29)<IF($B$9>0,4,3),"Pendiente",IF(AND(ABS(D29-$B$6)<=$B$6*$B$12/100,ABS(E29-$B$7)<=$B$7*$B$12/100,ABS(F29-$B$8)<=3,OR($B$9=0,ABS(G29-$B$9)<=3)),"Correcto","Revisar"))) | J29: =IF(OR(A29="",H29=""),"",IF(H29>$B$10+$B$11,"Sustituir (alargado)","Reutilizable"))
A30: =IF(7>$B$5,"",7) | B30: =IF(A30="","",IF(COUNTIF($B$15:$J$15,A30)>0,"Superior","Inferior")) | C30: =IF(A30="","",IFERROR(MATCH(A30,$B$15:$J$15,0),MATCH(A30,$B$16:$J$16,0))) | I30: =IF(A30="","",IF(COUNT(D30:G30)<IF($B$9>0,4,3),"Pendiente",IF(AND(ABS(D30-$B$6)<=$B$6*$B$12/100,ABS(E30-$B$7)<=$B$7*$B$12/100,ABS(F30-$B$8)<=3,OR($B$9=0,ABS(G30-$B$9)<=3)),"Correcto","Revisar"))) | J30: =IF(OR(A30="",H30=""),"",IF(H30>$B$10+$B$11,"Sustituir (alargado)","Reutilizable"))
A31: =IF(8>$B$5,"",8) | B31: =IF(A31="","",IF(COUNTIF($B$15:$J$15,A31)>0,"Superior","Inferior")) | C31: =IF(A31="","",IFERROR(MATCH(A31,$B$15:$J$15,0),MATCH(A31,$B$16:$J$16,0))) | I31: =IF(A31="","",IF(COUNT(D31:G31)<IF($B$9>0,4,3),"Pendiente",IF(AND(ABS(D31-$B$6)<=$B$6*$B$12/100,ABS(E31-$B$7)<=$B$7*$B$12/100,ABS(F31-$B$8)<=3,OR($B$9=0,ABS(G31-$B$9)<=3)),"Correcto","Revisar"))) | J31: =IF(OR(A31="",H31=""),"",IF(H31>$B$10+$B$11,"Sustituir (alargado)","Reutilizable"))
A32: =IF(9>$B$5,"",9) | B32: =IF(A32="","",IF(COUNTIF($B$15:$J$15,A32)>0,"Superior","Inferior")) | C32: =IF(A32="","",IFERROR(MATCH(A32,$B$15:$J$15,0),MATCH(A32,$B$16:$J$16,0))) | I32: =IF(A32="","",IF(COUNT(D32:G32)<IF($B$9>0,4,3),"Pendiente",IF(AND(ABS(D32-$B$6)<=$B$6*$B$12/100,ABS(E32-$B$7)<=$B$7*$B$12/100,ABS(F32-$B$8)<=3,OR($B$9=0,ABS(G32-$B$9)<=3)),"Correcto","Revisar"))) | J32: =IF(OR(A32="",H32=""),"",IF(H32>$B$10+$B$11,"Sustituir (alargado)","Reutilizable"))
A33: =IF(10>$B$5,"",10) | B33: =IF(A33="","",IF(COUNTIF($B$15:$J$15,A33)>0,"Superior","Inferior")) | C33: =IF(A33="","",IFERROR(MATCH(A33,$B$15:$J$15,0),MATCH(A33,$B$16:$J$16,0))) | I33: =IF(A33="","",IF(COUNT(D33:G33)<IF($B$9>0,4,3),"Pendiente",IF(AND(ABS(D33-$B$6)<=$B$6*$B$12/100,ABS(E33-$B$7)<=$B$7*$B$12/100,ABS(F33-$B$8)<=3,OR($B$9=0,ABS(G33-$B$9)<=3)),"Correcto","Revisar"))) | J33: =IF(OR(A33="",H33=""),"",IF(H33>$B$10+$B$11,"Sustituir (alargado)","Reutilizable"))
A34: =IF(11>$B$5,"",11) | B34: =IF(A34="","",IF(COUNTIF($B$15:$J$15,A34)>0,"Superior","Inferior")) | C34: =IF(A34="","",IFERROR(MATCH(A34,$B$15:$J$15,0),MATCH(A34,$B$16:$J$16,0))) | I34: =IF(A34="","",IF(COUNT(D34:G34)<IF($B$9>0,4,3),"Pendiente",IF(AND(ABS(D34-$B$6)<=$B$6*$B$12/100,ABS(E34-$B$7)<=$B$7*$B$12/100,ABS(F34-$B$8)<=3,OR($B$9=0,ABS(G34-$B$9)<=3)),"Correcto","Revisar"))) | J34: =IF(OR(A34="",H34=""),"",IF(H34>$B$10+$B$11,"Sustituir (alargado)","Reutilizable"))
A35: =IF(12>$B$5,"",12) | B35: =IF(A35="","",IF(COUNTIF($B$15:$J$15,A35)>0,"Superior","Inferior")) | C35: =IF(A35="","",IFERROR(MATCH(A35,$B$15:$J$15,0),MATCH(A35,$B$16:$J$16,0))) | I35: =IF(A35="","",IF(COUNT(D35:G35)<IF($B$9>0,4,3),"Pendiente",IF(AND(ABS(D35-$B$6)<=$B$6*$B$12/100,ABS(E35-$B$7)<=$B$7*$B$12/100,ABS(F35-$B$8)<=3,OR($B$9=0,ABS(G35-$B$9)<=3)),"Correcto","Revisar"))) | J35: =IF(OR(A35="",H35=""),"",IF(H35>$B$10+$B$11,"Sustituir (alargado)","Reutilizable"))
A36: =IF(13>$B$5,"",13) | B36: =IF(A36="","",IF(COUNTIF($B$15:$J$15,A36)>0,"Superior","Inferior")) | C36: =IF(A36="","",IFERROR(MATCH(A36,$B$15:$J$15,0),MATCH(A36,$B$16:$J$16,0))) | I36: =IF(A36="","",IF(COUNT(D36:G36)<IF($B$9>0,4,3),"Pendiente",IF(AND(ABS(D36-$B$6)<=$B$6*$B$12/100,ABS(E36-$B$7)<=$B$7*$B$12/100,ABS(F36-$B$8)<=3,OR($B$9=0,ABS(G36-$B$9)<=3)),"Correcto","Revisar"))) | J36: =IF(OR(A36="",H36=""),"",IF(H36>$B$10+$B$11,"Sustituir (alargado)","Reutilizable"))
A37: =IF(14>$B$5,"",14) | B37: =IF(A37="","",IF(COUNTIF($B$15:$J$15,A37)>0,"Superior","Inferior")) | C37: =IF(A37="","",IFERROR(MATCH(A37,$B$15:$J$15,0),MATCH(A37,$B$16:$J$16,0))) | I37: =IF(A37="","",IF(COUNT(D37:G37)<IF($B$9>0,4,3),"Pendiente",IF(AND(ABS(D37-$B$6)<=$B$6*$B$12/100,ABS(E37-$B$7)<=$B$7*$B$12/100,ABS(F37-$B$8)<=3,OR($B$9=0,ABS(G37-$B$9)<=3)),"Correcto","Revisar"))) | J37: =IF(OR(A37="",H37=""),"",IF(H37>$B$10+$B$11,"Sustituir (alargado)","Reutilizable"))
A38: =IF(15>$B$5,"",15) | B38: =IF(A38="","",IF(COUNTIF($B$15:$J$15,A38)>0,"Superior","Inferior")) | C38: =IF(A38="","",IFERROR(MATCH(A38,$B$15:$J$15,0),MATCH(A38,$B$16:$J$16,0))) | I38: =IF(A38="","",IF(COUNT(D38:G38)<IF($B$9>0,4,3),"Pendiente",IF(AND(ABS(D38-$B$6)<=$B$6*$B$12/100,ABS(E38-$B$7)<=$B$7*$B$12/100,ABS(F38-$B$8)<=3,OR($B$9=0,ABS(G38-$B$9)<=3)),"Correcto","Revisar"))) | J38: =IF(OR(A38="",H38=""),"",IF(H38>$B$10+$B$11,"Sustituir (alargado)","Reutilizable"))
A39: =IF(16>$B$5,"",16) | B39: =IF(A39="","",IF(COUNTIF($B$15:$J$15,A39)>0,"Superior","Inferior")) | C39: =IF(A39="","",IFERROR(MATCH(A39,$B$15:$J$15,0),MATCH(A39,$B$16:$J$16,0))) | I39: =IF(A39="","",IF(COUNT(D39:G39)<IF($B$9>0,4,3),"Pendiente",IF(AND(ABS(D39-$B$6)<=$B$6*$B$12/100,ABS(E39-$B$7)<=$B$7*$B$12/100,ABS(F39-$B$8)<=3,OR($B$9=0,ABS(G39-$B$9)<=3)),"Correcto","Revisar"))) | J39: =IF(OR(A39="",H39=""),"",IF(H39>$B$10+$B$11,"Sustituir (alargado)","Reutilizable"))
A40: =IF(17>$B$5,"",17) | B40: =IF(A40="","",IF(COUNTIF($B$15:$J$15,A40)>0,"Superior","Inferior")) | C40: =IF(A40="","",IFERROR(MATCH(A40,$B$15:$J$15,0),MATCH(A40,$B$16:$J$16,0))) | I40: =IF(A40="","",IF(COUNT(D40:G40)<IF($B$9>0,4,3),"Pendiente",IF(AND(ABS(D40-$B$6)<=$B$6*$B$12/100,ABS(E40-$B$7)<=$B$7*$B$12/100,ABS(F40-$B$8)<=3,OR($B$9=0,ABS(G40-$B$9)<=3)),"Correcto","Revisar"))) | J40: =IF(OR(A40="",H40=""),"",IF(H40>$B$10+$B$11,"Sustituir (alargado)","Reutilizable"))
A41: =IF(18>$B$5,"",18) | B41: =IF(A41="","",IF(COUNTIF($B$15:$J$15,A41)>0,"Superior","Inferior")) | C41: =IF(A41="","",IFERROR(MATCH(A41,$B$15:$J$15,0),MATCH(A41,$B$16:$J$16,0))) | I41: =IF(A41="","",IF(COUNT(D41:G41)<IF($B$9>0,4,3),"Pendiente",IF(AND(ABS(D41-$B$6)<=$B$6*$B$12/100,ABS(E41-$B$7)<=$B$7*$B$12/100,ABS(F41-$B$8)<=3,OR($B$9=0,ABS(G41-$B$9)<=3)),"Correcto","Revisar"))) | J41: =IF(OR(A41="",H41=""),"",IF(H41>$B$10+$B$11,"Sustituir (alargado)","Reutilizable"))
A43: =COUNTIF(I24:I41,"Correcto")&" de "&B5&" tornillos con el apriete completo y correcto · "&COUNTIF(J24:J41,"Sustituir*")&" tornillos para sustituir"

Sheet Muelles de válvula
A1: Simulador · Comprobación de los muelles de válvula (ley de Hooke)
A2: Sistemas del Funcionamiento del Motor (MA.02.06) · Unidad 3 · Edite solo las celdas amarillas (texto azul); todo lo demás se recalcula.
A4: Datos de entrada | B4: Valor
A5: Longitud libre especificada (mm) | B5: 45
A6: Longitud libre mínima admisible (mm) | B6: 43.8
A7: Longitud libre medida (mm) | B7: 44.5
A8: Altura de montaje, válvula cerrada (mm) | B8: 38
A9: Fuerza especificada a la altura de montaje (N) | B9: 230
A10: Fuerza medida en el probador a la altura de montaje (N) | B10: 214
A11: Alzada de la válvula (mm) | B11: 9
A12: Altura sólida, espiras juntas (mm) | B12: 26.5
A13: Falta de perpendicularidad medida (mm) | B13: 0.9
A14: Falta de perpendicularidad máxima (mm) | B14: 1.5
A15: Pérdida de fuerza admisible (%) | B15: 10
A17: Resultados | B17: Valor | C17: Cómo se obtiene
A18: Rigidez especificada k (N/mm) | B18: =B9/(B5-B8) | C18: k = F/(L libre − L montaje)
A19: Rigidez del muelle medido (N/mm) | B19: =B10/(B7-B8)
A20: Altura con la válvula abierta (mm) | B20: =B8-B11
A21: Fuerza especificada con la válvula abierta (N) | B21: =B18*(B5-B20) | C21: F = k·(L libre − L abierta)
A22: Fuerza del muelle medido con la válvula abierta (N) | B22: =B19*(B7-B20)
A23: Pérdida de fuerza a la altura de montaje (%) | B23: =(1-B10/B9)*100
A24: Margen hasta el bloqueo de espiras (mm) | B24: =B20-B12 | C24: Debe quedar holgura con la válvula abierta
A26: Longitud libre | B26: =IF(B7>=B6,"Correcta","Sustituir: muelle vencido")
A27: Fuerza | B27: =IF(B23<=B15,"Correcta","Sustituir: el muelle perdió fuerza (riesgo de flotación de la válvula)")
A28: Perpendicularidad | B28: =IF(B13<=B14,"Correcta","Sustituir: muelle deformado")
A29: Bloqueo de espiras | B29: =IF(B24>=1,"Correcto","Peligro: el muelle llega a espiras juntas con la válvula abierta")
A31: =IF(AND(B7>=B6,B23<=B15,B13<=B14,B24>=1),"Conclusión: el muelle puede volver a montarse","Conclusión: sustituir el muelle (y comprobar los demás del juego)")

Sheet Guía
B2: Guía de uso del simulador
B3: Objetivo: relacionar los ángulos del diagrama de distribución (AAE, RCE, AAA, RCA) con la curva de alzado de las válvulas y observar cómo un variador de fase modifica el cruce.
B4: Cómo usarlo
B5: 1. En la hoja Simulador escriba los ángulos del motor en las celdas amarillas (tómelos del manual o de Autodata).
B6: 2. Ajuste la alzada máxima de cada válvula y la fracción de rampa para que el perfil se parezca al de la leva real.
B7: 3. Indique cuántos grados desplaza el variador cada árbol. Con 0° las tres curvas de cada válvula coinciden.
B8: 4. Lea en la tabla de resultados el cruce base, máximo y mínimo, y compárelo con los corchetes del gráfico.
B9: Actividades propuestas (Unidad 3)
B10: a) Con AAE = 45°, RCE = 20°, AAA = 20° y RCA = 50°, calcule a mano la duración de admisión y de escape y verifíquelas con el simulador.
B11: b) Ponga la variación de fase de la admisión en 0° y aumente la del escape de 5° en 5°. ¿Cómo cambia el cruce máximo?
B12: c) Simule un salto de un diente de la correa (en un piñón de 21 dientes, 360°/21 × 2 ≈ 34° de cigüeñal) desplazando ambas fases. ¿Qué ocurre con el cruce?
B13: d) Explique por qué a bajo régimen conviene el cruce mínimo y a alto régimen el cruce máximo.
... B29: Registre la longitud libre, la fuerza en el probador, la perpendicularidad y la altura sólida. La hoja calcula la rigidez, la fuerza con la válvula abierta y el margen hasta el bloqueo de espiras, y decide si el muelle se reutiliza.

Sheet Datos
A1: Ángulo cigüeñal (°) | B1: Escape adelantado | C1: Escape base | D1: Escape retrasado | E1: Admisión adelantada | F1: Admisión base | G1: Admisión retrasada | I1: Cruce máximo x | J1: Cruce máximo y | K1: Cruce mínimo x | L1: Cruce mínimo y | M1: PMS x | N1: PMS y | Q1: Escape desfasado | R1: Admisión desfasada | W1: φ árbol (°) | X1: Esc x | Y1: Esc y | Z1: Adm x | AA1: Adm y | AB1: Base x | AC1: Base y | AE1: Evento | AF1: φ | AG1: x0 | AH1: y0 | AI1: x1 | AJ1: y1 | AL1: Cruce x | AM1: Cruce y
A2: 0 | B2: =IF(OR((($A2-Simulador!$E$5)/Simulador!$G$5)<=0,(($A2-Simulador!$E$5)/Simulador!$G$5)>=1),0,IF((($A2-Simulador!$E$5)/Simulador!$G$5)<Simulador!$B$11,Simulador!$B$9*(1-COS(PI()*(($A2-Simulador!$E$5)/Simulador!$G$5)/Simulador!$B$11))/2,IF((($A2-Simulador!$E$5)/Simulador!$G$5)>1-Simulador!$B$11,Simulador!$B$9*(1-COS(PI()*(1-(($A2-Simulador!$E$5)/Simulador!$G$5))/Simulador!$B$11))/2,Simulador!$B$9))) | C2: =IF(OR((($A2-Simulador!$E$6)/Simulador!$G$6)<=0,(($A2-Simulador!$E$6)/Simulador!$G$6)>=1),0,IF((($A2-Simulador!$E$6)/Simulador!$G$6)<Simulador!$B$11,Simulador!$B$9*(1-COS(PI()*(($A2-Simulador!$E$6)/Simulador!$G$6)/Simulador!$B$11))/2,IF((($A2-Simulador!$E$6)/Simulador!$G$6)>1-Simulador!$B$11,Simulador!$B$9*(1-COS(PI()*(1-(($A2-Simulador!$E$6)/Simulador!$G$6))/Simulador!$B$11))/2,Simulador!$B$9))) | D2: =IF(OR((($A2-Simulador!$E$7)/Simulador!$G$7)<=0,(($A2-Simulador!$E$7)/Simulador!$G$7)>=1),0,IF((($A2-Simulador!$E$7)/Simulador!$G$7)<Simulador!$B$11,Simulador!$B$9*(1-COS(PI()*(($A2-Simulador!$E$7)/Simulador!$G$7)/Simulador!$B$11))/2,IF((($A2-Simulador!$E$7)/Simulador!$G$7)>1-Simulador!$B$11,Simulador!$B$9*(1-COS(PI()*(1-(($A2-Simulador!$E$7)/Simulador!$G$7))/Simulador!$B$11))/2,Simulador!$B$9))) | E2: =IF(OR((($A2-Simulador!$E$8)/Simulador!$G$8)<=0,(($A2-Simulador!$E$8)/Simulador!$G$8)>=1),0,IF((($A2-Simulador!$E$8)/Simulador!$G$8)<Simulador!$B$11,Simulador!$B$10*(1-COS(PI()*(($A2-Simulador!$E$8)/Simulador!$G$8)/Simulador!$B$11))/2,IF((($A2-Simulador!$E$8)/Simulador!$G$8)>1-Simulador!$B$11,Simulador!$B$10*(1-COS(PI()*(1-(($A2-Simulador!$E$8)/Simulador!$G$8))/Simulador!$B$11))/2,Simulador!$B$10))) | F2: =IF(OR((($A2-Simulador!$E$9)/Simulador!$G$9)<=0,(($A2-Simulador!$E$9)/Simulador!$G$9)>=1),0,IF((($A2-Simulador!$E$9)/Simulador!$G$9)<Simulador!$B$11,Simulador!$B$10*(1-COS(PI()*(($A2-Simulador!$E$9)/Simulador!$G$9)/Simulador!$B$11))/2,IF((($A2-Simulador!$E$9)/Simulador!$G$9)>1-Simulador!$B$11,Simulador!$B$10*(1-COS(PI()*(1-(($A2-Simulador!$E$9)/Simulador!$G$9))/Simulador!$B$11))/2,Simulador!$B$10))) | G2: =IF(OR((($A2-Simulador!$E$10)/Simulador!$G$10)<=0,(($A2-Simulador!$E$10)/Simulador!$G$10)>=1),0,IF((($A2-Simulador!$E$10)/Simulador!$G$10)<Simulador!$B$11,Simulador!$B$10*(1-COS(PI()*(($A2-Simulador!$E$10)/Simulador!$G$10)/Simulador!$B$11))/2,IF((($A2-Simulador!$E$10)/Simulador!$G$10)>1-Simulador!$B$11,Simulador!$B$10*(1-COS(PI()*(1-(($A2-Simulador!$E$10)/Simulador!$G$10))/Simulador!$B$11))/2,Simulador!$B$10))) | I2: =Simulador!$E$8 | J2: 0 | K2: =Simulador!$E$10 | L2: 0 | M2: 360 | N2: 0 | Q2: =IF(OR((($A2-(Simulador!$E$6+'Salto de dientes'!$B$12))/Simulador!$G$6)<=0,(($A2-(Simulador!$E$6+'Salto de dientes'!$B$12))/Simulador!$G$6)>=1),0,IF((($A2-(Simulador!$E$6+'Salto de dientes'!$B$12))/Simulador!$G$6)<Simulador!$B$11,Simulador!$B$9*(1-COS(PI()*(($A2-(Simulador!$E$6+'Salto de dientes'!$B$12))/Simulador!$G$6)/Simulador!$B$11))/2,IF((($A2-(Simulador!$E$6+'Salto de dientes'!$B$12))/Simulador!$G$6)>1-Simulador!$B$11,Simulador!$B$9*(1-COS(PI()*(1-(($A2-(Simulador!$E$6+'Salto de dientes'!$B$12))/Simulador!$G$6))/Simulador!$B$11))/2,Simulador!$B$9))) | R2: =IF(OR((($A2-(Simulador!$E$9+'Salto de dientes'!$B$12))/Simulador!$G$9)<=0,(($A2-(Simulador!$E$9+'Salto de dientes'!$B$12))/Simulador!$G$9)>=1),0,IF((($A2-(Simulador!$E$9+'Salto de dientes'!$B$12))/Simulador!$G$9)<Simulador!$B$11,Simulador!$B$10*(1-COS(PI()*(($A2-(Simulador!$E$9+'Salto de dientes'!$B$12))/Simulador!$G$9)/Simulador!$B$11))/2,IF((($A2-(Simulador!$E$9+'Salto de dientes'!$B$12))/Simulador!$G$9)>1-Simulador!$B$11,Simulador!$B$10*(1-COS(PI()*(1-(($A2-(Simulador!$E$9+'Salto de dientes'!$B$12))/Simulador!$G$9))/Simulador!$B$11))/2,Simulador!$B$10))) | W2: -180 | X2: =('Levas superpuestas'!$B$5+IF(OR(((W2-('Levas superpuestas'!$B$14-'Levas superpuestas'!$B$8/4))/('Levas superpuestas'!$B$8/2))<=0,((W2-('Levas superpuestas'!$B$14-'Levas superpuestas'!$B$8/4))/('Levas superpuestas'!$B$8/2))>=1),0,IF(((W2-('Levas superpuestas'!$B$14-'Levas superpuestas'!$B$8/4))/('Levas superpuestas'!$B$8/2))<Simulador!$B$11,Simulador!$B$9*(1-COS(PI()*((W2-('Levas superpuestas'!$B$14-'Levas superpuestas'!$B$8/4))/('Levas superpuestas'!$B$8/2))/Simulador!$B$11))/2,IF(((W2-('Levas superpuestas'!$B$14-'Levas superpuestas'!$B$8/4))/('Levas superpuestas'!$B$8/2))>1-Simulador!$B$11,Simulador!$B$9*(1-COS(PI()*(1-((W2-('Levas superpuestas'!$B$14-'Levas superpuestas'!$B$8/4))/('Levas superpuestas'!$B$8/2)))/Simulador!$B$11))/2,Simulador!$B$9))))*SIN(RADIANS(W2)) | Y2: =('Levas superpuestas'!$B$5+IF(OR(((W2-('Levas superpuestas'!$B$14-'Levas superpuestas'!$B$8/4))/('Levas superpuestas'!$B$8/2))<=0,((W2-('Levas superpuestas'!$B$14-'Levas superpuestas'!$B$8/4))/('Levas superpuestas'!$B$8/2))>=1),0,IF(((W2-('Levas superpuestas'!$B$14-'Levas superpuestas'!$B$8/4))/('Levas superpuestas'!$B$8/2))<Simulador!$B$11,Simulador!$B$9*(1-COS(PI()*((W2-('Levas superpuestas'!$B$14-'Levas superpuestas'!$B$8/4))/('Levas superpuestas'!$B$8/2))/Simulador!$B$11))/2,IF(((W2-('Levas superpuestas'!$B$14-'Levas superpuestas'!$B$8/4))/('Levas superpuestas'!$B$8/2))>1-Simulador!$B$11,Simulador!$B$9*(1-COS(PI()*(1-((W2-('Levas superpuestas'!$B$14-'Levas superpuestas'!$B$8/4))/('Levas superpuestas'!$B$8/2)))/Simulador!$B$11))/2,Simulador!$B$9))))*COS(RADIANS(W2)) | Z2: =('Levas superpuestas'!$B$5+IF(OR(((W2-('Levas superpuestas'!$B$15-'Levas superpuestas'!$B$9/4))/('Levas superpuestas'!$B$9/2))<=0,((W2-('Levas superpuestas'!$B$15-'Levas superpuestas'!$B$9/4))/('Levas superpuestas'!$B$9/2))>=1),0,IF(((W2-('Levas superpuestas'!$B$15-'Levas superpuestas'!$B$9/4))/('Levas superpuestas'!$B$9/2))<Simulador!$B$11,Simulador!$B$10*(1-COS(PI()*((W2-('Levas superpuestas'!$B$15-'Levas superpuestas'!$B$9/4))/('Levas superpuestas'!$B$9/2))/Simulador!$B$11))/2,IF(((W2-('Levas superpuestas'!$B$15-'Levas superpuestas'!$B$9/4))/('Levas superpuestas'!$B$9/2))>1-Simulador!$B$11,Simulador!$B$10*(1-COS(PI()*(1-((W2-('Levas superpuestas'!$B$15-'Levas superpuestas'!$B$9/4))/('Levas superpuestas'!$B$9/2)))/Simulador!$B$11))/2,Simulador!$B$10))))*SIN(RADIANS(W2)) | AA2: =('Levas superpuestas'!$B$5+IF(OR(((W2-('Levas superpuestas'!$B$15-'Levas superpuestas'!$B$9/4))/('Levas superpuestas'!$B$9/2))<=0,((W2-('Levas superpuestas'!$B$15-'Levas superpuestas'!$B$9/4))/('Levas superpuestas'!$B$9/2))>=1),0,IF(((W2-('Levas superpuestas'!$B$15-'Levas superpuestas'!$B$9/4))/('Levas superpuestas'!$B$9/2))<Simulador!$B$11,Simulador!$B$10*(1-COS(PI()*((W2-('Levas superpuestas'!$B$15-'Levas superpuestas'!$B$9/4))/('Levas superpuestas'!$B$9/2))/Simulador!$B$11))/2,IF(((W2-('Levas superpuestas'!$B$15-'Levas superpuestas'!$B$9/4))/('Levas superpuestas'!$B$9/2))>1-Simulador!$B$11,Simulador!$B$10*(1-COS(PI()*(1-((W2-('Levas superpuestas'!$B$15-'Levas superpuestas'!$B$9/4))/('Levas superpuestas'!$B$9/2)))/Simulador!$B$11))/2,Simulador!$B$10))))*COS(RADIANS(W2)) | AB2: ='Levas superpuestas'!$B$5*SIN(RADIANS(W2)) | AC2: ='Levas superpuestas'!$B$5*COS(RADIANS(W2)) | AE2: MÁXIMA ELEVACIÓN ESCAPE | AF2: ='Levas superpuestas'!$B$14 | AG2: 0 | AH2: 0 | AL2: =0.55*'Levas superpuestas'!$B$5*SIN(RADIANS((('Levas superpuestas'!$B$15-'Levas superpuestas'!$B$9/4)+0/20*(('Levas superpuestas'!$B$14+'Levas superpuestas'!$B$8/4)-('Levas superpuestas'!$B$15-'Levas superpuestas'!$B$9/4))))) | AM2: =0.55*'Levas superpuestas'!$B$5*COS(RADIANS((('Levas superpuestas'!$B$15-'Levas superpuestas'!$B$9/4)+0/20*(('Levas superpuestas'!$B$14+'Levas superpuestas'!$B$8/4)-('Levas superpuestas'!$B$15-'Levas superpuestas'!$B$9/4)))))
A3: =A2+Simulador!$B$14 | B3: =IF(OR((($A3-Simulador!$E$5)/Simulador!$G$5)<=0,(($A3-Simulador!$E$5)/Simulador!$G$5)>=1),0,IF((($A3-Simulador!$E$5)/Simulador!$G$5)<Simulador!$B$11,Simulador!$B$9*(1-COS(PI()*(($A3-Simulador!$E$5)/Simulador!$G$5)/Simulador!$B$11))/2,IF((($A3-Simulador!$E$5)/Simulador!$G$5)>1-Simulador!$B$11,Simulador!$B$9*(1-COS(PI()*(1-(($A3-Simulador!$E$5)/Simulador!$G$5))/Simulador!$B$11))/2,Simulador!$B$9))) | C3: =IF(OR((($A3-Simulador!$E$6)/Simulador!$G$6)<=0,(($A3-Simulador!$E$6)/Simulador!$G$6)>=1),0,IF((($A3-Simulador!$E$6)/Simulador!$G$6)<Simulador!$B$11,Simulador!$B$9*(1-COS(PI()*(($A3-Simulador!$E$6)/Simulador!$G$6)/Simulador!$B$11))/2,IF((($A3-Simulador!$E$6)/Simulador!$G$6)>1-Simulador!$B$11,Simulador!$B$9*(1-COS(PI()*(1-(($A3-Simulador!$E$6)/Simulador!$G$6))/Simulador!$B$11))/2,Simulador!$B$9))) | D3: =IF(OR((($A3-Simulador!$E$7)/Simulador!$G$7)<=0,(($A3-Simulador!$E$7)/Simulador!$G$7)>=1),0,IF((($A3-Simulador!$E$7)/Simulador!$G$7)<Simulador!$B$11,Simulador!$B$9*(1-COS(PI()*(($A3-Simulador!$E$7)/Simulador!$G$7)/Simulador!$B$11))/2,IF((($A3-Simulador!$E$7)/Simulador!$G$7)>1-Simulador!$B$11,Simulador!$B$9*(1-COS(PI()*(1-(($A3-Simulador!$E$7)/Simulador!$G$7))/Simulador!$B$11))/2,Simulador!$B$9))) | E3: =IF(OR((($A3-Simulador!$E$8)/Simulador!$G$8)<=0,(($A3-Simulador!$E$8)/Simulador!$G$8)>=1),0,IF((($A3-Simulador!$E$8)/Simulador!$G$8)<Simulador!$B$11,Simulador!$B$10*(1-COS(PI()*(($A3-Simulador!$E$8)/Simulador!$G$8)/Simulador!$B$11))/2,IF((($A3-Simulador!$E$8)/Simulador!$G$8)>1-Simulador!$B$11,Simulador!$B$10*(1-COS(PI()*(1-(($A3-Simulador!$E$8)/Simulador!$G$8))/Simulador!$B$11))/2,Simulador!$B$10))) | F3: =IF(OR((($A3-Simulador!$E$9)/Simulador!$G$9)<=0,(($A3-Simulador!$E$9)/Simulador!$G$9)>=1),0,IF((($A3-Simulador!$E$9)/Simulador!$G$9)<Simulador!$B$11,Simulador!$B$10*(1-COS(PI()*(($A3-Simulador!$E$9)/Simulador!$G$9)/Simulador!$B$11))/2,IF((($A3-Simulador!$E$9)/Simulador!$G$9)>1-Simulador!$B$11,Simulador!$B$10*(1-COS(PI()*(1-(($A3-Simulador!$E$9)/Simulador!$G$9))/Simulador!$B$11))/2,Simulador!$B$10))) | G3: =IF(OR((($A3-Simulador!$E$10)/Simulador!$G$10)<=0,(($A3-Simulador!$E$10)/Simulador!$G$10)>=1),0,IF((($A3-Simulador!$E$10)/Simulador!$G$10)<Simulador!$B$11,Simulador!$B$10*(1-COS(PI()*(($A3-Simulador!$E$10)/Simulador!$G$10)/Simulador!$B$11))/2,IF((($A3-Simulador!$E$10)/Simulador!$G$10)>1-Simulador!$B$11,Simulador!$B$10*(1-COS(PI()*(1-(($A3-Simulador!$E$10)/Simulador!$G$10))/Simulador!$B$11))/2,Simulador!$B$10))) | I3: =Simulador!$E$8 | J3: 0.05 | K3: =Simulador!$E$10 | L3: 0.05 | M3: 360 | N3: =MAX(Simulador!$B$9,Simulador!$B$10)*1.05 | Q3: =IF(OR((($A3-(Simulador!$E$6+'Salto de dientes'!$B$12))/Simulador!$G$6)<=0,(($A3-(Simulador!$E$6+'Salto de dientes'!$B$12))/Simulador!$G$6)>=1),0,IF((($A3-(Simulador!$E$6+'Salto de dientes'!$B$12))/Simulador!$G$6)<Simulador!$B$11,Simulador!$B$9*(1-COS(PI()*(($A3-(Simulador!$E$6+'Salto de dientes'!$B$12))/Simulador!$G$6)/Simulador!$B$11))/2,IF((($A3-(Simulador!$E$6+'Salto de dientes'!$B$12))/Simulador!$G$6)>1-Simulador!$B$11,Simulador!$B$9*(1-COS(PI()*(1-(($A3-(Simulador!$E$6+'Salto de dientes'!$B$12))/Simulador!$G$6))/Simulador!$B$11))/2,Simulador!$B$9))) | R3: =IF(OR((($A3-(Simulador!$E$9+'Salto de dientes'!$B$12))/Simulador!$G$9)<=0,(($A3-(Simulador!$E$9+'Salto de dientes'!$B$12))/Simulador!$G$9)>=1),0,IF((($A3-(Simulador!$E$9+'Salto de dientes'!$B$12))/Simulador!$G$9)<Simulador!$B$11,Simulador!$B$10*(1-COS(PI()*(($A3-(Simulador!$E$9+'Salto de dientes'!$B$12))/Simulador!$G$9)/Simulador!$B$11))/2,IF((($A3-(Simulador!$E$9+'Salto de dientes'!$B$12))/Simulador!$G$9)>1-Simulador!$B$11,Simulador!$B$10*(1-COS(PI()*(1-(($A3-(Simulador!$E$9+'Salto de dientes'!$B$12))/Simulador!$G$9))/Simulador!$B$11))/2,Simulador!$B$10))) | W3: -177 | X3: =('Levas superpuestas'!$B$5+IF(OR(((W3-('Levas superpuestas'!$B$14-'Levas superpuestas'!$B$8/4))/('Levas superpuestas'!$B$8/2))<=0,((W3-('Levas superpuestas'!$B$14-'Levas superpuestas'!$B$8/4))/('Levas superpuestas'!$B$8/2))>=1),0,IF(((W3-('Levas superpuestas'!$B$14-'Levas superpuestas'!$B$8/4))/('Levas superpuestas'!$B$8/2))<Simulador!$B$11,Simulador!$B$9*(1-COS(PI()*((W3-('Levas superpuestas'!$B$14-'Levas superpuestas'!$B$8/4))/('Levas superpuestas'!$B$8/2))/Simulador!$B$11))/2,IF(((W3-('Levas superpuestas'!$B$14-'Levas superpuestas'!$B$8/4))/('Levas superpuestas'!$B$8/2))>1-Simulador!$B$11,Simulador!$B$9*(1-COS(PI()*(1-((W3-('Levas superpuestas'!$B$14-'Levas superpuestas'!$B$8/4))/('Levas superpuestas'!$B$8/2)))/Simulador!$B$11))/2,Simulador!$B$9))))*SIN(RADIANS(W3)) | Y3: =('Levas superpuestas'!$B$5+IF(OR(((W3-('Levas superpuestas'!$B$14-'Levas superpuestas'!$B$8/4))/('Levas superpuestas'!$B$8/2))<=0,((W3-('Levas superpuestas'!$B$14-'Levas superpuestas'!$B$8/4))/('Levas superpuestas'!$B$8/2))>=1),0,IF(((W3-('Levas superpuestas'!$B$14-'Levas superpuestas'!$B$8/4))/('Levas superpuestas'!$B$8/2))<Simulador!$B$11,Simulador!$B$9*(1-COS(PI()*((W3-('Levas superpuestas'!$B$14-'Levas superpuestas'!$B$8/4))/('Levas superpuestas'!$B$8/2))/Simulador!$B$11))/2,IF(((W3-('Levas superpuestas'!$B$14-'Levas superpuestas'!$B$8/4))/('Levas superpuestas'!$B$8/2))>1-Simulador!$B$11,Simulador!$B$9*(1-COS(PI()*(1-((W3-('Levas superpuestas'!$B$14-'Levas superpuestas'!$B$8/4))/('Levas superpuestas'!$B$8/2)))/Simulador!$B$11))/2,Simulador!$B$9))))*COS(RADIANS(W3)) | Z3: =('Levas superpuestas'!$B$5+IF(OR(((W3-('Levas superpuestas'!$B$15-'Levas superpuestas'!$B$9/4))/('Levas superpuestas'!$B$9/2))<=0,((W3-('Levas superpuestas'!$B$15-'Levas superpuestas'!$B$9/4))/('Levas superpuestas'!$B$9/2))>=1),0,IF(((W3-('Levas superpuestas'!$B$15-'Levas superpuestas'!$B$9/4))/('Levas superpuestas'!$B$9/2))<Simulador!$B$11,Simulador!$B$10*(1-COS(PI()*((W3-('Levas superpuestas'!$B$15-'Levas superpuestas'!$B$9/4))/('Levas superpuestas'!$B$9/2))/Simulador!$B$11))/2,IF(((W3-('Levas superpuestas'!$B$15-'Levas superpuestas'!$B$9/4))/('Levas superpuestas'!$B$9/2))>1-Simulador!$B$11,Simulador!$B$10*(1-COS(PI()*(1-((W3-('Levas superpuestas'!$B$15-'Levas superpuestas'!$B$9/4))/('Levas superpuestas'!$B$9/2)))/Simulador!$B$11))/2,Simulador!$B$10))))*SIN(RADIANS(W3)) | AA3: =('Levas superpuestas'!$B$5+IF(OR(((W3-('Levas superpuestas'!$B$15-'Levas superpuestas'!$B$9/4))/('Levas superpuestas'!$B$9/2))<=0,((W3-('Levas superpuestas'!$B$15-'Levas superpuestas'!$B$9/4))/('Levas superpuestas'!$B$9/2))>=1),0,IF(((W3-('Levas superpuestas'!$B$15-'Levas superpuestas'!$B$9/4))/('Levas superpuestas'!$B$9/2))<Simulador!$B$11,Simulador!$B$10*(1-COS(PI()*((W3-('Levas superpuestas'!$B$15-'Levas superpuestas'!$B$9/4))/('Levas superpuestas'!$B$9/2))/Simulador!$B$11))/2,IF(((W3-('Levas superpuestas'!$B$15-'Levas superpuestas'!$B$9/4))/('Levas superpuestas'!$B$9/2))>1-Simulador!$B$11,Simulador!$B$10*(1-COS(PI()*(1-((W3-('Levas superpuestas'!$B$15-'Levas superpuestas'!$B$9/4))/('Levas superpuestas'!$B$9/2)))/Simulador!$B$11))/2,Simulador!$B$10))))*COS(RADIANS(W3)) | AB3: ='Levas superpuestas'!$B$5*SIN(RADIANS(W3)) | AC3: ='Levas superpuestas'!$B$5*COS(RADIANS(W3)) | AG3: =('Levas superpuestas'!$B$5+MAX(Simulador!$B$9,Simulador!$B$10)+9)*SIN(RADIANS(AF2)) | AH3: =('Levas superpuestas'!$B$5+MAX(Simulador!$B$9,Simulador!$B$10)+9)*COS(RADIANS(AF2)) | AL3: =0.55*'Levas superpuestas'!$B$5*SIN(RADIANS((('Levas superpuestas'!$B$15-'Levas superpuestas'!$B$9/4)+1/20*(('Levas superpuestas'!$B$14+'Levas superpuestas'!$B$8/4)-('Levas superpuestas'!$B$15-'Levas superpuestas'!$B$9/4))))) | AM3: =0.55*'Levas superpuestas'!$B$5*COS(RADIANS((('Levas superpuestas'!$B$15-'Levas superpuestas'!$B$9/4)+1/20*(('Levas superpuestas'!$B$14+'Levas superpuestas'!$B$8/4)-('Levas superpuestas'!$B$15-'Levas superpuestas'!$B$9/4)))))
A4: =A3+Simulador!$B$14 | B4: =IF(OR((($A4-Simulador!$E$5)/Simulador!$G$5)<=0,(($A4-Simulador!$E$5)/Simulador!$G$5)>=1),0,IF((($A4-Simulador!$E$5)/Simulador!$G$5)<Simulador!$B$11,Simulador!$B$9*(1-COS(PI()*(($A4-Simulador!$E$5)/Simulador!$G$5)/Simulador!$B$11))/2,IF((($A4-Simulador!$E$5)/Simulador!$G$5)>1-Simulador!$B$11,Simulador!$B$9*(1-COS(PI()*(1-(($A4-Simulador!$E$5)/Simulador!$G$5))/Simulador!$B$11))/2,Simulador!$B$9))) | C4: =IF(OR((($A4-Simulador!$E$6)/Simulador!$G$6)<=0,(($A4-Simulador!$E$6)/Simulador!$G$6)>=1),0,IF((($A4-Simulador!$E$6)/Simulador!$G$6)<Simulador!$B$11,Simulador!$B$9*(1-COS(PI()*(($A4-Simulador!$E$6)/Simulador!$G$6)/Simulador!$B$11))/2,IF((($A4-Simulador!$E$6)/Simulador!$G$6)>1-Simulador!$B$11,Simulador!$B$9*(1-COS(PI()*(1-(($A4-Simulador!$E$6)/Simulador!$G$6))/Simulador!$B$11))/2,Simulador!$B$9))) | D4: =IF(OR((($A4-Simulador!$E$7)/Simulador!$G$7)<=0,(($A4-Simulador!$E$7)/Simulador!$G$7)>=1),0,IF((($A4-Simulador!$E$7)/Simulador!$G$7)<Simulador!$B$11,Simulador!$B$9*(1-COS(PI()*(($A4-Simulador!$E$7)/Simulador!$G$7)/Simulador!$B$11))/2,IF((($A4-Simulador!$E$7)/Simulador!$G$7)>1-Simulador!$B$11,Simulador!$B$9*(1-COS(PI()*(1-(($A4-Simulador!$E$7)/Simulador!$G$7))/Simulador!$B$11))/2,Simulador!$B$9))) | E4: =IF(OR((($A4-Simulador!$E$8)/Simulador!$G$8)<=0,(($A4-Simulador!$E$8)/Simulador!$G$8)>=1),0,IF((($A4-Simulador!$E$8)/Simulador!$G$8)<Simulador!$B$11,Simulador!$B$10*(1-COS(PI()*(($A4-Simulador!$E$8)/Simulador!$G$8)/Simulador!$B$11))/2,IF((($A4-Simulador!$E$8)/Simulador!$G$8)>1-Simulador!$B$11,Simulador!$B$10*(1-COS(PI()*(1-(($A4-Simulador!$E$8)/Simulador!$G$8))/Simulador!$B$11))/2,Simulador!$B$10))) | F4: =IF(OR((($A4-Simulador!$E$9)/Simulador!$G$9)<=0,(($A4-Simulador!$E$9)/Simulador!$G$9)>=1),0,IF((($A4-Simulador!$E$9)/Simulador!$G$9)<Simulador!$B$11,Simulador!$B$10*(1-COS(PI()*(($A4-Simulador!$E$9)/Simulador!$G$9)/Simulador!$B$11))/2,IF((($A4-Simulador!$E$9)/Simulador!$G$9)>1-Simulador!$B$11,Simulador!$B$10*(1-COS(PI()*(1-(($A4-Simulador!$E$9)/Simulador!$G$9))/Simulador!$B$11))/2,Simulador!$B$10))) | G4: =IF(OR((($A4-Simulador!$E$10)/Simulador!$G$10)<=0,(($A4-Simulador!$E$10)/Simulador!$G$10)>=1),0,IF((($A4-Simulador!$E$10)/Simulador!$G$10)<Simulador!$B$11,Simulador!$B$10*(1-COS(PI()*(($A4-Simulador!$E$10)/Simulador!$G$10)/Simulador!$B$11))/2,IF((($A4-Simulador!$E$10)/Simulador!$G$10)>1-Simulador!$B$11,Simulador!$B$10*(1-COS(PI()*(1-(($A4-Simulador!$E$10)/Simulador!$G$10))/Simulador!$B$11))/2,Simulador!$B$10))) | I4: =Simulador!$E$8 | J4: =MAX(Simulador!$B$9,Simulador!$B$10)*1.32-0.05 | K4: =Simulador!$E$10 | L4: =MAX(Simulador!$B$9,Simulador!$B$10)*1.16-0.05 | Q4: =IF(OR((($A4-(Simulador!$E$6+'Salto de dientes'!$B$12))/Simulador!$G$6)<=0,(($A4-(Simulador!$E$6+'Salto de dientes'!$B$12))/Simulador!$G$6)>=1),0,IF((($A4-(Simulador!$E$6+'Salto de dientes'!$B$12))/Simulador!$G$6)<Simulador!$B$11,Simulador!$B$9*(1-COS(PI()*(($A4-(Simulador!$E$6+'Salto de dientes'!$B$12))/Simulador!$G$6)/Simulador!$B$11))/2,IF((($A4-(Simulador!$E$6+'Salto de dientes'!$B$12))/Simulador!$G$6)>1-Simulador!$B$11,Simulador!$B$9*(1-COS(PI()*(1-(($A4-(Simulador!$E$6+'Salto de dientes'!$B$12))/Simulador!$G$6))/Simulador!$B$11))/2,Simulador!$B$9))) | R4: =IF(OR((($A4-(Simulador!$E$9+'Salto de dientes'!$B$12))/Simulador!$G$9)<=0,(($A4-(Simulador!$E$9+'Salto de dientes'!$B$12))/Simulador!$G$9)>=1),0,IF((($A4-(Simulador!$E$9+'Salto de dientes'!$B$12))/Simulador!$G$9)<Simulador!$B$11,Simulador!$B$10*(1-COS(PI()*(($A4-(Simulador!$E$9+'Salto de dientes'!$B$12))/Simulador!$G$9)/Simulador!$B$11))/2,IF((($A4-(Simulador!$E$9+'Salto de dientes'!$B$12))/Simulador!$G$9)>1-Simulador!$B$11,Simulador!$B$10*(1-COS(PI()*(1-(($A4-(Simulador!$E$9+'Salto de dientes'!$B$12))/Simulador!$G$9))/Simulador!$B$11))/2,Simulador!$B$10))) | W4: -174 | X4: =('Levas superpuestas'!$B$5+IF(OR(((W4-('Levas superpuestas'!$B$14-'Levas superpuestas'!$B$8/4))/('Levas superpuestas'!$B$8/2))<=0,((W4-('Levas superpuestas'!$B$14-'Levas superpuestas'!$B$8/4))/('Levas superpuestas'!$B$8/2))>=1),0,IF(((W4-('Levas superpuestas'!$B$14-'Levas superpuestas'!$B$8/4))/('Levas superpuestas'!$B$8/2))<Simulador!$B$11,Simulador!$B$9*(1-COS(PI()*((W4-('Levas superpuestas'!$B$14-'Levas superpuestas'!$B$8/4))/('Levas superpuestas'!$B$8/2))/Simulador!$B$11))/2,IF(((W4-('Levas superpuestas'!$B$14-'Levas superpuestas'!$B$8/4))/('Levas superpuestas'!$B$8/2))>1-Simulador!$B$11,Simulador!$B$9*(1-COS(PI()*(1-((W4-('Levas superpuestas'!$B$14-'Levas superpuestas'!$B$8/4))/('Levas superpuestas'!$B$8/2)))/Simulador!$B$11))/2,Simulador!$B$9))))*SIN(RADIANS(W4)) | Y4: =('Levas superpuestas'!$B$5+IF(OR(((W4-('Levas superpuestas'!$B$14-'Levas superpuestas'!$B$8/4))/('Levas superpuestas'!$B$8/2))<=0,((W4-('Levas superpuestas'!$B$14-'Levas superpuestas'!$B$8/4))/('Levas superpuestas'!$B$8/2))>=1),0,IF(((W4-('Levas superpuestas'!$B$14-'Levas superpuestas'!$B$8/4))/('Levas superpuestas'!$B$8/2))<Simulador!$B$11,Simulador!$B$9*(1-COS(PI()*((W4-('Levas superpuestas'!$B$14-'Levas superpuestas'!$B$8/4))/('Levas superpuestas'!$B$8/2))/Simulador!$B$11))/2,IF(((W4-('Levas superpuestas'!$B$14-'Levas superpuestas'!$B$8/4))/('Levas superpuestas'!$B$8/2))>1-Simulador!$B$11,Simulador!$B$9*(1-COS(PI()*(1-((W4-('Levas superpuestas'!$B$14-'Levas superpuestas'!$B$8/4))/('Levas superpuestas'!$B$8/2)))/Simulador!$B$11))/2,Simulador!$B$9))))*COS(RADIANS(W4)) | Z4: =('Levas superpuestas'!$B$5+IF(OR(((W4-('Levas superpuestas'!$B$15-'Levas superpuestas'!$B$9/4))/('Levas superpuestas'!$B$9/2))<=0,((W4-('Levas superpuestas'!$B$15-'Levas superpuestas'!$B$9/4))/('Levas superpuestas'!$B$9/2))>=1),0,IF(((W4-('Levas superpuestas'!$B$15-'Levas superpuestas'!$B$9/4))/('Levas superpuestas'!$B$9/2))<Simulador!$B$11,Simulador!$B$10*(1-COS(PI()*((W4-('Levas superpuestas'!$B$15-'Levas superpuestas'!$B$9/4))/('Levas superpuestas'!$B$9/2))/Simulador!$B$11))/2,IF(((W4-('Levas superpuestas'!$B$15-'Levas superpuestas'!$B$9/4))/('Levas superpuestas'!$B$9/2))>1-Simulador!$B$11,Simulador!$B$10*(1-COS(PI()*(1-((W4-('Levas superpuestas'!$B$15-'Levas superpuestas'!$B$9/4))/('Levas superpuestas'!$B$9/2)))/Simulador!$B$11))/2,Simulador!$B$10))))*SIN(RADIANS(W4)) | AA4: =('Levas superpuestas'!$B$5+IF(OR(((W4-('Levas superpuestas'!$B$15-'Levas superpuestas'!$B$9/4))/('Levas superpuestas'!$B$9/2))<=0,((W4-('Levas superpuestas'!$B$15-'Levas superpuestas'!$B$9/4))/('Levas superpuestas'!$B$9/2))>=1),0,IF(((W4-('Levas superpuestas'!$B$15-'Levas superpuestas'!$B$9/4))/('Levas superpuestas'!$B$9/2))<Simulador!$B$11,Simulador!$B$10*(1-COS(PI()*((W4-('Levas superpuestas'!$B$15-'Levas superpuestas'!$B$9/4))/('Levas superpuestas'!$B$9/2))/Simulador!$B$11))/2,IF(((W4-('Levas superpuestas'!$B$15-'Levas superpuestas'!$B$9/4))/('Levas superpuestas'!$B$9/2))>1-Simulador!$B$11,Simulador!$B$10*(1-COS(PI()*(1-((W4-('Levas superpuestas'!$B$15-'Levas superpuestas'!$B$9/4))/('Levas superpuestas'!$B$9/2)))/Simulador!$B$11))/2,Simulador!$B$10))))*COS(RADIANS(W4)) | AB4: ='Levas superpuestas'!$B$5*SIN(RADIANS(W4)) | AC4: ='Levas superpuestas'!$B$5*COS(RADIANS(W4)) | AL4: =0.55*'Levas superpuestas'!$B$5*SIN(RADIANS((('Levas superpuestas'!$B$15-'Levas superpuestas'!$B$9/4)+2/20*(('Levas superpuestas'!$B$14+'Levas superpuestas'!$B$8/4)-('Levas superpuestas'!$B$15-'Levas superpuestas'!$B$9/4))))) | AM4: =0.55*'Levas superpuestas'!$B$5*COS(RADIANS((('Levas superpuestas'!$B$15-'Levas superpuestas'!$B$9/4)+2/20*(('Levas superpuestas'!$B$14+'Levas superpuestas'!$B$8/4)-('Levas superpuestas'!$B$15-'Levas superpuestas'!$B$9/4)))))
