Workbook

Sheet Inicio
A1: Simuladores del tren de fuerza motriz — Mecánica de Patio III
A2: Instituto Superior Tecnológico Sudamericano · Tecnología Superior en Mecánica Automotriz · Periodo octubre 2026 – febrero 2027 · Docente: Ing. Miguel Ángel Minga González
B4: Cómo usar el libro
B5: Paso 1 | C5: Abra el archivo en Microsoft Excel (o en LibreOffice Calc). No usa macros: no necesita habilitar contenido. Si se abre en «Vista protegida», pulse «Habilitar edición».
B6: Paso 2 | C6: Cambie los datos en las celdas AMARILLAS (escriba el valor y pulse Enter). Al seleccionar una celda aparece el rango de valores admitido.
B7: Paso 3 | C7: Los resultados aparecen en las celdas VERDES y los esquemas y gráficos se redibujan al instante.
B8: Paso 4 | C8: Para estudiar un caso, cambie un solo dato cada vez y compare el esquema antes y después. Los valores iniciales son los de los ejemplos de la guía: anótelos para volver a ellos.
B9: Paso 5 | C9: Cada hoja termina con preguntas de análisis: resuelva primero el ejemplo a mano y compruebe su respuesta con el simulador.
B10: Paso 6 | C10: Las hojas están protegidas sin contraseña para no borrar fórmulas por accidente (Revisar → Desproteger hoja si necesita modificarlas).
B12: Celda de dato | C12: Escriba aquí el valor
B13: Esquema | C13: Gráficos y diagramas que se redibujan con cada dato
B14: Resultado | C14: Calculado con las ecuaciones de la guía
B16: Índice de simuladores
B17: Hoja | C17: Qué simula | D17: Ejemplos de la guía
B18: U1 Caja de cambios | C18: Unidad 1 · Escalonamiento de la caja: diagrama de sierra, fuerza de tracción frente a resistencias al avance, velocidad máxima, pendiente superable y par de engranajes de la marcha engranada. | D18: Ej. 1.1 a 1.4
B19: U1 Embrague | C19: Unidad 1 · Par transmisible del embrague, efecto del desgaste del forro (diafragma frente a muelles helicoidales) y mando hidráulico al pisar el pedal. | D19: Ej. 1.5 y 1.6
B20: U2 Junta cardán | C20: Unidad 2 · Irregularidad de la junta cardán simple y compensación con doble junta (ángulos y fase de horquillas); velocidad crítica del árbol. | D20: Ej. 2.1
B21: U2 Diferencial | C21: Unidad 2 · Grupo reductor, velocidad de las ruedas en curva (vista superior) y reparto de tracción con diferencial abierto, autoblocante o bloqueado. | D21: Ej. 2.2 y 2.3
B22: U3 Tren epicicloidal | C22: Unidad 3 · Tren epicicloidal simple con vista frontal y nomograma de palanca (ecuación de Willis); relaciones de una caja Simpson. | D22: Ej. 3.2 y 3.3
B23: U3 Convertidor | C23: Unidad 3 · Curva característica del convertidor (multiplicación de par y rendimiento), régimen de calado y punto de acoplamiento; principio de Pascal. | D23: Ej. 3.1 y 3.4
B24: U4 CVT | C24: Unidad 4 · Variador continuo: radios de las poleas, correa, relación de transmisión y velocidad del vehículo a régimen constante. | D24: Ej. 4.4
B25: U4 Híbrido | C25: Unidad 4 · Tren de reparto de potencia (e-CVT): nomograma de MG1, motor térmico y MG2; modo eléctrico y límites de MG1. | D25: Ej. 4.3
B26: U4 Sensores y PWM | C26: Unidad 4 · Señal de los sensores de velocidad, patinamiento, sensor NTC de temperatura del ATF con fallas simuladas (P0712/P0713) y electroválvulas PWM. | D26: Ej. 4.1 y 4.2
B28: Nota técnica: los modelos son didácticos. Usan las ecuaciones de la guía de la asignatura (Domínguez y Ferrer, 2018; Águeda Casado et al., 2012) y valores típicos de vehículos de turismo. Los resultados sirven para comprender tendencias y comprobar ejercicios; para diagnosticar y reparar, use siempre los datos del fabricante.

Sheet U1 Caja de cambios
A1: U1 · Escalonamiento de la caja de cambios | AA1: Datos de cálculo para los gráficos (no editar) | BS1: ="Par de engranajes de "&$C$52&"ª marcha (i = "&FIXED(INDEX($C$15:$C$19,$C$52),2,TRUE)&")" -> Par de engranajes de 2ª marcha (i = 2.02)
A2: Relaciona la curva del motor con la velocidad del vehículo en cada marcha (diagrama de sierra) y compara la fuerza de tracción con las resistencias al avance. Unidad 1: par y potencia, sistemas de transmisión, cálculo de una caja de cambios. | AA2: n | AB2: T | AC2: v1 | AD2: F1 | AE2: v2 | AF2: F2 | AG2: v3 | AH2: F3 | AI2: v4 | AJ2: F4 | AK2: v5 | AL2: F5 | AM2: Fres v4 | AN2: exc4 | AO2: Fres v5 | AP2: exc5 | AQ2: flag4 | AR2: vx4 | AS2: flag5 | AT2: vx5 | AV2: v | AW2: F resist. | AX2: v | AY2: F adher. | BA2: v sierra | BB2: n sierra | BS2: =1/(1+INDEX($C$15:$C$19,$C$52)) -> 0.33112583 | BT2: =INDEX($C$15:$C$19,$C$52)/(1+INDEX($C$15:$C$19,$C$52)) -> 0.66887417 | BU2: =$C$24*36 -> 1080 | BV2: =180-BU2/INDEX($C$15:$C$19,$C$52) -> -354.65347
B3: ◄ Volver al inicio | AA3: =B28 -> 1000 | AB3: =C28 -> 110 | AC3: =0.377*AA3*$C$6/$C$43 -> 7.4485625 | AD3: =AB3*$C$43*$C$7/$C$6 -> 5010.7655 | AE3: =0.377*AA3*$C$6/$C$44 -> 13.200918 | AF3: =AB3*$C$44*$C$7/$C$6 -> 2827.3034 | AG3: =0.377*AA3*$C$6/$C$45 -> 20.201404 | AH3: =AB3*$C$45*$C$7/$C$6 -> 1847.5448 | AI3: =0.377*AA3*$C$6/$C$46 -> 27.490571 | AJ3: =AB3*$C$46*$C$7/$C$6 -> 1357.6655 | AK3: =0.377*AA3*$C$6/$C$47 -> 35.08665 | AL3: =AB3*$C$47*$C$7/$C$6 -> 1063.7379 | AM3: =($C$5*9.81*($C$8*COS(ATAN($C$12/100))+SIN(ATAN($C$12/100)))+0.5*$C$11*$C$9*$C$10*(AI3/3.6)^2) -> 198.97204 | AN3: =AJ3-AM3 -> 1158.6935 | AO3: =($C$5*9.81*($C$8*COS(ATAN($C$12/100))+SIN(ATAN($C$12/100)))+0.5*$C$11*$C$9*$C$10*(AK3/3.6)^2) -> 213.05624 | AP3: =AL3-AO3 -> 850.68169 | AQ3: =IF(AND(AN3>=0,AN4<0),1,0) -> 0 | AR3: =IF(AQ3=1,AI3+AN3/(AN3-AN4)*(AI4-AI3),0) -> 0 | AS3: =IF(AND(AP3>=0,AP4<0),1,0) -> 0 | AT3: =IF(AS3=1,AK3+AP3/(AP3-AP4)*(AK4-AK3),0) -> 0 | AV3: =0 -> 0 | AW3: =($C$5*9.81*($C$8*COS(ATAN($C$12/100))+SIN(ATAN($C$12/100)))+0.5*$C$11*$C$9*$C$10*(AV3/3.6)^2) -> 176.58 | AX3: 0 | AY3: =($C$21*$C$5*9.81*$C$22/100) -> 5650.56 | BA3: =$AC$3 -> 7.4485625 | BB3: =$AA$3 -> 1000 | BD3: =AC3 -> 7.4485625 | BE3: =$AA$3 -> 1000 | BF3: =AE3 -> 13.200918 | BG3: =$AA$3 -> 1000 | BH3: =AG3 -> 20.201404 | BI3: =$AA$3 -> 1000 | BJ3: =AI3 -> 27.490571 | BK3: =$AA$3 -> 1000 | BL3: =AK3 -> 35.08665 | BM3: =$AA$3 -> 1000 | BO3: =$C$51 -> 57.892972 | BP3: =$C$53 -> 4385.5263 | BQ3: =$C$51 -> 57.892972 | BR3: =$C$55 -> 3718.851
B4: Datos del vehículo | AA4: =B29 -> 1500 | AB4: =C29 -> 125 | AC4: =0.377*AA4*$C$6/$C$43 -> 11.172844 | AD4: =AB4*$C$43*$C$7/$C$6 -> 5694.0517 | AE4: =0.377*AA4*$C$6/$C$44 -> 19.801376 | AF4: =AB4*$C$44*$C$7/$C$6 -> 3212.8448 | AG4: =0.377*AA4*$C$6/$C$45 -> 30.302106 | AH4: =AB4*$C$45*$C$7/$C$6 -> 2099.4828 | AI4: =0.377*AA4*$C$6/$C$46 -> 41.235856 | AJ4: =AB4*$C$46*$C$7/$C$6 -> 1542.8017 | AK4: =0.377*AA4*$C$6/$C$47 -> 52.629974 | AL4: =AB4*$C$47*$C$7/$C$6 -> 1208.7931 | AM4: =($C$5*9.81*($C$8*COS(ATAN($C$12/100))+SIN(ATAN($C$12/100)))+0.5*$C$11*$C$9*$C$10*(AI4/3.6)^2) -> 226.9621 | AN4: =AJ4-AM4 -> 1315.8396 | AO4: =($C$5*9.81*($C$8*COS(ATAN($C$12/100))+SIN(ATAN($C$12/100)))+0.5*$C$11*$C$9*$C$10*(AK4/3.6)^2) -> 258.65153 | AP4: =AL4-AO4 -> 950.14157 | AQ4: =IF(AND(AN4>=0,AN5<0),1,0) -> 0 | AR4: =IF(AQ4=1,AI4+AN4/(AN4-AN5)*(AI5-AI4),0) -> 0 | AS4: =IF(AND(AP4>=0,AP5<0),1,0) -> 0 | AT4: =IF(AS4=1,AK4+AP4/(AP4-AP5)*(AK5-AK4),0) -> 0 | AV4: =10 -> 10 | AW4: =($C$5*9.81*($C$8*COS(ATAN($C$12/100))+SIN(ATAN($C$12/100)))+0.5*$C$11*$C$9*$C$10*(AV4/3.6)^2) -> 179.54296 | AX4: 220 | AY4: =($C$21*$C$5*9.81*$C$22/100) -> 5650.56 | BA4: =$D$43 -> 40.967094 | BB4: =$C$20 -> 5500 | BD4: =AC14 -> 48.415656 | BE4: =$AA$14 -> 6500 | BF4: =AE14 -> 85.805965 | BG4: =$AA$14 -> 6500 | BH4: =AG14 -> 131.30913 | BI4: =$AA$14 -> 6500 | BJ4: =AI14 -> 178.68871 | BK4: =$AA$14 -> 6500 | BL4: =AK14 -> 228.06322 | BM4: =$AA$14 -> 6500 | BS4: =0+$BS$2*COS(RADIANS((0+(360-(0))*0/36))) -> 0.33112583 | BT4: =0+$BS$2*SIN(RADIANS((0+(360-(0))*0/36))) -> 0 | BU4: =1+$BT$2*COS(RADIANS((0+(360-(0))*0/36))) -> 1.6688742 | BV4: =0+$BT$2*SIN(RADIANS((0+(360-(0))*0/36))) -> 0 | BW4: 0 | BX4: 0 | BY4: 1 | BZ4: 0
B5: Masa del vehículo, m | C5: 1200 | D5: kg | AA5: =B30 -> 2000 | AB5: =C30 -> 135 | AC5: =0.377*AA5*$C$6/$C$43 -> 14.897125 | AD5: =AB5*$C$43*$C$7/$C$6 -> 6149.5759 | AE5: =0.377*AA5*$C$6/$C$44 -> 26.401835 | AF5: =AB5*$C$44*$C$7/$C$6 -> 3469.8724 | AG5: =0.377*AA5*$C$6/$C$45 -> 40.402809 | AH5: =AB5*$C$45*$C$7/$C$6 -> 2267.4414 | AI5: =0.377*AA5*$C$6/$C$46 -> 54.981142 | AJ5: =AB5*$C$46*$C$7/$C$6 -> 1666.2259 | AK5: =0.377*AA5*$C$6/$C$47 -> 70.173299 | AL5: =AB5*$C$47*$C$7/$C$6 -> 1305.4966 | AM5: =($C$5*9.81*($C$8*COS(ATAN($C$12/100))+SIN(ATAN($C$12/100)))+0.5*$C$11*$C$9*$C$10*(AI5/3.6)^2) -> 266.14818 | AN5: =AJ5-AM5 -> 1400.0777 | AO5: =($C$5*9.81*($C$8*COS(ATAN($C$12/100))+SIN(ATAN($C$12/100)))+0.5*$C$11*$C$9*$C$10*(AK5/3.6)^2) -> 322.48495 | AP5: =AL5-AO5 -> 983.01161 | AQ5: =IF(AND(AN5>=0,AN6<0),1,0) -> 0 | AR5: =IF(AQ5=1,AI5+AN5/(AN5-AN6)*(AI6-AI5),0) -> 0 | AS5: =IF(AND(AP5>=0,AP6<0),1,0) -> 0 | AT5: =IF(AS5=1,AK5+AP5/(AP5-AP6)*(AK6-AK5),0) -> 0 | AV5: =20 -> 20 | AW5: =($C$5*9.81*($C$8*COS(ATAN($C$12/100))+SIN(ATAN($C$12/100)))+0.5*$C$11*$C$9*$C$10*(AV5/3.6)^2) -> 188.43185 | BA5: =$D$43 -> 40.967094 | BB5: =$C$20*$C$44/$C$43 -> 3103.352 | BS5: =0+$BS$2*COS(RADIANS((0+(360-(0))*1/36))) -> 0.32609528 | BT5: =0+$BS$2*SIN(RADIANS((0+(360-(0))*1/36))) -> 0.057499397 | BU5: =1+$BT$2*COS(RADIANS((0+(360-(0))*1/36))) -> 1.6587125 | BV5: =0+$BT$2*SIN(RADIANS((0+(360-(0))*1/36))) -> 0.11614878 | BW5: =$BS$2*COS(RADIANS($BU$2)) -> 0.33112583 | BX5: =$BS$2*SIN(RADIANS($BU$2)) -> -2.4340698e-16 | BY5: =1+$BT$2*COS(RADIANS($BV$2)) -> 1.6659641 | BZ5: =$BT$2*SIN(RADIANS($BV$2)) -> 0.062325205
B6: Radio dinámico de la rueda, r | C6: 0.29 | D6: m | AA6: =B31 -> 2500 | AB6: =C31 -> 142 | AC6: =0.377*AA6*$C$6/$C$43 -> 18.621406 | AD6: =AB6*$C$43*$C$7/$C$6 -> 6468.4428 | AE6: =0.377*AA6*$C$6/$C$44 -> 33.002294 | AF6: =AB6*$C$44*$C$7/$C$6 -> 3649.7917 | AG6: =0.377*AA6*$C$6/$C$45 -> 50.503511 | AH6: =AB6*$C$45*$C$7/$C$6 -> 2385.0124 | AI6: =0.377*AA6*$C$6/$C$46 -> 68.726427 | AJ6: =AB6*$C$46*$C$7/$C$6 -> 1752.6228 | AK6: =0.377*AA6*$C$6/$C$47 -> 87.716624 | AL6: =AB6*$C$47*$C$7/$C$6 -> 1373.189 | AM6: =($C$5*9.81*($C$8*COS(ATAN($C$12/100))+SIN(ATAN($C$12/100)))+0.5*$C$11*$C$9*$C$10*(AI6/3.6)^2) -> 316.53027 | AN6: =AJ6-AM6 -> 1436.0925 | AO6: =($C$5*9.81*($C$8*COS(ATAN($C$12/100))+SIN(ATAN($C$12/100)))+0.5*$C$11*$C$9*$C$10*(AK6/3.6)^2) -> 404.55648 | AP6: =AL6-AO6 -> 968.63249 | AQ6: =IF(AND(AN6>=0,AN7<0),1,0) -> 0 | AR6: =IF(AQ6=1,AI6+AN6/(AN6-AN7)*(AI7-AI6),0) -> 0 | AS6: =IF(AND(AP6>=0,AP7<0),1,0) -> 0 | AT6: =IF(AS6=1,AK6+AP6/(AP6-AP7)*(AK7-AK6),0) -> 0 | AV6: =30 -> 30 | AW6: =($C$5*9.81*($C$8*COS(ATAN($C$12/100))+SIN(ATAN($C$12/100)))+0.5*$C$11*$C$9*$C$10*(AV6/3.6)^2) -> 203.24667 | BA6: =$D$44 -> 72.605047 | BB6: =$C$20 -> 5500 | BS6: =0+$BS$2*COS(RADIANS((0+(360-(0))*2/36))) -> 0.3111565 | BT6: =0+$BS$2*SIN(RADIANS((0+(360-(0))*2/36))) -> 0.1132517 | BU6: =1+$BT$2*COS(RADIANS((0+(360-(0))*2/36))) -> 1.6285361 | BV6: =0+$BT$2*SIN(RADIANS((0+(360-(0))*2/36))) -> 0.22876844 | BW6: 0 | BX6: 0 | BY6: 1 | BZ6: 0
B7: Rendimiento de la transmisión, η | C7: 0.9 | AA7: =B32 -> 3000 | AB7: =C32 -> 146 | AC7: =0.377*AA7*$C$6/$C$43 -> 22.345687 | AD7: =AB7*$C$43*$C$7/$C$6 -> 6650.6524 | AE7: =0.377*AA7*$C$6/$C$44 -> 39.602753 | AF7: =AB7*$C$44*$C$7/$C$6 -> 3752.6028 | AG7: =0.377*AA7*$C$6/$C$45 -> 60.604213 | AH7: =AB7*$C$45*$C$7/$C$6 -> 2452.1959 | AI7: =0.377*AA7*$C$6/$C$46 -> 82.471712 | AJ7: =AB7*$C$46*$C$7/$C$6 -> 1801.9924 | AK7: =0.377*AA7*$C$6/$C$47 -> 105.25995 | AL7: =AB7*$C$47*$C$7/$C$6 -> 1411.8703 | AM7: =($C$5*9.81*($C$8*COS(ATAN($C$12/100))+SIN(ATAN($C$12/100)))+0.5*$C$11*$C$9*$C$10*(AI7/3.6)^2) -> 378.1084 | AN7: =AJ7-AM7 -> 1423.884 | AO7: =($C$5*9.81*($C$8*COS(ATAN($C$12/100))+SIN(ATAN($C$12/100)))+0.5*$C$11*$C$9*$C$10*(AK7/3.6)^2) -> 504.86613 | AP7: =AL7-AO7 -> 907.00422 | AQ7: =IF(AND(AN7>=0,AN8<0),1,0) -> 0 | AR7: =IF(AQ7=1,AI7+AN7/(AN7-AN8)*(AI8-AI7),0) -> 0 | AS7: =IF(AND(AP7>=0,AP8<0),1,0) -> 0 | AT7: =IF(AS7=1,AK7+AP7/(AP7-AP8)*(AK8-AK7),0) -> 0 | AV7: =40 -> 40 | AW7: =($C$5*9.81*($C$8*COS(ATAN($C$12/100))+SIN(ATAN($C$12/100)))+0.5*$C$11*$C$9*$C$10*(AV7/3.6)^2) -> 223.98741 | BA7: =$D$44 -> 72.605047 | BB7: =$C$20*$C$45/$C$44 -> 3594.0594 | BS7: =0+$BS$2*COS(RADIANS((0+(360-(0))*3/36))) -> 0.28676338 | BT7: =0+$BS$2*SIN(RADIANS((0+(360-(0))*3/36))) -> 0.16556291 | BU7: =1+$BT$2*COS(RADIANS((0+(360-(0))*3/36))) -> 1.579262 | BV7: =0+$BT$2*SIN(RADIANS((0+(360-(0))*3/36))) -> 0.33443709 | BW7: =$BS$2*COS(RADIANS($BU$2+120)) -> -0.16556291 | BX7: =$BS$2*SIN(RADIANS($BU$2+120)) -> 0.28676338 | BY7: =1+$BT$2*COS(RADIANS($BV$2+120)) -> 0.61304272 | BZ7: =$BT$2*SIN(RADIANS($BV$2+120)) -> 0.54557925
B8: Coeficiente de rodadura, Cr | C8: 0.015 | AA8: =B33 -> 3500 | AB8: =C33 -> 148 | AC8: =0.377*AA8*$C$6/$C$43 -> 26.069969 | AD8: =AB8*$C$43*$C$7/$C$6 -> 6741.7572 | AE8: =0.377*AA8*$C$6/$C$44 -> 46.203212 | AF8: =AB8*$C$44*$C$7/$C$6 -> 3804.0083 | AG8: =0.377*AA8*$C$6/$C$45 -> 70.704915 | AH8: =AB8*$C$45*$C$7/$C$6 -> 2485.7876 | AI8: =0.377*AA8*$C$6/$C$46 -> 96.216998 | AJ8: =AB8*$C$46*$C$7/$C$6 -> 1826.6772 | AK8: =0.377*AA8*$C$6/$C$47 -> 122.80327 | AL8: =AB8*$C$47*$C$7/$C$6 -> 1431.211 | AM8: =($C$5*9.81*($C$8*COS(ATAN($C$12/100))+SIN(ATAN($C$12/100)))+0.5*$C$11*$C$9*$C$10*(AI8/3.6)^2) -> 450.88254 | AN8: =AJ8-AM8 -> 1375.7947 | AO8: =($C$5*9.81*($C$8*COS(ATAN($C$12/100))+SIN(ATAN($C$12/100)))+0.5*$C$11*$C$9*$C$10*(AK8/3.6)^2) -> 623.4139 | AP8: =AL8-AO8 -> 807.79714 | AQ8: =IF(AND(AN8>=0,AN9<0),1,0) -> 0 | AR8: =IF(AQ8=1,AI8+AN8/(AN8-AN9)*(AI9-AI8),0) -> 0 | AS8: =IF(AND(AP8>=0,AP9<0),1,0) -> 0 | AT8: =IF(AS8=1,AK8+AP8/(AP8-AP9)*(AK9-AK8),0) -> 0 | AV8: =50 -> 50 | AW8: =($C$5*9.81*($C$8*COS(ATAN($C$12/100))+SIN(ATAN($C$12/100)))+0.5*$C$11*$C$9*$C$10*(AV8/3.6)^2) -> 250.65407 | BA8: =$D$45 -> 111.10772 | BB8: =$C$20 -> 5500 | BS8: =0+$BS$2*COS(RADIANS((0+(360-(0))*4/36))) -> 0.2536571 | BT8: =0+$BS$2*SIN(RADIANS((0+(360-(0))*4/36))) -> 0.21284358 | BU8: =1+$BT$2*COS(RADIANS((0+(360-(0))*4/36))) -> 1.5123873 | BV8: =0+$BT$2*SIN(RADIANS((0+(360-(0))*4/36))) -> 0.42994403 | BW8: 0 | BX8: 0 | BY8: 1 | BZ8: 0
B9: Coeficiente aerodinámico, Cx | C9: 0.32 | AA9: =B34 -> 4000 | AB9: =C34 -> 147 | AC9: =0.377*AA9*$C$6/$C$43 -> 29.79425 | AD9: =AB9*$C$43*$C$7/$C$6 -> 6696.2048 | AE9: =0.377*AA9*$C$6/$C$44 -> 52.803671 | AF9: =AB9*$C$44*$C$7/$C$6 -> 3778.3055 | AG9: =0.377*AA9*$C$6/$C$45 -> 80.805617 | AH9: =AB9*$C$45*$C$7/$C$6 -> 2468.9917 | AI9: =0.377*AA9*$C$6/$C$46 -> 109.96228 | AJ9: =AB9*$C$46*$C$7/$C$6 -> 1814.3348 | AK9: =0.377*AA9*$C$6/$C$47 -> 140.3466 | AL9: =AB9*$C$47*$C$7/$C$6 -> 1421.5407 | AM9: =($C$5*9.81*($C$8*COS(ATAN($C$12/100))+SIN(ATAN($C$12/100)))+0.5*$C$11*$C$9*$C$10*(AI9/3.6)^2) -> 534.8527 | AN9: =AJ9-AM9 -> 1279.4821 | AO9: =($C$5*9.81*($C$8*COS(ATAN($C$12/100))+SIN(ATAN($C$12/100)))+0.5*$C$11*$C$9*$C$10*(AK9/3.6)^2) -> 760.19978 | AP9: =AL9-AO9 -> 661.34091 | AQ9: =IF(AND(AN9>=0,AN10<0),1,0) -> 0 | AR9: =IF(AQ9=1,AI9+AN9/(AN9-AN10)*(AI10-AI9),0) -> 0 | AS9: =IF(AND(AP9>=0,AP10<0),1,0) -> 0 | AT9: =IF(AS9=1,AK9+AP9/(AP9-AP10)*(AK10-AK9),0) -> 0 | AV9: =60 -> 60 | AW9: =($C$5*9.81*($C$8*COS(ATAN($C$12/100))+SIN(ATAN($C$12/100)))+0.5*$C$11*$C$9*$C$10*(AV9/3.6)^2) -> 283.24667 | BA9: =$D$45 -> 111.10772 | BB9: =$C$20*$C$46/$C$45 -> 4041.6667 | BS9: =0+$BS$2*COS(RADIANS((0+(360-(0))*5/36))) -> 0.21284358 | BT9: =0+$BS$2*SIN(RADIANS((0+(360-(0))*5/36))) -> 0.2536571 | BU9: =1+$BT$2*COS(RADIANS((0+(360-(0))*5/36))) -> 1.429944 | BV9: =0+$BT$2*SIN(RADIANS((0+(360-(0))*5/36))) -> 0.51238734 | BW9: =$BS$2*COS(RADIANS($BU$2+240)) -> -0.16556291 | BX9: =$BS$2*SIN(RADIANS($BU$2+240)) -> -0.28676338 | BY9: =1+$BT$2*COS(RADIANS($BV$2+240)) -> 0.72099314 | BZ9: =$BT$2*SIN(RADIANS($BV$2+240)) -> -0.60790446
B10: Área frontal, A | C10: 2 | D10: m² | AA10: =B35 -> 4500 | AB10: =C35 -> 144 | AC10: =0.377*AA10*$C$6/$C$43 -> 33.518531 | AD10: =AB10*$C$43*$C$7/$C$6 -> 6559.5476 | AE10: =0.377*AA10*$C$6/$C$44 -> 59.404129 | AF10: =AB10*$C$44*$C$7/$C$6 -> 3701.1972 | AG10: =0.377*AA10*$C$6/$C$45 -> 90.906319 | AH10: =AB10*$C$45*$C$7/$C$6 -> 2418.6041 | AI10: =0.377*AA10*$C$6/$C$46 -> 123.70757 | AJ10: =AB10*$C$46*$C$7/$C$6 -> 1777.3076 | AK10: =0.377*AA10*$C$6/$C$47 -> 157.88992 | AL10: =AB10*$C$47*$C$7/$C$6 -> 1392.5297 | AM10: =($C$5*9.81*($C$8*COS(ATAN($C$12/100))+SIN(ATAN($C$12/100)))+0.5*$C$11*$C$9*$C$10*(AI10/3.6)^2) -> 630.01889 | AN10: =AJ10-AM10 -> 1147.2887 | AO10: =($C$5*9.81*($C$8*COS(ATAN($C$12/100))+SIN(ATAN($C$12/100)))+0.5*$C$11*$C$9*$C$10*(AK10/3.6)^2) -> 915.22379 | AP10: =AL10-AO10 -> 477.30587 | AQ10: =IF(AND(AN10>=0,AN11<0),1,0) -> 0 | AR10: =IF(AQ10=1,AI10+AN10/(AN10-AN11)*(AI11-AI10),0) -> 0 | AS10: =IF(AND(AP10>=0,AP11<0),1,0) -> 0 | AT10: =IF(AS10=1,AK10+AP10/(AP10-AP11)*(AK11-AK10),0) -> 0 | AV10: =70 -> 70 | AW10: =($C$5*9.81*($C$8*COS(ATAN($C$12/100))+SIN(ATAN($C$12/100)))+0.5*$C$11*$C$9*$C$10*(AV10/3.6)^2) -> 321.76519 | BA10: =$D$46 -> 151.19814 | BB10: =$C$20 -> 5500 | BS10: =0+$BS$2*COS(RADIANS((0+(360-(0))*6/36))) -> 0.16556291 | BT10: =0+$BS$2*SIN(RADIANS((0+(360-(0))*6/36))) -> 0.28676338 | BU10: =1+$BT$2*COS(RADIANS((0+(360-(0))*6/36))) -> 1.3344371 | BV10: =0+$BT$2*SIN(RADIANS((0+(360-(0))*6/36))) -> 0.57926203
B11: Densidad del aire, ρ | C11: 1.2 | D11: kg/m³ | AA11: =B36 -> 5000 | AB11: =C36 -> 138 | AC11: =0.377*AA11*$C$6/$C$43 -> 37.242812 | AD11: =AB11*$C$43*$C$7/$C$6 -> 6286.2331 | AE11: =0.377*AA11*$C$6/$C$44 -> 66.004588 | AF11: =AB11*$C$44*$C$7/$C$6 -> 3546.9807 | AG11: =0.377*AA11*$C$6/$C$45 -> 101.00702 | AH11: =AB11*$C$45*$C$7/$C$6 -> 2317.829 | AI11: =0.377*AA11*$C$6/$C$46 -> 137.45285 | AJ11: =AB11*$C$46*$C$7/$C$6 -> 1703.2531 | AK11: =0.377*AA11*$C$6/$C$47 -> 175.43325 | AL11: =AB11*$C$47*$C$7/$C$6 -> 1334.5076 | AM11: =($C$5*9.81*($C$8*COS(ATAN($C$12/100))+SIN(ATAN($C$12/100)))+0.5*$C$11*$C$9*$C$10*(AI11/3.6)^2) -> 736.3811 | AN11: =AJ11-AM11 -> 966.87201 | AO11: =($C$5*9.81*($C$8*COS(ATAN($C$12/100))+SIN(ATAN($C$12/100)))+0.5*$C$11*$C$9*$C$10*(AK11/3.6)^2) -> 1088.4859 | AP11: =AL11-AO11 -> 246.02168 | AQ11: =IF(AND(AN11>=0,AN12<0),1,0) -> 0 | AR11: =IF(AQ11=1,AI11+AN11/(AN11-AN12)*(AI12-AI11),0) -> 0 | AS11: =IF(AND(AP11>=0,AP12<0),1,0) -> 1 | AT11: =IF(AS11=1,AK11+AP11/(AP11-AP12)*(AK12-AK11),0) -> 191.48618 | AV11: =80 -> 80 | AW11: =($C$5*9.81*($C$8*COS(ATAN($C$12/100))+SIN(ATAN($C$12/100)))+0.5*$C$11*$C$9*$C$10*(AV11/3.6)^2) -> 366.20963 | BA11: =$D$46 -> 151.19814 | BB11: =$C$20*$C$47/$C$46 -> 4309.2784 | BS11: =0+$BS$2*COS(RADIANS((0+(360-(0))*7/36))) -> 0.1132517 | BT11: =0+$BS$2*SIN(RADIANS((0+(360-(0))*7/36))) -> 0.3111565 | BU11: =1+$BT$2*COS(RADIANS((0+(360-(0))*7/36))) -> 1.2287684 | BV11: =0+$BT$2*SIN(RADIANS((0+(360-(0))*7/36))) -> 0.62853612
B12: Pendiente de la vía | C12: 0 | D12: % | AA12: =B37 -> 5500 | AB12: =C37 -> 130 | AC12: =0.377*AA12*$C$6/$C$43 -> 40.967094 | AD12: =AB12*$C$43*$C$7/$C$6 -> 5921.8138 | AE12: =0.377*AA12*$C$6/$C$44 -> 72.605047 | AF12: =AB12*$C$44*$C$7/$C$6 -> 3341.3586 | AG12: =0.377*AA12*$C$6/$C$45 -> 111.10772 | AH12: =AB12*$C$45*$C$7/$C$6 -> 2183.4621 | AI12: =0.377*AA12*$C$6/$C$46 -> 151.19814 | AJ12: =AB12*$C$46*$C$7/$C$6 -> 1604.5138 | AK12: =0.377*AA12*$C$6/$C$47 -> 192.97657 | AL12: =AB12*$C$47*$C$7/$C$6 -> 1257.1448 | AM12: =($C$5*9.81*($C$8*COS(ATAN($C$12/100))+SIN(ATAN($C$12/100)))+0.5*$C$11*$C$9*$C$10*(AI12/3.6)^2) -> 853.93933 | AN12: =AJ12-AM12 -> 750.57446 | AO12: =($C$5*9.81*($C$8*COS(ATAN($C$12/100))+SIN(ATAN($C$12/100)))+0.5*$C$11*$C$9*$C$10*(AK12/3.6)^2) -> 1279.9861 | AP12: =AL12-AO12 -> -22.841322 | AQ12: =IF(AND(AN12>=0,AN13<0),1,0) -> 0 | AR12: =IF(AQ12=1,AI12+AN12/(AN12-AN13)*(AI13-AI12),0) -> 0 | AS12: =IF(AND(AP12>=0,AP13<0),1,0) -> 0 | AT12: =IF(AS12=1,AK12+AP12/(AP12-AP13)*(AK13-AK12),0) -> 0 | AV12: =90 -> 90 | AW12: =($C$5*9.81*($C$8*COS(ATAN($C$12/100))+SIN(ATAN($C$12/100)))+0.5*$C$11*$C$9*$C$10*(AV12/3.6)^2) -> 416.58 | BA12: =$D$47 -> 192.97657 | BB12: =$C$20 -> 5500 | BS12: =0+$BS$2*COS(RADIANS((0+(360-(0))*8/36))) -> 0.057499397 | BT12: =0+$BS$2*SIN(RADIANS((0+(360-(0))*8/36))) -> 0.32609528 | BU12: =1+$BT$2*COS(RADIANS((0+(360-(0))*8/36))) -> 1.1161488 | BV12: =0+$BT$2*SIN(RADIANS((0+(360-(0))*8/36))) -> 0.65871247
B13: Transmisión | AA13: =B38 -> 6000 | AB13: =C38 -> 120 | AC13: =0.377*AA13*$C$6/$C$43 -> 44.691375 | AD13: =AB13*$C$43*$C$7/$C$6 -> 5466.2897 | AE13: =0.377*AA13*$C$6/$C$44 -> 79.205506 | AF13: =AB13*$C$44*$C$7/$C$6 -> 3084.331 | AG13: =0.377*AA13*$C$6/$C$45 -> 121.20843 | AH13: =AB13*$C$45*$C$7/$C$6 -> 2015.5034 | AI13: =0.377*AA13*$C$6/$C$46 -> 164.94342 | AJ13: =AB13*$C$46*$C$7/$C$6 -> 1481.0897 | AK13: =0.377*AA13*$C$6/$C$47 -> 210.5199 | AL13: =AB13*$C$47*$C$7/$C$6 -> 1160.4414 | AM13: =($C$5*9.81*($C$8*COS(ATAN($C$12/100))+SIN(ATAN($C$12/100)))+0.5*$C$11*$C$9*$C$10*(AI13/3.6)^2) -> 982.69358 | AN13: =AJ13-AM13 -> 498.39607 | AO13: =($C$5*9.81*($C$8*COS(ATAN($C$12/100))+SIN(ATAN($C$12/100)))+0.5*$C$11*$C$9*$C$10*(AK13/3.6)^2) -> 1489.7245 | AP13: =AL13-AO13 -> -329.28313 | AQ13: =IF(AND(AN13>=0,AN14<0),1,0) -> 0 | AR13: =IF(AQ13=1,AI13+AN13/(AN13-AN14)*(AI14-AI13),0) -> 0 | AS13: =IF(AND(AP13>=0,AP14<0),1,0) -> 0 | AT13: =IF(AS13=1,AK13+AP13/(AP13-AP14)*(AK14-AK13),0) -> 0 | AV13: =100 -> 100 | AW13: =($C$5*9.81*($C$8*COS(ATAN($C$12/100))+SIN(ATAN($C$12/100)))+0.5*$C$11*$C$9*$C$10*(AV13/3.6)^2) -> 472.8763 | BS13: =0+$BS$2*COS(RADIANS((0+(360-(0))*9/36))) -> 2.0283915e-17 | BT13: =0+$BS$2*SIN(RADIANS((0+(360-(0))*9/36))) -> 0.33112583 | BU13: =1+$BT$2*COS(RADIANS((0+(360-(0))*9/36))) -> 1 | BV13: =0+$BT$2*SIN(RADIANS((0+(360-(0))*9/36))) -> 0.66887417
B14: Relación del grupo reductor, i_d | C14: 4.1 | AA14: =B39 -> 6500 | AB14: =C39 -> 105 | AC14: =0.377*AA14*$C$6/$C$43 -> 48.415656 | AD14: =AB14*$C$43*$C$7/$C$6 -> 4783.0034 | AE14: =0.377*AA14*$C$6/$C$44 -> 85.805965 | AF14: =AB14*$C$44*$C$7/$C$6 -> 2698.7897 | AG14: =0.377*AA14*$C$6/$C$45 -> 131.30913 | AH14: =AB14*$C$45*$C$7/$C$6 -> 1763.5655 | AI14: =0.377*AA14*$C$6/$C$46 -> 178.68871 | AJ14: =AB14*$C$46*$C$7/$C$6 -> 1295.9534 | AK14: =0.377*AA14*$C$6/$C$47 -> 228.06322 | AL14: =AB14*$C$47*$C$7/$C$6 -> 1015.3862 | AM14: =($C$5*9.81*($C$8*COS(ATAN($C$12/100))+SIN(ATAN($C$12/100)))+0.5*$C$11*$C$9*$C$10*(AI14/3.6)^2) -> 1122.6439 | AN14: =AJ14-AM14 -> 173.30959 | AO14: =($C$5*9.81*($C$8*COS(ATAN($C$12/100))+SIN(ATAN($C$12/100)))+0.5*$C$11*$C$9*$C$10*(AK14/3.6)^2) -> 1717.701 | AP14: =AL14-AO14 -> -702.31478 | AV14: =110 -> 110 | AW14: =($C$5*9.81*($C$8*COS(ATAN($C$12/100))+SIN(ATAN($C$12/100)))+0.5*$C$11*$C$9*$C$10*(AV14/3.6)^2) -> 535.09852 | BS14: =0+$BS$2*COS(RADIANS((0+(360-(0))*10/36))) -> -0.057499397 | BT14: =0+$BS$2*SIN(RADIANS((0+(360-(0))*10/36))) -> 0.32609528 | BU14: =1+$BT$2*COS(RADIANS((0+(360-(0))*10/36))) -> 0.88385122 | BV14: =0+$BT$2*SIN(RADIANS((0+(360-(0))*10/36))) -> 0.65871247
B15: Relación de 1ª marcha, i1 | C15: 3.58 | AV15: =120 -> 120 | AW15: =($C$5*9.81*($C$8*COS(ATAN($C$12/100))+SIN(ATAN($C$12/100)))+0.5*$C$11*$C$9*$C$10*(AV15/3.6)^2) -> 603.24667 | BS15: =0+$BS$2*COS(RADIANS((0+(360-(0))*11/36))) -> -0.1132517 | BT15: =0+$BS$2*SIN(RADIANS((0+(360-(0))*11/36))) -> 0.3111565 | BU15: =1+$BT$2*COS(RADIANS((0+(360-(0))*11/36))) -> 0.77123156 | BV15: =0+$BT$2*SIN(RADIANS((0+(360-(0))*11/36))) -> 0.62853612
B16: Relación de 2ª marcha, i2 | C16: 2.02 | AV16: =130 -> 130 | AW16: =($C$5*9.81*($C$8*COS(ATAN($C$12/100))+SIN(ATAN($C$12/100)))+0.5*$C$11*$C$9*$C$10*(AV16/3.6)^2) -> 677.32074 | BS16: =0+$BS$2*COS(RADIANS((0+(360-(0))*12/36))) -> -0.16556291 | BT16: =0+$BS$2*SIN(RADIANS((0+(360-(0))*12/36))) -> 0.28676338 | BU16: =1+$BT$2*COS(RADIANS((0+(360-(0))*12/36))) -> 0.66556291 | BV16: =0+$BT$2*SIN(RADIANS((0+(360-(0))*12/36))) -> 0.57926203
B17: Relación de 3ª marcha, i3 | C17: 1.32 | AV17: =140 -> 140 | AW17: =($C$5*9.81*($C$8*COS(ATAN($C$12/100))+SIN(ATAN($C$12/100)))+0.5*$C$11*$C$9*$C$10*(AV17/3.6)^2) -> 757.32074 | BS17: =0+$BS$2*COS(RADIANS((0+(360-(0))*13/36))) -> -0.21284358 | BT17: =0+$BS$2*SIN(RADIANS((0+(360-(0))*13/36))) -> 0.2536571 | BU17: =1+$BT$2*COS(RADIANS((0+(360-(0))*13/36))) -> 0.57005597 | BV17: =0+$BT$2*SIN(RADIANS((0+(360-(0))*13/36))) -> 0.51238734
B18: Relación de 4ª marcha, i4 | C18: 0.97 | AV18: =150 -> 150 | AW18: =($C$5*9.81*($C$8*COS(ATAN($C$12/100))+SIN(ATAN($C$12/100)))+0.5*$C$11*$C$9*$C$10*(AV18/3.6)^2) -> 843.24667 | BS18: =0+$BS$2*COS(RADIANS((0+(360-(0))*14/36))) -> -0.2536571 | BT18: =0+$BS$2*SIN(RADIANS((0+(360-(0))*14/36))) -> 0.21284358 | BU18: =1+$BT$2*COS(RADIANS((0+(360-(0))*14/36))) -> 0.48761266 | BV18: =0+$BT$2*SIN(RADIANS((0+(360-(0))*14/36))) -> 0.42994403
B19: Relación de 5ª marcha, i5 | C19: 0.76 | T19: Cambie la posición en la aceleración (celda C24): el punto rojo recorre el diagrama de sierra y el par de engranajes muestra la marcha engranada en ese instante. | AV19: =160 -> 160 | AW19: =($C$5*9.81*($C$8*COS(ATAN($C$12/100))+SIN(ATAN($C$12/100)))+0.5*$C$11*$C$9*$C$10*(AV19/3.6)^2) -> 935.09852 | BS19: =0+$BS$2*COS(RADIANS((0+(360-(0))*15/36))) -> -0.28676338 | BT19: =0+$BS$2*SIN(RADIANS((0+(360-(0))*15/36))) -> 0.16556291 | BU19: =1+$BT$2*COS(RADIANS((0+(360-(0))*15/36))) -> 0.42073797 | BV19: =0+$BT$2*SIN(RADIANS((0+(360-(0))*15/36))) -> 0.33443709
B20: Régimen de cambio de marcha, n_c | C20: 5500 | D20: min⁻¹ | AV20: =170 -> 170 | AW20: =($C$5*9.81*($C$8*COS(ATAN($C$12/100))+SIN(ATAN($C$12/100)))+0.5*$C$11*$C$9*$C$10*(AV20/3.6)^2) -> 1032.8763 | BS20: =0+$BS$2*COS(RADIANS((0+(360-(0))*16/36))) -> -0.3111565 | BT20: =0+$BS$2*SIN(RADIANS((0+(360-(0))*16/36))) -> 0.1132517 | BU20: =1+$BT$2*COS(RADIANS((0+(360-(0))*16/36))) -> 0.37146388 | BV20: =0+$BT$2*SIN(RADIANS((0+(360-(0))*16/36))) -> 0.22876844
B21: Coeficiente de adherencia, μ | C21: 0.8 | AV21: =180 -> 180 | AW21: =($C$5*9.81*($C$8*COS(ATAN($C$12/100))+SIN(ATAN($C$12/100)))+0.5*$C$11*$C$9*$C$10*(AV21/3.6)^2) -> 1136.58 | BS21: =0+$BS$2*COS(RADIANS((0+(360-(0))*17/36))) -> -0.32609528 | BT21: =0+$BS$2*SIN(RADIANS((0+(360-(0))*17/36))) -> 0.057499397 | BU21: =1+$BT$2*COS(RADIANS((0+(360-(0))*17/36))) -> 0.34128753 | BV21: =0+$BT$2*SIN(RADIANS((0+(360-(0))*17/36))) -> 0.11614878
B22: Peso sobre el eje motriz | C22: 60 | D22: % | AV22: =190 -> 190 | AW22: =($C$5*9.81*($C$8*COS(ATAN($C$12/100))+SIN(ATAN($C$12/100)))+0.5*$C$11*$C$9*$C$10*(AV22/3.6)^2) -> 1246.2096 | BS22: =0+$BS$2*COS(RADIANS((0+(360-(0))*18/36))) -> -0.33112583 | BT22: =0+$BS$2*SIN(RADIANS((0+(360-(0))*18/36))) -> 4.056783e-17 | BU22: =1+$BT$2*COS(RADIANS((0+(360-(0))*18/36))) -> 0.33112583 | BV22: =0+$BT$2*SIN(RADIANS((0+(360-(0))*18/36))) -> 8.1947016e-17
B23: Punto de estudio | AV23: =200 -> 200 | AW23: =($C$5*9.81*($C$8*COS(ATAN($C$12/100))+SIN(ATAN($C$12/100)))+0.5*$C$11*$C$9*$C$10*(AV23/3.6)^2) -> 1361.7652 | BS23: =0+$BS$2*COS(RADIANS((0+(360-(0))*19/36))) -> -0.32609528 | BT23: =0+$BS$2*SIN(RADIANS((0+(360-(0))*19/36))) -> -0.057499397 | BU23: =1+$BT$2*COS(RADIANS((0+(360-(0))*19/36))) -> 0.34128753 | BV23: =0+$BT$2*SIN(RADIANS((0+(360-(0))*19/36))) -> -0.11614878
B24: Posición en la aceleración (0 = parado; 100 = v a n_c en 5ª) | C24: 30 | D24: % | AV24: =210 -> 210 | AW24: =($C$5*9.81*($C$8*COS(ATAN($C$12/100))+SIN(ATAN($C$12/100)))+0.5*$C$11*$C$9*$C$10*(AV24/3.6)^2) -> 1483.2467 | BS24: =0+$BS$2*COS(RADIANS((0+(360-(0))*20/36))) -> -0.3111565 | BT24: =0+$BS$2*SIN(RADIANS((0+(360-(0))*20/36))) -> -0.1132517 | BU24: =1+$BT$2*COS(RADIANS((0+(360-(0))*20/36))) -> 0.37146388 | BV24: =0+$BT$2*SIN(RADIANS((0+(360-(0))*20/36))) -> -0.22876844
AV25: =220 -> 220 | AW25: =($C$5*9.81*($C$8*COS(ATAN($C$12/100))+SIN(ATAN($C$12/100)))+0.5*$C$11*$C$9*$C$10*(AV25/3.6)^2) -> 1610.6541 | BS25: =0+$BS$2*COS(RADIANS((0+(360-(0))*21/36))) -> -0.28676338 | BT25: =0+$BS$2*SIN(RADIANS((0+(360-(0))*21/36))) -> -0.16556291 | BU25: =1+$BT$2*COS(RADIANS((0+(360-(0))*21/36))) -> 0.42073797 | BV25: =0+$BT$2*SIN(RADIANS((0+(360-(0))*21/36))) -> -0.33443709
B26: Curva del motor a plena carga (edite el par) | BS26: =0+$BS$2*COS(RADIANS((0+(360-(0))*22/36))) -> -0.2536571 | BT26: =0+$BS$2*SIN(RADIANS((0+(360-(0))*22/36))) -> -0.21284358 | BU26: =1+$BT$2*COS(RADIANS((0+(360-(0))*22/36))) -> 0.48761266 | BV26: =0+$BT$2*SIN(RADIANS((0+(360-(0))*22/36))) -> -0.42994403
B27: Régimen n [min⁻¹] | C27: Par T [N·m] | D27: Potencia P [kW] | BS27: =0+$BS$2*COS(RADIANS((0+(360-(0))*23/36))) -> -0.21284358 | BT27: =0+$BS$2*SIN(RADIANS((0+(360-(0))*23/36))) -> -0.2536571 | BU27: =1+$BT$2*COS(RADIANS((0+(360-(0))*23/36))) -> 0.57005597 | BV27: =0+$BT$2*SIN(RADIANS((0+(360-(0))*23/36))) -> -0.51238734
B28: 1000 | C28: 110 | D28: =B28*C28/9550 -> 11.518325 | BS28: =0+$BS$2*COS(RADIANS((0+(360-(0))*24/36))) -> -0.16556291 | BT28: =0+$BS$2*SIN(RADIANS((0+(360-(0))*24/36))) -> -0.28676338 | BU28: =1+$BT$2*COS(RADIANS((0+(360-(0))*24/36))) -> 0.66556291 | BV28: =0+$BT$2*SIN(RADIANS((0+(360-(0))*24/36))) -> -0.57926203
B29: 1500 | C29: 125 | D29: =B29*C29/9550 -> 19.633508 | BS29: =0+$BS$2*COS(RADIANS((0+(360-(0))*25/36))) -> -0.1132517 | BT29: =0+$BS$2*SIN(RADIANS((0+(360-(0))*25/36))) -> -0.3111565 | BU29: =1+$BT$2*COS(RADIANS((0+(360-(0))*25/36))) -> 0.77123156 | BV29: =0+$BT$2*SIN(RADIANS((0+(360-(0))*25/36))) -> -0.62853612
B30: 2000 | C30: 135 | D30: =B30*C30/9550 -> 28.272251 | BS30: =0+$BS$2*COS(RADIANS((0+(360-(0))*26/36))) -> -0.057499397 | BT30: =0+$BS$2*SIN(RADIANS((0+(360-(0))*26/36))) -> -0.32609528 | BU30: =1+$BT$2*COS(RADIANS((0+(360-(0))*26/36))) -> 0.88385122 | BV30: =0+$BT$2*SIN(RADIANS((0+(360-(0))*26/36))) -> -0.65871247
B31: 2500 | C31: 142 | D31: =B31*C31/9550 -> 37.172775 | BS31: =0+$BS$2*COS(RADIANS((0+(360-(0))*27/36))) -> -6.0851744e-17 | BT31: =0+$BS$2*SIN(RADIANS((0+(360-(0))*27/36))) -> -0.33112583 | BU31: =1+$BT$2*COS(RADIANS((0+(360-(0))*27/36))) -> 1 | BV31: =0+$BT$2*SIN(RADIANS((0+(360-(0))*27/36))) -> -0.66887417
B32: 3000 | C32: 146 | D32: =B32*C32/9550 -> 45.863874 | BS32: =0+$BS$2*COS(RADIANS((0+(360-(0))*28/36))) -> 0.057499397 | BT32: =0+$BS$2*SIN(RADIANS((0+(360-(0))*28/36))) -> -0.32609528 | BU32: =1+$BT$2*COS(RADIANS((0+(360-(0))*28/36))) -> 1.1161488 | BV32: =0+$BT$2*SIN(RADIANS((0+(360-(0))*28/36))) -> -0.65871247
B33: 3500 | C33: 148 | D33: =B33*C33/9550 -> 54.240838 | BS33: =0+$BS$2*COS(RADIANS((0+(360-(0))*29/36))) -> 0.1132517 | BT33: =0+$BS$2*SIN(RADIANS((0+(360-(0))*29/36))) -> -0.3111565 | BU33: =1+$BT$2*COS(RADIANS((0+(360-(0))*29/36))) -> 1.2287684 | BV33: =0+$BT$2*SIN(RADIANS((0+(360-(0))*29/36))) -> -0.62853612
B34: 4000 | C34: 147 | D34: =B34*C34/9550 -> 61.570681 | BS34: =0+$BS$2*COS(RADIANS((0+(360-(0))*30/36))) -> 0.16556291 | BT34: =0+$BS$2*SIN(RADIANS((0+(360-(0))*30/36))) -> -0.28676338 | BU34: =1+$BT$2*COS(RADIANS((0+(360-(0))*30/36))) -> 1.3344371 | BV34: =0+$BT$2*SIN(RADIANS((0+(360-(0))*30/36))) -> -0.57926203
B35: 4500 | C35: 144 | D35: =B35*C35/9550 -> 67.853403 | BS35: =0+$BS$2*COS(RADIANS((0+(360-(0))*31/36))) -> 0.21284358 | BT35: =0+$BS$2*SIN(RADIANS((0+(360-(0))*31/36))) -> -0.2536571 | BU35: =1+$BT$2*COS(RADIANS((0+(360-(0))*31/36))) -> 1.429944 | BV35: =0+$BT$2*SIN(RADIANS((0+(360-(0))*31/36))) -> -0.51238734
B36: 5000 | C36: 138 | D36: =B36*C36/9550 -> 72.251309 | BS36: =0+$BS$2*COS(RADIANS((0+(360-(0))*32/36))) -> 0.2536571 | BT36: =0+$BS$2*SIN(RADIANS((0+(360-(0))*32/36))) -> -0.21284358 | BU36: =1+$BT$2*COS(RADIANS((0+(360-(0))*32/36))) -> 1.5123873 | BV36: =0+$BT$2*SIN(RADIANS((0+(360-(0))*32/36))) -> -0.42994403
B37: 5500 | C37: 130 | D37: =B37*C37/9550 -> 74.86911 | BS37: =0+$BS$2*COS(RADIANS((0+(360-(0))*33/36))) -> 0.28676338 | BT37: =0+$BS$2*SIN(RADIANS((0+(360-(0))*33/36))) -> -0.16556291 | BU37: =1+$BT$2*COS(RADIANS((0+(360-(0))*33/36))) -> 1.579262 | BV37: =0+$BT$2*SIN(RADIANS((0+(360-(0))*33/36))) -> -0.33443709
B38: 6000 | C38: 120 | D38: =B38*C38/9550 -> 75.39267 | BS38: =0+$BS$2*COS(RADIANS((0+(360-(0))*34/36))) -> 0.3111565 | BT38: =0+$BS$2*SIN(RADIANS((0+(360-(0))*34/36))) -> -0.1132517 | BU38: =1+$BT$2*COS(RADIANS((0+(360-(0))*34/36))) -> 1.6285361 | BV38: =0+$BT$2*SIN(RADIANS((0+(360-(0))*34/36))) -> -0.22876844
B39: 6500 | C39: 105 | D39: =B39*C39/9550 -> 71.465969 | BS39: =0+$BS$2*COS(RADIANS((0+(360-(0))*35/36))) -> 0.32609528 | BT39: =0+$BS$2*SIN(RADIANS((0+(360-(0))*35/36))) -> -0.057499397 | BU39: =1+$BT$2*COS(RADIANS((0+(360-(0))*35/36))) -> 1.6587125 | BV39: =0+$BT$2*SIN(RADIANS((0+(360-(0))*35/36))) -> -0.11614878
BS40: =0+$BS$2*COS(RADIANS((0+(360-(0))*36/36))) -> 0.33112583 | BT40: =0+$BS$2*SIN(RADIANS((0+(360-(0))*36/36))) -> -8.1135659e-17 | BU40: =1+$BT$2*COS(RADIANS((0+(360-(0))*36/36))) -> 1.6688742 | BV40: =0+$BT$2*SIN(RADIANS((0+(360-(0))*36/36))) -> -1.6389403e-16
...

Sheet U1 Embrague
A1: U1 · Embrague monodisco y mando hidráulico | AA1: Datos de cálculo para los gráficos (no editar) | BE1: ="Pedal al "&$C$29&" %: bomba "&FIXED($C$35,1)&" mm → bombín "&FIXED($C$36,1)&" mm" -> Pedal al 0 %: bomba 0.0 mm → bombín 0.0 mm
A2: Par que transmite el embrague, efecto del desgaste de los forros según el tipo de muelle (diafragma o helicoidales) y multiplicación de fuerza del mando hidráulico. Unidad 1: el embrague, principio de funcionamiento y comprobaciones. | AA2: desgaste | AB2: F diafr. | AC2: F helic. | AD2: T diafr. | AE2: T helic. | AF2: T motor·FS | AG2: T motor | BE2: ="Disco: R = "&FIXED($C$7*1000,0)&" mm, r = "&FIXED($C$8*1000,0)&" mm, rm = "&FIXED($C$14*1000,1)&" mm" -> Disco: R = 100 mm, r = 70 mm, rm = 85.0 mm
B3: ◄ Volver al inicio | AA3: =0 -> 0 | AB3: =$C$5*((4-AA3)*((3.2-(4-AA3))*(3.2-(4-AA3)/2)+4))/(4*((3.2-4)*(3.2-4/2)+4)) -> 4000 | AC3: =$C$5*(1-AA3/10) -> 4000 | AD3: =$C$6*AB3*$C$14*$C$9 -> 204 | AE3: =$C$6*AC3*$C$14*$C$9 -> 204 | AF3: =$C$10*$C$11 -> 177.6 | AG3: =$C$10 -> 148 | AI3: =$C$12 -> 0 | AJ3: =($C$5*((4-$C$12)*((3.2-(4-$C$12))*(3.2-(4-$C$12)/2)+4))/(4*((3.2-4)*(3.2-4/2)+4))) -> 4000 | AK3: =$C$12 -> 0 | AL3: =$C$16 -> 204 | AM3: =0+$C$7*1000*COS(RADIANS((0+(360-(0))*0/72))) -> 100 | AN3: =0+$C$7*1000*SIN(RADIANS((0+(360-(0))*0/72))) -> 0 | AO3: =0+$C$8*1000*COS(RADIANS((0+(360-(0))*0/72))) -> 70 | AP3: =0+$C$8*1000*SIN(RADIANS((0+(360-(0))*0/72))) -> 0 | AQ3: =0+$C$14*1000*COS(RADIANS((0+(360-(0))*0/72))) -> 85 | AR3: =0+$C$14*1000*SIN(RADIANS((0+(360-(0))*0/72))) -> 0 | AS3: =0+22*COS(RADIANS((0+(360-(0))*0/36))) -> 22 | AT3: =0+22*SIN(RADIANS((0+(360-(0))*0/36))) -> 0 | AU3: =(10-$C$26/2) -> 2.05 | AV3: 48 | AW3: =(50-$C$27/2) -> 40.475 | AX3: 50 | AY3: =(10-$C$26/2) -> 2.05 | AZ3: =(40-$C$35) -> 40 | BA3: =(50-$C$27/2) -> 40.475 | BB3: =(6+$C$36) -> 6 | BC3: 10 | BD3: 0
B4: Embrague monodisco (Ejemplo 1.5) | AA4: =0.25 -> 0.25 | AB4: =$C$5*((4-AA4)*((3.2-(4-AA4))*(3.2-(4-AA4)/2)+4))/(4*((3.2-4)*(3.2-4/2)+4)) -> 4035.259 | AC4: =$C$5*(1-AA4/10) -> 3900 | AD4: =$C$6*AB4*$C$14*$C$9 -> 205.79821 | AE4: =$C$6*AC4*$C$14*$C$9 -> 198.9 | AF4: =$C$10*$C$11 -> 177.6 | AG4: =$C$10 -> 148 | AI4: =$C$12 -> 0 | AJ4: =($C$5*(1-$C$12/10)) -> 4000 | AK4: =$C$12 -> 0 | AL4: =$C$17 -> 204 | AM4: =0+$C$7*1000*COS(RADIANS((0+(360-(0))*1/72))) -> 99.61947 | AN4: =0+$C$7*1000*SIN(RADIANS((0+(360-(0))*1/72))) -> 8.7155743 | AO4: =0+$C$8*1000*COS(RADIANS((0+(360-(0))*1/72))) -> 69.733629 | AP4: =0+$C$8*1000*SIN(RADIANS((0+(360-(0))*1/72))) -> 6.100902 | AQ4: =0+$C$14*1000*COS(RADIANS((0+(360-(0))*1/72))) -> 84.676549 | AR4: =0+$C$14*1000*SIN(RADIANS((0+(360-(0))*1/72))) -> 7.4082381 | AS4: =0+22*COS(RADIANS((0+(360-(0))*1/36))) -> 21.665771 | AT4: =0+22*SIN(RADIANS((0+(360-(0))*1/36))) -> 3.8202599 | AU4: =(10-$C$26/2) -> 2.05 | AV4: 0 | AW4: =(50-$C$27/2) -> 40.475 | AX4: 0 | AY4: =(10+$C$26/2) -> 17.95 | AZ4: =(40-$C$35) -> 40 | BA4: =(50+$C$27/2) -> 59.525 | BB4: =(6+$C$36) -> 6 | BC4: 10 | BD4: -7
B5: Fuerza de apriete con forros nuevos, F | C5: 4000 | D5: N | AA5: =0.5 -> 0.5 | AB5: =$C$5*((4-AA5)*((3.2-(4-AA5))*(3.2-(4-AA5)/2)+4))/(4*((3.2-4)*(3.2-4/2)+4)) -> 4104.4408 | AC5: =$C$5*(1-AA5/10) -> 3800 | AD5: =$C$6*AB5*$C$14*$C$9 -> 209.32648 | AE5: =$C$6*AC5*$C$14*$C$9 -> 193.8 | AF5: =$C$10*$C$11 -> 177.6 | AG5: =$C$10 -> 148 | AM5: =0+$C$7*1000*COS(RADIANS((0+(360-(0))*2/72))) -> 98.480775 | AN5: =0+$C$7*1000*SIN(RADIANS((0+(360-(0))*2/72))) -> 17.364818 | AO5: =0+$C$8*1000*COS(RADIANS((0+(360-(0))*2/72))) -> 68.936543 | AP5: =0+$C$8*1000*SIN(RADIANS((0+(360-(0))*2/72))) -> 12.155372 | AQ5: =0+$C$14*1000*COS(RADIANS((0+(360-(0))*2/72))) -> 83.708659 | AR5: =0+$C$14*1000*SIN(RADIANS((0+(360-(0))*2/72))) -> 14.760095 | AS5: =0+22*COS(RADIANS((0+(360-(0))*2/36))) -> 20.673238 | AT5: =0+22*SIN(RADIANS((0+(360-(0))*2/36))) -> 7.5244432 | AU5: =(10+$C$26/2) -> 17.95 | AV5: 0 | AW5: =(50+$C$27/2) -> 59.525 | AX5: 0 | AY5: =(10+$C$26/2) -> 17.95 | AZ5: =(40-$C$35)+4 -> 44 | BA5: =(50+$C$27/2) -> 59.525 | BB5: =(6+$C$36)-4 -> 2 | BC5: 50 | BD5: -7
B6: Coeficiente de rozamiento, μ | C6: 0.3 | AA6: =0.75 -> 0.75 | AB6: =$C$5*((4-AA6)*((3.2-(4-AA6))*(3.2-(4-AA6)/2)+4))/(4*((3.2-4)*(3.2-4/2)+4)) -> 4192.1258 | AC6: =$C$5*(1-AA6/10) -> 3700 | AD6: =$C$6*AB6*$C$14*$C$9 -> 213.79842 | AE6: =$C$6*AC6*$C$14*$C$9 -> 188.7 | AF6: =$C$10*$C$11 -> 177.6 | AG6: =$C$10 -> 148 | AM6: =0+$C$7*1000*COS(RADIANS((0+(360-(0))*3/72))) -> 96.592583 | AN6: =0+$C$7*1000*SIN(RADIANS((0+(360-(0))*3/72))) -> 25.881905 | AO6: =0+$C$8*1000*COS(RADIANS((0+(360-(0))*3/72))) -> 67.614808 | AP6: =0+$C$8*1000*SIN(RADIANS((0+(360-(0))*3/72))) -> 18.117333 | AQ6: =0+$C$14*1000*COS(RADIANS((0+(360-(0))*3/72))) -> 82.103695 | AR6: =0+$C$14*1000*SIN(RADIANS((0+(360-(0))*3/72))) -> 21.999619 | AS6: =0+22*COS(RADIANS((0+(360-(0))*3/36))) -> 19.052559 | AT6: =0+22*SIN(RADIANS((0+(360-(0))*3/36))) -> 11 | AU6: =(10+$C$26/2) -> 17.95 | AV6: 48 | AW6: =(50+$C$27/2) -> 59.525 | AX6: 50 | AY6: =(10-$C$26/2) -> 2.05 | AZ6: =(40-$C$35)+4 -> 44 | BA6: =(50-$C$27/2) -> 40.475 | BB6: =(6+$C$36)-4 -> 2 | BC6: 50 | BD6: 0
B7: Radio exterior del forro, R | C7: 0.1 | D7: m | AA7: =1 -> 1 | AB7: =$C$5*((4-AA7)*((3.2-(4-AA7))*(3.2-(4-AA7)/2)+4))/(4*((3.2-4)*(3.2-4/2)+4)) -> 4282.8947 | AC7: =$C$5*(1-AA7/10) -> 3600 | AD7: =$C$6*AB7*$C$14*$C$9 -> 218.42763 | AE7: =$C$6*AC7*$C$14*$C$9 -> 183.6 | AF7: =$C$10*$C$11 -> 177.6 | AG7: =$C$10 -> 148 | AM7: =0+$C$7*1000*COS(RADIANS((0+(360-(0))*4/72))) -> 93.969262 | AN7: =0+$C$7*1000*SIN(RADIANS((0+(360-(0))*4/72))) -> 34.202014 | AO7: =0+$C$8*1000*COS(RADIANS((0+(360-(0))*4/72))) -> 65.778483 | AP7: =0+$C$8*1000*SIN(RADIANS((0+(360-(0))*4/72))) -> 23.94141 | AQ7: =0+$C$14*1000*COS(RADIANS((0+(360-(0))*4/72))) -> 79.873873 | AR7: =0+$C$14*1000*SIN(RADIANS((0+(360-(0))*4/72))) -> 29.071712 | AS7: =0+22*COS(RADIANS((0+(360-(0))*4/36))) -> 16.852978 | AT7: =0+22*SIN(RADIANS((0+(360-(0))*4/36))) -> 14.141327 | AY7: =(10-$C$26/2) -> 2.05 | AZ7: =(40-$C$35) -> 40 | BA7: =(50-$C$27/2) -> 40.475 | BB7: =(6+$C$36) -> 6
B8: Radio interior del forro, r | C8: 0.07 | D8: m | AA8: =1.25 -> 1.25 | AB8: =$C$5*((4-AA8)*((3.2-(4-AA8))*(3.2-(4-AA8)/2)+4))/(4*((3.2-4)*(3.2-4/2)+4)) -> 4361.3281 | AC8: =$C$5*(1-AA8/10) -> 3500 | AD8: =$C$6*AB8*$C$14*$C$9 -> 222.42773 | AE8: =$C$6*AC8*$C$14*$C$9 -> 178.5 | AF8: =$C$10*$C$11 -> 177.6 | AG8: =$C$10 -> 148 | AM8: =0+$C$7*1000*COS(RADIANS((0+(360-(0))*5/72))) -> 90.630779 | AN8: =0+$C$7*1000*SIN(RADIANS((0+(360-(0))*5/72))) -> 42.261826 | AO8: =0+$C$8*1000*COS(RADIANS((0+(360-(0))*5/72))) -> 63.441545 | AP8: =0+$C$8*1000*SIN(RADIANS((0+(360-(0))*5/72))) -> 29.583278 | AQ8: =0+$C$14*1000*COS(RADIANS((0+(360-(0))*5/72))) -> 77.036162 | AR8: =0+$C$14*1000*SIN(RADIANS((0+(360-(0))*5/72))) -> 35.922552 | AS8: =0+22*COS(RADIANS((0+(360-(0))*5/36))) -> 14.141327 | AT8: =0+22*SIN(RADIANS((0+(360-(0))*5/36))) -> 16.852978 | AY8: 10 | AZ8: =(40-$C$35)+4 -> 44 | BA8: 50 | BB8: =(6+$C$36) -> 6
B9: Número de caras de fricción, z | C9: 2 | AA9: =1.5 -> 1.5 | AB9: =$C$5*((4-AA9)*((3.2-(4-AA9))*(3.2-(4-AA9)/2)+4))/(4*((3.2-4)*(3.2-4/2)+4)) -> 4412.0066 | AC9: =$C$5*(1-AA9/10) -> 3400 | AD9: =$C$6*AB9*$C$14*$C$9 -> 225.01234 | AE9: =$C$6*AC9*$C$14*$C$9 -> 173.4 | AF9: =$C$10*$C$11 -> 177.6 | AG9: =$C$10 -> 148 | AM9: =0+$C$7*1000*COS(RADIANS((0+(360-(0))*6/72))) -> 86.60254 | AN9: =0+$C$7*1000*SIN(RADIANS((0+(360-(0))*6/72))) -> 50 | AO9: =0+$C$8*1000*COS(RADIANS((0+(360-(0))*6/72))) -> 60.621778 | AP9: =0+$C$8*1000*SIN(RADIANS((0+(360-(0))*6/72))) -> 35 | AQ9: =0+$C$14*1000*COS(RADIANS((0+(360-(0))*6/72))) -> 73.612159 | AR9: =0+$C$14*1000*SIN(RADIANS((0+(360-(0))*6/72))) -> 42.5 | AS9: =0+22*COS(RADIANS((0+(360-(0))*6/36))) -> 11 | AT9: =0+22*SIN(RADIANS((0+(360-(0))*6/36))) -> 19.052559 | AY9: 10 | AZ9: =(40-$C$35)+22 -> 62 | BA9: 50 | BB9: =(6+$C$36)+46 -> 52
B10: Par máximo del motor (hoja U1 Caja de cambios) | C10: =MAX('U1 Caja de cambios'!$C$28:$C$39) -> 148 | D10: N·m | AA10: =1.75 -> 1.75 | AB10: =$C$5*((4-AA10)*((3.2-(4-AA10))*(3.2-(4-AA10)/2)+4))/(4*((3.2-4)*(3.2-4/2)+4)) -> 4419.5107 | AC10: =$C$5*(1-AA10/10) -> 3300 | AD10: =$C$6*AB10*$C$14*$C$9 -> 225.39505 | AE10: =$C$6*AC10*$C$14*$C$9 -> 168.3 | AF10: =$C$10*$C$11 -> 177.6 | AG10: =$C$10 -> 148 | AM10: =0+$C$7*1000*COS(RADIANS((0+(360-(0))*7/72))) -> 81.915204 | AN10: =0+$C$7*1000*SIN(RADIANS((0+(360-(0))*7/72))) -> 57.357644 | AO10: =0+$C$8*1000*COS(RADIANS((0+(360-(0))*7/72))) -> 57.340643 | AP10: =0+$C$8*1000*SIN(RADIANS((0+(360-(0))*7/72))) -> 40.150351 | AQ10: =0+$C$14*1000*COS(RADIANS((0+(360-(0))*7/72))) -> 69.627924 | AR10: =0+$C$14*1000*SIN(RADIANS((0+(360-(0))*7/72))) -> 48.753997 | AS10: =0+22*COS(RADIANS((0+(360-(0))*7/36))) -> 7.5244432 | AT10: =0+22*SIN(RADIANS((0+(360-(0))*7/36))) -> 20.673238
B11: Factor de seguridad requerido | C11: 1.2 | AA11: =2 -> 2 | AB11: =$C$5*((4-AA11)*((3.2-(4-AA11))*(3.2-(4-AA11)/2)+4))/(4*((3.2-4)*(3.2-4/2)+4)) -> 4368.4211 | AC11: =$C$5*(1-AA11/10) -> 3200 | AD11: =$C$6*AB11*$C$14*$C$9 -> 222.78947 | AE11: =$C$6*AC11*$C$14*$C$9 -> 163.2 | AF11: =$C$10*$C$11 -> 177.6 | AG11: =$C$10 -> 148 | AM11: =0+$C$7*1000*COS(RADIANS((0+(360-(0))*8/72))) -> 76.604444 | AN11: =0+$C$7*1000*SIN(RADIANS((0+(360-(0))*8/72))) -> 64.278761 | AO11: =0+$C$8*1000*COS(RADIANS((0+(360-(0))*8/72))) -> 53.623111 | AP11: =0+$C$8*1000*SIN(RADIANS((0+(360-(0))*8/72))) -> 44.995133 | AQ11: =0+$C$14*1000*COS(RADIANS((0+(360-(0))*8/72))) -> 65.113778 | AR11: =0+$C$14*1000*SIN(RADIANS((0+(360-(0))*8/72))) -> 54.636947 | AS11: =0+22*COS(RADIANS((0+(360-(0))*8/36))) -> 3.8202599 | AT11: =0+22*SIN(RADIANS((0+(360-(0))*8/36))) -> 21.665771
B12: Desgaste del forro | C12: 0 | D12: mm | AA12: =2.25 -> 2.25 | AB12: =$C$5*((4-AA12)*((3.2-(4-AA12))*(3.2-(4-AA12)/2)+4))/(4*((3.2-4)*(3.2-4/2)+4)) -> 4243.3183 | AC12: =$C$5*(1-AA12/10) -> 3100 | AD12: =$C$6*AB12*$C$14*$C$9 -> 216.40923 | AE12: =$C$6*AC12*$C$14*$C$9 -> 158.1 | AF12: =$C$10*$C$11 -> 177.6 | AG12: =$C$10 -> 148 | AM12: =0+$C$7*1000*COS(RADIANS((0+(360-(0))*9/72))) -> 70.710678 | AN12: =0+$C$7*1000*SIN(RADIANS((0+(360-(0))*9/72))) -> 70.710678 | AO12: =0+$C$8*1000*COS(RADIANS((0+(360-(0))*9/72))) -> 49.497475 | AP12: =0+$C$8*1000*SIN(RADIANS((0+(360-(0))*9/72))) -> 49.497475 | AQ12: =0+$C$14*1000*COS(RADIANS((0+(360-(0))*9/72))) -> 60.104076 | AR12: =0+$C$14*1000*SIN(RADIANS((0+(360-(0))*9/72))) -> 60.104076 | AS12: =0+22*COS(RADIANS((0+(360-(0))*9/36))) -> 1.3476633e-15 | AT12: =0+22*SIN(RADIANS((0+(360-(0))*9/36))) -> 22
B13: Resultados | AA13: =2.5 -> 2.5 | AB13: =$C$5*((4-AA13)*((3.2-(4-AA13))*(3.2-(4-AA13)/2)+4))/(4*((3.2-4)*(3.2-4/2)+4)) -> 4028.7829 | AC13: =$C$5*(1-AA13/10) -> 3000 | AD13: =$C$6*AB13*$C$14*$C$9 -> 205.46793 | AE13: =$C$6*AC13*$C$14*$C$9 -> 153 | AF13: =$C$10*$C$11 -> 177.6 | AG13: =$C$10 -> 148 | AM13: =0+$C$7*1000*COS(RADIANS((0+(360-(0))*10/72))) -> 64.278761 | AN13: =0+$C$7*1000*SIN(RADIANS((0+(360-(0))*10/72))) -> 76.604444 | AO13: =0+$C$8*1000*COS(RADIANS((0+(360-(0))*10/72))) -> 44.995133 | AP13: =0+$C$8*1000*SIN(RADIANS((0+(360-(0))*10/72))) -> 53.623111 | AQ13: =0+$C$14*1000*COS(RADIANS((0+(360-(0))*10/72))) -> 54.636947 | AR13: =0+$C$14*1000*SIN(RADIANS((0+(360-(0))*10/72))) -> 65.113778 | AS13: =0+22*COS(RADIANS((0+(360-(0))*10/36))) -> -3.8202599 | AT13: =0+22*SIN(RADIANS((0+(360-(0))*10/36))) -> 21.665771
B14: Radio medio, rm = (R + r)/2 | C14: =($C$7+$C$8)/2 -> 0.085 | D14: m | AA14: =2.75 -> 2.75 | AB14: =$C$5*((4-AA14)*((3.2-(4-AA14))*(3.2-(4-AA14)/2)+4))/(4*((3.2-4)*(3.2-4/2)+4)) -> 3709.3956 | AC14: =$C$5*(1-AA14/10) -> 2900 | AD14: =$C$6*AB14*$C$14*$C$9 -> 189.17917 | AE14: =$C$6*AC14*$C$14*$C$9 -> 147.9 | AF14: =$C$10*$C$11 -> 177.6 | AG14: =$C$10 -> 148 | AM14: =0+$C$7*1000*COS(RADIANS((0+(360-(0))*11/72))) -> 57.357644 | AN14: =0+$C$7*1000*SIN(RADIANS((0+(360-(0))*11/72))) -> 81.915204 | AO14: =0+$C$8*1000*COS(RADIANS((0+(360-(0))*11/72))) -> 40.150351 | AP14: =0+$C$8*1000*SIN(RADIANS((0+(360-(0))*11/72))) -> 57.340643 | AQ14: =0+$C$14*1000*COS(RADIANS((0+(360-(0))*11/72))) -> 48.753997 | AR14: =0+$C$14*1000*SIN(RADIANS((0+(360-(0))*11/72))) -> 69.627924 | AS14: =0+22*COS(RADIANS((0+(360-(0))*11/36))) -> -7.5244432 | AT14: =0+22*SIN(RADIANS((0+(360-(0))*11/36))) -> 20.673238
B15: Par transmisible con forros nuevos, T = μ·F·rm·z | C15: =$C$6*$C$5*$C$14*$C$9 -> 204 | D15: N·m | AA15: =3 -> 3 | AB15: =$C$5*((4-AA15)*((3.2-(4-AA15))*(3.2-(4-AA15)/2)+4))/(4*((3.2-4)*(3.2-4/2)+4)) -> 3269.7368 | AC15: =$C$5*(1-AA15/10) -> 2800 | AD15: =$C$6*AB15*$C$14*$C$9 -> 166.75658 | AE15: =$C$6*AC15*$C$14*$C$9 -> 142.8 | AF15: =$C$10*$C$11 -> 177.6 | AG15: =$C$10 -> 148 | AM15: =0+$C$7*1000*COS(RADIANS((0+(360-(0))*12/72))) -> 50 | AN15: =0+$C$7*1000*SIN(RADIANS((0+(360-(0))*12/72))) -> 86.60254 | AO15: =0+$C$8*1000*COS(RADIANS((0+(360-(0))*12/72))) -> 35 | AP15: =0+$C$8*1000*SIN(RADIANS((0+(360-(0))*12/72))) -> 60.621778 | AQ15: =0+$C$14*1000*COS(RADIANS((0+(360-(0))*12/72))) -> 42.5 | AR15: =0+$C$14*1000*SIN(RADIANS((0+(360-(0))*12/72))) -> 73.612159 | AS15: =0+22*COS(RADIANS((0+(360-(0))*12/36))) -> -11 | AT15: =0+22*SIN(RADIANS((0+(360-(0))*12/36))) -> 19.052559
B16: Par con desgaste — muelle de diafragma | C16: =$C$6*($C$5*((4-$C$12)*((3.2-(4-$C$12))*(3.2-(4-$C$12)/2)+4))/(4*((3.2-4)*(3.2-4/2)+4)))*$C$14*$C$9 -> 204 | D16: N·m | AA16: =3.25 -> 3.25 | AB16: =$C$5*((4-AA16)*((3.2-(4-AA16))*(3.2-(4-AA16)/2)+4))/(4*((3.2-4)*(3.2-4/2)+4)) -> 2694.3873 | AC16: =$C$5*(1-AA16/10) -> 2700 | AD16: =$C$6*AB16*$C$14*$C$9 -> 137.41375 | AE16: =$C$6*AC16*$C$14*$C$9 -> 137.7 | AF16: =$C$10*$C$11 -> 177.6 | AG16: =$C$10 -> 148 | AM16: =0+$C$7*1000*COS(RADIANS((0+(360-(0))*13/72))) -> 42.261826 | AN16: =0+$C$7*1000*SIN(RADIANS((0+(360-(0))*13/72))) -> 90.630779 | AO16: =0+$C$8*1000*COS(RADIANS((0+(360-(0))*13/72))) -> 29.583278 | AP16: =0+$C$8*1000*SIN(RADIANS((0+(360-(0))*13/72))) -> 63.441545 | AQ16: =0+$C$14*1000*COS(RADIANS((0+(360-(0))*13/72))) -> 35.922552 | AR16: =0+$C$14*1000*SIN(RADIANS((0+(360-(0))*13/72))) -> 77.036162 | AS16: =0+22*COS(RADIANS((0+(360-(0))*13/36))) -> -14.141327 | AT16: =0+22*SIN(RADIANS((0+(360-(0))*13/36))) -> 16.852978
B17: Par con desgaste — muelles helicoidales | C17: =$C$6*($C$5*(1-$C$12/10))*$C$14*$C$9 -> 204 | D17: N·m | AA17: =3.5 -> 3.5 | AB17: =$C$5*((4-AA17)*((3.2-(4-AA17))*(3.2-(4-AA17)/2)+4))/(4*((3.2-4)*(3.2-4/2)+4)) -> 1967.9276 | AC17: =$C$5*(1-AA17/10) -> 2600 | AD17: =$C$6*AB17*$C$14*$C$9 -> 100.36431 | AE17: =$C$6*AC17*$C$14*$C$9 -> 132.6 | AF17: =$C$10*$C$11 -> 177.6 | AG17: =$C$10 -> 148 | AM17: =0+$C$7*1000*COS(RADIANS((0+(360-(0))*14/72))) -> 34.202014 | AN17: =0+$C$7*1000*SIN(RADIANS((0+(360-(0))*14/72))) -> 93.969262 | AO17: =0+$C$8*1000*COS(RADIANS((0+(360-(0))*14/72))) -> 23.94141 | AP17: =0+$C$8*1000*SIN(RADIANS((0+(360-(0))*14/72))) -> 65.778483 | AQ17: =0+$C$14*1000*COS(RADIANS((0+(360-(0))*14/72))) -> 29.071712 | AR17: =0+$C$14*1000*SIN(RADIANS((0+(360-(0))*14/72))) -> 79.873873 | AS17: =0+22*COS(RADIANS((0+(360-(0))*14/36))) -> -16.852978 | AT17: =0+22*SIN(RADIANS((0+(360-(0))*14/36))) -> 14.141327
B18: Factor de seguridad actual (diafragma) | C18: =$C$16/$C$10 -> 1.3783784 | AM18: =0+$C$7*1000*COS(RADIANS((0+(360-(0))*15/72))) -> 25.881905 | AN18: =0+$C$7*1000*SIN(RADIANS((0+(360-(0))*15/72))) -> 96.592583 | AO18: =0+$C$8*1000*COS(RADIANS((0+(360-(0))*15/72))) -> 18.117333 | AP18: =0+$C$8*1000*SIN(RADIANS((0+(360-(0))*15/72))) -> 67.614808 | AQ18: =0+$C$14*1000*COS(RADIANS((0+(360-(0))*15/72))) -> 21.999619 | AR18: =0+$C$14*1000*SIN(RADIANS((0+(360-(0))*15/72))) -> 82.103695 | AS18: =0+22*COS(RADIANS((0+(360-(0))*15/36))) -> -19.052559 | AT18: =0+22*SIN(RADIANS((0+(360-(0))*15/36))) -> 11
B19: Par máximo de motor admisible (forro nuevo) | C19: =$C$15/$C$11 -> 170 | D19: N·m | AM19: =0+$C$7*1000*COS(RADIANS((0+(360-(0))*16/72))) -> 17.364818 | AN19: =0+$C$7*1000*SIN(RADIANS((0+(360-(0))*16/72))) -> 98.480775 | AO19: =0+$C$8*1000*COS(RADIANS((0+(360-(0))*16/72))) -> 12.155372 | AP19: =0+$C$8*1000*SIN(RADIANS((0+(360-(0))*16/72))) -> 68.936543 | AQ19: =0+$C$14*1000*COS(RADIANS((0+(360-(0))*16/72))) -> 14.760095 | AR19: =0+$C$14*1000*SIN(RADIANS((0+(360-(0))*16/72))) -> 83.708659 | AS19: =0+22*COS(RADIANS((0+(360-(0))*16/36))) -> -20.673238 | AT19: =0+22*SIN(RADIANS((0+(360-(0))*16/36))) -> 7.5244432
B20: ="Diafragma: "&IF($C$16>=$C$10*$C$11,"transmite el par con seguridad.",IF($C$16>=$C$10,"transmite, pero sin margen de seguridad.","¡PATINA! El par del motor supera al transmisible.")) -> Diafragma: transmite el par con seguridad. | AM20: =0+$C$7*1000*COS(RADIANS((0+(360-(0))*17/72))) -> 8.7155743 | AN20: =0+$C$7*1000*SIN(RADIANS((0+(360-(0))*17/72))) -> 99.61947 | AO20: =0+$C$8*1000*COS(RADIANS((0+(360-(0))*17/72))) -> 6.100902 | AP20: =0+$C$8*1000*SIN(RADIANS((0+(360-(0))*17/72))) -> 69.733629 | AQ20: =0+$C$14*1000*COS(RADIANS((0+(360-(0))*17/72))) -> 7.4082381 | AR20: =0+$C$14*1000*SIN(RADIANS((0+(360-(0))*17/72))) -> 84.676549 | AS20: =0+22*COS(RADIANS((0+(360-(0))*17/36))) -> -21.665771 | AT20: =0+22*SIN(RADIANS((0+(360-(0))*17/36))) -> 3.8202599
B21: ="Helicoidales: "&IF($C$17>=$C$10*$C$11,"transmite el par con seguridad.",IF($C$17>=$C$10,"transmite, pero sin margen de seguridad.","¡PATINA! El par del motor supera al transmisible.")) -> Helicoidales: transmite el par con seguridad. | AM21: =0+$C$7*1000*COS(RADIANS((0+(360-(0))*18/72))) -> 6.1257423e-15 | AN21: =0+$C$7*1000*SIN(RADIANS((0+(360-(0))*18/72))) -> 100 | AO21: =0+$C$8*1000*COS(RADIANS((0+(360-(0))*18/72))) -> 4.2880196e-15 | AP21: =0+$C$8*1000*SIN(RADIANS((0+(360-(0))*18/72))) -> 70 | AQ21: =0+$C$14*1000*COS(RADIANS((0+(360-(0))*18/72))) -> 5.2068809e-15 | AR21: =0+$C$14*1000*SIN(RADIANS((0+(360-(0))*18/72))) -> 85 | AS21: =0+22*COS(RADIANS((0+(360-(0))*18/36))) -> -22 | AT21: =0+22*SIN(RADIANS((0+(360-(0))*18/36))) -> 2.6953266e-15
AM22: =0+$C$7*1000*COS(RADIANS((0+(360-(0))*19/72))) -> -8.7155743 | AN22: =0+$C$7*1000*SIN(RADIANS((0+(360-(0))*19/72))) -> 99.61947 | AO22: =0+$C$8*1000*COS(RADIANS((0+(360-(0))*19/72))) -> -6.100902 | AP22: =0+$C$8*1000*SIN(RADIANS((0+(360-(0))*19/72))) -> 69.733629 | AQ22: =0+$C$14*1000*COS(RADIANS((0+(360-(0))*19/72))) -> -7.4082381 | AR22: =0+$C$14*1000*SIN(RADIANS((0+(360-(0))*19/72))) -> 84.676549 | AS22: =0+22*COS(RADIANS((0+(360-(0))*19/36))) -> -21.665771 | AT22: =0+22*SIN(RADIANS((0+(360-(0))*19/36))) -> -3.8202599
B23: Mando hidráulico (Ejemplo 1.6) | AM23: =0+$C$7*1000*COS(RADIANS((0+(360-(0))*20/72))) -> -17.364818 | AN23: =0+$C$7*1000*SIN(RADIANS((0+(360-(0))*20/72))) -> 98.480775 | AO23: =0+$C$8*1000*COS(RADIANS((0+(360-(0))*20/72))) -> -12.155372 | AP23: =0+$C$8*1000*SIN(RADIANS((0+(360-(0))*20/72))) -> 68.936543 | AQ23: =0+$C$14*1000*COS(RADIANS((0+(360-(0))*20/72))) -> -14.760095 | AR23: =0+$C$14*1000*SIN(RADIANS((0+(360-(0))*20/72))) -> 83.708659 | AS23: =0+22*COS(RADIANS((0+(360-(0))*20/36))) -> -20.673238 | AT23: =0+22*SIN(RADIANS((0+(360-(0))*20/36))) -> -7.5244432
B24: Fuerza del pie sobre el pedal | C24: 150 | D24: N | AM24: =0+$C$7*1000*COS(RADIANS((0+(360-(0))*21/72))) -> -25.881905 | AN24: =0+$C$7*1000*SIN(RADIANS((0+(360-(0))*21/72))) -> 96.592583 | AO24: =0+$C$8*1000*COS(RADIANS((0+(360-(0))*21/72))) -> -18.117333 | AP24: =0+$C$8*1000*SIN(RADIANS((0+(360-(0))*21/72))) -> 67.614808 | AQ24: =0+$C$14*1000*COS(RADIANS((0+(360-(0))*21/72))) -> -21.999619 | AR24: =0+$C$14*1000*SIN(RADIANS((0+(360-(0))*21/72))) -> 82.103695 | AS24: =0+22*COS(RADIANS((0+(360-(0))*21/36))) -> -19.052559 | AT24: =0+22*SIN(RADIANS((0+(360-(0))*21/36))) -> -11
B25: Relación de palanca del pedal | C25: 6 | D25: : 1 | AM25: =0+$C$7*1000*COS(RADIANS((0+(360-(0))*22/72))) -> -34.202014 | AN25: =0+$C$7*1000*SIN(RADIANS((0+(360-(0))*22/72))) -> 93.969262 | AO25: =0+$C$8*1000*COS(RADIANS((0+(360-(0))*22/72))) -> -23.94141 | AP25: =0+$C$8*1000*SIN(RADIANS((0+(360-(0))*22/72))) -> 65.778483 | AQ25: =0+$C$14*1000*COS(RADIANS((0+(360-(0))*22/72))) -> -29.071712 | AR25: =0+$C$14*1000*SIN(RADIANS((0+(360-(0))*22/72))) -> 79.873873 | AS25: =0+22*COS(RADIANS((0+(360-(0))*22/36))) -> -16.852978 | AT25: =0+22*SIN(RADIANS((0+(360-(0))*22/36))) -> -14.141327
B26: Diámetro del pistón de la bomba | C26: 15.9 | D26: mm | AM26: =0+$C$7*1000*COS(RADIANS((0+(360-(0))*23/72))) -> -42.261826 | AN26: =0+$C$7*1000*SIN(RADIANS((0+(360-(0))*23/72))) -> 90.630779 | AO26: =0+$C$8*1000*COS(RADIANS((0+(360-(0))*23/72))) -> -29.583278 | AP26: =0+$C$8*1000*SIN(RADIANS((0+(360-(0))*23/72))) -> 63.441545 | AQ26: =0+$C$14*1000*COS(RADIANS((0+(360-(0))*23/72))) -> -35.922552 | AR26: =0+$C$14*1000*SIN(RADIANS((0+(360-(0))*23/72))) -> 77.036162 | AS26: =0+22*COS(RADIANS((0+(360-(0))*23/36))) -> -14.141327 | AT26: =0+22*SIN(RADIANS((0+(360-(0))*23/36))) -> -16.852978
B27: Diámetro del pistón del bombín | C27: 19.05 | D27: mm | AM27: =0+$C$7*1000*COS(RADIANS((0+(360-(0))*24/72))) -> -50 | AN27: =0+$C$7*1000*SIN(RADIANS((0+(360-(0))*24/72))) -> 86.60254 | AO27: =0+$C$8*1000*COS(RADIANS((0+(360-(0))*24/72))) -> -35 | AP27: =0+$C$8*1000*SIN(RADIANS((0+(360-(0))*24/72))) -> 60.621778 | AQ27: =0+$C$14*1000*COS(RADIANS((0+(360-(0))*24/72))) -> -42.5 | AR27: =0+$C$14*1000*SIN(RADIANS((0+(360-(0))*24/72))) -> 73.612159 | AS27: =0+22*COS(RADIANS((0+(360-(0))*24/36))) -> -11 | AT27: =0+22*SIN(RADIANS((0+(360-(0))*24/36))) -> -19.052559
B28: Carrera del pistón de la bomba | C28: 30 | D28: mm | AM28: =0+$C$7*1000*COS(RADIANS((0+(360-(0))*25/72))) -> -57.357644 | AN28: =0+$C$7*1000*SIN(RADIANS((0+(360-(0))*25/72))) -> 81.915204 | AO28: =0+$C$8*1000*COS(RADIANS((0+(360-(0))*25/72))) -> -40.150351 | AP28: =0+$C$8*1000*SIN(RADIANS((0+(360-(0))*25/72))) -> 57.340643 | AQ28: =0+$C$14*1000*COS(RADIANS((0+(360-(0))*25/72))) -> -48.753997 | AR28: =0+$C$14*1000*SIN(RADIANS((0+(360-(0))*25/72))) -> 69.627924 | AS28: =0+22*COS(RADIANS((0+(360-(0))*25/36))) -> -7.5244432 | AT28: =0+22*SIN(RADIANS((0+(360-(0))*25/36))) -> -20.673238
B29: Recorrido del pedal | C29: 0 | D29: % | AM29: =0+$C$7*1000*COS(RADIANS((0+(360-(0))*26/72))) -> -64.278761 | AN29: =0+$C$7*1000*SIN(RADIANS((0+(360-(0))*26/72))) -> 76.604444 | AO29: =0+$C$8*1000*COS(RADIANS((0+(360-(0))*26/72))) -> -44.995133 | AP29: =0+$C$8*1000*SIN(RADIANS((0+(360-(0))*26/72))) -> 53.623111 | AQ29: =0+$C$14*1000*COS(RADIANS((0+(360-(0))*26/72))) -> -54.636947 | AR29: =0+$C$14*1000*SIN(RADIANS((0+(360-(0))*26/72))) -> 65.113778 | AS29: =0+22*COS(RADIANS((0+(360-(0))*26/36))) -> -3.8202599 | AT29: =0+22*SIN(RADIANS((0+(360-(0))*26/36))) -> -21.665771
B30: Resultados del mando | AM30: =0+$C$7*1000*COS(RADIANS((0+(360-(0))*27/72))) -> -70.710678 | AN30: =0+$C$7*1000*SIN(RADIANS((0+(360-(0))*27/72))) -> 70.710678 | AO30: =0+$C$8*1000*COS(RADIANS((0+(360-(0))*27/72))) -> -49.497475 | AP30: =0+$C$8*1000*SIN(RADIANS((0+(360-(0))*27/72))) -> 49.497475 | AQ30: =0+$C$14*1000*COS(RADIANS((0+(360-(0))*27/72))) -> -60.104076 | AR30: =0+$C$14*1000*SIN(RADIANS((0+(360-(0))*27/72))) -> 60.104076 | AS30: =0+22*COS(RADIANS((0+(360-(0))*27/36))) -> -4.0429899e-15 | AT30: =0+22*SIN(RADIANS((0+(360-(0))*27/36))) -> -22
B31: Fuerza en la bomba = F_pie × relación | C31: =$C$24*$C$25 -> 900 | D31: N | AM31: =0+$C$7*1000*COS(RADIANS((0+(360-(0))*28/72))) -> -76.604444 | AN31: =0+$C$7*1000*SIN(RADIANS((0+(360-(0))*28/72))) -> 64.278761 | AO31: =0+$C$8*1000*COS(RADIANS((0+(360-(0))*28/72))) -> -53.623111 | AP31: =0+$C$8*1000*SIN(RADIANS((0+(360-(0))*28/72))) -> 44.995133 | AQ31: =0+$C$14*1000*COS(RADIANS((0+(360-(0))*28/72))) -> -65.113778 | AR31: =0+$C$14*1000*SIN(RADIANS((0+(360-(0))*28/72))) -> 54.636947 | AS31: =0+22*COS(RADIANS((0+(360-(0))*28/36))) -> 3.8202599 | AT31: =0+22*SIN(RADIANS((0+(360-(0))*28/36))) -> -21.665771
B32: Presión en el circuito | C32: =$C$31/(PI()*$C$26^2/4)*10 -> 45.327146 | D32: bar | AM32: =0+$C$7*1000*COS(RADIANS((0+(360-(0))*29/72))) -> -81.915204 | AN32: =0+$C$7*1000*SIN(RADIANS((0+(360-(0))*29/72))) -> 57.357644 | AO32: =0+$C$8*1000*COS(RADIANS((0+(360-(0))*29/72))) -> -57.340643 | AP32: =0+$C$8*1000*SIN(RADIANS((0+(360-(0))*29/72))) -> 40.150351 | AQ32: =0+$C$14*1000*COS(RADIANS((0+(360-(0))*29/72))) -> -69.627924 | AR32: =0+$C$14*1000*SIN(RADIANS((0+(360-(0))*29/72))) -> 48.753997 | AS32: =0+22*COS(RADIANS((0+(360-(0))*29/36))) -> 7.5244432 | AT32: =0+22*SIN(RADIANS((0+(360-(0))*29/36))) -> -20.673238
B33: Fuerza en el bombín | C33: =$C$32/10*PI()*$C$27^2/4 -> 1291.9277 | D33: N | AM33: =0+$C$7*1000*COS(RADIANS((0+(360-(0))*30/72))) -> -86.60254 | AN33: =0+$C$7*1000*SIN(RADIANS((0+(360-(0))*30/72))) -> 50 | AO33: =0+$C$8*1000*COS(RADIANS((0+(360-(0))*30/72))) -> -60.621778 | AP33: =0+$C$8*1000*SIN(RADIANS((0+(360-(0))*30/72))) -> 35 | AQ33: =0+$C$14*1000*COS(RADIANS((0+(360-(0))*30/72))) -> -73.612159 | AR33: =0+$C$14*1000*SIN(RADIANS((0+(360-(0))*30/72))) -> 42.5 | AS33: =0+22*COS(RADIANS((0+(360-(0))*30/36))) -> 11 | AT33: =0+22*SIN(RADIANS((0+(360-(0))*30/36))) -> -19.052559
B34: Carrera total del bombín | C34: =$C$28*($C$26/$C$27)^2 -> 20.899002 | D34: mm | AM34: =0+$C$7*1000*COS(RADIANS((0+(360-(0))*31/72))) -> -90.630779 | AN34: =0+$C$7*1000*SIN(RADIANS((0+(360-(0))*31/72))) -> 42.261826 | AO34: =0+$C$8*1000*COS(RADIANS((0+(360-(0))*31/72))) -> -63.441545 | AP34: =0+$C$8*1000*SIN(RADIANS((0+(360-(0))*31/72))) -> 29.583278 | AQ34: =0+$C$14*1000*COS(RADIANS((0+(360-(0))*31/72))) -> -77.036162 | AR34: =0+$C$14*1000*SIN(RADIANS((0+(360-(0))*31/72))) -> 35.922552 | AS34: =0+22*COS(RADIANS((0+(360-(0))*31/36))) -> 14.141327 | AT34: =0+22*SIN(RADIANS((0+(360-(0))*31/36))) -> -16.852978
B35: Desplazamiento actual de la bomba | C35: =$C$28*$C$29/100 -> 0 | D35: mm | AM35: =0+$C$7*1000*COS(RADIANS((0+(360-(0))*32/72))) -> -93.969262 | AN35: =0+$C$7*1000*SIN(RADIANS((0+(360-(0))*32/72))) -> 34.202014 | AO35: =0+$C$8*1000*COS(RADIANS((0+(360-(0))*32/72))) -> -65.778483 | AP35: =0+$C$8*1000*SIN(RADIANS((0+(360-(0))*32/72))) -> 23.94141 | AQ35: =0+$C$14*1000*COS(RADIANS((0+(360-(0))*32/72))) -> -79.873873 | AR35: =0+$C$14*1000*SIN(RADIANS((0+(360-(0))*32/72))) -> 29.071712 | AS35: =0+22*COS(RADIANS((0+(360-(0))*32/36))) -> 16.852978 | AT35: =0+22*SIN(RADIANS((0+(360-(0))*32/36))) -> -14.141327
B36: Desplazamiento actual del bombín | C36: =$C$35*($C$26/$C$27)^2 -> 0 | D36: mm | AM36: =0+$C$7*1000*COS(RADIANS((0+(360-(0))*33/72))) -> -96.592583 | AN36: =0+$C$7*1000*SIN(RADIANS((0+(360-(0))*33/72))) -> 25.881905 | AO36: =0+$C$8*1000*COS(RADIANS((0+(360-(0))*33/72))) -> -67.614808 | AP36: =0+$C$8*1000*SIN(RADIANS((0+(360-(0))*33/72))) -> 18.117333 | AQ36: =0+$C$14*1000*COS(RADIANS((0+(360-(0))*33/72))) -> -82.103695 | AR36: =0+$C$14*1000*SIN(RADIANS((0+(360-(0))*33/72))) -> 21.999619 | AS36: =0+22*COS(RADIANS((0+(360-(0))*33/36))) -> 19.052559 | AT36: =0+22*SIN(RADIANS((0+(360-(0))*33/36))) -> -11
B37: =IF($C$29<20,"Embragado: el disco está apretado y transmite el par.",IF($C$29<60,"Zona de acoplamiento: el disco patina (punto de fricción).","Desembragado: el diafragma libera el plato y el disco gira libre.")) -> Embragado: el disco está apretado y transmite el par. | AM37: =0+$C$7*1000*COS(RADIANS((0+(360-(0))*34/72))) -> -98.480775 | AN37: =0+$C$7*1000*SIN(RADIANS((0+(360-(0))*34/72))) -> 17.364818 | AO37: =0+$C$8*1000*COS(RADIANS((0+(360-(0))*34/72))) -> -68.936543 | AP37: =0+$C$8*1000*SIN(RADIANS((0+(360-(0))*34/72))) -> 12.155372 | AQ37: =0+$C$14*1000*COS(RADIANS((0+(360-(0))*34/72))) -> -83.708659 | AR37: =0+$C$14*1000*SIN(RADIANS((0+(360-(0))*34/72))) -> 14.760095 | AS37: =0+22*COS(RADIANS((0+(360-(0))*34/36))) -> 20.673238 | AT37: =0+22*SIN(RADIANS((0+(360-(0))*34/36))) -> -7.5244432
