Workbook

Sheet Carnot
A1: GUÍA 5 – CICLO DE CARNOT: DIAGRAMAS P–v, T–s Y T–v
A2: η = 1 − T_L/T_H
A3: Leyenda: celdas amarillas con texto azul = datos de entrada (editar). Texto negro = fórmulas (no editar).
A5: Parámetro | B5: Símbolo | C5: Valor | D5: Unidad | E5: Observación
A6: Temperatura del foco caliente | B6: T_H | C6: 700 | D6: K
A7: Temperatura del foco frío | B7: T_L | C7: 300 | D7: K
A8: Volumen específico en 1 | B8: v1 | C8: 0.15 | D8: m³/kg
A9: Volumen específico en 2 | B9: v2 | C9: 0.35 | D9: m³/kg
A10: Constante del aire | B10: R | C10: 0.287 | D10: kJ/(kg·K)
A11: Relación de calores específicos γ | B11: g | C11: 1.4 | D11: —
A12: Calor específico a v cte | B12: cv | C12: 0.718 | D12: kJ/(kg·K)
A13: Masa de fluido | B13: m | C13: 1 | D13: kg
A15: Estados del ciclo (s referida al estado 1)
A16: Estado | B16: P (kPa) | C16: T (K) | D16: v (m³/kg) | E16: s (kJ/kg·K) | F16: V (m³)
A17: 1 | B17: =Carnot!$C$10*Carnot!$C$6/Carnot!$C$8 -> 1339.3333 | C17: =Carnot!$C$6 -> 700 | D17: =Carnot!$C$8 -> 0.15 | E17: =0 -> 0 | F17: =Carnot!$D$17*Carnot!$C$13 -> 0.15
A18: 2 | B18: =Carnot!$C$10*Carnot!$C$6/Carnot!$C$9 -> 574 | C18: =Carnot!$C$6 -> 700 | D18: =Carnot!$C$9 -> 0.35 | E18: =Carnot!$C$10*LN(Carnot!$C$9/Carnot!$C$8) -> 0.24317449 | F18: =Carnot!$D$18*Carnot!$C$13 -> 0.35
A19: 3 | B19: =Carnot!$C$10*Carnot!$C$7/Carnot!$D$19 -> 29.579658 | C19: =Carnot!$C$7 -> 300 | D19: =Carnot!$C$9*(Carnot!$C$6/Carnot!$C$7)^(1/(Carnot!$C$11-1)) -> 2.9107842 | E19: =Carnot!$E$18 -> 0.24317449 | F19: =Carnot!$D$19*Carnot!$C$13 -> 2.9107842
A20: 4 | B20: =Carnot!$C$10*Carnot!$C$7/Carnot!$D$20 -> 69.019201 | C20: =Carnot!$C$7 -> 300 | D20: =Carnot!$C$8*(Carnot!$C$6/Carnot!$C$7)^(1/(Carnot!$C$11-1)) -> 1.2474789 | E20: =0 -> 0 | F20: =Carnot!$D$20*Carnot!$C$13 -> 1.2474789
A22: Balance por proceso (por unidad de masa): Q − W = ΔU
A23: Proceso | B23: Tipo | C23: Q (kJ/kg) | D23: W (kJ/kg) | E23: ΔU (kJ/kg) | F23: Δs (kJ/kg·K) | G23: Q − W − ΔU
A24: 1→2 | B24: Expansión isotérmica | C24: =Carnot!$C$10*Carnot!$C$6*LN(Carnot!$C$9/Carnot!$C$8) -> 170.22214 | D24: =C24 -> 170.22214 | E24: =0 -> 0 | F24: =Carnot!$E$18-Carnot!$E$17 -> 0.24317449 | G24: =C24-D24-E24 -> 0
A25: 2→3 | B25: Expansión adiabática | C25: =0 -> 0 | D25: =-E25 -> 287.2 | E25: =Carnot!$C$12*(Carnot!$C$19-Carnot!$C$18) -> -287.2 | F25: =Carnot!$E$19-Carnot!$E$18 -> 0 | G25: =C25-D25-E25 -> 0
A26: 3→4 | B26: Compresión isotérmica | C26: =Carnot!$C$10*Carnot!$C$7*LN(Carnot!$D$20/Carnot!$D$19) -> -72.952346 | D26: =C26 -> -72.952346 | E26: =0 -> 0 | F26: =Carnot!$E$20-Carnot!$E$19 -> -0.24317449 | G26: =C26-D26-E26 -> 0
A27: 4→1 | B27: Compresión adiabática | C27: =0 -> 0 | D27: =-E27 -> -287.2 | E27: =Carnot!$C$12*(Carnot!$C$17-Carnot!$C$20) -> 287.2 | F27: =Carnot!$E$17-Carnot!$E$20 -> 0 | G27: =C27-D27-E27 -> 0
A28: Ciclo | C28: =SUM(C24:C27) -> 97.269794 | D28: =SUM(D24:D27) -> 97.269794 | E28: =SUM(E24:E27) -> 0 | F28: =SUM(F24:F27) -> 0
A29: Convención: Q > 0 recibido por el gas; W > 0 realizado por el gas. En el ciclo ΔU = 0 y Δs = 0 (pequeñas diferencias se deben a redondeos de c_p y c_v).
A31: Resultados del ciclo
A32: Magnitud | B32: Ecuación | C32: Valor | D32: Unidad
A33: Calor aportado | B33: q_ent | C33: =Carnot!$C$24 -> 170.22214 | D33: kJ/kg
A34: Calor cedido | B34: q_sal | C34: =-Carnot!$C$26 -> 72.952346 | D34: kJ/kg
A35: Trabajo neto | B35: w = Σ W | C35: =Carnot!$D$28 -> 97.269794 | D35: kJ/kg
A36: Eficiencia térmica (balance) | B36: η = w/q_ent | C36: =C35/C33*100 -> 57.142857 | D36: %
A37: Eficiencia de Carnot (fórmula) | B37: η = 1 − T_L/T_H | C37: =(1-Carnot!$C$7/Carnot!$C$6)*100 -> 57.142857 | D37: %
A38: Eficiencia de Carnot entre T máx y T mín | B38: η_C = 1 − T_mín/T_máx | C38: =(1-Carnot!$C$7/Carnot!$C$6)*100 -> 57.142857 | D38: %
A39: Temperatura media de aporte de calor | B39: T_m = q_ent/Δs_ent | C39: =C33/Carnot!$F$24 -> 700 | D39: K
A40: Presión media efectiva | B40: PME = w/(v_máx − v_mín) | C40: =C35/(MAX(Carnot!$D$17,Carnot!$D$18,Carnot!$D$19,Carnot!$D$20)-MIN(Carnot!$D$17,Carnot!$D$18,Carnot!$D$19,Carnot!$D$20)) -> 35.232669 | D40: kPa
A41: Presión máxima | B41: P_máx | C41: =MAX(Carnot!$B$17,Carnot!$B$18,Carnot!$B$19,Carnot!$B$20) -> 1339.3333 | D41: kPa
A42: Temperatura máxima | B42: T_máx | C42: =MAX(Carnot!$C$17,Carnot!$C$18,Carnot!$C$19,Carnot!$C$20) -> 700 | D42: K

Sheet Puntos
A1: Puntos de los diagramas (20 por proceso)
A2: Columnas: proceso, fracción, v, T, P, s, V
A4: Proceso | B4: t | C4: v (m³/kg) | D4: T (K) | E4: P (kPa) | F4: s (kJ/kg·K) | G4: V (m³)
A5: 1→2 | B5: 0 | C5: =Carnot!$D$17+(Carnot!$D$18-Carnot!$D$17)*B5 -> 0.15 | D5: =Carnot!$C$17 -> 700 | E5: =Carnot!$C$10*D5/C5 -> 1339.3333 | F5: =Carnot!$C$10*LN(C5/Carnot!$D$17) -> 0 | G5: =C5*Carnot!$C$13 -> 0.15
A6: 1→2 | B6: 0.052632 | C6: =Carnot!$D$17+(Carnot!$D$18-Carnot!$D$17)*B6 -> 0.1605264 | D6: =Carnot!$C$17 -> 700 | E6: =Carnot!$C$10*D6/C6 -> 1251.5075 | F6: =Carnot!$C$10*LN(C6/Carnot!$D$17) -> 0.019465236 | G6: =C6*Carnot!$C$13 -> 0.1605264
A7: 1→2 | B7: 0.105263 | C7: =Carnot!$D$17+(Carnot!$D$18-Carnot!$D$17)*B7 -> 0.1710526 | D7: =Carnot!$C$17 -> 700 | E7: =Carnot!$C$10*D7/C7 -> 1174.4925 | F7: =Carnot!$C$10*LN(C7/Carnot!$D$17) -> 0.03769338 | G7: =C7*Carnot!$C$13 -> 0.1710526
A8: 1→2 | B8: 0.157895 | C8: =Carnot!$D$17+(Carnot!$D$18-Carnot!$D$17)*B8 -> 0.181579 | D8: =Carnot!$C$17 -> 700 | E8: =Carnot!$C$10*D8/C8 -> 1106.4055 | F8: =Carnot!$C$10*LN(C8/Carnot!$D$17) -> 0.054832936 | G8: =C8*Carnot!$C$13 -> 0.181579
A9: 1→2 | B9: 0.210526 | C9: =Carnot!$D$17+(Carnot!$D$18-Carnot!$D$17)*B9 -> 0.1921052 | D9: =Carnot!$C$17 -> 700 | E9: =Carnot!$C$10*D9/C9 -> 1045.7812 | F9: =Carnot!$C$10*LN(C9/Carnot!$D$17) -> 0.071006051 | G9: =C9*Carnot!$C$13 -> 0.1921052
A10: 1→2 | B10: 0.263158 | C10: =Carnot!$D$17+(Carnot!$D$18-Carnot!$D$17)*B10 -> 0.2026316 | D10: =Carnot!$C$17 -> 700 | E10: =Carnot!$C$10*D10/C10 -> 991.45444 | F10: =Carnot!$C$10*LN(C10/Carnot!$D$17) -> 0.086316472 | G10: =C10*Carnot!$C$13 -> 0.2026316
A11: 1→2 | B11: 0.315789 | C11: =Carnot!$D$17+(Carnot!$D$18-Carnot!$D$17)*B11 -> 0.2131578 | D11: =Carnot!$C$17 -> 700 | E11: =Carnot!$C$10*D11/C11 -> 942.49425 | F11: =Carnot!$C$10*LN(C11/Carnot!$D$17) -> 0.10085107 | G11: =C11*Carnot!$C$13 -> 0.2131578
A12: 1→2 | B12: 0.368421 | C12: =Carnot!$D$17+(Carnot!$D$18-Carnot!$D$17)*B12 -> 0.2236842 | D12: =Carnot!$C$17 -> 700 | E12: =Carnot!$C$10*D12/C12 -> 898.14122 | F12: =Carnot!$C$10*LN(C12/Carnot!$D$17) -> 0.11468518 | G12: =C12*Carnot!$C$13 -> 0.2236842
A13: 1→2 | B13: 0.421053 | C13: =Carnot!$D$17+(Carnot!$D$18-Carnot!$D$17)*B13 -> 0.2342106 | D13: =Carnot!$C$17 -> 700 | E13: =Carnot!$C$10*D13/C13 -> 857.77501 | F13: =Carnot!$C$10*LN(C13/Carnot!$D$17) -> 0.12788301 | G13: =C13*Carnot!$C$13 -> 0.2342106
A14: 1→2 | B14: 0.473684 | C14: =Carnot!$D$17+(Carnot!$D$18-Carnot!$D$17)*B14 -> 0.2447368 | D14: =Carnot!$C$17 -> 700 | E14: =Carnot!$C$10*D14/C14 -> 820.88186 | F14: =Carnot!$C$10*LN(C14/Carnot!$D$17) -> 0.14050029 | G14: =C14*Carnot!$C$13 -> 0.2447368
A15: 1→2 | B15: 0.526316 | C15: =Carnot!$D$17+(Carnot!$D$18-Carnot!$D$17)*B15 -> 0.2552632 | D15: =Carnot!$C$17 -> 700 | E15: =Carnot!$C$10*D15/C15 -> 787.0308 | F15: =Carnot!$C$10*LN(C15/Carnot!$D$17) -> 0.15258638 | G15: =C15*Carnot!$C$13 -> 0.2552632
A16: 1→2 | B16: 0.578947 | C16: =Carnot!$D$17+(Carnot!$D$18-Carnot!$D$17)*B16 -> 0.2657894 | D16: =Carnot!$C$17 -> 700 | E16: =Carnot!$C$10*D16/C16 -> 755.8616 | F16: =Carnot!$C$10*LN(C16/Carnot!$D$17) -> 0.16418379 | G16: =C16*Carnot!$C$13 -> 0.2657894
... A24: 1→2 | B24: 1 | C24: =Carnot!$D$17+(Carnot!$D$18-Carnot!$D$17)*B24 -> 0.35 | D24: =Carnot!$C$17 -> 700 | E24: =Carnot!$C$10*D24/C24 -> 574 | F24: =Carnot!$C$10*LN(C24/Carnot!$D$17) -> 0.24317449 | G24: =C24*Carnot!$C$13 -> 0.35
A25: 2→3 | B25: 0 | C25: =Carnot!$D$18+(Carnot!$D$19-Carnot!$D$18)*B25 -> 0.35 | D25: =Carnot!$C$18*(Carnot!$D$18/C25)^(Carnot!$C$11-1) -> 700 | E25: =Carnot!$C$10*D25/C25 -> 574 | F25: =Carnot!$E$18 -> 0.24317449 | G25: =C25*Carnot!$C$13 -> 0.35
A26: 2→3 | B26: 0.052632 | C26: =Carnot!$D$18+(Carnot!$D$19-Carnot!$D$18)*B26 -> 0.48477919 | D26: =Carnot!$C$18*(Carnot!$D$18/C26)^(Carnot!$C$11-1) -> 614.47988 | E26: =Carnot!$C$10*D26/C26 -> 363.78568 | F26: =Carnot!$E$18 -> 0.24317449 | G26: =C26*Carnot!$C$13 -> 0.48477919
A27: 2→3 | B27: 0.105263 | C27: =Carnot!$D$18+(Carnot!$D$19-Carnot!$D$18)*B27 -> 0.61955583 | D27: =Carnot!$C$18*(Carnot!$D$18/C27)^(Carnot!$C$11-1) -> 557.04859 | E27: =Carnot!$C$10*D27/C27 -> 258.04445 | F27: =Carnot!$E$18 -> 0.24317449 | G27: =C27*Carnot!$C$13 -> 0.61955583
A28: 2→3 | B28: 0.157895 | C28: =Carnot!$D$18+(Carnot!$D$19-Carnot!$D$18)*B28 -> 0.75433502 | D28: =Carnot!$C$18*(Carnot!$D$18/C28)^(Carnot!$C$11-1) -> 514.87233 | E28: =Carnot!$C$10*D28/C28 -> 195.89221 | F28: =Carnot!$E$18 -> 0.24317449 | G28: =C28*Carnot!$C$13 -> 0.75433502
A29: 2→3 | B29: 0.210526 | C29: =Carnot!$D$18+(Carnot!$D$19-Carnot!$D$18)*B29 -> 0.88911165 | D29: =Carnot!$C$18*(Carnot!$D$18/C29)^(Carnot!$C$11-1) -> 482.10622 | E29: =Carnot!$C$10*D29/C29 -> 155.62105 | F29: =Carnot!$E$18 -> 0.24317449 | G29: =C29*Carnot!$C$13 -> 0.88911165
A30: 2→3 | B30: 0.263158 | C30: =Carnot!$D$18+(Carnot!$D$19-Carnot!$D$18)*B30 -> 1.0238908 | D30: =Carnot!$C$18*(Carnot!$D$18/C30)^(Carnot!$C$11-1) -> 455.64205 | E30: =Carnot!$C$10*D30/C30 -> 127.71798 | F30: =Carnot!$E$18 -> 0.24317449 | G30: =C30*Carnot!$C$13 -> 1.0238908
A31: 2→3 | B31: 0.315789 | C31: =Carnot!$D$18+(Carnot!$D$19-Carnot!$D$18)*B31 -> 1.1586675 | D31: =Carnot!$C$18*(Carnot!$D$18/C31)^(Carnot!$C$11-1) -> 433.65238 | E31: =Carnot!$C$10*D31/C31 -> 107.41497 | F31: =Carnot!$E$18 -> 0.24317449 | G31: =C31*Carnot!$C$13 -> 1.1586675
A32: 2→3 | B32: 0.368421 | C32: =Carnot!$D$18+(Carnot!$D$19-Carnot!$D$18)*B32 -> 1.2934467 | D32: =Carnot!$C$18*(Carnot!$D$18/C32)^(Carnot!$C$11-1) -> 414.97874 | E32: =Carnot!$C$10*D32/C32 -> 92.078708 | F32: =Carnot!$E$18 -> 0.24317449 | G32: =C32*Carnot!$C$13 -> 1.2934467
A33: 2→3 | B33: 0.421053 | C33: =Carnot!$D$18+(Carnot!$D$19-Carnot!$D$18)*B33 -> 1.4282259 | D33: =Carnot!$C$18*(Carnot!$D$18/C33)^(Carnot!$C$11-1) -> 398.84716 | E33: =Carnot!$C$10*D33/C33 -> 80.147781 | F33: =Carnot!$E$18 -> 0.24317449 | G33: =C33*Carnot!$C$13 -> 1.4282259
A34: 2→3 | B34: 0.473684 | C34: =Carnot!$D$18+(Carnot!$D$19-Carnot!$D$18)*B34 -> 1.5630025 | D34: =Carnot!$C$18*(Carnot!$D$18/C34)^(Carnot!$C$11-1) -> 384.71701 | E34: =Carnot!$C$10*D34/C34 -> 70.642102 | F34: =Carnot!$E$18 -> 0.24317449 | G34: =C34*Carnot!$C$13 -> 1.5630025
A35: 2→3 | B35: 0.526316 | C35: =Carnot!$D$18+(Carnot!$D$19-Carnot!$D$18)*B35 -> 1.6977817 | D35: =Carnot!$C$18*(Carnot!$D$18/C35)^(Carnot!$C$11-1) -> 372.1967 | E35: =Carnot!$C$10*D35/C35 -> 62.917661 | F35: =Carnot!$E$18 -> 0.24317449 | G35: =C35*Carnot!$C$13 -> 1.6977817
A36: 2→3 | B36: 0.578947 | C36: =Carnot!$D$18+(Carnot!$D$19-Carnot!$D$18)*B36 -> 1.8325583 | D36: =Carnot!$C$18*(Carnot!$D$18/C36)^(Carnot!$C$11-1) -> 360.99579 | E36: =Carnot!$C$10*D36/C36 -> 56.536149 | F36: =Carnot!$E$18 -> 0.24317449 | G36: =C36*Carnot!$C$13 -> 1.8325583
... A44: 2→3 | B44: 1 | C44: =Carnot!$D$18+(Carnot!$D$19-Carnot!$D$18)*B44 -> 2.9107842 | D44: =Carnot!$C$18*(Carnot!$D$18/C44)^(Carnot!$C$11-1) -> 300 | E44: =Carnot!$C$10*D44/C44 -> 29.579658 | F44: =Carnot!$E$18 -> 0.24317449 | G44: =C44*Carnot!$C$13 -> 2.9107842
A45: 3→4 | B45: 0 | C45: =Carnot!$D$19+(Carnot!$D$20-Carnot!$D$19)*B45 -> 2.9107842 | D45: =Carnot!$C$19 -> 300 | E45: =Carnot!$C$10*D45/C45 -> 29.579658 | F45: =Carnot!$E$18+Carnot!$C$10*LN(C45/Carnot!$D$19) -> 0.24317449 | G45: =C45*Carnot!$C$13 -> 2.9107842
A46: 3→4 | B46: 0.052632 | C46: =Carnot!$D$19+(Carnot!$D$20-Carnot!$D$19)*B46 -> 2.8232411 | D46: =Carnot!$C$19 -> 300 | E46: =Carnot!$C$10*D46/C46 -> 30.496864 | F46: =Carnot!$E$18+Carnot!$C$10*LN(C46/Carnot!$D$19) -> 0.23441037 | G46: =C46*Carnot!$C$13 -> 2.8232411
A47: 3→4 | B47: 0.105263 | C47: =Carnot!$D$19+(Carnot!$D$20-Carnot!$D$19)*B47 -> 2.7356997 | D47: =Carnot!$C$19 -> 300 | E47: =Carnot!$C$10*D47/C47 -> 31.472753 | F47: =Carnot!$E$18+Carnot!$C$10*LN(C47/Carnot!$D$19) -> 0.22537036 | G47: =C47*Carnot!$C$13 -> 2.7356997
A48: 3→4 | B48: 0.157895 | C48: =Carnot!$D$19+(Carnot!$D$20-Carnot!$D$19)*B48 -> 2.6481566 | D48: =Carnot!$C$19 -> 300 | E48: =Carnot!$C$10*D48/C48 -> 32.513183 | F48: =Carnot!$E$18+Carnot!$C$10*LN(C48/Carnot!$D$19) -> 0.21603613 | G48: =C48*Carnot!$C$13 -> 2.6481566
A49: 3→4 | B49: 0.210526 | C49: =Carnot!$D$19+(Carnot!$D$20-Carnot!$D$19)*B49 -> 2.5606152 | D49: =Carnot!$C$19 -> 300 | E49: =Carnot!$C$10*D49/C49 -> 33.624732 | F49: =Carnot!$E$18+Carnot!$C$10*LN(C49/Carnot!$D$19) -> 0.20638826 | G49: =C49*Carnot!$C$13 -> 2.5606152
A50: 3→4 | B50: 0.263158 | C50: =Carnot!$D$19+(Carnot!$D$20-Carnot!$D$19)*B50 -> 2.4730721 | D50: =Carnot!$C$19 -> 300 | E50: =Carnot!$C$10*D50/C50 -> 34.814998 | F50: =Carnot!$E$18+Carnot!$C$10*LN(C50/Carnot!$D$19) -> 0.19640457 | G50: =C50*Carnot!$C$13 -> 2.4730721
A51: 3→4 | B51: 0.315789 | C51: =Carnot!$D$19+(Carnot!$D$20-Carnot!$D$19)*B51 -> 2.3855307 | D51: =Carnot!$C$19 -> 300 | E51: =Carnot!$C$10*D51/C51 -> 36.092598 | F51: =Carnot!$E$18+Carnot!$C$10*LN(C51/Carnot!$D$19) -> 0.18606122 | G51: =C51*Carnot!$C$13 -> 2.3855307
A52: 3→4 | B52: 0.368421 | C52: =Carnot!$D$19+(Carnot!$D$20-Carnot!$D$19)*B52 -> 2.2979876 | D52: =Carnot!$C$19 -> 300 | E52: =Carnot!$C$10*D52/C52 -> 37.467565 | F52: =Carnot!$E$18+Carnot!$C$10*LN(C52/Carnot!$D$19) -> 0.17533092 | G52: =C52*Carnot!$C$13 -> 2.2979876
A53: 3→4 | B53: 0.421053 | C53: =Carnot!$D$19+(Carnot!$D$20-Carnot!$D$19)*B53 -> 2.2104445 | D53: =Carnot!$C$19 -> 300 | E53: =Carnot!$C$10*D53/C53 -> 38.951441 | F53: =Carnot!$E$18+Carnot!$C$10*LN(C53/Carnot!$D$19) -> 0.16418379 | G53: =C53*Carnot!$C$13 -> 2.2104445
A54: 3→4 | B54: 0.473684 | C54: =Carnot!$D$19+(Carnot!$D$20-Carnot!$D$19)*B54 -> 2.1229031 | D54: =Carnot!$C$19 -> 300 | E54: =Carnot!$C$10*D54/C54 -> 40.557668 | F54: =Carnot!$E$18+Carnot!$C$10*LN(C54/Carnot!$D$19) -> 0.15258638 | G54: =C54*Carnot!$C$13 -> 2.1229031
A55: 3→4 | B55: 0.526316 | C55: =Carnot!$D$19+(Carnot!$D$20-Carnot!$D$19)*B55 -> 2.03536 | D55: =Carnot!$C$19 -> 300 | E55: =Carnot!$C$10*D55/C55 -> 42.302098 | F55: =Carnot!$E$18+Carnot!$C$10*LN(C55/Carnot!$D$19) -> 0.14050029 | G55: =C55*Carnot!$C$13 -> 2.03536
...

Sheet Graficas

Sheet Parametrico
A1: Eficiencia de Carnot en función de T_H
A2: T_L constante
A4: T_H (K) | B4: η Carnot (%) | C4: W_neto (kJ/kg)
A5: 400 | B5: =(1-Carnot!$C$7/A5)*100 -> 25 | C5: =Carnot!$C$10*LN(Carnot!$C$9/Carnot!$C$8)*(A5-Carnot!$C$7) -> 24.317449
A6: 500 | B6: =(1-Carnot!$C$7/A6)*100 -> 40 | C6: =Carnot!$C$10*LN(Carnot!$C$9/Carnot!$C$8)*(A6-Carnot!$C$7) -> 48.634897
A7: 600 | B7: =(1-Carnot!$C$7/A7)*100 -> 50 | C7: =Carnot!$C$10*LN(Carnot!$C$9/Carnot!$C$8)*(A7-Carnot!$C$7) -> 72.952346
A8: 700 | B8: =(1-Carnot!$C$7/A8)*100 -> 57.142857 | C8: =Carnot!$C$10*LN(Carnot!$C$9/Carnot!$C$8)*(A8-Carnot!$C$7) -> 97.269794
A9: 800 | B9: =(1-Carnot!$C$7/A9)*100 -> 62.5 | C9: =Carnot!$C$10*LN(Carnot!$C$9/Carnot!$C$8)*(A9-Carnot!$C$7) -> 121.58724
A10: 900 | B10: =(1-Carnot!$C$7/A10)*100 -> 66.666667 | C10: =Carnot!$C$10*LN(Carnot!$C$9/Carnot!$C$8)*(A10-Carnot!$C$7) -> 145.90469
A11: 1000 | B11: =(1-Carnot!$C$7/A11)*100 -> 70 | C11: =Carnot!$C$10*LN(Carnot!$C$9/Carnot!$C$8)*(A11-Carnot!$C$7) -> 170.22214
A12: 1100 | B12: =(1-Carnot!$C$7/A12)*100 -> 72.727273 | C12: =Carnot!$C$10*LN(Carnot!$C$9/Carnot!$C$8)*(A12-Carnot!$C$7) -> 194.53959
A13: 1200 | B13: =(1-Carnot!$C$7/A13)*100 -> 75 | C13: =Carnot!$C$10*LN(Carnot!$C$9/Carnot!$C$8)*(A13-Carnot!$C$7) -> 218.85704
A14: 1300 | B14: =(1-Carnot!$C$7/A14)*100 -> 76.923077 | C14: =Carnot!$C$10*LN(Carnot!$C$9/Carnot!$C$8)*(A14-Carnot!$C$7) -> 243.17449
A15: 1400 | B15: =(1-Carnot!$C$7/A15)*100 -> 78.571429 | C15: =Carnot!$C$10*LN(Carnot!$C$9/Carnot!$C$8)*(A15-Carnot!$C$7) -> 267.49193
A16: 1500 | B16: =(1-Carnot!$C$7/A16)*100 -> 80 | C16: =Carnot!$C$10*LN(Carnot!$C$9/Carnot!$C$8)*(A16-Carnot!$C$7) -> 291.80938
... A26: 2500 | B26: =(1-Carnot!$C$7/A26)*100 -> 88 | C26: =Carnot!$C$10*LN(Carnot!$C$9/Carnot!$C$8)*(A26-Carnot!$C$7) -> 534.98387
