Workbook

Sheet Otto
A1: GUÍA 6 – CICLO OTTO IDEAL: DIAGRAMAS P–v, P–V, T–s Y P–θ
A2: η = 1 − 1/r^(γ−1)
A3: Leyenda: celdas amarillas con texto azul = datos de entrada (editar). Texto negro = fórmulas (no editar).
A5: Parámetro | B5: Símbolo | C5: Valor | D5: Unidad | E5: Observación
A6: Presión inicial (Loja) | B6: P1 | C6: 79 | D6: kPa
A7: Temperatura inicial | B7: T1 | C7: 300 | D7: K
A8: Relación de compresión | B8: r | C8: 9 | D8: —
A9: Calor aportado q_ent | B9: q | C9: 1800 | D9: kJ/kg
A10: Relación de calores específicos γ | B10: g | C10: 1.4 | D10: —
A11: Calor específico a v cte | B11: cv | C11: 0.718 | D11: kJ/(kg·K)
A12: Calor específico a P cte | B12: cp | C12: 1.005 | D12: kJ/(kg·K)
A13: Constante del aire | B13: R | C13: 0.287 | D13: kJ/(kg·K)
A14: Diámetro del cilindro | B14: D | C14: 7.8 | D14: cm
A15: Carrera | B15: S | C15: 6.75 | D15: cm
A16: Número de cilindros | B16: Z | C16: 4 | D16: —
A17: Longitud de la biela | B17: Lb | C17: 13.1 | D17: cm
A18: Régimen de giro | B18: n | C18: 3000 | D18: rpm
A20: Geometría (ecuaciones de la guía original) y masa de aire
A21: Magnitud | B21: Ecuación | C21: Valor | D21: Unidad
A22: Área del pistón | B22: A_P = π·D²/4 | C22: =PI()*Otto!$C$14^2/4 -> 47.783624 | D22: cm²
A23: Volumen del cilindro | B23: V_C = A_P·S | C23: =Otto!$C$22*Otto!$C$15 -> 322.53946 | D23: cm³
A24: Volumen de la cámara | B24: V_CC = V_C/(r − 1) | C24: =Otto!$C$23/(Otto!$C$8-1) -> 40.317433 | D24: cm³
A25: Volumen unitario | B25: V_u = V_C + V_CC | C25: =Otto!$C$23+Otto!$C$24 -> 362.8569 | D25: cm³
A26: Relación biela–manivela | B26: λ = (S/2)/L | C26: =Otto!$C$15/2/Otto!$C$17 -> 0.25763359 | D26: —
A27: Volumen específico en 1 | B27: v1 = R·T1/P1 | C27: =Otto!$C$13*Otto!$C$7/Otto!$C$6 -> 1.0898734 | D27: m³/kg
A28: Masa de aire por cilindro | B28: m = V_u/v1 | C28: =Otto!$C$25*0.000001/Otto!$C$27 -> 0.0003329349 | D28: kg
A30: Estados del ciclo (s referida al estado 1)
A31: Estado | B31: P (kPa) | C31: T (K) | D31: v (m³/kg) | E31: s (kJ/kg·K) | F31: V (cm³)
A32: 1 | B32: =Otto!$C$6 -> 79 | C32: =Otto!$C$7 -> 300 | D32: =Otto!$C$27 -> 1.0898734 | E32: =0 -> 0 | F32: =Otto!$D$32*Otto!$C$28*1000000 -> 362.8569
A33: 2 | B33: =Otto!$C$6*Otto!$C$8^Otto!$C$10 -> 1712.2478 | C33: =Otto!$C$7*Otto!$C$8^(Otto!$C$10-1) -> 722.46741 | D33: =Otto!$C$27/Otto!$C$8 -> 0.12109705 | E33: =0 -> 0 | F33: =Otto!$D$33*Otto!$C$28*1000000 -> 40.317433
A34: 3 | B34: =Otto!$B$33*Otto!$C$34/Otto!$C$33 -> 7653.7519 | C34: =Otto!$C$33+Otto!$C$9/Otto!$C$11 -> 3229.4312 | D34: =Otto!$D$33 -> 0.12109705 | E34: =Otto!$C$11*LN(Otto!$C$34/Otto!$C$33) -> 1.0751253 | F34: =Otto!$D$34*Otto!$C$28*1000000 -> 40.317433
A35: 4 | B35: =Otto!$B$34/Otto!$C$8^Otto!$C$10 -> 353.13021 | C35: =Otto!$C$34/Otto!$C$8^(Otto!$C$10-1) -> 1341.0008 | D35: =Otto!$C$27 -> 1.0898734 | E35: =Otto!$E$34 -> 1.0751253 | F35: =Otto!$D$35*Otto!$C$28*1000000 -> 362.8569
A37: Balance por proceso (por unidad de masa): Q − W = ΔU
A38: Proceso | B38: Tipo | C38: Q (kJ/kg) | D38: W (kJ/kg) | E38: ΔU (kJ/kg) | F38: Δs (kJ/kg·K) | G38: Q − W − ΔU
A39: 1→2 | B39: Compresión adiabática | C39: =0 -> 0 | D39: =-E39 -> -303.3316 | E39: =Otto!$C$11*(Otto!$C$33-Otto!$C$32) -> 303.3316 | F39: =Otto!$E$33-Otto!$E$32 -> 0 | G39: =C39-D39-E39 -> 0
A40: 2→3 | B40: Aporte de calor a v cte | C40: =Otto!$C$11*(Otto!$C$34-Otto!$C$33) -> 1800 | D40: =0 -> 0 | E40: =Otto!$C$11*(Otto!$C$34-Otto!$C$33) -> 1800 | F40: =Otto!$E$34-Otto!$E$33 -> 1.0751253 | G40: =C40-D40-E40 -> 0
A41: 3→4 | B41: Expansión adiabática | C41: =0 -> 0 | D41: =-E41 -> 1355.893 | E41: =Otto!$C$11*(Otto!$C$35-Otto!$C$34) -> -1355.893 | F41: =Otto!$E$35-Otto!$E$34 -> 0 | G41: =C41-D41-E41 -> 0
A42: 4→1 | B42: Cesión de calor a v cte | C42: =Otto!$C$11*(Otto!$C$32-Otto!$C$35) -> -747.43856 | D42: =0 -> 0 | E42: =Otto!$C$11*(Otto!$C$32-Otto!$C$35) -> -747.43856 | F42: =Otto!$E$32-Otto!$E$35 -> -1.0751253 | G42: =C42-D42-E42 -> 0
A43: Ciclo | C43: =SUM(C39:C42) -> 1052.5614 | D43: =SUM(D39:D42) -> 1052.5614 | E43: =SUM(E39:E42) -> 0 | F43: =SUM(F39:F42) -> 0
A44: Convención: Q > 0 recibido por el gas; W > 0 realizado por el gas. En el ciclo ΔU = 0 y Δs = 0 (pequeñas diferencias se deben a redondeos de c_p y c_v).
...

Sheet Puntos
A1: Puntos de los diagramas (20 por proceso)
A2: Columnas: proceso, fracción, v, T, P, s, V
A4: Proceso | B4: t | C4: v (m³/kg) | D4: T (K) | E4: P (kPa) | F4: s (kJ/kg·K) | G4: V (cm³)
A5: 1→2 | B5: 0 | C5: =Otto!$D$32+(Otto!$D$33-Otto!$D$32)*B5 -> 1.0898734 | D5: =Otto!$C$32*(Otto!$D$32/C5)^(Otto!$C$10-1) -> 300 | E5: =Otto!$C$13*D5/C5 -> 79 | F5: =0 -> 0 | G5: =C5*Otto!$C$28*1000000 -> 362.8569
A6: 1→2 | B6: 0.052632 | C6: =Otto!$D$32+(Otto!$D$33-Otto!$D$32)*B6 -> 1.0388848 | D6: =Otto!$C$32*(Otto!$D$32/C6)^(Otto!$C$10-1) -> 305.8051 | E6: =Otto!$C$13*D6/C6 -> 84.481037 | F6: =0 -> 0 | G6: =C6*Otto!$C$28*1000000 -> 345.881
A7: 1→2 | B7: 0.105263 | C7: =Otto!$D$32+(Otto!$D$33-Otto!$D$32)*B7 -> 0.98789711 | D7: =Otto!$C$32*(Otto!$D$32/C7)^(Otto!$C$10-1) -> 312.02328 | E7: =Otto!$C$13*D7/C7 -> 90.64778 | F7: =0 -> 0 | G7: =C7*Otto!$C$28*1000000 -> 328.90543
A8: 1→2 | B8: 0.157895 | C8: =Otto!$D$32+(Otto!$D$33-Otto!$D$32)*B8 -> 0.93690847 | D8: =Otto!$C$32*(Otto!$D$32/C8)^(Otto!$C$10-1) -> 318.70789 | E8: =Otto!$C$13*D8/C8 -> 97.628708 | F8: =0 -> 0 | G8: =C8*Otto!$C$28*1000000 -> 311.92953
A9: 1→2 | B9: 0.210526 | C9: =Otto!$D$32+(Otto!$D$33-Otto!$D$32)*B9 -> 0.8859208 | D9: =Otto!$C$32*(Otto!$D$32/C9)^(Otto!$C$10-1) -> 325.92203 | E9: =Otto!$C$13*D9/C9 -> 105.58463 | F9: =0 -> 0 | G9: =C9*Otto!$C$28*1000000 -> 294.95395
A10: 1→2 | B10: 0.263158 | C10: =Otto!$D$32+(Otto!$D$33-Otto!$D$32)*B10 -> 0.83493217 | D10: =Otto!$C$32*(Otto!$D$32/C10)^(Otto!$C$10-1) -> 333.74226 | E10: =Otto!$C$13*D10/C10 -> 114.72073 | F10: =0 -> 0 | G10: =C10*Otto!$C$28*1000000 -> 277.97806
A11: 1→2 | B11: 0.315789 | C11: =Otto!$D$32+(Otto!$D$33-Otto!$D$32)*B11 -> 0.7839445 | D11: =Otto!$C$32*(Otto!$D$32/C11)^(Otto!$C$10-1) -> 342.26111 | E11: =Otto!$C$13*D11/C11 -> 125.30088 | F11: =0 -> 0 | G11: =C11*Otto!$C$28*1000000 -> 261.00248
A12: 1→2 | B12: 0.368421 | C12: =Otto!$D$32+(Otto!$D$33-Otto!$D$32)*B12 -> 0.73295586 | D12: =Otto!$C$32*(Otto!$D$32/C12)^(Otto!$C$10-1) -> 351.59327 | E12: =Otto!$C$13*D12/C12 -> 137.67168 | F12: =0 -> 0 | G12: =C12*Otto!$C$28*1000000 -> 244.02658
A13: 1→2 | B13: 0.421053 | C13: =Otto!$D$32+(Otto!$D$33-Otto!$D$32)*B13 -> 0.68196722 | D13: =Otto!$C$32*(Otto!$D$32/C13)^(Otto!$C$10-1) -> 361.88141 | E13: =Otto!$C$13*D13/C13 -> 152.29466 | F13: =0 -> 0 | G13: =C13*Otto!$C$28*1000000 -> 227.05069
A14: 1→2 | B14: 0.473684 | C14: =Otto!$D$32+(Otto!$D$33-Otto!$D$32)*B14 -> 0.63097955 | D14: =Otto!$C$32*(Otto!$D$32/C14)^(Otto!$C$10-1) -> 373.30651 | E14: =Otto!$C$13*D14/C14 -> 169.79785 | F14: =0 -> 0 | G14: =C14*Otto!$C$28*1000000 -> 210.07511
A15: 1→2 | B15: 0.526316 | C15: =Otto!$D$32+(Otto!$D$33-Otto!$D$32)*B15 -> 0.57999091 | D15: =Otto!$C$32*(Otto!$D$32/C15)^(Otto!$C$10-1) -> 386.10302 | E15: =Otto!$C$13*D15/C15 -> 191.05742 | F15: =0 -> 0 | G15: =C15*Otto!$C$28*1000000 -> 193.09922
A16: 1→2 | B16: 0.578947 | C16: =Otto!$D$32+(Otto!$D$33-Otto!$D$32)*B16 -> 0.52900324 | D16: =Otto!$C$32*(Otto!$D$32/C16)^(Otto!$C$10-1) -> 400.57915 | E16: =Otto!$C$13*D16/C16 -> 217.32611 | F16: =0 -> 0 | G16: =C16*Otto!$C$28*1000000 -> 176.12364
... A24: 1→2 | B24: 1 | C24: =Otto!$D$32+(Otto!$D$33-Otto!$D$32)*B24 -> 0.12109705 | D24: =Otto!$C$32*(Otto!$D$32/C24)^(Otto!$C$10-1) -> 722.46741 | E24: =Otto!$C$13*D24/C24 -> 1712.2478 | F24: =0 -> 0 | G24: =C24*Otto!$C$28*1000000 -> 40.317433
A25: 2→3 | B25: 0 | C25: =Otto!$D$33 -> 0.12109705 | D25: =Otto!$C$33+(Otto!$C$34-Otto!$C$33)*B25 -> 722.46741 | E25: =Otto!$C$13*D25/C25 -> 1712.2478 | F25: =Otto!$C$11*LN(D25/Otto!$C$33) -> 0 | G25: =C25*Otto!$C$28*1000000 -> 40.317433
A26: 2→3 | B26: 0.052632 | C26: =Otto!$D$33 -> 0.12109705 | D26: =Otto!$C$33+(Otto!$C$34-Otto!$C$33)*B26 -> 854.41392 | E26: =Otto!$C$13*D26/C26 -> 2024.961 | F26: =Otto!$C$11*LN(D26/Otto!$C$33) -> 0.1204398 | G26: =C26*Otto!$C$28*1000000 -> 40.317433
A27: 2→3 | B27: 0.105263 | C27: =Otto!$D$33 -> 0.12109705 | D27: =Otto!$C$33+(Otto!$C$34-Otto!$C$33)*B27 -> 986.35793 | E27: =Otto!$C$13*D27/C27 -> 2337.6683 | F27: =Otto!$C$11*LN(D27/Otto!$C$33) -> 0.22354715 | G27: =C27*Otto!$C$28*1000000 -> 40.317433
A28: 2→3 | B28: 0.157895 | C28: =Otto!$D$33 -> 0.12109705 | D28: =Otto!$C$33+(Otto!$C$34-Otto!$C$33)*B28 -> 1118.3045 | E28: =Otto!$C$13*D28/C28 -> 2650.3816 | F28: =Otto!$C$11*LN(D28/Otto!$C$33) -> 0.31369178 | G28: =C28*Otto!$C$28*1000000 -> 40.317433
A29: 2→3 | B29: 0.210526 | C29: =Otto!$D$33 -> 0.12109705 | D29: =Otto!$C$33+(Otto!$C$34-Otto!$C$33)*B29 -> 1250.2485 | E29: =Otto!$C$13*D29/C29 -> 2963.0889 | F29: =Otto!$C$11*LN(D29/Otto!$C$33) -> 0.39376935 | G29: =C29*Otto!$C$28*1000000 -> 40.317433
A30: 2→3 | B30: 0.263158 | C30: =Otto!$D$33 -> 0.12109705 | D30: =Otto!$C$33+(Otto!$C$34-Otto!$C$33)*B30 -> 1382.195 | E30: =Otto!$C$13*D30/C30 -> 3275.8021 | F30: =Otto!$C$11*LN(D30/Otto!$C$33) -> 0.46580665 | G30: =C30*Otto!$C$28*1000000 -> 40.317433
A31: 2→3 | B31: 0.315789 | C31: =Otto!$D$33 -> 0.12109705 | D31: =Otto!$C$33+(Otto!$C$34-Otto!$C$33)*B31 -> 1514.139 | E31: =Otto!$C$13*D31/C31 -> 3588.5094 | F31: =Otto!$C$11*LN(D31/Otto!$C$33) -> 0.53126969 | G31: =C31*Otto!$C$28*1000000 -> 40.317433
A32: 2→3 | B32: 0.368421 | C32: =Otto!$D$33 -> 0.12109705 | D32: =Otto!$C$33+(Otto!$C$34-Otto!$C$33)*B32 -> 1646.0855 | E32: =Otto!$C$13*D32/C32 -> 3901.2227 | F32: =Otto!$C$11*LN(D32/Otto!$C$33) -> 0.59126081 | G32: =C32*Otto!$C$28*1000000 -> 40.317433
A33: 2→3 | B33: 0.421053 | C33: =Otto!$D$33 -> 0.12109705 | D33: =Otto!$C$33+(Otto!$C$34-Otto!$C$33)*B33 -> 1778.032 | E33: =Otto!$C$13*D33/C33 -> 4213.9359 | F33: =Otto!$C$11*LN(D33/Otto!$C$33) -> 0.64662371 | G33: =C33*Otto!$C$28*1000000 -> 40.317433
A34: 2→3 | B34: 0.473684 | C34: =Otto!$D$33 -> 0.12109705 | D34: =Otto!$C$33+(Otto!$C$34-Otto!$C$33)*B34 -> 1909.976 | E34: =Otto!$C$13*D34/C34 -> 4526.6432 | F34: =Otto!$C$11*LN(D34/Otto!$C$33) -> 0.6980207 | G34: =C34*Otto!$C$28*1000000 -> 40.317433
A35: 2→3 | B35: 0.526316 | C35: =Otto!$D$33 -> 0.12109705 | D35: =Otto!$C$33+(Otto!$C$34-Otto!$C$33)*B35 -> 2041.9226 | E35: =Otto!$C$13*D35/C35 -> 4839.3565 | F35: =Otto!$C$11*LN(D35/Otto!$C$33) -> 0.74598388 | G35: =C35*Otto!$C$28*1000000 -> 40.317433
A36: 2→3 | B36: 0.578947 | C36: =Otto!$D$33 -> 0.12109705 | D36: =Otto!$C$33+(Otto!$C$34-Otto!$C$33)*B36 -> 2173.8666 | E36: =Otto!$C$13*D36/C36 -> 5152.0638 | F36: =Otto!$C$11*LN(D36/Otto!$C$33) -> 0.7909419 | G36: =C36*Otto!$C$28*1000000 -> 40.317433
... A44: 2→3 | B44: 1 | C44: =Otto!$D$33 -> 0.12109705 | D44: =Otto!$C$33+(Otto!$C$34-Otto!$C$33)*B44 -> 3229.4312 | E44: =Otto!$C$13*D44/C44 -> 7653.7519 | F44: =Otto!$C$11*LN(D44/Otto!$C$33) -> 1.0751253 | G44: =C44*Otto!$C$28*1000000 -> 40.317433
A45: 3→4 | B45: 0 | C45: =Otto!$D$34+(Otto!$D$35-Otto!$D$34)*B45 -> 0.12109705 | D45: =Otto!$C$34*(Otto!$D$34/C45)^(Otto!$C$10-1) -> 3229.4312 | E45: =Otto!$C$13*D45/C45 -> 7653.7519 | F45: =Otto!$E$34 -> 1.0751253 | G45: =C45*Otto!$C$28*1000000 -> 40.317433
A46: 3→4 | B46: 0.052632 | C46: =Otto!$D$34+(Otto!$D$35-Otto!$D$34)*B46 -> 0.17208568 | D46: =Otto!$C$34*(Otto!$D$34/C46)^(Otto!$C$10-1) -> 2805.9605 | E46: =Otto!$C$13*D46/C46 -> 4679.7075 | F46: =Otto!$E$34 -> 1.0751253 | G46: =C46*Otto!$C$28*1000000 -> 57.29333
A47: 3→4 | B47: 0.105263 | C47: =Otto!$D$34+(Otto!$D$35-Otto!$D$34)*B47 -> 0.22307335 | D47: =Otto!$C$34*(Otto!$D$34/C47)^(Otto!$C$10-1) -> 2529.3002 | E47: =Otto!$C$13*D47/C47 -> 3254.1276 | F47: =Otto!$E$34 -> 1.0751253 | G47: =C47*Otto!$C$28*1000000 -> 74.268905
A48: 3→4 | B48: 0.157895 | C48: =Otto!$D$34+(Otto!$D$35-Otto!$D$34)*B48 -> 0.27406199 | D48: =Otto!$C$34*(Otto!$D$34/C48)^(Otto!$C$10-1) -> 2329.3778 | E48: =Otto!$C$13*D48/C48 -> 2439.3438 | F48: =Otto!$E$34 -> 1.0751253 | G48: =C48*Otto!$C$28*1000000 -> 91.244802
A49: 3→4 | B49: 0.210526 | C49: =Otto!$D$34+(Otto!$D$35-Otto!$D$34)*B49 -> 0.32504966 | D49: =Otto!$C$34*(Otto!$D$34/C49)^(Otto!$C$10-1) -> 2175.7028 | E49: =Otto!$C$13*D49/C49 -> 1921.0194 | F49: =Otto!$E$34 -> 1.0751253 | G49: =C49*Otto!$C$28*1000000 -> 108.22038
A50: 3→4 | B50: 0.263158 | C50: =Otto!$D$34+(Otto!$D$35-Otto!$D$34)*B50 -> 0.3760383 | D50: =Otto!$C$34*(Otto!$D$34/C50)^(Otto!$C$10-1) -> 2052.5163 | E50: =Otto!$C$13*D50/C50 -> 1566.5218 | F50: =Otto!$E$34 -> 1.0751253 | G50: =C50*Otto!$C$28*1000000 -> 125.19627
A51: 3→4 | B51: 0.315789 | C51: =Otto!$D$34+(Otto!$D$35-Otto!$D$34)*B51 -> 0.42702597 | D51: =Otto!$C$34*(Otto!$D$34/C51)^(Otto!$C$10-1) -> 1950.7326 | E51: =Otto!$C$13*D51/C51 -> 1311.0684 | F51: =Otto!$E$34 -> 1.0751253 | G51: =C51*Otto!$C$28*1000000 -> 142.17185
A52: 3→4 | B52: 0.368421 | C52: =Otto!$D$34+(Otto!$D$35-Otto!$D$34)*B52 -> 0.47801461 | D52: =Otto!$C$34*(Otto!$D$34/C52)^(Otto!$C$10-1) -> 1864.6743 | E52: =Otto!$C$13*D52/C52 -> 1119.5506 | F52: =Otto!$E$34 -> 1.0751253 | G52: =C52*Otto!$C$28*1000000 -> 159.14774
A53: 3→4 | B53: 0.421053 | C53: =Otto!$D$34+(Otto!$D$35-Otto!$D$34)*B53 -> 0.52900324 | D53: =Otto!$C$34*(Otto!$D$34/C53)^(Otto!$C$10-1) -> 1790.5899 | E53: =Otto!$C$13*D53/C53 -> 971.44828 | F53: =Otto!$E$34 -> 1.0751253 | G53: =C53*Otto!$C$28*1000000 -> 176.12364
A54: 3→4 | B54: 0.473684 | C54: =Otto!$D$34+(Otto!$D$35-Otto!$D$34)*B54 -> 0.57999091 | D54: =Otto!$C$34*(Otto!$D$34/C54)^(Otto!$C$10-1) -> 1725.8815 | E54: =Otto!$C$13*D54/C54 -> 854.02717 | F54: =Otto!$E$34 -> 1.0751253 | G54: =C54*Otto!$C$28*1000000 -> 193.09922
A55: 3→4 | B55: 0.526316 | C55: =Otto!$D$34+(Otto!$D$35-Otto!$D$34)*B55 -> 0.63097955 | D55: =Otto!$C$34*(Otto!$D$34/C55)^(Otto!$C$10-1) -> 1668.6811 | E55: =Otto!$C$13*D55/C55 -> 758.99682 | F55: =Otto!$E$34 -> 1.0751253 | G55: =C55*Otto!$C$28*1000000 -> 210.07511
...

Sheet Graficas

Sheet Angulo
A1: Presión y temperatura en función del ángulo del cigüeñal (ciclo ideal de 720°)
A2: V(θ) = V_CC + (V_C/2)·[(1 − cos θ) + (1/λ)(1 − √(1 − λ²·sen²θ))]
A4: θ (°) | B4: Tiempo | C4: V (cm³) | D4: P (kPa) | E4: T (K) | G4: Ciclo ideal: la combustión ocurre en el PMS (360°) y el escape baja la presión a P1 en el PMI (540°). En admisión y escape se asigna T = T1 (el modelo ideal no describe la renovación de la carga).
A5: 0 | B5: Admisión | C5: =Otto!$C$24+Otto!$C$23/2*((1-COS(RADIANS(A5)))+1/Otto!$C$26*(1-SQRT(1-Otto!$C$26^2*SIN(RADIANS(A5))^2))) -> 40.317433 | D5: =Otto!$C$6 -> 79 | E5: =Otto!$C$7 -> 300
A6: 4 | B6: Admisión | C6: =Otto!$C$24+Otto!$C$23/2*((1-COS(RADIANS(A6)))+1/Otto!$C$26*(1-SQRT(1-Otto!$C$26^2*SIN(RADIANS(A6))^2))) -> 40.811373 | D6: =Otto!$C$6 -> 79 | E6: =Otto!$C$7 -> 300
A7: 8 | B7: Admisión | C7: =Otto!$C$24+Otto!$C$23/2*((1-COS(RADIANS(A7)))+1/Otto!$C$26*(1-SQRT(1-Otto!$C$26^2*SIN(RADIANS(A7))^2))) -> 42.289408 | D7: =Otto!$C$6 -> 79 | E7: =Otto!$C$7 -> 300
A8: 12 | B8: Admisión | C8: =Otto!$C$24+Otto!$C$23/2*((1-COS(RADIANS(A8)))+1/Otto!$C$26*(1-SQRT(1-Otto!$C$26^2*SIN(RADIANS(A8))^2))) -> 44.740223 | D8: =Otto!$C$6 -> 79 | E8: =Otto!$C$7 -> 300
A9: 16 | B9: Admisión | C9: =Otto!$C$24+Otto!$C$23/2*((1-COS(RADIANS(A9)))+1/Otto!$C$26*(1-SQRT(1-Otto!$C$26^2*SIN(RADIANS(A9))^2))) -> 48.145087 | D9: =Otto!$C$6 -> 79 | E9: =Otto!$C$7 -> 300
A10: 20 | B10: Admisión | C10: =Otto!$C$24+Otto!$C$23/2*((1-COS(RADIANS(A10)))+1/Otto!$C$26*(1-SQRT(1-Otto!$C$26^2*SIN(RADIANS(A10))^2))) -> 52.478049 | D10: =Otto!$C$6 -> 79 | E10: =Otto!$C$7 -> 300
A11: 24 | B11: Admisión | C11: =Otto!$C$24+Otto!$C$23/2*((1-COS(RADIANS(A11)))+1/Otto!$C$26*(1-SQRT(1-Otto!$C$26^2*SIN(RADIANS(A11))^2))) -> 57.706202 | D11: =Otto!$C$6 -> 79 | E11: =Otto!$C$7 -> 300
A12: 28 | B12: Admisión | C12: =Otto!$C$24+Otto!$C$23/2*((1-COS(RADIANS(A12)))+1/Otto!$C$26*(1-SQRT(1-Otto!$C$26^2*SIN(RADIANS(A12))^2))) -> 63.790031 | D12: =Otto!$C$6 -> 79 | E12: =Otto!$C$7 -> 300
A13: 32 | B13: Admisión | C13: =Otto!$C$24+Otto!$C$23/2*((1-COS(RADIANS(A13)))+1/Otto!$C$26*(1-SQRT(1-Otto!$C$26^2*SIN(RADIANS(A13))^2))) -> 70.683825 | D13: =Otto!$C$6 -> 79 | E13: =Otto!$C$7 -> 300
A14: 36 | B14: Admisión | C14: =Otto!$C$24+Otto!$C$23/2*((1-COS(RADIANS(A14)))+1/Otto!$C$26*(1-SQRT(1-Otto!$C$26^2*SIN(RADIANS(A14))^2))) -> 78.336164 | D14: =Otto!$C$6 -> 79 | E14: =Otto!$C$7 -> 300
A15: 40 | B15: Admisión | C15: =Otto!$C$24+Otto!$C$23/2*((1-COS(RADIANS(A15)))+1/Otto!$C$26*(1-SQRT(1-Otto!$C$26^2*SIN(RADIANS(A15))^2))) -> 86.690473 | D15: =Otto!$C$6 -> 79 | E15: =Otto!$C$7 -> 300
A16: 44 | B16: Admisión | C16: =Otto!$C$24+Otto!$C$23/2*((1-COS(RADIANS(A16)))+1/Otto!$C$26*(1-SQRT(1-Otto!$C$26^2*SIN(RADIANS(A16))^2))) -> 95.68563 | D16: =Otto!$C$6 -> 79 | E16: =Otto!$C$7 -> 300
... A50: 180 | B50: Admisión | C50: =Otto!$C$24+Otto!$C$23/2*((1-COS(RADIANS(A50)))+1/Otto!$C$26*(1-SQRT(1-Otto!$C$26^2*SIN(RADIANS(A50))^2))) -> 362.8569 | D50: =Otto!$C$6 -> 79 | E50: =Otto!$C$7 -> 300
A51: 184 | B51: Compresión | C51: =Otto!$C$24+Otto!$C$23/2*((1-COS(RADIANS(A51)))+1/Otto!$C$26*(1-SQRT(1-Otto!$C$26^2*SIN(RADIANS(A51))^2))) -> 362.56515 | D51: =Otto!$C$6*(Otto!$C$25/C51)^Otto!$C$10 -> 79.089012 | E51: =D51*C51*0.000001/(Otto!$C$28*Otto!$C$13) -> 300.09654
A52: 188 | B52: Compresión | C52: =Otto!$C$24+Otto!$C$23/2*((1-COS(RADIANS(A52)))+1/Otto!$C$26*(1-SQRT(1-Otto!$C$26^2*SIN(RADIANS(A52))^2))) -> 361.68994 | D52: =Otto!$C$6*(Otto!$C$25/C52)^Otto!$C$10 -> 79.35707 | E52: =D52*C52*0.000001/(Otto!$C$28*Otto!$C$13) -> 300.38679
A53: 192 | B53: Compresión | C53: =Otto!$C$24+Otto!$C$23/2*((1-COS(RADIANS(A53)))+1/Otto!$C$26*(1-SQRT(1-Otto!$C$26^2*SIN(RADIANS(A53))^2))) -> 360.23143 | D53: =Otto!$C$6*(Otto!$C$25/C53)^Otto!$C$10 -> 79.807258 | E53: =D53*C53*0.000001/(Otto!$C$28*Otto!$C$13) -> 300.87269
A54: 196 | B54: Compresión | C54: =Otto!$C$24+Otto!$C$23/2*((1-COS(RADIANS(A54)))+1/Otto!$C$26*(1-SQRT(1-Otto!$C$26^2*SIN(RADIANS(A54))^2))) -> 358.18992 | D54: =Otto!$C$6*(Otto!$C$25/C54)^Otto!$C$10 -> 80.44479 | E54: =D54*C54*0.000001/(Otto!$C$28*Otto!$C$13) -> 301.55745
A55: 200 | B55: Compresión | C55: =Otto!$C$24+Otto!$C$23/2*((1-COS(RADIANS(A55)))+1/Otto!$C$26*(1-SQRT(1-Otto!$C$26^2*SIN(RADIANS(A55))^2))) -> 355.566 | D55: =Otto!$C$6*(Otto!$C$25/C55)^Otto!$C$10 -> 81.27712 | E55: =D55*C55*0.000001/(Otto!$C$28*Otto!$C$13) -> 302.44563
A56: 204 | B56: Compresión | C56: =Otto!$C$24+Otto!$C$23/2*((1-COS(RADIANS(A56)))+1/Otto!$C$26*(1-SQRT(1-Otto!$C$26^2*SIN(RADIANS(A56))^2))) -> 352.36066 | D56: =Otto!$C$6*(Otto!$C$25/C56)^Otto!$C$10 -> 82.314101 | E56: =D56*C56*0.000001/(Otto!$C$28*Otto!$C$13) -> 303.54315
A57: 208 | B57: Compresión | C57: =Otto!$C$24+Otto!$C$23/2*((1-COS(RADIANS(A57)))+1/Otto!$C$26*(1-SQRT(1-Otto!$C$26^2*SIN(RADIANS(A57))^2))) -> 348.57547 | D57: =Otto!$C$6*(Otto!$C$25/C57)^Otto!$C$10 -> 83.568204 | E57: =D57*C57*0.000001/(Otto!$C$28*Otto!$C$13) -> 304.85735
A58: 212 | B58: Compresión | C58: =Otto!$C$24+Otto!$C$23/2*((1-COS(RADIANS(A58)))+1/Otto!$C$26*(1-SQRT(1-Otto!$C$26^2*SIN(RADIANS(A58))^2))) -> 344.2128 | D58: =Otto!$C$6*(Otto!$C$25/C58)^Otto!$C$10 -> 85.054794 | E58: =D58*C58*0.000001/(Otto!$C$28*Otto!$C$13) -> 306.39706
A59: 216 | B59: Compresión | C59: =Otto!$C$24+Otto!$C$23/2*((1-COS(RADIANS(A59)))+1/Otto!$C$26*(1-SQRT(1-Otto!$C$26^2*SIN(RADIANS(A59))^2))) -> 339.27607 | D59: =Otto!$C$6*(Otto!$C$25/C59)^Otto!$C$10 -> 86.792481 | E59: =D59*C59*0.000001/(Otto!$C$28*Otto!$C$13) -> 308.17267
A60: 220 | B60: Compresión | C60: =Otto!$C$24+Otto!$C$23/2*((1-COS(RADIANS(A60)))+1/Otto!$C$26*(1-SQRT(1-Otto!$C$26^2*SIN(RADIANS(A60))^2))) -> 333.77004 | D60: =Otto!$C$6*(Otto!$C$25/C60)^Otto!$C$10 -> 88.803553 | E60: =D60*C60*0.000001/(Otto!$C$28*Otto!$C$13) -> 310.1962
A61: 224 | B61: Compresión | C61: =Otto!$C$24+Otto!$C$23/2*((1-COS(RADIANS(A61)))+1/Otto!$C$26*(1-SQRT(1-Otto!$C$26^2*SIN(RADIANS(A61))^2))) -> 327.7011 | D61: =Otto!$C$6*(Otto!$C$25/C61)^Otto!$C$10 -> 91.114514 | E61: =D61*C61*0.000001/(Otto!$C$28*Otto!$C$13) -> 312.48145
A62: 228 | B62: Compresión | C62: =Otto!$C$24+Otto!$C$23/2*((1-COS(RADIANS(A62)))+1/Otto!$C$26*(1-SQRT(1-Otto!$C$26^2*SIN(RADIANS(A62))^2))) -> 321.07766 | D62: =Otto!$C$6*(Otto!$C$25/C62)^Otto!$C$10 -> 93.756739 | E62: =D62*C62*0.000001/(Otto!$C$28*Otto!$C$13) -> 315.04411
... A95: 360 | B95: Compresión | C95: =Otto!$C$24+Otto!$C$23/2*((1-COS(RADIANS(A95)))+1/Otto!$C$26*(1-SQRT(1-Otto!$C$26^2*SIN(RADIANS(A95))^2))) -> 40.317433 | D95: =Otto!$C$6*(Otto!$C$25/C95)^Otto!$C$10 -> 1712.2478 | E95: =D95*C95*0.000001/(Otto!$C$28*Otto!$C$13) -> 722.46741
A96: 364 | B96: Expansión | C96: =Otto!$C$24+Otto!$C$23/2*((1-COS(RADIANS(A96)))+1/Otto!$C$26*(1-SQRT(1-Otto!$C$26^2*SIN(RADIANS(A96))^2))) -> 40.811373 | D96: =Otto!$B$34*(Otto!$F$34/C96)^Otto!$C$10 -> 7524.3799 | E96: =D96*C96*0.000001/(Otto!$C$28*Otto!$C$13) -> 3213.7397
A97: 368 | B97: Expansión | C97: =Otto!$C$24+Otto!$C$23/2*((1-COS(RADIANS(A97)))+1/Otto!$C$26*(1-SQRT(1-Otto!$C$26^2*SIN(RADIANS(A97))^2))) -> 42.289408 | D97: =Otto!$B$34*(Otto!$F$34/C97)^Otto!$C$10 -> 7158.7988 | E97: =D97*C97*0.000001/(Otto!$C$28*Otto!$C$13) -> 3168.331
A98: 372 | B98: Expansión | C98: =Otto!$C$24+Otto!$C$23/2*((1-COS(RADIANS(A98)))+1/Otto!$C$26*(1-SQRT(1-Otto!$C$26^2*SIN(RADIANS(A98))^2))) -> 44.740223 | D98: =Otto!$B$34*(Otto!$F$34/C98)^Otto!$C$10 -> 6615.8706 | E98: =D98*C98*0.000001/(Otto!$C$28*Otto!$C$13) -> 3097.7326
A99: 376 | B99: Expansión | C99: =Otto!$C$24+Otto!$C$23/2*((1-COS(RADIANS(A99)))+1/Otto!$C$26*(1-SQRT(1-Otto!$C$26^2*SIN(RADIANS(A99))^2))) -> 48.145087 | D99: =Otto!$B$34*(Otto!$F$34/C99)^Otto!$C$10 -> 5970.2379 | E99: =D99*C99*0.000001/(Otto!$C$28*Otto!$C$13) -> 3008.1701
A100: 380 | B100: Expansión | C100: =Otto!$C$24+Otto!$C$23/2*((1-COS(RADIANS(A100)))+1/Otto!$C$26*(1-SQRT(1-Otto!$C$26^2*SIN(RADIANS(A100))^2))) -> 52.478049 | D100: =Otto!$B$34*(Otto!$F$34/C100)^Otto!$C$10 -> 5291.7053 | E100: =D100*C100*0.000001/(Otto!$C$28*Otto!$C$13) -> 2906.2443
A101: 384 | B101: Expansión | C101: =Otto!$C$24+Otto!$C$23/2*((1-COS(RADIANS(A101)))+1/Otto!$C$26*(1-SQRT(1-Otto!$C$26^2*SIN(RADIANS(A101))^2))) -> 57.706202 | D101: =Otto!$B$34*(Otto!$F$34/C101)^Otto!$C$10 -> 4632.8998 | E101: =D101*C101*0.000001/(Otto!$C$28*Otto!$C$13) -> 2797.9129
A102: 388 | B102: Expansión | C102: =Otto!$C$24+Otto!$C$23/2*((1-COS(RADIANS(A102)))+1/Otto!$C$26*(1-SQRT(1-Otto!$C$26^2*SIN(RADIANS(A102))^2))) -> 63.790031 | D102: =Otto!$B$34*(Otto!$F$34/C102)^Otto!$C$10 -> 4026.3402 | E102: =D102*C102*0.000001/(Otto!$C$28*Otto!$C$13) -> 2687.9554
A103: 392 | B103: Expansión | C103: =Otto!$C$24+Otto!$C$23/2*((1-COS(RADIANS(A103)))+1/Otto!$C$26*(1-SQRT(1-Otto!$C$26^2*SIN(RADIANS(A103))^2))) -> 70.683825 | D103: =Otto!$B$34*(Otto!$F$34/C103)^Otto!$C$10 -> 3487.5171 | E103: =D103*C103*0.000001/(Otto!$C$28*Otto!$C$13) -> 2579.8542
A104: 396 | B104: Expansión | C104: =Otto!$C$24+Otto!$C$23/2*((1-COS(RADIANS(A104)))+1/Otto!$C$26*(1-SQRT(1-Otto!$C$26^2*SIN(RADIANS(A104))^2))) -> 78.336164 | D104: =Otto!$B$34*(Otto!$F$34/C104)^Otto!$C$10 -> 3020.0712 | E104: =D104*C104*0.000001/(Otto!$C$28*Otto!$C$13) -> 2475.9294
A105: 400 | B105: Expansión | C105: =Otto!$C$24+Otto!$C$23/2*((1-COS(RADIANS(A105)))+1/Otto!$C$26*(1-SQRT(1-Otto!$C$26^2*SIN(RADIANS(A105))^2))) -> 86.690473 | D105: =Otto!$B$34*(Otto!$F$34/C105)^Otto!$C$10 -> 2620.6226 | E105: =D105*C105*0.000001/(Otto!$C$28*Otto!$C$13) -> 2377.5772
A106: 404 | B106: Expansión | C106: =Otto!$C$24+Otto!$C$23/2*((1-COS(RADIANS(A106)))+1/Otto!$C$26*(1-SQRT(1-Otto!$C$26^2*SIN(RADIANS(A106))^2))) -> 95.68563 | D106: =Otto!$B$34*(Otto!$F$34/C106)^Otto!$C$10 -> 2282.3329 | E106: =D106*C106*0.000001/(Otto!$C$28*Otto!$C$13) -> 2285.5172
...

Sheet Parametrico
A1: Influencia de la relación de compresión
A2: Demás datos de la hoja Otto
A4: r | B4: η (%) | C4: T2 (K) | D4: P3 (kPa) | E4: PME (kPa)
A5: 4 | B5: =(1-1/A5^(Otto!$C$10-1))*100 -> 42.565082 | C5: =Otto!$C$7*A5^(Otto!$C$10-1) -> 522.33034 | D5: =Otto!$C$6*A5^Otto!$C$10*(C5+Otto!$C$9/Otto!$C$11)/C5 -> 3190.8565 | E5: =Otto!$C$9*B5/100/(Otto!$C$27*(1-1/A5)) -> 937.32167
A6: 5 | B6: =(1-1/A6^(Otto!$C$10-1))*100 -> 47.469444 | C6: =Otto!$C$7*A6^(Otto!$C$10-1) -> 571.09618 | D6: =Otto!$C$6*A6^Otto!$C$10*(C6+Otto!$C$9/Otto!$C$11)/C6 -> 4052.779 | E6: =Otto!$C$9*B6/100/(Otto!$C$27*(1-1/A6)) -> 979.98765
A7: 6 | B7: =(1-1/A7^(Otto!$C$10-1))*100 -> 51.164066 | C7: =Otto!$C$7*A7^(Otto!$C$10-1) -> 614.30175 | D7: =Otto!$C$6*A7^Otto!$C$10*(C7+Otto!$C$9/Otto!$C$11)/C7 -> 4931.5996 | E7: =Otto!$C$9*B7/100/(Otto!$C$27*(1-1/A7)) -> 1014.0112
A8: 7 | B8: =(1-1/A8^(Otto!$C$10-1))*100 -> 54.084345 | C8: =Otto!$C$7*A8^(Otto!$C$10-1) -> 653.37193 | D8: =Otto!$C$6*A8^Otto!$C$10*(C8+Otto!$C$9/Otto!$C$11)/C8 -> 5825.5522 | E8: =Otto!$C$9*B8/100/(Otto!$C$27*(1-1/A8)) -> 1042.113
A9: 8 | B9: =(1-1/A9^(Otto!$C$10-1))*100 -> 56.472472 | C9: =Otto!$C$7*A9^(Otto!$C$10-1) -> 689.21901 | D9: =Otto!$C$6*A9^Otto!$C$10*(C9+Otto!$C$9/Otto!$C$11)/C9 -> 6733.2918 | E9: =Otto!$C$9*B9/100/(Otto!$C$27*(1-1/A9)) -> 1065.9214
A10: 9 | B10: =(1-1/A10^(Otto!$C$10-1))*100 -> 58.475635 | C10: =Otto!$C$7*A10^(Otto!$C$10-1) -> 722.46741 | D10: =Otto!$C$6*A10^Otto!$C$10*(C10+Otto!$C$9/Otto!$C$11)/C10 -> 7653.7519 | E10: =Otto!$C$9*B10/100/(Otto!$C$27*(1-1/A10)) -> 1086.4855
A11: 10 | B11: =(1-1/A11^(Otto!$C$10-1))*100 -> 60.189283 | C11: =Otto!$C$7*A11^(Otto!$C$10-1) -> 753.56593 | D11: =Otto!$C$6*A11^Otto!$C$10*(C11+Otto!$C$9/Otto!$C$11)/C11 -> 8586.0616 | E11: =Otto!$C$9*B11/100/(Otto!$C$27*(1-1/A11)) -> 1104.5188
A12: 11 | B12: =(1-1/A12^(Otto!$C$10-1))*100 -> 61.678462 | C12: =Otto!$C$7*A12^(Otto!$C$10-1) -> 782.84959 | D12: =Otto!$C$6*A12^Otto!$C$10*(C12+Otto!$C$9/Otto!$C$11)/C12 -> 9529.4928 | E12: =Otto!$C$9*B12/100/(Otto!$C$27*(1-1/A12)) -> 1120.5279
A13: 12 | B13: =(1-1/A13^(Otto!$C$10-1))*100 -> 62.989283 | C13: =Otto!$C$7*A13^(Otto!$C$10-1) -> 810.57602 | D13: =Otto!$C$6*A13^Otto!$C$10*(C13+Otto!$C$9/Otto!$C$11)/C13 -> 10483.426 | E13: =Otto!$C$9*B13/100/(Otto!$C$27*(1-1/A13)) -> 1134.8845
A14: 13 | B14: =(1-1/A14^(Otto!$C$10-1))*100 -> 64.155489 | C14: =Otto!$C$7*A14^(Otto!$C$10-1) -> 836.94823 | D14: =Otto!$C$6*A14^Otto!$C$10*(C14+Otto!$C$9/Otto!$C$11)/C14 -> 11447.325 | E14: =Otto!$C$9*B14/100/(Otto!$C$27*(1-1/A14)) -> 1147.8691
A15: 14 | B15: =(1-1/A15^(Otto!$C$10-1))*100 -> 65.202441 | C15: =Otto!$C$7*A15^(Otto!$C$10-1) -> 862.12943 | D15: =Otto!$C$6*A15^Otto!$C$10*(C15+Otto!$C$9/Otto!$C$11)/C15 -> 12420.724 | E15: =Otto!$C$9*B15/100/(Otto!$C$27*(1-1/A15)) -> 1159.6982
A16: 15 | B16: =(1-1/A16^(Otto!$C$10-1))*100 -> 66.149624 | C16: =Otto!$C$7*A16^(Otto!$C$10-1) -> 886.25308 | D16: =Otto!$C$6*A16^Otto!$C$10*(C16+Otto!$C$9/Otto!$C$11)/C16 -> 13403.207 | E16: =Otto!$C$9*B16/100/(Otto!$C$27*(1-1/A16)) -> 1170.5421
A17: 16 | B17: =(1-1/A17^(Otto!$C$10-1))*100 -> 67.012302 | C17: =Otto!$C$7*A17^(Otto!$C$10-1) -> 909.42994 | D17: =Otto!$C$6*A17^Otto!$C$10*(C17+Otto!$C$9/Otto!$C$11)/C17 -> 14394.406 | E17: =Otto!$C$9*B17/100/(Otto!$C$27*(1-1/A17)) -> 1180.5373
