Workbook

Sheet Diesel
A1: GUÍA 7 – CICLO DIESEL IDEAL: DIAGRAMAS P–v, P–V, T–s Y P–θ
A2: η = 1 − (1/r^(γ−1))·[(r_c^γ − 1)/(γ(r_c − 1))]
A3: Leyenda: celdas amarillas con texto azul = datos de entrada (editar). Texto negro = fórmulas (no editar).
A5: Parámetro | B5: Símbolo | C5: Valor | D5: Unidad | E5: Observación
A6: Presión inicial (Loja) | B6: P1 | C6: 79 | D6: kPa
A7: Temperatura inicial | B7: T1 | C7: 300 | D7: K
A8: Relación de compresión | B8: r | C8: 18 | D8: —
A9: Relación de corte r_c | B9: rc | C9: 2 | D9: —
A10: Relación de calores específicos γ | B10: g | C10: 1.4 | D10: —
A11: Calor específico a v cte | B11: cv | C11: 0.718 | D11: kJ/(kg·K)
A12: Calor específico a P cte | B12: cp | C12: 1.005 | D12: kJ/(kg·K)
A13: Constante del aire | B13: R | C13: 0.287 | D13: kJ/(kg·K)
A14: Diámetro del cilindro | B14: D | C14: 7.8 | D14: cm
A15: Carrera | B15: S | C15: 6.75 | D15: cm
A16: Número de cilindros | B16: Z | C16: 4 | D16: —
A17: Longitud de la biela | B17: Lb | C17: 13.1 | D17: cm
A18: Régimen de giro | B18: n | C18: 3000 | D18: rpm
A20: Geometría (ecuaciones de la guía original) y masa de aire
A21: Magnitud | B21: Ecuación | C21: Valor | D21: Unidad
A22: Área del pistón | B22: A_P = π·D²/4 | C22: =PI()*Diesel!$C$14^2/4 -> 47.783624 | D22: cm²
A23: Volumen del cilindro | B23: V_C = A_P·S | C23: =Diesel!$C$22*Diesel!$C$15 -> 322.53946 | D23: cm³
A24: Volumen de la cámara | B24: V_CC = V_C/(r − 1) | C24: =Diesel!$C$23/(Diesel!$C$8-1) -> 18.97291 | D24: cm³
A25: Volumen unitario | B25: V_u = V_C + V_CC | C25: =Diesel!$C$23+Diesel!$C$24 -> 341.51237 | D25: cm³
A26: Relación biela–manivela | B26: λ = (S/2)/L | C26: =Diesel!$C$15/2/Diesel!$C$17 -> 0.25763359 | D26: —
A27: Volumen específico en 1 | B27: v1 = R·T1/P1 | C27: =Diesel!$C$13*Diesel!$C$7/Diesel!$C$6 -> 1.0898734 | D27: m³/kg
A28: Masa de aire por cilindro | B28: m = V_u/v1 | C28: =Diesel!$C$25*0.000001/Diesel!$C$27 -> 0.00031335049 | D28: kg
A30: Estados del ciclo (s referida al estado 1)
A31: Estado | B31: P (kPa) | C31: T (K) | D31: v (m³/kg) | E31: s (kJ/kg·K) | F31: V (cm³)
A32: 1 | B32: =Diesel!$C$6 -> 79 | C32: =Diesel!$C$7 -> 300 | D32: =Diesel!$C$27 -> 1.0898734 | E32: =0 -> 0 | F32: =Diesel!$D$32*Diesel!$C$28*1000000 -> 341.51237
A33: 2 | B33: =Diesel!$C$6*Diesel!$C$8^Diesel!$C$10 -> 4518.6489 | C33: =Diesel!$C$7*Diesel!$C$8^(Diesel!$C$10-1) -> 953.30146 | D33: =Diesel!$C$27/Diesel!$C$8 -> 0.060548523 | E33: =0 -> 0 | F33: =Diesel!$D$33*Diesel!$C$28*1000000 -> 18.97291
A34: 3 | B34: =Diesel!$B$33 -> 4518.6489 | C34: =Diesel!$C$33*Diesel!$C$9 -> 1906.6029 | D34: =Diesel!$D$33*Diesel!$C$9 -> 0.12109705 | E34: =Diesel!$C$12*LN(Diesel!$C$9) -> 0.69661292 | F34: =Diesel!$D$34*Diesel!$C$28*1000000 -> 37.945819
A35: 4 | B35: =Diesel!$B$34*(Diesel!$D$34/Diesel!$C$27)^Diesel!$C$10 -> 208.48225 | C35: =Diesel!$C$34*(Diesel!$C$9/Diesel!$C$8)^(Diesel!$C$10-1) -> 791.70475 | D35: =Diesel!$C$27 -> 1.0898734 | E35: =Diesel!$E$34 -> 0.69661292 | F35: =Diesel!$D$35*Diesel!$C$28*1000000 -> 341.51237
A37: Balance por proceso (por unidad de masa): Q − W = ΔU
A38: Proceso | B38: Tipo | C38: Q (kJ/kg) | D38: W (kJ/kg) | E38: ΔU (kJ/kg) | F38: Δs (kJ/kg·K) | G38: Q − W − ΔU
A39: 1→2 | B39: Compresión adiabática | C39: =0 -> 0 | D39: =-E39 -> -469.07045 | E39: =Diesel!$C$11*(Diesel!$C$33-Diesel!$C$32) -> 469.07045 | F39: =Diesel!$E$33-Diesel!$E$32 -> 0 | G39: =C39-D39-E39 -> 0
A40: 2→3 | B40: Aporte de calor a P cte | C40: =Diesel!$C$12*(Diesel!$C$34-Diesel!$C$33) -> 958.06796 | D40: =Diesel!$B$33*(Diesel!$D$34-Diesel!$D$33) -> 273.59752 | E40: =Diesel!$C$11*(Diesel!$C$34-Diesel!$C$33) -> 684.47045 | F40: =Diesel!$E$34-Diesel!$E$33 -> 0.69661292 | G40: =C40-D40-E40 -> 0
A41: 3→4 | B41: Expansión adiabática | C41: =0 -> 0 | D41: =-E41 -> 800.49688 | E41: =Diesel!$C$11*(Diesel!$C$35-Diesel!$C$34) -> -800.49688 | F41: =Diesel!$E$35-Diesel!$E$34 -> 0 | G41: =C41-D41-E41 -> 0
A42: 4→1 | B42: Cesión de calor a v cte | C42: =Diesel!$C$11*(Diesel!$C$32-Diesel!$C$35) -> -353.04401 | D42: =0 -> 0 | E42: =Diesel!$C$11*(Diesel!$C$32-Diesel!$C$35) -> -353.04401 | F42: =Diesel!$E$32-Diesel!$E$35 -> -0.69661292 | G42: =C42-D42-E42 -> 0
A43: Ciclo | C43: =SUM(C39:C42) -> 605.02396 | D43: =SUM(D39:D42) -> 605.02396 | E43: =SUM(E39:E42) -> 0 | F43: =SUM(F39:F42) -> 0
A44: Convención: Q > 0 recibido por el gas; W > 0 realizado por el gas. En el ciclo ΔU = 0 y Δs = 0 (pequeñas diferencias se deben a redondeos de c_p y c_v).
...

Sheet Puntos
A1: Puntos de los diagramas (20 por proceso)
A2: Columnas: proceso, fracción, v, T, P, s, V
A4: Proceso | B4: t | C4: v (m³/kg) | D4: T (K) | E4: P (kPa) | F4: s (kJ/kg·K) | G4: V (cm³)
A5: 1→2 | B5: 0 | C5: =Diesel!$D$32+(Diesel!$D$33-Diesel!$D$32)*B5 -> 1.0898734 | D5: =Diesel!$C$32*(Diesel!$D$32/C5)^(Diesel!$C$10-1) -> 300 | E5: =Diesel!$C$13*D5/C5 -> 79 | F5: =0 -> 0 | G5: =C5*Diesel!$C$28*1000000 -> 341.51237
A6: 1→2 | B6: 0.052632 | C6: =Diesel!$D$32+(Diesel!$D$33-Diesel!$D$32)*B6 -> 1.035698 | D6: =Diesel!$C$32*(Diesel!$D$32/C6)^(Diesel!$C$10-1) -> 306.18113 | E6: =Diesel!$C$13*D6/C6 -> 84.845183 | F6: =0 -> 0 | G6: =C6*Diesel!$C$28*1000000 -> 324.53648
A7: 1→2 | B7: 0.105263 | C7: =Diesel!$D$32+(Diesel!$D$33-Diesel!$D$32)*B7 -> 0.98152359 | D7: =Diesel!$C$32*(Diesel!$D$32/C7)^(Diesel!$C$10-1) -> 312.83215 | E7: =Diesel!$C$13*D7/C7 -> 91.472919 | F7: =0 -> 0 | G7: =C7*Diesel!$C$28*1000000 -> 307.5609
A8: 1→2 | B8: 0.157895 | C8: =Diesel!$D$32+(Diesel!$D$33-Diesel!$D$32)*B8 -> 0.92734816 | D8: =Diesel!$C$32*(Diesel!$D$32/C8)^(Diesel!$C$10-1) -> 320.01811 | E8: =Diesel!$C$13*D8/C8 -> 99.040684 | F8: =0 -> 0 | G8: =C8*Diesel!$C$28*1000000 -> 290.585
A9: 1→2 | B9: 0.210526 | C9: =Diesel!$D$32+(Diesel!$D$33-Diesel!$D$32)*B9 -> 0.87317376 | D9: =Diesel!$C$32*(Diesel!$D$32/C9)^(Diesel!$C$10-1) -> 327.81695 | E9: =Diesel!$C$13*D9/C9 -> 107.74885 | F9: =0 -> 0 | G9: =C9*Diesel!$C$28*1000000 -> 273.60943
A10: 1→2 | B10: 0.263158 | C10: =Diesel!$D$32+(Diesel!$D$33-Diesel!$D$32)*B10 -> 0.81899834 | D10: =Diesel!$C$32*(Diesel!$D$32/C10)^(Diesel!$C$10-1) -> 336.32447 | E10: =Diesel!$C$13*D10/C10 -> 117.85753 | F10: =0 -> 0 | G10: =C10*Diesel!$C$28*1000000 -> 256.63353
A11: 1→2 | B11: 0.315789 | C11: =Diesel!$D$32+(Diesel!$D$33-Diesel!$D$32)*B11 -> 0.76482394 | D11: =Diesel!$C$32*(Diesel!$D$32/C11)^(Diesel!$C$10-1) -> 345.65838 | E11: =Diesel!$C$13*D11/C11 -> 129.70822 | F11: =0 -> 0 | G11: =C11*Diesel!$C$28*1000000 -> 239.65796
A12: 1→2 | B12: 0.368421 | C12: =Diesel!$D$32+(Diesel!$D$33-Diesel!$D$32)*B12 -> 0.71064851 | D12: =Diesel!$C$32*(Diesel!$D$32/C12)^(Diesel!$C$10-1) -> 355.967 | E12: =Diesel!$C$13*D12/C12 -> 143.75958 | F12: =0 -> 0 | G12: =C12*Diesel!$C$28*1000000 -> 222.68206
A13: 1→2 | B13: 0.421053 | C13: =Diesel!$D$32+(Diesel!$D$33-Diesel!$D$32)*B13 -> 0.65647308 | D13: =Diesel!$C$32*(Diesel!$D$32/C13)^(Diesel!$C$10-1) -> 367.43871 | E13: =Diesel!$C$13*D13/C13 -> 160.63859 | F13: =0 -> 0 | G13: =C13*Diesel!$C$28*1000000 -> 205.70616
A14: 1→2 | B14: 0.473684 | C14: =Diesel!$D$32+(Diesel!$D$33-Diesel!$D$32)*B14 -> 0.60229868 | D14: =Diesel!$C$32*(Diesel!$D$32/C14)^(Diesel!$C$10-1) -> 380.31803 | E14: =Diesel!$C$13*D14/C14 -> 181.22449 | F14: =0 -> 0 | G14: =C14*Diesel!$C$28*1000000 -> 188.73059
A15: 1→2 | B15: 0.526316 | C15: =Diesel!$D$32+(Diesel!$D$33-Diesel!$D$32)*B15 -> 0.54812326 | D15: =Diesel!$C$32*(Diesel!$D$32/C15)^(Diesel!$C$10-1) -> 394.93024 | E15: =Diesel!$C$13*D15/C15 -> 206.78739 | F15: =0 -> 0 | G15: =C15*Diesel!$C$28*1000000 -> 171.75469
A16: 1→2 | B16: 0.578947 | C16: =Diesel!$D$32+(Diesel!$D$33-Diesel!$D$32)*B16 -> 0.49394886 | D16: =Diesel!$C$32*(Diesel!$D$32/C16)^(Diesel!$C$10-1) -> 411.71708 | E16: =Diesel!$C$13*D16/C16 -> 239.22072 | F16: =0 -> 0 | G16: =C16*Diesel!$C$28*1000000 -> 154.77912
... A24: 1→2 | B24: 1 | C24: =Diesel!$D$32+(Diesel!$D$33-Diesel!$D$32)*B24 -> 0.060548523 | D24: =Diesel!$C$32*(Diesel!$D$32/C24)^(Diesel!$C$10-1) -> 953.30146 | E24: =Diesel!$C$13*D24/C24 -> 4518.6489 | F24: =0 -> 0 | G24: =C24*Diesel!$C$28*1000000 -> 18.97291
A25: 2→3 | B25: 0 | C25: =Diesel!$D$33*D25/Diesel!$C$33 -> 0.060548523 | D25: =Diesel!$C$33+(Diesel!$C$34-Diesel!$C$33)*B25 -> 953.30146 | E25: =Diesel!$C$13*D25/C25 -> 4518.6489 | F25: =Diesel!$C$12*LN(D25/Diesel!$C$33) -> 0 | G25: =C25*Diesel!$C$28*1000000 -> 18.97291
A26: 2→3 | B26: 0.052632 | C26: =Diesel!$D$33*D26/Diesel!$C$33 -> 0.063735313 | D26: =Diesel!$C$33+(Diesel!$C$34-Diesel!$C$33)*B26 -> 1003.4756 | E26: =Diesel!$C$13*D26/C26 -> 4518.6489 | F26: =Diesel!$C$12*LN(D26/Diesel!$C$33) -> 0.051550163 | G26: =C26*Diesel!$C$28*1000000 -> 19.971492
A27: 2→3 | B27: 0.105263 | C27: =Diesel!$D$33*D27/Diesel!$C$33 -> 0.066922042 | D27: =Diesel!$C$33+(Diesel!$C$34-Diesel!$C$33)*B27 -> 1053.6488 | E27: =Diesel!$C$13*D27/C27 -> 4518.6489 | F27: =Diesel!$C$12*LN(D27/Diesel!$C$33) -> 0.10058373 | G27: =C27*Diesel!$C$28*1000000 -> 20.970055
A28: 2→3 | B28: 0.157895 | C28: =Diesel!$D$33*D28/Diesel!$C$33 -> 0.070108832 | D28: =Diesel!$C$33+(Diesel!$C$34-Diesel!$C$33)*B28 -> 1103.823 | E28: =Diesel!$C$13*D28/C28 -> 4518.6489 | F28: =Diesel!$C$12*LN(D28/Diesel!$C$33) -> 0.14733672 | G28: =C28*Diesel!$C$28*1000000 -> 21.968637
A29: 2→3 | B29: 0.210526 | C29: =Diesel!$D$33*D29/Diesel!$C$33 -> 0.073295562 | D29: =Diesel!$C$33+(Diesel!$C$34-Diesel!$C$33)*B29 -> 1153.9962 | E29: =Diesel!$C$13*D29/C29 -> 4518.6489 | F29: =Diesel!$C$12*LN(D29/Diesel!$C$33) -> 0.19201025 | G29: =C29*Diesel!$C$28*1000000 -> 22.9672
A30: 2→3 | B30: 0.263158 | C30: =Diesel!$D$33*D30/Diesel!$C$33 -> 0.076482351 | D30: =Diesel!$C$33+(Diesel!$C$34-Diesel!$C$33)*B30 -> 1204.1704 | E30: =Diesel!$C$13*D30/C30 -> 4518.6489 | F30: =Diesel!$C$12*LN(D30/Diesel!$C$33) -> 0.23478301 | G30: =C30*Diesel!$C$28*1000000 -> 23.965783
A31: 2→3 | B31: 0.315789 | C31: =Diesel!$D$33*D31/Diesel!$C$33 -> 0.079669081 | D31: =Diesel!$C$33+(Diesel!$C$34-Diesel!$C$33)*B31 -> 1254.3436 | E31: =Diesel!$C$13*D31/C31 -> 4518.6489 | F31: =Diesel!$C$12*LN(D31/Diesel!$C$33) -> 0.27580867 | G31: =C31*Diesel!$C$28*1000000 -> 24.964346
A32: 2→3 | B32: 0.368421 | C32: =Diesel!$D$33*D32/Diesel!$C$33 -> 0.082855871 | D32: =Diesel!$C$33+(Diesel!$C$34-Diesel!$C$33)*B32 -> 1304.5177 | E32: =Diesel!$C$13*D32/C32 -> 4518.6489 | F32: =Diesel!$C$12*LN(D32/Diesel!$C$33) -> 0.31522581 | G32: =C32*Diesel!$C$28*1000000 -> 25.962928
A33: 2→3 | B33: 0.421053 | C33: =Diesel!$D$33*D33/Diesel!$C$33 -> 0.086042661 | D33: =Diesel!$C$33+(Diesel!$C$34-Diesel!$C$33)*B33 -> 1354.6919 | E33: =Diesel!$C$13*D33/C33 -> 4518.6489 | F33: =Diesel!$C$12*LN(D33/Diesel!$C$33) -> 0.35315514 | G33: =C33*Diesel!$C$28*1000000 -> 26.96151
A34: 2→3 | B34: 0.473684 | C34: =Diesel!$D$33*D34/Diesel!$C$33 -> 0.08922939 | D34: =Diesel!$C$33+(Diesel!$C$34-Diesel!$C$33)*B34 -> 1404.8651 | E34: =Diesel!$C$13*D34/C34 -> 4518.6489 | F34: =Diesel!$C$12*LN(D34/Diesel!$C$33) -> 0.38970422 | G34: =C34*Diesel!$C$28*1000000 -> 27.960073
A35: 2→3 | B35: 0.526316 | C35: =Diesel!$D$33*D35/Diesel!$C$33 -> 0.09241618 | D35: =Diesel!$C$33+(Diesel!$C$34-Diesel!$C$33)*B35 -> 1455.0393 | E35: =Diesel!$C$13*D35/C35 -> 4518.6489 | F35: =Diesel!$C$12*LN(D35/Diesel!$C$33) -> 0.42497127 | G35: =C35*Diesel!$C$28*1000000 -> 28.958656
A36: 2→3 | B36: 0.578947 | C36: =Diesel!$D$33*D36/Diesel!$C$33 -> 0.095602909 | D36: =Diesel!$C$33+(Diesel!$C$34-Diesel!$C$33)*B36 -> 1505.2125 | E36: =Diesel!$C$13*D36/C36 -> 4518.6489 | F36: =Diesel!$C$12*LN(D36/Diesel!$C$33) -> 0.45904196 | G36: =C36*Diesel!$C$28*1000000 -> 29.957219
... A44: 2→3 | B44: 1 | C44: =Diesel!$D$33*D44/Diesel!$C$33 -> 0.12109705 | D44: =Diesel!$C$33+(Diesel!$C$34-Diesel!$C$33)*B44 -> 1906.6029 | E44: =Diesel!$C$13*D44/C44 -> 4518.6489 | F44: =Diesel!$C$12*LN(D44/Diesel!$C$33) -> 0.69661292 | G44: =C44*Diesel!$C$28*1000000 -> 37.945819
A45: 3→4 | B45: 0 | C45: =Diesel!$D$34+(Diesel!$D$35-Diesel!$D$34)*B45 -> 0.12109705 | D45: =Diesel!$C$34*(Diesel!$D$34/C45)^(Diesel!$C$10-1) -> 1906.6029 | E45: =Diesel!$C$13*D45/C45 -> 4518.6489 | F45: =Diesel!$E$34 -> 0.69661292 | G45: =C45*Diesel!$C$28*1000000 -> 37.945819
A46: 3→4 | B46: 0.052632 | C46: =Diesel!$D$34+(Diesel!$D$35-Diesel!$D$34)*B46 -> 0.17208568 | D46: =Diesel!$C$34*(Diesel!$D$34/C46)^(Diesel!$C$10-1) -> 1656.5928 | E46: =Diesel!$C$13*D46/C46 -> 2762.8221 | F46: =Diesel!$E$34 -> 0.69661292 | G46: =C46*Diesel!$C$28*1000000 -> 53.923134
A47: 3→4 | B47: 0.105263 | C47: =Diesel!$D$34+(Diesel!$D$35-Diesel!$D$34)*B47 -> 0.22307335 | D47: =Diesel!$C$34*(Diesel!$D$34/C47)^(Diesel!$C$10-1) -> 1493.2571 | E47: =Diesel!$C$13*D47/C47 -> 1921.1833 | F47: =Diesel!$E$34 -> 0.69661292 | G47: =C47*Diesel!$C$28*1000000 -> 69.900145
A48: 3→4 | B48: 0.157895 | C48: =Diesel!$D$34+(Diesel!$D$35-Diesel!$D$34)*B48 -> 0.27406199 | D48: =Diesel!$C$34*(Diesel!$D$34/C48)^(Diesel!$C$10-1) -> 1375.2262 | E48: =Diesel!$C$13*D48/C48 -> 1440.1484 | F48: =Diesel!$E$34 -> 0.69661292 | G48: =C48*Diesel!$C$28*1000000 -> 85.87746
A49: 3→4 | B49: 0.210526 | C49: =Diesel!$D$34+(Diesel!$D$35-Diesel!$D$34)*B49 -> 0.32504966 | D49: =Diesel!$C$34*(Diesel!$D$34/C49)^(Diesel!$C$10-1) -> 1284.499 | E49: =Diesel!$C$13*D49/C49 -> 1134.1382 | F49: =Diesel!$E$34 -> 0.69661292 | G49: =C49*Diesel!$C$28*1000000 -> 101.85447
A50: 3→4 | B50: 0.263158 | C50: =Diesel!$D$34+(Diesel!$D$35-Diesel!$D$34)*B50 -> 0.3760383 | D50: =Diesel!$C$34*(Diesel!$D$34/C50)^(Diesel!$C$10-1) -> 1211.7718 | E50: =Diesel!$C$13*D50/C50 -> 924.84863 | F50: =Diesel!$E$34 -> 0.69661292 | G50: =C50*Diesel!$C$28*1000000 -> 117.83179
A51: 3→4 | B51: 0.315789 | C51: =Diesel!$D$34+(Diesel!$D$35-Diesel!$D$34)*B51 -> 0.42702597 | D51: =Diesel!$C$34*(Diesel!$D$34/C51)^(Diesel!$C$10-1) -> 1151.6804 | E51: =Diesel!$C$13*D51/C51 -> 774.03317 | F51: =Diesel!$E$34 -> 0.69661292 | G51: =C51*Diesel!$C$28*1000000 -> 133.8088
A52: 3→4 | B52: 0.368421 | C52: =Diesel!$D$34+(Diesel!$D$35-Diesel!$D$34)*B52 -> 0.47801461 | D52: =Diesel!$C$34*(Diesel!$D$34/C52)^(Diesel!$C$10-1) -> 1100.873 | E52: =Diesel!$C$13*D52/C52 -> 660.9642 | F52: =Diesel!$E$34 -> 0.69661292 | G52: =C52*Diesel!$C$28*1000000 -> 149.78611
A53: 3→4 | B53: 0.421053 | C53: =Diesel!$D$34+(Diesel!$D$35-Diesel!$D$34)*B53 -> 0.52900324 | D53: =Diesel!$C$34*(Diesel!$D$34/C53)^(Diesel!$C$10-1) -> 1057.1347 | E53: =Diesel!$C$13*D53/C53 -> 573.52704 | F53: =Diesel!$E$34 -> 0.69661292 | G53: =C53*Diesel!$C$28*1000000 -> 165.76343
A54: 3→4 | B54: 0.473684 | C54: =Diesel!$D$34+(Diesel!$D$35-Diesel!$D$34)*B54 -> 0.57999091 | D54: =Diesel!$C$34*(Diesel!$D$34/C54)^(Diesel!$C$10-1) -> 1018.932 | E54: =Diesel!$C$13*D54/C54 -> 504.20356 | F54: =Diesel!$E$34 -> 0.69661292 | G54: =C54*Diesel!$C$28*1000000 -> 181.74044
A55: 3→4 | B55: 0.526316 | C55: =Diesel!$D$34+(Diesel!$D$35-Diesel!$D$34)*B55 -> 0.63097955 | D55: =Diesel!$C$34*(Diesel!$D$34/C55)^(Diesel!$C$10-1) -> 985.16179 | E55: =Diesel!$C$13*D55/C55 -> 448.0992 | F55: =Diesel!$E$34 -> 0.69661292 | G55: =C55*Diesel!$C$28*1000000 -> 197.71775
...

Sheet Graficas

Sheet Angulo
A1: Presión y temperatura en función del ángulo del cigüeñal (ciclo ideal de 720°)
A2: V(θ) = V_CC + (V_C/2)·[(1 − cos θ) + (1/λ)(1 − √(1 − λ²·sen²θ))]
A4: θ (°) | B4: Tiempo | C4: V (cm³) | D4: P (kPa) | E4: T (K) | G4: Ciclo ideal: la combustión ocurre en el PMS (360°) y el escape baja la presión a P1 en el PMI (540°). En admisión y escape se asigna T = T1 (el modelo ideal no describe la renovación de la carga).
A5: 0 | B5: Admisión | C5: =Diesel!$C$24+Diesel!$C$23/2*((1-COS(RADIANS(A5)))+1/Diesel!$C$26*(1-SQRT(1-Diesel!$C$26^2*SIN(RADIANS(A5))^2))) -> 18.97291 | D5: =Diesel!$C$6 -> 79 | E5: =Diesel!$C$7 -> 300
A6: 4 | B6: Admisión | C6: =Diesel!$C$24+Diesel!$C$23/2*((1-COS(RADIANS(A6)))+1/Diesel!$C$26*(1-SQRT(1-Diesel!$C$26^2*SIN(RADIANS(A6))^2))) -> 19.46685 | D6: =Diesel!$C$6 -> 79 | E6: =Diesel!$C$7 -> 300
A7: 8 | B7: Admisión | C7: =Diesel!$C$24+Diesel!$C$23/2*((1-COS(RADIANS(A7)))+1/Diesel!$C$26*(1-SQRT(1-Diesel!$C$26^2*SIN(RADIANS(A7))^2))) -> 20.944885 | D7: =Diesel!$C$6 -> 79 | E7: =Diesel!$C$7 -> 300
A8: 12 | B8: Admisión | C8: =Diesel!$C$24+Diesel!$C$23/2*((1-COS(RADIANS(A8)))+1/Diesel!$C$26*(1-SQRT(1-Diesel!$C$26^2*SIN(RADIANS(A8))^2))) -> 23.395699 | D8: =Diesel!$C$6 -> 79 | E8: =Diesel!$C$7 -> 300
A9: 16 | B9: Admisión | C9: =Diesel!$C$24+Diesel!$C$23/2*((1-COS(RADIANS(A9)))+1/Diesel!$C$26*(1-SQRT(1-Diesel!$C$26^2*SIN(RADIANS(A9))^2))) -> 26.800564 | D9: =Diesel!$C$6 -> 79 | E9: =Diesel!$C$7 -> 300
A10: 20 | B10: Admisión | C10: =Diesel!$C$24+Diesel!$C$23/2*((1-COS(RADIANS(A10)))+1/Diesel!$C$26*(1-SQRT(1-Diesel!$C$26^2*SIN(RADIANS(A10))^2))) -> 31.133526 | D10: =Diesel!$C$6 -> 79 | E10: =Diesel!$C$7 -> 300
A11: 24 | B11: Admisión | C11: =Diesel!$C$24+Diesel!$C$23/2*((1-COS(RADIANS(A11)))+1/Diesel!$C$26*(1-SQRT(1-Diesel!$C$26^2*SIN(RADIANS(A11))^2))) -> 36.361679 | D11: =Diesel!$C$6 -> 79 | E11: =Diesel!$C$7 -> 300
A12: 28 | B12: Admisión | C12: =Diesel!$C$24+Diesel!$C$23/2*((1-COS(RADIANS(A12)))+1/Diesel!$C$26*(1-SQRT(1-Diesel!$C$26^2*SIN(RADIANS(A12))^2))) -> 42.445508 | D12: =Diesel!$C$6 -> 79 | E12: =Diesel!$C$7 -> 300
A13: 32 | B13: Admisión | C13: =Diesel!$C$24+Diesel!$C$23/2*((1-COS(RADIANS(A13)))+1/Diesel!$C$26*(1-SQRT(1-Diesel!$C$26^2*SIN(RADIANS(A13))^2))) -> 49.339302 | D13: =Diesel!$C$6 -> 79 | E13: =Diesel!$C$7 -> 300
A14: 36 | B14: Admisión | C14: =Diesel!$C$24+Diesel!$C$23/2*((1-COS(RADIANS(A14)))+1/Diesel!$C$26*(1-SQRT(1-Diesel!$C$26^2*SIN(RADIANS(A14))^2))) -> 56.991641 | D14: =Diesel!$C$6 -> 79 | E14: =Diesel!$C$7 -> 300
A15: 40 | B15: Admisión | C15: =Diesel!$C$24+Diesel!$C$23/2*((1-COS(RADIANS(A15)))+1/Diesel!$C$26*(1-SQRT(1-Diesel!$C$26^2*SIN(RADIANS(A15))^2))) -> 65.345949 | D15: =Diesel!$C$6 -> 79 | E15: =Diesel!$C$7 -> 300
A16: 44 | B16: Admisión | C16: =Diesel!$C$24+Diesel!$C$23/2*((1-COS(RADIANS(A16)))+1/Diesel!$C$26*(1-SQRT(1-Diesel!$C$26^2*SIN(RADIANS(A16))^2))) -> 74.341106 | D16: =Diesel!$C$6 -> 79 | E16: =Diesel!$C$7 -> 300
... A50: 180 | B50: Admisión | C50: =Diesel!$C$24+Diesel!$C$23/2*((1-COS(RADIANS(A50)))+1/Diesel!$C$26*(1-SQRT(1-Diesel!$C$26^2*SIN(RADIANS(A50))^2))) -> 341.51237 | D50: =Diesel!$C$6 -> 79 | E50: =Diesel!$C$7 -> 300
A51: 184 | B51: Compresión | C51: =Diesel!$C$24+Diesel!$C$23/2*((1-COS(RADIANS(A51)))+1/Diesel!$C$26*(1-SQRT(1-Diesel!$C$26^2*SIN(RADIANS(A51))^2))) -> 341.22062 | D51: =Diesel!$C$6*(Diesel!$C$25/C51)^Diesel!$C$10 -> 79.094581 | E51: =D51*C51*0.000001/(Diesel!$C$28*Diesel!$C$13) -> 300.10258
A52: 188 | B52: Compresión | C52: =Diesel!$C$24+Diesel!$C$23/2*((1-COS(RADIANS(A52)))+1/Diesel!$C$26*(1-SQRT(1-Diesel!$C$26^2*SIN(RADIANS(A52))^2))) -> 340.34542 | D52: =Diesel!$C$6*(Diesel!$C$25/C52)^Diesel!$C$10 -> 79.379479 | E52: =D52*C52*0.000001/(Diesel!$C$28*Diesel!$C$13) -> 300.41103
A53: 192 | B53: Compresión | C53: =Diesel!$C$24+Diesel!$C$23/2*((1-COS(RADIANS(A53)))+1/Diesel!$C$26*(1-SQRT(1-Diesel!$C$26^2*SIN(RADIANS(A53))^2))) -> 338.8869 | D53: =Diesel!$C$6*(Diesel!$C$25/C53)^Diesel!$C$10 -> 79.858181 | E53: =D53*C53*0.000001/(Diesel!$C$28*Diesel!$C$13) -> 300.92753
A54: 196 | B54: Compresión | C54: =Diesel!$C$24+Diesel!$C$23/2*((1-COS(RADIANS(A54)))+1/Diesel!$C$26*(1-SQRT(1-Diesel!$C$26^2*SIN(RADIANS(A54))^2))) -> 336.8454 | D54: =Diesel!$C$6*(Diesel!$C$25/C54)^Diesel!$C$10 -> 80.536592 | E54: =D54*C54*0.000001/(Diesel!$C$28*Diesel!$C$13) -> 301.65573
A55: 200 | B55: Compresión | C55: =Diesel!$C$24+Diesel!$C$23/2*((1-COS(RADIANS(A55)))+1/Diesel!$C$26*(1-SQRT(1-Diesel!$C$26^2*SIN(RADIANS(A55))^2))) -> 334.22148 | D55: =Diesel!$C$6*(Diesel!$C$25/C55)^Diesel!$C$10 -> 81.423171 | E55: =D55*C55*0.000001/(Diesel!$C$28*Diesel!$C$13) -> 302.60081
A56: 204 | B56: Compresión | C56: =Diesel!$C$24+Diesel!$C$23/2*((1-COS(RADIANS(A56)))+1/Diesel!$C$26*(1-SQRT(1-Diesel!$C$26^2*SIN(RADIANS(A56))^2))) -> 331.01614 | D56: =Diesel!$C$6*(Diesel!$C$25/C56)^Diesel!$C$10 -> 82.529131 | E56: =D56*C56*0.000001/(Diesel!$C$28*Diesel!$C$13) -> 303.7695
A57: 208 | B57: Compresión | C57: =Diesel!$C$24+Diesel!$C$23/2*((1-COS(RADIANS(A57)))+1/Diesel!$C$26*(1-SQRT(1-Diesel!$C$26^2*SIN(RADIANS(A57))^2))) -> 327.23095 | D57: =Diesel!$C$6*(Diesel!$C$25/C57)^Diesel!$C$10 -> 83.868715 | E57: =D57*C57*0.000001/(Diesel!$C$28*Diesel!$C$13) -> 305.17017
A58: 212 | B58: Compresión | C58: =Diesel!$C$24+Diesel!$C$23/2*((1-COS(RADIANS(A58)))+1/Diesel!$C$26*(1-SQRT(1-Diesel!$C$26^2*SIN(RADIANS(A58))^2))) -> 322.86828 | D58: =Diesel!$C$6*(Diesel!$C$25/C58)^Diesel!$C$10 -> 85.459546 | E58: =D58*C58*0.000001/(Diesel!$C$28*Diesel!$C$13) -> 306.81295
A59: 216 | B59: Compresión | C59: =Diesel!$C$24+Diesel!$C$23/2*((1-COS(RADIANS(A59)))+1/Diesel!$C$26*(1-SQRT(1-Diesel!$C$26^2*SIN(RADIANS(A59))^2))) -> 317.93155 | D59: =Diesel!$C$6*(Diesel!$C$25/C59)^Diesel!$C$10 -> 87.323078 | E59: =D59*C59*0.000001/(Diesel!$C$28*Diesel!$C$13) -> 308.70978
A60: 220 | B60: Compresión | C60: =Diesel!$C$24+Diesel!$C$23/2*((1-COS(RADIANS(A60)))+1/Diesel!$C$26*(1-SQRT(1-Diesel!$C$26^2*SIN(RADIANS(A60))^2))) -> 312.42551 | D60: =Diesel!$C$6*(Diesel!$C$25/C60)^Diesel!$C$10 -> 89.485161 | E60: =D60*C60*0.000001/(Diesel!$C$28*Diesel!$C$13) -> 310.8746
A61: 224 | B61: Compresión | C61: =Diesel!$C$24+Diesel!$C$23/2*((1-COS(RADIANS(A61)))+1/Diesel!$C$26*(1-SQRT(1-Diesel!$C$26^2*SIN(RADIANS(A61))^2))) -> 306.35658 | D61: =Diesel!$C$6*(Diesel!$C$25/C61)^Diesel!$C$10 -> 91.97674 | E61: =D61*C61*0.000001/(Diesel!$C$28*Diesel!$C$13) -> 313.32348
A62: 228 | B62: Compresión | C62: =Diesel!$C$24+Diesel!$C$23/2*((1-COS(RADIANS(A62)))+1/Diesel!$C$26*(1-SQRT(1-Diesel!$C$26^2*SIN(RADIANS(A62))^2))) -> 299.73314 | D62: =Diesel!$C$6*(Diesel!$C$25/C62)^Diesel!$C$10 -> 94.834736 | E62: =D62*C62*0.000001/(Diesel!$C$28*Diesel!$C$13) -> 316.07484
... A95: 360 | B95: Compresión | C95: =Diesel!$C$24+Diesel!$C$23/2*((1-COS(RADIANS(A95)))+1/Diesel!$C$26*(1-SQRT(1-Diesel!$C$26^2*SIN(RADIANS(A95))^2))) -> 18.97291 | D95: =Diesel!$C$6*(Diesel!$C$25/C95)^Diesel!$C$10 -> 4518.6489 | E95: =D95*C95*0.000001/(Diesel!$C$28*Diesel!$C$13) -> 953.30146
A96: 364 | B96: Expansión | C96: =Diesel!$C$24+Diesel!$C$23/2*((1-COS(RADIANS(A96)))+1/Diesel!$C$26*(1-SQRT(1-Diesel!$C$26^2*SIN(RADIANS(A96))^2))) -> 19.46685 | D96: =IF(C96<=Diesel!$F$34,Diesel!$B$33,Diesel!$B$34*(Diesel!$F$34/C96)^Diesel!$C$10) -> 4518.6489 | E96: =D96*C96*0.000001/(Diesel!$C$28*Diesel!$C$13) -> 978.11967
A97: 368 | B97: Expansión | C97: =Diesel!$C$24+Diesel!$C$23/2*((1-COS(RADIANS(A97)))+1/Diesel!$C$26*(1-SQRT(1-Diesel!$C$26^2*SIN(RADIANS(A97))^2))) -> 20.944885 | D97: =IF(C97<=Diesel!$F$34,Diesel!$B$33,Diesel!$B$34*(Diesel!$F$34/C97)^Diesel!$C$10) -> 4518.6489 | E97: =D97*C97*0.000001/(Diesel!$C$28*Diesel!$C$13) -> 1052.3841
A98: 372 | B98: Expansión | C98: =Diesel!$C$24+Diesel!$C$23/2*((1-COS(RADIANS(A98)))+1/Diesel!$C$26*(1-SQRT(1-Diesel!$C$26^2*SIN(RADIANS(A98))^2))) -> 23.395699 | D98: =IF(C98<=Diesel!$F$34,Diesel!$B$33,Diesel!$B$34*(Diesel!$F$34/C98)^Diesel!$C$10) -> 4518.6489 | E98: =D98*C98*0.000001/(Diesel!$C$28*Diesel!$C$13) -> 1175.5263
A99: 376 | B99: Expansión | C99: =Diesel!$C$24+Diesel!$C$23/2*((1-COS(RADIANS(A99)))+1/Diesel!$C$26*(1-SQRT(1-Diesel!$C$26^2*SIN(RADIANS(A99))^2))) -> 26.800564 | D99: =IF(C99<=Diesel!$F$34,Diesel!$B$33,Diesel!$B$34*(Diesel!$F$34/C99)^Diesel!$C$10) -> 4518.6489 | E99: =D99*C99*0.000001/(Diesel!$C$28*Diesel!$C$13) -> 1346.6051
A100: 380 | B100: Expansión | C100: =Diesel!$C$24+Diesel!$C$23/2*((1-COS(RADIANS(A100)))+1/Diesel!$C$26*(1-SQRT(1-Diesel!$C$26^2*SIN(RADIANS(A100))^2))) -> 31.133526 | D100: =IF(C100<=Diesel!$F$34,Diesel!$B$33,Diesel!$B$34*(Diesel!$F$34/C100)^Diesel!$C$10) -> 4518.6489 | E100: =D100*C100*0.000001/(Diesel!$C$28*Diesel!$C$13) -> 1564.3165
A101: 384 | B101: Expansión | C101: =Diesel!$C$24+Diesel!$C$23/2*((1-COS(RADIANS(A101)))+1/Diesel!$C$26*(1-SQRT(1-Diesel!$C$26^2*SIN(RADIANS(A101))^2))) -> 36.361679 | D101: =IF(C101<=Diesel!$F$34,Diesel!$B$33,Diesel!$B$34*(Diesel!$F$34/C101)^Diesel!$C$10) -> 4518.6489 | E101: =D101*C101*0.000001/(Diesel!$C$28*Diesel!$C$13) -> 1827.0071
A102: 388 | B102: Expansión | C102: =Diesel!$C$24+Diesel!$C$23/2*((1-COS(RADIANS(A102)))+1/Diesel!$C$26*(1-SQRT(1-Diesel!$C$26^2*SIN(RADIANS(A102))^2))) -> 42.445508 | D102: =IF(C102<=Diesel!$F$34,Diesel!$B$33,Diesel!$B$34*(Diesel!$F$34/C102)^Diesel!$C$10) -> 3862.5461 | E102: =D102*C102*0.000001/(Diesel!$C$28*Diesel!$C$13) -> 1823.0271
A103: 392 | B103: Expansión | C103: =Diesel!$C$24+Diesel!$C$23/2*((1-COS(RADIANS(A103)))+1/Diesel!$C$26*(1-SQRT(1-Diesel!$C$26^2*SIN(RADIANS(A103))^2))) -> 49.339302 | D103: =IF(C103<=Diesel!$F$34,Diesel!$B$33,Diesel!$B$34*(Diesel!$F$34/C103)^Diesel!$C$10) -> 3128.7287 | E103: =D103*C103*0.000001/(Diesel!$C$28*Diesel!$C$13) -> 1716.519
A104: 396 | B104: Expansión | C104: =Diesel!$C$24+Diesel!$C$23/2*((1-COS(RADIANS(A104)))+1/Diesel!$C$26*(1-SQRT(1-Diesel!$C$26^2*SIN(RADIANS(A104))^2))) -> 56.991641 | D104: =IF(C104<=Diesel!$F$34,Diesel!$B$33,Diesel!$B$34*(Diesel!$F$34/C104)^Diesel!$C$10) -> 2556.8337 | E104: =D104*C104*0.000001/(Diesel!$C$28*Diesel!$C$13) -> 1620.3221
A105: 400 | B105: Expansión | C105: =Diesel!$C$24+Diesel!$C$23/2*((1-COS(RADIANS(A105)))+1/Diesel!$C$26*(1-SQRT(1-Diesel!$C$26^2*SIN(RADIANS(A105))^2))) -> 65.345949 | D105: =IF(C105<=Diesel!$F$34,Diesel!$B$33,Diesel!$B$34*(Diesel!$F$34/C105)^Diesel!$C$10) -> 2111.2126 | E105: =D105*C105*0.000001/(Diesel!$C$28*Diesel!$C$13) -> 1534.0459
A106: 404 | B106: Expansión | C106: =Diesel!$C$24+Diesel!$C$23/2*((1-COS(RADIANS(A106)))+1/Diesel!$C$26*(1-SQRT(1-Diesel!$C$26^2*SIN(RADIANS(A106))^2))) -> 74.341106 | D106: =IF(C106<=Diesel!$F$34,Diesel!$B$33,Diesel!$B$34*(Diesel!$F$34/C106)^Diesel!$C$10) -> 1762.4527 | E106: =D106*C106*0.000001/(Diesel!$C$28*Diesel!$C$13) -> 1456.915
...

Sheet Parametrico
A1: Comparación Otto–Diesel y efecto de r_c
A4: r | B4: η Otto (%) | C4: η Diesel r_c=1,5 (%) | D4: η Diesel r_c=2 (%) | E4: η Diesel r_c=3 (%)
A5: 6 | B5: =(1-1/A5^(Diesel!$C$10-1))*100 -> 51.164066 | C5: =(1-1/A5^(Diesel!$C$10-1)*((1.5^Diesel!$C$10-1)/(Diesel!$C$10*(1.5-1))))*100 -> 46.690797 | D5: =(1-1/A5^(Diesel!$C$10-1)*((2^Diesel!$C$10-1)/(Diesel!$C$10*(2-1))))*100 -> 42.826522 | E5: =(1-1/A5^(Diesel!$C$10-1)*((3^Diesel!$C$10-1)/(Diesel!$C$10*(3-1))))*100 -> 36.242303
A6: 7 | B6: =(1-1/A6^(Diesel!$C$10-1))*100 -> 54.084345 | C6: =(1-1/A6^(Diesel!$C$10-1)*((1.5^Diesel!$C$10-1)/(Diesel!$C$10*(1.5-1))))*100 -> 49.878567 | D6: =(1-1/A6^(Diesel!$C$10-1)*((2^Diesel!$C$10-1)/(Diesel!$C$10*(2-1))))*100 -> 46.245368 | E6: =(1-1/A6^(Diesel!$C$10-1)*((3^Diesel!$C$10-1)/(Diesel!$C$10*(3-1))))*100 -> 40.05487
A7: 8 | B7: =(1-1/A7^(Diesel!$C$10-1))*100 -> 56.472472 | C7: =(1-1/A7^(Diesel!$C$10-1)*((1.5^Diesel!$C$10-1)/(Diesel!$C$10*(1.5-1))))*100 -> 52.485441 | D7: =(1-1/A7^(Diesel!$C$10-1)*((2^Diesel!$C$10-1)/(Diesel!$C$10*(2-1))))*100 -> 49.041209 | E7: =(1-1/A7^(Diesel!$C$10-1)*((3^Diesel!$C$10-1)/(Diesel!$C$10*(3-1))))*100 -> 43.172687
A8: 9 | B8: =(1-1/A8^(Diesel!$C$10-1))*100 -> 58.475635 | C8: =(1-1/A8^(Diesel!$C$10-1)*((1.5^Diesel!$C$10-1)/(Diesel!$C$10*(1.5-1))))*100 -> 54.672091 | D8: =(1-1/A8^(Diesel!$C$10-1)*((2^Diesel!$C$10-1)/(Diesel!$C$10*(2-1))))*100 -> 51.386364 | E8: =(1-1/A8^(Diesel!$C$10-1)*((3^Diesel!$C$10-1)/(Diesel!$C$10*(3-1))))*100 -> 45.787914
A9: 10 | B9: =(1-1/A9^(Diesel!$C$10-1))*100 -> 60.189283 | C9: =(1-1/A9^(Diesel!$C$10-1)*((1.5^Diesel!$C$10-1)/(Diesel!$C$10*(1.5-1))))*100 -> 56.542705 | D9: =(1-1/A9^(Diesel!$C$10-1)*((2^Diesel!$C$10-1)/(Diesel!$C$10*(2-1))))*100 -> 53.392575 | E9: =(1-1/A9^(Diesel!$C$10-1)*((3^Diesel!$C$10-1)/(Diesel!$C$10*(3-1))))*100 -> 48.025165
A10: 11 | B10: =(1-1/A10^(Diesel!$C$10-1))*100 -> 61.678462 | C10: =(1-1/A10^(Diesel!$C$10-1)*((1.5^Diesel!$C$10-1)/(Diesel!$C$10*(1.5-1))))*100 -> 58.16829 | D10: =(1-1/A10^(Diesel!$C$10-1)*((2^Diesel!$C$10-1)/(Diesel!$C$10*(2-1))))*100 -> 55.135995 | E10: =(1-1/A10^(Diesel!$C$10-1)*((3^Diesel!$C$10-1)/(Diesel!$C$10*(3-1))))*100 -> 49.969361
A11: 12 | B11: =(1-1/A11^(Diesel!$C$10-1))*100 -> 62.989283 | C11: =(1-1/A11^(Diesel!$C$10-1)*((1.5^Diesel!$C$10-1)/(Diesel!$C$10*(1.5-1))))*100 -> 59.599179 | D11: =(1-1/A11^(Diesel!$C$10-1)*((2^Diesel!$C$10-1)/(Diesel!$C$10*(2-1))))*100 -> 56.670606 | E11: =(1-1/A11^(Diesel!$C$10-1)*((3^Diesel!$C$10-1)/(Diesel!$C$10*(3-1))))*100 -> 51.680701
A12: 13 | B12: =(1-1/A12^(Diesel!$C$10-1))*100 -> 64.155489 | C12: =(1-1/A12^(Diesel!$C$10-1)*((1.5^Diesel!$C$10-1)/(Diesel!$C$10*(1.5-1))))*100 -> 60.872207 | D12: =(1-1/A12^(Diesel!$C$10-1)*((2^Diesel!$C$10-1)/(Diesel!$C$10*(2-1))))*100 -> 58.035914 | E12: =(1-1/A12^(Diesel!$C$10-1)*((3^Diesel!$C$10-1)/(Diesel!$C$10*(3-1))))*100 -> 53.203241
A13: 14 | B13: =(1-1/A13^(Diesel!$C$10-1))*100 -> 65.202441 | C13: =(1-1/A13^(Diesel!$C$10-1)*((1.5^Diesel!$C$10-1)/(Diesel!$C$10*(1.5-1))))*100 -> 62.015057 | D13: =(1-1/A13^(Diesel!$C$10-1)*((2^Diesel!$C$10-1)/(Diesel!$C$10*(2-1))))*100 -> 59.261607 | E13: =(1-1/A13^(Diesel!$C$10-1)*((3^Diesel!$C$10-1)/(Diesel!$C$10*(3-1))))*100 -> 54.570087
A14: 15 | B14: =(1-1/A14^(Diesel!$C$10-1))*100 -> 66.149624 | C14: =(1-1/A14^(Diesel!$C$10-1)*((1.5^Diesel!$C$10-1)/(Diesel!$C$10*(1.5-1))))*100 -> 63.049001 | D14: =(1-1/A14^(Diesel!$C$10-1)*((2^Diesel!$C$10-1)/(Diesel!$C$10*(2-1))))*100 -> 60.370499 | E14: =(1-1/A14^(Diesel!$C$10-1)*((3^Diesel!$C$10-1)/(Diesel!$C$10*(3-1))))*100 -> 55.806681
A15: 16 | B15: =(1-1/A15^(Diesel!$C$10-1))*100 -> 67.012302 | C15: =(1-1/A15^(Diesel!$C$10-1)*((1.5^Diesel!$C$10-1)/(Diesel!$C$10*(1.5-1))))*100 -> 63.990698 | D15: =(1-1/A15^(Diesel!$C$10-1)*((2^Diesel!$C$10-1)/(Diesel!$C$10*(2-1))))*100 -> 61.380458 | E15: =(1-1/A15^(Diesel!$C$10-1)*((3^Diesel!$C$10-1)/(Diesel!$C$10*(3-1))))*100 -> 56.93295
A16: 17 | B16: =(1-1/A16^(Diesel!$C$10-1))*100 -> 67.802628 | C16: =(1-1/A16^(Diesel!$C$10-1)*((1.5^Diesel!$C$10-1)/(Diesel!$C$10*(1.5-1))))*100 -> 64.853416 | D16: =(1-1/A16^(Diesel!$C$10-1)*((2^Diesel!$C$10-1)/(Diesel!$C$10*(2-1))))*100 -> 62.305712 | E16: =(1-1/A16^(Diesel!$C$10-1)*((3^Diesel!$C$10-1)/(Diesel!$C$10*(3-1))))*100 -> 57.964758
... A23: 24 | B23: =(1-1/A23^(Diesel!$C$10-1))*100 -> 71.951121 | C23: =(1-1/A23^(Diesel!$C$10-1)*((1.5^Diesel!$C$10-1)/(Diesel!$C$10*(1.5-1))))*100 -> 69.381903 | D23: =(1-1/A23^(Diesel!$C$10-1)*((2^Diesel!$C$10-1)/(Diesel!$C$10*(2-1))))*100 -> 67.16246 | E23: =(1-1/A23^(Diesel!$C$10-1)*((3^Diesel!$C$10-1)/(Diesel!$C$10*(3-1))))*100 -> 63.380819
