Workbook

Sheet Dual
A1: CICLO DUAL O MIXTO (SABATHÉ): DIAGRAMAS P–v, P–V, T–s, T–v Y P–θ
A2: η = 1 − (1/r^(γ−1))·[(α·β^γ − 1)/((α − 1) + γ·α·(β − 1))]
A3: Leyenda: celdas amarillas con texto azul = datos de entrada (editar). Texto negro = fórmulas (no editar).
A5: Parámetro | B5: Símbolo | C5: Valor | D5: Unidad | E5: Observación
A6: Presión inicial (Loja) | B6: P1 | C6: 79 | D6: kPa | E6: Inicio de la compresión
A7: Temperatura inicial | B7: T1 | C7: 300 | D7: K
A8: Relación de compresión r = v1/v2 | B8: r | C8: 16 | D8: — | E8: Motor diésel rápido
A9: Relación de presiones α = P3/P2 | B9: α | C9: 1.5 | D9: — | E9: Combustión a volumen constante
A10: Relación de corte β = v4/v3 | B10: β | C10: 1.6 | D10: — | E10: Combustión a presión constante
A11: Relación de calores específicos γ | B11: g | C11: 1.4 | D11: — | E11: Aire
A12: Calor específico a v cte | B12: cv | C12: 0.718 | D12: kJ/(kg·K) | E12: Aire
A13: Calor específico a P cte | B13: cp | C13: 1.005 | D13: kJ/(kg·K) | E13: Aire
A14: Constante del aire | B14: R | C14: 0.287 | D14: kJ/(kg·K) | E14: Aire
A15: Diámetro del cilindro | B15: D | C15: 7.8 | D15: cm | E15: Guía 14
A16: Carrera | B16: S | C16: 6.75 | D16: cm | E16: Guía 14
A17: Número de cilindros | B17: Z | C17: 4 | D17: —
A18: Longitud de la biela | B18: Lb | C18: 13.1 | D18: cm
A19: Régimen de giro | B19: n | C19: 3000 | D19: rpm
A21: Geometría (ecuaciones de la guía original) y masa de aire
A22: Magnitud | B22: Ecuación | C22: Valor | D22: Unidad
A23: Área del pistón | B23: A_P = π·D²/4 | C23: =PI()*Dual!$C$15^2/4 -> 47.783624 | D23: cm²
A24: Volumen del cilindro | B24: V_C = A_P·S | C24: =Dual!$C$23*Dual!$C$16 -> 322.53946 | D24: cm³
A25: Volumen de la cámara | B25: V_CC = V_C/(r − 1) | C25: =Dual!$C$24/(Dual!$C$8-1) -> 21.502631 | D25: cm³
A26: Volumen unitario | B26: V_u = V_C + V_CC | C26: =Dual!$C$24+Dual!$C$25 -> 344.04209 | D26: cm³
A27: Relación biela–manivela | B27: λ = (S/2)/L | C27: =Dual!$C$16/2/Dual!$C$18 -> 0.25763359 | D27: —
A28: Volumen específico en 1 | B28: v1 = R·T1/P1 | C28: =Dual!$C$14*Dual!$C$7/Dual!$C$6 -> 1.0898734 | D28: m³/kg
A29: Masa de aire por cilindro | B29: m = V_u/v1 | C29: =Dual!$C$26*0.000001/Dual!$C$28 -> 0.00031567161 | D29: kg
A31: Estados del ciclo (s referida al estado 1)
A32: Estado | B32: P (kPa) | C32: T (K) | D32: v (m³/kg) | E32: s (kJ/kg·K) | F32: V (cm³) | G32: Descripción
A33: 1 | B33: =Dual!$C$6 -> 79 | C33: =Dual!$C$7 -> 300 | D33: =Dual!$C$28 -> 1.0898734 | E33: =0 -> 0 | F33: =Dual!$D$33*Dual!$C$29*1000000 -> 344.04209 | G33: Inicio de la compresión (PMI)
A34: 2 | B34: =Dual!$C$6*Dual!$C$8^Dual!$C$11 -> 3831.7315 | C34: =Dual!$C$7*Dual!$C$8^(Dual!$C$11-1) -> 909.42994 | D34: =Dual!$C$28/Dual!$C$8 -> 0.068117089 | E34: =0 -> 0 | F34: =Dual!$D$34*Dual!$C$29*1000000 -> 21.502631 | G34: Fin de la compresión (PMS)
A35: 3 | B35: =Dual!$C$9*Dual!$B$34 -> 5747.5972 | C35: =Dual!$C$9*Dual!$C$34 -> 1364.1449 | D35: =Dual!$D$34 -> 0.068117089 | E35: =Dual!$C$12*LN(Dual!$C$9) -> 0.29112395 | F35: =Dual!$D$35*Dual!$C$29*1000000 -> 21.502631 | G35: Fin de la combustión a v cte
A36: 4 | B36: =Dual!$B$35 -> 5747.5972 | C36: =Dual!$C$10*Dual!$C$35 -> 2182.6319 | D36: =Dual!$C$10*Dual!$D$35 -> 0.10898734 | E36: =Dual!$E$35+Dual!$C$13*LN(Dual!$C$10) -> 0.7634776 | F36: =Dual!$D$36*Dual!$C$29*1000000 -> 34.404209 | G36: Fin de la combustión a P cte
A37: 5 | B37: =Dual!$B$36*(Dual!$D$36/Dual!$C$28)^Dual!$C$11 -> 228.81597 | C37: =Dual!$C$36*(Dual!$D$36/Dual!$C$28)^(Dual!$C$11-1) -> 868.92139 | D37: =Dual!$C$28 -> 1.0898734 | E37: =Dual!$E$36 -> 0.7634776 | F37: =Dual!$D$37*Dual!$C$29*1000000 -> 344.04209 | G37: Apertura del escape (PMI)
A39: Balance por proceso (por unidad de masa): Q − W = ΔU
A40: Proceso | B40: Tipo | C40: Q (kJ/kg) | D40: W (kJ/kg) | E40: ΔU (kJ/kg) | F40: Δs (kJ/kg·K) | G40: Q − W − ΔU
A41: 1→2 | B41: Compresión adiabática | C41: =0 -> 0 | D41: =Dual!$C$12*(Dual!$C$33-Dual!$C$34) -> -437.5707 | E41: =Dual!$C$12*(Dual!$C$34-Dual!$C$33) -> 437.5707 | F41: =Dual!$E$34-Dual!$E$33 -> 0 | G41: =C41-D41-E41 -> 0
A42: 2→3 | B42: Aporte de calor a v cte | C42: =Dual!$C$12*(Dual!$C$35-Dual!$C$34) -> 326.48535 | D42: =0 -> 0 | E42: =Dual!$C$12*(Dual!$C$35-Dual!$C$34) -> 326.48535 | F42: =Dual!$E$35-Dual!$E$34 -> 0.29112395 | G42: =C42-D42-E42 -> 0
A43: 3→4 | B43: Aporte de calor a P cte | C43: =Dual!$C$13*(Dual!$C$36-Dual!$C$35) -> 822.57938 | D43: =Dual!$B$35*(Dual!$D$36-Dual!$D$35) -> 234.90575 | E43: =Dual!$C$12*(Dual!$C$36-Dual!$C$35) -> 587.67363 | F43: =Dual!$E$36-Dual!$E$35 -> 0.47235365 | G43: =C43-D43-E43 -> 0
A44: 4→5 | B44: Expansión adiabática | C44: =0 -> 0 | D44: =Dual!$C$12*(Dual!$C$36-Dual!$C$37) -> 943.24411 | E44: =Dual!$C$12*(Dual!$C$37-Dual!$C$36) -> -943.24411 | F44: =Dual!$E$37-Dual!$E$36 -> 0 | G44: =C44-D44-E44 -> 0
...

Sheet Puntos
A1: Puntos de los diagramas (20 por proceso)
A4: Proceso | B4: t | C4: v (m³/kg) | D4: T (K) | E4: P (kPa) | F4: s (kJ/kg·K) | G4: V (cm³)
A5: 1→2 | B5: 0 | C5: =Dual!$D$33+(Dual!$D$34-Dual!$D$33)*B5 -> 1.0898734 | D5: =Dual!$C$33*(Dual!$D$33/C5)^(Dual!$C$11-1) -> 300 | E5: =Dual!$C$14*D5/C5 -> 79 | F5: =0 -> 0 | G5: =C5*Dual!$C$29*1000000 -> 344.04209
A6: 1→2 | B6: 0.052632 | C6: =Dual!$D$33+(Dual!$D$34-Dual!$D$33)*B6 -> 1.0360963 | D6: =Dual!$C$33*(Dual!$D$33/C6)^(Dual!$C$11-1) -> 306.13404 | E6: =Dual!$C$14*D6/C6 -> 84.799517 | F6: =0 -> 0 | G6: =C6*Dual!$C$29*1000000 -> 327.0662
A7: 1→2 | B7: 0.105263 | C7: =Dual!$D$33+(Dual!$D$34-Dual!$D$33)*B7 -> 0.98232028 | D7: =Dual!$C$33*(Dual!$D$33/C7)^(Dual!$C$11-1) -> 312.73064 | E7: =Dual!$C$14*D7/C7 -> 91.369073 | F7: =0 -> 0 | G7: =C7*Dual!$C$29*1000000 -> 310.09062
A8: 1→2 | B8: 0.157895 | C8: =Dual!$D$33+(Dual!$D$34-Dual!$D$33)*B8 -> 0.9285432 | D8: =Dual!$C$33*(Dual!$D$33/C8)^(Dual!$C$11-1) -> 319.8533 | E8: =Dual!$C$14*D8/C8 -> 98.862278 | F8: =0 -> 0 | G8: =C8*Dual!$C$29*1000000 -> 293.11473
A9: 1→2 | B9: 0.210526 | C9: =Dual!$D$33+(Dual!$D$34-Dual!$D$33)*B9 -> 0.87476714 | D9: =Dual!$C$33*(Dual!$D$33/C9)^(Dual!$C$11-1) -> 327.57797 | E9: =Dual!$C$14*D9/C9 -> 107.47418 | F9: =0 -> 0 | G9: =C9*Dual!$C$29*1000000 -> 276.13915
A10: 1→2 | B10: 0.263158 | C10: =Dual!$D$33+(Dual!$D$34-Dual!$D$33)*B10 -> 0.82099007 | D10: =Dual!$C$33*(Dual!$D$33/C10)^(Dual!$C$11-1) -> 335.99787 | E10: =Dual!$C$14*D10/C10 -> 117.45744 | F10: =0 -> 0 | G10: =C10*Dual!$C$29*1000000 -> 259.16325
A11: 1→2 | B11: 0.315789 | C11: =Dual!$D$33+(Dual!$D$34-Dual!$D$33)*B11 -> 0.76721401 | D11: =Dual!$C$33*(Dual!$D$33/C11)^(Dual!$C$11-1) -> 345.22725 | E11: =Dual!$C$14*D11/C11 -> 129.14287 | F11: =0 -> 0 | G11: =C11*Dual!$C$29*1000000 -> 242.18768
A12: 1→2 | B12: 0.368421 | C12: =Dual!$D$33+(Dual!$D$34-Dual!$D$33)*B12 -> 0.71343693 | D12: =Dual!$C$33*(Dual!$D$33/C12)^(Dual!$C$11-1) -> 355.40984 | E12: =Dual!$C$14*D12/C12 -> 142.97357 | F12: =0 -> 0 | G12: =C12*Dual!$C$29*1000000 -> 225.21178
A13: 1→2 | B13: 0.421053 | C13: =Dual!$D$33+(Dual!$D$34-Dual!$D$33)*B13 -> 0.65965985 | D13: =Dual!$C$33*(Dual!$D$33/C13)^(Dual!$C$11-1) -> 366.72765 | E13: =Dual!$C$14*D13/C13 -> 159.55319 | F13: =0 -> 0 | G13: =C13*Dual!$C$29*1000000 -> 208.23589
A14: 1→2 | B14: 0.473684 | C14: =Dual!$D$33+(Dual!$D$34-Dual!$D$33)*B14 -> 0.60588379 | D14: =Dual!$C$33*(Dual!$D$33/C14)^(Dual!$C$11-1) -> 379.41627 | E14: =Dual!$C$14*D14/C14 -> 179.72501 | F14: =0 -> 0 | G14: =C14*Dual!$C$29*1000000 -> 191.26031
A15: 1→2 | B15: 0.526316 | C15: =Dual!$D$33+(Dual!$D$34-Dual!$D$33)*B15 -> 0.55210671 | D15: =Dual!$C$33*(Dual!$D$33/C15)^(Dual!$C$11-1) -> 393.78799 | E15: =Dual!$C$14*D15/C15 -> 204.70165 | F15: =0 -> 0 | G15: =C15*Dual!$C$29*1000000 -> 174.28441
A16: 1→2 | B16: 0.578947 | C16: =Dual!$D$33+(Dual!$D$34-Dual!$D$33)*B16 -> 0.49833066 | D16: =Dual!$C$33*(Dual!$D$33/C16)^(Dual!$C$11-1) -> 410.26516 | E16: =Dual!$C$14*D16/C16 -> 236.28107 | F16: =0 -> 0 | G16: =C16*Dual!$C$29*1000000 -> 157.30884
... A24: 1→2 | B24: 1 | C24: =Dual!$D$33+(Dual!$D$34-Dual!$D$33)*B24 -> 0.068117089 | D24: =Dual!$C$33*(Dual!$D$33/C24)^(Dual!$C$11-1) -> 909.42994 | E24: =Dual!$C$14*D24/C24 -> 3831.7315 | F24: =0 -> 0 | G24: =C24*Dual!$C$29*1000000 -> 21.502631
A25: 2→3 | B25: 0 | C25: =Dual!$D$34 -> 0.068117089 | D25: =Dual!$C$34+(Dual!$C$35-Dual!$C$34)*B25 -> 909.42994 | E25: =Dual!$C$14*D25/C25 -> 3831.7315 | F25: =Dual!$C$12*LN(D25/Dual!$C$34) -> 0 | G25: =C25*Dual!$C$29*1000000 -> 21.502631
A26: 2→3 | B26: 0.052632 | C26: =Dual!$D$34 -> 0.068117089 | D26: =Dual!$C$34+(Dual!$C$35-Dual!$C$34)*B26 -> 933.3625 | E26: =Dual!$C$14*D26/C26 -> 3932.5673 | F26: =Dual!$C$12*LN(D26/Dual!$C$34) -> 0.018650547 | G26: =C26*Dual!$C$29*1000000 -> 21.502631
A27: 2→3 | B27: 0.105263 | C27: =Dual!$D$34 -> 0.068117089 | D27: =Dual!$C$34+(Dual!$C$35-Dual!$C$34)*B27 -> 957.2946 | E27: =Dual!$C$14*D27/C27 -> 4033.4013 | F27: =Dual!$C$12*LN(D27/Dual!$C$34) -> 0.036828532 | G27: =C27*Dual!$C$29*1000000 -> 21.502631
A28: 2→3 | B28: 0.157895 | C28: =Dual!$D$34 -> 0.068117089 | D28: =Dual!$C$34+(Dual!$C$35-Dual!$C$34)*B28 -> 981.22716 | E28: =Dual!$C$14*D28/C28 -> 4134.2371 | F28: =Dual!$C$12*LN(D28/Dual!$C$34) -> 0.054557969 | G28: =C28*Dual!$C$29*1000000 -> 21.502631
A29: 2→3 | B29: 0.210526 | C29: =Dual!$D$34 -> 0.068117089 | D29: =Dual!$C$34+(Dual!$C$35-Dual!$C$34)*B29 -> 1005.1593 | E29: =Dual!$C$14*D29/C29 -> 4235.071 | F29: =Dual!$C$12*LN(D29/Dual!$C$34) -> 0.071859821 | G29: =C29*Dual!$C$29*1000000 -> 21.502631
A30: 2→3 | B30: 0.263158 | C30: =Dual!$D$34 -> 0.068117089 | D30: =Dual!$C$34+(Dual!$C$35-Dual!$C$34)*B30 -> 1029.0918 | E30: =Dual!$C$14*D30/C30 -> 4335.9069 | F30: =Dual!$C$12*LN(D30/Dual!$C$34) -> 0.088754854 | G30: =C30*Dual!$C$29*1000000 -> 21.502631
A31: 2→3 | B31: 0.315789 | C31: =Dual!$D$34 -> 0.068117089 | D31: =Dual!$C$34+(Dual!$C$35-Dual!$C$34)*B31 -> 1053.0239 | E31: =Dual!$C$14*D31/C31 -> 4436.7408 | F31: =Dual!$C$12*LN(D31/Dual!$C$34) -> 0.10526115 | G31: =C31*Dual!$C$29*1000000 -> 21.502631
A32: 2→3 | B32: 0.368421 | C32: =Dual!$D$34 -> 0.068117089 | D32: =Dual!$C$34+(Dual!$C$35-Dual!$C$34)*B32 -> 1076.9565 | E32: =Dual!$C$14*D32/C32 -> 4537.5767 | F32: =Dual!$C$12*LN(D32/Dual!$C$34) -> 0.12139679 | G32: =C32*Dual!$C$29*1000000 -> 21.502631
A33: 2→3 | B33: 0.421053 | C33: =Dual!$D$34 -> 0.068117089 | D33: =Dual!$C$34+(Dual!$C$35-Dual!$C$34)*B33 -> 1100.889 | E33: =Dual!$C$14*D33/C33 -> 4638.4125 | F33: =Dual!$C$12*LN(D33/Dual!$C$34) -> 0.13717777 | G33: =C33*Dual!$C$29*1000000 -> 21.502631
A34: 2→3 | B34: 0.473684 | C34: =Dual!$D$34 -> 0.068117089 | D34: =Dual!$C$34+(Dual!$C$35-Dual!$C$34)*B34 -> 1124.8211 | E34: =Dual!$C$14*D34/C34 -> 4739.2464 | F34: =Dual!$C$12*LN(D34/Dual!$C$34) -> 0.15261905 | G34: =C34*Dual!$C$29*1000000 -> 21.502631
A35: 2→3 | B35: 0.526316 | C35: =Dual!$D$34 -> 0.068117089 | D35: =Dual!$C$34+(Dual!$C$35-Dual!$C$34)*B35 -> 1148.7537 | E35: =Dual!$C$14*D35/C35 -> 4840.0823 | F35: =Dual!$C$12*LN(D35/Dual!$C$34) -> 0.16773552 | G35: =C35*Dual!$C$29*1000000 -> 21.502631
A36: 2→3 | B36: 0.578947 | C36: =Dual!$D$34 -> 0.068117089 | D36: =Dual!$C$34+(Dual!$C$35-Dual!$C$34)*B36 -> 1172.6858 | E36: =Dual!$C$14*D36/C36 -> 4940.9162 | F36: =Dual!$C$12*LN(D36/Dual!$C$34) -> 0.18254001 | G36: =C36*Dual!$C$29*1000000 -> 21.502631
... A44: 2→3 | B44: 1 | C44: =Dual!$D$34 -> 0.068117089 | D44: =Dual!$C$34+(Dual!$C$35-Dual!$C$34)*B44 -> 1364.1449 | E44: =Dual!$C$14*D44/C44 -> 5747.5972 | F44: =Dual!$C$12*LN(D44/Dual!$C$34) -> 0.29112395 | G44: =C44*Dual!$C$29*1000000 -> 21.502631
A45: 3→4 | B45: 0 | C45: =Dual!$D$35*D45/Dual!$C$35 -> 0.068117089 | D45: =Dual!$C$35+(Dual!$C$36-Dual!$C$35)*B45 -> 1364.1449 | E45: =Dual!$C$14*D45/C45 -> 5747.5972 | F45: =Dual!$E$35+Dual!$C$13*LN(D45/Dual!$C$35) -> 0.29112395 | G45: =C45*Dual!$C$29*1000000 -> 21.502631
A46: 3→4 | B46: 0.052632 | C46: =Dual!$D$35*D46/Dual!$C$35 -> 0.070268172 | D46: =Dual!$C$35+(Dual!$C$36-Dual!$C$35)*B46 -> 1407.2235 | E46: =Dual!$C$14*D46/C46 -> 5747.5972 | F46: =Dual!$E$35+Dual!$C$13*LN(D46/Dual!$C$35) -> 0.32237023 | G46: =C46*Dual!$C$29*1000000 -> 22.181667
A47: 3→4 | B47: 0.105263 | C47: =Dual!$D$35*D47/Dual!$C$35 -> 0.072419214 | D47: =Dual!$C$35+(Dual!$C$36-Dual!$C$35)*B47 -> 1450.3013 | E47: =Dual!$C$14*D47/C47 -> 5747.5972 | F47: =Dual!$E$35+Dual!$C$13*LN(D47/Dual!$C$35) -> 0.3526737 | G47: =C47*Dual!$C$29*1000000 -> 22.86069
A48: 3→4 | B48: 0.157895 | C48: =Dual!$D$35*D48/Dual!$C$35 -> 0.074570297 | D48: =Dual!$C$35+(Dual!$C$36-Dual!$C$35)*B48 -> 1493.3799 | E48: =Dual!$C$14*D48/C48 -> 5747.5972 | F48: =Dual!$E$35+Dual!$C$13*LN(D48/Dual!$C$35) -> 0.38209067 | G48: =C48*Dual!$C$29*1000000 -> 23.539726
A49: 3→4 | B49: 0.210526 | C49: =Dual!$D$35*D49/Dual!$C$35 -> 0.07672134 | D49: =Dual!$C$35+(Dual!$C$36-Dual!$C$35)*B49 -> 1536.4577 | E49: =Dual!$C$14*D49/C49 -> 5747.5972 | F49: =Dual!$E$35+Dual!$C$13*LN(D49/Dual!$C$35) -> 0.41067048 | G49: =C49*Dual!$C$29*1000000 -> 24.218749
A50: 3→4 | B50: 0.263158 | C50: =Dual!$D$35*D50/Dual!$C$35 -> 0.078872423 | D50: =Dual!$C$35+(Dual!$C$36-Dual!$C$35)*B50 -> 1579.5363 | E50: =Dual!$C$14*D50/C50 -> 5747.5972 | F50: =Dual!$E$35+Dual!$C$13*LN(D50/Dual!$C$35) -> 0.43846049 | G50: =C50*Dual!$C$29*1000000 -> 24.897785
A51: 3→4 | B51: 0.315789 | C51: =Dual!$D$35*D51/Dual!$C$35 -> 0.081023465 | D51: =Dual!$C$35+(Dual!$C$36-Dual!$C$35)*B51 -> 1622.6141 | E51: =Dual!$C$14*D51/C51 -> 5747.5972 | F51: =Dual!$E$35+Dual!$C$13*LN(D51/Dual!$C$35) -> 0.46550219 | G51: =C51*Dual!$C$29*1000000 -> 25.576808
A52: 3→4 | B52: 0.368421 | C52: =Dual!$D$35*D52/Dual!$C$35 -> 0.083174548 | D52: =Dual!$C$35+(Dual!$C$36-Dual!$C$35)*B52 -> 1665.6927 | E52: =Dual!$C$14*D52/C52 -> 5747.5972 | F52: =Dual!$E$35+Dual!$C$13*LN(D52/Dual!$C$35) -> 0.49183579 | G52: =C52*Dual!$C$29*1000000 -> 26.255843
A53: 3→4 | B53: 0.421053 | C53: =Dual!$D$35*D53/Dual!$C$35 -> 0.085325631 | D53: =Dual!$C$35+(Dual!$C$36-Dual!$C$35)*B53 -> 1708.7713 | E53: =Dual!$C$14*D53/C53 -> 5747.5972 | F53: =Dual!$E$35+Dual!$C$13*LN(D53/Dual!$C$35) -> 0.51749696 | G53: =C53*Dual!$C$29*1000000 -> 26.934879
A54: 3→4 | B54: 0.473684 | C54: =Dual!$D$35*D54/Dual!$C$35 -> 0.087476674 | D54: =Dual!$C$35+(Dual!$C$36-Dual!$C$35)*B54 -> 1751.8491 | E54: =Dual!$C$14*D54/C54 -> 5747.5972 | F54: =Dual!$E$35+Dual!$C$13*LN(D54/Dual!$C$35) -> 0.54251872 | G54: =C54*Dual!$C$29*1000000 -> 27.613902
A55: 3→4 | B55: 0.526316 | C55: =Dual!$D$35*D55/Dual!$C$35 -> 0.089627757 | D55: =Dual!$C$35+(Dual!$C$36-Dual!$C$35)*B55 -> 1794.9277 | E55: =Dual!$C$14*D55/C55 -> 5747.5972 | F55: =Dual!$E$35+Dual!$C$13*LN(D55/Dual!$C$35) -> 0.56693307 | G55: =C55*Dual!$C$29*1000000 -> 28.292938
A56: 3→4 | B56: 0.578947 | C56: =Dual!$D$35*D56/Dual!$C$35 -> 0.091778799 | D56: =Dual!$C$35+(Dual!$C$36-Dual!$C$35)*B56 -> 1838.0055 | E56: =Dual!$C$14*D56/C56 -> 5747.5972 | F56: =Dual!$E$35+Dual!$C$13*LN(D56/Dual!$C$35) -> 0.59076792 | G56: =C56*Dual!$C$29*1000000 -> 28.971961
...

Sheet Angulo
A1: Presión y temperatura vs. ángulo del cigüeñal (ciclo dual ideal, 720°)
A2: V(θ) = V_CC + (V_C/2)·[(1 − cos θ) + (1/λ)(1 − √(1 − λ²·sen²θ))]
A4: θ (°) | B4: Tiempo | C4: V (cm³) | D4: P (kPa) | E4: T (K) | G4: Ciclo ideal: aporte de calor a v cte en el PMS (360°) y luego a P cte hasta V = β·V_CC. En admisión y escape se asigna T = T1.
A5: 0 | B5: Admisión | C5: =Dual!$C$25+Dual!$C$24/2*((1-COS(RADIANS(A5)))+1/Dual!$C$27*(1-SQRT(1-Dual!$C$27^2*SIN(RADIANS(A5))^2))) -> 21.502631 | D5: =Dual!$C$6 -> 79 | E5: =Dual!$C$7 -> 300
A6: 4 | B6: Admisión | C6: =Dual!$C$25+Dual!$C$24/2*((1-COS(RADIANS(A6)))+1/Dual!$C$27*(1-SQRT(1-Dual!$C$27^2*SIN(RADIANS(A6))^2))) -> 21.996571 | D6: =Dual!$C$6 -> 79 | E6: =Dual!$C$7 -> 300
A7: 8 | B7: Admisión | C7: =Dual!$C$25+Dual!$C$24/2*((1-COS(RADIANS(A7)))+1/Dual!$C$27*(1-SQRT(1-Dual!$C$27^2*SIN(RADIANS(A7))^2))) -> 23.474606 | D7: =Dual!$C$6 -> 79 | E7: =Dual!$C$7 -> 300
A8: 12 | B8: Admisión | C8: =Dual!$C$25+Dual!$C$24/2*((1-COS(RADIANS(A8)))+1/Dual!$C$27*(1-SQRT(1-Dual!$C$27^2*SIN(RADIANS(A8))^2))) -> 25.925421 | D8: =Dual!$C$6 -> 79 | E8: =Dual!$C$7 -> 300
A9: 16 | B9: Admisión | C9: =Dual!$C$25+Dual!$C$24/2*((1-COS(RADIANS(A9)))+1/Dual!$C$27*(1-SQRT(1-Dual!$C$27^2*SIN(RADIANS(A9))^2))) -> 29.330285 | D9: =Dual!$C$6 -> 79 | E9: =Dual!$C$7 -> 300
A10: 20 | B10: Admisión | C10: =Dual!$C$25+Dual!$C$24/2*((1-COS(RADIANS(A10)))+1/Dual!$C$27*(1-SQRT(1-Dual!$C$27^2*SIN(RADIANS(A10))^2))) -> 33.663247 | D10: =Dual!$C$6 -> 79 | E10: =Dual!$C$7 -> 300
A11: 24 | B11: Admisión | C11: =Dual!$C$25+Dual!$C$24/2*((1-COS(RADIANS(A11)))+1/Dual!$C$27*(1-SQRT(1-Dual!$C$27^2*SIN(RADIANS(A11))^2))) -> 38.8914 | D11: =Dual!$C$6 -> 79 | E11: =Dual!$C$7 -> 300
A12: 28 | B12: Admisión | C12: =Dual!$C$25+Dual!$C$24/2*((1-COS(RADIANS(A12)))+1/Dual!$C$27*(1-SQRT(1-Dual!$C$27^2*SIN(RADIANS(A12))^2))) -> 44.975229 | D12: =Dual!$C$6 -> 79 | E12: =Dual!$C$7 -> 300
A13: 32 | B13: Admisión | C13: =Dual!$C$25+Dual!$C$24/2*((1-COS(RADIANS(A13)))+1/Dual!$C$27*(1-SQRT(1-Dual!$C$27^2*SIN(RADIANS(A13))^2))) -> 51.869023 | D13: =Dual!$C$6 -> 79 | E13: =Dual!$C$7 -> 300
A14: 36 | B14: Admisión | C14: =Dual!$C$25+Dual!$C$24/2*((1-COS(RADIANS(A14)))+1/Dual!$C$27*(1-SQRT(1-Dual!$C$27^2*SIN(RADIANS(A14))^2))) -> 59.521362 | D14: =Dual!$C$6 -> 79 | E14: =Dual!$C$7 -> 300
A15: 40 | B15: Admisión | C15: =Dual!$C$25+Dual!$C$24/2*((1-COS(RADIANS(A15)))+1/Dual!$C$27*(1-SQRT(1-Dual!$C$27^2*SIN(RADIANS(A15))^2))) -> 67.875671 | D15: =Dual!$C$6 -> 79 | E15: =Dual!$C$7 -> 300
A16: 44 | B16: Admisión | C16: =Dual!$C$25+Dual!$C$24/2*((1-COS(RADIANS(A16)))+1/Dual!$C$27*(1-SQRT(1-Dual!$C$27^2*SIN(RADIANS(A16))^2))) -> 76.870828 | D16: =Dual!$C$6 -> 79 | E16: =Dual!$C$7 -> 300
... A50: 180 | B50: Admisión | C50: =Dual!$C$25+Dual!$C$24/2*((1-COS(RADIANS(A50)))+1/Dual!$C$27*(1-SQRT(1-Dual!$C$27^2*SIN(RADIANS(A50))^2))) -> 344.04209 | D50: =Dual!$C$6 -> 79 | E50: =Dual!$C$7 -> 300
A51: 184 | B51: Compresión | C51: =Dual!$C$25+Dual!$C$24/2*((1-COS(RADIANS(A51)))+1/Dual!$C$27*(1-SQRT(1-Dual!$C$27^2*SIN(RADIANS(A51))^2))) -> 343.75034 | D51: =Dual!$C$6*(Dual!$C$26/C51)^Dual!$C$11 -> 79.093885 | E51: =D51*C51*0.000001/(Dual!$C$29*Dual!$C$14) -> 300.10182
A52: 188 | B52: Compresión | C52: =Dual!$C$25+Dual!$C$24/2*((1-COS(RADIANS(A52)))+1/Dual!$C$27*(1-SQRT(1-Dual!$C$27^2*SIN(RADIANS(A52))^2))) -> 342.87514 | D52: =Dual!$C$6*(Dual!$C$26/C52)^Dual!$C$11 -> 79.376677 | E52: =D52*C52*0.000001/(Dual!$C$29*Dual!$C$14) -> 300.408
A53: 192 | B53: Compresión | C53: =Dual!$C$25+Dual!$C$24/2*((1-COS(RADIANS(A53)))+1/Dual!$C$27*(1-SQRT(1-Dual!$C$27^2*SIN(RADIANS(A53))^2))) -> 341.41662 | D53: =Dual!$C$6*(Dual!$C$26/C53)^Dual!$C$11 -> 79.851813 | E53: =D53*C53*0.000001/(Dual!$C$29*Dual!$C$14) -> 300.92067
A54: 196 | B54: Compresión | C54: =Dual!$C$25+Dual!$C$24/2*((1-COS(RADIANS(A54)))+1/Dual!$C$27*(1-SQRT(1-Dual!$C$27^2*SIN(RADIANS(A54))^2))) -> 339.37512 | D54: =Dual!$C$6*(Dual!$C$26/C54)^Dual!$C$11 -> 80.525107 | E54: =D54*C54*0.000001/(Dual!$C$29*Dual!$C$14) -> 301.64344
A55: 200 | B55: Compresión | C55: =Dual!$C$25+Dual!$C$24/2*((1-COS(RADIANS(A55)))+1/Dual!$C$27*(1-SQRT(1-Dual!$C$27^2*SIN(RADIANS(A55))^2))) -> 336.7512 | D55: =Dual!$C$6*(Dual!$C$26/C55)^Dual!$C$11 -> 81.40489 | E55: =D55*C55*0.000001/(Dual!$C$29*Dual!$C$14) -> 302.5814
A56: 204 | B56: Compresión | C56: =Dual!$C$25+Dual!$C$24/2*((1-COS(RADIANS(A56)))+1/Dual!$C$27*(1-SQRT(1-Dual!$C$27^2*SIN(RADIANS(A56))^2))) -> 333.54586 | D56: =Dual!$C$6*(Dual!$C$26/C56)^Dual!$C$11 -> 82.5022 | E56: =D56*C56*0.000001/(Dual!$C$29*Dual!$C$14) -> 303.74117
A57: 208 | B57: Compresión | C57: =Dual!$C$25+Dual!$C$24/2*((1-COS(RADIANS(A57)))+1/Dual!$C$27*(1-SQRT(1-Dual!$C$27^2*SIN(RADIANS(A57))^2))) -> 329.76067 | D57: =Dual!$C$6*(Dual!$C$26/C57)^Dual!$C$11 -> 83.83105 | E57: =D57*C57*0.000001/(Dual!$C$29*Dual!$C$14) -> 305.13101
A58: 212 | B58: Compresión | C58: =Dual!$C$25+Dual!$C$24/2*((1-COS(RADIANS(A58)))+1/Dual!$C$27*(1-SQRT(1-Dual!$C$27^2*SIN(RADIANS(A58))^2))) -> 325.398 | D58: =Dual!$C$6*(Dual!$C$26/C58)^Dual!$C$11 -> 85.408771 | E58: =D58*C58*0.000001/(Dual!$C$29*Dual!$C$14) -> 306.76085
A59: 216 | B59: Compresión | C59: =Dual!$C$25+Dual!$C$24/2*((1-COS(RADIANS(A59)))+1/Dual!$C$27*(1-SQRT(1-Dual!$C$27^2*SIN(RADIANS(A59))^2))) -> 320.46127 | D59: =Dual!$C$6*(Dual!$C$26/C59)^Dual!$C$11 -> 87.25645 | E59: =D59*C59*0.000001/(Dual!$C$29*Dual!$C$14) -> 308.64246
A60: 220 | B60: Compresión | C60: =Dual!$C$25+Dual!$C$24/2*((1-COS(RADIANS(A60)))+1/Dual!$C$27*(1-SQRT(1-Dual!$C$27^2*SIN(RADIANS(A60))^2))) -> 314.95523 | D60: =Dual!$C$6*(Dual!$C$26/C60)^Dual!$C$11 -> 89.39947 | E60: =D60*C60*0.000001/(Dual!$C$29*Dual!$C$14) -> 310.78951
A61: 224 | B61: Compresión | C61: =Dual!$C$25+Dual!$C$24/2*((1-COS(RADIANS(A61)))+1/Dual!$C$27*(1-SQRT(1-Dual!$C$27^2*SIN(RADIANS(A61))^2))) -> 308.8863 | D61: =Dual!$C$6*(Dual!$C$26/C61)^Dual!$C$11 -> 91.868199 | E61: =D61*C61*0.000001/(Dual!$C$29*Dual!$C$14) -> 313.2178
A62: 228 | B62: Compresión | C62: =Dual!$C$25+Dual!$C$24/2*((1-COS(RADIANS(A62)))+1/Dual!$C$27*(1-SQRT(1-Dual!$C$27^2*SIN(RADIANS(A62))^2))) -> 302.26286 | D62: =Dual!$C$6*(Dual!$C$26/C62)^Dual!$C$11 -> 94.698827 | E62: =D62*C62*0.000001/(Dual!$C$29*Dual!$C$14) -> 315.94535
... A95: 360 | B95: Compresión | C95: =Dual!$C$25+Dual!$C$24/2*((1-COS(RADIANS(A95)))+1/Dual!$C$27*(1-SQRT(1-Dual!$C$27^2*SIN(RADIANS(A95))^2))) -> 21.502631 | D95: =Dual!$C$6*(Dual!$C$26/C95)^Dual!$C$11 -> 3831.7315 | E95: =D95*C95*0.000001/(Dual!$C$29*Dual!$C$14) -> 909.42994
A96: 364 | B96: Expansión | C96: =Dual!$C$25+Dual!$C$24/2*((1-COS(RADIANS(A96)))+1/Dual!$C$27*(1-SQRT(1-Dual!$C$27^2*SIN(RADIANS(A96))^2))) -> 21.996571 | D96: =IF(C96<=Dual!$C$10*Dual!$C$25,Dual!$B$35,Dual!$B$35*(Dual!$C$10*Dual!$C$25/C96)^Dual!$C$11) -> 5747.5972 | E96: =D96*C96*0.000001/(Dual!$C$29*Dual!$C$14) -> 1395.4809
A97: 368 | B97: Expansión | C97: =Dual!$C$25+Dual!$C$24/2*((1-COS(RADIANS(A97)))+1/Dual!$C$27*(1-SQRT(1-Dual!$C$27^2*SIN(RADIANS(A97))^2))) -> 23.474606 | D97: =IF(C97<=Dual!$C$10*Dual!$C$25,Dual!$B$35,Dual!$B$35*(Dual!$C$10*Dual!$C$25/C97)^Dual!$C$11) -> 5747.5972 | E97: =D97*C97*0.000001/(Dual!$C$29*Dual!$C$14) -> 1489.2487
A98: 372 | B98: Expansión | C98: =Dual!$C$25+Dual!$C$24/2*((1-COS(RADIANS(A98)))+1/Dual!$C$27*(1-SQRT(1-Dual!$C$27^2*SIN(RADIANS(A98))^2))) -> 25.925421 | D98: =IF(C98<=Dual!$C$10*Dual!$C$25,Dual!$B$35,Dual!$B$35*(Dual!$C$10*Dual!$C$25/C98)^Dual!$C$11) -> 5747.5972 | E98: =D98*C98*0.000001/(Dual!$C$29*Dual!$C$14) -> 1644.7304
A99: 376 | B99: Expansión | C99: =Dual!$C$25+Dual!$C$24/2*((1-COS(RADIANS(A99)))+1/Dual!$C$27*(1-SQRT(1-Dual!$C$27^2*SIN(RADIANS(A99))^2))) -> 29.330285 | D99: =IF(C99<=Dual!$C$10*Dual!$C$25,Dual!$B$35,Dual!$B$35*(Dual!$C$10*Dual!$C$25/C99)^Dual!$C$11) -> 5747.5972 | E99: =D99*C99*0.000001/(Dual!$C$29*Dual!$C$14) -> 1860.7378
A100: 380 | B100: Expansión | C100: =Dual!$C$25+Dual!$C$24/2*((1-COS(RADIANS(A100)))+1/Dual!$C$27*(1-SQRT(1-Dual!$C$27^2*SIN(RADIANS(A100))^2))) -> 33.663247 | D100: =IF(C100<=Dual!$C$10*Dual!$C$25,Dual!$B$35,Dual!$B$35*(Dual!$C$10*Dual!$C$25/C100)^Dual!$C$11) -> 5747.5972 | E100: =D100*C100*0.000001/(Dual!$C$29*Dual!$C$14) -> 2135.6246
A101: 384 | B101: Expansión | C101: =Dual!$C$25+Dual!$C$24/2*((1-COS(RADIANS(A101)))+1/Dual!$C$27*(1-SQRT(1-Dual!$C$27^2*SIN(RADIANS(A101))^2))) -> 38.8914 | D101: =IF(C101<=Dual!$C$10*Dual!$C$25,Dual!$B$35,Dual!$B$35*(Dual!$C$10*Dual!$C$25/C101)^Dual!$C$11) -> 4841.1388 | E101: =D101*C101*0.000001/(Dual!$C$29*Dual!$C$14) -> 2078.1825
A102: 388 | B102: Expansión | C102: =Dual!$C$25+Dual!$C$24/2*((1-COS(RADIANS(A102)))+1/Dual!$C$27*(1-SQRT(1-Dual!$C$27^2*SIN(RADIANS(A102))^2))) -> 44.975229 | D102: =IF(C102<=Dual!$C$10*Dual!$C$25,Dual!$B$35,Dual!$B$35*(Dual!$C$10*Dual!$C$25/C102)^Dual!$C$11) -> 3949.8427 | E102: =D102*C102*0.000001/(Dual!$C$29*Dual!$C$14) -> 1960.8112
A103: 392 | B103: Expansión | C103: =Dual!$C$25+Dual!$C$24/2*((1-COS(RADIANS(A103)))+1/Dual!$C$27*(1-SQRT(1-Dual!$C$27^2*SIN(RADIANS(A103))^2))) -> 51.869023 | D103: =IF(C103<=Dual!$C$10*Dual!$C$25,Dual!$B$35,Dual!$B$35*(Dual!$C$10*Dual!$C$25/C103)^Dual!$C$11) -> 3234.9774 | E103: =D103*C103*0.000001/(Dual!$C$29*Dual!$C$14) -> 1852.0892
A104: 396 | B104: Expansión | C104: =Dual!$C$25+Dual!$C$24/2*((1-COS(RADIANS(A104)))+1/Dual!$C$27*(1-SQRT(1-Dual!$C$27^2*SIN(RADIANS(A104))^2))) -> 59.521362 | D104: =IF(C104<=Dual!$C$10*Dual!$C$25,Dual!$B$35,Dual!$B$35*(Dual!$C$10*Dual!$C$25/C104)^Dual!$C$11) -> 2668.0904 | E104: =D104*C104*0.000001/(Dual!$C$29*Dual!$C$14) -> 1752.8953
A105: 400 | B105: Expansión | C105: =Dual!$C$25+Dual!$C$24/2*((1-COS(RADIANS(A105)))+1/Dual!$C$27*(1-SQRT(1-Dual!$C$27^2*SIN(RADIANS(A105))^2))) -> 67.875671 | D105: =IF(C105<=Dual!$C$10*Dual!$C$25,Dual!$B$35,Dual!$B$35*(Dual!$C$10*Dual!$C$25/C105)^Dual!$C$11) -> 2219.9478 | E105: =D105*C105*0.000001/(Dual!$C$29*Dual!$C$14) -> 1663.1808
A106: 404 | B106: Expansión | C106: =Dual!$C$25+Dual!$C$24/2*((1-COS(RADIANS(A106)))+1/Dual!$C$27*(1-SQRT(1-Dual!$C$27^2*SIN(RADIANS(A106))^2))) -> 76.870828 | D106: =IF(C106<=Dual!$C$10*Dual!$C$25,Dual!$B$35,Dual!$B$35*(Dual!$C$10*Dual!$C$25/C106)^Dual!$C$11) -> 1864.9894 | E106: =D106*C106*0.000001/(Dual!$C$29*Dual!$C$14) -> 1582.4154
...

Sheet Parametrico
A1: Comparación de eficiencias: Otto, Diesel y dual
A2: β de la hoja Dual para Diesel y dual; α variable en el dual
A4: r | B4: η Otto (%) | C4: η Diesel β (%) | D4: η dual α=1,25 (%) | E4: η dual α=1,5 (%) | F4: η dual α=2 (%) | H4: Efecto de α con r y β de la hoja Dual
A5: 8 | B5: =(1-1/A5^(Dual!$C$11-1))*100 -> 56.472472 | C5: =(1-1/A5^(Dual!$C$11-1)*((Dual!$C$10^Dual!$C$11-1)/(Dual!$C$11*(Dual!$C$10-1))))*100 -> 51.760284 | D5: =(1-1/A5^(Dual!$C$11-1)*((1.25*Dual!$C$10^Dual!$C$11-1)/((1.25-1)+Dual!$C$11*1.25*(Dual!$C$10-1))))*100 -> 52.666474 | E5: =(1-1/A5^(Dual!$C$11-1)*((1.5*Dual!$C$10^Dual!$C$11-1)/((1.5-1)+Dual!$C$11*1.5*(Dual!$C$10-1))))*100 -> 53.098974 | F5: =(1-1/A5^(Dual!$C$11-1)*((2*Dual!$C$10^Dual!$C$11-1)/((2-1)+Dual!$C$11*2*(Dual!$C$10-1))))*100 -> 53.518563 | H5: α | I5: η dual (%) | J5: P máx (kPa) | K5: T máx (K)
A6: 9 | B6: =(1-1/A6^(Dual!$C$11-1))*100 -> 58.475635 | C6: =(1-1/A6^(Dual!$C$11-1)*((Dual!$C$10^Dual!$C$11-1)/(Dual!$C$11*(Dual!$C$10-1))))*100 -> 53.980305 | D6: =(1-1/A6^(Dual!$C$11-1)*((1.25*Dual!$C$10^Dual!$C$11-1)/((1.25-1)+Dual!$C$11*1.25*(Dual!$C$10-1))))*100 -> 54.844792 | E6: =(1-1/A6^(Dual!$C$11-1)*((1.5*Dual!$C$10^Dual!$C$11-1)/((1.5-1)+Dual!$C$11*1.5*(Dual!$C$10-1))))*100 -> 55.257388 | F6: =(1-1/A6^(Dual!$C$11-1)*((2*Dual!$C$10^Dual!$C$11-1)/((2-1)+Dual!$C$11*2*(Dual!$C$10-1))))*100 -> 55.657667 | H6: 1 | I6: =(1-1/Dual!$C$8^(Dual!$C$11-1)*((H6*Dual!$C$10^Dual!$C$11-1)/((H6-1)+Dual!$C$11*H6*(Dual!$C$10-1))))*100 -> 63.441132 | J6: =H6*Dual!$B$34 -> 3831.7315 | K6: =Dual!$C$10*H6*Dual!$C$34 -> 1455.0879
A7: 10 | B7: =(1-1/A7^(Dual!$C$11-1))*100 -> 60.189283 | C7: =(1-1/A7^(Dual!$C$11-1)*((Dual!$C$10^Dual!$C$11-1)/(Dual!$C$11*(Dual!$C$10-1))))*100 -> 55.879468 | D7: =(1-1/A7^(Dual!$C$11-1)*((1.25*Dual!$C$10^Dual!$C$11-1)/((1.25-1)+Dual!$C$11*1.25*(Dual!$C$10-1))))*100 -> 56.708279 | E7: =(1-1/A7^(Dual!$C$11-1)*((1.5*Dual!$C$10^Dual!$C$11-1)/((1.5-1)+Dual!$C$11*1.5*(Dual!$C$10-1))))*100 -> 57.103847 | F7: =(1-1/A7^(Dual!$C$11-1)*((2*Dual!$C$10^Dual!$C$11-1)/((2-1)+Dual!$C$11*2*(Dual!$C$10-1))))*100 -> 57.487608 | H7: 1.25 | I7: =(1-1/Dual!$C$8^(Dual!$C$11-1)*((H7*Dual!$C$10^Dual!$C$11-1)/((H7-1)+Dual!$C$11*H7*(Dual!$C$10-1))))*100 -> 64.127895 | J7: =H7*Dual!$B$34 -> 4789.6644 | K7: =Dual!$C$10*H7*Dual!$C$34 -> 1818.8599
A8: 11 | B8: =(1-1/A8^(Dual!$C$11-1))*100 -> 61.678462 | C8: =(1-1/A8^(Dual!$C$11-1)*((Dual!$C$10^Dual!$C$11-1)/(Dual!$C$11*(Dual!$C$10-1))))*100 -> 57.529863 | D8: =(1-1/A8^(Dual!$C$11-1)*((1.25*Dual!$C$10^Dual!$C$11-1)/((1.25-1)+Dual!$C$11*1.25*(Dual!$C$10-1))))*100 -> 58.32767 | E8: =(1-1/A8^(Dual!$C$11-1)*((1.5*Dual!$C$10^Dual!$C$11-1)/((1.5-1)+Dual!$C$11*1.5*(Dual!$C$10-1))))*100 -> 58.708442 | F8: =(1-1/A8^(Dual!$C$11-1)*((2*Dual!$C$10^Dual!$C$11-1)/((2-1)+Dual!$C$11*2*(Dual!$C$10-1))))*100 -> 59.077848 | H8: 1.5 | I8: =(1-1/Dual!$C$8^(Dual!$C$11-1)*((H8*Dual!$C$10^Dual!$C$11-1)/((H8-1)+Dual!$C$11*H8*(Dual!$C$10-1))))*100 -> 64.455669 | J8: =H8*Dual!$B$34 -> 5747.5972 | K8: =Dual!$C$10*H8*Dual!$C$34 -> 2182.6319
A9: 12 | B9: =(1-1/A9^(Dual!$C$11-1))*100 -> 62.989283 | C9: =(1-1/A9^(Dual!$C$11-1)*((Dual!$C$10^Dual!$C$11-1)/(Dual!$C$11*(Dual!$C$10-1))))*100 -> 58.982589 | D9: =(1-1/A9^(Dual!$C$11-1)*((1.25*Dual!$C$10^Dual!$C$11-1)/((1.25-1)+Dual!$C$11*1.25*(Dual!$C$10-1))))*100 -> 59.753107 | E9: =(1-1/A9^(Dual!$C$11-1)*((1.5*Dual!$C$10^Dual!$C$11-1)/((1.5-1)+Dual!$C$11*1.5*(Dual!$C$10-1))))*100 -> 60.120855 | F9: =(1-1/A9^(Dual!$C$11-1)*((2*Dual!$C$10^Dual!$C$11-1)/((2-1)+Dual!$C$11*2*(Dual!$C$10-1))))*100 -> 60.477624 | H9: 1.75 | I9: =(1-1/Dual!$C$8^(Dual!$C$11-1)*((H9*Dual!$C$10^Dual!$C$11-1)/((H9-1)+Dual!$C$11*H9*(Dual!$C$10-1))))*100 -> 64.647608 | J9: =H9*Dual!$B$34 -> 6705.5301 | K9: =Dual!$C$10*H9*Dual!$C$34 -> 2546.4038
A10: 13 | B10: =(1-1/A10^(Dual!$C$11-1))*100 -> 64.155489 | C10: =(1-1/A10^(Dual!$C$11-1)*((Dual!$C$10^Dual!$C$11-1)/(Dual!$C$11*(Dual!$C$10-1))))*100 -> 60.275046 | D10: =(1-1/A10^(Dual!$C$11-1)*((1.25*Dual!$C$10^Dual!$C$11-1)/((1.25-1)+Dual!$C$11*1.25*(Dual!$C$10-1))))*100 -> 61.021285 | E10: =(1-1/A10^(Dual!$C$11-1)*((1.5*Dual!$C$10^Dual!$C$11-1)/((1.5-1)+Dual!$C$11*1.5*(Dual!$C$10-1))))*100 -> 61.377445 | F10: =(1-1/A10^(Dual!$C$11-1)*((2*Dual!$C$10^Dual!$C$11-1)/((2-1)+Dual!$C$11*2*(Dual!$C$10-1))))*100 -> 61.722973 | H10: 2 | I10: =(1-1/Dual!$C$8^(Dual!$C$11-1)*((H10*Dual!$C$10^Dual!$C$11-1)/((H10-1)+Dual!$C$11*H10*(Dual!$C$10-1))))*100 -> 64.773658 | J10: =H10*Dual!$B$34 -> 7663.463 | K10: =Dual!$C$10*H10*Dual!$C$34 -> 2910.1758
A11: 14 | B11: =(1-1/A11^(Dual!$C$11-1))*100 -> 65.202441 | C11: =(1-1/A11^(Dual!$C$11-1)*((Dual!$C$10^Dual!$C$11-1)/(Dual!$C$11*(Dual!$C$10-1))))*100 -> 61.435338 | D11: =(1-1/A11^(Dual!$C$11-1)*((1.25*Dual!$C$10^Dual!$C$11-1)/((1.25-1)+Dual!$C$11*1.25*(Dual!$C$10-1))))*100 -> 62.159781 | E11: =(1-1/A11^(Dual!$C$11-1)*((1.5*Dual!$C$10^Dual!$C$11-1)/((1.5-1)+Dual!$C$11*1.5*(Dual!$C$10-1))))*100 -> 62.505538 | F11: =(1-1/A11^(Dual!$C$11-1)*((2*Dual!$C$10^Dual!$C$11-1)/((2-1)+Dual!$C$11*2*(Dual!$C$10-1))))*100 -> 62.840974 | H11: 2.25 | I11: =(1-1/Dual!$C$8^(Dual!$C$11-1)*((H11*Dual!$C$10^Dual!$C$11-1)/((H11-1)+Dual!$C$11*H11*(Dual!$C$10-1))))*100 -> 64.862776 | J11: =H11*Dual!$B$34 -> 8621.3958 | K11: =Dual!$C$10*H11*Dual!$C$34 -> 3273.9478
A12: 15 | B12: =(1-1/A12^(Dual!$C$11-1))*100 -> 66.149624 | C12: =(1-1/A12^(Dual!$C$11-1)*((Dual!$C$10^Dual!$C$11-1)/(Dual!$C$11*(Dual!$C$10-1))))*100 -> 62.485062 | D12: =(1-1/A12^(Dual!$C$11-1)*((1.25*Dual!$C$10^Dual!$C$11-1)/((1.25-1)+Dual!$C$11*1.25*(Dual!$C$10-1))))*100 -> 63.189785 | E12: =(1-1/A12^(Dual!$C$11-1)*((1.5*Dual!$C$10^Dual!$C$11-1)/((1.5-1)+Dual!$C$11*1.5*(Dual!$C$10-1))))*100 -> 63.526131 | F12: =(1-1/A12^(Dual!$C$11-1)*((2*Dual!$C$10^Dual!$C$11-1)/((2-1)+Dual!$C$11*2*(Dual!$C$10-1))))*100 -> 63.852436 | H12: 2.5 | I12: =(1-1/Dual!$C$8^(Dual!$C$11-1)*((H12*Dual!$C$10^Dual!$C$11-1)/((H12-1)+Dual!$C$11*H12*(Dual!$C$10-1))))*100 -> 64.929119 | J12: =H12*Dual!$B$34 -> 9579.3287 | K12: =Dual!$C$10*H12*Dual!$C$34 -> 3637.7198
A13: 16 | B13: =(1-1/A13^(Dual!$C$11-1))*100 -> 67.012302 | C13: =(1-1/A13^(Dual!$C$11-1)*((Dual!$C$10^Dual!$C$11-1)/(Dual!$C$11*(Dual!$C$10-1))))*100 -> 63.441132 | D13: =(1-1/A13^(Dual!$C$11-1)*((1.25*Dual!$C$10^Dual!$C$11-1)/((1.25-1)+Dual!$C$11*1.25*(Dual!$C$10-1))))*100 -> 64.127895 | E13: =(1-1/A13^(Dual!$C$11-1)*((1.5*Dual!$C$10^Dual!$C$11-1)/((1.5-1)+Dual!$C$11*1.5*(Dual!$C$10-1))))*100 -> 64.455669 | F13: =(1-1/A13^(Dual!$C$11-1)*((2*Dual!$C$10^Dual!$C$11-1)/((2-1)+Dual!$C$11*2*(Dual!$C$10-1))))*100 -> 64.773658
A14: 17 | B14: =(1-1/A14^(Dual!$C$11-1))*100 -> 67.802628 | C14: =(1-1/A14^(Dual!$C$11-1)*((Dual!$C$10^Dual!$C$11-1)/(Dual!$C$11*(Dual!$C$10-1))))*100 -> 64.317016 | D14: =(1-1/A14^(Dual!$C$11-1)*((1.25*Dual!$C$10^Dual!$C$11-1)/((1.25-1)+Dual!$C$11*1.25*(Dual!$C$10-1))))*100 -> 64.987326 | E14: =(1-1/A14^(Dual!$C$11-1)*((1.5*Dual!$C$10^Dual!$C$11-1)/((1.5-1)+Dual!$C$11*1.5*(Dual!$C$10-1))))*100 -> 65.307246 | F14: =(1-1/A14^(Dual!$C$11-1)*((2*Dual!$C$10^Dual!$C$11-1)/((2-1)+Dual!$C$11*2*(Dual!$C$10-1))))*100 -> 65.617617 | H14: Con α = 1 el ciclo dual se reduce al Diesel; con β = 1, al Otto.
A15: 18 | B15: =(1-1/A15^(Dual!$C$11-1))*100 -> 68.530416 | C15: =(1-1/A15^(Dual!$C$11-1)*((Dual!$C$10^Dual!$C$11-1)/(Dual!$C$11*(Dual!$C$10-1))))*100 -> 65.123593 | D15: =(1-1/A15^(Dual!$C$11-1)*((1.25*Dual!$C$10^Dual!$C$11-1)/((1.25-1)+Dual!$C$11*1.25*(Dual!$C$10-1))))*100 -> 65.778751 | E15: =(1-1/A15^(Dual!$C$11-1)*((1.5*Dual!$C$10^Dual!$C$11-1)/((1.5-1)+Dual!$C$11*1.5*(Dual!$C$10-1))))*100 -> 66.091441 | F15: =(1-1/A15^(Dual!$C$11-1)*((2*Dual!$C$10^Dual!$C$11-1)/((2-1)+Dual!$C$11*2*(Dual!$C$10-1))))*100 -> 66.394796
A16: 19 | B16: =(1-1/A16^(Dual!$C$11-1))*100 -> 69.203699 | C16: =(1-1/A16^(Dual!$C$11-1)*((Dual!$C$10^Dual!$C$11-1)/(Dual!$C$11*(Dual!$C$10-1))))*100 -> 65.869763 | D16: =(1-1/A16^(Dual!$C$11-1)*((1.25*Dual!$C$10^Dual!$C$11-1)/((1.25-1)+Dual!$C$11*1.25*(Dual!$C$10-1))))*100 -> 66.510905 | E16: =(1-1/A16^(Dual!$C$11-1)*((1.5*Dual!$C$10^Dual!$C$11-1)/((1.5-1)+Dual!$C$11*1.5*(Dual!$C$10-1))))*100 -> 66.816904 | F16: =(1-1/A16^(Dual!$C$11-1)*((2*Dual!$C$10^Dual!$C$11-1)/((2-1)+Dual!$C$11*2*(Dual!$C$10-1))))*100 -> 67.113769
A17: 20 | B17: =(1-1/A17^(Dual!$C$11-1))*100 -> 69.829118 | C17: =(1-1/A17^(Dual!$C$11-1)*((Dual!$C$10^Dual!$C$11-1)/(Dual!$C$11*(Dual!$C$10-1))))*100 -> 66.56289 | D17: =(1-1/A17^(Dual!$C$11-1)*((1.25*Dual!$C$10^Dual!$C$11-1)/((1.25-1)+Dual!$C$11*1.25*(Dual!$C$10-1))))*100 -> 67.19101 | E17: =(1-1/A17^(Dual!$C$11-1)*((1.5*Dual!$C$10^Dual!$C$11-1)/((1.5-1)+Dual!$C$11*1.5*(Dual!$C$10-1))))*100 -> 67.490795 | F17: =(1-1/A17^(Dual!$C$11-1)*((2*Dual!$C$10^Dual!$C$11-1)/((2-1)+Dual!$C$11*2*(Dual!$C$10-1))))*100 -> 67.781632
A18: 21 | B18: =(1-1/A18^(Dual!$C$11-1))*100 -> 70.412227 | C18: =(1-1/A18^(Dual!$C$11-1)*((Dual!$C$10^Dual!$C$11-1)/(Dual!$C$11*(Dual!$C$10-1))))*100 -> 67.209124 | D18: =(1-1/A18^(Dual!$C$11-1)*((1.25*Dual!$C$10^Dual!$C$11-1)/((1.25-1)+Dual!$C$11*1.25*(Dual!$C$10-1))))*100 -> 67.825105 | E18: =(1-1/A18^(Dual!$C$11-1)*((1.5*Dual!$C$10^Dual!$C$11-1)/((1.5-1)+Dual!$C$11*1.5*(Dual!$C$10-1))))*100 -> 68.119096 | F18: =(1-1/A18^(Dual!$C$11-1)*((2*Dual!$C$10^Dual!$C$11-1)/((2-1)+Dual!$C$11*2*(Dual!$C$10-1))))*100 -> 68.404311
A19: 22 | B19: =(1-1/A19^(Dual!$C$11-1))*100 -> 70.957705 | C19: =(1-1/A19^(Dual!$C$11-1)*((Dual!$C$10^Dual!$C$11-1)/(Dual!$C$11*(Dual!$C$10-1))))*100 -> 67.813655 | D19: =(1-1/A19^(Dual!$C$11-1)*((1.25*Dual!$C$10^Dual!$C$11-1)/((1.25-1)+Dual!$C$11*1.25*(Dual!$C$10-1))))*100 -> 68.41828 | E19: =(1-1/A19^(Dual!$C$11-1)*((1.5*Dual!$C$10^Dual!$C$11-1)/((1.5-1)+Dual!$C$11*1.5*(Dual!$C$10-1))))*100 -> 68.706851 | F19: =(1-1/A19^(Dual!$C$11-1)*((2*Dual!$C$10^Dual!$C$11-1)/((2-1)+Dual!$C$11*2*(Dual!$C$10-1))))*100 -> 68.986808
A20: 23 | B20: =(1-1/A20^(Dual!$C$11-1))*100 -> 71.469534 | C20: =(1-1/A20^(Dual!$C$11-1)*((Dual!$C$10^Dual!$C$11-1)/(Dual!$C$11*(Dual!$C$10-1))))*100 -> 68.380893 | D20: =(1-1/A20^(Dual!$C$11-1)*((1.25*Dual!$C$10^Dual!$C$11-1)/((1.25-1)+Dual!$C$11*1.25*(Dual!$C$10-1))))*100 -> 68.974862 | E20: =(1-1/A20^(Dual!$C$11-1)*((1.5*Dual!$C$10^Dual!$C$11-1)/((1.5-1)+Dual!$C$11*1.5*(Dual!$C$10-1))))*100 -> 69.258348 | F20: =(1-1/A20^(Dual!$C$11-1)*((2*Dual!$C$10^Dual!$C$11-1)/((2-1)+Dual!$C$11*2*(Dual!$C$10-1))))*100 -> 69.533371
A21: 24 | B21: =(1-1/A21^(Dual!$C$11-1))*100 -> 71.951121 | C21: =(1-1/A21^(Dual!$C$11-1)*((Dual!$C$10^Dual!$C$11-1)/(Dual!$C$11*(Dual!$C$10-1))))*100 -> 68.914616 | D21: =(1-1/A21^(Dual!$C$11-1)*((1.25*Dual!$C$10^Dual!$C$11-1)/((1.25-1)+Dual!$C$11*1.25*(Dual!$C$10-1))))*100 -> 69.498559 | E21: =(1-1/A21^(Dual!$C$11-1)*((1.5*Dual!$C$10^Dual!$C$11-1)/((1.5-1)+Dual!$C$11*1.5*(Dual!$C$10-1))))*100 -> 69.777259 | F21: =(1-1/A21^(Dual!$C$11-1)*((2*Dual!$C$10^Dual!$C$11-1)/((2-1)+Dual!$C$11*2*(Dual!$C$10-1))))*100 -> 70.04764

Sheet Graficas
